Workbook

Sheet 0831
B1: 屏榮 新豐廠組合室生產人時性分析
B3: 日期 | C3: =TEXT('0831 4度C'!A2,"yyyy.mm.ddaaaa") -> 2025.08.31星期日 | E3: 訂單量 | F3: ='0831 4度C'!D1 -> 177923 | H3: 營業額 | I3: ='0831 4度C'!F1 -> 6112909.4
B4: 人時性 | C4: 項目 | E4: ➀ | G4: ➁ | I4: ➂
C5: 組合室 | E5: 全溫層 | G5: 4度C-各編組展開 | I5: ③三明治-各編組展開
C6: 排關平均 | E6: =AVERAGE(D13:M13) -> 145.72901 | F6: =AVERAGE(D27:O27,D13:J13) -> 149.18301 | G6: =AVERAGE(D13:J13) -> 149.18301 | I6: =AVERAGE(K13:M13) -> 137.66968
C7: 實績平均 | E7: =AVERAGE(D14:M14) -> 136.81184 | F7: =AVERAGE(D28:O28,D14:J14) -> 140.20342 | G7: =AVERAGE(D14:J14) -> 140.20342 | I7: =AVERAGE(K14:M14) -> 128.89813
C8: 達成率平均 | E8: =AVERAGE(D15:M15) -> 0.93827697 | F8: =AVERAGE(D15:J15,D29:O29) -> 0.93912102 | G8: =AVERAGE(D15:J15) -> 0.93912102 | I8: =AVERAGE(K15:M15) -> 0.9363075 | K8: ※現行日本鮮食廠以達成率80%為基本(即為現行KPI)
B10: 溫層 | D10: ➁4度C-各編組展開 | K10: ③三明治-各編組展開
B11: 編組 | D11: 1 | E11: 2 | F11: 3 | G11: 4 | H11: 5 | I11: 6 | J11: 7 | K11: 1 | L11: 2 | M11: 3
D12: 新豐6線 | E12: 新豐2線 | F12: 新豐5線 | G12: 新豐7線 | H12: 新豐3線 | I12: 新豐1線 | J12: 新豐10線 | K12: 新豐8線 | L12: 新豐9線 | M12: 新豐4線
B13: 人時性 | C13: 排關 | D13: =SUMIFS('0831 4度C'!$K:$K,'0831 4度C'!$A:$A,"新豐6線",'0831 4度C'!$B:$B,"平均") -> 117.64706 | E13: =SUMIFS('0831 4度C'!$K:$K,'0831 4度C'!$A:$A,"新豐2線",'0831 4度C'!$B:$B,"平均") -> 83.333333 | F13: =SUMIFS('0831 4度C'!$K:$K,'0831 4度C'!$A:$A,"新豐5線",'0831 4度C'!$B:$B,"平均") -> 93.220339 | G13: =SUMIFS('0831 4度C'!$K:$K,'0831 4度C'!$A:$A,"新豐7線",'0831 4度C'!$B:$B,"平均") -> 116.50485 | H13: =SUMIFS('0831 4度C'!$K:$K,'0831 4度C'!$A:$A,"新豐3線",'0831 4度C'!$B:$B,"平均") -> 300 | I13: =SUMIFS('0831 4度C'!$K:$K,'0831 4度C'!$A:$A,"新豐1線",'0831 4度C'!$B:$B,"平均") -> 114.45783 | J13: =SUMIFS('0831 4度C'!$K:$K,'0831 4度C'!$A:$A,"新豐10線",'0831 4度C'!$B:$B,"平均") -> 219.11765 | K13: =SUMIFS('0831 4度C'!$K:$K,'0831 4度C'!$A:$A,"新豐8線",'0831 4度C'!$B:$B,"平均") -> 140 | L13: =SUMIFS('0831 4度C'!$K:$K,'0831 4度C'!$A:$A,"新豐9線",'0831 4度C'!$B:$B,"平均") -> 130.43478 | M13: =SUMIFS('0831 4度C'!$K:$K,'0831 4度C'!$A:$A,"新豐4線",'0831 4度C'!$B:$B,"平均") -> 142.57426
C14: 實績 | D14: =SUMIFS('0831 4度C'!$N:$N,'0831 4度C'!$A:$A,"新豐6線",'0831 4度C'!$B:$B,"平均") -> 111.02455 | E14: =SUMIFS('0831 4度C'!$N:$N,'0831 4度C'!$A:$A,"新豐2線",'0831 4度C'!$B:$B,"平均") -> 77.805499 | F14: =SUMIFS('0831 4度C'!$N:$N,'0831 4度C'!$A:$A,"新豐5線",'0831 4度C'!$B:$B,"平均") -> 87.243513 | G14: =SUMIFS('0831 4度C'!$N:$N,'0831 4度C'!$A:$A,"新豐7線",'0831 4度C'!$B:$B,"平均") -> 109.44308 | H14: =SUMIFS('0831 4度C'!$N:$N,'0831 4度C'!$A:$A,"新豐3線",'0831 4度C'!$B:$B,"平均") -> 282.18049 | I14: =SUMIFS('0831 4度C'!$N:$N,'0831 4度C'!$A:$A,"新豐1線",'0831 4度C'!$B:$B,"平均") -> 107.5526 | J14: =SUMIFS('0831 4度C'!$N:$N,'0831 4度C'!$A:$A,"新豐10線",'0831 4度C'!$B:$B,"平均") -> 206.17424 | K14: =SUMIFS('0831 4度C'!$N:$N,'0831 4度C'!$A:$A,"新豐8線",'0831 4度C'!$B:$B,"平均") -> 131.17921 | L14: =SUMIFS('0831 4度C'!$N:$N,'0831 4度C'!$A:$A,"新豐9線",'0831 4度C'!$B:$B,"平均") -> 122.2055 | M14: =SUMIFS('0831 4度C'!$N:$N,'0831 4度C'!$A:$A,"新豐4線",'0831 4度C'!$B:$B,"平均") -> 133.30969
C15: 達成率 | D15: =D14/D13 -> 0.94370867 | E15: =E14/E13 -> 0.93366599 | F15: =F14/F13 -> 0.93588495 | G15: =G14/G13 -> 0.93938645 | H15: =H14/H13 -> 0.94060165 | I15: =I14/I13 -> 0.93967006 | J15: =J14/J13 -> 0.9409294 | K15: =K14/K13 -> 0.93699432 | ... M15: =M14/M13 -> 0.93501935
B16: 作業 時間 | C16: 開始 | D16: =VLOOKUP("新豐6線",'0831 4度C'!$A:$T,19,0) -> 0.70833333 | E16: =VLOOKUP("新豐2線",'0831 4度C'!$A:$T,19,0) -> 0.125 | F16: =VLOOKUP("新豐5線",'0831 4度C'!$A:$T,19,0) -> 0.25 | G16: =VLOOKUP("新豐7線",'0831 4度C'!$A:$T,19,0) -> 0.20833333 | H16: =VLOOKUP("新豐3線",'0831 4度C'!$A:$T,19,0) -> 0.125 | I16: =VLOOKUP("新豐1線",'0831 4度C'!$A:$T,19,0) -> 0.29166667 | J16: =VLOOKUP("新豐10線",'0831 4度C'!$A:$T,19,0) -> 0.125 | K16: =VLOOKUP("新豐8線",'0831 4度C'!$A:$T,19,0) -> 0.125 | L16: =VLOOKUP("新豐9線",'0831 4度C'!$A:$T,19,0) -> 0.125 | M16: =VLOOKUP("新豐4線",'0831 4度C'!$A:$T,19,0) -> 0.125
C17: 結束 | D17: =LOOKUP(2,1/(('0831 4度C'!$A:$A="新豐6線")*('0831 4度C'!$T:$T<>"")),'0831 4度C'!$T:$T) -> 0.84166667 | E17: =LOOKUP(2,1/(('0831 4度C'!$A:$A="新豐2線")*('0831 4度C'!$T:$T<>"")),'0831 4度C'!$T:$T) -> 0.68888889 | F17: =LOOKUP(2,1/(('0831 4度C'!$A:$A="新豐5線")*('0831 4度C'!$T:$T<>"")),'0831 4度C'!$T:$T) -> 0.84861111 | G17: =LOOKUP(2,1/(('0831 4度C'!$A:$A="新豐7線")*('0831 4度C'!$T:$T<>"")),'0831 4度C'!$T:$T) -> 0.80625 | H17: =LOOKUP(2,1/(('0831 4度C'!$A:$A="新豐3線")*('0831 4度C'!$T:$T<>"")),'0831 4度C'!$T:$T) -> 0.59513889 | I17: =LOOKUP(2,1/(('0831 4度C'!$A:$A="新豐1線")*('0831 4度C'!$T:$T<>"")),'0831 4度C'!$T:$T) -> 0.85138889 | J17: =LOOKUP(2,1/(('0831 4度C'!$A:$A="新豐10線")*('0831 4度C'!$T:$T<>"")),'0831 4度C'!$T:$T) -> 0.45416667 | K17: =LOOKUP(2,1/(('0831 4度C'!$A:$A="新豐8線")*('0831 4度C'!$T:$T<>"")),'0831 4度C'!$T:$T) -> 0.67152778 | L17: =LOOKUP(2,1/(('0831 4度C'!$A:$A="新豐9線")*('0831 4度C'!$T:$T<>"")),'0831 4度C'!$T:$T) -> 0.7625 | M17: =LOOKUP(2,1/(('0831 4度C'!$A:$A="新豐4線")*('0831 4度C'!$T:$T<>"")),'0831 4度C'!$T:$T) -> 0.66736111
B18: 配置人數 | D18: =SUMIFS('0831 4度C'!$I:$I,'0831 4度C'!$A:$A,"新豐6線",'0831 4度C'!$B:$B,"平均") -> 17 | E18: =SUMIFS('0831 4度C'!$I:$I,'0831 4度C'!$A:$A,"新豐2線",'0831 4度C'!$B:$B,"平均") -> 18 | F18: =SUMIFS('0831 4度C'!$I:$I,'0831 4度C'!$A:$A,"新豐5線",'0831 4度C'!$B:$B,"平均") -> 19.666667 | G18: =SUMIFS('0831 4度C'!$I:$I,'0831 4度C'!$A:$A,"新豐7線",'0831 4度C'!$B:$B,"平均") -> 17.166667 | H18: =SUMIFS('0831 4度C'!$I:$I,'0831 4度C'!$A:$A,"新豐3線",'0831 4度C'!$B:$B,"平均") -> 10 | I18: =SUMIFS('0831 4度C'!$I:$I,'0831 4度C'!$A:$A,"新豐1線",'0831 4度C'!$B:$B,"平均") -> 16.6 | J18: =SUMIFS('0831 4度C'!$I:$I,'0831 4度C'!$A:$A,"新豐10線",'0831 4度C'!$B:$B,"平均") -> 11.333333 | K18: =SUMIFS('0831 4度C'!$I:$I,'0831 4度C'!$A:$A,"新豐8線",'0831 4度C'!$B:$B,"平均") -> 17.142857 | L18: =SUMIFS('0831 4度C'!$I:$I,'0831 4度C'!$A:$A,"新豐9線",'0831 4度C'!$B:$B,"平均") -> 18.4 | M18: =SUMIFS('0831 4度C'!$I:$I,'0831 4度C'!$A:$A,"新豐4線",'0831 4度C'!$B:$B,"平均") -> 16.833333
B19: 主要應用設備 | D19: ET-55 | E19: 熱縮爐 | F19: L型包裝機 | G19: L型包裝機 | H19: 伺服包裝機 | I19: ET-55 | J19: 伺服包裝機 | K19: 三明治包裝機 | L19: 三明治包裝機 | M19: 三明治包裝機
B20: 次要應用設備 | F20: 圓盤機 | G20: ET-55
B21: 備註 | E21: 握沙拉 | F21: 共用L型包裝機 | H21: 調理麵包 | I21: 炒飯+沙拉 | J21: 調理麵包

Sheet 0831 4度C
A1: 新豐廠四度C日報分析 | C1: 總生產量 | D1: =SUM(F5:F72) -> 177923 | E1: 營業額 | F1: =SUM(G5:G72) -> 6112909.4 | G1: 出勤人數 | H1: =L8+L13+L52+L58+L17+L65+L32+L43+L24+L72 -> 162.14286 | I1: 產線配置圖 | L1: 生產實績 | O1: 人時性差異分析 | S1: 日報登錄 | Y1: 分析說明 | AA1: 產能差異分析
A2: 45900 | B2: 星期日 | C2: 人時性 | D2: =AVERAGE(N8,N13,N52,N58,N17,N65,N24,N32,N43,N72) -> 136.81184 | E2: 平均廠價 | F2: =F1/D1 -> 34.35705 | G2: 多次生產數 | H2: =COUNT(H5:H72) -> 9
A3: 線別 | B3: 品類 | C3: 品名 | E3: 廠價 | F3: 生產量 | G3: 營收 | H3: 多次 生產 | I3: 人數 | J3: 產能/時 | K3: 人時性 | L3: 人數 | M3: 產能/時 | N3: 人時性 | O3: 人數 | P3: 人時性 | Q3: 達成率 | R3: 達成率平均 | S3: 生產時間 | U3: 換線、休息/分 | V3: 稼動時間/分 | W3: 休息時間 | Y3: (新豐回填) | AA3: 產能/時 | AB3: 達成率 | AC3: 達成率平均
S4: 開始 | T4: 結束 | W4: 開始 | X4: 結束
A5: 新豐6線 | B5: 微波主食 | C5: 二配煸椒烘蛋飯 | E5: 46.93 | F5: 1086 | G5: =E5*F5 -> 50965.98 | I5: 17 | J5: 2000 | K5: =J5/I5 -> 117.64706 | L5: 17 | M5: =F5/V5*60 -> 1916.4706 | N5: =M5/L5 -> 112.73356 | O5: =L5-I5 -> 0 | P5: =N5-K5 -> -4.9134948 | Q5: =N5/K5 -> 0.95823529 | R5: =Q8 -> 0.94370867 | S5: 0.70833333 | T5: 0.73194444 | V5: =(T5-S5)*24*60 -> 34 | AA5: =M5-J5 -> -83.529412 | AB5: =M5/J5 -> 0.95823529 | AC5: =AB8 -> 0.94370867
A6: 新豐6線 | B6: 微波主食 | C6: 二配川味麻婆燒豆腐燴飯 | E6: 50.49 | F6: 2314 | G6: =E6*F6 -> 116833.86 | I6: 16 | J6: 2000 | K6: =J6/I6 -> 125 | L6: 16 | M6: =F6/V6*60 -> 1876.2162 | N6: =M6/L6 -> 117.26351 | O6: =L6-I6 -> 0 | P6: =N6-K6 -> -7.7364865 | Q6: =N6/K6 -> 0.93810811 | S6: 0.73680556 | T6: 0.78819444 | U6: =(S6-T5)*24*60 -> 7 | V6: =(T6-S6)*24*60 -> 74 | AA6: =M6-J6 -> -123.78378 | AB6: =M6/J6 -> 0.93810811
A7: 新豐6線 | B7: 微波主食 | C7: 二配港式香滑嫩蛋牛肉燴飯 | E7: 50.67 | F7: 2150 | G7: =E7*F7 -> 108940.5 | I7: 18 | J7: 2000 | K7: =J7/I7 -> 111.11111 | L7: 18 | M7: =F7/V7*60 -> 1869.5652 | N7: =M7/L7 -> 103.86473 | O7: =L7-I7 -> 0 | P7: =N7-K7 -> -7.2463768 | Q7: =N7/K7 -> 0.93478261 | S7: 0.79375 | T7: 0.84166667 | U7: =(S7-T6)*24*60 -> 8 | V7: =(T7-S7)*24*60 -> 69 | AA7: =M7-J7 -> -130.43478 | AB7: =M7/J7 -> 0.93478261
A8: 新豐6線 | B8: 平均 | I8: 17 | J8: 2000 | K8: =J8/I8 -> 117.64706 | L8: 17 | M8: =AVERAGE(M5:M7) -> 1887.4173 | N8: =M8/L8 -> 111.02455 | O8: =L8-I8 -> 0 | P8: =N8-K8 -> -6.6225094 | Q8: =N8/K8 -> 0.94370867 | AA8: =M8-J8 -> -112.58266 | AB8: =M8/J8 -> 0.94370867
A9: 新豐2線 | B9: 沙拉 | C9: 青醬優格雞肉握沙拉(113年) | E9: 39.62 | F9: 5211 | G9: =E9*F9 -> 206459.82 | I9: 19 | J9: 1500 | K9: =J9/I9 -> 78.947368 | L9: 19 | M9: =F9/V9*60 -> 1402.0628 | N9: =M9/L9 -> 73.792778 | O9: =L9-I9 -> 0 | P9: =N9-K9 -> -5.1545905 | Q9: =N9/K9 -> 0.93470852 | R9: =Q13 -> 0.93366599 | S9: 0.125 | T9: 0.27986111 | V9: =(T9-S9)*24*60 -> 223 | W9: =T9 -> 0.27986111 | X9: =S10 -> 0.3 | AA9: =M9-J9 -> -97.93722 | AB9: =M9/J9 -> 0.93470852 | AC9: =AB13 -> 0.93366599
A10: 新豐2線 | B10: 沙拉 | C10: 青檸烤雞握沙拉(113年) | E10: 39.8 | F10: 3000 | G10: =E10*F10 -> 119400 | H10: 2 | I10: 17 | J10: 1500 | K10: =J10/I10 -> 88.235294 | L10: 17 | M10: =F10/V10*60 -> 1395.3488 | N10: =M10/L10 -> 82.079343 | O10: =L10-I10 -> 0 | P10: =N10-K10 -> -6.1559508 | Q10: =N10/K10 -> 0.93023256 | S10: 0.3 | T10: 0.38958333 | U10: =(S10-T9)*24*60 -> 29 | V10: =(T10-S10)*24*60 -> 129 | AA10: =M10-J10 -> -104.65116 | AB10: =M10/J10 -> 0.93023256
A11: 新豐2線 | B11: 沙拉 | C11: 地瓜瓜握沙拉 | E11: 39.29 | F11: 4252 | G11: =E11*F11 -> 167061.08 | I11: 19 | J11: 1500 | K11: =J11/I11 -> 78.947368 | L11: 19 | M11: =F11/V11*60 -> 1401.7582 | N11: =M11/L11 -> 73.77675 | O11: =L11-I11 -> 0 | P11: =N11-K11 -> -5.1706189 | Q11: =N11/K11 -> 0.93450549 | S11: 0.39444444 | T11: 0.52083333 | U11: =(S11-T10)*24*60 -> 7 | V11: =(T11-S11)*24*60 -> 182 | W11: =T11 -> 0.52083333 | X11: =S12 -> 0.56111111 | AA11: =M11-J11 -> -98.241758 | AB11: =M11/J11 -> 0.93450549
A12: 新豐2線 | B12: 沙拉 | C12: 青檸烤雞握沙拉(113年) | E12: 39.8 | F12: 4302 | G12: =E12*F12 -> 171219.6 | I12: 17 | J12: 1500 | K12: =J12/I12 -> 88.235294 | L12: 17 | M12: =F12/V12*60 -> 1402.8261 | N12: =M12/L12 -> 82.519182 | O12: =L12-I12 -> 0 | P12: =N12-K12 -> -5.7161125 | Q12: =N12/K12 -> 0.93521739 | S12: 0.56111111 | T12: 0.68888889 | U12: =(S12-T11)*24*60 -> 58 | V12: =(T12-S12)*24*60 -> 184 | AA12: =M12-J12 -> -97.173913 | AB12: =M12/J12 -> 0.93521739
A13: 新豐2線 | B13: 平均 | I13: 18 | J13: 1500 | K13: =J13/I13 -> 83.333333 | L13: 18 | M13: =AVERAGE(M9:M12) -> 1400.499 | N13: =M13/L13 -> 77.805499 | O13: =L13-I13 -> 0 | P13: =N13-K13 -> -5.5278341 | Q13: =N13/K13 -> 0.93366599 | AA13: =M13-J13 -> -99.501013 | AB13: =M13/J13 -> 0.93366599
A14: 新豐5線 | B14: 小吃 | C14: 剝皮辣椒雞湯 | E14: 41 | F14: 2041 | G14: =E14*F14 -> 83681 | I14: 26 | J14: 1500 | K14: =J14/I14 -> 57.692308 | L14: 26 | M14: =F14/V14*60 -> 1407.5862 | N14: =M14/L14 -> 54.137931 | O14: =L14-I14 -> 0 | P14: =N14-K14 -> -3.5543767 | Q14: =N14/K14 -> 0.9383908 | R14: =Q17 -> 0.93588495 | S14: 0.25 | T14: 0.31041667 | V14: =(T14-S14)*24*60 -> 87 | AA14: =M14-J14 -> -92.413793 | AB14: =M14/J14 -> 0.9383908 | AC14: =AB17 -> 0.93588495
A15: 新豐5線 | B15: 微波主食 | C15: 二配金咖哩濃厚辛辣咖哩飯 | E15: 50.98 | F15: 2924 | G15: =E15*F15 -> 149065.52 | I15: 17 | J15: 2000 | K15: =J15/I15 -> 117.64706 | L15: 17 | M15: =F15/V15*60 -> 1866.383 | N15: =M15/L15 -> 109.78723 | O15: =L15-I15 -> 0 | P15: =N15-K15 -> -7.8598248 | Q15: =N15/K15 -> 0.93319149 | S15: 0.70833333 | T15: 0.77361111 | U15: =IF(S15=TIME(17,0,0),"",(S15-T14)*24*60) | V15: =(T15-S15)*24*60 -> 94 | AA15: =M15-J15 -> -133.61702 | AB15: =M15/J15 -> 0.93319149
A16: 新豐5線 | B16: 微波主食 | C16: 二配金咖哩果香甘口咖哩飯 | E16: 50.92 | F16: 3216 | G16: =E16*F16 -> 163758.72 | I16: 16 | J16: 2000 | K16: =J16/I16 -> 125 | L16: 16 | M16: =F16/V16*60 -> 1873.3981 | N16: =M16/L16 -> 117.08738 | O16: =L16-I16 -> 0 | P16: =N16-K16 -> -7.9126214 | Q16: =N16/K16 -> 0.93669903 | S16: 0.77708333 | T16: 0.84861111 | U16: =IF(S16=TIME(17,0,0),"",(S16-T15)*24*60) -> 5 | V16: =(T16-S16)*24*60 -> 103 | AA16: =M16-J16 -> -126.60194 | AB16: =M16/J16 -> 0.93669903
A17: 新豐5線 | B17: 平均 | I17: 19.666667 | J17: 1833.3333 | K17: =J17/I17 -> 93.220339 | L17: 19.666667 | M17: =AVERAGE(M14:M16) -> 1715.7891 | N17: =M17/L17 -> 87.243513 | O17: =L17-I17 -> 0 | P17: =N17-K17 -> -5.9768264 | Q17: =N17/K17 -> 0.93588495 | AA17: =M17-J17 -> -117.54425 | AB17: =M17/J17 -> 0.93588495
A18: 新豐7線 | B18: 小吃 | C18: 古早味炒炊粉 | E18: 43.14 | F18: 1597 | G18: =E18*F18 -> 68894.58 | I18: 17 | J18: 2000 | K18: =J18/I18 -> 117.64706 | L18: 17 | M18: =F18/V18*60 -> 1878.8235 | N18: =M18/L18 -> 110.51903 | O18: =L18-I18 -> 0 | P18: =N18-K18 -> -7.1280277 | Q18: =N18/K18 -> 0.93941176 | R18: =Q24 -> 0.93938645 | S18: 0.20833333 | T18: 0.24375 | V18: =(T18-S18)*24*60 -> 51 | AA18: =M18-J18 -> -121.17647 | AB18: =M18/J18 -> 0.93941176 | AC18: =AB24 -> 0.93938645
A19: 新豐7線 | B19: 微波主食 | C19: 鐵板滑蛋炸豬排丼 | E19: 57.73 | F19: 2970 | G19: =E19*F19 -> 171458.1 | I19: 16 | J19: 2000 | K19: =J19/I19 -> 125 | L19: 16 | M19: =F19/V19*60 -> 1875.7895 | N19: =M19/L19 -> 117.23684 | O19: =L19-I19 -> 0 | P19: =N19-K19 -> -7.7631579 | Q19: =N19/K19 -> 0.93789474 | S19: 0.24861111 | T19: 0.31458333 | U19: =IF(S19=TIME(17,0,0),"",(S19-T18)*24*60) -> 7 | V19: =(T19-S19)*24*60 -> 95 | AA19: =M19-J19 -> -124.21053 | AB19: =M19/J19 -> 0.93789474
A20: 新豐7線 | B20: 微波主食 | C20: 極上炙烤親子丼 | E20: 53.68 | F20: 2021 | G20: =E20*F20 -> 108487.28 | I20: 17 | J20: 2000 | K20: =J20/I20 -> 117.64706 | L20: 17 | M20: =F20/V20*60 -> 1865.5385 | N20: =M20/L20 -> 109.73756 | O20: =L20-I20 -> 0 | P20: =N20-K20 -> -7.9095023 | Q20: =N20/K20 -> 0.93276923 | S20: 0.32013889 | T20: 0.36527778 | U20: =IF(S20=TIME(17,0,0),"",(S20-T19)*24*60) -> 8 | V20: =(T20-S20)*24*60 -> 65 | AA20: =M20-J20 -> -134.46154 | AB20: =M20/J20 -> 0.93276923
A21: 新豐7線 | B21: 微波主食 | C21: 海老鰻魚丼滋丼 | E21: 58.17 | F21: 1838 | G21: =E21*F21 -> 106916.46 | I21: 18 | J21: 2000 | K21: =J21/I21 -> 111.11111 | L21: 18 | M21: =F21/V21*60 -> 1869.1525 | N21: =M21/L21 -> 103.84181 | O21: =L21-I21 -> 0 | P21: =N21-K21 -> -7.2693032 | Q21: =N21/K21 -> 0.93457627 | S21: 0.36944444 | T21: 0.41041667 | U21: =IF(S21=TIME(17,0,0),"",(S21-T20)*24*60) -> 6 | V21: =(T21-S21)*24*60 -> 59 | AA21: =M21-J21 -> -130.84746 | AB21: =M21/J21 -> 0.93457627
A22: 新豐7線 | B22: 微波主食 | C22: 二配美味蟹煲 | E22: 54.09 | F22: 3666 | G22: =E22*F22 -> 198293.94 | I22: 20 | J22: 2000 | K22: =J22/I22 -> 100 | L22: 20 | M22: =F22/V22*60 -> 1880 | N22: =M22/L22 -> 94 | O22: =L22-I22 -> 0 | P22: =N22-K22 -> -6 | Q22: =N22/K22 -> 0.94 | S22: 0.70833333 | T22: 0.78958333 | U22: =IF(S22=TIME(17,0,0),"",(S22-T21)*24*60) | V22: =(T22-S22)*24*60 -> 117 | AA22: =M22-J22 -> -120 | AB22: =M22/J22 -> 0.94
A23: 新豐7線 | B23: 微波主食 | C23: 二配極旨黑咖哩漢堡排飯 | E23: 53.27 | F23: 571 | G23: =E23*F23 -> 30417.17 | I23: 15 | J23: 2000 | K23: =J23/I23 -> 133.33333 | L23: 15 | M23: =F23/V23*60 -> 1903.3333 | N23: =M23/L23 -> 126.88889 | O23: =L23-I23 -> 0 | P23: =N23-K23 -> -6.4444444 | Q23: =N23/K23 -> 0.95166667 | S23: 0.79375 | T23: 0.80625 | U23: =IF(S23=TIME(17,0,0),"",(S23-T22)*24*60) -> 6 | V23: =(T23-S23)*24*60 -> 18 | AA23: =M23-J23 -> -96.666667 | AB23: =M23/J23 -> 0.95166667
A24: 新豐7線 | B24: 平均 | I24: 17.166667 | J24: 2000 | K24: =J24/I24 -> 116.50485 | L24: 17.166667 | M24: =AVERAGE(M18:M23) -> 1878.7729 | N24: =M24/L24 -> 109.44308 | O24: =L24-I24 -> 0 | P24: =N24-K24 -> -7.0617734 | Q24: =N24/K24 -> 0.93938645 | AA24: =M24-J24 -> -121.22711 | AB24: =M24/J24 -> 0.93938645
A25: 新豐8線 | B25: 三明治 | C25: 經典總匯三明治 | E25: 26.2 | F25: 4467 | G25: =E25*F25 -> 117035.4 | I25: 20 | J25: 2400 | K25: =J25/I25 -> 120 | L25: 20 | M25: =F25/V25*60 -> 2233.5 | N25: =M25/L25 -> 111.675 | O25: =L25-I25 -> 0 | P25: =N25-K25 -> -8.325 | Q25: =N25/K25 -> 0.930625 | R25: =Q32 -> 0.93699432 | S25: 0.125 | T25: 0.20833333 | V25: =(T25-S25)*24*60 -> 120 | W25: =T25 -> 0.20833333 | X25: =S26 -> 0.22847222 | AA25: =M25-J25 -> -166.5 | AB25: =M25/J25 -> 0.930625 | AC25: =AB32 -> 0.93699432
A26: 新豐8線 | B26: 三明治 | C26: 紐奧良風味烤雞鮮蔬三明治 | E26: 31.29 | F26: 4000 | G26: =E26*F26 -> 125160 | H26: 2 | I26: 16 | J26: 2400 | K26: =J26/I26 -> 150 | L26: 16 | M26: =F26/V26*60 -> 2242.9907 | N26: =M26/L26 -> 140.18692 | O26: =L26-I26 -> 0 | P26: =N26-K26 -> -9.8130841 | Q26: =N26/K26 -> 0.93457944 | S26: 0.22847222 | T26: 0.30277778 | U26: =(S26-T25)*24*60 -> 29 | V26: =(T26-S26)*24*60 -> 107 | AA26: =M26-J26 -> -157.00935 | AB26: =M26/J26 -> 0.93457944
A27: 新豐8線 | B27: 三明治 | C27: 起司芋見肉鬆三明治 | E27: 24.25 | F27: 4732 | G27: =E27*F27 -> 114751 | I27: 18 | J27: 2400 | K27: =J27/I27 -> 133.33333 | L27: 18 | M27: =F27/V27*60 -> 2253.3333 | N27: =M27/L27 -> 125.18519 | O27: =L27-I27 -> 0 | P27: =N27-K27 -> -8.1481481 | Q27: =N27/K27 -> 0.93888889 | S27: 0.30763889 | T27: 0.39513889 | U27: =(S27-T26)*24*60 -> 7 | V27: =(T27-S27)*24*60 -> 126 | AA27: =M27-J27 -> -146.66667 | AB27: =M27/J27 -> 0.93888889
A28: 新豐8線 | B28: 三明治 | C28: 藍莓優格三明治(114年) | E28: 22.35 | F28: 1920 | G28: =E28*F28 -> 42912 | I28: 16 | J28: 2400 | K28: =J28/I28 -> 150 | L28: 16 | M28: =F28/V28*60 -> 2258.8235 | N28: =M28/L28 -> 141.17647 | O28: =L28-I28 -> 0 | P28: =N28-K28 -> -8.8235294 | Q28: =N28/K28 -> 0.94117647 | S28: 0.39861111 | T28: 0.43402778 | U28: =(S28-T27)*24*60 -> 5 | V28: =(T28-S28)*24*60 -> 51 | AA28: =M28-J28 -> -141.17647 | AB28: =M28/J28 -> 0.94117647
A29: 新豐8線 | B29: 三明治 | C29: 日式芥末蛋沙拉三明治 | E29: 25.98 | F29: 3000 | G29: =E29*F29 -> 77940 | H29: 2 | I29: 17 | J29: 2400 | K29: =J29/I29 -> 141.17647 | L29: 17 | M29: =F29/V29*60 -> 2250 | N29: =M29/L29 -> 132.35294 | O29: =L29-I29 -> 0 | P29: =N29-K29 -> -8.8235294 | Q29: =N29/K29 -> 0.9375 | S29: 0.43958333 | T29: 0.49513889 | U29: =(S29-T28)*24*60 -> 8 | V29: =(T29-S29)*24*60 -> 80 | W29: =T29 -> 0.49513889 | X29: =S30 -> 0.53611111 | AA29: =M29-J29 -> -150 | AB29: =M29/J29 -> 0.9375
A30: 新豐8線 | B30: 三明治 | C30: 紐奧良風味烤雞鮮蔬三明治 | E30: 31.29 | F30: 5475 | G30: =E30*F30 -> 171312.75 | I30: 16 | J30: 2400 | K30: =J30/I30 -> 150 | L30: 16 | M30: =F30/V30*60 -> 2250 | N30: =M30/L30 -> 140.625 | O30: =L30-I30 -> 0 | P30: =N30-K30 -> -9.375 | Q30: =N30/K30 -> 0.9375 | S30: 0.53611111 | T30: 0.6375 | U30: =(S30-T29)*24*60 -> 59 | V30: =(T30-S30)*24*60 -> 146 | AA30: =M30-J30 -> -150 | AB30: =M30/J30 -> 0.9375
A31: 新豐8線 | B31: 三明治 | C31: 日式芥末蛋沙拉三明治 | E31: 25.98 | F31: 1577 | G31: =E31*F31 -> 40970.46 | I31: 17 | J31: 2400 | K31: =J31/I31 -> 141.17647 | L31: 17 | M31: =F31/V31*60 -> 2252.8571 | N31: =M31/L31 -> 132.52101 | O31: =L31-I31 -> 0 | P31: =N31-K31 -> -8.6554622 | Q31: =N31/K31 -> 0.93869048 | S31: 0.64236111 | T31: 0.67152778 | U31: =(S31-T30)*24*60 -> 7 | V31: =(T31-S31)*24*60 -> 42 | AA31: =M31-J31 -> -147.14286 | AB31: =M31/J31 -> 0.93869048
A32: 新豐8線 | B32: 平均 | I32: 17.142857 | J32: 2400 | K32: =J32/I32 -> 140 | L32: 17.142857 | M32: =AVERAGE(M25:M31) -> 2248.7864 | N32: =M32/L32 -> 131.17921 | O32: =L32-I32 -> 0 | P32: =N32-K32 -> -8.8207945 | Q32: =N32/K32 -> 0.93699432 | AA32: =M32-J32 -> -151.21362 | AB32: =M32/J32 -> 0.93699432
A33: 新豐9線 | B33: 三明治 | C33: 鮪魚起司溏心蛋三明治 | E33: 26.2 | F33: 3000 | G33: =E33*F33 -> 78600 | H33: 2 | I33: 18 | J33: 2400 | K33: =J33/I33 -> 133.33333 | L33: 18 | M33: =F33/V33*60 -> 2250 | N33: =M33/L33 -> 125 | O33: =L33-I33 -> 0 | P33: =N33-K33 -> -8.3333333 | Q33: =N33/K33 -> 0.9375 | R33: =Q43 -> 0.93690882 | S33: 0.125 | T33: 0.18055556 | V33: =(T33-S33)*24*60 -> 80 | W33: =T33 -> 0.18055556 | X33: =S34 -> 0.19930556 | AA33: =M33-J33 -> -150 | AB33: =M33/J33 -> 0.9375 | AC33: =AB43 -> 0.93690882
A34: 新豐9線 | B34: 三明治 | C34: 瘋狂起司三明治(113年) | E34: 24.45 | F34: 2445 | G34: =E34*F34 -> 59780.25 | I34: 20 | J34: 2400 | K34: =J34/I34 -> 120 | L34: 20 | M34: =F34/V34*60 -> 2256.9231 | N34: =M34/L34 -> 112.84615 | O34: =L34-I34 -> 0 | P34: =N34-K34 -> -7.1538462 | Q34: =N34/K34 -> 0.94038462 | S34: 0.19930556 | T34: 0.24444444 | U34: =(S34-T33)*24*60 -> 27 | V34: =(T34-S34)*24*60 -> 65 | AA34: =M34-J34 -> -143.07692 | AB34: =M34/J34 -> 0.94038462
A35: 新豐9線 | B35: 三明治 | C35: 醬燒烤雞三明治 | E35: 26.39 | F35: 4000 | G35: =E35*F35 -> 105560 | H35: 2 | I35: 19 | J35: 2400 | K35: =J35/I35 -> 126.31579 | L35: 19 | M35: =F35/V35*60 -> 2242.9907 | N35: =M35/L35 -> 118.05214 | O35: =L35-I35 -> 0 | P35: =N35-K35 -> -8.2636498 | Q35: =N35/K35 -> 0.93457944 | S35: 0.24930556 | T35: 0.32361111 | U35: =(S35-T34)*24*60 -> 7 | V35: =(T35-S35)*24*60 -> 107 | AA35: =M35-J35 -> -157.00935 | AB35: =M35/J35 -> 0.93457944
A36: 新豐9線 | B36: 三明治 | C36: 輕乳酪巧克力三明治 | E36: 20.52 | F36: 3752 | G36: =E36*F36 -> 76991.04 | I36: 18 | J36: 2400 | K36: =J36/I36 -> 133.33333 | L36: 18 | M36: =F36/V36*60 -> 2251.2 | N36: =M36/L36 -> 125.06667 | O36: =L36-I36 -> 0 | P36: =N36-K36 -> -8.2666667 | Q36: =N36/K36 -> 0.938 | S36: 0.32777778 | T36: 0.39722222 | U36: =(S36-T35)*24*60 -> 6 | V36: =(T36-S36)*24*60 -> 100 | AA36: =M36-J36 -> -148.8 | AB36: =M36/J36 -> 0.938
A37: 新豐9線 | B37: 三明治 | C37: 好多菜三明治 | E37: 26.2 | F37: 3000 | G37: =E37*F37 -> 78600 | H37: 2 | I37: 19 | J37: 2400 | K37: =J37/I37 -> 126.31579 | L37: 19 | M37: =F37/V37*60 -> 2250 | N37: =M37/L37 -> 118.42105 | O37: =L37-I37 -> 0 | P37: =N37-K37 -> -7.8947368 | Q37: =N37/K37 -> 0.9375 | S37: 0.40208333 | T37: 0.45763889 | U37: =(S37-T36)*24*60 -> 7 | V37: =(T37-S37)*24*60 -> 80 | AA37: =M37-J37 -> -150 | AB37: =M37/J37 -> 0.9375
A38: 新豐9線 | B38: 三明治 | C38: 龍蝦風味總匯三明治 | E38: 25.98 | F38: 2700 | G38: =E38*F38 -> 70146 | H38: 2 | I38: 17 | J38: 2400 | K38: =J38/I38 -> 141.17647 | L38: 17 | M38: =F38/V38*60 -> 2250 | N38: =M38/L38 -> 132.35294 | O38: =L38-I38 -> 0 | P38: =N38-K38 -> -8.8235294 | Q38: =N38/K38 -> 0.9375 | S38: 0.46180556 | T38: 0.51180556 | U38: =(S38-T37)*24*60 -> 6 | V38: =(T38-S38)*24*60 -> 72 | W38: =T38 -> 0.51180556 | X38: =S39 -> 0.55277778 | AA38: =M38-J38 -> -150 | AB38: =M38/J38 -> 0.9375
A39: 新豐9線 | B39: 三明治 | C39: 鮪魚起司溏心蛋三明治 | E39: 26.2 | F39: 4153 | G39: =E39*F39 -> 108808.6 | I39: 18 | J39: 2400 | K39: =J39/I39 -> 133.33333 | L39: 18 | M39: =F39/V39*60 -> 2244.8649 | N39: =M39/L39 -> 124.71471 | O39: =L39-I39 -> 0 | P39: =N39-K39 -> -8.6186186 | Q39: =N39/K39 -> 0.93536036 | S39: 0.55277778 | T39: 0.62986111 | U39: =(S39-T38)*24*60 -> 59 | V39: =(T39-S39)*24*60 -> 111 | AA39: =M39-J39 -> -155.13514 | AB39: =M39/J39 -> 0.93536036
A40: 新豐9線 | B40: 三明治 | C40: 醬燒烤雞三明治 | E40: 26.39 | F40: 2437 | G40: =E40*F40 -> 64312.43 | I40: 19 | J40: 2400 | K40: =J40/I40 -> 126.31579 | L40: 19 | M40: =F40/V40*60 -> 2249.5385 | N40: =M40/L40 -> 118.39676 | O40: =L40-I40 -> 0 | P40: =N40-K40 -> -7.9190283 | Q40: =N40/K40 -> 0.93730769 | S40: 0.63333333 | T40: 0.67847222 | U40: =(S40-T39)*24*60 -> 5 | V40: =(T40-S40)*24*60 -> 65 | AA40: =M40-J40 -> -150.46154 | AB40: =M40/J40 -> 0.93730769
...

Sheet 0830
B1: 屏榮 新豐廠組合室生產人時性分析
B3: 日期 | C3: =TEXT('0830 4度C'!A2,"yyyy.mm.ddaaaa") -> 2025.08.30星期六 | E3: 訂單量 | F3: ='0830 4度C'!D1 -> 136235 | H3: 營業額 | I3: ='0830 4度C'!F1 -> 4840642
B4: 人時性 | C4: 項目 | E4: ➀ | G4: ➁ | I4: ➂
C5: 組合室 | E5: 全溫層 | G5: 4度C-各編組展開 | I5: ③三明治-各編組展開
C6: 排關平均 | E6: =AVERAGE(D13:M13) -> 144.99616 | F6: =AVERAGE(D27:O27,D13:J13) -> 148.96656 | G6: =AVERAGE(D13:J13) -> 148.96656 | I6: =AVERAGE(K13:M13) -> 135.73188
C7: 實績平均 | E7: =AVERAGE(D14:M14) -> 135.99291 | F7: =AVERAGE(D28:O28,D14:J14) -> 139.6229 | G7: =AVERAGE(D14:J14) -> 139.6229 | I7: =AVERAGE(K14:M14) -> 127.52295
C8: 達成率平均 | E8: =AVERAGE(D15:M15) -> 0.93748136 | F8: =AVERAGE(D15:J15,D29:O29) -> 0.93663944 | G8: =AVERAGE(D15:J15) -> 0.93663944 | I8: =AVERAGE(K15:M15) -> 0.93944584 | K8: ※現行日本鮮食廠以達成率80%為基本(即為現行KPI)
B10: 溫層 | D10: ➁4度C-各編組展開 | K10: ③三明治-各編組展開
B11: 編組 | D11: 1 | E11: 2 | F11: 3 | G11: 4 | H11: 5 | I11: 6 | J11: 7 | K11: 1 | L11: 2 | M11: 3
D12: 新豐6線 | E12: 新豐2線 | F12: 新豐5線 | G12: 新豐7線 | H12: 新豐3線 | I12: 新豐1線 | J12: 新豐10線 | K12: 新豐8線 | L12: 新豐9線 | M12: 新豐4線
B13: 人時性 | C13: 排關 | D13: =SUMIFS('0830 4度C'!$K:$K,'0830 4度C'!$A:$A,"新豐6線",'0830 4度C'!$B:$B,"平均") -> 117.64706 | E13: =SUMIFS('0830 4度C'!$K:$K,'0830 4度C'!$A:$A,"新豐2線",'0830 4度C'!$B:$B,"平均") -> 81.818182 | F13: =SUMIFS('0830 4度C'!$K:$K,'0830 4度C'!$A:$A,"新豐5線",'0830 4度C'!$B:$B,"平均") -> 93.220339 | G13: =SUMIFS('0830 4度C'!$K:$K,'0830 4度C'!$A:$A,"新豐7線",'0830 4度C'!$B:$B,"平均") -> 116.50485 | H13: =SUMIFS('0830 4度C'!$K:$K,'0830 4度C'!$A:$A,"新豐3線",'0830 4度C'!$B:$B,"平均") -> 300 | I13: =SUMIFS('0830 4度C'!$K:$K,'0830 4度C'!$A:$A,"新豐1線",'0830 4度C'!$B:$B,"平均") -> 114.45783 | J13: =SUMIFS('0830 4度C'!$K:$K,'0830 4度C'!$A:$A,"新豐10線",'0830 4度C'!$B:$B,"平均") -> 219.11765 | K13: =SUMIFS('0830 4度C'!$K:$K,'0830 4度C'!$A:$A,"新豐8線",'0830 4度C'!$B:$B,"平均") -> 137.93103 | L13: =SUMIFS('0830 4度C'!$K:$K,'0830 4度C'!$A:$A,"新豐9線",'0830 4度C'!$B:$B,"平均") -> 129.72973 | M13: =SUMIFS('0830 4度C'!$K:$K,'0830 4度C'!$A:$A,"新豐4線",'0830 4度C'!$B:$B,"平均") -> 139.53488
C14: 實績 | D14: =SUMIFS('0830 4度C'!$N:$N,'0830 4度C'!$A:$A,"新豐6線",'0830 4度C'!$B:$B,"平均") -> 110.08992 | E14: =SUMIFS('0830 4度C'!$N:$N,'0830 4度C'!$A:$A,"新豐2線",'0830 4度C'!$B:$B,"平均") -> 76.307568 | F14: =SUMIFS('0830 4度C'!$N:$N,'0830 4度C'!$A:$A,"新豐5線",'0830 4度C'!$B:$B,"平均") -> 87.130976 | G14: =SUMIFS('0830 4度C'!$N:$N,'0830 4度C'!$A:$A,"新豐7線",'0830 4度C'!$B:$B,"平均") -> 109.31894 | H14: =SUMIFS('0830 4度C'!$N:$N,'0830 4度C'!$A:$A,"新豐3線",'0830 4度C'!$B:$B,"平均") -> 280.76455 | I14: =SUMIFS('0830 4度C'!$N:$N,'0830 4度C'!$A:$A,"新豐1線",'0830 4度C'!$B:$B,"平均") -> 107.18971 | J14: =SUMIFS('0830 4度C'!$N:$N,'0830 4度C'!$A:$A,"新豐10線",'0830 4度C'!$B:$B,"平均") -> 206.55863 | K14: =SUMIFS('0830 4度C'!$N:$N,'0830 4度C'!$A:$A,"新豐8線",'0830 4度C'!$B:$B,"平均") -> 129.49821 | L14: =SUMIFS('0830 4度C'!$N:$N,'0830 4度C'!$A:$A,"新豐9線",'0830 4度C'!$B:$B,"平均") -> 121.48186 | M14: =SUMIFS('0830 4度C'!$N:$N,'0830 4度C'!$A:$A,"新豐4線",'0830 4度C'!$B:$B,"平均") -> 131.58877
C15: 達成率 | D15: =D14/D13 -> 0.93576433 | E15: =E14/E13 -> 0.93264806 | F15: =F14/F13 -> 0.93467774 | G15: =G14/G13 -> 0.93832089 | H15: =H14/H13 -> 0.93588183 | I15: =I14/I13 -> 0.93649958 | J15: =J14/J13 -> 0.94268367 | K15: =K14/K13 -> 0.93886203 | ... M15: =M14/M13 -> 0.94305282
B16: 作業 時間 | C16: 開始 | D16: =VLOOKUP("新豐6線",'0830 4度C'!$A:$T,19,0) -> 0.70833333 | E16: =VLOOKUP("新豐2線",'0830 4度C'!$A:$T,19,0) -> 0.125 | F16: =VLOOKUP("新豐5線",'0830 4度C'!$A:$T,19,0) -> 0.25 | G16: =VLOOKUP("新豐7線",'0830 4度C'!$A:$T,19,0) -> 0.20833333 | H16: =VLOOKUP("新豐3線",'0830 4度C'!$A:$T,19,0) -> 0.125 | I16: =VLOOKUP("新豐1線",'0830 4度C'!$A:$T,19,0) -> 0.29166667 | J16: =VLOOKUP("新豐10線",'0830 4度C'!$A:$T,19,0) -> 0.125 | K16: =VLOOKUP("新豐8線",'0830 4度C'!$A:$T,19,0) -> 0.125 | L16: =VLOOKUP("新豐9線",'0830 4度C'!$A:$T,19,0) -> 0.125 | M16: =VLOOKUP("新豐4線",'0830 4度C'!$A:$T,19,0) -> 0.125
C17: 結束 | D17: =LOOKUP(2,1/(('0830 4度C'!$A:$A="新豐6線")*('0830 4度C'!$T:$T<>"")),'0830 4度C'!$T:$T) -> 0.83958333 | E17: =LOOKUP(2,1/(('0830 4度C'!$A:$A="新豐2線")*('0830 4度C'!$T:$T<>"")),'0830 4度C'!$T:$T) -> 0.52916667 | F17: =LOOKUP(2,1/(('0830 4度C'!$A:$A="新豐5線")*('0830 4度C'!$T:$T<>"")),'0830 4度C'!$T:$T) -> 0.84236111 | G17: =LOOKUP(2,1/(('0830 4度C'!$A:$A="新豐7線")*('0830 4度C'!$T:$T<>"")),'0830 4度C'!$T:$T) -> 0.80416667 | H17: =LOOKUP(2,1/(('0830 4度C'!$A:$A="新豐3線")*('0830 4度C'!$T:$T<>"")),'0830 4度C'!$T:$T) -> 0.46458333 | I17: =LOOKUP(2,1/(('0830 4度C'!$A:$A="新豐1線")*('0830 4度C'!$T:$T<>"")),'0830 4度C'!$T:$T) -> 0.84791667 | J17: =LOOKUP(2,1/(('0830 4度C'!$A:$A="新豐10線")*('0830 4度C'!$T:$T<>"")),'0830 4度C'!$T:$T) -> 0.40138889 | K17: =LOOKUP(2,1/(('0830 4度C'!$A:$A="新豐8線")*('0830 4度C'!$T:$T<>"")),'0830 4度C'!$T:$T) -> 0.48611111 | L17: =LOOKUP(2,1/(('0830 4度C'!$A:$A="新豐9線")*('0830 4度C'!$T:$T<>"")),'0830 4度C'!$T:$T) -> 0.54097222 | M17: =LOOKUP(2,1/(('0830 4度C'!$A:$A="新豐4線")*('0830 4度C'!$T:$T<>"")),'0830 4度C'!$T:$T) -> 0.475
B18: 配置人數 | D18: =SUMIFS('0830 4度C'!$I:$I,'0830 4度C'!$A:$A,"新豐6線",'0830 4度C'!$B:$B,"平均") -> 17 | E18: =SUMIFS('0830 4度C'!$I:$I,'0830 4度C'!$A:$A,"新豐2線",'0830 4度C'!$B:$B,"平均") -> 18.333333 | F18: =SUMIFS('0830 4度C'!$I:$I,'0830 4度C'!$A:$A,"新豐5線",'0830 4度C'!$B:$B,"平均") -> 19.666667 | G18: =SUMIFS('0830 4度C'!$I:$I,'0830 4度C'!$A:$A,"新豐7線",'0830 4度C'!$B:$B,"平均") -> 17.166667 | H18: =SUMIFS('0830 4度C'!$I:$I,'0830 4度C'!$A:$A,"新豐3線",'0830 4度C'!$B:$B,"平均") -> 10 | I18: =SUMIFS('0830 4度C'!$I:$I,'0830 4度C'!$A:$A,"新豐1線",'0830 4度C'!$B:$B,"平均") -> 16.6 | J18: =SUMIFS('0830 4度C'!$I:$I,'0830 4度C'!$A:$A,"新豐10線",'0830 4度C'!$B:$B,"平均") -> 11.333333 | K18: =SUMIFS('0830 4度C'!$I:$I,'0830 4度C'!$A:$A,"新豐8線",'0830 4度C'!$B:$B,"平均") -> 17.4 | L18: =SUMIFS('0830 4度C'!$I:$I,'0830 4度C'!$A:$A,"新豐9線",'0830 4度C'!$B:$B,"平均") -> 18.5 | M18: =SUMIFS('0830 4度C'!$I:$I,'0830 4度C'!$A:$A,"新豐4線",'0830 4度C'!$B:$B,"平均") -> 17.2
B19: 主要應用設備 | D19: ET-55 | E19: 熱縮爐 | F19: L型包裝機 | G19: L型包裝機 | H19: 伺服包裝機 | I19: ET-55 | J19: 伺服包裝機 | K19: 三明治包裝機 | L19: 三明治包裝機 | M19: 三明治包裝機
B20: 次要應用設備 | F20: 圓盤機 | G20: ET-55
B21: 備註 | E21: 握沙拉 | F21: 共用L型包裝機 | H21: 調理麵包 | I21: 炒飯+沙拉 | J21: 調理麵包

Sheet 0830 4度C
A1: 新豐廠四度C日報分析 | C1: 總生產量 | D1: =SUM(F5:F63) -> 136235 | E1: 營業額 | F1: =SUM(G5:G63) -> 4840642 | G1: 出勤人數 | H1: =L8+L12+L44+L50+L16+L57+L29+L36+L23+L63 -> 163.2 | I1: 產線配置圖 | L1: 生產實績 | O1: 人時性差異分析 | S1: 日報登錄 | Y1: 分析說明 | AA1: 產能差異分析
A2: 45899 | B2: 星期六 | C2: 人時性 | D2: =AVERAGE(N8,N12,N44,N50,N16,N57,N23,N29,N36,N63) -> 135.99291 | E2: 平均廠價 | F2: =F1/D1 -> 35.53156 | G2: 多次生產數 | H2: =COUNT(H5:H63) -> 0
A3: 線別 | B3: 品類 | C3: 品名 | E3: 廠價 | F3: 生產量 | G3: 營收 | H3: 多次 生產 | I3: 人數 | J3: 產能/時 | K3: 人時性 | L3: 人數 | M3: 產能/時 | N3: 人時性 | O3: 人數 | P3: 人時性 | Q3: 達成率 | R3: 達成率平均 | S3: 生產時間 | U3: 換線、休息/分 | V3: 稼動時間/分 | W3: 休息時間 | Y3: (新豐回填) | AA3: 產能/時 | AB3: 達成率 | AC3: 達成率平均
S4: 開始 | T4: 結束 | W4: 開始 | X4: 結束
A5: 新豐6線 | B5: 微波主食 | C5: 二配煸椒烘蛋飯 | E5: 46.93 | F5: 1087 | G5: =E5*F5 -> 51012.91 | I5: 17 | J5: 2000 | K5: =J5/I5 -> 117.64706 | L5: 17 | M5: =F5/V5*60 -> 1863.4286 | N5: =M5/L5 -> 109.61345 | O5: =L5-I5 -> 0 | P5: =N5-K5 -> -8.0336134 | Q5: =N5/K5 -> 0.93171429 | R5: =Q8 -> 0.93576433 | S5: 0.70833333 | T5: 0.73263889 | V5: =(T5-S5)*24*60 -> 35 | AA5: =M5-J5 -> -136.57143 | AB5: =M5/J5 -> 0.93171429 | AC5: =AB8 -> 0.93576433
A6: 新豐6線 | B6: 微波主食 | C6: 二配川味麻婆燒豆腐燴飯 | E6: 50.49 | F6: 2169 | G6: =E6*F6 -> 109512.81 | I6: 16 | J6: 2000 | K6: =J6/I6 -> 125 | L6: 16 | M6: =F6/V6*60 -> 1886.087 | N6: =M6/L6 -> 117.88043 | O6: =L6-I6 -> 0 | P6: =N6-K6 -> -7.1195652 | Q6: =N6/K6 -> 0.94304348 | S6: 0.7375 | T6: 0.78541667 | U6: =(S6-T5)*24*60 -> 7 | V6: =(T6-S6)*24*60 -> 69 | AA6: =M6-J6 -> -113.91304 | AB6: =M6/J6 -> 0.94304348
A7: 新豐6線 | B7: 微波主食 | C7: 二配港式香滑嫩蛋牛肉燴飯 | E7: 50.67 | F7: 2207 | G7: =E7*F7 -> 111828.69 | I7: 18 | J7: 2000 | K7: =J7/I7 -> 111.11111 | L7: 18 | M7: =F7/V7*60 -> 1865.0704 | N7: =M7/L7 -> 103.61502 | O7: =L7-I7 -> 0 | P7: =N7-K7 -> -7.4960876 | Q7: =N7/K7 -> 0.93253521 | S7: 0.79027778 | T7: 0.83958333 | U7: =(S7-T6)*24*60 -> 7 | V7: =(T7-S7)*24*60 -> 71 | AA7: =M7-J7 -> -134.92958 | AB7: =M7/J7 -> 0.93253521
A8: 新豐6線 | B8: 平均 | I8: 17 | J8: 2000 | K8: =J8/I8 -> 117.64706 | L8: 17 | M8: =AVERAGE(M5:M7) -> 1871.5287 | N8: =M8/L8 -> 110.08992 | O8: =L8-I8 -> 0 | P8: =N8-K8 -> -7.5571382 | Q8: =N8/K8 -> 0.93576433 | AA8: =M8-J8 -> -128.47135 | AB8: =M8/J8 -> 0.93576433
A9: 新豐2線 | B9: 沙拉 | C9: 青醬優格雞肉握沙拉(113年) | E9: 39.62 | F9: 4031 | G9: =E9*F9 -> 159708.22 | I9: 19 | J9: 1500 | K9: =J9/I9 -> 78.947368 | L9: 19 | M9: =F9/V9*60 -> 1398.0347 | N9: =M9/L9 -> 73.580773 | O9: =L9-I9 -> 0 | P9: =N9-K9 -> -5.3665957 | Q9: =N9/K9 -> 0.93202312 | R9: =Q12 -> 0.93264806 | S9: 0.125 | T9: 0.24513889 | V9: =(T9-S9)*24*60 -> 173 | W9: =T9 -> 0.24513889 | X9: =S10 -> 0.26597222 | AA9: =M9-J9 -> -101.96532 | AB9: =M9/J9 -> 0.93202312 | AC9: =AB12 -> 0.93264806
A10: 新豐2線 | B10: 沙拉 | C10: 青檸烤雞握沙拉(113年) | E10: 39.8 | F10: 5330 | G10: =E10*F10 -> 212134 | I10: 17 | J10: 1500 | K10: =J10/I10 -> 88.235294 | L10: 17 | M10: =F10/V10*60 -> 1402.6316 | N10: =M10/L10 -> 82.50774 | O10: =L10-I10 -> 0 | P10: =N10-K10 -> -5.7275542 | Q10: =N10/K10 -> 0.93508772 | S10: 0.26597222 | T10: 0.42430556 | U10: =(S10-T9)*24*60 -> 30 | V10: =(T10-S10)*24*60 -> 228 | AA10: =M10-J10 -> -97.368421 | AB10: =M10/J10 -> 0.93508772
A11: 新豐2線 | B11: 沙拉 | C11: 地瓜瓜握沙拉 | E11: 39.29 | F11: 3351 | G11: =E11*F11 -> 131660.79 | I11: 19 | J11: 1500 | K11: =J11/I11 -> 78.947368 | L11: 19 | M11: =F11/V11*60 -> 1396.25 | N11: =M11/L11 -> 73.486842 | O11: =L11-I11 -> 0 | P11: =N11-K11 -> -5.4605263 | Q11: =N11/K11 -> 0.93083333 | S11: 0.42916667 | T11: 0.52916667 | U11: =(S11-T10)*24*60 -> 7 | V11: =(T11-S11)*24*60 -> 144 | AA11: =M11-J11 -> -103.75 | AB11: =M11/J11 -> 0.93083333
A12: 新豐2線 | B12: 平均 | I12: 18.333333 | J12: 1500 | K12: =J12/I12 -> 81.818182 | L12: 18.333333 | M12: =AVERAGE(M9:M11) -> 1398.9721 | N12: =M12/L12 -> 76.307568 | O12: =L12-I12 -> 0 | P12: =N12-K12 -> -5.5106134 | Q12: =N12/K12 -> 0.93264806 | AA12: =M12-J12 -> -101.02791 | AB12: =M12/J12 -> 0.93264806
A13: 新豐5線 | B13: 小吃 | C13: 剝皮辣椒雞湯 | E13: 41 | F13: 1821 | G13: =E13*F13 -> 74661 | I13: 26 | J13: 1500 | K13: =J13/I13 -> 57.692308 | L13: 26 | M13: =F13/V13*60 -> 1400.7692 | N13: =M13/L13 -> 53.87574 | O13: =L13-I13 -> 0 | P13: =N13-K13 -> -3.816568 | Q13: =N13/K13 -> 0.93384615 | R13: =Q16 -> 0.93467774 | S13: 0.25 | T13: 0.30416667 | V13: =(T13-S13)*24*60 -> 78 | AA13: =M13-J13 -> -99.230769 | AB13: =M13/J13 -> 0.93384615 | AC13: =AB16 -> 0.93467774
A14: 新豐5線 | B14: 微波主食 | C14: 二配金咖哩濃厚辛辣咖哩飯 | E14: 50.98 | F14: 2804 | G14: =E14*F14 -> 142947.92 | I14: 17 | J14: 2000 | K14: =J14/I14 -> 117.64706 | L14: 17 | M14: =F14/V14*60 -> 1869.3333 | N14: =M14/L14 -> 109.96078 | O14: =L14-I14 -> 0 | P14: =N14-K14 -> -7.6862745 | Q14: =N14/K14 -> 0.93466667 | S14: 0.70833333 | T14: 0.77083333 | U14: =IF(S14=TIME(17,0,0),"",(S14-T13)*24*60) | V14: =(T14-S14)*24*60 -> 90 | AA14: =M14-J14 -> -130.66667 | AB14: =M14/J14 -> 0.93466667
A15: 新豐5線 | B15: 微波主食 | C15: 二配金咖哩果香甘口咖哩飯 | E15: 50.92 | F15: 2993 | G15: =E15*F15 -> 152403.56 | I15: 16 | J15: 2000 | K15: =J15/I15 -> 125 | L15: 16 | M15: =F15/V15*60 -> 1870.625 | N15: =M15/L15 -> 116.91406 | O15: =L15-I15 -> 0 | P15: =N15-K15 -> -8.0859375 | Q15: =N15/K15 -> 0.9353125 | S15: 0.77569444 | T15: 0.84236111 | U15: =IF(S15=TIME(17,0,0),"",(S15-T14)*24*60) -> 7 | V15: =(T15-S15)*24*60 -> 96 | AA15: =M15-J15 -> -129.375 | AB15: =M15/J15 -> 0.9353125
A16: 新豐5線 | B16: 平均 | I16: 19.666667 | J16: 1833.3333 | K16: =J16/I16 -> 93.220339 | L16: 19.666667 | M16: =AVERAGE(M13:M15) -> 1713.5759 | N16: =M16/L16 -> 87.130976 | O16: =L16-I16 -> 0 | P16: =N16-K16 -> -6.0893633 | Q16: =N16/K16 -> 0.93467774 | AA16: =M16-J16 -> -119.75748 | AB16: =M16/J16 -> 0.93467774
A17: 新豐7線 | B17: 小吃 | C17: 古早味炒炊粉 | E17: 43.14 | F17: 1276 | G17: =E17*F17 -> 55046.64 | I17: 17 | J17: 2000 | K17: =J17/I17 -> 117.64706 | L17: 17 | M17: =F17/V17*60 -> 1867.3171 | N17: =M17/L17 -> 109.84218 | O17: =L17-I17 -> 0 | P17: =N17-K17 -> -7.804878 | Q17: =N17/K17 -> 0.93365854 | R17: =Q23 -> 0.93832089 | S17: 0.20833333 | T17: 0.23680556 | V17: =(T17-S17)*24*60 -> 41 | AA17: =M17-J17 -> -132.68293 | AB17: =M17/J17 -> 0.93365854 | AC17: =AB23 -> 0.93832089
A18: 新豐7線 | B18: 微波主食 | C18: 鐵板滑蛋炸豬排丼 | E18: 57.73 | F18: 2100 | G18: =E18*F18 -> 121233 | I18: 16 | J18: 2000 | K18: =J18/I18 -> 125 | L18: 16 | M18: =F18/V18*60 -> 1880.597 | N18: =M18/L18 -> 117.53731 | O18: =L18-I18 -> 0 | P18: =N18-K18 -> -7.4626866 | Q18: =N18/K18 -> 0.94029851 | S18: 0.24166667 | T18: 0.28819444 | U18: =IF(S18=TIME(17,0,0),"",(S18-T17)*24*60) -> 7 | V18: =(T18-S18)*24*60 -> 67 | AA18: =M18-J18 -> -119.40299 | AB18: =M18/J18 -> 0.94029851
A19: 新豐7線 | B19: 微波主食 | C19: 極上炙烤親子丼 | E19: 53.68 | F19: 1516 | G19: =E19*F19 -> 81378.88 | I19: 17 | J19: 2000 | K19: =J19/I19 -> 117.64706 | L19: 17 | M19: =F19/V19*60 -> 1895 | N19: =M19/L19 -> 111.47059 | O19: =L19-I19 -> 0 | P19: =N19-K19 -> -6.1764706 | Q19: =N19/K19 -> 0.9475 | S19: 0.29236111 | T19: 0.32569444 | U19: =IF(S19=TIME(17,0,0),"",(S19-T18)*24*60) -> 6 | V19: =(T19-S19)*24*60 -> 48 | AA19: =M19-J19 -> -105 | AB19: =M19/J19 -> 0.9475
A20: 新豐7線 | B20: 微波主食 | C20: 海老鰻魚丼滋丼 | E20: 58.17 | F20: 1654 | G20: =E20*F20 -> 96213.18 | I20: 18 | J20: 2000 | K20: =J20/I20 -> 111.11111 | L20: 18 | M20: =F20/V20*60 -> 1872.4528 | N20: =M20/L20 -> 104.02516 | O20: =L20-I20 -> 0 | P20: =N20-K20 -> -7.0859539 | Q20: =N20/K20 -> 0.93622642 | S20: 0.33055556 | T20: 0.36736111 | U20: =IF(S20=TIME(17,0,0),"",(S20-T19)*24*60) -> 7 | V20: =(T20-S20)*24*60 -> 53 | AA20: =M20-J20 -> -127.54717 | AB20: =M20/J20 -> 0.93622642
A21: 新豐7線 | B21: 微波主食 | C21: 二配美味蟹煲 | E21: 54.09 | F21: 3524 | G21: =E21*F21 -> 190613.16 | I21: 20 | J21: 2000 | K21: =J21/I21 -> 100 | L21: 20 | M21: =F21/V21*60 -> 1871.1504 | N21: =M21/L21 -> 93.557522 | O21: =L21-I21 -> 0 | P21: =N21-K21 -> -6.4424779 | Q21: =N21/K21 -> 0.93557522 | S21: 0.70833333 | T21: 0.78680556 | U21: =IF(S21=TIME(17,0,0),"",(S21-T20)*24*60) | V21: =(T21-S21)*24*60 -> 113 | AA21: =M21-J21 -> -128.84956 | AB21: =M21/J21 -> 0.93557522
A22: 新豐7線 | B22: 微波主食 | C22: 二配極旨黑咖哩漢堡排飯 | E22: 53.27 | F22: 562 | G22: =E22*F22 -> 29937.74 | I22: 15 | J22: 2000 | K22: =J22/I22 -> 133.33333 | L22: 15 | M22: =F22/V22*60 -> 1873.3333 | N22: =M22/L22 -> 124.88889 | O22: =L22-I22 -> 0 | P22: =N22-K22 -> -8.4444444 | Q22: =N22/K22 -> 0.93666667 | S22: 0.79166667 | T22: 0.80416667 | U22: =IF(S22=TIME(17,0,0),"",(S22-T21)*24*60) -> 7 | V22: =(T22-S22)*24*60 -> 18 | AA22: =M22-J22 -> -126.66667 | AB22: =M22/J22 -> 0.93666667
A23: 新豐7線 | B23: 平均 | I23: 17.166667 | J23: 2000 | K23: =J23/I23 -> 116.50485 | L23: 17.166667 | M23: =AVERAGE(M17:M22) -> 1876.6418 | N23: =M23/L23 -> 109.31894 | O23: =L23-I23 -> 0 | P23: =N23-K23 -> -7.1859156 | Q23: =N23/K23 -> 0.93832089 | AA23: =M23-J23 -> -123.35822 | AB23: =M23/J23 -> 0.93832089
A24: 新豐8線 | B24: 三明治 | C24: 經典總匯三明治 | E24: 26.2 | F24: 3148 | G24: =E24*F24 -> 82477.6 | I24: 20 | J24: 2400 | K24: =J24/I24 -> 120 | L24: 20 | M24: =F24/V24*60 -> 2248.5714 | N24: =M24/L24 -> 112.42857 | O24: =L24-I24 -> 0 | P24: =N24-K24 -> -7.5714286 | Q24: =N24/K24 -> 0.93690476 | R24: =Q29 -> 0.93886203 | S24: 0.125 | T24: 0.18333333 | V24: =(T24-S24)*24*60 -> 84 | W24: =T24 -> 0.18333333 | X24: =S25 -> 0.20416667 | AA24: =M24-J24 -> -151.42857 | AB24: =M24/J24 -> 0.93690476 | AC24: =AB29 -> 0.93886203
A25: 新豐8線 | B25: 三明治 | C25: 紐奧良風味烤雞鮮蔬三明治 | E25: 31.29 | F25: 6350 | G25: =E25*F25 -> 198691.5 | I25: 16 | J25: 2400 | K25: =J25/I25 -> 150 | L25: 16 | M25: =F25/V25*60 -> 2241.1765 | N25: =M25/L25 -> 140.07353 | O25: =L25-I25 -> 0 | P25: =N25-K25 -> -9.9264706 | Q25: =N25/K25 -> 0.93382353 | S25: 0.20416667 | T25: 0.32222222 | U25: =(S25-T24)*24*60 -> 30 | V25: =(T25-S25)*24*60 -> 170 | AA25: =M25-J25 -> -158.82353 | AB25: =M25/J25 -> 0.93382353
A26: 新豐8線 | B26: 三明治 | C26: 起司芋見肉鬆三明治 | E26: 24.25 | F26: 3379 | G26: =E26*F26 -> 81940.75 | I26: 18 | J26: 2400 | K26: =J26/I26 -> 133.33333 | L26: 18 | M26: =F26/V26*60 -> 2252.6667 | N26: =M26/L26 -> 125.14815 | O26: =L26-I26 -> 0 | P26: =N26-K26 -> -8.1851852 | Q26: =N26/K26 -> 0.93861111 | S26: 0.32708333 | T26: 0.38958333 | U26: =(S26-T25)*24*60 -> 7 | V26: =(T26-S26)*24*60 -> 90 | AA26: =M26-J26 -> -147.33333 | AB26: =M26/J26 -> 0.93861111
A27: 新豐8線 | B27: 三明治 | C27: 日式芥末蛋沙拉三明治 | E27: 25.98 | F27: 3373 | G27: =E27*F27 -> 87630.54 | I27: 17 | J27: 2400 | K27: =J27/I27 -> 141.17647 | L27: 17 | M27: =F27/V27*60 -> 2248.6667 | N27: =M27/L27 -> 132.27451 | O27: =L27-I27 -> 0 | P27: =N27-K27 -> -8.9019608 | Q27: =N27/K27 -> 0.93694444 | S27: 0.39375 | T27: 0.45625 | U27: =(S27-T26)*24*60 -> 6 | V27: =(T27-S27)*24*60 -> 90 | AA27: =M27-J27 -> -151.33333 | AB27: =M27/J27 -> 0.93694444
A28: 新豐8線 | B28: 三明治 | C28: 藍莓優格三明治(114年) | E28: 22.35 | F28: 1441 | G28: =E28*F28 -> 32206.35 | I28: 16 | J28: 2400 | K28: =J28/I28 -> 150 | L28: 16 | M28: =F28/V28*60 -> 2275.2632 | N28: =M28/L28 -> 142.20395 | O28: =L28-I28 -> 0 | P28: =N28-K28 -> -7.7960526 | Q28: =N28/K28 -> 0.94802632 | S28: 0.45972222 | T28: 0.48611111 | U28: =(S28-T27)*24*60 -> 5 | V28: =(T28-S28)*24*60 -> 38 | AA28: =M28-J28 -> -124.73684 | AB28: =M28/J28 -> 0.94802632
A29: 新豐8線 | B29: 平均 | I29: 17.4 | J29: 2400 | K29: =J29/I29 -> 137.93103 | L29: 17.4 | M29: =AVERAGE(M24:M28) -> 2253.2689 | N29: =M29/L29 -> 129.49821 | O29: =L29-I29 -> 0 | P29: =N29-K29 -> -8.4328231 | Q29: =N29/K29 -> 0.93886203 | AA29: =M29-J29 -> -146.73112 | AB29: =M29/J29 -> 0.93886203
A30: 新豐9線 | B30: 三明治 | C30: 鮪魚起司溏心蛋三明治 | E30: 26.2 | F30: 4724 | G30: =E30*F30 -> 123768.8 | I30: 18 | J30: 2400 | K30: =J30/I30 -> 133.33333 | L30: 18 | M30: =F30/V30*60 -> 2249.5238 | N30: =M30/L30 -> 124.97354 | O30: =L30-I30 -> 0 | P30: =N30-K30 -> -8.3597884 | Q30: =N30/K30 -> 0.93730159 | R30: =Q36 -> 0.93642267 | S30: 0.125 | T30: 0.2125 | V30: =(T30-S30)*24*60 -> 126 | W30: =T30 -> 0.2125 | X30: =S31 -> 0.23194444 | AA30: =M30-J30 -> -150.47619 | AB30: =M30/J30 -> 0.93730159 | AC30: =AB36 -> 0.93642267
A31: 新豐9線 | B31: 三明治 | C31: 瘋狂起司三明治(113年) | E31: 24.45 | F31: 1660 | G31: =E31*F31 -> 40587 | I31: 20 | J31: 2400 | K31: =J31/I31 -> 120 | L31: 20 | M31: =F31/V31*60 -> 2263.6364 | N31: =M31/L31 -> 113.18182 | O31: =L31-I31 -> 0 | P31: =N31-K31 -> -6.8181818 | Q31: =N31/K31 -> 0.94318182 | S31: 0.23194444 | T31: 0.2625 | U31: =(S31-T30)*24*60 -> 28 | V31: =(T31-S31)*24*60 -> 44 | AA31: =M31-J31 -> -136.36364 | AB31: =M31/J31 -> 0.94318182
A32: 新豐9線 | B32: 三明治 | C32: 醬燒烤雞三明治 | E32: 26.39 | F32: 4374 | G32: =E32*F32 -> 115429.86 | I32: 19 | J32: 2400 | K32: =J32/I32 -> 126.31579 | L32: 19 | M32: =F32/V32*60 -> 2243.0769 | N32: =M32/L32 -> 118.05668 | O32: =L32-I32 -> 0 | P32: =N32-K32 -> -8.2591093 | Q32: =N32/K32 -> 0.93461538 | S32: 0.26805556 | T32: 0.34930556 | U32: =(S32-T31)*24*60 -> 8 | V32: =(T32-S32)*24*60 -> 117 | AA32: =M32-J32 -> -156.92308 | AB32: =M32/J32 -> 0.93461538
A33: 新豐9線 | B33: 三明治 | C33: 輕乳酪巧克力三明治 | E33: 20.52 | F33: 2686 | G33: =E33*F33 -> 55116.72 | I33: 18 | J33: 2400 | K33: =J33/I33 -> 133.33333 | L33: 18 | M33: =F33/V33*60 -> 2238.3333 | N33: =M33/L33 -> 124.35185 | O33: =L33-I33 -> 0 | P33: =N33-K33 -> -8.9814815 | Q33: =N33/K33 -> 0.93263889 | S33: 0.35486111 | T33: 0.40486111 | U33: =(S33-T32)*24*60 -> 8 | V33: =(T33-S33)*24*60 -> 72 | AA33: =M33-J33 -> -161.66667 | AB33: =M33/J33 -> 0.93263889
A34: 新豐9線 | B34: 三明治 | C34: 好多菜三明治 | E34: 26.2 | F34: 3546 | G34: =E34*F34 -> 92905.2 | I34: 19 | J34: 2400 | K34: =J34/I34 -> 126.31579 | L34: 19 | M34: =F34/V34*60 -> 2239.5789 | N34: =M34/L34 -> 117.87258 | O34: =L34-I34 -> 0 | P34: =N34-K34 -> -8.4432133 | Q34: =N34/K34 -> 0.93315789 | S34: 0.40902778 | T34: 0.475 | U34: =(S34-T33)*24*60 -> 6 | V34: =(T34-S34)*24*60 -> 95 | AA34: =M34-J34 -> -160.42105 | AB34: =M34/J34 -> 0.93315789
A35: 新豐9線 | B35: 三明治 | C35: 龍蝦風味總匯三明治 | E35: 25.98 | F35: 3338 | G35: =E35*F35 -> 86721.24 | I35: 17 | J35: 2400 | K35: =J35/I35 -> 141.17647 | L35: 17 | M35: =F35/V35*60 -> 2250.3371 | N35: =M35/L35 -> 132.37277 | O35: =L35-I35 -> 0 | P35: =N35-K35 -> -8.8037013 | Q35: =N35/K35 -> 0.93764045 | S35: 0.47916667 | T35: 0.54097222 | U35: =(S35-T34)*24*60 -> 6 | V35: =(T35-S35)*24*60 -> 89 | AA35: =M35-J35 -> -149.66292 | AB35: =M35/J35 -> 0.93764045
A36: 新豐9線 | B36: 平均 | I36: 18.5 | J36: 2400 | K36: =J36/I36 -> 129.72973 | L36: 18.5 | M36: =AVERAGE(M30:M35) -> 2247.4144 | N36: =M36/L36 -> 121.48186 | O36: =L36-I36 -> 0 | P36: =N36-K36 -> -8.2478698 | Q36: =N36/K36 -> 0.93642267 | AA36: =M36-J36 -> -152.58559 | AB36: =M36/J36 -> 0.93642267
A37: 新豐3線 | B37: 調理麵包 | C37: 豬肉起司蛋堡 | E37: 27.17 | F37: 4722 | G37: =E37*F37 -> 128296.74 | I37: 10 | J37: 3000 | K37: =J37/I37 -> 300 | L37: 10 | M37: =F37/V37*60 -> 2805.1485 | N37: =M37/L37 -> 280.51485 | O37: =L37-I37 -> 0 | P37: =N37-K37 -> -19.485149 | Q37: =N37/K37 -> 0.9350495 | R37: =Q44 -> 0.93588183 | S37: 0.125 | T37: 0.19513889 | V37: =(T37-S37)*24*60 -> 101 | AA37: =M37-J37 -> -194.85149 | AB37: =M37/J37 -> 0.9350495 | AC37: =AB44 -> 0.93588183
A38: 新豐3線 | B38: 調理麵包 | C38: 豬肉起司堡 | E38: 21.13 | F38: 3917 | G38: =E38*F38 -> 82766.21 | I38: 10 | J38: 3000 | K38: =J38/I38 -> 300 | L38: 10 | M38: =F38/V38*60 -> 2797.8571 | N38: =M38/L38 -> 279.78571 | O38: =L38-I38 -> 0 | P38: =N38-K38 -> -20.214286 | Q38: =N38/K38 -> 0.93261905 | S38: 0.20069444 | T38: 0.25902778 | U38: =(S38-T37)*24*60 -> 8 | V38: =(T38-S38)*24*60 -> 84 | AA38: =M38-J38 -> -202.14286 | AB38: =M38/J38 -> 0.93261905
A39: 新豐3線 | B39: 調理麵包 | C39: 經典雙牛起司堡(113年) | E39: 35.12 | F39: 3698 | G39: =E39*F39 -> 129873.76 | I39: 10 | J39: 3000 | K39: =J39/I39 -> 300 | L39: 10 | M39: =F39/V39*60 -> 2808.6076 | N39: =M39/L39 -> 280.86076 | O39: =L39-I39 -> 0 | P39: =N39-K39 -> -19.139241 | Q39: =N39/K39 -> 0.93620253 | S39: 0.26388889 | T39: 0.31875 | U39: =(S39-T38)*24*60 -> 7 | V39: =(T39-S39)*24*60 -> 79 | AA39: =M39-J39 -> -191.39241 | AB39: =M39/J39 -> 0.93620253
A40: 新豐3線 | B40: 調理麵包 | C40: 美式起司巨牛堡 | E40: 40.18 | F40: 1743 | G40: =E40*F40 -> 70033.74 | I40: 10 | J40: 3000 | K40: =J40/I40 -> 300 | L40: 10 | M40: =F40/V40*60 -> 2826.4865 | N40: =M40/L40 -> 282.64865 | O40: =L40-I40 -> 0 | P40: =N40-K40 -> -17.351351 | Q40: =N40/K40 -> 0.94216216 | S40: 0.32430556 | T40: 0.35 | U40: =(S40-T39)*24*60 -> 8 | V40: =(T40-S40)*24*60 -> 37 | AA40: =M40-J40 -> -173.51351 | AB40: =M40/J40 -> 0.94216216
...

Sheet 0829
B1: 屏榮 新豐廠組合室生產人時性分析
B3: 日期 | C3: =TEXT('0829 4度C'!A2,"yyyy.mm.ddaaaa") -> 2025.08.29星期五 | E3: 訂單量 | F3: ='0829 4度C'!D1 -> 129900 | H3: 營業額 | I3: ='0829 4度C'!F1 -> 4553981.3
B4: 人時性 | C4: 項目 | E4: ➀ | G4: ➁ | I4: ➂
C5: 組合室 | E5: 全溫層 | G5: 4度C-各編組展開 | I5: ③三明治-各編組展開
C6: 排關平均 | E6: =AVERAGE(D13:M13) -> 145.14767 | F6: =AVERAGE(D27:O27,D13:J13) -> 149.18301 | G6: =AVERAGE(D13:J13) -> 149.18301 | I6: =AVERAGE(K13:M13) -> 135.73188
C7: 實績平均 | E7: =AVERAGE(D14:M14) -> 136.49527 | F7: =AVERAGE(D28:O28,D14:J14) -> 140.42511 | G7: =AVERAGE(D14:J14) -> 140.42511 | I7: =AVERAGE(K14:M14) -> 127.32566
C8: 達成率平均 | E8: =AVERAGE(D15:M15) -> 0.93977186 | F8: =AVERAGE(D15:J15,D29:O29) -> 0.94054222 | G8: =AVERAGE(D15:J15) -> 0.94054222 | I8: =AVERAGE(K15:M15) -> 0.93797437 | K8: ※現行日本鮮食廠以達成率80%為基本(即為現行KPI)
B10: 溫層 | D10: ➁4度C-各編組展開 | K10: ③三明治-各編組展開
B11: 編組 | D11: 1 | E11: 2 | F11: 3 | G11: 4 | H11: 5 | I11: 6 | J11: 7 | K11: 1 | L11: 2 | M11: 3
D12: 新豐6線 | E12: 新豐2線 | F12: 新豐5線 | G12: 新豐7線 | H12: 新豐3線 | I12: 新豐1線 | J12: 新豐10線 | K12: 新豐8線 | L12: 新豐9線 | M12: 新豐4線
B13: 人時性 | C13: 排關 | D13: =SUMIFS('0829 4度C'!$K:$K,'0829 4度C'!$A:$A,"新豐6線",'0829 4度C'!$B:$B,"平均") -> 117.64706 | E13: =SUMIFS('0829 4度C'!$K:$K,'0829 4度C'!$A:$A,"新豐2線",'0829 4度C'!$B:$B,"平均") -> 83.333333 | F13: =SUMIFS('0829 4度C'!$K:$K,'0829 4度C'!$A:$A,"新豐5線",'0829 4度C'!$B:$B,"平均") -> 93.220339 | G13: =SUMIFS('0829 4度C'!$K:$K,'0829 4度C'!$A:$A,"新豐7線",'0829 4度C'!$B:$B,"平均") -> 116.50485 | H13: =SUMIFS('0829 4度C'!$K:$K,'0829 4度C'!$A:$A,"新豐3線",'0829 4度C'!$B:$B,"平均") -> 300 | I13: =SUMIFS('0829 4度C'!$K:$K,'0829 4度C'!$A:$A,"新豐1線",'0829 4度C'!$B:$B,"平均") -> 114.45783 | J13: =SUMIFS('0829 4度C'!$K:$K,'0829 4度C'!$A:$A,"新豐10線",'0829 4度C'!$B:$B,"平均") -> 219.11765 | K13: =SUMIFS('0829 4度C'!$K:$K,'0829 4度C'!$A:$A,"新豐8線",'0829 4度C'!$B:$B,"平均") -> 137.93103 | L13: =SUMIFS('0829 4度C'!$K:$K,'0829 4度C'!$A:$A,"新豐9線",'0829 4度C'!$B:$B,"平均") -> 129.72973 | M13: =SUMIFS('0829 4度C'!$K:$K,'0829 4度C'!$A:$A,"新豐4線",'0829 4度C'!$B:$B,"平均") -> 139.53488
C14: 實績 | D14: =SUMIFS('0829 4度C'!$N:$N,'0829 4度C'!$A:$A,"新豐6線",'0829 4度C'!$B:$B,"平均") -> 110.60835 | E14: =SUMIFS('0829 4度C'!$N:$N,'0829 4度C'!$A:$A,"新豐2線",'0829 4度C'!$B:$B,"平均") -> 77.976309 | F14: =SUMIFS('0829 4度C'!$N:$N,'0829 4度C'!$A:$A,"新豐5線",'0829 4度C'!$B:$B,"平均") -> 87.304627 | G14: =SUMIFS('0829 4度C'!$N:$N,'0829 4度C'!$A:$A,"新豐7線",'0829 4度C'!$B:$B,"平均") -> 110.5008 | H14: =SUMIFS('0829 4度C'!$N:$N,'0829 4度C'!$A:$A,"新豐3線",'0829 4度C'!$B:$B,"平均") -> 282.85274 | I14: =SUMIFS('0829 4度C'!$N:$N,'0829 4度C'!$A:$A,"新豐1線",'0829 4度C'!$B:$B,"平均") -> 107.41681 | J14: =SUMIFS('0829 4度C'!$N:$N,'0829 4度C'!$A:$A,"新豐10線",'0829 4度C'!$B:$B,"平均") -> 206.31613 | K14: =SUMIFS('0829 4度C'!$N:$N,'0829 4度C'!$A:$A,"新豐8線",'0829 4度C'!$B:$B,"平均") -> 129.26383 | L14: =SUMIFS('0829 4度C'!$N:$N,'0829 4度C'!$A:$A,"新豐9線",'0829 4度C'!$B:$B,"平均") -> 121.19884 | M14: =SUMIFS('0829 4度C'!$N:$N,'0829 4度C'!$A:$A,"新豐4線",'0829 4度C'!$B:$B,"平均") -> 131.51431
C15: 達成率 | D15: =D14/D13 -> 0.94017095 | E15: =E14/E13 -> 0.9357157 | F15: =F14/F13 -> 0.93654054 | G15: =G14/G13 -> 0.94846519 | H15: =H14/H13 -> 0.94284246 | I15: =I14/I13 -> 0.93848372 | J15: =J14/J13 -> 0.94157695 | K15: =K14/K13 -> 0.93716278 | ... M15: =M14/M13 -> 0.94251924
B16: 作業 時間 | C16: 開始 | D16: =VLOOKUP("新豐6線",'0829 4度C'!$A:$T,19,0) -> 0.70833333 | E16: =VLOOKUP("新豐2線",'0829 4度C'!$A:$T,19,0) -> 0.125 | F16: =VLOOKUP("新豐5線",'0829 4度C'!$A:$T,19,0) -> 0.25 | G16: =VLOOKUP("新豐7線",'0829 4度C'!$A:$T,19,0) -> 0.20833333 | H16: =VLOOKUP("新豐3線",'0829 4度C'!$A:$T,19,0) -> 0.125 | I16: =VLOOKUP("新豐1線",'0829 4度C'!$A:$T,19,0) -> 0.29166667 | J16: =VLOOKUP("新豐10線",'0829 4度C'!$A:$T,19,0) -> 0.125 | K16: =VLOOKUP("新豐8線",'0829 4度C'!$A:$T,19,0) -> 0.125 | L16: =VLOOKUP("新豐9線",'0829 4度C'!$A:$T,19,0) -> 0.125 | M16: =VLOOKUP("新豐4線",'0829 4度C'!$A:$T,19,0) -> 0.125
C17: 結束 | D17: =LOOKUP(2,1/(('0829 4度C'!$A:$A="新豐6線")*('0829 4度C'!$T:$T<>"")),'0829 4度C'!$T:$T) -> 0.80763889 | E17: =LOOKUP(2,1/(('0829 4度C'!$A:$A="新豐2線")*('0829 4度C'!$T:$T<>"")),'0829 4度C'!$T:$T) -> 0.56111111 | F17: =LOOKUP(2,1/(('0829 4度C'!$A:$A="新豐5線")*('0829 4度C'!$T:$T<>"")),'0829 4度C'!$T:$T) -> 0.82361111 | G17: =LOOKUP(2,1/(('0829 4度C'!$A:$A="新豐7線")*('0829 4度C'!$T:$T<>"")),'0829 4度C'!$T:$T) -> 0.78819444 | H17: =LOOKUP(2,1/(('0829 4度C'!$A:$A="新豐3線")*('0829 4度C'!$T:$T<>"")),'0829 4度C'!$T:$T) -> 0.45 | I17: =LOOKUP(2,1/(('0829 4度C'!$A:$A="新豐1線")*('0829 4度C'!$T:$T<>"")),'0829 4度C'!$T:$T) -> 0.82638889 | J17: =LOOKUP(2,1/(('0829 4度C'!$A:$A="新豐10線")*('0829 4度C'!$T:$T<>"")),'0829 4度C'!$T:$T) -> 0.39930556 | K17: =LOOKUP(2,1/(('0829 4度C'!$A:$A="新豐8線")*('0829 4度C'!$T:$T<>"")),'0829 4度C'!$T:$T) -> 0.48055556 | L17: =LOOKUP(2,1/(('0829 4度C'!$A:$A="新豐9線")*('0829 4度C'!$T:$T<>"")),'0829 4度C'!$T:$T) -> 0.58194444 | M17: =LOOKUP(2,1/(('0829 4度C'!$A:$A="新豐4線")*('0829 4度C'!$T:$T<>"")),'0829 4度C'!$T:$T) -> 0.475
B18: 配置人數 | D18: =SUMIFS('0829 4度C'!$I:$I,'0829 4度C'!$A:$A,"新豐6線",'0829 4度C'!$B:$B,"平均") -> 17 | E18: =SUMIFS('0829 4度C'!$I:$I,'0829 4度C'!$A:$A,"新豐2線",'0829 4度C'!$B:$B,"平均") -> 18 | F18: =SUMIFS('0829 4度C'!$I:$I,'0829 4度C'!$A:$A,"新豐5線",'0829 4度C'!$B:$B,"平均") -> 19.666667 | G18: =SUMIFS('0829 4度C'!$I:$I,'0829 4度C'!$A:$A,"新豐7線",'0829 4度C'!$B:$B,"平均") -> 17.166667 | H18: =SUMIFS('0829 4度C'!$I:$I,'0829 4度C'!$A:$A,"新豐3線",'0829 4度C'!$B:$B,"平均") -> 10 | I18: =SUMIFS('0829 4度C'!$I:$I,'0829 4度C'!$A:$A,"新豐1線",'0829 4度C'!$B:$B,"平均") -> 16.6 | J18: =SUMIFS('0829 4度C'!$I:$I,'0829 4度C'!$A:$A,"新豐10線",'0829 4度C'!$B:$B,"平均") -> 11.333333 | K18: =SUMIFS('0829 4度C'!$I:$I,'0829 4度C'!$A:$A,"新豐8線",'0829 4度C'!$B:$B,"平均") -> 17.4 | L18: =SUMIFS('0829 4度C'!$I:$I,'0829 4度C'!$A:$A,"新豐9線",'0829 4度C'!$B:$B,"平均") -> 18.5 | M18: =SUMIFS('0829 4度C'!$I:$I,'0829 4度C'!$A:$A,"新豐4線",'0829 4度C'!$B:$B,"平均") -> 17.2
B19: 主要應用設備 | D19: ET-55 | E19: 熱縮爐 | F19: L型包裝機 | G19: L型包裝機 | H19: 伺服包裝機 | I19: ET-55 | J19: 伺服包裝機 | K19: 三明治包裝機 | L19: 三明治包裝機 | M19: 三明治包裝機
B20: 次要應用設備 | F20: 圓盤機 | G20: ET-55
B21: 備註 | E21: 握沙拉 | F21: 共用L型包裝機 | H21: 調理麵包 | I21: 炒飯+沙拉 | J21: 調理麵包

Sheet 0829 4度C
A1: 新豐廠四度C日報分析 | C1: 總生產量 | D1: =SUM(F5:F66) -> 129900 | E1: 營業額 | F1: =SUM(G5:G66) -> 4553981.3 | G1: 出勤人數 | H1: 162.86667 | I1: 產線配置圖 | L1: 生產實績 | O1: 人時性差異分析 | S1: 日報登錄 | Y1: 分析說明 | AA1: 產能差異分析
A2: 45898 | B2: 星期五 | C2: 人時性 | D2: =AVERAGE(N8,N13,N47,N53,N17,N60,N24,N30,N39,N66) -> 136.49527 | E2: 平均廠價 | F2: =F1/D1 -> 35.057592 | G2: 多次生產數 | H2: 3
A3: 線別 | B3: 品類 | C3: 品名 | E3: 廠價 | F3: 生產量 | G3: 營收 | H3: 多次 生產 | I3: 人數 | J3: 產能/時 | K3: 人時性 | L3: 人數 | M3: 產能/時 | N3: 人時性 | O3: 人數 | P3: 人時性 | Q3: 達成率 | R3: 達成率平均 | S3: 生產時間 | U3: 換線、休息/分 | V3: 稼動時間/分 | W3: 休息時間 | Y3: (新豐回填) | AA3: 產能/時 | AB3: 達成率 | AC3: 達成率平均
S4: 開始 | T4: 結束 | W4: 開始 | X4: 結束
A5: 新豐6線 | B5: 微波主食 | C5: 二配煸椒烘蛋飯 | E5: 46.93 | F5: 725 | G5: =E5*F5 -> 34024.25 | I5: 17 | J5: 2000 | K5: =J5/I5 -> 117.64706 | L5: 17 | M5: =F5/V5*60 -> 1891.3043 | N5: =M5/L5 -> 111.2532 | O5: =L5-I5 -> 0 | P5: =N5-K5 -> -6.3938619 | Q5: =N5/K5 -> 0.94565217 | R5: =Q8 -> 0.94017095 | S5: 0.70833333 | T5: 0.72430556 | V5: =(T5-S5)*24*60 -> 23 | AA5: =M5-J5 -> -108.69565 | AB5: =M5/J5 -> 0.94565217 | AC5: =AB8 -> 0.94017095
A6: 新豐6線 | B6: 微波主食 | C6: 二配川味麻婆燒豆腐燴飯 | E6: 50.49 | F6: 1774 | G6: =E6*F6 -> 89569.26 | I6: 16 | J6: 2000 | K6: =J6/I6 -> 125 | L6: 16 | M6: =F6/V6*60 -> 1867.3684 | N6: =M6/L6 -> 116.71053 | O6: =L6-I6 -> 0 | P6: =N6-K6 -> -8.2894737 | Q6: =N6/K6 -> 0.93368421 | S6: 0.72847222 | T6: 0.76805556 | U6: =(S6-T5)*24*60 -> 6 | V6: =(T6-S6)*24*60 -> 57 | AA6: =M6-J6 -> -132.63158 | AB6: =M6/J6 -> 0.93368421
A7: 新豐6線 | B7: 微波主食 | C7: 二配港式香滑嫩蛋牛肉燴飯 | E7: 50.67 | F7: 1600 | G7: =E7*F7 -> 81072 | I7: 18 | J7: 2000 | K7: =J7/I7 -> 111.11111 | L7: 18 | M7: =F7/V7*60 -> 1882.3529 | N7: =M7/L7 -> 104.57516 | O7: =L7-I7 -> 0 | P7: =N7-K7 -> -6.5359477 | Q7: =N7/K7 -> 0.94117647 | S7: 0.77222222 | T7: 0.80763889 | U7: =(S7-T6)*24*60 -> 6 | V7: =(T7-S7)*24*60 -> 51 | AA7: =M7-J7 -> -117.64706 | AB7: =M7/J7 -> 0.94117647
A8: 新豐6線 | B8: 平均 | I8: 17 | J8: 2000 | K8: =J8/I8 -> 117.64706 | L8: 17 | M8: =AVERAGE(M5:M7) -> 1880.3419 | N8: =M8/L8 -> 110.60835 | O8: =L8-I8 -> 0 | P8: =N8-K8 -> -7.0387116 | Q8: =N8/K8 -> 0.94017095 | AA8: =M8-J8 -> -119.6581 | AB8: =M8/J8 -> 0.94017095
A9: 新豐2線 | B9: 沙拉 | C9: 青醬優格雞肉握沙拉(113年) | E9: 39.62 | F9: 3957 | G9: =E9*F9 -> 156776.34 | I9: 19 | J9: 1500 | K9: =J9/I9 -> 78.947368 | L9: 19 | M9: =F9/V9*60 -> 1396.5882 | N9: =M9/L9 -> 73.504644 | O9: =L9-I9 -> 0 | P9: =N9-K9 -> -5.4427245 | Q9: =N9/K9 -> 0.93105882 | R9: =Q13 -> 0.9357157 | S9: 0.125 | T9: 0.24305556 | V9: =(T9-S9)*24*60 -> 170 | W9: =T9 -> 0.24305556 | X9: =S10 -> 0.26388889 | AA9: =M9-J9 -> -103.41176 | AB9: =M9/J9 -> 0.93105882 | AC9: =AB13 -> 0.9357157
A10: 新豐2線 | B10: 沙拉 | C10: 青檸烤雞握沙拉(113年) | E10: 39.8 | F10: 4000 | G10: =E10*F10 -> 159200 | H10: 2 | I10: 17 | J10: 1500 | K10: =J10/I10 -> 88.235294 | L10: 17 | M10: =F10/V10*60 -> 1395.3488 | N10: =M10/L10 -> 82.079343 | O10: =L10-I10 -> 0 | P10: =N10-K10 -> -6.1559508 | Q10: =N10/K10 -> 0.93023256 | S10: 0.26388889 | T10: 0.38333333 | U10: =(S10-T9)*24*60 -> 30 | V10: =(T10-S10)*24*60 -> 172 | AA10: =M10-J10 -> -104.65116 | AB10: =M10/J10 -> 0.93023256
A11: 新豐2線 | B11: 沙拉 | C11: 地瓜瓜握沙拉 | E11: 39.29 | F11: 3273 | G11: =E11*F11 -> 128596.17 | I11: 19 | J11: 1500 | K11: =J11/I11 -> 78.947368 | L11: 19 | M11: =F11/V11*60 -> 1402.7143 | N11: =M11/L11 -> 73.827068 | O11: =L11-I11 -> 0 | P11: =N11-K11 -> -5.1203008 | Q11: =N11/K11 -> 0.93514286 | S11: 0.38680556 | T11: 0.48402778 | U11: =(S11-T10)*24*60 -> 5 | V11: =(T11-S11)*24*60 -> 140 | W11: =T11 -> 0.48402778 | X11: =S12 -> 0.52222222 | AA11: =M11-J11 -> -97.285714 | AB11: =M11/J11 -> 0.93514286
A12: 新豐2線 | B12: 沙拉 | C12: 青檸烤雞握沙拉(113年) | E12: 39.8 | F12: 1325 | G12: =E12*F12 -> 52735 | I12: 17 | J12: 1500 | K12: =J12/I12 -> 88.235294 | L12: 17 | M12: =F12/V12*60 -> 1419.6429 | N12: =M12/L12 -> 83.508403 | O12: =L12-I12 -> 0 | P12: =N12-K12 -> -4.7268908 | Q12: =N12/K12 -> 0.94642857 | S12: 0.52222222 | T12: 0.56111111 | U12: =(S12-T11)*24*60 -> 55 | V12: =(T12-S12)*24*60 -> 56 | AA12: =M12-J12 -> -80.357143 | AB12: =M12/J12 -> 0.94642857
A13: 新豐2線 | B13: 平均 | I13: 18 | J13: 1500 | K13: =J13/I13 -> 83.333333 | L13: 18 | M13: =AVERAGE(M9:M12) -> 1403.5736 | N13: =M13/L13 -> 77.976309 | O13: =L13-I13 -> 0 | P13: =N13-K13 -> -5.3570248 | Q13: =N13/K13 -> 0.9357157 | AA13: =M13-J13 -> -96.426446 | AB13: =M13/J13 -> 0.9357157
A14: 新豐5線 | B14: 小吃 | C14: 剝皮辣椒雞湯 | E14: 41 | F14: 1641 | G14: =E14*F14 -> 67281 | I14: 26 | J14: 1500 | K14: =J14/I14 -> 57.692308 | L14: 26 | M14: =F14/V14*60 -> 1406.5714 | N14: =M14/L14 -> 54.098901 | O14: =L14-I14 -> 0 | P14: =N14-K14 -> -3.5934066 | Q14: =N14/K14 -> 0.93771429 | R14: =Q17 -> 0.93654054 | S14: 0.25 | T14: 0.29861111 | V14: =(T14-S14)*24*60 -> 70 | AA14: =M14-J14 -> -93.428571 | AB14: =M14/J14 -> 0.93771429 | AC14: =AB17 -> 0.93654054
A15: 新豐5線 | B15: 微波主食 | C15: 二配金咖哩濃厚辛辣咖哩飯 | E15: 50.98 | F15: 2310 | G15: =E15*F15 -> 117763.8 | I15: 17 | J15: 2000 | K15: =J15/I15 -> 117.64706 | L15: 17 | M15: =F15/V15*60 -> 1872.973 | N15: =M15/L15 -> 110.17488 | O15: =L15-I15 -> 0 | P15: =N15-K15 -> -7.4721781 | Q15: =N15/K15 -> 0.93648649 | S15: 0.70833333 | T15: 0.75972222 | U15: =IF(S15=TIME(17,0,0),"",(S15-T14)*24*60) | V15: =(T15-S15)*24*60 -> 74 | AA15: =M15-J15 -> -127.02703 | AB15: =M15/J15 -> 0.93648649
A16: 新豐5線 | B16: 微波主食 | C16: 二配金咖哩果香甘口咖哩飯 | E16: 50.92 | F16: 2620 | G16: =E16*F16 -> 133410.4 | I16: 16 | J16: 2000 | K16: =J16/I16 -> 125 | L16: 16 | M16: =F16/V16*60 -> 1871.4286 | N16: =M16/L16 -> 116.96429 | O16: =L16-I16 -> 0 | P16: =N16-K16 -> -8.0357143 | Q16: =N16/K16 -> 0.93571429 | S16: 0.76527778 | T16: 0.82361111 | U16: =IF(S16=TIME(17,0,0),"",(S16-T15)*24*60) -> 8 | V16: =(T16-S16)*24*60 -> 84 | AA16: =M16-J16 -> -128.57143 | AB16: =M16/J16 -> 0.93571429
A17: 新豐5線 | B17: 平均 | I17: 19.666667 | J17: 1833.3333 | K17: =J17/I17 -> 93.220339 | L17: 19.666667 | M17: =AVERAGE(M14:M16) -> 1716.991 | N17: =M17/L17 -> 87.304627 | O17: =L17-I17 -> 0 | P17: =N17-K17 -> -5.9157123 | Q17: =N17/K17 -> 0.93654054 | AA17: =M17-J17 -> -116.34234 | AB17: =M17/J17 -> 0.93654054
A18: 新豐7線 | B18: 小吃 | C18: 古早味炒炊粉 | E18: 43.14 | F18: 1154 | G18: =E18*F18 -> 49783.56 | I18: 17 | J18: 2000 | K18: =J18/I18 -> 117.64706 | L18: 17 | M18: =F18/V18*60 -> 1871.3514 | N18: =M18/L18 -> 110.07949 | O18: =L18-I18 -> 0 | P18: =N18-K18 -> -7.5675676 | Q18: =N18/K18 -> 0.93567568 | R18: =Q24 -> 0.94846519 | S18: 0.20833333 | T18: 0.23402778 | V18: =(T18-S18)*24*60 -> 37 | AA18: =M18-J18 -> -128.64865 | AB18: =M18/J18 -> 0.93567568 | AC18: =AB24 -> 0.94846519
A19: 新豐7線 | B19: 微波主食 | C19: 鐵板滑蛋炸豬排丼 | E19: 57.73 | F19: 2033 | G19: =E19*F19 -> 117365.09 | I19: 16 | J19: 2000 | K19: =J19/I19 -> 125 | L19: 16 | M19: =F19/V19*60 -> 1876.6154 | N19: =M19/L19 -> 117.28846 | O19: =L19-I19 -> 0 | P19: =N19-K19 -> -7.7115385 | Q19: =N19/K19 -> 0.93830769 | S19: 0.23888889 | T19: 0.28402778 | U19: =IF(S19=TIME(17,0,0),"",(S19-T18)*24*60) -> 7 | V19: =(T19-S19)*24*60 -> 65 | AA19: =M19-J19 -> -123.38462 | AB19: =M19/J19 -> 0.93830769
A20: 新豐7線 | B20: 微波主食 | C20: 極上炙烤親子丼 | E20: 53.68 | F20: 1437 | G20: =E20*F20 -> 77138.16 | I20: 17 | J20: 2000 | K20: =J20/I20 -> 117.64706 | L20: 17 | M20: =F20/V20*60 -> 1874.3478 | N20: =M20/L20 -> 110.25575 | O20: =L20-I20 -> 0 | P20: =N20-K20 -> -7.3913043 | Q20: =N20/K20 -> 0.93717391 | S20: 0.2875 | T20: 0.31944444 | U20: =IF(S20=TIME(17,0,0),"",(S20-T19)*24*60) -> 5 | V20: =(T20-S20)*24*60 -> 46 | AA20: =M20-J20 -> -125.65217 | AB20: =M20/J20 -> 0.93717391
A21: 新豐7線 | B21: 微波主食 | C21: 海老鰻魚丼滋丼 | E21: 58.17 | F21: 1444 | G21: =E21*F21 -> 83997.48 | I21: 18 | J21: 2000 | K21: =J21/I21 -> 111.11111 | L21: 18 | M21: =F21/V21*60 -> 1883.4783 | N21: =M21/L21 -> 104.63768 | O21: =L21-I21 -> 0 | P21: =N21-K21 -> -6.47343 | Q21: =N21/K21 -> 0.94173913 | S21: 0.32361111 | T21: 0.35555556 | U21: =IF(S21=TIME(17,0,0),"",(S21-T20)*24*60) -> 6 | V21: =(T21-S21)*24*60 -> 46 | AA21: =M21-J21 -> -116.52174 | AB21: =M21/J21 -> 0.94173913
A22: 新豐7線 | B22: 微波主食 | C22: 二配美味蟹煲 | E22: 54.09 | F22: 2970 | G22: =E22*F22 -> 160647.3 | I22: 20 | J22: 2000 | K22: =J22/I22 -> 100 | L22: 20 | M22: =F22/V22*60 -> 1875.7895 | N22: =M22/L22 -> 93.789474 | O22: =L22-I22 -> 0 | P22: =N22-K22 -> -6.2105263 | Q22: =N22/K22 -> 0.93789474 | S22: 0.70833333 | T22: 0.77430556 | U22: =IF(S22=TIME(17,0,0),"",(S22-T21)*24*60) | V22: =(T22-S22)*24*60 -> 95 | AA22: =M22-J22 -> -124.21053 | AB22: =M22/J22 -> 0.93789474
A23: 新豐7線 | B23: 微波主食 | C23: 二配極旨黑咖哩漢堡排飯 | E23: 53.27 | F23: 400 | G23: =E23*F23 -> 21308 | I23: 15 | J23: 2000 | K23: =J23/I23 -> 133.33333 | L23: 15 | M23: =F23/V23*60 -> 2000 | N23: =M23/L23 -> 133.33333 | O23: =L23-I23 -> 0 | P23: =N23-K23 -> 4.5474735e-13 | Q23: =N23/K23 -> 1 | S23: 0.77986111 | T23: 0.78819444 | U23: =IF(S23=TIME(17,0,0),"",(S23-T22)*24*60) -> 8 | V23: =(T23-S23)*24*60 -> 12 | AA23: =M23-J23 -> 7.0485839e-12 | AB23: =M23/J23 -> 1
A24: 新豐7線 | B24: 平均 | I24: 17.166667 | J24: 2000 | K24: =J24/I24 -> 116.50485 | L24: 17.166667 | M24: =AVERAGE(M18:M23) -> 1896.9304 | N24: =M24/L24 -> 110.5008 | O24: =L24-I24 -> 0 | P24: =N24-K24 -> -6.0040554 | Q24: =N24/K24 -> 0.94846519 | AA24: =M24-J24 -> -103.06962 | AB24: =M24/J24 -> 0.94846519
