Workbook

Sheet 0930
B1: 屏榮 新豐廠組合室生產人時性分析
B3: 日期 | C3: =TEXT('0930 4度C'!A2,"yyyy.mm.ddaaaa") -> 2025.09.30星期二 | E3: 訂單量 | F3: ='0930 4度C'!D1 -> 193383 | H3: 營業額 | I3: ='0930 4度C'!F1 -> 6240376.6
B4: 人時性 | C4: 項目 | E4: ➀ | G4: ➁ | I4: ➂
C5: 組合室 | E5: 全溫層 | G5: 4度C-各編組展開 | I5: ③三明治-各編組展開
C6: 排關平均 | E6: =AVERAGE(D13:M13) -> 150.7212 | F6: =AVERAGE(D27:O27,D13:J13) -> 156.36994 | G6: =AVERAGE(D13:J13) -> 156.36994 | I6: =AVERAGE(K13:M13) -> 137.54079
C7: 實績平均 | E7: =AVERAGE(D14:M14) -> 144.42422 | F7: =AVERAGE(D28:O28,D14:J14) -> 149.8658 | G7: =AVERAGE(D14:J14) -> 149.8658 | I7: =AVERAGE(K14:M14) -> 131.72718
C8: 達成率平均 | E8: =AVERAGE(D15:M15) -> 0.95830574 | F8: =AVERAGE(D15:J15,D29:O29) -> 0.95852973 | G8: =AVERAGE(D15:J15) -> 0.95852973 | I8: =AVERAGE(K15:M15) -> 0.9577831 | K8: ※現行日本鮮食廠以達成率80%為基本(即為現行KPI)
B10: 溫層 | D10: ➁4度C-各編組展開 | K10: ③三明治-各編組展開
B11: 編組 | D11: 1 | E11: 2 | F11: 3 | G11: 4 | H11: 5 | I11: 6 | J11: 7 | K11: 1 | L11: 2 | M11: 3
D12: 新豐6線 | E12: 新豐2線 | F12: 新豐5線 | G12: 新豐7線 | H12: 新豐3線 | I12: 新豐1線 | J12: 新豐10線 | K12: 新豐8線 | L12: 新豐9線 | M12: 新豐4線
B13: 人時性 | C13: 排關 | D13: =SUMIFS('0930 4度C'!$K:$K,'0930 4度C'!$A:$A,"新豐6線",'0930 4度C'!$B:$B,"平均") -> 125 | E13: =SUMIFS('0930 4度C'!$K:$K,'0930 4度C'!$A:$A,"新豐2線",'0930 4度C'!$B:$B,"平均") -> 83.333333 | F13: =SUMIFS('0930 4度C'!$K:$K,'0930 4度C'!$A:$A,"新豐5線",'0930 4度C'!$B:$B,"平均") -> 109.02778 | G13: =SUMIFS('0930 4度C'!$K:$K,'0930 4度C'!$A:$A,"新豐7線",'0930 4度C'!$B:$B,"平均") -> 120.48193 | H13: =SUMIFS('0930 4度C'!$K:$K,'0930 4度C'!$A:$A,"新豐3線",'0930 4度C'!$B:$B,"平均") -> 307.69231 | I13: =SUMIFS('0930 4度C'!$K:$K,'0930 4度C'!$A:$A,"新豐1線",'0930 4度C'!$B:$B,"平均") -> 117.34694 | J13: =SUMIFS('0930 4度C'!$K:$K,'0930 4度C'!$A:$A,"新豐10線",'0930 4度C'!$B:$B,"平均") -> 231.70732 | K13: =SUMIFS('0930 4度C'!$K:$K,'0930 4度C'!$A:$A,"新豐8線",'0930 4度C'!$B:$B,"平均") -> 130.04926 | L13: =SUMIFS('0930 4度C'!$K:$K,'0930 4度C'!$A:$A,"新豐9線",'0930 4度C'!$B:$B,"平均") -> 142.22222 | M13: =SUMIFS('0930 4度C'!$K:$K,'0930 4度C'!$A:$A,"新豐4線",'0930 4度C'!$B:$B,"平均") -> 140.35088
C14: 實績 | D14: =SUMIFS('0930 4度C'!$N:$N,'0930 4度C'!$A:$A,"新豐6線",'0930 4度C'!$B:$B,"平均") -> 120.39444 | E14: =SUMIFS('0930 4度C'!$N:$N,'0930 4度C'!$A:$A,"新豐2線",'0930 4度C'!$B:$B,"平均") -> 79.54728 | F14: =SUMIFS('0930 4度C'!$N:$N,'0930 4度C'!$A:$A,"新豐5線",'0930 4度C'!$B:$B,"平均") -> 104.71344 | G14: =SUMIFS('0930 4度C'!$N:$N,'0930 4度C'!$A:$A,"新豐7線",'0930 4度C'!$B:$B,"平均") -> 115.48148 | H14: =SUMIFS('0930 4度C'!$N:$N,'0930 4度C'!$A:$A,"新豐3線",'0930 4度C'!$B:$B,"平均") -> 294.49182 | I14: =SUMIFS('0930 4度C'!$N:$N,'0930 4度C'!$A:$A,"新豐1線",'0930 4度C'!$B:$B,"平均") -> 112.37001 | J14: =SUMIFS('0930 4度C'!$N:$N,'0930 4度C'!$A:$A,"新豐10線",'0930 4度C'!$B:$B,"平均") -> 222.06215 | K14: =SUMIFS('0930 4度C'!$N:$N,'0930 4度C'!$A:$A,"新豐8線",'0930 4度C'!$B:$B,"平均") -> 124.71978 | L14: =SUMIFS('0930 4度C'!$N:$N,'0930 4度C'!$A:$A,"新豐9線",'0930 4度C'!$B:$B,"平均") -> 135.5768 | M14: =SUMIFS('0930 4度C'!$N:$N,'0930 4度C'!$A:$A,"新豐4線",'0930 4度C'!$B:$B,"平均") -> 134.88497
C15: 達成率 | D15: =D14/D13 -> 0.96315556 | E15: =E14/E13 -> 0.95456736 | F15: =F14/F13 -> 0.96042901 | G15: =G14/G13 -> 0.95849632 | H15: =H14/H13 -> 0.95709842 | I15: =I14/I13 -> 0.95758794 | J15: =J14/J13 -> 0.95837348 | K15: =K14/K13 -> 0.95901949 | ... M15: =M14/M13 -> 0.96105543
B16: 作業 時間 | C16: 開始 | D16: =VLOOKUP("新豐6線",'0930 4度C'!$A:$T,19,0) -> 0.70833333 | E16: =VLOOKUP("新豐2線",'0930 4度C'!$A:$T,19,0) -> 0.20833333 | F16: =VLOOKUP("新豐5線",'0930 4度C'!$A:$T,19,0) -> 0.20833333 | G16: =VLOOKUP("新豐7線",'0930 4度C'!$A:$T,19,0) -> 0.20833333 | H16: =VLOOKUP("新豐3線",'0930 4度C'!$A:$T,19,0) -> 0.20833333 | I16: =VLOOKUP("新豐1線",'0930 4度C'!$A:$T,19,0) -> 0.29166667 | J16: =VLOOKUP("新豐10線",'0930 4度C'!$A:$T,19,0) -> 0.20833333 | K16: =VLOOKUP("新豐8線",'0930 4度C'!$A:$T,19,0) -> 0.125 | L16: =VLOOKUP("新豐9線",'0930 4度C'!$A:$T,19,0) -> 0.125 | M16: =VLOOKUP("新豐4線",'0930 4度C'!$A:$T,19,0) -> 0.125
C17: 結束 | D17: =LOOKUP(2,1/(('0930 4度C'!$A:$A="新豐6線")*('0930 4度C'!$T:$T<>"")),'0930 4度C'!$T:$T) -> 0.8375 | E17: =LOOKUP(2,1/(('0930 4度C'!$A:$A="新豐2線")*('0930 4度C'!$T:$T<>"")),'0930 4度C'!$T:$T) -> 0.62569444 | F17: =LOOKUP(2,1/(('0930 4度C'!$A:$A="新豐5線")*('0930 4度C'!$T:$T<>"")),'0930 4度C'!$T:$T) -> 0.85069444 | G17: =LOOKUP(2,1/(('0930 4度C'!$A:$A="新豐7線")*('0930 4度C'!$T:$T<>"")),'0930 4度C'!$T:$T) -> 0.775 | H17: =LOOKUP(2,1/(('0930 4度C'!$A:$A="新豐3線")*('0930 4度C'!$T:$T<>"")),'0930 4度C'!$T:$T) -> 0.64652778 | I17: =LOOKUP(2,1/(('0930 4度C'!$A:$A="新豐1線")*('0930 4度C'!$T:$T<>"")),'0930 4度C'!$T:$T) -> 0.85625 | J17: =LOOKUP(2,1/(('0930 4度C'!$A:$A="新豐10線")*('0930 4度C'!$T:$T<>"")),'0930 4度C'!$T:$T) -> 0.43125 | K17: =LOOKUP(2,1/(('0930 4度C'!$A:$A="新豐8線")*('0930 4度C'!$T:$T<>"")),'0930 4度C'!$T:$T) -> 0.77847222 | L17: =LOOKUP(2,1/(('0930 4度C'!$A:$A="新豐9線")*('0930 4度C'!$T:$T<>"")),'0930 4度C'!$T:$T) -> 0.77430556 | M17: =LOOKUP(2,1/(('0930 4度C'!$A:$A="新豐4線")*('0930 4度C'!$T:$T<>"")),'0930 4度C'!$T:$T) -> 0.68263889
B18: 配置人數 | D18: =SUMIFS('0930 4度C'!$I:$I,'0930 4度C'!$A:$A,"新豐6線",'0930 4度C'!$B:$B,"平均") -> 16 | E18: =SUMIFS('0930 4度C'!$I:$I,'0930 4度C'!$A:$A,"新豐2線",'0930 4度C'!$B:$B,"平均") -> 18 | F18: =SUMIFS('0930 4度C'!$I:$I,'0930 4度C'!$A:$A,"新豐5線",'0930 4度C'!$B:$B,"平均") -> 18 | G18: =SUMIFS('0930 4度C'!$I:$I,'0930 4度C'!$A:$A,"新豐7線",'0930 4度C'!$B:$B,"平均") -> 16.6 | H18: =SUMIFS('0930 4度C'!$I:$I,'0930 4度C'!$A:$A,"新豐3線",'0930 4度C'!$B:$B,"平均") -> 9.75 | I18: =SUMIFS('0930 4度C'!$I:$I,'0930 4度C'!$A:$A,"新豐1線",'0930 4度C'!$B:$B,"平均") -> 16.333333 | J18: =SUMIFS('0930 4度C'!$I:$I,'0930 4度C'!$A:$A,"新豐10線",'0930 4度C'!$B:$B,"平均") -> 10.25 | K18: =SUMIFS('0930 4度C'!$I:$I,'0930 4度C'!$A:$A,"新豐8線",'0930 4度C'!$B:$B,"平均") -> 18.454545 | L18: =SUMIFS('0930 4度C'!$I:$I,'0930 4度C'!$A:$A,"新豐9線",'0930 4度C'!$B:$B,"平均") -> 16.875 | M18: =SUMIFS('0930 4度C'!$I:$I,'0930 4度C'!$A:$A,"新豐4線",'0930 4度C'!$B:$B,"平均") -> 17.1
B19: 主要應用設備 | D19: ET-55 | E19: 熱縮爐 | F19: L型包裝機 | G19: L型包裝機 | H19: 伺服包裝機 | I19: ET-55 | J19: 伺服包裝機 | K19: 三明治包裝機 | L19: 三明治包裝機 | M19: 三明治包裝機
B20: 次要應用設備 | F20: 圓盤機 | G20: ET-55
B21: 備註 | E21: 握沙拉 | F21: 共用L型包裝機 | H21: 調理麵包 | I21: 炒飯+沙拉 | J21: 調理麵包

Sheet 0930 4度C
A1: 新豐廠四度C日報分析 | C1: 總生產量 | D1: =SUM(F5:F82) -> 193383 | E1: 營業額 | F1: =SUM(G5:G82) -> 6240376.6 | G1: 出勤人數 | H1: =L8+L12+L57+L64+L21+L69+L39+L48+L27+L82 -> 157.36288 | I1: 產線配置圖 | L1: 生產實績 | O1: 人時性差異分析 | S1: 日報登錄 | Y1: 分析說明 | AA1: 產能差異分析
A2: 45930 | B2: 星期二 | C2: 人時性 | D2: =AVERAGE(N8,N12,N57,N64,N21,N69,N27,N39,N48,N82) -> 144.42422 | E2: 平均廠價 | F2: =F1/D1 -> 32.26952 | G2: 多次生產數 | H2: =COUNT(H5:H82) -> 20
A3: 線別 | B3: 品類 | C3: 品名 | E3: 廠價 | F3: 生產量 | G3: 營收 | H3: 多次 生產 | I3: 人數 | J3: 產能/時 | K3: 人時性 | L3: 人數 | M3: 產能/時 | N3: 人時性 | O3: 人數 | P3: 人時性 | Q3: 達成率 | R3: 達成率平均 | S3: 生產時間 | U3: 換線、休息/分 | V3: 稼動時間/分 | W3: 休息時間 | Y3: (新豐回填) | AA3: 產能/時 | AB3: 達成率 | AC3: 達成率平均
S4: 開始 | T4: 結束 | W4: 開始 | X4: 結束
A5: 新豐6線 | B5: 微波主食 | C5: 二配煸椒烘蛋飯 | E5: 46.93 | F5: 1132 | G5: =E5*F5 -> 53124.76 | I5: 16 | J5: 2000 | K5: =J5/I5 -> 125 | L5: 16 | M5: =F5/V5*60 -> 1940.5714 | N5: =M5/L5 -> 121.28571 | O5: =L5-I5 -> 0 | P5: =N5-K5 -> -3.7142857 | Q5: =N5/K5 -> 0.97028571 | R5: =Q8 -> 0.96315556 | S5: 0.70833333 | T5: 0.73263889 | V5: =(T5-S5)*24*60 -> 35 | AA5: =M5-J5 -> -59.428571 | AB5: =M5/J5 -> 0.97028571 | AC5: =AB8 -> 0.96315556
A6: 新豐6線 | B6: 微波主食 | C6: 二配川味麻婆燒豆腐燴飯 | E6: 50.49 | F6: 2392 | G6: =E6*F6 -> 120772.08 | I6: 15 | J6: 2000 | K6: =J6/I6 -> 133.33333 | L6: 15 | M6: =F6/V6*60 -> 1913.6 | N6: =M6/L6 -> 127.57333 | O6: =L6-I6 -> 0 | P6: =N6-K6 -> -5.76 | Q6: =N6/K6 -> 0.9568 | S6: 0.7375 | T6: 0.78958333 | U6: =(S6-T5)*24*60 -> 7 | V6: =(T6-S6)*24*60 -> 75 | AA6: =M6-J6 -> -86.4 | AB6: =M6/J6 -> 0.9568
A7: 新豐6線 | B7: 微波主食 | C7: 二配港式香滑嫩蛋牛肉燴飯 | E7: 50.67 | F7: 2021 | G7: =E7*F7 -> 102404.07 | I7: 17 | J7: 2000 | K7: =J7/I7 -> 117.64706 | L7: 17 | M7: =F7/V7*60 -> 1924.7619 | N7: =M7/L7 -> 113.22129 | O7: =L7-I7 -> 0 | P7: =N7-K7 -> -4.4257703 | Q7: =N7/K7 -> 0.96238095 | S7: 0.79375 | T7: 0.8375 | U7: =(S7-T6)*24*60 -> 6 | V7: =(T7-S7)*24*60 -> 63 | AA7: =M7-J7 -> -75.238095 | AB7: =M7/J7 -> 0.96238095
A8: 新豐6線 | B8: 平均 | I8: 16 | J8: 2000 | K8: =J8/I8 -> 125 | L8: 16 | M8: =AVERAGE(M5:M7) -> 1926.3111 | N8: =M8/L8 -> 120.39444 | O8: =L8-I8 -> 0 | P8: =N8-K8 -> -4.6055556 | Q8: =N8/K8 -> 0.96315556 | AA8: =M8-J8 -> -73.688889 | AB8: =M8/J8 -> 0.96315556
A9: 新豐2線 | B9: 沙拉 | C9: 青檸烤雞握沙拉(113年) | E9: 39.8 | F9: 6000 | G9: =E9*F9 -> 238800 | H9: 2 | I9: 17 | J9: 1500 | K9: =J9/I9 -> 88.235294 | L9: 17 | M9: =F9/V9*60 -> 1428.5714 | N9: =M9/L9 -> 84.033613 | O9: =L9-I9 -> 0 | P9: =N9-K9 -> -4.2016807 | Q9: =N9/K9 -> 0.95238095 | R9: =Q12 -> 0.95456736 | S9: 0.20833333 | T9: 0.38333333 | V9: =(T9-S9)*24*60 -> 252 | AA9: =M9-J9 -> -71.428571 | AB9: =M9/J9 -> 0.95238095 | AC9: =AB12 -> 0.95456736
A10: 新豐2線 | B10: 沙拉 | C10: 韓式泡菜豆腐握沙拉 | E10: 39.36 | F10: 3560 | G10: =E10*F10 -> 140121.6 | I10: 20 | J10: 1500 | K10: =J10/I10 -> 75 | L10: 20 | M10: =F10/V10*60 -> 1433.557 | N10: =M10/L10 -> 71.677852 | O10: =L10-I10 -> 0 | P10: =N10-K10 -> -3.3221477 | Q10: =N10/K10 -> 0.9557047 | S10: 0.38888889 | T10: 0.49236111 | U10: =(S10-T9)*24*60 -> 8 | V10: =(T10-S10)*24*60 -> 149 | W10: =T10 -> 0.49236111 | X10: =S11 -> 0.575 | AA10: =M10-J10 -> -66.442953 | AB10: =M10/J10 -> 0.9557047
A11: 新豐2線 | B11: 沙拉 | C11: 青檸烤雞握沙拉(113年) | E11: 39.8 | F11: 1744 | G11: =E11*F11 -> 69411.2 | I11: 17 | J11: 1500 | K11: =J11/I11 -> 88.235294 | L11: 17 | M11: =F11/V11*60 -> 1433.4247 | N11: =M11/L11 -> 84.319098 | O11: =L11-I11 -> 0 | P11: =N11-K11 -> -3.9161966 | Q11: =N11/K11 -> 0.95561644 | S11: 0.575 | T11: 0.62569444 | U11: =(S11-T10)*24*60 -> 119 | V11: =(T11-S11)*24*60 -> 73 | AA11: =M11-J11 -> -66.575342 | AB11: =M11/J11 -> 0.95561644
A12: 新豐2線 | B12: 平均 | I12: 18 | J12: 1500 | K12: =J12/I12 -> 83.333333 | L12: 18 | M12: =AVERAGE(M9:M11) -> 1431.851 | N12: =M12/L12 -> 79.54728 | O12: =L12-I12 -> 0 | P12: =N12-K12 -> -3.7860531 | Q12: =N12/K12 -> 0.95456736 | AA12: =M12-J12 -> -68.148956 | AB12: =M12/J12 -> 0.95456736
A13: 新豐5線 | B13: 小吃 | C13: 剝皮辣椒雞湯 | E13: 41 | F13: 2111 | G13: =E13*F13 -> 86551 | I13: 26 | J13: 1500 | K13: =J13/I13 -> 57.692308 | L13: 26 | M13: =F13/V13*60 -> 1439.3182 | N13: =M13/L13 -> 55.358392 | O13: =L13-I13 -> 0 | P13: =N13-K13 -> -2.3339161 | Q13: =N13/K13 -> 0.95954545 | R13: =Q21 -> 0.96042901 | S13: 0.20833333 | T13: 0.26944444 | V13: =(T13-S13)*24*60 -> 88 | AA13: =M13-J13 -> -60.681818 | AB13: =M13/J13 -> 0.95954545 | AC13: =AB21 -> 0.96042901
A14: 新豐5線 | B14: 沙拉 | C14: 青醬優格雞肉握沙拉(113年) | E14: 39.62 | F14: 2800 | G14: =E14*F14 -> 110936 | H14: 2 | I14: 19 | J14: 1500 | K14: =J14/I14 -> 78.947368 | L14: 19 | M14: =F14/V14*60 -> 1435.8974 | N14: =M14/L14 -> 75.573549 | O14: =L14-I14 -> 0 | P14: =N14-K14 -> -3.3738192 | Q14: =N14/K14 -> 0.95726496 | S14: 0.27361111 | T14: 0.35486111 | U14: =IF(S14=TIME(17,0,0),"",(S14-T13)*24*60) -> 6 | V14: =(T14-S14)*24*60 -> 117 | AA14: =M14-J14 -> -64.102564 | AB14: =M14/J14 -> 0.95726496
A15: 新豐5線 | B15: 三明治 | C15: 瘋狂起司三明治(113年) | E15: 24.45 | F15: 1400 | G15: =E15*F15 -> 34230 | H15: 2 | I15: 20 | J15: 2400 | K15: =J15/I15 -> 120 | L15: 20 | M15: =F15/V15*60 -> 2333.3333 | N15: =M15/L15 -> 116.66667 | O15: =L15-I15 -> 0 | P15: =N15-K15 -> -3.3333333 | Q15: =N15/K15 -> 0.97222222 | S15: 0.35972222 | T15: 0.38472222 | U15: =IF(S15=TIME(17,0,0),"",(S15-T14)*24*60) -> 7 | V15: =(T15-S15)*24*60 -> 36 | AA15: =M15-J15 -> -66.666667 | AB15: =M15/J15 -> 0.97222222
A16: 新豐5線 | B16: 沙拉 | C16: 青醬優格雞肉握沙拉(113年) | E16: 39.62 | F16: 2326 | G16: =E16*F16 -> 92156.12 | I16: 19 | J16: 1500 | K16: =J16/I16 -> 78.947368 | L16: 19 | M16: =F16/V16*60 -> 1438.7629 | N16: =M16/L16 -> 75.724362 | O16: =L16-I16 -> 0 | P16: =N16-K16 -> -3.223006 | Q16: =N16/K16 -> 0.95917526 | S16: 0.38958333 | T16: 0.45694444 | U16: =IF(S16=TIME(17,0,0),"",(S16-T15)*24*60) -> 7 | V16: =(T16-S16)*24*60 -> 97 | W16: =T16 -> 0.45694444 | X16: =S17 -> 0.53819444 | AA16: =M16-J16 -> -61.237113 | AB16: =M16/J16 -> 0.95917526
A17: 新豐5線 | B17: 三明治 | C17: 泰奶奶蓋QQ三明治 | E17: 24.25 | F17: 2772 | G17: =E17*F17 -> 67221 | I17: 14 | J17: 2400 | K17: =J17/I17 -> 171.42857 | L17: 14 | M17: =F17/V17*60 -> 2310 | N17: =M17/L17 -> 165 | O17: =L17-I17 -> 0 | P17: =N17-K17 -> -6.4285714 | Q17: =N17/K17 -> 0.9625 | S17: 0.53819444 | T17: 0.58819444 | U17: =IF(S17=TIME(17,0,0),"",(S17-T16)*24*60) -> 117 | V17: =(T17-S17)*24*60 -> 72 | AA17: =M17-J17 -> -90 | AB17: =M17/J17 -> 0.9625
A18: 新豐5線 | B18: 三明治 | C18: 雞蛋沙拉三明治 | E18: 25 | F18: 2231 | G18: =E18*F18 -> 55775 | I18: 15 | J18: 2400 | K18: =J18/I18 -> 160 | L18: 15 | M18: =F18/V18*60 -> 2307.931 | N18: =M18/L18 -> 153.86207 | O18: =L18-I18 -> 0 | P18: =N18-K18 -> -6.137931 | Q18: =N18/K18 -> 0.96163793 | S18: 0.59375 | T18: 0.63402778 | U18: =IF(S18=TIME(17,0,0),"",(S18-T17)*24*60) -> 8 | V18: =(T18-S18)*24*60 -> 58 | AA18: =M18-J18 -> -92.068966 | AB18: =M18/J18 -> 0.96163793
A19: 新豐5線 | B19: 微波主食 | C19: 二配金咖哩濃厚辛辣咖哩飯 | E19: 50.98 | F19: 3055 | G19: =E19*F19 -> 155743.9 | I19: 16 | J19: 2000 | K19: =J19/I19 -> 125 | L19: 16 | M19: =F19/V19*60 -> 1909.375 | N19: =M19/L19 -> 119.33594 | O19: =L19-I19 -> 0 | P19: =N19-K19 -> -5.6640625 | Q19: =N19/K19 -> 0.9546875 | S19: 0.70833333 | T19: 0.775 | U19: =IF(S19=TIME(17,0,0),"",(S19-T18)*24*60) | V19: =(T19-S19)*24*60 -> 96 | AA19: =M19-J19 -> -90.625 | AB19: =M19/J19 -> 0.9546875
A20: 新豐5線 | B20: 微波主食 | C20: 二配金咖哩果香甘口咖哩飯 | E20: 50.92 | F20: 3237 | G20: =E20*F20 -> 164828.04 | I20: 15 | J20: 2000 | K20: =J20/I20 -> 133.33333 | L20: 15 | M20: =F20/V20*60 -> 1904.1176 | N20: =M20/L20 -> 126.94118 | O20: =L20-I20 -> 0 | P20: =N20-K20 -> -6.3921569 | Q20: =N20/K20 -> 0.95205882 | S20: 0.77986111 | T20: 0.85069444 | U20: =IF(S20=TIME(17,0,0),"",(S20-T19)*24*60) -> 7 | V20: =(T20-S20)*24*60 -> 102 | AA20: =M20-J20 -> -95.882353 | AB20: =M20/J20 -> 0.95205882
A21: 新豐5線 | B21: 平均 | I21: 18 | J21: 1962.5 | K21: =J21/I21 -> 109.02778 | L21: 18 | M21: =AVERAGE(M13:M20) -> 1884.8419 | N21: =M21/L21 -> 104.71344 | O21: =L21-I21 -> 0 | P21: =N21-K21 -> -4.3143367 | Q21: =N21/K21 -> 0.96042901 | AA21: =M21-J21 -> -77.65806 | AB21: =M21/J21 -> 0.96042901
A22: 新豐7線 | B22: 小吃 | C22: 古早味炒炊粉 | E22: 43.14 | F22: 1399 | G22: =E22*F22 -> 60352.86 | I22: 17 | J22: 2000 | K22: =J22/I22 -> 117.64706 | L22: 17 | M22: =F22/V22*60 -> 1907.7273 | N22: =M22/L22 -> 112.21925 | O22: =L22-I22 -> 0 | P22: =N22-K22 -> -5.4278075 | Q22: =N22/K22 -> 0.95386364 | R22: =Q27 -> 0.95849632 | S22: 0.20833333 | T22: 0.23888889 | V22: =(T22-S22)*24*60 -> 44 | AA22: =M22-J22 -> -92.272727 | AB22: =M22/J22 -> 0.95386364 | AC22: =AB27 -> 0.95849632
A23: 新豐7線 | B23: 微波主食 | C23: 鐵板滑蛋炸豬排丼 | E23: 57.73 | F23: 2997 | G23: =E23*F23 -> 173016.81 | I23: 15 | J23: 2000 | K23: =J23/I23 -> 133.33333 | L23: 15 | M23: =F23/V23*60 -> 1912.9787 | N23: =M23/L23 -> 127.53191 | O23: =L23-I23 -> 0 | P23: =N23-K23 -> -5.8014184 | Q23: =N23/K23 -> 0.95648936 | S23: 0.24444444 | T23: 0.30972222 | U23: =IF(S23=TIME(17,0,0),"",(S23-T22)*24*60) -> 8 | V23: =(T23-S23)*24*60 -> 94 | AA23: =M23-J23 -> -87.021277 | AB23: =M23/J23 -> 0.95648936
A24: 新豐7線 | B24: 微波主食 | C24: 極上炙烤親子丼 | E24: 53.68 | F24: 1963 | G24: =E24*F24 -> 105373.84 | I24: 16 | J24: 2000 | K24: =J24/I24 -> 125 | L24: 16 | M24: =F24/V24*60 -> 1930.8197 | N24: =M24/L24 -> 120.67623 | O24: =L24-I24 -> 0 | P24: =N24-K24 -> -4.3237705 | Q24: =N24/K24 -> 0.96540984 | S24: 0.31388889 | T24: 0.35625 | U24: =IF(S24=TIME(17,0,0),"",(S24-T23)*24*60) -> 6 | V24: =(T24-S24)*24*60 -> 61 | AA24: =M24-J24 -> -69.180328 | AB24: =M24/J24 -> 0.96540984
A25: 新豐7線 | B25: 微波主食 | C25: 白味噌壽喜燒飯 | E25: 53.27 | F25: 2055 | G25: =E25*F25 -> 109469.85 | I25: 16 | J25: 2000 | K25: =J25/I25 -> 125 | L25: 16 | M25: =F25/V25*60 -> 1926.5625 | N25: =M25/L25 -> 120.41016 | O25: =L25-I25 -> 0 | P25: =N25-K25 -> -4.5898438 | Q25: =N25/K25 -> 0.96328125 | S25: 0.36180556 | T25: 0.40625 | U25: =IF(S25=TIME(17,0,0),"",(S25-T24)*24*60) -> 8 | V25: =(T25-S25)*24*60 -> 64 | AA25: =M25-J25 -> -73.4375 | AB25: =M25/J25 -> 0.96328125
A26: 新豐7線 | B26: 微波主食 | C26: 二配美味蟹煲 | E26: 54.09 | F26: 3051 | G26: =E26*F26 -> 165028.59 | I26: 19 | J26: 2000 | K26: =J26/I26 -> 105.26316 | L26: 19 | M26: =F26/V26*60 -> 1906.875 | N26: =M26/L26 -> 100.36184 | O26: =L26-I26 -> 0 | P26: =N26-K26 -> -4.9013158 | Q26: =N26/K26 -> 0.9534375 | S26: 0.70833333 | T26: 0.775 | U26: =IF(S26=TIME(17,0,0),"",(S26-T25)*24*60) | V26: =(T26-S26)*24*60 -> 96 | AA26: =M26-J26 -> -93.125 | AB26: =M26/J26 -> 0.9534375
A27: 新豐7線 | B27: 平均 | I27: 16.6 | J27: 2000 | K27: =J27/I27 -> 120.48193 | L27: 16.6 | M27: =AVERAGE(M22:M26) -> 1916.9926 | N27: =M27/L27 -> 115.48148 | O27: =L27-I27 -> 0 | P27: =N27-K27 -> -5.0004438 | Q27: =N27/K27 -> 0.95849632 | AA27: =M27-J27 -> -83.007366 | AB27: =M27/J27 -> 0.95849632
A28: 新豐8線 | B28: 三明治 | C28: 經典總匯三明治 | E28: 26.2 | F28: 3200 | G28: =E28*F28 -> 83840 | H28: 2 | I28: 20 | J28: 2400 | K28: =J28/I28 -> 120 | L28: 20 | M28: =F28/V28*60 -> 2285.7143 | N28: =M28/L28 -> 114.28571 | O28: =L28-I28 -> 0 | P28: =N28-K28 -> -5.7142857 | Q28: =N28/K28 -> 0.95238095 | R28: =Q39 -> 0.95901949 | S28: 0.125 | T28: 0.18333333 | V28: =(T28-S28)*24*60 -> 84 | W28: =T28 -> 0.18333333 | X28: =S29 -> 0.20486111 | AA28: =M28-J28 -> -114.28571 | AB28: =M28/J28 -> 0.95238095 | AC28: =AB39 -> 0.95901949
A29: 新豐8線 | B29: 三明治 | C29: 紐奧良風味烤雞鮮蔬三明治 | E29: 31.29 | F29: 4400 | G29: =E29*F29 -> 137676 | H29: 2 | I29: 18 | J29: 2400 | K29: =J29/I29 -> 133.33333 | L29: 18 | M29: =F29/V29*60 -> 2295.6522 | N29: =M29/L29 -> 127.53623 | O29: =L29-I29 -> 0 | P29: =N29-K29 -> -5.7971014 | Q29: =N29/K29 -> 0.95652174 | S29: 0.20486111 | T29: 0.28472222 | U29: =(S29-T28)*24*60 -> 31 | V29: =(T29-S29)*24*60 -> 115 | AA29: =M29-J29 -> -104.34783 | AB29: =M29/J29 -> 0.95652174
A30: 新豐8線 | B30: 三明治 | C30: 雞蛋沙拉三明治 | E30: 25 | F30: 2700 | G30: =E30*F30 -> 67500 | H30: 2 | I30: 15 | J30: 2400 | K30: =J30/I30 -> 160 | L30: 15 | M30: =F30/V30*60 -> 2314.2857 | N30: =M30/L30 -> 154.28571 | O30: =L30-I30 -> 0 | P30: =N30-K30 -> -5.7142857 | Q30: =N30/K30 -> 0.96428571 | S30: 0.29027778 | T30: 0.33888889 | U30: =(S30-T29)*24*60 -> 8 | V30: =(T30-S30)*24*60 -> 70 | AA30: =M30-J30 -> -85.714286 | AB30: =M30/J30 -> 0.96428571
A31: 新豐8線 | B31: 三明治 | C31: 陽光地瓜總匯三明治 | E31: 26.18 | F31: 2800 | G31: =E31*F31 -> 73304 | H31: 2 | I31: 19 | J31: 2400 | K31: =J31/I31 -> 126.31579 | L31: 19 | M31: =F31/V31*60 -> 2301.3699 | N31: =M31/L31 -> 121.12473 | O31: =L31-I31 -> 0 | P31: =N31-K31 -> -5.1910598 | Q31: =N31/K31 -> 0.95890411 | S31: 0.34444444 | T31: 0.39513889 | U31: =(S31-T30)*24*60 -> 8 | V31: =(T31-S31)*24*60 -> 73 | AA31: =M31-J31 -> -98.630137 | AB31: =M31/J31 -> 0.95890411
A32: 新豐8線 | B32: 三明治 | C32: 好多菜三明治 | E32: 26.2 | F32: 2900 | G32: =E32*F32 -> 75980 | H32: 2 | I32: 19 | J32: 2400 | K32: =J32/I32 -> 126.31579 | L32: 19 | M32: =F32/V32*60 -> 2289.4737 | N32: =M32/L32 -> 120.49861 | O32: =L32-I32 -> 0 | P32: =N32-K32 -> -5.8171745 | Q32: =N32/K32 -> 0.95394737 | S32: 0.40069444 | T32: 0.45347222 | U32: =(S32-T31)*24*60 -> 8 | V32: =(T32-S32)*24*60 -> 76 | AA32: =M32-J32 -> -110.52632 | AB32: =M32/J32 -> 0.95394737
A33: 新豐8線 | B33: 三明治 | C33: 輕乳酪巧克力三明治 | E33: 20.52 | F33: 2300 | G33: =E33*F33 -> 47196 | H33: 2 | I33: 18 | J33: 2400 | K33: =J33/I33 -> 133.33333 | L33: 18 | M33: =F33/V33*60 -> 2300 | N33: =M33/L33 -> 127.77778 | O33: =L33-I33 -> 0 | P33: =N33-K33 -> -5.5555556 | Q33: =N33/K33 -> 0.95833333 | S33: 0.45763889 | T33: 0.49930556 | U33: =(S33-T32)*24*60 -> 6 | V33: =(T33-S33)*24*60 -> 60 | AA33: =M33-J33 -> -100 | AB33: =M33/J33 -> 0.95833333
A34: 新豐8線 | B34: 三明治 | C34: 紐奧良風味烤雞鮮蔬三明治 | E34: 31.29 | F34: 6311 | G34: =E34*F34 -> 197471.19 | I34: 18 | J34: 2400 | K34: =J34/I34 -> 133.33333 | L34: 18 | M34: =F34/V34*60 -> 2294.9091 | N34: =M34/L34 -> 127.49495 | O34: =L34-I34 -> 0 | P34: =N34-K34 -> -5.8383838 | Q34: =N34/K34 -> 0.95621212 | S34: 0.50347222 | T34: 0.61805556 | U34: =(S34-T33)*24*60 -> 6 | V34: =(T34-S34)*24*60 -> 165 | AA34: =M34-J34 -> -105.09091 | AB34: =M34/J34 -> 0.95621212
A35: 新豐8線 | B35: 三明治 | C35: 陽光地瓜總匯三明治 | E35: 26.18 | F35: 2039 | G35: =E35*F35 -> 53381.02 | I35: 19 | J35: 2400 | K35: =J35/I35 -> 126.31579 | L35: 19 | M35: =F35/V35*60 -> 2308.3019 | N35: =M35/L35 -> 121.48957 | O35: =L35-I35 -> 0 | P35: =N35-K35 -> -4.8262165 | Q35: =N35/K35 -> 0.96179245 | S35: 0.62361111 | T35: 0.66041667 | U35: =(S35-T34)*24*60 -> 8 | V35: =(T35-S35)*24*60 -> 53 | AA35: =M35-J35 -> -91.698113 | AB35: =M35/J35 -> 0.96179245
A36: 新豐8線 | B36: 三明治 | C36: 經典總匯三明治 | E36: 26.2 | F36: 2391 | G36: =E36*F36 -> 62644.2 | I36: 20 | J36: 2400 | K36: =J36/I36 -> 120 | L36: 20 | M36: =F36/V36*60 -> 2313.871 | N36: =M36/L36 -> 115.69355 | O36: =L36-I36 -> 0 | P36: =N36-K36 -> -4.3064516 | Q36: =N36/K36 -> 0.9641129 | S36: 0.66388889 | T36: 0.70694444 | U36: =(S36-T35)*24*60 -> 5 | V36: =(T36-S36)*24*60 -> 62 | AA36: =M36-J36 -> -86.129032 | AB36: =M36/J36 -> 0.9641129
A37: 新豐8線 | B37: 三明治 | C37: 好多菜三明治 | E37: 26.2 | F37: 1899 | G37: =E37*F37 -> 49753.8 | I37: 19 | J37: 2400 | K37: =J37/I37 -> 126.31579 | L37: 19 | M37: =F37/V37*60 -> 2325.3061 | N37: =M37/L37 -> 122.38453 | O37: =L37-I37 -> 0 | P37: =N37-K37 -> -3.9312567 | Q37: =N37/K37 -> 0.96887755 | S37: 0.71180556 | T37: 0.74583333 | U37: =(S37-T36)*24*60 -> 7 | V37: =(T37-S37)*24*60 -> 49 | AA37: =M37-J37 -> -74.693878 | AB37: =M37/J37 -> 0.96887755
A38: 新豐8線 | B38: 三明治 | C38: 輕乳酪巧克力三明治 | E38: 20.52 | F38: 1488 | G38: =E38*F38 -> 30533.76 | I38: 18 | J38: 2400 | K38: =J38/I38 -> 133.33333 | L38: 18 | M38: =F38/V38*60 -> 2289.2308 | N38: =M38/L38 -> 127.17949 | O38: =L38-I38 -> 0 | P38: =N38-K38 -> -6.1538462 | Q38: =N38/K38 -> 0.95384615 | S38: 0.75138889 | T38: 0.77847222 | U38: =(S38-T37)*24*60 -> 8 | V38: =(T38-S38)*24*60 -> 39 | AA38: =M38-J38 -> -110.76923 | AB38: =M38/J38 -> 0.95384615
A39: 新豐8線 | B39: 平均 | I39: 18.454545 | J39: 2400 | K39: =J39/I39 -> 130.04926 | L39: 18.454545 | M39: =AVERAGE(M28:M38) -> 2301.6468 | N39: =M39/L39 -> 124.71978 | O39: =L39-I39 -> 0 | P39: =N39-K39 -> -5.3294849 | Q39: =N39/K39 -> 0.95901949 | AA39: =M39-J39 -> -98.353222 | AB39: =M39/J39 -> 0.95901949
A40: 新豐9線 | B40: 三明治 | C40: 鮪魚起司溏心蛋三明治 | E40: 26.2 | F40: 4500 | G40: =E40*F40 -> 117900 | H40: 2 | I40: 18 | J40: 2400 | K40: =J40/I40 -> 133.33333 | L40: 18 | M40: =F40/V40*60 -> 2288.1356 | N40: =M40/L40 -> 127.11864 | O40: =L40-I40 -> 0 | P40: =N40-K40 -> -6.2146893 | Q40: =N40/K40 -> 0.95338983 | R40: =Q48 -> 0.9532744 | S40: 0.125 | T40: 0.20694444 | V40: =(T40-S40)*24*60 -> 118 | W40: =T40 -> 0.20694444 | X40: =S41 -> 0.22708333 | AA40: =M40-J40 -> -111.86441 | AB40: =M40/J40 -> 0.95338983 | AC40: =AB48 -> 0.9532744
...

Sheet 0929
B1: 屏榮 新豐廠組合室生產人時性分析
B3: 日期 | C3: =TEXT('0929 4度C'!A2,"yyyy.mm.ddaaaa") -> 2025.09.29星期一 | E3: 訂單量 | F3: ='0929 4度C'!D1 -> 199941 | H3: 營業額 | I3: ='0929 4度C'!F1 -> 6458150
B4: 人時性 | C4: 項目 | E4: ➀ | G4: ➁ | I4: ➂
C5: 組合室 | E5: 全溫層 | G5: 4度C-各編組展開 | I5: ③三明治-各編組展開
C6: 排關平均 | E6: =AVERAGE(D13:M13) -> 150.07566 | F6: =AVERAGE(D27:O27,D13:J13) -> 155.40086 | G6: =AVERAGE(D13:J13) -> 155.40086 | I6: =AVERAGE(K13:M13) -> 137.65018
C7: 實績平均 | E7: =AVERAGE(D14:M14) -> 143.83798 | F7: =AVERAGE(D28:O28,D14:J14) -> 149.03834 | G7: =AVERAGE(D14:J14) -> 149.03834 | I7: =AVERAGE(K14:M14) -> 131.70381
C8: 達成率平均 | E8: =AVERAGE(D15:M15) -> 0.95786887 | F8: =AVERAGE(D15:J15,D29:O29) -> 0.95832756 | G8: =AVERAGE(D15:J15) -> 0.95832756 | I8: =AVERAGE(K15:M15) -> 0.95679859 | K8: ※現行日本鮮食廠以達成率80%為基本(即為現行KPI)
B10: 溫層 | D10: ➁4度C-各編組展開 | K10: ③三明治-各編組展開
B11: 編組 | D11: 1 | E11: 2 | F11: 3 | G11: 4 | H11: 5 | I11: 6 | J11: 7 | K11: 1 | L11: 2 | M11: 3
D12: 新豐6線 | E12: 新豐2線 | F12: 新豐5線 | G12: 新豐7線 | H12: 新豐3線 | I12: 新豐1線 | J12: 新豐10線 | K12: 新豐8線 | L12: 新豐9線 | M12: 新豐4線
B13: 人時性 | C13: 排關 | D13: =SUMIFS('0929 4度C'!$K:$K,'0929 4度C'!$A:$A,"新豐6線",'0929 4度C'!$B:$B,"平均") -> 125 | E13: =SUMIFS('0929 4度C'!$K:$K,'0929 4度C'!$A:$A,"新豐2線",'0929 4度C'!$B:$B,"平均") -> 88.235294 | F13: =SUMIFS('0929 4度C'!$K:$K,'0929 4度C'!$A:$A,"新豐5線",'0929 4度C'!$B:$B,"平均") -> 96.124031 | G13: =SUMIFS('0929 4度C'!$K:$K,'0929 4度C'!$A:$A,"新豐7線",'0929 4度C'!$B:$B,"平均") -> 119.04762 | H13: =SUMIFS('0929 4度C'!$K:$K,'0929 4度C'!$A:$A,"新豐3線",'0929 4度C'!$B:$B,"平均") -> 310.34483 | I13: =SUMIFS('0929 4度C'!$K:$K,'0929 4度C'!$A:$A,"新豐1線",'0929 4度C'!$B:$B,"平均") -> 117.34694 | J13: =SUMIFS('0929 4度C'!$K:$K,'0929 4度C'!$A:$A,"新豐10線",'0929 4度C'!$B:$B,"平均") -> 231.70732 | K13: =SUMIFS('0929 4度C'!$K:$K,'0929 4度C'!$A:$A,"新豐8線",'0929 4度C'!$B:$B,"平均") -> 132 | L13: =SUMIFS('0929 4度C'!$K:$K,'0929 4度C'!$A:$A,"新豐9線",'0929 4度C'!$B:$B,"平均") -> 142.22222 | M13: =SUMIFS('0929 4度C'!$K:$K,'0929 4度C'!$A:$A,"新豐4線",'0929 4度C'!$B:$B,"平均") -> 138.72832
C14: 實績 | D14: =SUMIFS('0929 4度C'!$N:$N,'0929 4度C'!$A:$A,"新豐6線",'0929 4度C'!$B:$B,"平均") -> 119.63386 | E14: =SUMIFS('0929 4度C'!$N:$N,'0929 4度C'!$A:$A,"新豐2線",'0929 4度C'!$B:$B,"平均") -> 84.378774 | F14: =SUMIFS('0929 4度C'!$N:$N,'0929 4度C'!$A:$A,"新豐5線",'0929 4度C'!$B:$B,"平均") -> 91.824089 | G14: =SUMIFS('0929 4度C'!$N:$N,'0929 4度C'!$A:$A,"新豐7線",'0929 4度C'!$B:$B,"平均") -> 113.97594 | H14: =SUMIFS('0929 4度C'!$N:$N,'0929 4度C'!$A:$A,"新豐3線",'0929 4度C'!$B:$B,"平均") -> 297.09047 | I14: =SUMIFS('0929 4度C'!$N:$N,'0929 4度C'!$A:$A,"新豐1線",'0929 4度C'!$B:$B,"平均") -> 112.52904 | J14: =SUMIFS('0929 4度C'!$N:$N,'0929 4度C'!$A:$A,"新豐10線",'0929 4度C'!$B:$B,"平均") -> 223.83623 | K14: =SUMIFS('0929 4度C'!$N:$N,'0929 4度C'!$A:$A,"新豐8線",'0929 4度C'!$B:$B,"平均") -> 126.28014 | L14: =SUMIFS('0929 4度C'!$N:$N,'0929 4度C'!$A:$A,"新豐9線",'0929 4度C'!$B:$B,"平均") -> 136.08022 | M14: =SUMIFS('0929 4度C'!$N:$N,'0929 4度C'!$A:$A,"新豐4線",'0929 4度C'!$B:$B,"平均") -> 132.75107
C15: 達成率 | D15: =D14/D13 -> 0.95707085 | E15: =E14/E13 -> 0.95629278 | F15: =F14/F13 -> 0.95526674 | G15: =G14/G13 -> 0.95739791 | H15: =H14/H13 -> 0.95729151 | I15: =I14/I13 -> 0.95894313 | J15: =J14/J13 -> 0.96603004 | K15: =K14/K13 -> 0.95666775 | ... M15: =M14/M13 -> 0.956914
B16: 作業 時間 | C16: 開始 | D16: =VLOOKUP("新豐6線",'0929 4度C'!$A:$T,19,0) -> 0.70833333 | E16: =VLOOKUP("新豐2線",'0929 4度C'!$A:$T,19,0) -> 0.29166667 | F16: =VLOOKUP("新豐5線",'0929 4度C'!$A:$T,19,0) -> 0.20833333 | G16: =VLOOKUP("新豐7線",'0929 4度C'!$A:$T,19,0) -> 0.20833333 | H16: =VLOOKUP("新豐3線",'0929 4度C'!$A:$T,19,0) -> 0.083333333 | I16: =VLOOKUP("新豐1線",'0929 4度C'!$A:$T,19,0) -> 0.29166667 | J16: =VLOOKUP("新豐10線",'0929 4度C'!$A:$T,19,0) -> 0.20833333 | K16: =VLOOKUP("新豐8線",'0929 4度C'!$A:$T,19,0) -> 0.083333333 | L16: =VLOOKUP("新豐9線",'0929 4度C'!$A:$T,19,0) -> 0.083333333 | M16: =VLOOKUP("新豐4線",'0929 4度C'!$A:$T,19,0) -> 0.083333333
C17: 結束 | D17: =LOOKUP(2,1/(('0929 4度C'!$A:$A="新豐6線")*('0929 4度C'!$T:$T<>"")),'0929 4度C'!$T:$T) -> 0.84097222 | E17: =LOOKUP(2,1/(('0929 4度C'!$A:$A="新豐2線")*('0929 4度C'!$T:$T<>"")),'0929 4度C'!$T:$T) -> 0.60069444 | F17: =LOOKUP(2,1/(('0929 4度C'!$A:$A="新豐5線")*('0929 4度C'!$T:$T<>"")),'0929 4度C'!$T:$T) -> 0.85277778 | G17: =LOOKUP(2,1/(('0929 4度C'!$A:$A="新豐7線")*('0929 4度C'!$T:$T<>"")),'0929 4度C'!$T:$T) -> 0.77638889 | H17: =LOOKUP(2,1/(('0929 4度C'!$A:$A="新豐3線")*('0929 4度C'!$T:$T<>"")),'0929 4度C'!$T:$T) -> 0.50833333 | I17: =LOOKUP(2,1/(('0929 4度C'!$A:$A="新豐1線")*('0929 4度C'!$T:$T<>"")),'0929 4度C'!$T:$T) -> 0.85347222 | J17: =LOOKUP(2,1/(('0929 4度C'!$A:$A="新豐10線")*('0929 4度C'!$T:$T<>"")),'0929 4度C'!$T:$T) -> 0.4375 | K17: =LOOKUP(2,1/(('0929 4度C'!$A:$A="新豐8線")*('0929 4度C'!$T:$T<>"")),'0929 4度C'!$T:$T) -> 0.77986111 | L17: =LOOKUP(2,1/(('0929 4度C'!$A:$A="新豐9線")*('0929 4度C'!$T:$T<>"")),'0929 4度C'!$T:$T) -> 0.74097222 | M17: =LOOKUP(2,1/(('0929 4度C'!$A:$A="新豐4線")*('0929 4度C'!$T:$T<>"")),'0929 4度C'!$T:$T) -> 0.75694444
B18: 配置人數 | D18: =SUMIFS('0929 4度C'!$I:$I,'0929 4度C'!$A:$A,"新豐6線",'0929 4度C'!$B:$B,"平均") -> 16 | E18: =SUMIFS('0929 4度C'!$I:$I,'0929 4度C'!$A:$A,"新豐2線",'0929 4度C'!$B:$B,"平均") -> 17 | F18: =SUMIFS('0929 4度C'!$I:$I,'0929 4度C'!$A:$A,"新豐5線",'0929 4度C'!$B:$B,"平均") -> 18.428571 | G18: =SUMIFS('0929 4度C'!$I:$I,'0929 4度C'!$A:$A,"新豐7線",'0929 4度C'!$B:$B,"平均") -> 16.8 | H18: =SUMIFS('0929 4度C'!$I:$I,'0929 4度C'!$A:$A,"新豐3線",'0929 4度C'!$B:$B,"平均") -> 9.6666667 | I18: =SUMIFS('0929 4度C'!$I:$I,'0929 4度C'!$A:$A,"新豐1線",'0929 4度C'!$B:$B,"平均") -> 16.333333 | J18: =SUMIFS('0929 4度C'!$I:$I,'0929 4度C'!$A:$A,"新豐10線",'0929 4度C'!$B:$B,"平均") -> 10.25 | K18: =SUMIFS('0929 4度C'!$I:$I,'0929 4度C'!$A:$A,"新豐8線",'0929 4度C'!$B:$B,"平均") -> 18.181818 | L18: =SUMIFS('0929 4度C'!$I:$I,'0929 4度C'!$A:$A,"新豐9線",'0929 4度C'!$B:$B,"平均") -> 16.875 | M18: =SUMIFS('0929 4度C'!$I:$I,'0929 4度C'!$A:$A,"新豐4線",'0929 4度C'!$B:$B,"平均") -> 17.3
B19: 主要應用設備 | D19: ET-55 | E19: 熱縮爐 | F19: L型包裝機 | G19: L型包裝機 | H19: 伺服包裝機 | I19: ET-55 | J19: 伺服包裝機 | K19: 三明治包裝機 | L19: 三明治包裝機 | M19: 三明治包裝機
B20: 次要應用設備 | F20: 圓盤機 | G20: ET-55
B21: 備註 | E21: 握沙拉 | F21: 共用L型包裝機 | H21: 調理麵包 | I21: 炒飯+沙拉 | J21: 調理麵包

Sheet 0929 4度C
A1: 新豐廠四度C日報分析 | C1: 總生產量 | D1: =SUM(F5:F76) -> 199941 | E1: 營業額 | F1: =SUM(G5:G76) -> 6458150 | G1: 出勤人數 | H1: =L8+L11+L53+L60+L19+L65+L37+L46+L25+L76 -> 156.83539 | I1: 產線配置圖 | L1: 生產實績 | O1: 人時性差異分析 | S1: 日報登錄 | Y1: 分析說明 | AA1: 產能差異分析
A2: 45929 | B2: 星期一 | C2: 人時性 | D2: =AVERAGE(N8,N11,N53,N60,N19,N65,N25,N37,N46,N76) -> 143.83798 | E2: 平均廠價 | F2: =F1/D1 -> 32.300278 | G2: 多次生產數 | H2: =COUNT(H5:H76) -> 14
A3: 線別 | B3: 品類 | C3: 品名 | E3: 廠價 | F3: 生產量 | G3: 營收 | H3: 多次 生產 | I3: 人數 | J3: 產能/時 | K3: 人時性 | L3: 人數 | M3: 產能/時 | N3: 人時性 | O3: 人數 | P3: 人時性 | Q3: 達成率 | R3: 達成率平均 | S3: 生產時間 | U3: 換線、休息/分 | V3: 稼動時間/分 | W3: 休息時間 | Y3: (新豐回填) | AA3: 產能/時 | AB3: 達成率 | AC3: 達成率平均
S4: 開始 | T4: 結束 | W4: 開始 | X4: 結束
A5: 新豐6線 | B5: 微波主食 | C5: 二配煸椒烘蛋飯 | E5: 46.93 | F5: 1081 | G5: =E5*F5 -> 50731.33 | I5: 16 | J5: 2000 | K5: =J5/I5 -> 125 | L5: 16 | M5: =F5/V5*60 -> 1907.6471 | N5: =M5/L5 -> 119.22794 | O5: =L5-I5 -> 0 | P5: =N5-K5 -> -5.7720588 | Q5: =N5/K5 -> 0.95382353 | R5: =Q8 -> 0.95707085 | S5: 0.70833333 | T5: 0.73194444 | V5: =(T5-S5)*24*60 -> 34 | AA5: =M5-J5 -> -92.352941 | AB5: =M5/J5 -> 0.95382353 | AC5: =AB8 -> 0.95707085
A6: 新豐6線 | B6: 微波主食 | C6: 二配川味麻婆燒豆腐燴飯 | E6: 50.49 | F6: 2455 | G6: =E6*F6 -> 123952.95 | I6: 15 | J6: 2000 | K6: =J6/I6 -> 133.33333 | L6: 15 | M6: =F6/V6*60 -> 1912.987 | N6: =M6/L6 -> 127.53247 | O6: =L6-I6 -> 0 | P6: =N6-K6 -> -5.8008658 | Q6: =N6/K6 -> 0.95649351 | S6: 0.73680556 | T6: 0.79027778 | U6: =(S6-T5)*24*60 -> 7 | V6: =(T6-S6)*24*60 -> 77 | AA6: =M6-J6 -> -87.012987 | AB6: =M6/J6 -> 0.95649351
A7: 新豐6線 | B7: 微波主食 | C7: 二配港式香滑嫩蛋牛肉燴飯 | E7: 50.67 | F7: 2146 | G7: =E7*F7 -> 108737.82 | I7: 17 | J7: 2000 | K7: =J7/I7 -> 117.64706 | L7: 17 | M7: =F7/V7*60 -> 1921.791 | N7: =M7/L7 -> 113.04653 | O7: =L7-I7 -> 0 | P7: =N7-K7 -> -4.6005268 | Q7: =N7/K7 -> 0.96089552 | S7: 0.79444444 | T7: 0.84097222 | U7: =(S7-T6)*24*60 -> 6 | V7: =(T7-S7)*24*60 -> 67 | AA7: =M7-J7 -> -78.208955 | AB7: =M7/J7 -> 0.96089552
A8: 新豐6線 | B8: 平均 | I8: 16 | J8: 2000 | K8: =J8/I8 -> 125 | L8: 16 | M8: =AVERAGE(M5:M7) -> 1914.1417 | N8: =M8/L8 -> 119.63386 | O8: =L8-I8 -> 0 | P8: =N8-K8 -> -5.3661434 | Q8: =N8/K8 -> 0.95707085 | AA8: =M8-J8 -> -85.858294 | AB8: =M8/J8 -> 0.95707085
A9: 新豐2線 | B9: 沙拉 | C9: 青檸烤雞握沙拉(113年) | E9: 39.8 | F9: 6000 | G9: =E9*F9 -> 238800 | H9: 2 | I9: 17 | J9: 1500 | K9: =J9/I9 -> 88.235294 | L9: 17 | M9: =F9/V9*60 -> 1434.2629 | N9: =M9/L9 -> 84.368409 | O9: =L9-I9 -> 0 | P9: =N9-K9 -> -3.8668854 | Q9: =N9/K9 -> 0.9561753 | R9: =Q11 -> 0.95629278 | S9: 0.29166667 | T9: 0.46597222 | V9: =(T9-S9)*24*60 -> 251 | W9: =T9 -> 0.46597222 | X9: =S10 -> 0.54652778 | AA9: =M9-J9 -> -65.737052 | AB9: =M9/J9 -> 0.9561753 | AC9: =AB11 -> 0.95629278
A10: 新豐2線 | B10: 沙拉 | C10: 青檸烤雞握沙拉(113年) | E10: 39.8 | F10: 1865 | G10: =E10*F10 -> 74227 | I10: 17 | J10: 1500 | K10: =J10/I10 -> 88.235294 | L10: 17 | M10: =F10/V10*60 -> 1434.6154 | N10: =M10/L10 -> 84.38914 | O10: =L10-I10 -> 0 | P10: =N10-K10 -> -3.8461538 | Q10: =N10/K10 -> 0.95641026 | S10: 0.54652778 | T10: 0.60069444 | U10: =(S10-T9)*24*60 -> 116 | V10: =(T10-S10)*24*60 -> 78 | AA10: =M10-J10 -> -65.384615 | AB10: =M10/J10 -> 0.95641026
A11: 新豐2線 | B11: 平均 | I11: 17 | J11: 1500 | K11: =J11/I11 -> 88.235294 | L11: 17 | M11: =AVERAGE(M9:M10) -> 1434.4392 | N11: =M11/L11 -> 84.378774 | O11: =L11-I11 -> 0 | P11: =N11-K11 -> -3.8565196 | Q11: =N11/K11 -> 0.95629278 | AA11: =M11-J11 -> -65.560834 | AB11: =M11/J11 -> 0.95629278
A12: 新豐5線 | B12: 小吃 | C12: 剝皮辣椒雞湯 | E12: 41 | F12: 2250 | G12: =E12*F12 -> 92250 | I12: 26 | J12: 1500 | K12: =J12/I12 -> 57.692308 | L12: 26 | M12: =F12/V12*60 -> 1436.1702 | N12: =M12/L12 -> 55.237316 | O12: =L12-I12 -> 0 | P12: =N12-K12 -> -2.4549918 | Q12: =N12/K12 -> 0.95744681 | R12: =Q19 -> 0.95526674 | S12: 0.20833333 | T12: 0.27361111 | V12: =(T12-S12)*24*60 -> 94 | AA12: =M12-J12 -> -63.829787 | AB12: =M12/J12 -> 0.95744681 | AC12: =AB19 -> 0.95526674
A13: 新豐5線 | B13: 沙拉 | C13: 青醬優格雞肉握沙拉(113年) | E13: 39.62 | F13: 2950 | G13: =E13*F13 -> 116879 | H13: 2 | I13: 19 | J13: 1500 | K13: =J13/I13 -> 78.947368 | L13: 19 | M13: =F13/V13*60 -> 1439.0244 | N13: =M13/L13 -> 75.738126 | O13: =L13-I13 -> 0 | P13: =N13-K13 -> -3.2092426 | Q13: =N13/K13 -> 0.95934959 | S13: 0.27708333 | T13: 0.3625 | U13: =IF(S13=TIME(17,0,0),"",(S13-T12)*24*60) -> 5 | V13: =(T13-S13)*24*60 -> 123 | AA13: =M13-J13 -> -60.97561 | AB13: =M13/J13 -> 0.95934959
A14: 新豐5線 | B14: 沙拉 | C14: 韓式泡菜豆腐握沙拉 | E14: 39.36 | F14: 3985 | G14: =E14*F14 -> 156849.6 | I14: 20 | J14: 1500 | K14: =J14/I14 -> 75 | L14: 20 | M14: =F14/V14*60 -> 1431.7365 | N14: =M14/L14 -> 71.586826 | O14: =L14-I14 -> 0 | P14: =N14-K14 -> -3.4131737 | Q14: =N14/K14 -> 0.95449102 | S14: 0.36597222 | T14: 0.48194444 | U14: =IF(S14=TIME(17,0,0),"",(S14-T13)*24*60) -> 5 | V14: =(T14-S14)*24*60 -> 167 | W14: =T14 -> 0.48194444 | X14: =S15 -> 0.5625 | AA14: =M14-J14 -> -68.263473 | AB14: =M14/J14 -> 0.95449102
A15: 新豐5線 | B15: 沙拉 | C15: 青醬優格雞肉握沙拉(113年) | E15: 39.62 | F15: 2403 | G15: =E15*F15 -> 95206.86 | I15: 19 | J15: 1500 | K15: =J15/I15 -> 78.947368 | L15: 19 | M15: =F15/V15*60 -> 1441.8 | N15: =M15/L15 -> 75.884211 | O15: =L15-I15 -> 0 | P15: =N15-K15 -> -3.0631579 | Q15: =N15/K15 -> 0.9612 | S15: 0.5625 | T15: 0.63194444 | U15: =IF(S15=TIME(17,0,0),"",(S15-T14)*24*60) -> 116 | V15: =(T15-S15)*24*60 -> 100 | AA15: =M15-J15 -> -58.2 | AB15: =M15/J15 -> 0.9612
A16: 新豐5線 | B16: 三明治 | C16: 泰奶奶蓋QQ三明治 | E16: 24.25 | F16: 3272 | G16: =E16*F16 -> 79346 | I16: 14 | J16: 2400 | K16: =J16/I16 -> 171.42857 | L16: 14 | M16: =F16/V16*60 -> 2282.7907 | N16: =M16/L16 -> 163.05648 | O16: =L16-I16 -> 0 | P16: =N16-K16 -> -8.372093 | Q16: =N16/K16 -> 0.95116279 | S16: 0.63680556 | T16: 0.69652778 | U16: =IF(S16=TIME(17,0,0),"",(S16-T15)*24*60) -> 7 | V16: =(T16-S16)*24*60 -> 86 | AA16: =M16-J16 -> -117.2093 | AB16: =M16/J16 -> 0.95116279
A17: 新豐5線 | B17: 微波主食 | C17: 二配金咖哩濃厚辛辣咖哩飯 | E17: 50.98 | F17: 3052 | G17: =E17*F17 -> 155590.96 | I17: 16 | J17: 2000 | K17: =J17/I17 -> 125 | L17: 16 | M17: =F17/V17*60 -> 1907.5 | N17: =M17/L17 -> 119.21875 | O17: =L17-I17 -> 0 | P17: =N17-K17 -> -5.78125 | Q17: =N17/K17 -> 0.95375 | S17: 0.70833333 | T17: 0.775 | U17: =IF(S17=TIME(17,0,0),"",(S17-T16)*24*60) | V17: =(T17-S17)*24*60 -> 96 | AA17: =M17-J17 -> -92.5 | AB17: =M17/J17 -> 0.95375
A18: 新豐5線 | B18: 微波主食 | C18: 二配金咖哩果香甘口咖哩飯 | E18: 50.92 | F18: 3336 | G18: =E18*F18 -> 169869.12 | I18: 15 | J18: 2000 | K18: =J18/I18 -> 133.33333 | L18: 15 | M18: =F18/V18*60 -> 1906.2857 | N18: =M18/L18 -> 127.08571 | O18: =L18-I18 -> 0 | P18: =N18-K18 -> -6.247619 | Q18: =N18/K18 -> 0.95314286 | S18: 0.77986111 | T18: 0.85277778 | U18: =IF(S18=TIME(17,0,0),"",(S18-T17)*24*60) -> 7 | V18: =(T18-S18)*24*60 -> 105 | AA18: =M18-J18 -> -93.714286 | AB18: =M18/J18 -> 0.95314286
A19: 新豐5線 | B19: 平均 | I19: 18.428571 | J19: 1771.4286 | K19: =J19/I19 -> 96.124031 | L19: 18.428571 | M19: =AVERAGE(M12:M18) -> 1692.1868 | N19: =M19/L19 -> 91.824089 | O19: =L19-I19 -> 0 | P19: =N19-K19 -> -4.2999415 | Q19: =N19/K19 -> 0.95526674 | AA19: =M19-J19 -> -79.24178 | AB19: =M19/J19 -> 0.95526674
A20: 新豐7線 | B20: 小吃 | C20: 古早味炒炊粉 | E20: 43.14 | F20: 1502 | G20: =E20*F20 -> 64796.28 | I20: 17 | J20: 2000 | K20: =J20/I20 -> 117.64706 | L20: 17 | M20: =F20/V20*60 -> 1917.4468 | N20: =M20/L20 -> 112.79099 | O20: =L20-I20 -> 0 | P20: =N20-K20 -> -4.8560701 | Q20: =N20/K20 -> 0.9587234 | R20: =Q25 -> 0.95739791 | S20: 0.20833333 | T20: 0.24097222 | V20: =(T20-S20)*24*60 -> 47 | AA20: =M20-J20 -> -82.553191 | AB20: =M20/J20 -> 0.9587234 | AC20: =AB25 -> 0.95739791
A21: 新豐7線 | B21: 微波主食 | C21: 鐵板滑蛋炸豬排丼 | E21: 57.73 | F21: 3070 | G21: =E21*F21 -> 177231.1 | I21: 15 | J21: 2000 | K21: =J21/I21 -> 133.33333 | L21: 15 | M21: =F21/V21*60 -> 1918.75 | N21: =M21/L21 -> 127.91667 | O21: =L21-I21 -> 0 | P21: =N21-K21 -> -5.4166667 | Q21: =N21/K21 -> 0.959375 | S21: 0.24652778 | T21: 0.31319444 | U21: =IF(S21=TIME(17,0,0),"",(S21-T20)*24*60) -> 8 | V21: =(T21-S21)*24*60 -> 96 | AA21: =M21-J21 -> -81.25 | AB21: =M21/J21 -> 0.959375
A22: 新豐7線 | B22: 微波主食 | C22: 極上炙烤親子丼 | E22: 53.68 | F22: 2009 | G22: =E22*F22 -> 107843.12 | I22: 16 | J22: 2000 | K22: =J22/I22 -> 125 | L22: 16 | M22: =F22/V22*60 -> 1913.3333 | N22: =M22/L22 -> 119.58333 | O22: =L22-I22 -> 0 | P22: =N22-K22 -> -5.4166667 | Q22: =N22/K22 -> 0.95666667 | S22: 0.31666667 | T22: 0.36041667 | U22: =IF(S22=TIME(17,0,0),"",(S22-T21)*24*60) -> 5 | V22: =(T22-S22)*24*60 -> 63 | AA22: =M22-J22 -> -86.666667 | AB22: =M22/J22 -> 0.95666667
A23: 新豐7線 | B23: 微波主食 | C23: 白味噌壽喜燒飯 | E23: 53.27 | F23: 2229 | G23: =E23*F23 -> 118738.83 | I23: 17 | J23: 2000 | K23: =J23/I23 -> 117.64706 | L23: 17 | M23: =F23/V23*60 -> 1910.5714 | N23: =M23/L23 -> 112.38655 | O23: =L23-I23 -> 0 | P23: =N23-K23 -> -5.2605042 | Q23: =N23/K23 -> 0.95528571 | S23: 0.36388889 | T23: 0.4125 | U23: =IF(S23=TIME(17,0,0),"",(S23-T22)*24*60) -> 5 | V23: =(T23-S23)*24*60 -> 70 | AA23: =M23-J23 -> -89.428571 | AB23: =M23/J23 -> 0.95528571
A24: 新豐7線 | B24: 微波主食 | C24: 二配美味蟹煲 | E24: 54.09 | F24: 3126 | G24: =E24*F24 -> 169085.34 | I24: 19 | J24: 2000 | K24: =J24/I24 -> 105.26316 | L24: 19 | M24: =F24/V24*60 -> 1913.8776 | N24: =M24/L24 -> 100.7304 | O24: =L24-I24 -> 0 | P24: =N24-K24 -> -4.5327605 | Q24: =N24/K24 -> 0.95693878 | S24: 0.70833333 | T24: 0.77638889 | U24: =IF(S24=TIME(17,0,0),"",(S24-T23)*24*60) | V24: =(T24-S24)*24*60 -> 98 | AA24: =M24-J24 -> -86.122449 | AB24: =M24/J24 -> 0.95693878
A25: 新豐7線 | B25: 平均 | I25: 16.8 | J25: 2000 | K25: =J25/I25 -> 119.04762 | L25: 16.8 | M25: =AVERAGE(M20:M24) -> 1914.7958 | N25: =M25/L25 -> 113.97594 | O25: =L25-I25 -> 0 | P25: =N25-K25 -> -5.0716771 | Q25: =N25/K25 -> 0.95739791 | AA25: =M25-J25 -> -85.204176 | AB25: =M25/J25 -> 0.95739791
A26: 新豐8線 | B26: 三明治 | C26: 經典總匯三明治 | E26: 26.2 | F26: 3000 | G26: =E26*F26 -> 78600 | H26: 2 | I26: 20 | J26: 2400 | K26: =J26/I26 -> 120 | L26: 20 | M26: =F26/V26*60 -> 2307.6923 | N26: =M26/L26 -> 115.38462 | O26: =L26-I26 -> 0 | P26: =N26-K26 -> -4.6153846 | Q26: =N26/K26 -> 0.96153846 | R26: =Q37 -> 0.95666775 | S26: 0.083333333 | T26: 0.1375 | V26: =(T26-S26)*24*60 -> 78 | W26: =T26 -> 0.1375 | X26: =S27 -> 0.15486111 | AA26: =M26-J26 -> -92.307692 | AB26: =M26/J26 -> 0.96153846 | AC26: =AB37 -> 0.95666775
A27: 新豐8線 | B27: 三明治 | C27: 紐奧良風味烤雞鮮蔬三明治 | E27: 31.29 | F27: 6100 | G27: =E27*F27 -> 190869 | H27: 2 | I27: 18 | J27: 2400 | K27: =J27/I27 -> 133.33333 | L27: 18 | M27: =F27/V27*60 -> 2287.5 | N27: =M27/L27 -> 127.08333 | O27: =L27-I27 -> 0 | P27: =N27-K27 -> -6.25 | Q27: =N27/K27 -> 0.953125 | S27: 0.15486111 | T27: 0.26597222 | U27: =(S27-T26)*24*60 -> 25 | V27: =(T27-S27)*24*60 -> 160 | AA27: =M27-J27 -> -112.5 | AB27: =M27/J27 -> 0.953125
A28: 新豐8線 | B28: 三明治 | C28: 雞蛋沙拉三明治 | E28: 25 | F28: 2700 | G28: =E28*F28 -> 67500 | H28: 2 | I28: 15 | J28: 2400 | K28: =J28/I28 -> 160 | L28: 15 | M28: =F28/V28*60 -> 2281.6901 | N28: =M28/L28 -> 152.11268 | O28: =L28-I28 -> 0 | P28: =N28-K28 -> -7.8873239 | Q28: =N28/K28 -> 0.95070423 | S28: 0.27152778 | T28: 0.32083333 | U28: =(S28-T27)*24*60 -> 8 | V28: =(T28-S28)*24*60 -> 71 | AA28: =M28-J28 -> -118.30986 | AB28: =M28/J28 -> 0.95070423
A29: 新豐8線 | B29: 三明治 | C29: 陽光地瓜總匯三明治 | E29: 26.18 | F29: 3000 | G29: =E29*F29 -> 78540 | H29: 2 | I29: 19 | J29: 2400 | K29: =J29/I29 -> 126.31579 | L29: 19 | M29: =F29/V29*60 -> 2307.6923 | N29: =M29/L29 -> 121.45749 | O29: =L29-I29 -> 0 | P29: =N29-K29 -> -4.8582996 | Q29: =N29/K29 -> 0.96153846 | S29: 0.32638889 | T29: 0.38055556 | U29: =(S29-T28)*24*60 -> 8 | V29: =(T29-S29)*24*60 -> 78 | AA29: =M29-J29 -> -92.307692 | AB29: =M29/J29 -> 0.96153846
A30: 新豐8線 | B30: 三明治 | C30: 好多菜三明治 | E30: 26.2 | F30: 3000 | G30: =E30*F30 -> 78600 | H30: 2 | I30: 19 | J30: 2400 | K30: =J30/I30 -> 126.31579 | L30: 19 | M30: =F30/V30*60 -> 2307.6923 | N30: =M30/L30 -> 121.45749 | O30: =L30-I30 -> 0 | P30: =N30-K30 -> -4.8582996 | Q30: =N30/K30 -> 0.96153846 | S30: 0.38611111 | T30: 0.44027778 | U30: =(S30-T29)*24*60 -> 8 | V30: =(T30-S30)*24*60 -> 78 | AA30: =M30-J30 -> -92.307692 | AB30: =M30/J30 -> 0.96153846
A31: 新豐8線 | B31: 三明治 | C31: 輕乳酪巧克力三明治 | E31: 20.52 | F31: 3924 | G31: =E31*F31 -> 80520.48 | I31: 18 | J31: 2400 | K31: =J31/I31 -> 133.33333 | L31: 18 | M31: =F31/V31*60 -> 2285.8252 | N31: =M31/L31 -> 126.99029 | O31: =L31-I31 -> 0 | P31: =N31-K31 -> -6.3430421 | Q31: =N31/K31 -> 0.95242718 | S31: 0.44583333 | T31: 0.51736111 | U31: =(S31-T30)*24*60 -> 8 | V31: =(T31-S31)*24*60 -> 103 | AA31: =M31-J31 -> -114.17476 | AB31: =M31/J31 -> 0.95242718
A32: 新豐8線 | B32: 三明治 | C32: 陽光地瓜總匯三明治 | E32: 26.18 | F32: 2181 | G32: =E32*F32 -> 57098.58 | I32: 19 | J32: 2400 | K32: =J32/I32 -> 126.31579 | L32: 19 | M32: =F32/V32*60 -> 2295.7895 | N32: =M32/L32 -> 120.83102 | O32: =L32-I32 -> 0 | P32: =N32-K32 -> -5.4847645 | Q32: =N32/K32 -> 0.95657895 | S32: 0.52222222 | T32: 0.56180556 | U32: =(S32-T31)*24*60 -> 7 | V32: =(T32-S32)*24*60 -> 57 | AA32: =M32-J32 -> -104.21053 | AB32: =M32/J32 -> 0.95657895
A33: 新豐8線 | B33: 三明治 | C33: 紐奧良風味烤雞鮮蔬三明治 | E33: 31.29 | F33: 4625 | G33: =E33*F33 -> 144716.25 | I33: 18 | J33: 2400 | K33: =J33/I33 -> 133.33333 | L33: 18 | M33: =F33/V33*60 -> 2293.3884 | N33: =M33/L33 -> 127.41047 | O33: =L33-I33 -> 0 | P33: =N33-K33 -> -5.922865 | Q33: =N33/K33 -> 0.95557851 | S33: 0.56597222 | T33: 0.65 | U33: =(S33-T32)*24*60 -> 6 | V33: =(T33-S33)*24*60 -> 121 | AA33: =M33-J33 -> -106.61157 | AB33: =M33/J33 -> 0.95557851
A34: 新豐8線 | B34: 三明治 | C34: 經典總匯三明治 | E34: 26.2 | F34: 2337 | G34: =E34*F34 -> 61229.4 | I34: 20 | J34: 2400 | K34: =J34/I34 -> 120 | L34: 20 | M34: =F34/V34*60 -> 2298.6885 | N34: =M34/L34 -> 114.93443 | O34: =L34-I34 -> 0 | P34: =N34-K34 -> -5.0655738 | Q34: =N34/K34 -> 0.95778689 | S34: 0.65347222 | T34: 0.69583333 | U34: =(S34-T33)*24*60 -> 5 | V34: =(T34-S34)*24*60 -> 61 | AA34: =M34-J34 -> -101.31148 | AB34: =M34/J34 -> 0.95778689
A35: 新豐8線 | B35: 三明治 | C35: 好多菜三明治 | E35: 26.2 | F35: 1948 | G35: =E35*F35 -> 51037.6 | I35: 19 | J35: 2400 | K35: =J35/I35 -> 126.31579 | L35: 19 | M35: =F35/V35*60 -> 2291.7647 | N35: =M35/L35 -> 120.6192 | O35: =L35-I35 -> 0 | P35: =N35-K35 -> -5.6965944 | Q35: =N35/K35 -> 0.95490196 | S35: 0.7 | T35: 0.73541667 | U35: =(S35-T34)*24*60 -> 6 | V35: =(T35-S35)*24*60 -> 51 | AA35: =M35-J35 -> -108.23529 | AB35: =M35/J35 -> 0.95490196
A36: 新豐8線 | B36: 三明治 | C36: 雞蛋沙拉三明治 | E36: 25 | F36: 2260 | G36: =E36*F36 -> 56500 | I36: 15 | J36: 2400 | K36: =J36/I36 -> 160 | L36: 15 | M36: =F36/V36*60 -> 2298.3051 | N36: =M36/L36 -> 153.22034 | O36: =L36-I36 -> 0 | P36: =N36-K36 -> -6.779661 | Q36: =N36/K36 -> 0.95762712 | S36: 0.73888889 | T36: 0.77986111 | U36: =(S36-T35)*24*60 -> 5 | V36: =(T36-S36)*24*60 -> 59 | AA36: =M36-J36 -> -101.69492 | AB36: =M36/J36 -> 0.95762712
A37: 新豐8線 | B37: 平均 | I37: 18.181818 | J37: 2400 | K37: =J37/I37 -> 132 | L37: 18.181818 | M37: =AVERAGE(M26:M36) -> 2296.0026 | N37: =M37/L37 -> 126.28014 | O37: =L37-I37 -> 0 | P37: =N37-K37 -> -5.7198574 | Q37: =N37/K37 -> 0.95666775 | AA37: =M37-J37 -> -103.99741 | AB37: =M37/J37 -> 0.95666775
A38: 新豐9線 | B38: 三明治 | C38: 鮪魚起司溏心蛋三明治 | E38: 26.2 | F38: 5000 | G38: =E38*F38 -> 131000 | H38: 2 | I38: 18 | J38: 2400 | K38: =J38/I38 -> 133.33333 | L38: 18 | M38: =F38/V38*60 -> 2290.0763 | N38: =M38/L38 -> 127.22646 | O38: =L38-I38 -> 0 | P38: =N38-K38 -> -6.1068702 | Q38: =N38/K38 -> 0.95419847 | R38: =Q46 -> 0.95681402 | S38: 0.083333333 | T38: 0.17430556 | V38: =(T38-S38)*24*60 -> 131 | W38: =T38 -> 0.17430556 | X38: =S39 -> 0.19166667 | AA38: =M38-J38 -> -109.92366 | AB38: =M38/J38 -> 0.95419847 | AC38: =AB46 -> 0.95681402
A39: 新豐9線 | B39: 三明治 | C39: 醬燒烤雞三明治 | E39: 26.39 | F39: 4200 | G39: =E39*F39 -> 110838 | H39: 2 | I39: 19 | J39: 2400 | K39: =J39/I39 -> 126.31579 | L39: 19 | M39: =F39/V39*60 -> 2290.9091 | N39: =M39/L39 -> 120.57416 | O39: =L39-I39 -> 0 | P39: =N39-K39 -> -5.7416268 | Q39: =N39/K39 -> 0.95454545 | S39: 0.19166667 | T39: 0.26805556 | U39: =(S39-T38)*24*60 -> 25 | V39: =(T39-S39)*24*60 -> 110 | AA39: =M39-J39 -> -109.09091 | AB39: =M39/J39 -> 0.95454545
A40: 新豐9線 | B40: 三明治 | C40: 經典火腿玉米蛋三明治 | E40: 24.43 | F40: 5400 | G40: =E40*F40 -> 131922 | H40: 2 | I40: 15 | J40: 2400 | K40: =J40/I40 -> 160 | L40: 15 | M40: =F40/V40*60 -> 2297.8723 | N40: =M40/L40 -> 153.19149 | O40: =L40-I40 -> 0 | P40: =N40-K40 -> -6.8085106 | Q40: =N40/K40 -> 0.95744681 | S40: 0.27291667 | T40: 0.37083333 | U40: =(S40-T39)*24*60 -> 7 | V40: =(T40-S40)*24*60 -> 141 | AA40: =M40-J40 -> -102.12766 | AB40: =M40/J40 -> 0.95744681
...

Sheet 0928
B1: 屏榮 新豐廠組合室生產人時性分析
B3: 日期 | C3: =TEXT('0928 4度C'!A2,"yyyy.mm.ddaaaa") -> 2025.09.28星期日 | E3: 訂單量 | F3: ='0928 4度C'!D1 -> 145605 | H3: 營業額 | I3: ='0928 4度C'!F1 -> 4811205.6
B4: 人時性 | C4: 項目 | E4: ➀ | G4: ➁ | I4: ➂
C5: 組合室 | E5: 全溫層 | G5: 4度C-各編組展開 | I5: ③三明治-各編組展開
C6: 排關平均 | E6: =AVERAGE(D13:M13) -> 149.55969 | F6: =AVERAGE(D27:O27,D13:J13) -> 154.31767 | G6: =AVERAGE(D13:J13) -> 154.31767 | I6: =AVERAGE(K13:M13) -> 138.45775
C7: 實績平均 | E7: =AVERAGE(D14:M14) -> 143.24769 | F7: =AVERAGE(D28:O28,D14:J14) -> 147.90015 | G7: =AVERAGE(D14:J14) -> 147.90015 | I7: =AVERAGE(K14:M14) -> 132.39194
C8: 達成率平均 | E8: =AVERAGE(D15:M15) -> 0.95761807 | F8: =AVERAGE(D15:J15,D29:O29) -> 0.95820715 | G8: =AVERAGE(D15:J15) -> 0.95820715 | I8: =AVERAGE(K15:M15) -> 0.95624354 | K8: ※現行日本鮮食廠以達成率80%為基本(即為現行KPI)
B10: 溫層 | D10: ➁4度C-各編組展開 | K10: ③三明治-各編組展開
B11: 編組 | D11: 1 | E11: 2 | F11: 3 | G11: 4 | H11: 5 | I11: 6 | J11: 7 | K11: 1 | L11: 2 | M11: 3
D12: 新豐6線 | E12: 新豐2線 | F12: 新豐5線 | G12: 新豐7線 | H12: 新豐3線 | I12: 新豐1線 | J12: 新豐10線 | K12: 新豐8線 | L12: 新豐9線 | M12: 新豐4線
B13: 人時性 | C13: 排關 | D13: =SUMIFS('0928 4度C'!$K:$K,'0928 4度C'!$A:$A,"新豐6線",'0928 4度C'!$B:$B,"平均") -> 125 | E13: =SUMIFS('0928 4度C'!$K:$K,'0928 4度C'!$A:$A,"新豐2線",'0928 4度C'!$B:$B,"平均") -> 88.235294 | F13: =SUMIFS('0928 4度C'!$K:$K,'0928 4度C'!$A:$A,"新豐5線",'0928 4度C'!$B:$B,"平均") -> 88.541667 | G13: =SUMIFS('0928 4度C'!$K:$K,'0928 4度C'!$A:$A,"新豐7線",'0928 4度C'!$B:$B,"平均") -> 119.04762 | H13: =SUMIFS('0928 4度C'!$K:$K,'0928 4度C'!$A:$A,"新豐3線",'0928 4度C'!$B:$B,"平均") -> 310.34483 | I13: =SUMIFS('0928 4度C'!$K:$K,'0928 4度C'!$A:$A,"新豐1線",'0928 4度C'!$B:$B,"平均") -> 117.34694 | J13: =SUMIFS('0928 4度C'!$K:$K,'0928 4度C'!$A:$A,"新豐10線",'0928 4度C'!$B:$B,"平均") -> 231.70732 | K13: =SUMIFS('0928 4度C'!$K:$K,'0928 4度C'!$A:$A,"新豐8線",'0928 4度C'!$B:$B,"平均") -> 133.33333 | L13: =SUMIFS('0928 4度C'!$K:$K,'0928 4度C'!$A:$A,"新豐9線",'0928 4度C'!$B:$B,"平均") -> 145.45455 | M13: =SUMIFS('0928 4度C'!$K:$K,'0928 4度C'!$A:$A,"新豐4線",'0928 4度C'!$B:$B,"平均") -> 136.58537
C14: 實績 | D14: =SUMIFS('0928 4度C'!$N:$N,'0928 4度C'!$A:$A,"新豐6線",'0928 4度C'!$B:$B,"平均") -> 120.08964 | E14: =SUMIFS('0928 4度C'!$N:$N,'0928 4度C'!$A:$A,"新豐2線",'0928 4度C'!$B:$B,"平均") -> 84.324324 | F14: =SUMIFS('0928 4度C'!$N:$N,'0928 4度C'!$A:$A,"新豐5線",'0928 4度C'!$B:$B,"平均") -> 84.775048 | G14: =SUMIFS('0928 4度C'!$N:$N,'0928 4度C'!$A:$A,"新豐7線",'0928 4度C'!$B:$B,"平均") -> 113.85188 | H14: =SUMIFS('0928 4度C'!$N:$N,'0928 4度C'!$A:$A,"新豐3線",'0928 4度C'!$B:$B,"平均") -> 297.12685 | I14: =SUMIFS('0928 4度C'!$N:$N,'0928 4度C'!$A:$A,"新豐1線",'0928 4度C'!$B:$B,"平均") -> 112.57112 | J14: =SUMIFS('0928 4度C'!$N:$N,'0928 4度C'!$A:$A,"新豐10線",'0928 4度C'!$B:$B,"平均") -> 222.56222 | K14: =SUMIFS('0928 4度C'!$N:$N,'0928 4度C'!$A:$A,"新豐8線",'0928 4度C'!$B:$B,"平均") -> 127.72044 | L14: =SUMIFS('0928 4度C'!$N:$N,'0928 4度C'!$A:$A,"新豐9線",'0928 4度C'!$B:$B,"平均") -> 138.81491 | M14: =SUMIFS('0928 4度C'!$N:$N,'0928 4度C'!$A:$A,"新豐4線",'0928 4度C'!$B:$B,"平均") -> 130.64046
C15: 達成率 | D15: =D14/D13 -> 0.96071709 | E15: =E14/E13 -> 0.95567568 | F15: =F14/F13 -> 0.95745937 | G15: =G14/G13 -> 0.95635578 | H15: =H14/H13 -> 0.95740875 | I15: =I14/I13 -> 0.95930174 | J15: =J14/J13 -> 0.96053169 | K15: =K14/K13 -> 0.95790331 | ... M15: =M14/M13 -> 0.95647482
B16: 作業 時間 | C16: 開始 | D16: =VLOOKUP("新豐6線",'0928 4度C'!$A:$T,19,0) -> 0.70833333 | E16: =VLOOKUP("新豐2線",'0928 4度C'!$A:$T,19,0) -> 0.20833333 | F16: =VLOOKUP("新豐5線",'0928 4度C'!$A:$T,19,0) -> 0.20833333 | G16: =VLOOKUP("新豐7線",'0928 4度C'!$A:$T,19,0) -> 0.20833333 | H16: =VLOOKUP("新豐3線",'0928 4度C'!$A:$T,19,0) -> 0.083333333 | I16: =VLOOKUP("新豐1線",'0928 4度C'!$A:$T,19,0) -> 0.29166667 | J16: =VLOOKUP("新豐10線",'0928 4度C'!$A:$T,19,0) -> 0.20833333 | K16: =VLOOKUP("新豐8線",'0928 4度C'!$A:$T,19,0) -> 0.083333333 | L16: =VLOOKUP("新豐9線",'0928 4度C'!$A:$T,19,0) -> 0.083333333 | M16: =VLOOKUP("新豐4線",'0928 4度C'!$A:$T,19,0) -> 0.083333333
C17: 結束 | D17: =LOOKUP(2,1/(('0928 4度C'!$A:$A="新豐6線")*('0928 4度C'!$T:$T<>"")),'0928 4度C'!$T:$T) -> 0.825 | E17: =LOOKUP(2,1/(('0928 4度C'!$A:$A="新豐2線")*('0928 4度C'!$T:$T<>"")),'0928 4度C'!$T:$T) -> 0.3625 | F17: =LOOKUP(2,1/(('0928 4度C'!$A:$A="新豐5線")*('0928 4度C'!$T:$T<>"")),'0928 4度C'!$T:$T) -> 0.83819444 | G17: =LOOKUP(2,1/(('0928 4度C'!$A:$A="新豐7線")*('0928 4度C'!$T:$T<>"")),'0928 4度C'!$T:$T) -> 0.775 | H17: =LOOKUP(2,1/(('0928 4度C'!$A:$A="新豐3線")*('0928 4度C'!$T:$T<>"")),'0928 4度C'!$T:$T) -> 0.425 | I17: =LOOKUP(2,1/(('0928 4度C'!$A:$A="新豐1線")*('0928 4度C'!$T:$T<>"")),'0928 4度C'!$T:$T) -> 0.84027778 | J17: =LOOKUP(2,1/(('0928 4度C'!$A:$A="新豐10線")*('0928 4度C'!$T:$T<>"")),'0928 4度C'!$T:$T) -> 0.39513889 | K17: =LOOKUP(2,1/(('0928 4度C'!$A:$A="新豐8線")*('0928 4度C'!$T:$T<>"")),'0928 4度C'!$T:$T) -> 0.60416667 | L17: =LOOKUP(2,1/(('0928 4度C'!$A:$A="新豐9線")*('0928 4度C'!$T:$T<>"")),'0928 4度C'!$T:$T) -> 0.54513889 | M17: =LOOKUP(2,1/(('0928 4度C'!$A:$A="新豐4線")*('0928 4度C'!$T:$T<>"")),'0928 4度C'!$T:$T) -> 0.53680556
B18: 配置人數 | D18: =SUMIFS('0928 4度C'!$I:$I,'0928 4度C'!$A:$A,"新豐6線",'0928 4度C'!$B:$B,"平均") -> 16 | E18: =SUMIFS('0928 4度C'!$I:$I,'0928 4度C'!$A:$A,"新豐2線",'0928 4度C'!$B:$B,"平均") -> 17 | F18: =SUMIFS('0928 4度C'!$I:$I,'0928 4度C'!$A:$A,"新豐5線",'0928 4度C'!$B:$B,"平均") -> 19.2 | G18: =SUMIFS('0928 4度C'!$I:$I,'0928 4度C'!$A:$A,"新豐7線",'0928 4度C'!$B:$B,"平均") -> 16.8 | H18: =SUMIFS('0928 4度C'!$I:$I,'0928 4度C'!$A:$A,"新豐3線",'0928 4度C'!$B:$B,"平均") -> 9.6666667 | I18: =SUMIFS('0928 4度C'!$I:$I,'0928 4度C'!$A:$A,"新豐1線",'0928 4度C'!$B:$B,"平均") -> 16.333333 | J18: =SUMIFS('0928 4度C'!$I:$I,'0928 4度C'!$A:$A,"新豐10線",'0928 4度C'!$B:$B,"平均") -> 10.25 | K18: =SUMIFS('0928 4度C'!$I:$I,'0928 4度C'!$A:$A,"新豐8線",'0928 4度C'!$B:$B,"平均") -> 18 | L18: =SUMIFS('0928 4度C'!$I:$I,'0928 4度C'!$A:$A,"新豐9線",'0928 4度C'!$B:$B,"平均") -> 16.5 | M18: =SUMIFS('0928 4度C'!$I:$I,'0928 4度C'!$A:$A,"新豐4線",'0928 4度C'!$B:$B,"平均") -> 17.571429
B19: 主要應用設備 | D19: ET-55 | E19: 熱縮爐 | F19: L型包裝機 | G19: L型包裝機 | H19: 伺服包裝機 | I19: ET-55 | J19: 伺服包裝機 | K19: 三明治包裝機 | L19: 三明治包裝機 | M19: 三明治包裝機
B20: 次要應用設備 | F20: 圓盤機 | G20: ET-55
B21: 備註 | E21: 握沙拉 | F21: 共用L型包裝機 | H21: 調理麵包 | I21: 炒飯+沙拉 | J21: 調理麵包

Sheet 0928 4度C
A1: 新豐廠四度C日報分析 | C1: 總生產量 | D1: =SUM(F5:F63) -> 145605 | E1: 營業額 | F1: =SUM(G5:G63) -> 4811205.6 | G1: 出勤人數 | H1: =L8+L10+L43+L50+L16+L55+L31+L36+L22+L63 -> 157.32143 | I1: 產線配置圖 | L1: 生產實績 | O1: 人時性差異分析 | S1: 日報登錄 | Y1: 分析說明 | AA1: 產能差異分析
A2: 45928 | B2: 星期日 | C2: 人時性 | D2: =AVERAGE(N8,N10,N43,N50,N16,N55,N22,N31,N36,N63) -> 143.24769 | E2: 平均廠價 | F2: =F1/D1 -> 33.04286 | G2: 多次生產數 | H2: =COUNT(H5:H62) -> 1
A3: 線別 | B3: 品類 | C3: 品名 | E3: 廠價 | F3: 生產量 | G3: 營收 | H3: 多次 生產 | I3: 人數 | J3: 產能/時 | K3: 人時性 | L3: 人數 | M3: 產能/時 | N3: 人時性 | O3: 人數 | P3: 人時性 | Q3: 達成率 | R3: 達成率平均 | S3: 生產時間 | U3: 換線、休息/分 | V3: 稼動時間/分 | W3: 休息時間 | Y3: (新豐回填) | AA3: 產能/時 | AB3: 達成率 | AC3: 達成率平均
S4: 開始 | T4: 結束 | W4: 開始 | X4: 結束
A5: 新豐6線 | B5: 微波主食 | C5: 二配煸椒烘蛋飯 | E5: 46.93 | F5: 901 | G5: =E5*F5 -> 42283.93 | I5: 16 | J5: 2000 | K5: =J5/I5 -> 125 | L5: 16 | M5: =F5/V5*60 -> 1930.7143 | N5: =M5/L5 -> 120.66964 | O5: =L5-I5 -> 0 | P5: =N5-K5 -> -4.3303571 | Q5: =N5/K5 -> 0.96535714 | R5: =Q8 -> 0.96071709 | S5: 0.70833333 | T5: 0.72777778 | V5: =(T5-S5)*24*60 -> 28 | AA5: =M5-J5 -> -69.285714 | AB5: =M5/J5 -> 0.96535714 | AC5: =AB8 -> 0.96071709
A6: 新豐6線 | B6: 微波主食 | C6: 二配川味麻婆燒豆腐燴飯 | E6: 50.49 | F6: 2171 | G6: =E6*F6 -> 109613.79 | I6: 15 | J6: 2000 | K6: =J6/I6 -> 133.33333 | L6: 15 | M6: =F6/V6*60 -> 1915.5882 | N6: =M6/L6 -> 127.70588 | O6: =L6-I6 -> 0 | P6: =N6-K6 -> -5.627451 | Q6: =N6/K6 -> 0.95779412 | S6: 0.73194444 | T6: 0.77916667 | U6: =(S6-T5)*24*60 -> 6 | V6: =(T6-S6)*24*60 -> 68 | AA6: =M6-J6 -> -84.411765 | AB6: =M6/J6 -> 0.95779412
A7: 新豐6線 | B7: 微波主食 | C7: 二配港式香滑嫩蛋牛肉燴飯 | E7: 50.67 | F7: 1918 | G7: =E7*F7 -> 97185.06 | I7: 17 | J7: 2000 | K7: =J7/I7 -> 117.64706 | L7: 17 | M7: =F7/V7*60 -> 1918 | N7: =M7/L7 -> 112.82353 | O7: =L7-I7 -> 0 | P7: =N7-K7 -> -4.8235294 | Q7: =N7/K7 -> 0.959 | S7: 0.78333333 | T7: 0.825 | U7: =(S7-T6)*24*60 -> 6 | V7: =(T7-S7)*24*60 -> 60 | AA7: =M7-J7 -> -82 | AB7: =M7/J7 -> 0.959
A8: 新豐6線 | B8: 平均 | I8: 16 | J8: 2000 | K8: =J8/I8 -> 125 | L8: 16 | M8: =AVERAGE(M5:M7) -> 1921.4342 | N8: =M8/L8 -> 120.08964 | O8: =L8-I8 -> 0 | P8: =N8-K8 -> -4.9103641 | Q8: =N8/K8 -> 0.96071709 | AA8: =M8-J8 -> -78.565826 | AB8: =M8/J8 -> 0.96071709
A9: 新豐2線 | B9: 沙拉 | C9: 青檸烤雞握沙拉(113年) | E9: 39.8 | F9: 5304 | G9: =E9*F9 -> 211099.2 | I9: 17 | J9: 1500 | K9: =J9/I9 -> 88.235294 | L9: 17 | M9: =F9/V9*60 -> 1433.5135 | N9: =M9/L9 -> 84.324324 | O9: =L9-I9 -> 0 | P9: =N9-K9 -> -3.9109698 | Q9: =N9/K9 -> 0.95567568 | R9: =Q10 -> 0.95567568 | S9: 0.20833333 | T9: 0.3625 | V9: =(T9-S9)*24*60 -> 222 | AA9: =M9-J9 -> -66.486486 | AB9: =M9/J9 -> 0.95567568 | AC9: =AB10 -> 0.95567568
A10: 新豐2線 | B10: 平均 | I10: 17 | J10: 1500 | K10: =J10/I10 -> 88.235294 | L10: 17 | M10: =AVERAGE(M9:M9) -> 1433.5135 | N10: =M10/L10 -> 84.324324 | O10: =L10-I10 -> 0 | P10: =N10-K10 -> -3.9109698 | Q10: =N10/K10 -> 0.95567568 | AA10: =M10-J10 -> -66.486486 | AB10: =M10/J10 -> 0.95567568
A11: 新豐5線 | B11: 小吃 | C11: 剝皮辣椒雞湯 | E11: 41 | F11: 1827 | G11: =E11*F11 -> 74907 | I11: 26 | J11: 1500 | K11: =J11/I11 -> 57.692308 | L11: 26 | M11: =F11/V11*60 -> 1442.3684 | N11: =M11/L11 -> 55.475709 | O11: =L11-I11 -> 0 | P11: =N11-K11 -> -2.2165992 | Q11: =N11/K11 -> 0.96157895 | R11: =Q16 -> 0.95745937 | S11: 0.20833333 | T11: 0.26111111 | V11: =(T11-S11)*24*60 -> 76 | AA11: =M11-J11 -> -57.631579 | AB11: =M11/J11 -> 0.96157895 | AC11: =AB16 -> 0.95745937
A12: 新豐5線 | B12: 沙拉 | C12: 青醬優格雞肉握沙拉(113年) | E12: 39.62 | F12: 3764 | G12: =E12*F12 -> 149129.68 | I12: 19 | J12: 1500 | K12: =J12/I12 -> 78.947368 | L12: 19 | M12: =F12/V12*60 -> 1429.3671 | N12: =M12/L12 -> 75.229847 | O12: =L12-I12 -> 0 | P12: =N12-K12 -> -3.7175217 | Q12: =N12/K12 -> 0.95291139 | S12: 0.26458333 | T12: 0.37430556 | U12: =IF(S12=TIME(17,0,0),"",(S12-T11)*24*60) -> 5 | V12: =(T12-S12)*24*60 -> 158 | AA12: =M12-J12 -> -70.632911 | AB12: =M12/J12 -> 0.95291139
A13: 新豐5線 | B13: 沙拉 | C13: 韓式泡菜豆腐握沙拉 | E13: 39.36 | F13: 2688 | G13: =E13*F13 -> 105799.68 | I13: 20 | J13: 1500 | K13: =J13/I13 -> 75 | L13: 20 | M13: =F13/V13*60 -> 1440 | N13: =M13/L13 -> 72 | O13: =L13-I13 -> 0 | P13: =N13-K13 -> -3 | Q13: =N13/K13 -> 0.96 | S13: 0.37777778 | T13: 0.45555556 | U13: =IF(S13=TIME(17,0,0),"",(S13-T12)*24*60) -> 5 | V13: =(T13-S13)*24*60 -> 112 | AA13: =M13-J13 -> -60 | AB13: =M13/J13 -> 0.96
A14: 新豐5線 | B14: 微波主食 | C14: 二配金咖哩濃厚辛辣咖哩飯 | E14: 50.98 | F14: 2773 | G14: =E14*F14 -> 141367.54 | I14: 16 | J14: 2000 | K14: =J14/I14 -> 125 | L14: 16 | M14: =F14/V14*60 -> 1912.4138 | N14: =M14/L14 -> 119.52586 | O14: =L14-I14 -> 0 | P14: =N14-K14 -> -5.4741379 | Q14: =N14/K14 -> 0.9562069 | S14: 0.70833333 | T14: 0.76875 | U14: =IF(S14=TIME(17,0,0),"",(S14-T13)*24*60) | V14: =(T14-S14)*24*60 -> 87 | AA14: =M14-J14 -> -87.586207 | AB14: =M14/J14 -> 0.9562069
A15: 新豐5線 | B15: 微波主食 | C15: 二配金咖哩果香甘口咖哩飯 | E15: 50.92 | F15: 2999 | G15: =E15*F15 -> 152709.08 | I15: 15 | J15: 2000 | K15: =J15/I15 -> 133.33333 | L15: 15 | M15: =F15/V15*60 -> 1914.2553 | N15: =M15/L15 -> 127.61702 | O15: =L15-I15 -> 0 | P15: =N15-K15 -> -5.7163121 | Q15: =N15/K15 -> 0.95712766 | S15: 0.77291667 | T15: 0.83819444 | U15: =IF(S15=TIME(17,0,0),"",(S15-T14)*24*60) -> 6 | V15: =(T15-S15)*24*60 -> 94 | AA15: =M15-J15 -> -85.744681 | AB15: =M15/J15 -> 0.95712766
A16: 新豐5線 | B16: 平均 | I16: 19.2 | J16: 1700 | K16: =J16/I16 -> 88.541667 | L16: 19.2 | M16: =AVERAGE(M11:M15) -> 1627.6809 | N16: =M16/L16 -> 84.775048 | O16: =L16-I16 -> 0 | P16: =N16-K16 -> -3.7666185 | Q16: =N16/K16 -> 0.95745937 | AA16: =M16-J16 -> -72.319076 | AB16: =M16/J16 -> 0.95745937
A17: 新豐7線 | B17: 小吃 | C17: 古早味炒炊粉 | E17: 43.14 | F17: 1175 | G17: =E17*F17 -> 50689.5 | I17: 17 | J17: 2000 | K17: =J17/I17 -> 117.64706 | L17: 17 | M17: =F17/V17*60 -> 1905.4054 | N17: =M17/L17 -> 112.08267 | O17: =L17-I17 -> 0 | P17: =N17-K17 -> -5.5643879 | Q17: =N17/K17 -> 0.9527027 | R17: =Q22 -> 0.95635578 | S17: 0.20833333 | T17: 0.23402778 | V17: =(T17-S17)*24*60 -> 37 | AA17: =M17-J17 -> -94.594595 | AB17: =M17/J17 -> 0.9527027 | AC17: =AB22 -> 0.95635578
A18: 新豐7線 | B18: 微波主食 | C18: 鐵板滑蛋炸豬排丼 | E18: 57.73 | F18: 2268 | G18: =E18*F18 -> 130931.64 | I18: 15 | J18: 2000 | K18: =J18/I18 -> 133.33333 | L18: 15 | M18: =F18/V18*60 -> 1916.6197 | N18: =M18/L18 -> 127.77465 | O18: =L18-I18 -> 0 | P18: =N18-K18 -> -5.5586854 | Q18: =N18/K18 -> 0.95830986 | S18: 0.2375 | T18: 0.28680556 | U18: =IF(S18=TIME(17,0,0),"",(S18-T17)*24*60) -> 5 | V18: =(T18-S18)*24*60 -> 71 | AA18: =M18-J18 -> -83.380282 | AB18: =M18/J18 -> 0.95830986
A19: 新豐7線 | B19: 微波主食 | C19: 極上炙烤親子丼 | E19: 53.68 | F19: 1653 | G19: =E19*F19 -> 88733.04 | I19: 16 | J19: 2000 | K19: =J19/I19 -> 125 | L19: 16 | M19: =F19/V19*60 -> 1907.3077 | N19: =M19/L19 -> 119.20673 | O19: =L19-I19 -> 0 | P19: =N19-K19 -> -5.7932692 | Q19: =N19/K19 -> 0.95365385 | S19: 0.29236111 | T19: 0.32847222 | U19: =IF(S19=TIME(17,0,0),"",(S19-T18)*24*60) -> 8 | V19: =(T19-S19)*24*60 -> 52 | AA19: =M19-J19 -> -92.692308 | AB19: =M19/J19 -> 0.95365385
A20: 新豐7線 | B20: 微波主食 | C20: 白味噌壽喜燒飯 | E20: 53.27 | F20: 1603 | G20: =E20*F20 -> 85391.81 | I20: 17 | J20: 2000 | K20: =J20/I20 -> 117.64706 | L20: 17 | M20: =F20/V20*60 -> 1923.6 | N20: =M20/L20 -> 113.15294 | O20: =L20-I20 -> 0 | P20: =N20-K20 -> -4.4941176 | Q20: =N20/K20 -> 0.9618 | S20: 0.33402778 | T20: 0.36875 | U20: =IF(S20=TIME(17,0,0),"",(S20-T19)*24*60) -> 8 | V20: =(T20-S20)*24*60 -> 50 | AA20: =M20-J20 -> -76.4 | AB20: =M20/J20 -> 0.9618
A21: 新豐7線 | B21: 微波主食 | C21: 二配美味蟹煲 | E21: 54.09 | F21: 3057 | G21: =E21*F21 -> 165353.13 | I21: 19 | J21: 2000 | K21: =J21/I21 -> 105.26316 | L21: 19 | M21: =F21/V21*60 -> 1910.625 | N21: =M21/L21 -> 100.55921 | O21: =L21-I21 -> 0 | P21: =N21-K21 -> -4.7039474 | Q21: =N21/K21 -> 0.9553125 | S21: 0.70833333 | T21: 0.775 | U21: =IF(S21=TIME(17,0,0),"",(S21-T20)*24*60) | V21: =(T21-S21)*24*60 -> 96 | AA21: =M21-J21 -> -89.375 | AB21: =M21/J21 -> 0.9553125
A22: 新豐7線 | B22: 平均 | I22: 16.8 | J22: 2000 | K22: =J22/I22 -> 119.04762 | L22: 16.8 | M22: =AVERAGE(M17:M21) -> 1912.7116 | N22: =M22/L22 -> 113.85188 | O22: =L22-I22 -> 0 | P22: =N22-K22 -> -5.1957403 | Q22: =N22/K22 -> 0.95635578 | AA22: =M22-J22 -> -87.288437 | AB22: =M22/J22 -> 0.95635578
A23: 新豐8線 | B23: 三明治 | C23: 經典總匯三明治 | E23: 26.2 | F23: 3497 | G23: =E23*F23 -> 91621.4 | I23: 20 | J23: 2400 | K23: =J23/I23 -> 120 | L23: 20 | M23: =F23/V23*60 -> 2305.7143 | N23: =M23/L23 -> 115.28571 | O23: =L23-I23 -> 0 | P23: =N23-K23 -> -4.7142857 | Q23: =N23/K23 -> 0.96071429 | R23: =Q31 -> 0.95790331 | S23: 0.083333333 | T23: 0.14652778 | V23: =(T23-S23)*24*60 -> 91 | W23: =T23 -> 0.14652778 | X23: =S24 -> 0.16666667 | AA23: =M23-J23 -> -94.285714 | AB23: =M23/J23 -> 0.96071429 | AC23: =AB31 -> 0.95790331
