Workbook

Sheet 1231
B1: 屏榮 新豐廠組合室生產人時性分析
B3: 日期 | C3: =TEXT('1231 4度C'!A2,"yyyy.mm.ddaaaa") -> 2025.12.31星期三 | E3: 訂單量 | F3: ='1231 4度C'!D1 -> 128248 | H3: 營業額 | I3: ='1231 4度C'!F1 -> 4527463.8
B4: 人時性 | C4: 項目 | E4: ➀ | G4: ➁ | I4: ➂
C5: 組合室 | E5: 全溫層 | G5: 4度C-各編組展開 | I5: ③三明治-各編組展開
C6: 排關平均 | E6: =AVERAGE(D13:M13) -> 147.54091 | F6: =AVERAGE(D27:O27,D13:J13) -> 151.35637 | G6: =AVERAGE(D13:J13) -> 151.35637 | I6: =AVERAGE(K13:M13) -> 138.63817
C7: 實績平均 | E7: =AVERAGE(D14:M14) -> 140.96861 | F7: =AVERAGE(D28:O28,D14:J14) -> 144.57472 | G7: =AVERAGE(D14:J14) -> 144.57472 | I7: =AVERAGE(K14:M14) -> 132.55435
C8: 達成率平均 | E8: =AVERAGE(D15:M15) -> 0.95275972 | F8: =AVERAGE(D15:J15,D29:O29) -> 0.95132001 | G8: =AVERAGE(D15:J15) -> 0.95132001 | I8: =AVERAGE(K15:M15) -> 0.95611905 | K8: ※現行日本鮮食廠以達成率80%為基本(即為現行KPI)
B10: 溫層 | D10: ➁4度C-各編組展開 | K10: ③三明治-各編組展開
B11: 編組 | D11: 1 | E11: 2 | F11: 3 | G11: 4 | H11: 5 | I11: 6 | J11: 7 | K11: 1 | L11: 2 | M11: 3
D12: 新豐6線 | E12: 新豐2線 | F12: 新豐5線 | G12: 新豐7線 | H12: 新豐3線 | I12: 新豐1線 | J12: 新豐10線 | K12: 新豐8線 | L12: 新豐9線 | M12: 新豐4線
B13: 人時性 | C13: 排關 | D13: =SUMIFS('1231 4度C'!$K:$K,'1231 4度C'!$A:$A,"新豐6線",'1231 4度C'!$B:$B,"平均") -> 115.38462 | E13: =SUMIFS('1231 4度C'!$K:$K,'1231 4度C'!$A:$A,"新豐2線",'1231 4度C'!$B:$B,"平均") -> 83.333333 | F13: =SUMIFS('1231 4度C'!$K:$K,'1231 4度C'!$A:$A,"新豐5線",'1231 4度C'!$B:$B,"平均") -> 108.20896 | G13: =SUMIFS('1231 4度C'!$K:$K,'1231 4度C'!$A:$A,"新豐7線",'1231 4度C'!$B:$B,"平均") -> 118.05556 | H13: =SUMIFS('1231 4度C'!$K:$K,'1231 4度C'!$A:$A,"新豐3線",'1231 4度C'!$B:$B,"平均") -> 235.29412 | I13: =SUMIFS('1231 4度C'!$K:$K,'1231 4度C'!$A:$A,"新豐1線",'1231 4度C'!$B:$B,"平均") -> 104.57516 | J13: =SUMIFS('1231 4度C'!$K:$K,'1231 4度C'!$A:$A,"新豐10線",'1231 4度C'!$B:$B,"平均") -> 294.64286 | K13: =SUMIFS('1231 4度C'!$K:$K,'1231 4度C'!$A:$A,"新豐8線",'1231 4度C'!$B:$B,"平均") -> 131.86813 | L13: =SUMIFS('1231 4度C'!$K:$K,'1231 4度C'!$A:$A,"新豐9線",'1231 4度C'!$B:$B,"平均") -> 137.70492 | M13: =SUMIFS('1231 4度C'!$K:$K,'1231 4度C'!$A:$A,"新豐4線",'1231 4度C'!$B:$B,"平均") -> 146.34146
C14: 實績 | D14: =SUMIFS('1231 4度C'!$N:$N,'1231 4度C'!$A:$A,"新豐6線",'1231 4度C'!$B:$B,"平均") -> 111.25531 | E14: =SUMIFS('1231 4度C'!$N:$N,'1231 4度C'!$A:$A,"新豐2線",'1231 4度C'!$B:$B,"平均") -> 79.764497 | F14: =SUMIFS('1231 4度C'!$N:$N,'1231 4度C'!$A:$A,"新豐5線",'1231 4度C'!$B:$B,"平均") -> 104.26674 | G14: =SUMIFS('1231 4度C'!$N:$N,'1231 4度C'!$A:$A,"新豐7線",'1231 4度C'!$B:$B,"平均") -> 113.30181 | H14: =SUMIFS('1231 4度C'!$N:$N,'1231 4度C'!$A:$A,"新豐3線",'1231 4度C'!$B:$B,"平均") -> 225.53905 | I14: =SUMIFS('1231 4度C'!$N:$N,'1231 4度C'!$A:$A,"新豐1線",'1231 4度C'!$B:$B,"平均") -> 92.964319 | J14: =SUMIFS('1231 4度C'!$N:$N,'1231 4度C'!$A:$A,"新豐10線",'1231 4度C'!$B:$B,"平均") -> 284.93132 | K14: =SUMIFS('1231 4度C'!$N:$N,'1231 4度C'!$A:$A,"新豐8線",'1231 4度C'!$B:$B,"平均") -> 126.23667 | L14: =SUMIFS('1231 4度C'!$N:$N,'1231 4度C'!$A:$A,"新豐9線",'1231 4度C'!$B:$B,"平均") -> 131.40273 | M14: =SUMIFS('1231 4度C'!$N:$N,'1231 4度C'!$A:$A,"新豐4線",'1231 4度C'!$B:$B,"平均") -> 140.02365
C15: 達成率 | D15: =D14/D13 -> 0.96421271 | E15: =E14/E13 -> 0.95717396 | F15: =F14/F13 -> 0.9635685 | G15: =G14/G13 -> 0.959733 | H15: =H14/H13 -> 0.95854096 | I15: =I14/I13 -> 0.8889713 | J15: =J14/J13 -> 0.96703964 | K15: =K14/K13 -> 0.95729478 | ... M15: =M14/M13 -> 0.95682829
B16: 作業 時間 | C16: 開始 | D16: =VLOOKUP("新豐6線",'1231 4度C'!$A:$T,19,0) -> 0.70833333 | E16: =VLOOKUP("新豐2線",'1231 4度C'!$A:$T,19,0) -> 0.16666667 | F16: =VLOOKUP("新豐5線",'1231 4度C'!$A:$T,19,0) -> 0.20833333 | G16: =VLOOKUP("新豐7線",'1231 4度C'!$A:$T,19,0) -> 0.20833333 | H16: =VLOOKUP("新豐3線",'1231 4度C'!$A:$T,19,0) -> 0.083333333 | I16: =VLOOKUP("新豐1線",'1231 4度C'!$A:$T,19,0) -> 0.20833333 | J16: =VLOOKUP("新豐10線",'1231 4度C'!$A:$T,19,0) -> 0.20833333 | K16: =VLOOKUP("新豐8線",'1231 4度C'!$A:$T,19,0) -> 0.083333333 | L16: =VLOOKUP("新豐9線",'1231 4度C'!$A:$T,19,0) -> 0.083333333 | M16: =VLOOKUP("新豐4線",'1231 4度C'!$A:$T,19,0) -> 0.083333333
C17: 結束 | D17: =LOOKUP(2,1/(('1231 4度C'!$A:$A="新豐6線")*('1231 4度C'!$T:$T<>"")),'1231 4度C'!$T:$T) -> 0.80763889 | E17: =LOOKUP(2,1/(('1231 4度C'!$A:$A="新豐2線")*('1231 4度C'!$T:$T<>"")),'1231 4度C'!$T:$T) -> 0.37569444 | F17: =LOOKUP(2,1/(('1231 4度C'!$A:$A="新豐5線")*('1231 4度C'!$T:$T<>"")),'1231 4度C'!$T:$T) -> 0.89722222 | G17: =LOOKUP(2,1/(('1231 4度C'!$A:$A="新豐7線")*('1231 4度C'!$T:$T<>"")),'1231 4度C'!$T:$T) -> 0.91805556 | H17: =LOOKUP(2,1/(('1231 4度C'!$A:$A="新豐3線")*('1231 4度C'!$T:$T<>"")),'1231 4度C'!$T:$T) -> 0.41527778 | I17: =LOOKUP(2,1/(('1231 4度C'!$A:$A="新豐1線")*('1231 4度C'!$T:$T<>"")),'1231 4度C'!$T:$T) -> 0.90902778 | J17: =LOOKUP(2,1/(('1231 4度C'!$A:$A="新豐10線")*('1231 4度C'!$T:$T<>"")),'1231 4度C'!$T:$T) -> 0.42777778 | K17: =LOOKUP(2,1/(('1231 4度C'!$A:$A="新豐8線")*('1231 4度C'!$T:$T<>"")),'1231 4度C'!$T:$T) -> 0.44583333 | L17: =LOOKUP(2,1/(('1231 4度C'!$A:$A="新豐9線")*('1231 4度C'!$T:$T<>"")),'1231 4度C'!$T:$T) -> 0.39791667 | M17: =LOOKUP(2,1/(('1231 4度C'!$A:$A="新豐4線")*('1231 4度C'!$T:$T<>"")),'1231 4度C'!$T:$T) -> 0.44513889
B18: 配置人數 | D18: =SUMIFS('1231 4度C'!$I:$I,'1231 4度C'!$A:$A,"新豐6線",'1231 4度C'!$B:$B,"平均") -> 17.333333 | E18: =SUMIFS('1231 4度C'!$I:$I,'1231 4度C'!$A:$A,"新豐2線",'1231 4度C'!$B:$B,"平均") -> 18 | F18: =SUMIFS('1231 4度C'!$I:$I,'1231 4度C'!$A:$A,"新豐5線",'1231 4度C'!$B:$B,"平均") -> 16.75 | G18: =SUMIFS('1231 4度C'!$I:$I,'1231 4度C'!$A:$A,"新豐7線",'1231 4度C'!$B:$B,"平均") -> 16 | H18: =SUMIFS('1231 4度C'!$I:$I,'1231 4度C'!$A:$A,"新豐3線",'1231 4度C'!$B:$B,"平均") -> 11.333333 | I18: =SUMIFS('1231 4度C'!$I:$I,'1231 4度C'!$A:$A,"新豐1線",'1231 4度C'!$B:$B,"平均") -> 19.125 | J18: =SUMIFS('1231 4度C'!$I:$I,'1231 4度C'!$A:$A,"新豐10線",'1231 4度C'!$B:$B,"平均") -> 9.3333333 | K18: =SUMIFS('1231 4度C'!$I:$I,'1231 4度C'!$A:$A,"新豐8線",'1231 4度C'!$B:$B,"平均") -> 18.2 | L18: =SUMIFS('1231 4度C'!$I:$I,'1231 4度C'!$A:$A,"新豐9線",'1231 4度C'!$B:$B,"平均") -> 17.428571 | M18: =SUMIFS('1231 4度C'!$I:$I,'1231 4度C'!$A:$A,"新豐4線",'1231 4度C'!$B:$B,"平均") -> 16.4
B19: 主要應用設備 | D19: ET-55 | E19: 熱縮爐 | F19: L型包裝機 | G19: L型包裝機 | H19: 伺服包裝機 | I19: ET-55 | J19: 伺服包裝機 | K19: 三明治包裝機 | L19: 三明治包裝機 | M19: 三明治包裝機
B20: 次要應用設備 | F20: 圓盤機 | G20: ET-55
B21: 備註 | E21: 握沙拉 | F21: 共用L型包裝機 | H21: 調理麵包 | I21: 炒飯+沙拉 | J21: 調理麵包

Sheet 1231 4度C
A1: 新豐廠四度C日報分析 | C1: 總生產量 | D1: =SUM(F5:F73) -> 128248 | E1: 營業額 | F1: =SUM(G5:G73) -> 4527463.8 | G1: 出勤人數 | H1: =L8+L11+L51+L60+L20+L67+L36+L44+L30+L73 -> 159.90357 | I1: 產線配置圖 | L1: 生產實績 | O1: 人時性差異分析 | S1: 日報登錄 | Y1: 分析說明 | AA1: 產能差異分析
A2: 46022 | B2: 星期三 | C2: 人時性 | D2: =AVERAGE(N8,N11,N51,N60,N20,N67,N30,N36,N44,N73) -> 140.96861 | E2: 平均廠價 | F2: =F1/D1 -> 35.302412 | G2: 多次生產數 | H2: =COUNT(H5:H73) -> 3
A3: 線別 | B3: 品類 | C3: 品名 | E3: 廠價 | F3: 生產量 | G3: 營收 | H3: 多次 生產 | I3: 人數 | J3: 產能/時 | K3: 人時性 | L3: 人數 | M3: 產能/時 | N3: 人時性 | O3: 人數 | P3: 人時性 | Q3: 達成率 | R3: 達成率平均 | S3: 生產時間 | U3: 換線、休息/分 | V3: 稼動時間/分 | W3: 休息時間 | Y3: (新豐回填) | AA3: 產能/時 | AB3: 達成率 | AC3: 達成率平均
S4: 開始 | T4: 結束 | W4: 開始 | X4: 結束
A5: 新豐6線 | B5: 微波主食 | C5: 二配港式香滑嫩蛋牛肉燴飯 | E5: 50.67 | F5: 1317 | G5: =E5*F5 -> 66732.39 | I5: 17 | J5: 2000 | K5: =J5/I5 -> 117.64706 | L5: 17 | M5: =F5/V5*60 -> 1927.3171 | N5: =M5/L5 -> 113.37159 | O5: =L5-I5 -> 0 | P5: =N5-K5 -> -4.2754663 | Q5: =N5/K5 -> 0.96365854 | R5: =Q8 -> 0.96421271 | S5: 0.70833333 | T5: 0.73680556 | V5: =(T5-S5)*24*60 -> 41 | AA5: =M5-J5 -> -72.682927 | AB5: =M5/J5 -> 0.96365854 | AC5: =AB8 -> 0.96421271
A6: 新豐6線 | B6: 微波主食 | C6: 二配美味蟹煲 | E6: 54.09 | F6: 1360 | G6: =E6*F6 -> 73562.4 | I6: 19 | J6: 2000 | K6: =J6/I6 -> 105.26316 | L6: 19 | M6: =F6/V6*60 -> 1942.8571 | N6: =M6/L6 -> 102.25564 | O6: =L6-I6 -> 0 | P6: =N6-K6 -> -3.0075188 | Q6: =N6/K6 -> 0.97142857 | S6: 0.74097222 | T6: 0.77013889 | U6: =IF(S6=TIME(17,0,0),"",(S6-T5)*24*60) -> 6 | V6: =(T6-S6)*24*60 -> 42 | AA6: =M6-J6 -> -57.142857 | AB6: =M6/J6 -> 0.97142857
A7: 新豐6線 | B7: 微波主食 | C7: 二配麻油雞燴飯 | E7: 50.29 | F7: 1564 | G7: =E7*F7 -> 78653.56 | I7: 16 | J7: 2000 | K7: =J7/I7 -> 125 | L7: 16 | M7: =F7/V7*60 -> 1915.102 | N7: =M7/L7 -> 119.69388 | O7: =L7-I7 -> 0 | P7: =N7-K7 -> -5.3061224 | Q7: =N7/K7 -> 0.95755102 | S7: 0.77361111 | T7: 0.80763889 | U7: =IF(S7=TIME(17,0,0),"",(S7-T6)*24*60) -> 5 | V7: =(T7-S7)*24*60 -> 49 | AA7: =M7-J7 -> -84.897959 | AB7: =M7/J7 -> 0.95755102
A8: 新豐6線 | B8: 平均 | I8: 17.333333 | J8: 2000 | K8: =J8/I8 -> 115.38462 | L8: 17.333333 | M8: =AVERAGE(M5:M7) -> 1928.4254 | N8: =M8/L8 -> 111.25531 | O8: =L8-I8 -> 0 | P8: =N8-K8 -> -4.1293028 | Q8: =N8/K8 -> 0.96421271 | AA8: =M8-J8 -> -71.574581 | AB8: =M8/J8 -> 0.96421271
A9: 新豐2線 | B9: 沙拉 | C9: 青醬優格雞肉握沙拉(113年) | E9: 39.62 | F9: 2636 | G9: =E9*F9 -> 104438.32 | I9: 19 | J9: 1500 | K9: =J9/I9 -> 78.947368 | L9: 19 | M9: =F9/V9*60 -> 1437.8182 | N9: =M9/L9 -> 75.674641 | O9: =L9-I9 -> 0 | P9: =N9-K9 -> -3.2727273 | Q9: =N9/K9 -> 0.95854545 | R9: =Q11 -> 0.95717396 | S9: 0.16666667 | T9: 0.24305556 | V9: =(T9-S9)*24*60 -> 110 | W9: =T9 -> 0.24305556 | X9: =S10 -> 0.26319444 | AA9: =M9-J9 -> -62.181818 | AB9: =M9/J9 -> 0.95854545 | AC9: =AB11 -> 0.95717396
A10: 新豐2線 | B10: 沙拉 | C10: 青檸烤雞握沙拉(113年) | E10: 39.8 | F10: 3871 | G10: =E10*F10 -> 154065.8 | I10: 17 | J10: 1500 | K10: =J10/I10 -> 88.235294 | L10: 17 | M10: =F10/V10*60 -> 1433.7037 | N10: =M10/L10 -> 84.335512 | O10: =L10-I10 -> 0 | P10: =N10-K10 -> -3.8997821 | Q10: =N10/K10 -> 0.95580247 | S10: 0.26319444 | T10: 0.37569444 | U10: =IF(S10=TIME(17,0,0),"",(S10-T9)*24*60) -> 29 | V10: =(T10-S10)*24*60 -> 162 | AA10: =M10-J10 -> -66.296296 | AB10: =M10/J10 -> 0.95580247
A11: 新豐2線 | B11: 平均 | I11: 18 | J11: 1500 | K11: =J11/I11 -> 83.333333 | L11: 18 | M11: =AVERAGE(M9:M10) -> 1435.7609 | N11: =M11/L11 -> 79.764497 | O11: =L11-I11 -> 0 | P11: =N11-K11 -> -3.5688365 | Q11: =N11/K11 -> 0.95717396 | AA11: =M11-J11 -> -64.239057 | AB11: =M11/J11 -> 0.95717396
A12: 新豐5線 | B12: 小吃 | C12: 剝皮辣椒雞湯 | E12: 41 | F12: 2035 | G12: =E12*F12 -> 83435 | I12: 26 | J12: 1500 | K12: =J12/I12 -> 57.692308 | L12: 26 | M12: =F12/V12*60 -> 1436.4706 | N12: =M12/L12 -> 55.248869 | O12: =L12-I12 -> 0 | P12: =N12-K12 -> -2.4434389 | Q12: =N12/K12 -> 0.95764706 | R12: =Q20 -> 0.9635685 | S12: 0.20833333 | T12: 0.26736111 | V12: =(T12-S12)*24*60 -> 85 | AA12: =M12-J12 -> -63.529412 | AB12: =M12/J12 -> 0.95764706 | AC12: =AB20 -> 0.9635685
A13: 新豐5線 | B13: 季節調理麵 | C13: 柚子雞白湯拉麵 | E13: 72.4 | F13: 807 | G13: =E13*F13 -> 58426.8 | I13: 18 | J13: 1500 | K13: =J13/I13 -> 83.333333 | L13: 18 | M13: =F13/V13*60 -> 1467.2727 | N13: =M13/L13 -> 81.515152 | O13: =L13-I13 -> 0 | P13: =N13-K13 -> -1.8181818 | Q13: =N13/K13 -> 0.97818182 | S13: 0.27222222 | T13: 0.29513889 | U13: =IF(S13=TIME(17,0,0),"",(S13-T12)*24*60) -> 7 | V13: =(T13-S13)*24*60 -> 33 | AA13: =M13-J13 -> -32.727273 | AB13: =M13/J13 -> 0.97818182
A14: 新豐5線 | B14: 熱食義麵 | C14: 焗烤起司肉醬筆尖麵 | E14: 50.67 | F14: 1392 | G14: =E14*F14 -> 70532.64 | I14: 16 | J14: 1500 | K14: =J14/I14 -> 93.75 | L14: 16 | M14: =F14/V14*60 -> 1440 | N14: =M14/L14 -> 90 | O14: =L14-I14 -> 0 | P14: =N14-K14 -> -3.75 | Q14: =N14/K14 -> 0.96 | S14: 0.30069444 | T14: 0.34097222 | U14: =IF(S14=TIME(17,0,0),"",(S14-T13)*24*60) -> 8 | V14: =(T14-S14)*24*60 -> 58 | AA14: =M14-J14 -> -60 | AB14: =M14/J14 -> 0.96
A15: 新豐5線 | B15: 微波主食 | C15: 二配金咖哩濃厚辛口咖哩飯 | E15: 50.98 | F15: 800 | G15: =E15*F15 -> 40784 | H15: 2 | I15: 16 | J15: 2000 | K15: =J15/I15 -> 125 | L15: 16 | M15: =F15/V15*60 -> 1920 | N15: =M15/L15 -> 120 | O15: =L15-I15 -> 0 | P15: =N15-K15 -> -5 | Q15: =N15/K15 -> 0.96 | S15: 0.70833333 | T15: 0.72569444 | U15: =IF(S15=TIME(17,0,0),"",(S15-T14)*24*60) | V15: =(T15-S15)*24*60 -> 25 | AA15: =M15-J15 -> -80 | AB15: =M15/J15 -> 0.96
A16: 新豐5線 | B16: 微波主食 | C16: 二配金咖哩果香甘口咖哩飯 | E16: 50.92 | F16: 800 | G16: =E16*F16 -> 40736 | H16: 2 | I16: 15 | J16: 2000 | K16: =J16/I16 -> 133.33333 | L16: 15 | M16: =F16/V16*60 -> 1920 | N16: =M16/L16 -> 128 | O16: =L16-I16 -> 0 | P16: =N16-K16 -> -5.3333333 | Q16: =N16/K16 -> 0.96 | S16: 0.72916667 | T16: 0.74652778 | U16: =IF(S16=TIME(17,0,0),"",(S16-T15)*24*60) -> 5 | V16: =(T16-S16)*24*60 -> 25 | AA16: =M16-J16 -> -80 | AB16: =M16/J16 -> 0.96
A17: 新豐5線 | B17: 微波主食 | C17: 二配泰式綠咖哩雞 | E17: 50.67 | F17: 1550 | G17: =E17*F17 -> 78538.5 | I17: 15 | J17: 2000 | K17: =J17/I17 -> 133.33333 | L17: 15 | M17: =F17/V17*60 -> 1937.5 | N17: =M17/L17 -> 129.16667 | O17: =L17-I17 -> 0 | P17: =N17-K17 -> -4.1666667 | Q17: =N17/K17 -> 0.96875 | S17: 0.75 | T17: 0.78333333 | U17: =IF(S17=TIME(17,0,0),"",(S17-T16)*24*60) -> 5 | V17: =(T17-S17)*24*60 -> 48 | AA17: =M17-J17 -> -62.5 | AB17: =M17/J17 -> 0.96875
A18: 新豐5線 | B18: 微波主食 | C18: 二配厚香料咖哩雞排飯 | E18: 57.3 | F18: 1914 | G18: =E18*F18 -> 109672.2 | I18: 13 | J18: 2000 | K18: =J18/I18 -> 153.84615 | L18: 13 | M18: =F18/V18*60 -> 1914 | N18: =M18/L18 -> 147.23077 | O18: =L18-I18 -> 0 | P18: =N18-K18 -> -6.6153846 | Q18: =N18/K18 -> 0.957 | S18: 0.78888889 | T18: 0.83055556 | U18: =IF(S18=TIME(17,0,0),"",(S18-T17)*24*60) -> 8 | V18: =(T18-S18)*24*60 -> 60 | W18: =T18 -> 0.83055556 | X18: =S19 -> 0.86944444 | AA18: =M18-J18 -> -86 | AB18: =M18/J18 -> 0.957
A19: 新豐5線 | B19: 微波主食 | C19: 二配金咖哩果香甘口咖哩飯 | E19: 50.92 | F19: 1291 | G19: =E19*F19 -> 65737.72 | I19: 15 | J19: 2000 | K19: =J19/I19 -> 133.33333 | L19: 15 | M19: =F19/V19*60 -> 1936.5 | N19: =M19/L19 -> 129.1 | O19: =L19-I19 -> 0 | P19: =N19-K19 -> -4.2333333 | Q19: =N19/K19 -> 0.96825 | S19: 0.86944444 | T19: 0.89722222 | U19: =IF(S19=TIME(17,0,0),"",(S19-T18)*24*60) -> 56 | V19: =(T19-S19)*24*60 -> 40 | AA19: =M19-J19 -> -63.5 | AB19: =M19/J19 -> 0.96825
A20: 新豐5線 | B20: 平均 | I20: 16.75 | J20: 1812.5 | K20: =J20/I20 -> 108.20896 | L20: 16.75 | M20: =AVERAGE(M12:M19) -> 1746.4679 | N20: =M20/L20 -> 104.26674 | O20: =L20-I20 -> 0 | P20: =N20-K20 -> -3.9422141 | Q20: =N20/K20 -> 0.9635685 | AA20: =M20-J20 -> -66.032086 | AB20: =M20/J20 -> 0.9635685
A21: 新豐7線 | B21: 小吃 | C21: 古早味炒炊粉 | E21: 43.14 | F21: 868 | G21: =E21*F21 -> 37445.52 | I21: 17 | J21: 2000 | K21: =J21/I21 -> 117.64706 | L21: 17 | M21: =F21/V21*60 -> 1928.8889 | N21: =M21/L21 -> 113.46405 | O21: =L21-I21 -> 0 | P21: =N21-K21 -> -4.1830065 | Q21: =N21/K21 -> 0.96444444 | R21: =Q30 -> 0.959733 | S21: 0.20833333 | T21: 0.22708333 | V21: =(T21-S21)*24*60 -> 27 | AA21: =M21-J21 -> -71.111111 | AB21: =M21/J21 -> 0.96444444 | AC21: =AB30 -> 0.959733
A22: 新豐7線 | B22: 熱食義麵 | C22: 麻婆豆腐波浪麵 | E22: 49.9 | F22: 867 | G22: =E22*F22 -> 43263.3 | I22: 17 | J22: 2000 | K22: =J22/I22 -> 117.64706 | L22: 17 | M22: =F22/V22*60 -> 1926.6667 | N22: =M22/L22 -> 113.33333 | O22: =L22-I22 -> 0 | P22: =N22-K22 -> -4.3137255 | Q22: =N22/K22 -> 0.96333333 | S22: 0.23263889 | T22: 0.25138889 | U22: =IF(S22=TIME(17,0,0),"",(S22-T21)*24*60) -> 8 | V22: =(T22-S22)*24*60 -> 27 | AA22: =M22-J22 -> -73.333333 | AB22: =M22/J22 -> 0.96333333
A23: 新豐7線 | B23: 微波主食 | C23: 鐵板滑蛋炸豬排丼 | E23: 57.73 | F23: 2270 | G23: =E23*F23 -> 131047.1 | I23: 14 | J23: 2000 | K23: =J23/I23 -> 142.85714 | L23: 14 | M23: =F23/V23*60 -> 1918.3099 | N23: =M23/L23 -> 137.02213 | O23: =L23-I23 -> 0 | P23: =N23-K23 -> -5.8350101 | Q23: =N23/K23 -> 0.95915493 | S23: 0.25625 | T23: 0.30555556 | U23: =IF(S23=TIME(17,0,0),"",(S23-T22)*24*60) -> 7 | V23: =(T23-S23)*24*60 -> 71 | AA23: =M23-J23 -> -81.690141 | AB23: =M23/J23 -> 0.95915493
A24: 新豐7線 | B24: 微波主食 | C24: 極上炙烤親子丼 | E24: 53.68 | F24: 1331 | G24: =E24*F24 -> 71448.08 | I24: 16 | J24: 2000 | K24: =J24/I24 -> 125 | L24: 16 | M24: =F24/V24*60 -> 1901.4286 | N24: =M24/L24 -> 118.83929 | O24: =L24-I24 -> 0 | P24: =N24-K24 -> -6.1607143 | Q24: =N24/K24 -> 0.95071429 | S24: 0.31111111 | T24: 0.34027778 | U24: =IF(S24=TIME(17,0,0),"",(S24-T23)*24*60) -> 8 | V24: =(T24-S24)*24*60 -> 42 | AA24: =M24-J24 -> -98.571429 | AB24: =M24/J24 -> 0.95071429
A25: 新豐7線 | B25: 微波主食 | C25: 日式野菜烘蛋燴飯 | E25: 49.91 | F25: 825 | G25: =E25*F25 -> 41175.75 | I25: 17 | J25: 2000 | K25: =J25/I25 -> 117.64706 | L25: 17 | M25: =F25/V25*60 -> 1903.8462 | N25: =M25/L25 -> 111.99095 | O25: =L25-I25 -> 0 | P25: =N25-K25 -> -5.6561086 | Q25: =N25/K25 -> 0.95192308 | S25: 0.34583333 | T25: 0.36388889 | U25: =IF(S25=TIME(17,0,0),"",(S25-T24)*24*60) -> 8 | V25: =(T25-S25)*24*60 -> 26 | AA25: =M25-J25 -> -96.153846 | AB25: =M25/J25 -> 0.95192308
A26: 新豐7線 | B26: 微波主食 | C26: 二配川味麻婆燒豆腐燴飯 | E26: 50.49 | F26: 1892 | G26: =E26*F26 -> 95527.08 | I26: 15 | J26: 2000 | K26: =J26/I26 -> 133.33333 | L26: 15 | M26: =F26/V26*60 -> 1924.0678 | N26: =M26/L26 -> 128.27119 | O26: =L26-I26 -> 0 | P26: =N26-K26 -> -5.0621469 | Q26: =N26/K26 -> 0.9620339 | S26: 0.70833333 | T26: 0.74930556 | U26: =IF(S26=TIME(17,0,0),"",(S26-T25)*24*60) | V26: =(T26-S26)*24*60 -> 59 | AA26: =M26-J26 -> -75.932203 | AB26: =M26/J26 -> 0.9620339
A27: 新豐7線 | B27: 微波主食 | C27: 二配粗飽系雞排炒飯(114年) | E27: 57.73 | F27: 1207 | G27: =E27*F27 -> 69680.11 | I27: 16 | J27: 1500 | K27: =J27/I27 -> 93.75 | L27: 16 | M27: =F27/V27*60 -> 1448.4 | N27: =M27/L27 -> 90.525 | O27: =L27-I27 -> 0 | P27: =N27-K27 -> -3.225 | Q27: =N27/K27 -> 0.9656 | S27: 0.75416667 | T27: 0.78888889 | U27: =IF(S27=TIME(17,0,0),"",(S27-T26)*24*60) -> 7 | V27: =(T27-S27)*24*60 -> 50 | AA27: =M27-J27 -> -51.6 | AB27: =M27/J27 -> 0.9656
A28: 新豐7線 | B28: 微波主食 | C28: 二配起司控培根白醬焗烤飯 | E28: 53.68 | F28: 1903 | G28: =E28*F28 -> 102153.04 | I28: 16 | J28: 1500 | K28: =J28/I28 -> 93.75 | L28: 16 | M28: =F28/V28*60 -> 1445.3165 | N28: =M28/L28 -> 90.332278 | O28: =L28-I28 -> 0 | P28: =N28-K28 -> -3.4177215 | Q28: =N28/K28 -> 0.9635443 | S28: 0.79444444 | T28: 0.84930556 | U28: =IF(S28=TIME(17,0,0),"",(S28-T27)*24*60) -> 8 | V28: =(T28-S28)*24*60 -> 79 | W28: =T28 -> 0.84930556 | X28: =S29 -> 0.88958333 | AA28: =M28-J28 -> -54.683544 | AB28: =M28/J28 -> 0.9635443
A29: 新豐7線 | B29: 微波主食 | C29: 二配金咖哩濃厚辛口咖哩飯 | E29: 50.98 | F29: 1311 | G29: =E29*F29 -> 66834.78 | I29: 16 | J29: 2000 | K29: =J29/I29 -> 125 | L29: 16 | M29: =F29/V29*60 -> 1918.5366 | N29: =M29/L29 -> 119.90854 | O29: =L29-I29 -> 0 | P29: =N29-K29 -> -5.0914634 | Q29: =N29/K29 -> 0.95926829 | S29: 0.88958333 | T29: 0.91805556 | U29: =IF(S29=TIME(17,0,0),"",(S29-T28)*24*60) -> 58 | V29: =(T29-S29)*24*60 -> 41 | AA29: =M29-J29 -> -81.463415 | AB29: =M29/J29 -> 0.95926829
A30: 新豐7線 | B30: 平均 | I30: 16 | J30: 1888.8889 | K30: =J30/I30 -> 118.05556 | L30: 16 | M30: =AVERAGE(M21:M29) -> 1812.829 | N30: =M30/L30 -> 113.30181 | O30: =L30-I30 -> 0 | P30: =N30-K30 -> -4.7537432 | Q30: =N30/K30 -> 0.959733 | AA30: =M30-J30 -> -76.059891 | AB30: =M30/J30 -> 0.959733
A31: 新豐8線 | B31: 三明治 | C31: 紐奧良風味烤雞鮮蔬三明治 | E31: 31.29 | F31: 5837 | G31: =E31*F31 -> 182639.73 | I31: 18 | J31: 2400 | K31: =J31/I31 -> 133.33333 | L31: 18 | M31: =F31/V31*60 -> 2289.0196 | N31: =M31/L31 -> 127.16776 | O31: =L31-I31 -> 0 | P31: =N31-K31 -> -6.1655773 | Q31: =N31/K31 -> 0.95375817 | R31: =Q36 -> 0.95729478 | S31: 0.083333333 | T31: 0.18958333 | V31: =(T31-S31)*24*60 -> 153 | W31: =T31 -> 0.18958333 | X31: =S32 -> 0.20833333 | AA31: =M31-J31 -> -110.98039 | AB31: =M31/J31 -> 0.95375817 | AC31: =AB36 -> 0.95729478
A32: 新豐8線 | B32: 三明治 | C32: 經典總匯三明治 | E32: 26.2 | F32: 3504 | G32: =E32*F32 -> 91804.8 | I32: 20 | J32: 2400 | K32: =J32/I32 -> 120 | L32: 20 | M32: =F32/V32*60 -> 2285.2174 | N32: =M32/L32 -> 114.26087 | O32: =L32-I32 -> 0 | P32: =N32-K32 -> -5.7391304 | Q32: =N32/K32 -> 0.95217391 | S32: 0.20833333 | T32: 0.27222222 | U32: =(S32-T31)*24*60 -> 27 | V32: =(T32-S32)*24*60 -> 92 | AA32: =M32-J32 -> -114.78261 | AB32: =M32/J32 -> 0.95217391
A33: 新豐8線 | B33: 三明治 | C33: 雞蛋沙拉三明治(114年) | E33: 25.99 | F33: 3143 | G33: =E33*F33 -> 81686.57 | I33: 14 | J33: 2400 | K33: =J33/I33 -> 171.42857 | L33: 14 | M33: =F33/V33*60 -> 2299.7561 | N33: =M33/L33 -> 164.26829 | O33: =L33-I33 -> 0 | P33: =N33-K33 -> -7.1602787 | Q33: =N33/K33 -> 0.95823171 | S33: 0.27777778 | T33: 0.33472222 | U33: =(S33-T32)*24*60 -> 8 | V33: =(T33-S33)*24*60 -> 82 | AA33: =M33-J33 -> -100.2439 | AB33: =M33/J33 -> 0.95823171
A34: 新豐8線 | B34: 三明治 | C34: 肉鬆火腿三明治 | E34: 20.52 | F34: 3033 | G34: =E34*F34 -> 62237.16 | I34: 18 | J34: 2400 | K34: =J34/I34 -> 133.33333 | L34: 18 | M34: =F34/V34*60 -> 2303.5443 | N34: =M34/L34 -> 127.97468 | O34: =L34-I34 -> 0 | P34: =N34-K34 -> -5.3586498 | Q34: =N34/K34 -> 0.95981013 | S34: 0.33819444 | T34: 0.39305556 | U34: =(S34-T33)*24*60 -> 5 | V34: =(T34-S34)*24*60 -> 79 | AA34: =M34-J34 -> -96.455696 | AB34: =M34/J34 -> 0.95981013
A35: 新豐8線 | B35: 三明治 | C35: 好多菜三明治(114年) | E35: 25.98 | F35: 2618 | G35: =E35*F35 -> 68015.64 | I35: 21 | J35: 2400 | K35: =J35/I35 -> 114.28571 | L35: 21 | M35: =F35/V35*60 -> 2310 | N35: =M35/L35 -> 110 | O35: =L35-I35 -> 0 | P35: =N35-K35 -> -4.2857143 | Q35: =N35/K35 -> 0.9625 | S35: 0.39861111 | T35: 0.44583333 | U35: =(S35-T34)*24*60 -> 8 | V35: =(T35-S35)*24*60 -> 68 | AA35: =M35-J35 -> -90 | AB35: =M35/J35 -> 0.9625
A36: 新豐8線 | B36: 平均 | I36: 18.2 | J36: 2400 | K36: =J36/I36 -> 131.86813 | L36: 18.2 | M36: =AVERAGE(M31:M35) -> 2297.5075 | N36: =M36/L36 -> 126.23667 | O36: =L36-I36 -> 0 | P36: =N36-K36 -> -5.6314571 | Q36: =N36/K36 -> 0.95729478 | AA36: =M36-J36 -> -102.49252 | AB36: =M36/J36 -> 0.95729478
A37: 新豐9線 | B37: 三明治 | C37: 檸檬紅茶三明治 | E37: 22.69 | F37: 653 | G37: =E37*F37 -> 14816.57 | I37: 15 | J37: 2400 | K37: =J37/I37 -> 160 | L37: 15 | M37: =F37/V37*60 -> 2304.7059 | N37: =M37/L37 -> 153.64706 | O37: =L37-I37 -> 0 | P37: =N37-K37 -> -6.3529412 | Q37: =N37/K37 -> 0.96029412 | R37: =Q44 -> 0.95423408 | S37: 0.083333333 | T37: 0.095138889 | V37: =(T37-S37)*24*60 -> 17 | W37: =T37 -> 0.095138889 | X37: =S38 -> 0.11527778 | AA37: =M37-J37 -> -95.294118 | AB37: =M37/J37 -> 0.96029412 | AC37: =AB44 -> 0.95423408
A38: 新豐9線 | B38: 三明治 | C38: 鮪魚起司溏心蛋三明治 | E38: 26.2 | F38: 4224 | G38: =E38*F38 -> 110668.8 | I38: 18 | J38: 2400 | K38: =J38/I38 -> 133.33333 | L38: 18 | M38: =F38/V38*60 -> 2283.2432 | N38: =M38/L38 -> 126.84685 | O38: =L38-I38 -> 0 | P38: =N38-K38 -> -6.4864865 | Q38: =N38/K38 -> 0.95135135 | S38: 0.11527778 | T38: 0.19236111 | U38: =(S38-T37)*24*60 -> 29 | V38: =(T38-S38)*24*60 -> 111 | AA38: =M38-J38 -> -116.75676 | AB38: =M38/J38 -> 0.95135135
A39: 新豐9線 | B39: 三明治 | C39: 陽光地瓜總匯三明治 | E39: 26.18 | F39: 1748 | G39: =E39*F39 -> 45762.64 | I39: 19 | J39: 2400 | K39: =J39/I39 -> 126.31579 | L39: 19 | M39: =F39/V39*60 -> 2330.6667 | N39: =M39/L39 -> 122.66667 | O39: =L39-I39 -> 0 | P39: =N39-K39 -> -3.6491228 | Q39: =N39/K39 -> 0.97111111 | S39: 0.19722222 | T39: 0.22847222 | U39: =(S39-T38)*24*60 -> 7 | V39: =(T39-S39)*24*60 -> 45 | AA39: =M39-J39 -> -69.333333 | AB39: =M39/J39 -> 0.97111111
A40: 新豐9線 | B40: 三明治 | C40: 醬燒烤雞三明治 | E40: 26.39 | F40: 4164 | G40: =E40*F40 -> 109887.96 | I40: 19 | J40: 2400 | K40: =J40/I40 -> 126.31579 | L40: 19 | M40: =F40/V40*60 -> 2292.1101 | N40: =M40/L40 -> 120.63737 | O40: =L40-I40 -> 0 | P40: =N40-K40 -> -5.6784162 | Q40: =N40/K40 -> 0.95504587 | S40: 0.23333333 | T40: 0.30902778 | U40: =(S40-T39)*24*60 -> 7 | V40: =(T40-S40)*24*60 -> 109 | AA40: =M40-J40 -> -107.88991 | AB40: =M40/J40 -> 0.95504587
...

Sheet 1230
B1: 屏榮 新豐廠組合室生產人時性分析
B3: 日期 | C3: =TEXT('1230 4度C'!A2,"yyyy.mm.ddaaaa") -> 2025.12.30星期二 | E3: 訂單量 | F3: ='1230 4度C'!D1 -> 160703 | H3: 營業額 | I3: ='1230 4度C'!F1 -> 5536615.5
B4: 人時性 | C4: 項目 | E4: ➀ | G4: ➁ | I4: ➂
C5: 組合室 | E5: 全溫層 | G5: 4度C-各編組展開 | I5: ③三明治-各編組展開
C6: 排關平均 | E6: =AVERAGE(D13:M13) -> 147.77632 | F6: =AVERAGE(D27:O27,D13:J13) -> 151.35637 | G6: =AVERAGE(D13:J13) -> 151.35637 | I6: =AVERAGE(K13:M13) -> 139.42287
C7: 實績平均 | E7: =AVERAGE(D14:M14) -> 140.93349 | F7: =AVERAGE(D28:O28,D14:J14) -> 144.08813 | G7: =AVERAGE(D14:J14) -> 144.08813 | I7: =AVERAGE(K14:M14) -> 133.57268
C8: 達成率平均 | E8: =AVERAGE(D15:M15) -> 0.95138806 | F8: =AVERAGE(D15:J15,D29:O29) -> 0.94854216 | G8: =AVERAGE(D15:J15) -> 0.94854216 | I8: =AVERAGE(K15:M15) -> 0.95802849 | K8: ※現行日本鮮食廠以達成率80%為基本(即為現行KPI)
B10: 溫層 | D10: ➁4度C-各編組展開 | K10: ③三明治-各編組展開
B11: 編組 | D11: 1 | E11: 2 | F11: 3 | G11: 4 | H11: 5 | I11: 6 | J11: 7 | K11: 1 | L11: 2 | M11: 3
D12: 新豐6線 | E12: 新豐2線 | F12: 新豐5線 | G12: 新豐7線 | H12: 新豐3線 | I12: 新豐1線 | J12: 新豐10線 | K12: 新豐8線 | L12: 新豐9線 | M12: 新豐4線
B13: 人時性 | C13: 排關 | D13: =SUMIFS('1230 4度C'!$K:$K,'1230 4度C'!$A:$A,"新豐6線",'1230 4度C'!$B:$B,"平均") -> 115.38462 | E13: =SUMIFS('1230 4度C'!$K:$K,'1230 4度C'!$A:$A,"新豐2線",'1230 4度C'!$B:$B,"平均") -> 83.333333 | F13: =SUMIFS('1230 4度C'!$K:$K,'1230 4度C'!$A:$A,"新豐5線",'1230 4度C'!$B:$B,"平均") -> 108.20896 | G13: =SUMIFS('1230 4度C'!$K:$K,'1230 4度C'!$A:$A,"新豐7線",'1230 4度C'!$B:$B,"平均") -> 118.05556 | H13: =SUMIFS('1230 4度C'!$K:$K,'1230 4度C'!$A:$A,"新豐3線",'1230 4度C'!$B:$B,"平均") -> 235.29412 | I13: =SUMIFS('1230 4度C'!$K:$K,'1230 4度C'!$A:$A,"新豐1線",'1230 4度C'!$B:$B,"平均") -> 104.57516 | J13: =SUMIFS('1230 4度C'!$K:$K,'1230 4度C'!$A:$A,"新豐10線",'1230 4度C'!$B:$B,"平均") -> 294.64286 | K13: =SUMIFS('1230 4度C'!$K:$K,'1230 4度C'!$A:$A,"新豐8線",'1230 4度C'!$B:$B,"平均") -> 132.11009 | L13: =SUMIFS('1230 4度C'!$K:$K,'1230 4度C'!$A:$A,"新豐9線",'1230 4度C'!$B:$B,"平均") -> 137.70492 | M13: =SUMIFS('1230 4度C'!$K:$K,'1230 4度C'!$A:$A,"新豐4線",'1230 4度C'!$B:$B,"平均") -> 148.45361
C14: 實績 | D14: =SUMIFS('1230 4度C'!$N:$N,'1230 4度C'!$A:$A,"新豐6線",'1230 4度C'!$B:$B,"平均") -> 110.30483 | E14: =SUMIFS('1230 4度C'!$N:$N,'1230 4度C'!$A:$A,"新豐2線",'1230 4度C'!$B:$B,"平均") -> 79.607143 | F14: =SUMIFS('1230 4度C'!$N:$N,'1230 4度C'!$A:$A,"新豐5線",'1230 4度C'!$B:$B,"平均") -> 103.79169 | G14: =SUMIFS('1230 4度C'!$N:$N,'1230 4度C'!$A:$A,"新豐7線",'1230 4度C'!$B:$B,"平均") -> 113.38966 | H14: =SUMIFS('1230 4度C'!$N:$N,'1230 4度C'!$A:$A,"新豐3線",'1230 4度C'!$B:$B,"平均") -> 225.26943 | I14: =SUMIFS('1230 4度C'!$N:$N,'1230 4度C'!$A:$A,"新豐1線",'1230 4度C'!$B:$B,"平均") -> 93.133536 | J14: =SUMIFS('1230 4度C'!$N:$N,'1230 4度C'!$A:$A,"新豐10線",'1230 4度C'!$B:$B,"平均") -> 283.12058 | K14: =SUMIFS('1230 4度C'!$N:$N,'1230 4度C'!$A:$A,"新豐8線",'1230 4度C'!$B:$B,"平均") -> 126.17337 | L14: =SUMIFS('1230 4度C'!$N:$N,'1230 4度C'!$A:$A,"新豐9線",'1230 4度C'!$B:$B,"平均") -> 132.48501 | M14: =SUMIFS('1230 4度C'!$N:$N,'1230 4度C'!$A:$A,"新豐4線",'1230 4度C'!$B:$B,"平均") -> 142.05966
C15: 達成率 | D15: =D14/D13 -> 0.95597522 | E15: =E14/E13 -> 0.95528571 | F15: =F14/F13 -> 0.95917842 | G15: =G14/G13 -> 0.96047714 | H15: =H14/H13 -> 0.95739506 | I15: =I14/I13 -> 0.89058943 | J15: =J14/J13 -> 0.9608941 | K15: =K14/K13 -> 0.95506229 | ... M15: =M14/M13 -> 0.95692966
B16: 作業 時間 | C16: 開始 | D16: =VLOOKUP("新豐6線",'1230 4度C'!$A:$T,19,0) -> 0.70833333 | E16: =VLOOKUP("新豐2線",'1230 4度C'!$A:$T,19,0) -> 0.16666667 | F16: =VLOOKUP("新豐5線",'1230 4度C'!$A:$T,19,0) -> 0.20833333 | G16: =VLOOKUP("新豐7線",'1230 4度C'!$A:$T,19,0) -> 0.20833333 | H16: =VLOOKUP("新豐3線",'1230 4度C'!$A:$T,19,0) -> 0.083333333 | I16: =VLOOKUP("新豐1線",'1230 4度C'!$A:$T,19,0) -> 0.20833333 | J16: =VLOOKUP("新豐10線",'1230 4度C'!$A:$T,19,0) -> 0.20833333 | K16: =VLOOKUP("新豐8線",'1230 4度C'!$A:$T,19,0) -> 0.083333333 | L16: =VLOOKUP("新豐9線",'1230 4度C'!$A:$T,19,0) -> 0.083333333 | M16: =VLOOKUP("新豐4線",'1230 4度C'!$A:$T,19,0) -> 0.083333333
C17: 結束 | D17: =LOOKUP(2,1/(('1230 4度C'!$A:$A="新豐6線")*('1230 4度C'!$T:$T<>"")),'1230 4度C'!$T:$T) -> 0.82638889 | E17: =LOOKUP(2,1/(('1230 4度C'!$A:$A="新豐2線")*('1230 4度C'!$T:$T<>"")),'1230 4度C'!$T:$T) -> 0.43472222 | F17: =LOOKUP(2,1/(('1230 4度C'!$A:$A="新豐5線")*('1230 4度C'!$T:$T<>"")),'1230 4度C'!$T:$T) -> 0.90763889 | G17: =LOOKUP(2,1/(('1230 4度C'!$A:$A="新豐7線")*('1230 4度C'!$T:$T<>"")),'1230 4度C'!$T:$T) -> 0.93125 | H17: =LOOKUP(2,1/(('1230 4度C'!$A:$A="新豐3線")*('1230 4度C'!$T:$T<>"")),'1230 4度C'!$T:$T) -> 0.47847222 | I17: =LOOKUP(2,1/(('1230 4度C'!$A:$A="新豐1線")*('1230 4度C'!$T:$T<>"")),'1230 4度C'!$T:$T) -> 0.93333333 | J17: =LOOKUP(2,1/(('1230 4度C'!$A:$A="新豐10線")*('1230 4度C'!$T:$T<>"")),'1230 4度C'!$T:$T) -> 0.45763889 | K17: =LOOKUP(2,1/(('1230 4度C'!$A:$A="新豐8線")*('1230 4度C'!$T:$T<>"")),'1230 4度C'!$T:$T) -> 0.61388889 | L17: =LOOKUP(2,1/(('1230 4度C'!$A:$A="新豐9線")*('1230 4度C'!$T:$T<>"")),'1230 4度C'!$T:$T) -> 0.51597222 | M17: =LOOKUP(2,1/(('1230 4度C'!$A:$A="新豐4線")*('1230 4度C'!$T:$T<>"")),'1230 4度C'!$T:$T) -> 0.59513889
B18: 配置人數 | D18: =SUMIFS('1230 4度C'!$I:$I,'1230 4度C'!$A:$A,"新豐6線",'1230 4度C'!$B:$B,"平均") -> 17.333333 | E18: =SUMIFS('1230 4度C'!$I:$I,'1230 4度C'!$A:$A,"新豐2線",'1230 4度C'!$B:$B,"平均") -> 18 | F18: =SUMIFS('1230 4度C'!$I:$I,'1230 4度C'!$A:$A,"新豐5線",'1230 4度C'!$B:$B,"平均") -> 16.75 | G18: =SUMIFS('1230 4度C'!$I:$I,'1230 4度C'!$A:$A,"新豐7線",'1230 4度C'!$B:$B,"平均") -> 16 | H18: =SUMIFS('1230 4度C'!$I:$I,'1230 4度C'!$A:$A,"新豐3線",'1230 4度C'!$B:$B,"平均") -> 11.333333 | I18: =SUMIFS('1230 4度C'!$I:$I,'1230 4度C'!$A:$A,"新豐1線",'1230 4度C'!$B:$B,"平均") -> 19.125 | J18: =SUMIFS('1230 4度C'!$I:$I,'1230 4度C'!$A:$A,"新豐10線",'1230 4度C'!$B:$B,"平均") -> 9.3333333 | K18: =SUMIFS('1230 4度C'!$I:$I,'1230 4度C'!$A:$A,"新豐8線",'1230 4度C'!$B:$B,"平均") -> 18.166667 | L18: =SUMIFS('1230 4度C'!$I:$I,'1230 4度C'!$A:$A,"新豐9線",'1230 4度C'!$B:$B,"平均") -> 17.428571 | M18: =SUMIFS('1230 4度C'!$I:$I,'1230 4度C'!$A:$A,"新豐4線",'1230 4度C'!$B:$B,"平均") -> 16.166667
B19: 主要應用設備 | D19: ET-55 | E19: 熱縮爐 | F19: L型包裝機 | G19: L型包裝機 | H19: 伺服包裝機 | I19: ET-55 | J19: 伺服包裝機 | K19: 三明治包裝機 | L19: 三明治包裝機 | M19: 三明治包裝機
B20: 次要應用設備 | F20: 圓盤機 | G20: ET-55
B21: 備註 | E21: 握沙拉 | F21: 共用L型包裝機 | H21: 調理麵包 | I21: 炒飯+沙拉 | J21: 調理麵包

Sheet 1230 4度C
A1: 新豐廠四度C日報分析 | C1: 總生產量 | D1: =SUM(F5:F75) -> 160703 | E1: 營業額 | F1: =SUM(G5:G75) -> 5536615.5 | G1: 出勤人數 | H1: =L8+L11+L52+L61+L20+L68+L37+L45+L30+L75 -> 159.6369 | I1: 產線配置圖 | L1: 生產實績 | O1: 人時性差異分析 | S1: 日報登錄 | Y1: 分析說明 | AA1: 產能差異分析
A2: 46021 | B2: 星期二 | C2: 人時性 | D2: =AVERAGE(N8,N11,N52,N61,N20,N68,N30,N37,N45,N75) -> 140.93349 | E2: 平均廠價 | F2: =F1/D1 -> 34.452472 | G2: 多次生產數 | H2: =COUNT(H5:H75) -> 5
A3: 線別 | B3: 品類 | C3: 品名 | E3: 廠價 | F3: 生產量 | G3: 營收 | H3: 多次 生產 | I3: 人數 | J3: 產能/時 | K3: 人時性 | L3: 人數 | M3: 產能/時 | N3: 人時性 | O3: 人數 | P3: 人時性 | Q3: 達成率 | R3: 達成率平均 | S3: 生產時間 | U3: 換線、休息/分 | V3: 稼動時間/分 | W3: 休息時間 | Y3: (新豐回填) | AA3: 產能/時 | AB3: 達成率 | AC3: 達成率平均
S4: 開始 | T4: 結束 | W4: 開始 | X4: 結束
A5: 新豐6線 | B5: 微波主食 | C5: 二配港式香滑嫩蛋牛肉燴飯 | E5: 50.67 | F5: 1427 | G5: =E5*F5 -> 72306.09 | I5: 17 | J5: 2000 | K5: =J5/I5 -> 117.64706 | L5: 17 | M5: =F5/V5*60 -> 1902.6667 | N5: =M5/L5 -> 111.92157 | O5: =L5-I5 -> 0 | P5: =N5-K5 -> -5.7254902 | Q5: =N5/K5 -> 0.95133333 | R5: =Q8 -> 0.95597522 | S5: 0.70833333 | T5: 0.73958333 | V5: =(T5-S5)*24*60 -> 45 | AA5: =M5-J5 -> -97.333333 | AB5: =M5/J5 -> 0.95133333 | AC5: =AB8 -> 0.95597522
A6: 新豐6線 | B6: 微波主食 | C6: 二配美味蟹煲 | E6: 54.09 | F6: 1507 | G6: =E6*F6 -> 81513.63 | I6: 19 | J6: 2000 | K6: =J6/I6 -> 105.26316 | L6: 19 | M6: =F6/V6*60 -> 1923.8298 | N6: =M6/L6 -> 101.2542 | O6: =L6-I6 -> 0 | P6: =N6-K6 -> -4.0089586 | Q6: =N6/K6 -> 0.96191489 | S6: 0.74513889 | T6: 0.77777778 | U6: =IF(S6=TIME(17,0,0),"",(S6-T5)*24*60) -> 8 | V6: =(T6-S6)*24*60 -> 47 | AA6: =M6-J6 -> -76.170213 | AB6: =M6/J6 -> 0.96191489
A7: 新豐6線 | B7: 微波主食 | C7: 二配麻油雞燴飯 | E7: 50.29 | F7: 1973 | G7: =E7*F7 -> 99222.17 | I7: 16 | J7: 2000 | K7: =J7/I7 -> 125 | L7: 16 | M7: =F7/V7*60 -> 1909.3548 | N7: =M7/L7 -> 119.33468 | O7: =L7-I7 -> 0 | P7: =N7-K7 -> -5.6653226 | Q7: =N7/K7 -> 0.95467742 | S7: 0.78333333 | T7: 0.82638889 | U7: =IF(S7=TIME(17,0,0),"",(S7-T6)*24*60) -> 8 | V7: =(T7-S7)*24*60 -> 62 | AA7: =M7-J7 -> -90.645161 | AB7: =M7/J7 -> 0.95467742
A8: 新豐6線 | B8: 平均 | I8: 17.333333 | J8: 2000 | K8: =J8/I8 -> 115.38462 | L8: 17.333333 | M8: =AVERAGE(M5:M7) -> 1911.9504 | N8: =M8/L8 -> 110.30483 | O8: =L8-I8 -> 0 | P8: =N8-K8 -> -5.0797828 | Q8: =N8/K8 -> 0.95597522 | AA8: =M8-J8 -> -88.049569 | AB8: =M8/J8 -> 0.95597522
A9: 新豐2線 | B9: 沙拉 | C9: 青醬優格雞肉握沙拉(113年) | E9: 39.62 | F9: 3347 | G9: =E9*F9 -> 132608.14 | I9: 19 | J9: 1500 | K9: =J9/I9 -> 78.947368 | L9: 19 | M9: =F9/V9*60 -> 1434.4286 | N9: =M9/L9 -> 75.496241 | O9: =L9-I9 -> 0 | P9: =N9-K9 -> -3.4511278 | Q9: =N9/K9 -> 0.95628571 | R9: =Q11 -> 0.95528571 | S9: 0.16666667 | T9: 0.26388889 | V9: =(T9-S9)*24*60 -> 140 | W9: =T9 -> 0.26388889 | X9: =S10 -> 0.28402778 | AA9: =M9-J9 -> -65.571429 | AB9: =M9/J9 -> 0.95628571 | AC9: =AB11 -> 0.95528571
A10: 新豐2線 | B10: 沙拉 | C10: 青檸烤雞握沙拉(113年) | E10: 39.8 | F10: 5177 | G10: =E10*F10 -> 206044.6 | I10: 17 | J10: 1500 | K10: =J10/I10 -> 88.235294 | L10: 17 | M10: =F10/V10*60 -> 1431.4286 | N10: =M10/L10 -> 84.201681 | O10: =L10-I10 -> 0 | P10: =N10-K10 -> -4.0336134 | Q10: =N10/K10 -> 0.95428571 | S10: 0.28402778 | T10: 0.43472222 | U10: =IF(S10=TIME(17,0,0),"",(S10-T9)*24*60) -> 29 | V10: =(T10-S10)*24*60 -> 217 | AA10: =M10-J10 -> -68.571429 | AB10: =M10/J10 -> 0.95428571
A11: 新豐2線 | B11: 平均 | I11: 18 | J11: 1500 | K11: =J11/I11 -> 83.333333 | L11: 18 | M11: =AVERAGE(M9:M10) -> 1432.9286 | N11: =M11/L11 -> 79.607143 | O11: =L11-I11 -> 0 | P11: =N11-K11 -> -3.7261905 | Q11: =N11/K11 -> 0.95528571 | AA11: =M11-J11 -> -67.071429 | AB11: =M11/J11 -> 0.95528571
A12: 新豐5線 | B12: 小吃 | C12: 剝皮辣椒雞湯 | E12: 41 | F12: 2261 | G12: =E12*F12 -> 92701 | I12: 26 | J12: 1500 | K12: =J12/I12 -> 57.692308 | L12: 26 | M12: =F12/V12*60 -> 1443.1915 | N12: =M12/L12 -> 55.507365 | O12: =L12-I12 -> 0 | P12: =N12-K12 -> -2.1849427 | Q12: =N12/K12 -> 0.96212766 | R12: =Q20 -> 0.95917842 | S12: 0.20833333 | T12: 0.27361111 | V12: =(T12-S12)*24*60 -> 94 | AA12: =M12-J12 -> -56.808511 | AB12: =M12/J12 -> 0.96212766 | AC12: =AB20 -> 0.95917842
A13: 新豐5線 | B13: 季節調理麵 | C13: 柚子雞白湯拉麵 | E13: 72.4 | F13: 1049 | G13: =E13*F13 -> 75947.6 | I13: 18 | J13: 1500 | K13: =J13/I13 -> 83.333333 | L13: 18 | M13: =F13/V13*60 -> 1430.4545 | N13: =M13/L13 -> 79.469697 | O13: =L13-I13 -> 0 | P13: =N13-K13 -> -3.8636364 | Q13: =N13/K13 -> 0.95363636 | S13: 0.27708333 | T13: 0.30763889 | U13: =IF(S13=TIME(17,0,0),"",(S13-T12)*24*60) -> 5 | V13: =(T13-S13)*24*60 -> 44 | AA13: =M13-J13 -> -69.545455 | AB13: =M13/J13 -> 0.95363636
A14: 新豐5線 | B14: 熱食義麵 | C14: 焗烤起司肉醬筆尖麵 | E14: 50.67 | F14: 1495 | G14: =E14*F14 -> 75751.65 | I14: 16 | J14: 1500 | K14: =J14/I14 -> 93.75 | L14: 16 | M14: =F14/V14*60 -> 1446.7742 | N14: =M14/L14 -> 90.423387 | O14: =L14-I14 -> 0 | P14: =N14-K14 -> -3.3266129 | Q14: =N14/K14 -> 0.96451613 | S14: 0.31319444 | T14: 0.35625 | U14: =IF(S14=TIME(17,0,0),"",(S14-T13)*24*60) -> 8 | V14: =(T14-S14)*24*60 -> 62 | AA14: =M14-J14 -> -53.225806 | AB14: =M14/J14 -> 0.96451613
A15: 新豐5線 | B15: 微波主食 | C15: 二配金咖哩濃厚辛口咖哩飯 | E15: 50.98 | F15: 800 | G15: =E15*F15 -> 40784 | H15: 2 | I15: 16 | J15: 2000 | K15: =J15/I15 -> 125 | L15: 16 | M15: =F15/V15*60 -> 1920 | N15: =M15/L15 -> 120 | O15: =L15-I15 -> 0 | P15: =N15-K15 -> -5 | Q15: =N15/K15 -> 0.96 | S15: 0.70833333 | T15: 0.72569444 | U15: =IF(S15=TIME(17,0,0),"",(S15-T14)*24*60) | V15: =(T15-S15)*24*60 -> 25 | AA15: =M15-J15 -> -80 | AB15: =M15/J15 -> 0.96
A16: 新豐5線 | B16: 微波主食 | C16: 二配金咖哩果香甘口咖哩飯 | E16: 50.92 | F16: 800 | G16: =E16*F16 -> 40736 | H16: 2 | I16: 15 | J16: 2000 | K16: =J16/I16 -> 133.33333 | L16: 15 | M16: =F16/V16*60 -> 1920 | N16: =M16/L16 -> 128 | O16: =L16-I16 -> 0 | P16: =N16-K16 -> -5.3333333 | Q16: =N16/K16 -> 0.96 | S16: 0.72986111 | T16: 0.74722222 | U16: =IF(S16=TIME(17,0,0),"",(S16-T15)*24*60) -> 6 | V16: =(T16-S16)*24*60 -> 25 | AA16: =M16-J16 -> -80 | AB16: =M16/J16 -> 0.96
A17: 新豐5線 | B17: 微波主食 | C17: 二配泰式綠咖哩雞 | E17: 50.67 | F17: 1516 | G17: =E17*F17 -> 76815.72 | I17: 15 | J17: 2000 | K17: =J17/I17 -> 133.33333 | L17: 15 | M17: =F17/V17*60 -> 1935.3191 | N17: =M17/L17 -> 129.02128 | O17: =L17-I17 -> 0 | P17: =N17-K17 -> -4.3120567 | Q17: =N17/K17 -> 0.96765957 | S17: 0.75208333 | T17: 0.78472222 | U17: =IF(S17=TIME(17,0,0),"",(S17-T16)*24*60) -> 7 | V17: =(T17-S17)*24*60 -> 47 | AA17: =M17-J17 -> -64.680851 | AB17: =M17/J17 -> 0.96765957
A18: 新豐5線 | B18: 微波主食 | C18: 二配厚香料咖哩雞排飯 | E18: 57.3 | F18: 1940 | G18: =E18*F18 -> 111162 | I18: 13 | J18: 2000 | K18: =J18/I18 -> 153.84615 | L18: 13 | M18: =F18/V18*60 -> 1908.1967 | N18: =M18/L18 -> 146.78436 | O18: =L18-I18 -> 0 | P18: =N18-K18 -> -7.0617907 | Q18: =N18/K18 -> 0.95409836 | S18: 0.78888889 | T18: 0.83125 | U18: =IF(S18=TIME(17,0,0),"",(S18-T17)*24*60) -> 6 | V18: =(T18-S18)*24*60 -> 61 | W18: =T18 -> 0.83125 | X18: =S19 -> 0.87083333 | AA18: =M18-J18 -> -91.803279 | AB18: =M18/J18 -> 0.95409836
A19: 新豐5線 | B19: 微波主食 | C19: 二配金咖哩果香甘口咖哩飯 | E19: 50.92 | F19: 1682 | G19: =E19*F19 -> 85647.44 | I19: 15 | J19: 2000 | K19: =J19/I19 -> 133.33333 | L19: 15 | M19: =F19/V19*60 -> 1904.1509 | N19: =M19/L19 -> 126.9434 | O19: =L19-I19 -> 0 | P19: =N19-K19 -> -6.3899371 | Q19: =N19/K19 -> 0.95207547 | S19: 0.87083333 | T19: 0.90763889 | U19: =IF(S19=TIME(17,0,0),"",(S19-T18)*24*60) -> 57 | V19: =(T19-S19)*24*60 -> 53 | AA19: =M19-J19 -> -95.849057 | AB19: =M19/J19 -> 0.95207547
A20: 新豐5線 | B20: 平均 | I20: 16.75 | J20: 1812.5 | K20: =J20/I20 -> 108.20896 | L20: 16.75 | M20: =AVERAGE(M12:M19) -> 1738.5109 | N20: =M20/L20 -> 103.79169 | O20: =L20-I20 -> 0 | P20: =N20-K20 -> -4.4172609 | Q20: =N20/K20 -> 0.95917842 | AA20: =M20-J20 -> -73.98912 | AB20: =M20/J20 -> 0.95917842
A21: 新豐7線 | B21: 小吃 | C21: 古早味炒炊粉 | E21: 43.14 | F21: 1056 | G21: =E21*F21 -> 45555.84 | I21: 17 | J21: 2000 | K21: =J21/I21 -> 117.64706 | L21: 17 | M21: =F21/V21*60 -> 1920 | N21: =M21/L21 -> 112.94118 | O21: =L21-I21 -> 0 | P21: =N21-K21 -> -4.7058824 | Q21: =N21/K21 -> 0.96 | R21: =Q30 -> 0.96047714 | S21: 0.20833333 | T21: 0.23125 | V21: =(T21-S21)*24*60 -> 33 | AA21: =M21-J21 -> -80 | AB21: =M21/J21 -> 0.96 | AC21: =AB30 -> 0.96047714
A22: 新豐7線 | B22: 熱食義麵 | C22: 麻婆豆腐波浪麵 | E22: 49.9 | F22: 1151 | G22: =E22*F22 -> 57434.9 | I22: 17 | J22: 2000 | K22: =J22/I22 -> 117.64706 | L22: 17 | M22: =F22/V22*60 -> 1918.3333 | N22: =M22/L22 -> 112.84314 | O22: =L22-I22 -> 0 | P22: =N22-K22 -> -4.8039216 | Q22: =N22/K22 -> 0.95916667 | S22: 0.23472222 | T22: 0.25972222 | U22: =IF(S22=TIME(17,0,0),"",(S22-T21)*24*60) -> 5 | V22: =(T22-S22)*24*60 -> 36 | AA22: =M22-J22 -> -81.666667 | AB22: =M22/J22 -> 0.95916667
A23: 新豐7線 | B23: 微波主食 | C23: 鐵板滑蛋炸豬排丼 | E23: 57.73 | F23: 2629 | G23: =E23*F23 -> 151772.17 | I23: 14 | J23: 2000 | K23: =J23/I23 -> 142.85714 | L23: 14 | M23: =F23/V23*60 -> 1923.6585 | N23: =M23/L23 -> 137.40418 | O23: =L23-I23 -> 0 | P23: =N23-K23 -> -5.4529617 | Q23: =N23/K23 -> 0.96182927 | S23: 0.26319444 | T23: 0.32013889 | U23: =IF(S23=TIME(17,0,0),"",(S23-T22)*24*60) -> 5 | V23: =(T23-S23)*24*60 -> 82 | AA23: =M23-J23 -> -76.341463 | AB23: =M23/J23 -> 0.96182927
A24: 新豐7線 | B24: 微波主食 | C24: 極上炙烤親子丼 | E24: 53.68 | F24: 1537 | G24: =E24*F24 -> 82506.16 | I24: 16 | J24: 2000 | K24: =J24/I24 -> 125 | L24: 16 | M24: =F24/V24*60 -> 1921.25 | N24: =M24/L24 -> 120.07813 | O24: =L24-I24 -> 0 | P24: =N24-K24 -> -4.921875 | Q24: =N24/K24 -> 0.960625 | S24: 0.32430556 | T24: 0.35763889 | U24: =IF(S24=TIME(17,0,0),"",(S24-T23)*24*60) -> 6 | V24: =(T24-S24)*24*60 -> 48 | AA24: =M24-J24 -> -78.75 | AB24: =M24/J24 -> 0.960625
A25: 新豐7線 | B25: 微波主食 | C25: 日式野菜烘蛋燴飯 | E25: 49.91 | F25: 903 | G25: =E25*F25 -> 45068.73 | I25: 17 | J25: 2000 | K25: =J25/I25 -> 117.64706 | L25: 17 | M25: =F25/V25*60 -> 1935 | N25: =M25/L25 -> 113.82353 | O25: =L25-I25 -> 0 | P25: =N25-K25 -> -3.8235294 | Q25: =N25/K25 -> 0.9675 | S25: 0.3625 | T25: 0.38194444 | U25: =IF(S25=TIME(17,0,0),"",(S25-T24)*24*60) -> 7 | V25: =(T25-S25)*24*60 -> 28 | AA25: =M25-J25 -> -65 | AB25: =M25/J25 -> 0.9675
A26: 新豐7線 | B26: 微波主食 | C26: 二配川味麻婆燒豆腐燴飯 | E26: 50.49 | F26: 2042 | G26: =E26*F26 -> 103100.58 | I26: 15 | J26: 2000 | K26: =J26/I26 -> 133.33333 | L26: 15 | M26: =F26/V26*60 -> 1914.375 | N26: =M26/L26 -> 127.625 | O26: =L26-I26 -> 0 | P26: =N26-K26 -> -5.7083333 | Q26: =N26/K26 -> 0.9571875 | S26: 0.70833333 | T26: 0.75277778 | U26: =IF(S26=TIME(17,0,0),"",(S26-T25)*24*60) | V26: =(T26-S26)*24*60 -> 64 | AA26: =M26-J26 -> -85.625 | AB26: =M26/J26 -> 0.9571875
A27: 新豐7線 | B27: 微波主食 | C27: 二配粗飽系雞排炒飯(114年) | E27: 57.73 | F27: 1200 | G27: =E27*F27 -> 69276 | I27: 16 | J27: 1500 | K27: =J27/I27 -> 93.75 | L27: 16 | M27: =F27/V27*60 -> 1440 | N27: =M27/L27 -> 90 | O27: =L27-I27 -> 0 | P27: =N27-K27 -> -3.75 | Q27: =N27/K27 -> 0.96 | S27: 0.75625 | T27: 0.79097222 | U27: =IF(S27=TIME(17,0,0),"",(S27-T26)*24*60) -> 5 | V27: =(T27-S27)*24*60 -> 50 | AA27: =M27-J27 -> -60 | AB27: =M27/J27 -> 0.96
A28: 新豐7線 | B28: 微波主食 | C28: 二配起司控培根白醬焗烤飯 | E28: 53.68 | F28: 2000 | G28: =E28*F28 -> 107360 | I28: 16 | J28: 1500 | K28: =J28/I28 -> 93.75 | L28: 16 | M28: =F28/V28*60 -> 1428.5714 | N28: =M28/L28 -> 89.285714 | O28: =L28-I28 -> 0 | P28: =N28-K28 -> -4.4642857 | Q28: =N28/K28 -> 0.95238095 | S28: 0.79583333 | T28: 0.85416667 | U28: =IF(S28=TIME(17,0,0),"",(S28-T27)*24*60) -> 7 | V28: =(T28-S28)*24*60 -> 84 | W28: =T28 -> 0.85416667 | X28: =S29 -> 0.89513889 | AA28: =M28-J28 -> -71.428571 | AB28: =M28/J28 -> 0.95238095
A29: 新豐7線 | B29: 微波主食 | C29: 二配金咖哩濃厚辛口咖哩飯 | E29: 50.98 | F29: 1670 | G29: =E29*F29 -> 85136.6 | I29: 16 | J29: 2000 | K29: =J29/I29 -> 125 | L29: 16 | M29: =F29/V29*60 -> 1926.9231 | N29: =M29/L29 -> 120.43269 | O29: =L29-I29 -> 0 | P29: =N29-K29 -> -4.5673077 | Q29: =N29/K29 -> 0.96346154 | S29: 0.89513889 | T29: 0.93125 | U29: =IF(S29=TIME(17,0,0),"",(S29-T28)*24*60) -> 59 | V29: =(T29-S29)*24*60 -> 52 | AA29: =M29-J29 -> -73.076923 | AB29: =M29/J29 -> 0.96346154
A30: 新豐7線 | B30: 平均 | I30: 16 | J30: 1888.8889 | K30: =J30/I30 -> 118.05556 | L30: 16 | M30: =AVERAGE(M21:M29) -> 1814.2346 | N30: =M30/L30 -> 113.38966 | O30: =L30-I30 -> 0 | P30: =N30-K30 -> -4.6658932 | Q30: =N30/K30 -> 0.96047714 | AA30: =M30-J30 -> -74.654292 | AB30: =M30/J30 -> 0.96047714
A31: 新豐8線 | B31: 三明治 | C31: 紐奧良風味烤雞鮮蔬三明治 | E31: 31.29 | F31: 4900 | G31: =E31*F31 -> 153321 | H31: 2 | I31: 18 | J31: 2400 | K31: =J31/I31 -> 133.33333 | L31: 18 | M31: =F31/V31*60 -> 2296.875 | N31: =M31/L31 -> 127.60417 | O31: =L31-I31 -> 0 | P31: =N31-K31 -> -5.7291667 | Q31: =N31/K31 -> 0.95703125 | R31: =Q37 -> 0.95506229 | S31: 0.083333333 | T31: 0.17222222 | V31: =(T31-S31)*24*60 -> 128 | W31: =T31 -> 0.17222222 | X31: =S32 -> 0.18958333 | AA31: =M31-J31 -> -103.125 | AB31: =M31/J31 -> 0.95703125 | AC31: =AB37 -> 0.95506229
A32: 新豐8線 | B32: 三明治 | C32: 經典總匯三明治 | E32: 26.2 | F32: 4703 | G32: =E32*F32 -> 123218.6 | I32: 20 | J32: 2400 | K32: =J32/I32 -> 120 | L32: 20 | M32: =F32/V32*60 -> 2294.1463 | N32: =M32/L32 -> 114.70732 | O32: =L32-I32 -> 0 | P32: =N32-K32 -> -5.2926829 | Q32: =N32/K32 -> 0.95589431 | S32: 0.18958333 | T32: 0.275 | U32: =(S32-T31)*24*60 -> 25 | V32: =(T32-S32)*24*60 -> 123 | AA32: =M32-J32 -> -105.85366 | AB32: =M32/J32 -> 0.95589431
A33: 新豐8線 | B33: 三明治 | C33: 雞蛋沙拉三明治(114年) | E33: 25.99 | F33: 4265 | G33: =E33*F33 -> 110847.35 | I33: 14 | J33: 2400 | K33: =J33/I33 -> 171.42857 | L33: 14 | M33: =F33/V33*60 -> 2284.8214 | N33: =M33/L33 -> 163.20153 | O33: =L33-I33 -> 0 | P33: =N33-K33 -> -8.2270408 | Q33: =N33/K33 -> 0.95200893 | S33: 0.28055556 | T33: 0.35833333 | U33: =(S33-T32)*24*60 -> 8 | V33: =(T33-S33)*24*60 -> 112 | AA33: =M33-J33 -> -115.17857 | AB33: =M33/J33 -> 0.95200893
A34: 新豐8線 | B34: 三明治 | C34: 肉鬆火腿三明治 | E34: 20.52 | F34: 4156 | G34: =E34*F34 -> 85281.12 | I34: 18 | J34: 2400 | K34: =J34/I34 -> 133.33333 | L34: 18 | M34: =F34/V34*60 -> 2287.7064 | N34: =M34/L34 -> 127.0948 | O34: =L34-I34 -> 0 | P34: =N34-K34 -> -6.2385321 | Q34: =N34/K34 -> 0.95321101 | S34: 0.36388889 | T34: 0.43958333 | U34: =(S34-T33)*24*60 -> 8 | V34: =(T34-S34)*24*60 -> 109 | AA34: =M34-J34 -> -112.29358 | AB34: =M34/J34 -> 0.95321101
A35: 新豐8線 | B35: 三明治 | C35: 好多菜三明治(114年) | E35: 25.98 | F35: 3535 | G35: =E35*F35 -> 91839.3 | I35: 21 | J35: 2400 | K35: =J35/I35 -> 114.28571 | L35: 21 | M35: =F35/V35*60 -> 2305.4348 | N35: =M35/L35 -> 109.78261 | O35: =L35-I35 -> 0 | P35: =N35-K35 -> -4.5031056 | Q35: =N35/K35 -> 0.96059783 | S35: 0.44375 | T35: 0.50763889 | U35: =(S35-T34)*24*60 -> 6 | V35: =(T35-S35)*24*60 -> 92 | W35: =T35 -> 0.50763889 | X35: =S36 -> 0.55 | AA35: =M35-J35 -> -94.565217 | AB35: =M35/J35 -> 0.96059783
A36: 新豐8線 | B36: 三明治 | C36: 紐奧良風味烤雞鮮蔬三明治 | E36: 31.29 | F36: 3502 | G36: =E36*F36 -> 109577.58 | I36: 18 | J36: 2400 | K36: =J36/I36 -> 133.33333 | L36: 18 | M36: =F36/V36*60 -> 2283.913 | N36: =M36/L36 -> 126.88406 | O36: =L36-I36 -> 0 | P36: =N36-K36 -> -6.4492754 | Q36: =N36/K36 -> 0.95163043 | S36: 0.55 | T36: 0.61388889 | U36: =(S36-T35)*24*60 -> 61 | V36: =(T36-S36)*24*60 -> 92 | AA36: =M36-J36 -> -116.08696 | AB36: =M36/J36 -> 0.95163043
A37: 新豐8線 | B37: 平均 | I37: 18.166667 | J37: 2400 | K37: =J37/I37 -> 132.11009 | L37: 18.166667 | M37: =AVERAGE(M31:M36) -> 2292.1495 | N37: =M37/L37 -> 126.17337 | O37: =L37-I37 -> 0 | P37: =N37-K37 -> -5.9367246 | Q37: =N37/K37 -> 0.95506229 | AA37: =M37-J37 -> -107.8505 | AB37: =M37/J37 -> 0.95506229
A38: 新豐9線 | B38: 三明治 | C38: 檸檬紅茶三明治 | E38: 22.69 | F38: 1135 | G38: =E38*F38 -> 25753.15 | I38: 15 | J38: 2400 | K38: =J38/I38 -> 160 | L38: 15 | M38: =F38/V38*60 -> 2348.2759 | N38: =M38/L38 -> 156.55172 | O38: =L38-I38 -> 0 | P38: =N38-K38 -> -3.4482759 | Q38: =N38/K38 -> 0.97844828 | R38: =Q45 -> 0.96209351 | S38: 0.083333333 | T38: 0.10347222 | V38: =(T38-S38)*24*60 -> 29 | W38: =T38 -> 0.10347222 | X38: =S39 -> 0.12361111 | AA38: =M38-J38 -> -51.724138 | AB38: =M38/J38 -> 0.97844828 | AC38: =AB45 -> 0.96209351
A39: 新豐9線 | B39: 三明治 | C39: 鮪魚起司溏心蛋三明治 | E39: 26.2 | F39: 5978 | G39: =E39*F39 -> 156623.6 | I39: 18 | J39: 2400 | K39: =J39/I39 -> 133.33333 | L39: 18 | M39: =F39/V39*60 -> 2284.586 | N39: =M39/L39 -> 126.92144 | O39: =L39-I39 -> 0 | P39: =N39-K39 -> -6.4118896 | Q39: =N39/K39 -> 0.95191083 | S39: 0.12361111 | T39: 0.23263889 | U39: =(S39-T38)*24*60 -> 29 | V39: =(T39-S39)*24*60 -> 157 | AA39: =M39-J39 -> -115.41401 | AB39: =M39/J39 -> 0.95191083
A40: 新豐9線 | B40: 三明治 | C40: 陽光地瓜總匯三明治 | E40: 26.18 | F40: 2249 | G40: =E40*F40 -> 58878.82 | I40: 19 | J40: 2400 | K40: =J40/I40 -> 126.31579 | L40: 19 | M40: =F40/V40*60 -> 2287.1186 | N40: =M40/L40 -> 120.37467 | O40: =L40-I40 -> 0 | P40: =N40-K40 -> -5.941124 | Q40: =N40/K40 -> 0.9529661 | S40: 0.23819444 | T40: 0.27916667 | U40: =(S40-T39)*24*60 -> 8 | V40: =(T40-S40)*24*60 -> 59 | AA40: =M40-J40 -> -112.88136 | AB40: =M40/J40 -> 0.9529661
...

Sheet 1229
B1: 屏榮 新豐廠組合室生產人時性分析
B3: 日期 | C3: =TEXT('1229 4度C'!A2,"yyyy.mm.ddaaaa") -> 2025.12.29星期一 | E3: 訂單量 | F3: ='1229 4度C'!D1 -> 176087 | H3: 營業額 | I3: ='1229 4度C'!F1 -> 6065182
B4: 人時性 | C4: 項目 | E4: ➀ | G4: ➁ | I4: ➂
C5: 組合室 | E5: 全溫層 | G5: 4度C-各編組展開 | I5: ③三明治-各編組展開
C6: 排關平均 | E6: =AVERAGE(D13:M13) -> 147.36424 | F6: =AVERAGE(D27:O27,D13:J13) -> 151.1162 | G6: =AVERAGE(D13:J13) -> 151.1162 | I6: =AVERAGE(K13:M13) -> 138.60967
C7: 實績平均 | E7: =AVERAGE(D14:M14) -> 140.46116 | F7: =AVERAGE(D28:O28,D14:J14) -> 143.80833 | G7: =AVERAGE(D14:J14) -> 143.80833 | I7: =AVERAGE(K14:M14) -> 132.6511
C8: 達成率平均 | E8: =AVERAGE(D15:M15) -> 0.95154561 | F8: =AVERAGE(D15:J15,D29:O29) -> 0.94918505 | G8: =AVERAGE(D15:J15) -> 0.94918505 | I8: =AVERAGE(K15:M15) -> 0.95705359 | K8: ※現行日本鮮食廠以達成率80%為基本(即為現行KPI)
B10: 溫層 | D10: ➁4度C-各編組展開 | K10: ③三明治-各編組展開
B11: 編組 | D11: 1 | E11: 2 | F11: 3 | G11: 4 | H11: 5 | I11: 6 | J11: 7 | K11: 1 | L11: 2 | M11: 3
D12: 新豐6線 | E12: 新豐2線 | F12: 新豐5線 | G12: 新豐7線 | H12: 新豐3線 | I12: 新豐1線 | J12: 新豐10線 | K12: 新豐8線 | L12: 新豐9線 | M12: 新豐4線
B13: 人時性 | C13: 排關 | D13: =SUMIFS('1229 4度C'!$K:$K,'1229 4度C'!$A:$A,"新豐6線",'1229 4度C'!$B:$B,"平均") -> 115.38462 | E13: =SUMIFS('1229 4度C'!$K:$K,'1229 4度C'!$A:$A,"新豐2線",'1229 4度C'!$B:$B,"平均") -> 83.333333 | F13: =SUMIFS('1229 4度C'!$K:$K,'1229 4度C'!$A:$A,"新豐5線",'1229 4度C'!$B:$B,"平均") -> 110 | G13: =SUMIFS('1229 4度C'!$K:$K,'1229 4度C'!$A:$A,"新豐7線",'1229 4度C'!$B:$B,"平均") -> 114.58333 | H13: =SUMIFS('1229 4度C'!$K:$K,'1229 4度C'!$A:$A,"新豐3線",'1229 4度C'!$B:$B,"平均") -> 235.29412 | I13: =SUMIFS('1229 4度C'!$K:$K,'1229 4度C'!$A:$A,"新豐1線",'1229 4度C'!$B:$B,"平均") -> 104.57516 | J13: =SUMIFS('1229 4度C'!$K:$K,'1229 4度C'!$A:$A,"新豐10線",'1229 4度C'!$B:$B,"平均") -> 294.64286 | K13: =SUMIFS('1229 4度C'!$K:$K,'1229 4度C'!$A:$A,"新豐8線",'1229 4度C'!$B:$B,"平均") -> 130.23256 | L13: =SUMIFS('1229 4度C'!$K:$K,'1229 4度C'!$A:$A,"新豐9線",'1229 4度C'!$B:$B,"平均") -> 137.14286 | M13: =SUMIFS('1229 4度C'!$K:$K,'1229 4度C'!$A:$A,"新豐4線",'1229 4度C'!$B:$B,"平均") -> 148.45361
C14: 實績 | D14: =SUMIFS('1229 4度C'!$N:$N,'1229 4度C'!$A:$A,"新豐6線",'1229 4度C'!$B:$B,"平均") -> 110.69286 | E14: =SUMIFS('1229 4度C'!$N:$N,'1229 4度C'!$A:$A,"新豐2線",'1229 4度C'!$B:$B,"平均") -> 79.525057 | F14: =SUMIFS('1229 4度C'!$N:$N,'1229 4度C'!$A:$A,"新豐5線",'1229 4度C'!$B:$B,"平均") -> 105.78237 | G14: =SUMIFS('1229 4度C'!$N:$N,'1229 4度C'!$A:$A,"新豐7線",'1229 4度C'!$B:$B,"平均") -> 110.25185 | H14: =SUMIFS('1229 4度C'!$N:$N,'1229 4度C'!$A:$A,"新豐3線",'1229 4度C'!$B:$B,"平均") -> 224.70764 | I14: =SUMIFS('1229 4度C'!$N:$N,'1229 4度C'!$A:$A,"新豐1線",'1229 4度C'!$B:$B,"平均") -> 93.489424 | J14: =SUMIFS('1229 4度C'!$N:$N,'1229 4度C'!$A:$A,"新豐10線",'1229 4度C'!$B:$B,"平均") -> 282.2091 | K14: =SUMIFS('1229 4度C'!$N:$N,'1229 4度C'!$A:$A,"新豐8線",'1229 4度C'!$B:$B,"平均") -> 124.51899 | L14: =SUMIFS('1229 4度C'!$N:$N,'1229 4度C'!$A:$A,"新豐9線",'1229 4度C'!$B:$B,"平均") -> 131.66824 | M14: =SUMIFS('1229 4度C'!$N:$N,'1229 4度C'!$A:$A,"新豐4線",'1229 4度C'!$B:$B,"平均") -> 141.76606
C15: 達成率 | D15: =D14/D13 -> 0.9593381 | E15: =E14/E13 -> 0.95430068 | F15: =F14/F13 -> 0.96165792 | G15: =G14/G13 -> 0.96219796 | H15: =H14/H13 -> 0.95500749 | I15: =I14/I13 -> 0.89399262 | J15: =J14/J13 -> 0.95780059 | K15: =K14/K13 -> 0.95612793 | ... M15: =M14/M13 -> 0.95495195
B16: 作業 時間 | C16: 開始 | D16: =VLOOKUP("新豐6線",'1229 4度C'!$A:$T,19,0) -> 0.70833333 | E16: =VLOOKUP("新豐2線",'1229 4度C'!$A:$T,19,0) -> 0.16666667 | F16: =VLOOKUP("新豐5線",'1229 4度C'!$A:$T,19,0) -> 0.20833333 | G16: =VLOOKUP("新豐7線",'1229 4度C'!$A:$T,19,0) -> 0.20833333 | H16: =VLOOKUP("新豐3線",'1229 4度C'!$A:$T,19,0) -> 0.083333333 | I16: =VLOOKUP("新豐1線",'1229 4度C'!$A:$T,19,0) -> 0.20833333 | J16: =VLOOKUP("新豐10線",'1229 4度C'!$A:$T,19,0) -> 0.20833333 | K16: =VLOOKUP("新豐8線",'1229 4度C'!$A:$T,19,0) -> 0.083333333 | L16: =VLOOKUP("新豐9線",'1229 4度C'!$A:$T,19,0) -> 0.083333333 | M16: =VLOOKUP("新豐4線",'1229 4度C'!$A:$T,19,0) -> 0.083333333
C17: 結束 | D17: =LOOKUP(2,1/(('1229 4度C'!$A:$A="新豐6線")*('1229 4度C'!$T:$T<>"")),'1229 4度C'!$T:$T) -> 0.82777778 | E17: =LOOKUP(2,1/(('1229 4度C'!$A:$A="新豐2線")*('1229 4度C'!$T:$T<>"")),'1229 4度C'!$T:$T) -> 0.46388889 | F17: =LOOKUP(2,1/(('1229 4度C'!$A:$A="新豐5線")*('1229 4度C'!$T:$T<>"")),'1229 4度C'!$T:$T) -> 0.96180556 | G17: =LOOKUP(2,1/(('1229 4度C'!$A:$A="新豐7線")*('1229 4度C'!$T:$T<>"")),'1229 4度C'!$T:$T) -> 0.90902778 | H17: =LOOKUP(2,1/(('1229 4度C'!$A:$A="新豐3線")*('1229 4度C'!$T:$T<>"")),'1229 4度C'!$T:$T) -> 0.50763889 | I17: =LOOKUP(2,1/(('1229 4度C'!$A:$A="新豐1線")*('1229 4度C'!$T:$T<>"")),'1229 4度C'!$T:$T) -> 0.94930556 | J17: =LOOKUP(2,1/(('1229 4度C'!$A:$A="新豐10線")*('1229 4度C'!$T:$T<>"")),'1229 4度C'!$T:$T) -> 0.48541667 | K17: =LOOKUP(2,1/(('1229 4度C'!$A:$A="新豐8線")*('1229 4度C'!$T:$T<>"")),'1229 4度C'!$T:$T) -> 0.65972222 | L17: =LOOKUP(2,1/(('1229 4度C'!$A:$A="新豐9線")*('1229 4度C'!$T:$T<>"")),'1229 4度C'!$T:$T) -> 0.58472222 | M17: =LOOKUP(2,1/(('1229 4度C'!$A:$A="新豐4線")*('1229 4度C'!$T:$T<>"")),'1229 4度C'!$T:$T) -> 0.65416667
B18: 配置人數 | D18: =SUMIFS('1229 4度C'!$I:$I,'1229 4度C'!$A:$A,"新豐6線",'1229 4度C'!$B:$B,"平均") -> 17.333333 | E18: =SUMIFS('1229 4度C'!$I:$I,'1229 4度C'!$A:$A,"新豐2線",'1229 4度C'!$B:$B,"平均") -> 18 | F18: =SUMIFS('1229 4度C'!$I:$I,'1229 4度C'!$A:$A,"新豐5線",'1229 4度C'!$B:$B,"平均") -> 16.666667 | G18: =SUMIFS('1229 4度C'!$I:$I,'1229 4度C'!$A:$A,"新豐7線",'1229 4度C'!$B:$B,"平均") -> 16 | H18: =SUMIFS('1229 4度C'!$I:$I,'1229 4度C'!$A:$A,"新豐3線",'1229 4度C'!$B:$B,"平均") -> 11.333333 | I18: =SUMIFS('1229 4度C'!$I:$I,'1229 4度C'!$A:$A,"新豐1線",'1229 4度C'!$B:$B,"平均") -> 19.125 | J18: =SUMIFS('1229 4度C'!$I:$I,'1229 4度C'!$A:$A,"新豐10線",'1229 4度C'!$B:$B,"平均") -> 9.3333333 | K18: =SUMIFS('1229 4度C'!$I:$I,'1229 4度C'!$A:$A,"新豐8線",'1229 4度C'!$B:$B,"平均") -> 18.428571 | L18: =SUMIFS('1229 4度C'!$I:$I,'1229 4度C'!$A:$A,"新豐9線",'1229 4度C'!$B:$B,"平均") -> 17.5 | M18: =SUMIFS('1229 4度C'!$I:$I,'1229 4度C'!$A:$A,"新豐4線",'1229 4度C'!$B:$B,"平均") -> 16.166667
B19: 主要應用設備 | D19: ET-55 | E19: 熱縮爐 | F19: L型包裝機 | G19: L型包裝機 | H19: 伺服包裝機 | I19: ET-55 | J19: 伺服包裝機 | K19: 三明治包裝機 | L19: 三明治包裝機 | M19: 三明治包裝機
B20: 次要應用設備 | F20: 圓盤機 | G20: ET-55
B21: 備註 | E21: 握沙拉 | F21: 共用L型包裝機 | H21: 調理麵包 | I21: 炒飯+沙拉 | J21: 調理麵包

Sheet 1229 4度C
A1: 新豐廠四度C日報分析 | C1: 總生產量 | D1: 176087 | E1: 營業額 | F1: 6065182 | G1: 出勤人數 | H1: =L8+L11+L55+L64+L21+L71+L39+L48+L31+L78 -> 159.8869 | I1: 產線配置圖 | L1: 生產實績 | O1: 人時性差異分析 | S1: 日報登錄 | Y1: 分析說明 | AA1: 產能差異分析
A2: 46020 | B2: 星期一 | C2: 人時性 | D2: 140.46116 | E2: 平均廠價 | F2: 34.444235 | G2: 多次生產數 | H2: =COUNT(H5:H78) -> 8
A3: 線別 | B3: 品類 | C3: 品名 | E3: 廠價 | F3: 生產量 | G3: 營收 | H3: 多次 生產 | I3: 人數 | J3: 產能/時 | K3: 人時性 | L3: 人數 | M3: 產能/時 | N3: 人時性 | O3: 人數 | P3: 人時性 | Q3: 達成率 | R3: 達成率平均 | S3: 生產時間 | U3: 換線、休息/分 | V3: 稼動時間/分 | W3: 休息時間 | Y3: (新豐回填) | AA3: 產能/時 | AB3: 達成率 | AC3: 達成率平均
S4: 開始 | T4: 結束 | W4: 開始 | X4: 結束
A5: 新豐6線 | B5: 微波主食 | C5: 二配港式香滑嫩蛋牛肉燴飯 | E5: 50.67 | F5: 1507 | G5: =E5*F5 -> 76359.69 | I5: 17 | J5: 2000 | K5: =J5/I5 -> 117.64706 | L5: 17 | M5: =F5/V5*60 -> 1923.8298 | N5: =M5/L5 -> 113.16646 | O5: =L5-I5 -> 0 | P5: =N5-K5 -> -4.4806008 | Q5: =N5/K5 -> 0.96191489 | R5: =Q8 -> 0.9593381 | S5: 0.70833333 | T5: 0.74097222 | V5: =(T5-S5)*24*60 -> 47 | AA5: =M5-J5 -> -76.170213 | AB5: =M5/J5 -> 0.96191489 | AC5: =AB8 -> 0.9593381
A6: 新豐6線 | B6: 微波主食 | C6: 二配美味蟹煲 | E6: 54.09 | F6: 1564 | G6: =E6*F6 -> 84596.76 | I6: 19 | J6: 2000 | K6: =J6/I6 -> 105.26316 | L6: 19 | M6: =F6/V6*60 -> 1915.102 | N6: =M6/L6 -> 100.79484 | O6: =L6-I6 -> 0 | P6: =N6-K6 -> -4.4683136 | Q6: =N6/K6 -> 0.95755102 | S6: 0.74652778 | T6: 0.78055556 | U6: =IF(S6=TIME(17,0,0),"",(S6-T5)*24*60) -> 8 | V6: =(T6-S6)*24*60 -> 49 | AA6: =M6-J6 -> -84.897959 | AB6: =M6/J6 -> 0.95755102
A7: 新豐6線 | B7: 微波主食 | C7: 二配麻油雞燴飯 | E7: 50.29 | F7: 1981 | G7: =E7*F7 -> 99624.49 | I7: 16 | J7: 2000 | K7: =J7/I7 -> 125 | L7: 16 | M7: =F7/V7*60 -> 1917.0968 | N7: =M7/L7 -> 119.81855 | O7: =L7-I7 -> 0 | P7: =N7-K7 -> -5.1814516 | Q7: =N7/K7 -> 0.95854839 | S7: 0.78472222 | T7: 0.82777778 | U7: =IF(S7=TIME(17,0,0),"",(S7-T6)*24*60) -> 6 | V7: =(T7-S7)*24*60 -> 62 | AA7: =M7-J7 -> -82.903226 | AB7: =M7/J7 -> 0.95854839
A8: 新豐6線 | B8: 平均 | I8: 17.333333 | J8: 2000 | K8: =J8/I8 -> 115.38462 | L8: 17.333333 | M8: =AVERAGE(M5:M7) -> 1918.6762 | N8: =M8/L8 -> 110.69286 | O8: =L8-I8 -> 0 | P8: =N8-K8 -> -4.6917576 | Q8: =N8/K8 -> 0.9593381 | AA8: =M8-J8 -> -81.323799 | AB8: =M8/J8 -> 0.9593381
A9: 新豐2線 | B9: 沙拉 | C9: 青醬優格雞肉握沙拉(113年) | E9: 39.62 | F9: 3780 | G9: =E9*F9 -> 149763.6 | I9: 19 | J9: 1500 | K9: =J9/I9 -> 78.947368 | L9: 19 | M9: =F9/V9*60 -> 1435.443 | N9: =M9/L9 -> 75.549634 | O9: =L9-I9 -> 0 | P9: =N9-K9 -> -3.3977348 | Q9: =N9/K9 -> 0.95696203 | R9: =Q11 -> 0.95430068 | S9: 0.16666667 | T9: 0.27638889 | V9: =(T9-S9)*24*60 -> 158 | W9: =T9 -> 0.27638889 | X9: =S10 -> 0.29444444 | AA9: =M9-J9 -> -64.556962 | AB9: =M9/J9 -> 0.95696203 | AC9: =AB11 -> 0.95430068
A10: 新豐2線 | B10: 沙拉 | C10: 青檸烤雞握沙拉(113年) | E10: 39.8 | F10: 5805 | G10: =E10*F10 -> 231039 | I10: 17 | J10: 1500 | K10: =J10/I10 -> 88.235294 | L10: 17 | M10: =F10/V10*60 -> 1427.459 | N10: =M10/L10 -> 83.968177 | O10: =L10-I10 -> 0 | P10: =N10-K10 -> -4.2671167 | Q10: =N10/K10 -> 0.95163934 | S10: 0.29444444 | T10: 0.46388889 | U10: =IF(S10=TIME(17,0,0),"",(S10-T9)*24*60) -> 26 | V10: =(T10-S10)*24*60 -> 244 | AA10: =M10-J10 -> -72.540984 | AB10: =M10/J10 -> 0.95163934
A11: 新豐2線 | B11: 平均 | I11: 18 | J11: 1500 | K11: =J11/I11 -> 83.333333 | L11: 18 | M11: =AVERAGE(M9:M10) -> 1431.451 | N11: =M11/L11 -> 79.525057 | O11: =L11-I11 -> 0 | P11: =N11-K11 -> -3.8082763 | Q11: =N11/K11 -> 0.95430068 | AA11: =M11-J11 -> -68.548973 | AB11: =M11/J11 -> 0.95430068
A12: 新豐5線 | B12: 小吃 | C12: 剝皮辣椒雞湯 | E12: 41 | F12: 2411 | G12: =E12*F12 -> 98851 | I12: 26 | J12: 1500 | K12: =J12/I12 -> 57.692308 | L12: 26 | M12: =F12/V12*60 -> 1432.2772 | N12: =M12/L12 -> 55.087586 | O12: =L12-I12 -> 0 | P12: =N12-K12 -> -2.604722 | Q12: =N12/K12 -> 0.95485149 | R12: =Q21 -> 0.96165792 | S12: 0.20833333 | T12: 0.27847222 | V12: =(T12-S12)*24*60 -> 101 | AA12: =M12-J12 -> -67.722772 | AB12: =M12/J12 -> 0.95485149 | AC12: =AB21 -> 0.96165792
A13: 新豐5線 | B13: 季節調理麵 | C13: 柚子雞白湯拉麵 | E13: 72.4 | F13: 1160 | G13: =E13*F13 -> 83984 | I13: 18 | J13: 1500 | K13: =J13/I13 -> 83.333333 | L13: 18 | M13: =F13/V13*60 -> 1450 | N13: =M13/L13 -> 80.555556 | O13: =L13-I13 -> 0 | P13: =N13-K13 -> -2.7777778 | Q13: =N13/K13 -> 0.96666667 | S13: 0.28194444 | T13: 0.31527778 | U13: =IF(S13=TIME(17,0,0),"",(S13-T12)*24*60) -> 5 | V13: =(T13-S13)*24*60 -> 48 | AA13: =M13-J13 -> -50 | AB13: =M13/J13 -> 0.96666667
A14: 新豐5線 | B14: 熱食義麵 | C14: 焗烤起司肉醬筆尖麵 | E14: 50.67 | F14: 1622 | G14: =E14*F14 -> 82186.74 | I14: 16 | J14: 1500 | K14: =J14/I14 -> 93.75 | L14: 16 | M14: =F14/V14*60 -> 1431.1765 | N14: =M14/L14 -> 89.448529 | O14: =L14-I14 -> 0 | P14: =N14-K14 -> -4.3014706 | Q14: =N14/K14 -> 0.95411765 | S14: 0.32083333 | T14: 0.36805556 | U14: =IF(S14=TIME(17,0,0),"",(S14-T13)*24*60) -> 8 | V14: =(T14-S14)*24*60 -> 68 | AA14: =M14-J14 -> -68.823529 | AB14: =M14/J14 -> 0.95411765
A15: 新豐5線 | B15: 微波主食 | C15: 二配金咖哩濃厚辛口咖哩飯 | E15: 50.98 | F15: 800 | G15: =E15*F15 -> 40784 | H15: 2 | I15: 16 | J15: 2000 | K15: =J15/I15 -> 125 | L15: 16 | M15: =F15/V15*60 -> 1920 | N15: =M15/L15 -> 120 | O15: =L15-I15 -> 0 | P15: =N15-K15 -> -5 | Q15: =N15/K15 -> 0.96 | S15: 0.70833333 | T15: 0.72569444 | U15: =IF(S15=TIME(17,0,0),"",(S15-T14)*24*60) | V15: =(T15-S15)*24*60 -> 25 | AA15: =M15-J15 -> -80 | AB15: =M15/J15 -> 0.96
A16: 新豐5線 | B16: 微波主食 | C16: 二配金咖哩果香甘口咖哩飯 | E16: 50.92 | F16: 800 | G16: =E16*F16 -> 40736 | H16: 2 | I16: 15 | J16: 2000 | K16: =J16/I16 -> 133.33333 | L16: 15 | M16: =F16/V16*60 -> 1920 | N16: =M16/L16 -> 128 | O16: =L16-I16 -> 0 | P16: =N16-K16 -> -5.3333333 | Q16: =N16/K16 -> 0.96 | S16: 0.72916667 | T16: 0.74652778 | U16: =IF(S16=TIME(17,0,0),"",(S16-T15)*24*60) -> 5 | V16: =(T16-S16)*24*60 -> 25 | AA16: =M16-J16 -> -80 | AB16: =M16/J16 -> 0.96
A17: 新豐5線 | B17: 微波主食 | C17: 二配泰式綠咖哩雞 | E17: 50.67 | F17: 1681 | G17: =E17*F17 -> 85176.27 | I17: 15 | J17: 2000 | K17: =J17/I17 -> 133.33333 | L17: 15 | M17: =F17/V17*60 -> 1939.6154 | N17: =M17/L17 -> 129.30769 | O17: =L17-I17 -> 0 | P17: =N17-K17 -> -4.025641 | Q17: =N17/K17 -> 0.96980769 | S17: 0.75 | T17: 0.78611111 | U17: =IF(S17=TIME(17,0,0),"",(S17-T16)*24*60) -> 5 | V17: =(T17-S17)*24*60 -> 52 | AA17: =M17-J17 -> -60.384615 | AB17: =M17/J17 -> 0.96980769
A18: 新豐5線 | B18: 微波主食 | C18: 二配厚香料咖哩雞排飯 | E18: 57.3 | F18: 2212 | G18: =E18*F18 -> 126747.6 | I18: 13 | J18: 2000 | K18: =J18/I18 -> 153.84615 | L18: 13 | M18: =F18/V18*60 -> 1923.4783 | N18: =M18/L18 -> 147.95987 | O18: =L18-I18 -> 0 | P18: =N18-K18 -> -5.8862876 | Q18: =N18/K18 -> 0.96173913 | S18: 0.79027778 | T18: 0.83819444 | U18: =IF(S18=TIME(17,0,0),"",(S18-T17)*24*60) -> 6 | V18: =(T18-S18)*24*60 -> 69 | W18: =T18 -> 0.83819444 | X18: =S19 -> 0.87916667 | AA18: =M18-J18 -> -76.521739 | AB18: =M18/J18 -> 0.96173913
A19: 新豐5線 | B19: 微波主食 | C19: 二配金咖哩濃厚辛口咖哩飯 | E19: 50.98 | F19: 1819 | G19: =E19*F19 -> 92732.62 | I19: 16 | J19: 2000 | K19: =J19/I19 -> 125 | L19: 16 | M19: =F19/V19*60 -> 1914.7368 | N19: =M19/L19 -> 119.67105 | O19: =L19-I19 -> 0 | P19: =N19-K19 -> -5.3289474 | Q19: =N19/K19 -> 0.95736842 | S19: 0.87916667 | T19: 0.91875 | U19: =IF(S19=TIME(17,0,0),"",(S19-T18)*24*60) -> 59 | V19: =(T19-S19)*24*60 -> 57 | AA19: =M19-J19 -> -85.263158 | AB19: =M19/J19 -> 0.95736842
A20: 新豐5線 | B20: 微波主食 | C20: 二配金咖哩果香甘口咖哩飯 | E20: 50.92 | F20: 1807 | G20: =E20*F20 -> 92012.44 | I20: 15 | J20: 2000 | K20: =J20/I20 -> 133.33333 | L20: 15 | M20: =F20/V20*60 -> 1936.0714 | N20: =M20/L20 -> 129.07143 | O20: =L20-I20 -> 0 | P20: =N20-K20 -> -4.2619048 | Q20: =N20/K20 -> 0.96803571 | S20: 0.92291667 | T20: 0.96180556 | U20: =IF(S20=TIME(17,0,0),"",(S20-T19)*24*60) -> 6 | V20: =(T20-S20)*24*60 -> 56 | AA20: =M20-J20 -> -63.928571 | AB20: =M20/J20 -> 0.96803571
A21: 新豐5線 | B21: 平均 | I21: 16.666667 | J21: 1833.3333 | K21: =J21/I21 -> 110 | L21: 16.666667 | M21: =AVERAGE(M12:M20) -> 1763.0395 | N21: =M21/L21 -> 105.78237 | O21: =L21-I21 -> 0 | P21: =N21-K21 -> -4.2176292 | Q21: =N21/K21 -> 0.96165792 | AA21: =M21-J21 -> -70.293821 | AB21: =M21/J21 -> 0.96165792
A22: 新豐7線 | B22: 小吃 | C22: 古早味炒炊粉 | E22: 43.14 | F22: 1171 | G22: =E22*F22 -> 50516.94 | I22: 17 | J22: 2000 | K22: =J22/I22 -> 117.64706 | L22: 17 | M22: =F22/V22*60 -> 1951.6667 | N22: =M22/L22 -> 114.80392 | O22: =L22-I22 -> 0 | P22: =N22-K22 -> -2.8431373 | Q22: =N22/K22 -> 0.97583333 | R22: =Q31 -> 0.96219796 | S22: 0.20833333 | T22: 0.23333333 | V22: =(T22-S22)*24*60 -> 36 | AA22: =M22-J22 -> -48.333333 | AB22: =M22/J22 -> 0.97583333 | AC22: =AB31 -> 0.96219796
