Workbook

Sheet 0731
B1: 屏榮 新豐廠組合室生產人時性分析
B3: 日期 | C3: =TEXT('0731 4度C'!A2,"yyyy.mm.ddaaaa") -> 2025.07.31星期四 | E3: 訂單量 | F3: ='0731 4度C'!D1 -> 152356 | H3: 營業額 | I3: ='0731 4度C'!F1 -> 5197137.5
B4: 人時性 | C4: 項目 | E4: ➀ | G4: ➁ | I4: ➂
C5: 組合室 | E5: 全溫層 | G5: 4度C-各編組展開 | I5: ③三明治-各編組展開
C6: 排關平均 | E6: =AVERAGE(D13:M13) -> 142.20317 | F6: =AVERAGE(D27:O27,D13:J13) -> 145.01729 | G6: =AVERAGE(D13:J13) -> 145.01729 | I6: =AVERAGE(K13:M13) -> 135.63691
C7: 實績平均 | E7: =AVERAGE(D14:M14) -> 130.65572 | F7: =AVERAGE(D28:O28,D14:J14) -> 133.34696 | G7: =AVERAGE(D14:J14) -> 133.34696 | I7: =AVERAGE(K14:M14) -> 124.37617
C8: 達成率平均 | E8: =AVERAGE(D15:M15) -> 0.91882064 | F8: =AVERAGE(D15:J15,D29:O29) -> 0.91962653 | G8: =AVERAGE(D15:J15) -> 0.91962653 | I8: =AVERAGE(K15:M15) -> 0.91694021 | K8: ※現行日本鮮食廠以達成率80%為基本(即為現行KPI)
B10: 溫層 | D10: ➁4度C-各編組展開 | K10: ③三明治-各編組展開
B11: 編組 | D11: 1 | E11: 2 | F11: 3 | G11: 4 | H11: 5 | I11: 6 | J11: 7 | K11: 1 | L11: 2 | M11: 3
D12: 燴飯線 | E12: 沙拉一線 | F12: 沙拉二線 | G12: 沙拉三線 | H12: 自動包裝線 | I12: 涼麵一線 | J12: 三明治四線 | K12: 三明治一線 | L12: 三明治二線 | M12: 自動包裝二線
B13: 人時性 | C13: 排關 | D13: =SUMIFS('0731 4度C'!$K:$K,'0731 4度C'!$A:$A,"燴飯線",'0731 4度C'!$B:$B,"平均") -> 105.88235 | E13: =SUMIFS('0731 4度C'!$K:$K,'0731 4度C'!$A:$A,"沙拉線一線",'0731 4度C'!$B:$B,"平均") -> 81.081081 | F13: =SUMIFS('0731 4度C'!$K:$K,'0731 4度C'!$A:$A,"沙拉線二線",'0731 4度C'!$B:$B,"平均") -> 81.298969 | G13: =SUMIFS('0731 4度C'!$K:$K,'0731 4度C'!$A:$A,"沙拉線三線",'0731 4度C'!$B:$B,"平均") -> 104.19162 | H13: =SUMIFS('0731 4度C'!$K:$K,'0731 4度C'!$A:$A,"自動包裝線",'0731 4度C'!$B:$B,"平均") -> 300 | I13: =SUMIFS('0731 4度C'!$K:$K,'0731 4度C'!$A:$A,"涼麵一線",'0731 4度C'!$B:$B,"平均") -> 89.552239 | J13: =SUMIFS('0731 4度C'!$K:$K,'0731 4度C'!$A:$A,"三明治四線",'0731 4度C'!$B:$B,"平均") -> 253.11475 | K13: =SUMIFS('0731 4度C'!$K:$K,'0731 4度C'!$A:$A,"三明治一線",'0731 4度C'!$B:$B,"平均") -> 138.46154 | L13: =SUMIFS('0731 4度C'!$K:$K,'0731 4度C'!$A:$A,"三明治二線",'0731 4度C'!$B:$B,"平均") -> 127.27273 | M13: =SUMIFS('0731 4度C'!$K:$K,'0731 4度C'!$A:$A,"自動包裝二線",'0731 4度C'!$B:$B,"平均") -> 141.17647
C14: 實績 | D14: =SUMIFS('0731 4度C'!$N:$N,'0731 4度C'!$A:$A,"燴飯線",'0731 4度C'!$B:$B,"平均") -> 98.135169 | E14: =SUMIFS('0731 4度C'!$N:$N,'0731 4度C'!$A:$A,"沙拉線一線",'0731 4度C'!$B:$B,"平均") -> 74.18448 | F14: =SUMIFS('0731 4度C'!$N:$N,'0731 4度C'!$A:$A,"沙拉線二線",'0731 4度C'!$B:$B,"平均") -> 74.786701 | G14: =SUMIFS('0731 4度C'!$N:$N,'0731 4度C'!$A:$A,"沙拉線三線",'0731 4度C'!$B:$B,"平均") -> 96.152448 | H14: =SUMIFS('0731 4度C'!$N:$N,'0731 4度C'!$A:$A,"自動包裝線",'0731 4度C'!$B:$B,"平均") -> 275.42494 | I14: =SUMIFS('0731 4度C'!$N:$N,'0731 4度C'!$A:$A,"涼麵一線",'0731 4度C'!$B:$B,"平均") -> 81.94436 | J14: =SUMIFS('0731 4度C'!$N:$N,'0731 4度C'!$A:$A,"三明治四線",'0731 4度C'!$B:$B,"平均") -> 232.80063 | K14: =SUMIFS('0731 4度C'!$N:$N,'0731 4度C'!$A:$A,"三明治一線",'0731 4度C'!$B:$B,"平均") -> 126.98175 | L14: =SUMIFS('0731 4度C'!$N:$N,'0731 4度C'!$A:$A,"三明治二線",'0731 4度C'!$B:$B,"平均") -> 116.55421 | M14: =SUMIFS('0731 4度C'!$N:$N,'0731 4度C'!$A:$A,"自動包裝二線",'0731 4度C'!$B:$B,"平均") -> 129.59254
C15: 達成率 | D15: =D14/D13 -> 0.92683215 | E15: =E14/E13 -> 0.91494192 | F15: =F14/F13 -> 0.91989729 | G15: =G14/G13 -> 0.92284246 | H15: =H14/H13 -> 0.91808313 | I15: =I14/I13 -> 0.91504535 | J15: =J14/J13 -> 0.91974344 | K15: =K14/K13 -> 0.91709041 | ... M15: =M14/M13 -> 0.91794716
B16: 作業 時間 | C16: 開始 | D16: =VLOOKUP("燴飯線",'0731 4度C'!$A:$T,19,0) -> 0.70833333 | E16: =VLOOKUP("沙拉線一線",'0731 4度C'!$A:$T,19,0) -> 0.12986111 | F16: =VLOOKUP("沙拉線二線",'0731 4度C'!$A:$T,19,0) -> 0.25 | G16: =VLOOKUP("沙拉線三線",'0731 4度C'!$A:$T,19,0) -> 0.16666667 | H16: =VLOOKUP("自動包裝線",'0731 4度C'!$A:$T,19,0) -> 0.20833333 | I16: =VLOOKUP("涼麵一線",'0731 4度C'!$A:$T,19,0) -> 0.29166667 | J16: =VLOOKUP("三明治四線",'0731 4度C'!$A:$T,19,0) -> 0.20833333 | K16: =VLOOKUP("三明治一線",'0731 4度C'!$A:$T,19,0) -> 0.125 | L16: =VLOOKUP("三明治二線",'0731 4度C'!$A:$T,19,0) -> 0.125 | M16: =VLOOKUP("自動包裝二線",'0731 4度C'!$A:$T,19,0) -> 0.125
C17: 結束 | D17: =LOOKUP(2,1/(('0731 4度C'!$A:$A="燴飯線")*('0731 4度C'!$T:$T<>"")),'0731 4度C'!$T:$T) -> 0.82638889 | E17: =LOOKUP(2,1/(('0731 4度C'!$A:$A="沙拉線一線")*('0731 4度C'!$T:$T<>"")),'0731 4度C'!$T:$T) -> 0.61458333 | F17: =LOOKUP(2,1/(('0731 4度C'!$A:$A="沙拉線二線")*('0731 4度C'!$T:$T<>"")),'0731 4度C'!$T:$T) -> 0.87569444 | G17: =LOOKUP(2,1/(('0731 4度C'!$A:$A="沙拉線三線")*('0731 4度C'!$T:$T<>"")),'0731 4度C'!$T:$T) -> 0.91319444 | H17: =LOOKUP(2,1/(('0731 4度C'!$A:$A="自動包裝線")*('0731 4度C'!$T:$T<>"")),'0731 4度C'!$T:$T) -> 0.61458333 | I17: =LOOKUP(2,1/(('0731 4度C'!$A:$A="涼麵一線")*('0731 4度C'!$T:$T<>"")),'0731 4度C'!$T:$T) -> 0.80416667 | J17: =LOOKUP(2,1/(('0731 4度C'!$A:$A="三明治四線")*('0731 4度C'!$T:$T<>"")),'0731 4度C'!$T:$T) -> 0.49305556 | K17: =LOOKUP(2,1/(('0731 4度C'!$A:$A="三明治一線")*('0731 4度C'!$T:$T<>"")),'0731 4度C'!$T:$T) -> 0.61597222 | L17: =LOOKUP(2,1/(('0731 4度C'!$A:$A="三明治二線")*('0731 4度C'!$T:$T<>"")),'0731 4度C'!$T:$T) -> 0.61388889 | M17: =LOOKUP(2,1/(('0731 4度C'!$A:$A="自動包裝二線")*('0731 4度C'!$T:$T<>"")),'0731 4度C'!$T:$T) -> 0.58541667
B18: 配置人數 | D18: =SUMIFS('0731 4度C'!$I:$I,'0731 4度C'!$A:$A,"燴飯線",'0731 4度C'!$B:$B,"平均") -> 17 | E18: =SUMIFS('0731 4度C'!$I:$I,'0731 4度C'!$A:$A,"沙拉線一線",'0731 4度C'!$B:$B,"平均") -> 18.5 | F18: =SUMIFS('0731 4度C'!$I:$I,'0731 4度C'!$A:$A,"沙拉線二線",'0731 4度C'!$B:$B,"平均") -> 19.4 | G18: =SUMIFS('0731 4度C'!$I:$I,'0731 4度C'!$A:$A,"沙拉線三線",'0731 4度C'!$B:$B,"平均") -> 16.7 | H18: =SUMIFS('0731 4度C'!$I:$I,'0731 4度C'!$A:$A,"自動包裝線",'0731 4度C'!$B:$B,"平均") -> 10 | I18: =SUMIFS('0731 4度C'!$I:$I,'0731 4度C'!$A:$A,"涼麵一線",'0731 4度C'!$B:$B,"平均") -> 16.75 | J18: =SUMIFS('0731 4度C'!$I:$I,'0731 4度C'!$A:$A,"三明治四線",'0731 4度C'!$B:$B,"平均") -> 10.166667 | K18: =SUMIFS('0731 4度C'!$I:$I,'0731 4度C'!$A:$A,"三明治一線",'0731 4度C'!$B:$B,"平均") -> 17.333333 | L18: =SUMIFS('0731 4度C'!$I:$I,'0731 4度C'!$A:$A,"三明治二線",'0731 4度C'!$B:$B,"平均") -> 18.857143 | M18: =SUMIFS('0731 4度C'!$I:$I,'0731 4度C'!$A:$A,"自動包裝二線",'0731 4度C'!$B:$B,"平均") -> 17
B19: 主要應用設備 | D19: ET-55 | E19: 熱縮爐 | F19: L型包裝機 | G19: L型包裝機 | H19: 伺服包裝機 | I19: ET-55 | J19: 伺服包裝機 | K19: 三明治包裝機 | L19: 三明治包裝機 | M19: 三明治包裝機
B20: 次要應用設備 | F20: 圓盤機 | G20: ET-55
B21: 備註 | E21: 握沙拉 | F21: 共用L型包裝機 | H21: 調理麵包 | I21: 炒飯+沙拉 | J21: 調理麵包

Sheet 0731 4度C
A1: 新豐廠四度C日報分析 | C1: 總生產量 | D1: =SUM(F5:F73) -> 152356 | E1: 營業額 | F1: =SUM(G5:G73) -> 5197137.5 | G1: 出勤人數 | H1: =L8+L13+L54+L59+L19+L66+L37+L45+L30+L73 -> 161.70714 | I1: 產線配置圖 | L1: 生產實績 | O1: 人時性差異分析 | S1: 日報登錄 | Y1: 分析說明 | AA1: 產能差異分析
A2: 45869 | B2: 星期四 | C2: 人時性 | D2: =AVERAGE(N8,N13,N54,N59,N19,N66,N30,N37,N45,N73) -> 130.65572 | E2: 平均廠價 | F2: =F1/D1 -> 34.111801 | G2: 多次生產數 | H2: =COUNT(H5:H73) -> 8
A3: 線別 | B3: 品類 | C3: 品名 | E3: 廠價 | F3: 生產量 | G3: 營收 | H3: 多次 生產 | I3: 人數 | J3: 產能/時 | K3: 人時性 | L3: 人數 | M3: 產能/時 | N3: 人時性 | O3: 人數 | P3: 人時性 | Q3: 達成率 | R3: 達成率平均 | S3: 生產時間 | U3: 換線、休息/分 | V3: 稼動時間/分 | W3: 休息時間 | Y3: (新豐回填) | AA3: 產能/時 | AB3: 達成率 | AC3: 達成率平均
S4: 開始 | T4: 結束 | W4: 開始 | X4: 結束
A5: 燴飯線 | B5: 微波主食 | C5: 二配煸椒烘蛋飯 | E5: 46.93 | F5: 788 | G5: =E5*F5 -> 36980.84 | I5: 17 | J5: 1800 | K5: =J5/I5 -> 105.88235 | L5: 17 | M5: =F5/V5*60 -> 1688.5714 | N5: =M5/L5 -> 99.327731 | O5: =L5-I5 -> 0 | P5: =N5-K5 -> -6.5546218 | Q5: =N5/K5 -> 0.93809524 | R5: =Q8 -> 0.92683215 | S5: 0.70833333 | T5: 0.72777778 | V5: =(T5-S5)*24*60 -> 28 | AA5: =M5-J5 -> -111.42857 | AB5: =M5/J5 -> 0.93809524 | AC5: =AB8 -> 0.92683215
A6: 燴飯線 | B6: 微波主食 | C6: 二配川味麻婆燒豆腐燴飯 | E6: 50.49 | F6: 1691 | G6: =E6*F6 -> 85378.59 | I6: 16 | J6: 1800 | K6: =J6/I6 -> 112.5 | L6: 16 | M6: =F6/V6*60 -> 1663.2787 | N6: =M6/L6 -> 103.95492 | O6: =L6-I6 -> 0 | P6: =N6-K6 -> -8.545082 | Q6: =N6/K6 -> 0.92404372 | S6: 0.73125 | T6: 0.77361111 | U6: =(S6-T5)*24*60 -> 5 | V6: =(T6-S6)*24*60 -> 61 | AA6: =M6-J6 -> -136.72131 | AB6: =M6/J6 -> 0.92404372
A7: 燴飯線 | B7: 微波主食 | C7: 二配港式香滑嫩蛋牛肉燴飯 | E7: 50.67 | F7: 1901 | G7: =E7*F7 -> 96323.67 | I7: 18 | J7: 1800 | K7: =J7/I7 -> 100 | L7: 18 | M7: =F7/V7*60 -> 1653.0435 | N7: =M7/L7 -> 91.835749 | O7: =L7-I7 -> 0 | P7: =N7-K7 -> -8.1642512 | Q7: =N7/K7 -> 0.91835749 | S7: 0.77847222 | T7: 0.82638889 | U7: =(S7-T6)*24*60 -> 7 | V7: =(T7-S7)*24*60 -> 69 | AA7: =M7-J7 -> -146.95652 | AB7: =M7/J7 -> 0.91835749
A8: 燴飯線 | B8: 平均 | I8: 17 | J8: 1800 | K8: =J8/I8 -> 105.88235 | L8: 17 | M8: =AVERAGE(M5:M7) -> 1668.2979 | N8: =M8/L8 -> 98.135169 | O8: =L8-I8 -> 0 | P8: =N8-K8 -> -7.7471844 | Q8: =N8/K8 -> 0.92683215 | AA8: =M8-J8 -> -131.70213 | AB8: =M8/J8 -> 0.92683215
A9: 沙拉線一線 | B9: 沙拉 | C9: 青醬優格雞肉握沙拉(113年) | E9: 39.62 | F9: 4127 | G9: =E9*F9 -> 163511.74 | I9: 19 | J9: 1500 | K9: =J9/I9 -> 78.947368 | L9: 19 | M9: =F9/V9*60 -> 1375.6667 | N9: =M9/L9 -> 72.403509 | O9: =L9-I9 -> 0 | P9: =N9-K9 -> -6.5438596 | Q9: =N9/K9 -> 0.91711111 | R9: =Q13 -> 0.91494192 | S9: 0.12986111 | T9: 0.25486111 | V9: =(T9-S9)*24*60 -> 180 | AA9: =M9-J9 -> -124.33333 | AB9: =M9/J9 -> 0.91711111 | AC9: =AB13 -> 0.91494192
A10: 沙拉線一線 | B10: 沙拉 | C10: 青檸烤雞握沙拉(113年) | E10: 39.8 | F10: 2600 | G10: =E10*F10 -> 103480 | H10: 2 | I10: 18 | J10: 1500 | K10: =J10/I10 -> 83.333333 | L10: 18 | M10: =F10/V10*60 -> 1368.4211 | N10: =M10/L10 -> 76.023392 | O10: =L10-I10 -> 0 | P10: =N10-K10 -> -7.3099415 | Q10: =N10/K10 -> 0.9122807 | S10: 0.27708333 | T10: 0.35625 | U10: =(S10-T9)*24*60 -> 32 | V10: =(T10-S10)*24*60 -> 114 | AA10: =M10-J10 -> -131.57895 | AB10: =M10/J10 -> 0.9122807
A11: 沙拉線一線 | B11: 沙拉 | C11: 地瓜瓜握沙拉 | E11: 39.29 | F11: 3665 | G11: =E11*F11 -> 143997.85 | I11: 19 | J11: 1500 | K11: =J11/I11 -> 78.947368 | L11: 19 | M11: =F11/V11*60 -> 1374.375 | N11: =M11/L11 -> 72.335526 | O11: =L11-I11 -> 0 | P11: =N11-K11 -> -6.6118421 | Q11: =N11/K11 -> 0.91625 | S11: 0.36597222 | T11: 0.47708333 | U11: =(S11-T10)*24*60 -> 14 | V11: =(T11-S11)*24*60 -> 160 | AA11: =M11-J11 -> -125.625 | AB11: =M11/J11 -> 0.91625
A12: 沙拉線一線 | B12: 沙拉 | C12: 青檸烤雞握沙拉(113年) | E12: 39.8 | F12: 3268 | G12: =E12*F12 -> 130066.4 | I12: 18 | J12: 1500 | K12: =J12/I12 -> 83.333333 | L12: 18 | M12: =F12/V12*60 -> 1371.1888 | N12: =M12/L12 -> 76.177156 | O12: =L12-I12 -> 0 | P12: =N12-K12 -> -7.1561772 | Q12: =N12/K12 -> 0.91412587 | S12: 0.51527778 | T12: 0.61458333 | U12: =(S12-T11)*24*60 -> 55 | V12: =(T12-S12)*24*60 -> 143 | AA12: =M12-J12 -> -128.81119 | AB12: =M12/J12 -> 0.91412587
A13: 沙拉線一線 | B13: 平均 | I13: 18.5 | J13: 1500 | K13: =J13/I13 -> 81.081081 | L13: 18.5 | M13: =AVERAGE(M9:M12) -> 1372.4129 | N13: =M13/L13 -> 74.18448 | O13: =L13-I13 -> 0 | P13: =N13-K13 -> -6.8966009 | Q13: =N13/K13 -> 0.91494192 | AA13: =M13-J13 -> -127.58712 | AB13: =M13/J13 -> 0.91494192
A14: 沙拉線二線 | B14: 小菜、微波 | C14: 剝皮辣椒雞湯 | E14: 41 | F14: 1725 | G14: =E14*F14 -> 70725 | I14: 26 | J14: 1286 | K14: =J14/I14 -> 49.461538 | L14: 26 | M14: =F14/V14*60 -> 1176.1364 | N14: =M14/L14 -> 45.236014 | O14: =L14-I14 -> 0 | P14: =N14-K14 -> -4.2255245 | Q14: =N14/K14 -> 0.91456949 | R14: =Q19 -> 0.91989729 | S14: 0.25 | T14: 0.31111111 | V14: =(T14-S14)*24*60 -> 88 | AA14: =M14-J14 -> -109.86364 | AB14: =M14/J14 -> 0.91456949 | AC14: =AB19 -> 0.91989729
A15: 沙拉線二線 | B15: 沙拉 | C15: 厚蛋時蔬握沙拉 | E15: 39.29 | F15: 3081 | G15: =E15*F15 -> 121052.49 | I15: 18 | J15: 1500 | K15: =J15/I15 -> 83.333333 | L15: 18 | M15: =F15/V15*60 -> 1369.3333 | N15: =M15/L15 -> 76.074074 | O15: =L15-I15 -> 0 | P15: =N15-K15 -> -7.2592593 | Q15: =N15/K15 -> 0.91288889 | S15: 0.31944444 | T15: 0.41319444 | U15: =(S15-T14)*24*60 -> 12 | V15: =(T15-S15)*24*60 -> 135 | AA15: =M15-J15 -> -130.66667 | AB15: =M15/J15 -> 0.91288889
A16: 沙拉線二線 | B16: 微波主食 | C16: 二配金咖哩濃厚辛辣咖哩飯 | E16: 50.98 | F16: 2331 | G16: =E16*F16 -> 118834.38 | I16: 17 | J16: 1800 | K16: =J16/I16 -> 105.88235 | L16: 17 | M16: =F16/V16*60 -> 1645.4118 | N16: =M16/L16 -> 96.788927 | O16: =L16-I16 -> 0 | P16: =N16-K16 -> -9.0934256 | Q16: =N16/K16 -> 0.91411765 | S16: 0.70833333 | T16: 0.76736111 | U16: =(S16-T15)*24*60 -> 425 | V16: =(T16-S16)*24*60 -> 85 | AA16: =M16-J16 -> -154.58824 | AB16: =M16/J16 -> 0.91411765
A17: 沙拉線二線 | B17: 微波主食 | C17: 二配粗飽系雞排炒飯 | E17: 57.73 | F17: 1403 | G17: =E17*F17 -> 80995.19 | I17: 16 | J17: 1500 | K17: =J17/I17 -> 93.75 | L17: 16 | M17: =F17/V17*60 -> 1380 | N17: =M17/L17 -> 86.25 | O17: =L17-I17 -> 0 | P17: =N17-K17 -> -7.5 | Q17: =N17/K17 -> 0.92 | S17: 0.77083333 | T17: 0.81319444 | U17: =(S17-T16)*24*60 -> 5 | V17: =(T17-S17)*24*60 -> 61 | AA17: =M17-J17 -> -120 | AB17: =M17/J17 -> 0.92
A18: 沙拉線二線 | B18: 微波主食 | C18: 二配美味蟹煲 | E18: 54.09 | F18: 982 | G18: =E18*F18 -> 53116.38 | I18: 20 | J18: 1800 | K18: =J18/I18 -> 90 | L18: 20 | M18: =F18/V18*60 -> 1683.4286 | N18: =M18/L18 -> 84.171429 | O18: =L18-I18 -> 0 | P18: =N18-K18 -> -5.8285714 | Q18: =N18/K18 -> 0.9352381 | S18: 0.85138889 | T18: 0.87569444 | U18: =(S18-T17)*24*60 -> 55 | V18: =(T18-S18)*24*60 -> 35 | AA18: =M18-J18 -> -116.57143 | AB18: =M18/J18 -> 0.9352381
A19: 沙拉線二線 | B19: 平均 | I19: 19.4 | J19: 1577.2 | K19: =J19/I19 -> 81.298969 | L19: 19.4 | M19: =AVERAGE(M14:M18) -> 1450.862 | N19: =M19/L19 -> 74.786701 | O19: =L19-I19 -> 0 | P19: =N19-K19 -> -6.5122677 | Q19: =N19/K19 -> 0.91989729 | AA19: =M19-J19 -> -126.33799 | AB19: =M19/J19 -> 0.91989729
A20: 沙拉線三線 | B20: 小吃 | C20: 古早味炒炊粉 | E20: 43.14 | F20: 1210 | G20: =E20*F20 -> 52199.4 | I20: 17 | J20: 1200 | K20: =J20/I20 -> 70.588235 | L20: 17 | M20: =F20/V20*60 -> 1100 | N20: =M20/L20 -> 64.705882 | O20: =L20-I20 -> 0 | P20: =N20-K20 -> -5.8823529 | Q20: =N20/K20 -> 0.91666667 | R20: =Q30 -> 0.92284246 | S20: 0.16666667 | T20: 0.2125 | V20: =(T20-S20)*24*60 -> 66 | AA20: =M20-J20 -> -100 | AB20: =M20/J20 -> 0.91666667 | AC20: =AB30 -> 0.92284246
A21: 沙拉線三線 | B21: 微波主食 | C21: 鐵板滑蛋炸豬排丼 | E21: 57.73 | F21: 2866 | G21: =E21*F21 -> 165454.18 | I21: 16 | J21: 1800 | K21: =J21/I21 -> 112.5 | L21: 16 | M21: =F21/V21*60 -> 1653.4615 | N21: =M21/L21 -> 103.34135 | O21: =L21-I21 -> 0 | P21: =N21-K21 -> -9.1586538 | Q21: =N21/K21 -> 0.91858974 | S21: 0.23194444 | T21: 0.30416667 | U21: =(S21-T20)*24*60 -> 28 | V21: =(T21-S21)*24*60 -> 104 | AA21: =M21-J21 -> -146.53846 | AB21: =M21/J21 -> 0.91858974
A22: 沙拉線三線 | B22: 微波主食 | C22: 極上炙烤親子丼 | E22: 53.68 | F22: 1678 | G22: =E22*F22 -> 90075.04 | I22: 17 | J22: 1800 | K22: =J22/I22 -> 105.88235 | L22: 17 | M22: =F22/V22*60 -> 1650.4918 | N22: =M22/L22 -> 97.087753 | O22: =L22-I22 -> 0 | P22: =N22-K22 -> -8.7945998 | Q22: =N22/K22 -> 0.91693989 | S22: 0.30833333 | T22: 0.35069444 | U22: =(S22-T21)*24*60 -> 6 | V22: =(T22-S22)*24*60 -> 61 | AA22: =M22-J22 -> -149.5082 | AB22: =M22/J22 -> 0.91693989
A23: 沙拉線三線 | B23: 微波主食 | C23: 紅燒纖牛若風味燴飯 | E23: 50.67 | F23: 986 | G23: =E23*F23 -> 49960.62 | I23: 16 | J23: 1800 | K23: =J23/I23 -> 112.5 | L23: 16 | M23: =F23/V23*60 -> 1643.3333 | N23: =M23/L23 -> 102.70833 | O23: =L23-I23 -> 0 | P23: =N23-K23 -> -9.7916667 | Q23: =N23/K23 -> 0.91296296 | S23: 0.35416667 | T23: 0.37916667 | U23: =(S23-T22)*24*60 -> 5 | V23: =(T23-S23)*24*60 -> 36 | AA23: =M23-J23 -> -156.66667 | AB23: =M23/J23 -> 0.91296296
A24: 沙拉線三線 | B24: 微波主食 | C24: 海老鰻魚丼滋丼 | E24: 58.17 | F24: 2849 | G24: =E24*F24 -> 165726.33 | I24: 18 | J24: 1800 | K24: =J24/I24 -> 100 | L24: 18 | M24: =F24/V24*60 -> 1643.6538 | N24: =M24/L24 -> 91.314103 | O24: =L24-I24 -> 0 | P24: =N24-K24 -> -8.6858974 | Q24: =N24/K24 -> 0.91314103 | S24: 0.38263889 | T24: 0.45486111 | U24: =(S24-T23)*24*60 -> 5 | V24: =(T24-S24)*24*60 -> 104 | AA24: =M24-J24 -> -156.34615 | AB24: =M24/J24 -> 0.91314103
A25: 沙拉線三線 | B25: 微波主食 | C25: 二配金咖哩果香甘口咖哩飯 | E25: 50.92 | F25: 1000 | G25: =E25*F25 -> 50920 | H25: 2 | I25: 16 | J25: 1800 | K25: =J25/I25 -> 112.5 | L25: 16 | M25: =F25/V25*60 -> 1666.6667 | N25: =M25/L25 -> 104.16667 | O25: =L25-I25 -> 0 | P25: =N25-K25 -> -8.3333333 | Q25: =N25/K25 -> 0.92592593 | S25: 0.70833333 | T25: 0.73333333 | U25: =(S25-T24)*24*60 -> 365 | V25: =(T25-S25)*24*60 -> 36 | AA25: =M25-J25 -> -133.33333 | AB25: =M25/J25 -> 0.92592593
A26: 沙拉線三線 | B26: 微波主食 | C26: 二配極旨黑咖哩漢堡排飯 | E26: 53.27 | F26: 436 | G26: =E26*F26 -> 23225.72 | I26: 15 | J26: 1800 | K26: =J26/I26 -> 120 | L26: 15 | M26: =F26/V26*60 -> 1744 | N26: =M26/L26 -> 116.26667 | O26: =L26-I26 -> 0 | P26: =N26-K26 -> -3.7333333 | Q26: =N26/K26 -> 0.96888889 | S26: 0.73680556 | T26: 0.74722222 | U26: =(S26-T25)*24*60 -> 5 | V26: =(T26-S26)*24*60 -> 15 | AA26: =M26-J26 -> -56 | AB26: =M26/J26 -> 0.96888889
A27: 沙拉線三線 | B27: 微波主食 | C27: 二配黑胡椒素豬若飯 | E27: 49.91 | F27: 663 | G27: =E27*F27 -> 33090.33 | I27: 16 | J27: 1800 | K27: =J27/I27 -> 112.5 | L27: 16 | M27: =F27/V27*60 -> 1657.5 | N27: =M27/L27 -> 103.59375 | O27: =L27-I27 -> 0 | P27: =N27-K27 -> -8.90625 | Q27: =N27/K27 -> 0.92083333 | S27: 0.75069444 | T27: 0.76736111 | U27: =(S27-T26)*24*60 -> 5 | V27: =(T27-S27)*24*60 -> 24 | AA27: =M27-J27 -> -142.5 | AB27: =M27/J27 -> 0.92083333
A28: 沙拉線三線 | B28: 微波主食 | C28: 二配美味蟹煲 | E28: 54.09 | F28: 2500 | G28: =E28*F28 -> 135225 | H28: 2 | I28: 20 | J28: 1800 | K28: =J28/I28 -> 90 | L28: 20 | M28: =F28/V28*60 -> 1648.3516 | N28: =M28/L28 -> 82.417582 | O28: =L28-I28 -> 0 | P28: =N28-K28 -> -7.5824176 | Q28: =N28/K28 -> 0.91575092 | S28: 0.77083333 | T28: 0.83402778 | U28: =(S28-T27)*24*60 -> 5 | V28: =(T28-S28)*24*60 -> 91 | AA28: =M28-J28 -> -151.64835 | AB28: =M28/J28 -> 0.91575092
A29: 沙拉線三線 | B29: 微波主食 | C29: 二配金咖哩果香甘口咖哩飯 | E29: 50.92 | F29: 1540 | G29: =E29*F29 -> 78416.8 | I29: 16 | J29: 1800 | K29: =J29/I29 -> 112.5 | L29: 16 | M29: =F29/V29*60 -> 1650 | N29: =M29/L29 -> 103.125 | O29: =L29-I29 -> 0 | P29: =N29-K29 -> -9.375 | Q29: =N29/K29 -> 0.91666667 | S29: 0.87430556 | T29: 0.91319444 | U29: =(S29-T28)*24*60 -> 58 | V29: =(T29-S29)*24*60 -> 56 | AA29: =M29-J29 -> -150 | AB29: =M29/J29 -> 0.91666667
A30: 沙拉線三線 | B30: 平均 | I30: 16.7 | J30: 1740 | K30: =J30/I30 -> 104.19162 | L30: 16.7 | M30: =AVERAGE(M20:M29) -> 1605.7459 | N30: =M30/L30 -> 96.152448 | O30: =L30-I30 -> 0 | P30: =N30-K30 -> -8.0391686 | Q30: =N30/K30 -> 0.92284246 | AA30: =M30-J30 -> -134.25412 | AB30: =M30/J30 -> 0.92284246
A31: 三明治一線 | B31: 三明治 | C31: 經典總匯三明治 | E31: 26.2 | F31: 3648 | G31: =E31*F31 -> 95577.6 | I31: 20 | J31: 2400 | K31: =J31/I31 -> 120 | L31: 20 | M31: =F31/V31*60 -> 2188.8 | N31: =M31/L31 -> 109.44 | O31: =L31-I31 -> 0 | P31: =N31-K31 -> -10.56 | Q31: =N31/K31 -> 0.912 | R31: =Q37 -> 0.91709041 | S31: 0.125 | T31: 0.19444444 | V31: =(T31-S31)*24*60 -> 100 | AA31: =M31-J31 -> -211.2 | AB31: =M31/J31 -> 0.912 | AC31: =AB37 -> 0.91709041
A32: 三明治一線 | B32: 三明治 | C32: 肉鬆火腿三明治 | E32: 20.52 | F32: 3960 | G32: =E32*F32 -> 81259.2 | I32: 18 | J32: 2400 | K32: =J32/I32 -> 133.33333 | L32: 18 | M32: =F32/V32*60 -> 2200 | N32: =M32/L32 -> 122.22222 | O32: =L32-I32 -> 0 | P32: =N32-K32 -> -11.111111 | Q32: =N32/K32 -> 0.91666667 | S32: 0.21180556 | T32: 0.28680556 | U32: =(S32-T31)*24*60 -> 25 | V32: =(T32-S32)*24*60 -> 108 | AA32: =M32-J32 -> -200 | AB32: =M32/J32 -> 0.91666667
A33: 三明治一線 | B33: 三明治 | C33: 紐奧良風味烤雞鮮蔬三明治 | E33: 31.29 | F33: 3500 | G33: =E33*F33 -> 109515 | H33: 2 | I33: 16 | J33: 2400 | K33: =J33/I33 -> 150 | L33: 16 | M33: =F33/V33*60 -> 2210.5263 | N33: =M33/L33 -> 138.15789 | O33: =L33-I33 -> 0 | P33: =N33-K33 -> -11.842105 | Q33: =N33/K33 -> 0.92105263 | S33: 0.29027778 | T33: 0.35625 | U33: =(S33-T32)*24*60 -> 5 | V33: =(T33-S33)*24*60 -> 95 | AA33: =M33-J33 -> -189.47368 | AB33: =M33/J33 -> 0.92105263
A34: 三明治一線 | B34: 三明治 | C34: 起司芋見肉鬆三明治 | E34: 24.25 | F34: 4773 | G34: =E34*F34 -> 115745.25 | I34: 18 | J34: 2400 | K34: =J34/I34 -> 133.33333 | L34: 18 | M34: =F34/V34*60 -> 2186.1069 | N34: =M34/L34 -> 121.45038 | O34: =L34-I34 -> 0 | P34: =N34-K34 -> -11.882952 | Q34: =N34/K34 -> 0.91087786 | S34: 0.35972222 | T34: 0.45069444 | U34: =(S34-T33)*24*60 -> 5 | V34: =(T34-S34)*24*60 -> 131 | AA34: =M34-J34 -> -213.89313 | AB34: =M34/J34 -> 0.91087786
A35: 三明治一線 | B35: 三明治 | C35: 藍莓優格三明治(114年) | E35: 22.35 | F35: 2149 | G35: =E35*F35 -> 48030.15 | I35: 16 | J35: 2400 | K35: =J35/I35 -> 150 | L35: 16 | M35: =F35/V35*60 -> 2223.1034 | N35: =M35/L35 -> 138.94397 | O35: =L35-I35 -> 0 | P35: =N35-K35 -> -11.056034 | Q35: =N35/K35 -> 0.9262931 | S35: 0.45486111 | T35: 0.49513889 | U35: =(S35-T34)*24*60 -> 6 | V35: =(T35-S35)*24*60 -> 58 | AA35: =M35-J35 -> -176.89655 | AB35: =M35/J35 -> 0.9262931
A36: 三明治一線 | B36: 三明治 | C36: 紐奧良風味烤雞鮮蔬三明治 | E36: 31.29 | F36: 4212 | G36: =E36*F36 -> 131793.48 | I36: 16 | J36: 2400 | K36: =J36/I36 -> 150 | L36: 16 | M36: =F36/V36*60 -> 2197.5652 | N36: =M36/L36 -> 137.34783 | O36: =L36-I36 -> 0 | P36: =N36-K36 -> -12.652174 | Q36: =N36/K36 -> 0.91565217 | S36: 0.53611111 | T36: 0.61597222 | U36: =(S36-T35)*24*60 -> 59 | V36: =(T36-S36)*24*60 -> 115 | AA36: =M36-J36 -> -202.43478 | AB36: =M36/J36 -> 0.91565217
A37: 三明治一線 | B37: 平均 | I37: 17.333333 | J37: 2400 | K37: =J37/I37 -> 138.46154 | L37: 17.333333 | M37: =AVERAGE(M31:M36) -> 2201.017 | N37: =M37/L37 -> 126.98175 | O37: =L37-I37 -> 0 | P37: =N37-K37 -> -11.47979 | Q37: =N37/K37 -> 0.91709041 | AA37: =M37-J37 -> -198.98302 | AB37: =M37/J37 -> 0.91709041
A38: 三明治二線 | B38: 三明治 | C38: 鮪魚起司溏心蛋三明治 | E38: 26.2 | F38: 2500 | G38: =E38*F38 -> 65500 | H38: 2 | I38: 18 | J38: 2400 | K38: =J38/I38 -> 133.33333 | L38: 18 | M38: =F38/V38*60 -> 2205.8824 | N38: =M38/L38 -> 122.54902 | O38: =L38-I38 -> 0 | P38: =N38-K38 -> -10.784314 | Q38: =N38/K38 -> 0.91911765 | R38: =Q45 -> 0.91578306 | S38: 0.125 | T38: 0.17222222 | V38: =(T38-S38)*24*60 -> 68 | AA38: =M38-J38 -> -194.11765 | AB38: =M38/J38 -> 0.91911765 | AC38: =AB45 -> 0.91578306
A39: 三明治二線 | B39: 三明治 | C39: 瘋狂起司三明治(113年) | E39: 24.45 | F39: 2089 | G39: =E39*F39 -> 51076.05 | I39: 20 | J39: 2400 | K39: =J39/I39 -> 120 | L39: 20 | M39: =F39/V39*60 -> 2198.9474 | N39: =M39/L39 -> 109.94737 | O39: =L39-I39 -> 0 | P39: =N39-K39 -> -10.052632 | Q39: =N39/K39 -> 0.91622807 | S39: 0.19236111 | T39: 0.23194444 | U39: =(S39-T38)*24*60 -> 29 | V39: =(T39-S39)*24*60 -> 57 | AA39: =M39-J39 -> -201.05263 | AB39: =M39/J39 -> 0.91622807
A40: 三明治二線 | B40: 三明治 | C40: 蛋蛋嘉年華三明治 | E40: 26.2 | F40: 2829 | G40: =E40*F40 -> 74119.8 | I40: 20 | J40: 2400 | K40: =J40/I40 -> 120 | L40: 20 | M40: =F40/V40*60 -> 2204.4156 | N40: =M40/L40 -> 110.22078 | O40: =L40-I40 -> 0 | P40: =N40-K40 -> -9.7792208 | Q40: =N40/K40 -> 0.91850649 | S40: 0.23611111 | T40: 0.28958333 | U40: =(S40-T39)*24*60 -> 6 | V40: =(T40-S40)*24*60 -> 77 | AA40: =M40-J40 -> -195.58442 | AB40: =M40/J40 -> 0.91850649
...

Sheet 0730
B1: 屏榮 新豐廠組合室生產人時性分析
B3: 日期 | C3: =TEXT('0730 4度C'!A2,"yyyy.mm.ddaaaa") -> 2025.07.30星期三 | E3: 訂單量 | F3: ='0730 4度C'!D1 -> 164943 | H3: 營業額 | I3: ='0730 4度C'!F1 -> 5659460.7
B4: 人時性 | C4: 項目 | E4: ➀ | G4: ➁ | I4: ➂
C5: 組合室 | E5: 全溫層 | G5: 4度C-各編組展開 | I5: ③三明治-各編組展開
C6: 排關平均 | E6: =AVERAGE(D13:M13) -> 142.12751 | F6: =AVERAGE(D27:O27,D13:J13) -> 145.01729 | G6: =AVERAGE(D13:J13) -> 145.01729 | I6: =AVERAGE(K13:M13) -> 135.38471
C7: 實績平均 | E7: =AVERAGE(D14:M14) -> 130.47378 | F7: =AVERAGE(D28:O28,D14:J14) -> 133.19488 | G7: =AVERAGE(D14:J14) -> 133.19488 | I7: =AVERAGE(K14:M14) -> 124.12453
C8: 達成率平均 | E8: =AVERAGE(D15:M15) -> 0.91764768 | F8: =AVERAGE(D15:J15,D29:O29) -> 0.91800081 | G8: =AVERAGE(D15:J15) -> 0.91800081 | I8: =AVERAGE(K15:M15) -> 0.91682373 | K8: ※現行日本鮮食廠以達成率80%為基本(即為現行KPI)
B10: 溫層 | D10: ➁4度C-各編組展開 | K10: ③三明治-各編組展開
B11: 編組 | D11: 1 | E11: 2 | F11: 3 | G11: 4 | H11: 5 | I11: 6 | J11: 7 | K11: 1 | L11: 2 | M11: 3
D12: 燴飯線 | E12: 沙拉一線 | F12: 沙拉二線 | G12: 沙拉三線 | H12: 自動包裝線 | I12: 涼麵一線 | J12: 三明治四線 | K12: 三明治一線 | L12: 三明治二線 | M12: 自動包裝二線
B13: 人時性 | C13: 排關 | D13: =SUMIFS('0730 4度C'!$K:$K,'0730 4度C'!$A:$A,"燴飯線",'0730 4度C'!$B:$B,"平均") -> 105.88235 | E13: =SUMIFS('0730 4度C'!$K:$K,'0730 4度C'!$A:$A,"沙拉線一線",'0730 4度C'!$B:$B,"平均") -> 81.081081 | F13: =SUMIFS('0730 4度C'!$K:$K,'0730 4度C'!$A:$A,"沙拉線二線",'0730 4度C'!$B:$B,"平均") -> 81.298969 | G13: =SUMIFS('0730 4度C'!$K:$K,'0730 4度C'!$A:$A,"沙拉線三線",'0730 4度C'!$B:$B,"平均") -> 104.19162 | H13: =SUMIFS('0730 4度C'!$K:$K,'0730 4度C'!$A:$A,"自動包裝線",'0730 4度C'!$B:$B,"平均") -> 300 | I13: =SUMIFS('0730 4度C'!$K:$K,'0730 4度C'!$A:$A,"涼麵一線",'0730 4度C'!$B:$B,"平均") -> 89.552239 | J13: =SUMIFS('0730 4度C'!$K:$K,'0730 4度C'!$A:$A,"三明治四線",'0730 4度C'!$B:$B,"平均") -> 253.11475 | K13: =SUMIFS('0730 4度C'!$K:$K,'0730 4度C'!$A:$A,"三明治一線",'0730 4度C'!$B:$B,"平均") -> 137.70492 | L13: =SUMIFS('0730 4度C'!$K:$K,'0730 4度C'!$A:$A,"三明治二線",'0730 4度C'!$B:$B,"平均") -> 127.27273 | M13: =SUMIFS('0730 4度C'!$K:$K,'0730 4度C'!$A:$A,"自動包裝二線",'0730 4度C'!$B:$B,"平均") -> 141.17647
C14: 實績 | D14: =SUMIFS('0730 4度C'!$N:$N,'0730 4度C'!$A:$A,"燴飯線",'0730 4度C'!$B:$B,"平均") -> 97.059132 | E14: =SUMIFS('0730 4度C'!$N:$N,'0730 4度C'!$A:$A,"沙拉線一線",'0730 4度C'!$B:$B,"平均") -> 74.194345 | F14: =SUMIFS('0730 4度C'!$N:$N,'0730 4度C'!$A:$A,"沙拉線二線",'0730 4度C'!$B:$B,"平均") -> 74.381192 | G14: =SUMIFS('0730 4度C'!$N:$N,'0730 4度C'!$A:$A,"沙拉線三線",'0730 4度C'!$B:$B,"平均") -> 96.202348 | H14: =SUMIFS('0730 4度C'!$N:$N,'0730 4度C'!$A:$A,"自動包裝線",'0730 4度C'!$B:$B,"平均") -> 275.37409 | I14: =SUMIFS('0730 4度C'!$N:$N,'0730 4度C'!$A:$A,"涼麵一線",'0730 4度C'!$B:$B,"平均") -> 82.183693 | J14: =SUMIFS('0730 4度C'!$N:$N,'0730 4度C'!$A:$A,"三明治四線",'0730 4度C'!$B:$B,"平均") -> 232.96939 | K14: =SUMIFS('0730 4度C'!$N:$N,'0730 4度C'!$A:$A,"三明治一線",'0730 4度C'!$B:$B,"平均") -> 126.13686 | L14: =SUMIFS('0730 4度C'!$N:$N,'0730 4度C'!$A:$A,"三明治二線",'0730 4度C'!$B:$B,"平均") -> 116.69596 | M14: =SUMIFS('0730 4度C'!$N:$N,'0730 4度C'!$A:$A,"自動包裝二線",'0730 4度C'!$B:$B,"平均") -> 129.54078
C15: 達成率 | D15: =D14/D13 -> 0.91666958 | E15: =E14/E13 -> 0.91506359 | F15: =F14/F13 -> 0.91490942 | G15: =G14/G13 -> 0.92332139 | H15: =H14/H13 -> 0.91791363 | I15: =I14/I13 -> 0.9177179 | J15: =J14/J13 -> 0.92041014 | K15: =K14/K13 -> 0.91599386 | ... M15: =M14/M13 -> 0.9175805
B16: 作業 時間 | C16: 開始 | D16: =VLOOKUP("燴飯線",'0730 4度C'!$A:$T,19,0) -> 0.70833333 | E16: =VLOOKUP("沙拉線一線",'0730 4度C'!$A:$T,19,0) -> 0.12916667 | F16: =VLOOKUP("沙拉線二線",'0730 4度C'!$A:$T,19,0) -> 0.25 | G16: =VLOOKUP("沙拉線三線",'0730 4度C'!$A:$T,19,0) -> 0.16666667 | H16: =VLOOKUP("自動包裝線",'0730 4度C'!$A:$T,19,0) -> 0.20833333 | I16: =VLOOKUP("涼麵一線",'0730 4度C'!$A:$T,19,0) -> 0.29166667 | J16: =VLOOKUP("三明治四線",'0730 4度C'!$A:$T,19,0) -> 0.20833333 | K16: =VLOOKUP("三明治一線",'0730 4度C'!$A:$T,19,0) -> 0.125 | L16: =VLOOKUP("三明治二線",'0730 4度C'!$A:$T,19,0) -> 0.083333333 | M16: =VLOOKUP("自動包裝二線",'0730 4度C'!$A:$T,19,0) -> 0.125
C17: 結束 | D17: =LOOKUP(2,1/(('0730 4度C'!$A:$A="燴飯線")*('0730 4度C'!$T:$T<>"")),'0730 4度C'!$T:$T) -> 0.84236111 | E17: =LOOKUP(2,1/(('0730 4度C'!$A:$A="沙拉線一線")*('0730 4度C'!$T:$T<>"")),'0730 4度C'!$T:$T) -> 0.63541667 | F17: =LOOKUP(2,1/(('0730 4度C'!$A:$A="沙拉線二線")*('0730 4度C'!$T:$T<>"")),'0730 4度C'!$T:$T) -> 0.93611111 | G17: =LOOKUP(2,1/(('0730 4度C'!$A:$A="沙拉線三線")*('0730 4度C'!$T:$T<>"")),'0730 4度C'!$T:$T) -> 0.9375 | H17: =LOOKUP(2,1/(('0730 4度C'!$A:$A="自動包裝線")*('0730 4度C'!$T:$T<>"")),'0730 4度C'!$T:$T) -> 0.625 | I17: =LOOKUP(2,1/(('0730 4度C'!$A:$A="涼麵一線")*('0730 4度C'!$T:$T<>"")),'0730 4度C'!$T:$T) -> 0.81736111 | J17: =LOOKUP(2,1/(('0730 4度C'!$A:$A="三明治四線")*('0730 4度C'!$T:$T<>"")),'0730 4度C'!$T:$T) -> 0.49791667 | K17: =LOOKUP(2,1/(('0730 4度C'!$A:$A="三明治一線")*('0730 4度C'!$T:$T<>"")),'0730 4度C'!$T:$T) -> 0.65416667 | L17: =LOOKUP(2,1/(('0730 4度C'!$A:$A="三明治二線")*('0730 4度C'!$T:$T<>"")),'0730 4度C'!$T:$T) -> 0.60902778 | M17: =LOOKUP(2,1/(('0730 4度C'!$A:$A="自動包裝二線")*('0730 4度C'!$T:$T<>"")),'0730 4度C'!$T:$T) -> 0.62083333
B18: 配置人數 | D18: =SUMIFS('0730 4度C'!$I:$I,'0730 4度C'!$A:$A,"燴飯線",'0730 4度C'!$B:$B,"平均") -> 17 | E18: =SUMIFS('0730 4度C'!$I:$I,'0730 4度C'!$A:$A,"沙拉線一線",'0730 4度C'!$B:$B,"平均") -> 18.5 | F18: =SUMIFS('0730 4度C'!$I:$I,'0730 4度C'!$A:$A,"沙拉線二線",'0730 4度C'!$B:$B,"平均") -> 19.4 | G18: =SUMIFS('0730 4度C'!$I:$I,'0730 4度C'!$A:$A,"沙拉線三線",'0730 4度C'!$B:$B,"平均") -> 16.7 | H18: =SUMIFS('0730 4度C'!$I:$I,'0730 4度C'!$A:$A,"自動包裝線",'0730 4度C'!$B:$B,"平均") -> 10 | I18: =SUMIFS('0730 4度C'!$I:$I,'0730 4度C'!$A:$A,"涼麵一線",'0730 4度C'!$B:$B,"平均") -> 16.75 | J18: =SUMIFS('0730 4度C'!$I:$I,'0730 4度C'!$A:$A,"三明治四線",'0730 4度C'!$B:$B,"平均") -> 10.166667 | K18: =SUMIFS('0730 4度C'!$I:$I,'0730 4度C'!$A:$A,"三明治一線",'0730 4度C'!$B:$B,"平均") -> 17.428571 | L18: =SUMIFS('0730 4度C'!$I:$I,'0730 4度C'!$A:$A,"三明治二線",'0730 4度C'!$B:$B,"平均") -> 18.857143 | M18: =SUMIFS('0730 4度C'!$I:$I,'0730 4度C'!$A:$A,"自動包裝二線",'0730 4度C'!$B:$B,"平均") -> 17
B19: 主要應用設備 | D19: ET-55 | E19: 熱縮爐 | F19: L型包裝機 | G19: L型包裝機 | H19: 伺服包裝機 | I19: ET-55 | J19: 伺服包裝機 | K19: 三明治包裝機 | L19: 三明治包裝機 | M19: 三明治包裝機
B20: 次要應用設備 | F20: 圓盤機 | G20: ET-55
B21: 備註 | E21: 握沙拉 | F21: 共用L型包裝機 | H21: 調理麵包 | I21: 炒飯+沙拉 | J21: 調理麵包

Sheet 0730 4度C
A1: 新豐廠四度C日報分析 | C1: 總生產量 | D1: =SUM(F5:F74) -> 164943 | E1: 營業額 | F1: =SUM(G5:G74) -> 5659460.7 | G1: 出勤人數 | H1: =L8+L13+L55+L60+L19+L67+L38+L46+L30+L74 -> 161.80238 | I1: 產線配置圖 | L1: 生產實績 | O1: 人時性差異分析 | S1: 日報登錄 | Y1: 分析說明 | AA1: 產能差異分析
A2: 45868 | B2: 星期三 | C2: 人時性 | D2: =AVERAGE(N8,N13,N55,N60,N19,N67,N30,N38,N46,N74) -> 130.47378 | E2: 平均廠價 | F2: =F1/D1 -> 34.311615 | G2: 多次生產數 | H2: =COUNT(H5:H74) -> 9
A3: 線別 | B3: 品類 | C3: 品名 | E3: 廠價 | F3: 生產量 | G3: 營收 | H3: 多次 生產 | I3: 人數 | J3: 產能/時 | K3: 人時性 | L3: 人數 | M3: 產能/時 | N3: 人時性 | O3: 人數 | P3: 人時性 | Q3: 達成率 | R3: 達成率平均 | S3: 生產時間 | U3: 換線、休息/分 | V3: 稼動時間/分 | W3: 休息時間 | Y3: (新豐回填) | AA3: 產能/時 | AB3: 達成率 | AC3: 達成率平均
S4: 開始 | T4: 結束 | W4: 開始 | X4: 結束
A5: 燴飯線 | B5: 微波主食 | C5: 二配煸椒烘蛋飯 | E5: 46.93 | F5: 907 | G5: =E5*F5 -> 42565.51 | I5: 17 | J5: 1800 | K5: =J5/I5 -> 105.88235 | L5: 17 | M5: =F5/V5*60 -> 1649.0909 | N5: =M5/L5 -> 97.005348 | O5: =L5-I5 -> 0 | P5: =N5-K5 -> -8.8770053 | Q5: =N5/K5 -> 0.91616162 | R5: =Q8 -> 0.91666958 | S5: 0.70833333 | T5: 0.73125 | V5: =(T5-S5)*24*60 -> 33 | AA5: =M5-J5 -> -150.90909 | AB5: =M5/J5 -> 0.91616162 | AC5: =AB8 -> 0.91666958
A6: 燴飯線 | B6: 微波主食 | C6: 二配川味麻婆燒豆腐燴飯 | E6: 50.49 | F6: 1927 | G6: =E6*F6 -> 97294.23 | I6: 16 | J6: 1800 | K6: =J6/I6 -> 112.5 | L6: 16 | M6: =F6/V6*60 -> 1651.7143 | N6: =M6/L6 -> 103.23214 | O6: =L6-I6 -> 0 | P6: =N6-K6 -> -9.2678571 | Q6: =N6/K6 -> 0.91761905 | S6: 0.73541667 | T6: 0.78402778 | U6: =(S6-T5)*24*60 -> 6 | V6: =(T6-S6)*24*60 -> 70 | AA6: =M6-J6 -> -148.28571 | AB6: =M6/J6 -> 0.91761905
A7: 燴飯線 | B7: 微波主食 | C7: 二配港式香滑嫩蛋牛肉燴飯 | E7: 50.67 | F7: 2089 | G7: =E7*F7 -> 105849.63 | I7: 18 | J7: 1800 | K7: =J7/I7 -> 100 | L7: 18 | M7: =F7/V7*60 -> 1649.2105 | N7: =M7/L7 -> 91.622807 | O7: =L7-I7 -> 0 | P7: =N7-K7 -> -8.377193 | Q7: =N7/K7 -> 0.91622807 | S7: 0.78958333 | T7: 0.84236111 | U7: =(S7-T6)*24*60 -> 8 | V7: =(T7-S7)*24*60 -> 76 | AA7: =M7-J7 -> -150.78947 | AB7: =M7/J7 -> 0.91622807
A8: 燴飯線 | B8: 平均 | I8: 17 | J8: 1800 | K8: =J8/I8 -> 105.88235 | L8: 17 | M8: =AVERAGE(M5:M7) -> 1650.0052 | N8: =M8/L8 -> 97.059132 | O8: =L8-I8 -> 0 | P8: =N8-K8 -> -8.8232212 | Q8: =N8/K8 -> 0.91666958 | AA8: =M8-J8 -> -149.99476 | AB8: =M8/J8 -> 0.91666958
A9: 沙拉線一線 | B9: 沙拉 | C9: 青醬優格雞肉握沙拉(113年) | E9: 39.62 | F9: 4421 | G9: =E9*F9 -> 175160.02 | I9: 19 | J9: 1500 | K9: =J9/I9 -> 78.947368 | L9: 19 | M9: =F9/V9*60 -> 1367.3196 | N9: =M9/L9 -> 71.964189 | O9: =L9-I9 -> 0 | P9: =N9-K9 -> -6.9831796 | Q9: =N9/K9 -> 0.91154639 | R9: =Q13 -> 0.91506359 | S9: 0.12916667 | T9: 0.26388889 | V9: =(T9-S9)*24*60 -> 194 | AA9: =M9-J9 -> -132.68041 | AB9: =M9/J9 -> 0.91154639 | AC9: =AB13 -> 0.91506359
A10: 沙拉線一線 | B10: 沙拉 | C10: 青檸烤雞握沙拉(113年) | E10: 39.8 | F10: 2600 | G10: =E10*F10 -> 103480 | H10: 2 | I10: 18 | J10: 1500 | K10: =J10/I10 -> 83.333333 | L10: 18 | M10: =F10/V10*60 -> 1380.531 | N10: =M10/L10 -> 76.696165 | O10: =L10-I10 -> 0 | P10: =N10-K10 -> -6.6371681 | Q10: =N10/K10 -> 0.92035398 | S10: 0.28888889 | T10: 0.36736111 | U10: =(S10-T9)*24*60 -> 36 | V10: =(T10-S10)*24*60 -> 113 | AA10: =M10-J10 -> -119.46903 | AB10: =M10/J10 -> 0.92035398
A11: 沙拉線一線 | B11: 沙拉 | C11: 地瓜瓜握沙拉 | E11: 39.29 | F11: 3771 | G11: =E11*F11 -> 148162.59 | I11: 19 | J11: 1500 | K11: =J11/I11 -> 78.947368 | L11: 19 | M11: =F11/V11*60 -> 1371.2727 | N11: =M11/L11 -> 72.172249 | O11: =L11-I11 -> 0 | P11: =N11-K11 -> -6.7751196 | Q11: =N11/K11 -> 0.91418182 | S11: 0.37569444 | T11: 0.49027778 | U11: =(S11-T10)*24*60 -> 12 | V11: =(T11-S11)*24*60 -> 165 | AA11: =M11-J11 -> -128.72727 | AB11: =M11/J11 -> 0.91418182
A12: 沙拉線一線 | B12: 沙拉 | C12: 青檸烤雞握沙拉(113年) | E12: 39.8 | F12: 3451 | G12: =E12*F12 -> 137349.8 | I12: 18 | J12: 1500 | K12: =J12/I12 -> 83.333333 | L12: 18 | M12: =F12/V12*60 -> 1371.2583 | N12: =M12/L12 -> 76.181015 | O12: =L12-I12 -> 0 | P12: =N12-K12 -> -7.1523179 | Q12: =N12/K12 -> 0.91417219 | S12: 0.53055556 | T12: 0.63541667 | U12: =(S12-T11)*24*60 -> 58 | V12: =(T12-S12)*24*60 -> 151 | AA12: =M12-J12 -> -128.74172 | AB12: =M12/J12 -> 0.91417219
A13: 沙拉線一線 | B13: 平均 | I13: 18.5 | J13: 1500 | K13: =J13/I13 -> 81.081081 | L13: 18.5 | M13: =AVERAGE(M9:M12) -> 1372.5954 | N13: =M13/L13 -> 74.194345 | O13: =L13-I13 -> 0 | P13: =N13-K13 -> -6.8867356 | Q13: =N13/K13 -> 0.91506359 | AA13: =M13-J13 -> -127.40461 | AB13: =M13/J13 -> 0.91506359
A14: 沙拉線二線 | B14: 小菜、微波 | C14: 剝皮辣椒雞湯 | E14: 41 | F14: 1883 | G14: =E14*F14 -> 77203 | I14: 26 | J14: 1286 | K14: =J14/I14 -> 49.461538 | L14: 26 | M14: =F14/V14*60 -> 1176.875 | N14: =M14/L14 -> 45.264423 | O14: =L14-I14 -> 0 | P14: =N14-K14 -> -4.1971154 | Q14: =N14/K14 -> 0.91514386 | R14: =Q19 -> 0.91490942 | S14: 0.25 | T14: 0.31666667 | V14: =(T14-S14)*24*60 -> 96 | AA14: =M14-J14 -> -109.125 | AB14: =M14/J14 -> 0.91514386 | AC14: =AB19 -> 0.91490942
A15: 沙拉線二線 | B15: 沙拉 | C15: 厚蛋時蔬握沙拉 | E15: 39.29 | F15: 3241 | G15: =E15*F15 -> 127338.89 | I15: 18 | J15: 1500 | K15: =J15/I15 -> 83.333333 | L15: 18 | M15: =F15/V15*60 -> 1369.4366 | N15: =M15/L15 -> 76.079812 | O15: =L15-I15 -> 0 | P15: =N15-K15 -> -7.2535211 | Q15: =N15/K15 -> 0.91295775 | S15: 0.32569444 | T15: 0.42430556 | U15: =(S15-T14)*24*60 -> 13 | V15: =(T15-S15)*24*60 -> 142 | AA15: =M15-J15 -> -130.56338 | AB15: =M15/J15 -> 0.91295775
A16: 沙拉線二線 | B16: 微波主食 | C16: 二配金咖哩濃厚辛辣咖哩飯 | E16: 50.98 | F16: 2704 | G16: =E16*F16 -> 137849.92 | I16: 17 | J16: 1800 | K16: =J16/I16 -> 105.88235 | L16: 17 | M16: =F16/V16*60 -> 1655.5102 | N16: =M16/L16 -> 97.382953 | O16: =L16-I16 -> 0 | P16: =N16-K16 -> -8.4993998 | Q16: =N16/K16 -> 0.91972789 | S16: 0.70833333 | T16: 0.77638889 | U16: =(S16-T15)*24*60 -> 409 | V16: =(T16-S16)*24*60 -> 98 | AA16: =M16-J16 -> -144.4898 | AB16: =M16/J16 -> 0.91972789
A17: 沙拉線二線 | B17: 微波主食 | C17: 二配粗飽系雞排炒飯 | E17: 57.73 | F17: 1480 | G17: =E17*F17 -> 85440.4 | I17: 16 | J17: 1500 | K17: =J17/I17 -> 93.75 | L17: 16 | M17: =F17/V17*60 -> 1366.1538 | N17: =M17/L17 -> 85.384615 | O17: =L17-I17 -> 0 | P17: =N17-K17 -> -8.3653846 | Q17: =N17/K17 -> 0.91076923 | S17: 0.78194444 | T17: 0.82708333 | U17: =(S17-T16)*24*60 -> 8 | V17: =(T17-S17)*24*60 -> 65 | AA17: =M17-J17 -> -133.84615 | AB17: =M17/J17 -> 0.91076923
A18: 沙拉線二線 | B18: 微波主食 | C18: 二配美味蟹煲 | E18: 51.62 | F18: 2745 | G18: =E18*F18 -> 141696.9 | I18: 20 | J18: 1800 | K18: =J18/I18 -> 90 | L18: 20 | M18: =F18/V18*60 -> 1647 | N18: =M18/L18 -> 82.35 | O18: =L18-I18 -> 0 | P18: =N18-K18 -> -7.65 | Q18: =N18/K18 -> 0.915 | S18: 0.86666667 | T18: 0.93611111 | U18: =(S18-T17)*24*60 -> 57 | V18: =(T18-S18)*24*60 -> 100 | AA18: =M18-J18 -> -153 | AB18: =M18/J18 -> 0.915
A19: 沙拉線二線 | B19: 平均 | I19: =AVERAGE(I14:I18) -> 19.4 | J19: 1577.2 | K19: =J19/I19 -> 81.298969 | L19: =AVERAGE(L14:L18) -> 19.4 | M19: =AVERAGE(M14:M18) -> 1442.9951 | N19: =M19/L19 -> 74.381192 | O19: =L19-I19 -> 0 | P19: =N19-K19 -> -6.9177766 | Q19: =N19/K19 -> 0.91490942 | AA19: =M19-J19 -> -134.20487 | AB19: =M19/J19 -> 0.91490942
A20: 沙拉線三線 | B20: 小吃 | C20: 古早味炒炊粉 | E20: 43.14 | F20: 1275 | G20: =E20*F20 -> 55003.5 | I20: 17 | J20: 1200 | K20: =J20/I20 -> 70.588235 | L20: 17 | M20: =F20/V20*60 -> 1108.6957 | N20: =M20/L20 -> 65.217391 | O20: =L20-I20 -> 0 | P20: =N20-K20 -> -5.370844 | Q20: =N20/K20 -> 0.92391304 | R20: =Q30 -> 0.92332139 | S20: 0.16666667 | T20: 0.21458333 | V20: =(T20-S20)*24*60 -> 69 | AA20: =M20-J20 -> -91.304348 | AB20: =M20/J20 -> 0.92391304 | AC20: =AB30 -> 0.92332139
A21: 沙拉線三線 | B21: 微波主食 | C21: 鐵板滑蛋炸豬排丼 | E21: 57.73 | F21: 3086 | G21: =E21*F21 -> 178154.78 | I21: 16 | J21: 1800 | K21: =J21/I21 -> 112.5 | L21: 16 | M21: =F21/V21*60 -> 1653.2143 | N21: =M21/L21 -> 103.32589 | O21: =L21-I21 -> 0 | P21: =N21-K21 -> -9.1741071 | Q21: =N21/K21 -> 0.91845238 | S21: 0.23472222 | T21: 0.3125 | U21: =(S21-T20)*24*60 -> 29 | V21: =(T21-S21)*24*60 -> 112 | AA21: =M21-J21 -> -146.78571 | AB21: =M21/J21 -> 0.91845238
A22: 沙拉線三線 | B22: 微波主食 | C22: 極上炙烤親子丼 | E22: 53.68 | F22: 1878 | G22: =E22*F22 -> 100811.04 | I22: 17 | J22: 1800 | K22: =J22/I22 -> 105.88235 | L22: 17 | M22: =F22/V22*60 -> 1657.0588 | N22: =M22/L22 -> 97.474048 | O22: =L22-I22 -> 0 | P22: =N22-K22 -> -8.4083045 | Q22: =N22/K22 -> 0.92058824 | S22: 0.31597222 | T22: 0.36319444 | U22: =(S22-T21)*24*60 -> 5 | V22: =(T22-S22)*24*60 -> 68 | AA22: =M22-J22 -> -142.94118 | AB22: =M22/J22 -> 0.92058824
A23: 沙拉線三線 | B23: 微波主食 | C23: 紅燒纖牛若風味燴飯 | E23: 50.67 | F23: 1018 | G23: =E23*F23 -> 51582.06 | I23: 16 | J23: 1800 | K23: =J23/I23 -> 112.5 | L23: 16 | M23: =F23/V23*60 -> 1650.8108 | N23: =M23/L23 -> 103.17568 | O23: =L23-I23 -> 0 | P23: =N23-K23 -> -9.3243243 | Q23: =N23/K23 -> 0.91711712 | S23: 0.36875 | T23: 0.39444444 | U23: =(S23-T22)*24*60 -> 8 | V23: =(T23-S23)*24*60 -> 37 | AA23: =M23-J23 -> -149.18919 | AB23: =M23/J23 -> 0.91711712
A24: 沙拉線三線 | B24: 微波主食 | C24: 海老鰻魚丼滋丼 | E24: 58.17 | F24: 3088 | G24: =E24*F24 -> 179628.96 | I24: 18 | J24: 1800 | K24: =J24/I24 -> 100 | L24: 18 | M24: =F24/V24*60 -> 1654.2857 | N24: =M24/L24 -> 91.904762 | O24: =L24-I24 -> 0 | P24: =N24-K24 -> -8.0952381 | Q24: =N24/K24 -> 0.91904762 | S24: 0.39861111 | T24: 0.47638889 | U24: =(S24-T23)*24*60 -> 6 | V24: =(T24-S24)*24*60 -> 112 | AA24: =M24-J24 -> -145.71429 | AB24: =M24/J24 -> 0.91904762
A25: 沙拉線三線 | B25: 微波主食 | C25: 二配金咖哩果香甘口咖哩飯 | E25: 50.92 | F25: 1000 | G25: =E25*F25 -> 50920 | H25: 2 | I25: 16 | J25: 1800 | K25: =J25/I25 -> 112.5 | L25: 16 | M25: =F25/V25*60 -> 1666.6667 | N25: =M25/L25 -> 104.16667 | O25: =L25-I25 -> 0 | P25: =N25-K25 -> -8.3333333 | Q25: =N25/K25 -> 0.92592593 | S25: 0.70833333 | T25: 0.73333333 | U25: =(S25-T24)*24*60 -> 334 | V25: =(T25-S25)*24*60 -> 36 | AA25: =M25-J25 -> -133.33333 | AB25: =M25/J25 -> 0.92592593
A26: 沙拉線三線 | B26: 微波主食 | C26: 二配極旨黑咖哩漢堡排飯 | E26: 53.27 | F26: 544 | G26: =E26*F26 -> 28978.88 | I26: 15 | J26: 1800 | K26: =J26/I26 -> 120 | L26: 15 | M26: =F26/V26*60 -> 1717.8947 | N26: =M26/L26 -> 114.52632 | O26: =L26-I26 -> 0 | P26: =N26-K26 -> -5.4736842 | Q26: =N26/K26 -> 0.95438596 | S26: 0.7375 | T26: 0.75069444 | U26: =(S26-T25)*24*60 -> 6 | V26: =(T26-S26)*24*60 -> 19 | AA26: =M26-J26 -> -82.105263 | AB26: =M26/J26 -> 0.95438596
A27: 沙拉線三線 | B27: 微波主食 | C27: 二配黑胡椒素豬若飯 | E27: 49.91 | F27: 1052 | G27: =E27*F27 -> 52505.32 | I27: 16 | J27: 1800 | K27: =J27/I27 -> 112.5 | L27: 16 | M27: =F27/V27*60 -> 1661.0526 | N27: =M27/L27 -> 103.81579 | O27: =L27-I27 -> 0 | P27: =N27-K27 -> -8.6842105 | Q27: =N27/K27 -> 0.92280702 | S27: 0.75416667 | T27: 0.78055556 | U27: =(S27-T26)*24*60 -> 5 | V27: =(T27-S27)*24*60 -> 38 | AA27: =M27-J27 -> -138.94737 | AB27: =M27/J27 -> 0.92280702
A28: 沙拉線三線 | B28: 微波主食 | C28: 二配美味蟹煲 | E28: 51.62 | F28: 2500 | G28: =E28*F28 -> 129050 | H28: 2 | I28: 20 | J28: 1800 | K28: =J28/I28 -> 90 | L28: 20 | M28: =F28/V28*60 -> 1648.3516 | N28: =M28/L28 -> 82.417582 | O28: =L28-I28 -> 0 | P28: =N28-K28 -> -7.5824176 | Q28: =N28/K28 -> 0.91575092 | S28: 0.78611111 | T28: 0.84930556 | U28: =(S28-T27)*24*60 -> 8 | V28: =(T28-S28)*24*60 -> 91 | AA28: =M28-J28 -> -151.64835 | AB28: =M28/J28 -> 0.91575092
A29: 沙拉線三線 | B29: 微波主食 | C29: 二配金咖哩果香甘口咖哩飯 | E29: 50.92 | F29: 1840 | G29: =E29*F29 -> 93692.8 | I29: 16 | J29: 1800 | K29: =J29/I29 -> 112.5 | L29: 16 | M29: =F29/V29*60 -> 1647.7612 | N29: =M29/L29 -> 102.98507 | O29: =L29-I29 -> 0 | P29: =N29-K29 -> -9.5149254 | Q29: =N29/K29 -> 0.91542289 | S29: 0.89097222 | T29: 0.9375 | U29: =(S29-T28)*24*60 -> 60 | V29: =(T29-S29)*24*60 -> 67 | AA29: =M29-J29 -> -152.23881 | AB29: =M29/J29 -> 0.91542289
A30: 沙拉線三線 | B30: 平均 | I30: 16.7 | J30: 1740 | K30: =J30/I30 -> 104.19162 | L30: 16.7 | M30: =AVERAGE(M20:M29) -> 1606.5792 | N30: =M30/L30 -> 96.202348 | O30: =L30-I30 -> 0 | P30: =N30-K30 -> -7.9892685 | Q30: =N30/K30 -> 0.92332139 | AA30: =M30-J30 -> -133.42078 | AB30: =M30/J30 -> 0.92332139
A31: 三明治一線 | B31: 三明治 | C31: 經典總匯三明治 | E31: 26.2 | F31: 3963 | G31: =E31*F31 -> 103830.6 | I31: 20 | J31: 2400 | K31: =J31/I31 -> 120 | L31: 20 | M31: =F31/V31*60 -> 2201.6667 | N31: =M31/L31 -> 110.08333 | O31: =L31-I31 -> 0 | P31: =N31-K31 -> -9.9166667 | Q31: =N31/K31 -> 0.91736111 | R31: =Q38 -> 0.91599386 | S31: 0.125 | T31: 0.2 | V31: =(T31-S31)*24*60 -> 108 | AA31: =M31-J31 -> -198.33333 | AB31: =M31/J31 -> 0.91736111 | AC31: =AB38 -> 0.91599386
A32: 三明治一線 | B32: 三明治 | C32: 肉鬆火腿三明治 | E32: 20.52 | F32: 4214 | G32: =E32*F32 -> 86471.28 | I32: 18 | J32: 2400 | K32: =J32/I32 -> 133.33333 | L32: 18 | M32: =F32/V32*60 -> 2198.6087 | N32: =M32/L32 -> 122.14493 | O32: =L32-I32 -> 0 | P32: =N32-K32 -> -11.188406 | Q32: =N32/K32 -> 0.91608696 | S32: 0.22013889 | T32: 0.3 | U32: =(S32-T31)*24*60 -> 29 | V32: =(T32-S32)*24*60 -> 115 | AA32: =M32-J32 -> -201.3913 | AB32: =M32/J32 -> 0.91608696
A33: 三明治一線 | B33: 三明治 | C33: 紐奧良風味烤雞鮮蔬三明治 | E33: 31.29 | F33: 3500 | G33: =E33*F33 -> 109515 | H33: 2 | I33: 16 | J33: 2400 | K33: =J33/I33 -> 150 | L33: 16 | M33: =F33/V33*60 -> 2187.5 | N33: =M33/L33 -> 136.71875 | O33: =L33-I33 -> 0 | P33: =N33-K33 -> -13.28125 | Q33: =N33/K33 -> 0.91145833 | S33: 0.30416667 | T33: 0.37083333 | U33: =(S33-T32)*24*60 -> 6 | V33: =(T33-S33)*24*60 -> 96 | AA33: =M33-J33 -> -212.5 | AB33: =M33/J33 -> 0.91145833
A34: 三明治一線 | B34: 三明治 | C34: 起司芋見肉鬆三明治 | E34: 24.25 | F34: 3200 | G34: =E34*F34 -> 77600 | H34: 2 | I34: 18 | J34: 2400 | K34: =J34/I34 -> 133.33333 | L34: 18 | M34: =F34/V34*60 -> 2206.8966 | N34: =M34/L34 -> 122.60536 | O34: =L34-I34 -> 0 | P34: =N34-K34 -> -10.727969 | Q34: =N34/K34 -> 0.91954023 | S34: 0.37569444 | T34: 0.43611111 | U34: =(S34-T33)*24*60 -> 7 | V34: =(T34-S34)*24*60 -> 87 | AA34: =M34-J34 -> -193.10345 | AB34: =M34/J34 -> 0.91954023
A35: 三明治一線 | B35: 三明治 | C35: 藍莓優格三明治(114年) | E35: 22.35 | F35: 2256 | G35: =E35*F35 -> 50421.6 | I35: 16 | J35: 2400 | K35: =J35/I35 -> 150 | L35: 16 | M35: =F35/V35*60 -> 2219.0164 | N35: =M35/L35 -> 138.68852 | O35: =L35-I35 -> 0 | P35: =N35-K35 -> -11.311475 | Q35: =N35/K35 -> 0.92459016 | S35: 0.44097222 | T35: 0.48333333 | U35: =(S35-T34)*24*60 -> 7 | V35: =(T35-S35)*24*60 -> 61 | AA35: =M35-J35 -> -180.98361 | AB35: =M35/J35 -> 0.92459016
A36: 三明治一線 | B36: 三明治 | C36: 紐奧良風味烤雞鮮蔬三明治 | E36: 31.29 | F36: 4739 | G36: =E36*F36 -> 148283.31 | I36: 16 | J36: 2400 | K36: =J36/I36 -> 150 | L36: 16 | M36: =F36/V36*60 -> 2187.2308 | N36: =M36/L36 -> 136.70192 | O36: =L36-I36 -> 0 | P36: =N36-K36 -> -13.298077 | Q36: =N36/K36 -> 0.91134615 | S36: 0.52222222 | T36: 0.6125 | U36: =(S36-T35)*24*60 -> 56 | V36: =(T36-S36)*24*60 -> 130 | AA36: =M36-J36 -> -212.76923 | AB36: =M36/J36 -> 0.91134615
A37: 三明治一線 | B37: 三明治 | C37: 起司芋見肉鬆三明治 | E37: 24.25 | F37: 1969 | G37: =E37*F37 -> 47748.25 | I37: 18 | J37: 2400 | K37: =J37/I37 -> 133.33333 | L37: 18 | M37: =F37/V37*60 -> 2187.7778 | N37: =M37/L37 -> 121.54321 | O37: =L37-I37 -> 0 | P37: =N37-K37 -> -11.790123 | Q37: =N37/K37 -> 0.91157407 | S37: 0.61666667 | T37: 0.65416667 | U37: =(S37-T36)*24*60 -> 6 | V37: =(T37-S37)*24*60 -> 54 | AA37: =M37-J37 -> -212.22222 | AB37: =M37/J37 -> 0.91157407
A38: 三明治一線 | B38: 平均 | I38: 17.428571 | J38: 2400 | K38: =J38/I38 -> 137.70492 | L38: 17.428571 | M38: =AVERAGE(M31:M37) -> 2198.3853 | N38: =M38/L38 -> 126.13686 | O38: =L38-I38 -> 0 | P38: =N38-K38 -> -11.568059 | Q38: =N38/K38 -> 0.91599386 | AA38: =M38-J38 -> -201.61474 | AB38: =M38/J38 -> 0.91599386
A39: 三明治二線 | B39: 三明治 | C39: 鮪魚起司溏心蛋三明治 | E39: 26.2 | F39: 2500 | G39: =E39*F39 -> 65500 | H39: 2 | I39: 18 | J39: 2400 | K39: =J39/I39 -> 133.33333 | L39: 18 | M39: =F39/V39*60 -> 2205.8824 | N39: =M39/L39 -> 122.54902 | O39: =L39-I39 -> 0 | P39: =N39-K39 -> -10.784314 | Q39: =N39/K39 -> 0.91911765 | R39: =Q46 -> 0.91689682 | S39: 0.083333333 | T39: 0.13055556 | V39: =(T39-S39)*24*60 -> 68 | AA39: =M39-J39 -> -194.11765 | AB39: =M39/J39 -> 0.91911765 | AC39: =AB46 -> 0.91689682
A40: 三明治二線 | B40: 三明治 | C40: 瘋狂起司三明治(113年) | E40: 24.45 | F40: 2261 | G40: =E40*F40 -> 55281.45 | I40: 20 | J40: 2400 | K40: =J40/I40 -> 120 | L40: 20 | M40: =F40/V40*60 -> 2223.9344 | N40: =M40/L40 -> 111.19672 | O40: =L40-I40 -> 0 | P40: =N40-K40 -> -8.8032787 | Q40: =N40/K40 -> 0.92663934 | S40: 0.15138889 | T40: 0.19375 | U40: =(S40-T39)*24*60 -> 30 | V40: =(T40-S40)*24*60 -> 61 | AA40: =M40-J40 -> -176.06557 | AB40: =M40/J40 -> 0.92663934
...

Sheet 0729
B1: 屏榮 新豐廠組合室生產人時性分析
B3: 日期 | C3: =TEXT('0729 4度C'!A2,"yyyy.mm.ddaaaa") -> 2025.07.29星期二 | E3: 訂單量 | F3: ='0729 4度C'!D1 -> 169100 | H3: 營業額 | I3: ='0729 4度C'!F1 -> 5815237.7
B4: 人時性 | C4: 項目 | E4: ➀ | G4: ➁ | I4: ➂
C5: 組合室 | E5: 全溫層 | G5: 4度C-各編組展開 | I5: ③三明治-各編組展開
C6: 排關平均 | E6: =AVERAGE(D13:M13) -> 142.11547 | F6: =AVERAGE(D27:O27,D13:J13) -> 145.01729 | G6: =AVERAGE(D13:J13) -> 145.01729 | I6: =AVERAGE(K13:M13) -> 135.34457
C7: 實績平均 | E7: =AVERAGE(D14:M14) -> 130.48172 | F7: =AVERAGE(D28:O28,D14:J14) -> 133.20032 | G7: =AVERAGE(D14:J14) -> 133.20032 | I7: =AVERAGE(K14:M14) -> 124.13834
C8: 達成率平均 | E8: =AVERAGE(D15:M15) -> 0.91723352 | F8: =AVERAGE(D15:J15,D29:O29) -> 0.91724313 | G8: =AVERAGE(D15:J15) -> 0.91724313 | I8: =AVERAGE(K15:M15) -> 0.9172111 | K8: ※現行日本鮮食廠以達成率80%為基本(即為現行KPI)
B10: 溫層 | D10: ➁4度C-各編組展開 | K10: ③三明治-各編組展開
B11: 編組 | D11: 1 | E11: 2 | F11: 3 | G11: 4 | H11: 5 | I11: 6 | J11: 7 | K11: 1 | L11: 2 | M11: 3
D12: 燴飯線 | E12: 沙拉一線 | F12: 沙拉二線 | G12: 沙拉三線 | H12: 自動包裝線 | I12: 涼麵一線 | J12: 三明治四線 | K12: 三明治一線 | L12: 三明治二線 | M12: 自動包裝二線
B13: 人時性 | C13: 排關 | D13: =SUMIFS('0729 4度C'!$K:$K,'0729 4度C'!$A:$A,"燴飯線",'0729 4度C'!$B:$B,"平均") -> 105.88235 | E13: =SUMIFS('0729 4度C'!$K:$K,'0729 4度C'!$A:$A,"沙拉線一線",'0729 4度C'!$B:$B,"平均") -> 81.081081 | F13: =SUMIFS('0729 4度C'!$K:$K,'0729 4度C'!$A:$A,"沙拉線二線",'0729 4度C'!$B:$B,"平均") -> 81.298969 | G13: =SUMIFS('0729 4度C'!$K:$K,'0729 4度C'!$A:$A,"沙拉線三線",'0729 4度C'!$B:$B,"平均") -> 104.19162 | H13: =SUMIFS('0729 4度C'!$K:$K,'0729 4度C'!$A:$A,"自動包裝線",'0729 4度C'!$B:$B,"平均") -> 300 | I13: =SUMIFS('0729 4度C'!$K:$K,'0729 4度C'!$A:$A,"涼麵一線",'0729 4度C'!$B:$B,"平均") -> 89.552239 | J13: =SUMIFS('0729 4度C'!$K:$K,'0729 4度C'!$A:$A,"三明治四線",'0729 4度C'!$B:$B,"平均") -> 253.11475 | K13: =SUMIFS('0729 4度C'!$K:$K,'0729 4度C'!$A:$A,"三明治一線",'0729 4度C'!$B:$B,"平均") -> 137.70492 | L13: =SUMIFS('0729 4度C'!$K:$K,'0729 4度C'!$A:$A,"三明治二線",'0729 4度C'!$B:$B,"平均") -> 127.15232 | M13: =SUMIFS('0729 4度C'!$K:$K,'0729 4度C'!$A:$A,"自動包裝二線",'0729 4度C'!$B:$B,"平均") -> 141.17647
C14: 實績 | D14: =SUMIFS('0729 4度C'!$N:$N,'0729 4度C'!$A:$A,"燴飯線",'0729 4度C'!$B:$B,"平均") -> 96.595212 | E14: =SUMIFS('0729 4度C'!$N:$N,'0729 4度C'!$A:$A,"沙拉線一線",'0729 4度C'!$B:$B,"平均") -> 74.273802 | F14: =SUMIFS('0729 4度C'!$N:$N,'0729 4度C'!$A:$A,"沙拉線二線",'0729 4度C'!$B:$B,"平均") -> 74.323214 | G14: =SUMIFS('0729 4度C'!$N:$N,'0729 4度C'!$A:$A,"沙拉線三線",'0729 4度C'!$B:$B,"平均") -> 95.978781 | H14: =SUMIFS('0729 4度C'!$N:$N,'0729 4度C'!$A:$A,"自動包裝線",'0729 4度C'!$B:$B,"平均") -> 276.14078 | I14: =SUMIFS('0729 4度C'!$N:$N,'0729 4度C'!$A:$A,"涼麵一線",'0729 4度C'!$B:$B,"平均") -> 81.996393 | J14: =SUMIFS('0729 4度C'!$N:$N,'0729 4度C'!$A:$A,"三明治四線",'0729 4度C'!$B:$B,"平均") -> 233.09405 | K14: =SUMIFS('0729 4度C'!$N:$N,'0729 4度C'!$A:$A,"三明治一線",'0729 4度C'!$B:$B,"平均") -> 125.97242 | L14: =SUMIFS('0729 4度C'!$N:$N,'0729 4度C'!$A:$A,"三明治二線",'0729 4度C'!$B:$B,"平均") -> 116.73419 | M14: =SUMIFS('0729 4度C'!$N:$N,'0729 4度C'!$A:$A,"自動包裝二線",'0729 4度C'!$B:$B,"平均") -> 129.7084
C15: 達成率 | D15: =D14/D13 -> 0.91228811 | E15: =E14/E13 -> 0.91604355 | F15: =F14/F13 -> 0.91419627 | G15: =G14/G13 -> 0.92117566 | H15: =H14/H13 -> 0.92046928 | I15: =I14/I13 -> 0.91562639 | J15: =J14/J13 -> 0.92090267 | K15: =K14/K13 -> 0.91479972 | ... M15: =M14/M13 -> 0.9187678
B16: 作業 時間 | C16: 開始 | D16: =VLOOKUP("燴飯線",'0729 4度C'!$A:$T,19,0) -> 0.70833333 | E16: =VLOOKUP("沙拉線一線",'0729 4度C'!$A:$T,19,0) -> 0.13055556 | F16: =VLOOKUP("沙拉線二線",'0729 4度C'!$A:$T,19,0) -> 0.25 | G16: =VLOOKUP("沙拉線三線",'0729 4度C'!$A:$T,19,0) -> 0.16666667 | H16: =VLOOKUP("自動包裝線",'0729 4度C'!$A:$T,19,0) -> 0.20833333 | I16: =VLOOKUP("涼麵一線",'0729 4度C'!$A:$T,19,0) -> 0.29166667 | J16: =VLOOKUP("三明治四線",'0729 4度C'!$A:$T,19,0) -> 0.20833333 | K16: =VLOOKUP("三明治一線",'0729 4度C'!$A:$T,19,0) -> 0.125 | L16: =VLOOKUP("三明治二線",'0729 4度C'!$A:$T,19,0) -> 0.083333333 | M16: =VLOOKUP("自動包裝二線",'0729 4度C'!$A:$T,19,0) -> 0.125
C17: 結束 | D17: =LOOKUP(2,1/(('0729 4度C'!$A:$A="燴飯線")*('0729 4度C'!$T:$T<>"")),'0729 4度C'!$T:$T) -> 0.85555556 | E17: =LOOKUP(2,1/(('0729 4度C'!$A:$A="沙拉線一線")*('0729 4度C'!$T:$T<>"")),'0729 4度C'!$T:$T) -> 0.63819444 | F17: =LOOKUP(2,1/(('0729 4度C'!$A:$A="沙拉線二線")*('0729 4度C'!$T:$T<>"")),'0729 4度C'!$T:$T) -> 0.96041667 | G17: =LOOKUP(2,1/(('0729 4度C'!$A:$A="沙拉線三線")*('0729 4度C'!$T:$T<>"")),'0729 4度C'!$T:$T) -> 0.94791667 | H17: =LOOKUP(2,1/(('0729 4度C'!$A:$A="自動包裝線")*('0729 4度C'!$T:$T<>"")),'0729 4度C'!$T:$T) -> 0.62152778 | I17: =LOOKUP(2,1/(('0729 4度C'!$A:$A="涼麵一線")*('0729 4度C'!$T:$T<>"")),'0729 4度C'!$T:$T) -> 0.82847222 | J17: =LOOKUP(2,1/(('0729 4度C'!$A:$A="三明治四線")*('0729 4度C'!$T:$T<>"")),'0729 4度C'!$T:$T) -> 0.47916667 | K17: =LOOKUP(2,1/(('0729 4度C'!$A:$A="三明治一線")*('0729 4度C'!$T:$T<>"")),'0729 4度C'!$T:$T) -> 0.67916667 | L17: =LOOKUP(2,1/(('0729 4度C'!$A:$A="三明治二線")*('0729 4度C'!$T:$T<>"")),'0729 4度C'!$T:$T) -> 0.63333333 | M17: =LOOKUP(2,1/(('0729 4度C'!$A:$A="自動包裝二線")*('0729 4度C'!$T:$T<>"")),'0729 4度C'!$T:$T) -> 0.64027778
B18: 配置人數 | D18: =SUMIFS('0729 4度C'!$I:$I,'0729 4度C'!$A:$A,"燴飯線",'0729 4度C'!$B:$B,"平均") -> 17 | E18: =SUMIFS('0729 4度C'!$I:$I,'0729 4度C'!$A:$A,"沙拉線一線",'0729 4度C'!$B:$B,"平均") -> 18.5 | F18: =SUMIFS('0729 4度C'!$I:$I,'0729 4度C'!$A:$A,"沙拉線二線",'0729 4度C'!$B:$B,"平均") -> 19.4 | G18: =SUMIFS('0729 4度C'!$I:$I,'0729 4度C'!$A:$A,"沙拉線三線",'0729 4度C'!$B:$B,"平均") -> 16.7 | H18: =SUMIFS('0729 4度C'!$I:$I,'0729 4度C'!$A:$A,"自動包裝線",'0729 4度C'!$B:$B,"平均") -> 10 | I18: =SUMIFS('0729 4度C'!$I:$I,'0729 4度C'!$A:$A,"涼麵一線",'0729 4度C'!$B:$B,"平均") -> 16.75 | J18: =SUMIFS('0729 4度C'!$I:$I,'0729 4度C'!$A:$A,"三明治四線",'0729 4度C'!$B:$B,"平均") -> 10.166667 | K18: =SUMIFS('0729 4度C'!$I:$I,'0729 4度C'!$A:$A,"三明治一線",'0729 4度C'!$B:$B,"平均") -> 17.428571 | L18: =SUMIFS('0729 4度C'!$I:$I,'0729 4度C'!$A:$A,"三明治二線",'0729 4度C'!$B:$B,"平均") -> 18.875 | M18: =SUMIFS('0729 4度C'!$I:$I,'0729 4度C'!$A:$A,"自動包裝二線",'0729 4度C'!$B:$B,"平均") -> 17
B19: 主要應用設備 | D19: ET-55 | E19: 熱縮爐 | F19: L型包裝機 | G19: L型包裝機 | H19: 伺服包裝機 | I19: ET-55 | J19: 伺服包裝機 | K19: 三明治包裝機 | L19: 三明治包裝機 | M19: 三明治包裝機
B20: 次要應用設備 | F20: 圓盤機 | G20: ET-55
B21: 備註 | E21: 握沙拉 | F21: 共用L型包裝機 | H21: 調理麵包 | I21: 炒飯+沙拉 | J21: 調理麵包

Sheet 0729 4度C
A1: 新豐廠四度C日報分析 | C1: 總生產量 | D1: =SUM(F5:F75) -> 169100 | E1: 營業額 | F1: =SUM(G5:G75) -> 5815237.7 | G1: 出勤人數 | H1: =L8+L13+L56+L61+L19+L68+L38+L47+L30+L75 -> 161.82024 | I1: 產線配置圖 | L1: 生產實績 | O1: 人時性差異分析 | S1: 日報登錄 | Y1: 分析說明 | AA1: 產能差異分析
A2: 45867 | B2: 星期二 | C2: 人時性 | D2: =AVERAGE(N8,N13,N56,N61,N19,N68,N30,N38,N47,N75) -> 130.48172 | E2: 平均廠價 | F2: =F1/D1 -> 34.389342 | G2: 多次生產數 | H2: =COUNT(H5:H75) -> 10
A3: 線別 | B3: 品類 | C3: 品名 | E3: 廠價 | F3: 生產量 | G3: 營收 | H3: 多次 生產 | I3: 人數 | J3: 產能/時 | K3: 人時性 | L3: 人數 | M3: 產能/時 | N3: 人時性 | O3: 人數 | P3: 人時性 | Q3: 達成率 | R3: 達成率平均 | S3: 生產時間 | U3: 換線、休息/分 | V3: 稼動時間/分 | W3: 休息時間 | Y3: (新豐回填) | AA3: 產能/時 | AB3: 達成率 | AC3: 達成率平均
S4: 開始 | T4: 結束 | W4: 開始 | X4: 結束
A5: 燴飯線 | B5: 微波主食 | C5: 二配煸椒烘蛋飯 | E5: 46.93 | F5: 1012 | G5: =E5*F5 -> 47493.16 | I5: 17 | J5: 1800 | K5: =J5/I5 -> 105.88235 | L5: 17 | M5: =F5/V5*60 -> 1641.0811 | N5: =M5/L5 -> 96.534181 | O5: =L5-I5 -> 0 | P5: =N5-K5 -> -9.3481717 | Q5: =N5/K5 -> 0.91171171 | R5: =Q8 -> 0.91228811 | S5: 0.70833333 | T5: 0.73402778 | V5: =(T5-S5)*24*60 -> 37 | AA5: =M5-J5 -> -158.91892 | AB5: =M5/J5 -> 0.91171171 | AC5: =AB8 -> 0.91228811
A6: 燴飯線 | B6: 微波主食 | C6: 二配川味麻婆燒豆腐燴飯 | E6: 50.49 | F6: 2137 | G6: =E6*F6 -> 107897.13 | I6: 16 | J6: 1800 | K6: =J6/I6 -> 112.5 | L6: 16 | M6: =F6/V6*60 -> 1643.8462 | N6: =M6/L6 -> 102.74038 | O6: =L6-I6 -> 0 | P6: =N6-K6 -> -9.7596154 | Q6: =N6/K6 -> 0.91324786 | S6: 0.7375 | T6: 0.79166667 | U6: =(S6-T5)*24*60 -> 5 | V6: =(T6-S6)*24*60 -> 78 | AA6: =M6-J6 -> -156.15385 | AB6: =M6/J6 -> 0.91324786
A7: 燴飯線 | B7: 微波主食 | C7: 二配港式香滑嫩蛋牛肉燴飯 | E7: 50.67 | F7: 2298 | G7: =E7*F7 -> 116439.66 | I7: 18 | J7: 1800 | K7: =J7/I7 -> 100 | L7: 18 | M7: =F7/V7*60 -> 1641.4286 | N7: =M7/L7 -> 91.190476 | O7: =L7-I7 -> 0 | P7: =N7-K7 -> -8.8095238 | Q7: =N7/K7 -> 0.91190476 | S7: 0.79722222 | T7: 0.85555556 | U7: =(S7-T6)*24*60 -> 8 | V7: =(T7-S7)*24*60 -> 84 | AA7: =M7-J7 -> -158.57143 | AB7: =M7/J7 -> 0.91190476
A8: 燴飯線 | B8: 平均 | I8: 17 | J8: 1800 | K8: =J8/I8 -> 105.88235 | L8: 17 | M8: =AVERAGE(M5:M7) -> 1642.1186 | N8: =M8/L8 -> 96.595212 | O8: =L8-I8 -> 0 | P8: =N8-K8 -> -9.2871411 | Q8: =N8/K8 -> 0.91228811 | AA8: =M8-J8 -> -157.8814 | AB8: =M8/J8 -> 0.91228811
A9: 沙拉線一線 | B9: 沙拉 | C9: 青醬優格雞肉握沙拉(113年) | E9: 39.62 | F9: 4464 | G9: =E9*F9 -> 176863.68 | I9: 19 | J9: 1500 | K9: =J9/I9 -> 78.947368 | L9: 19 | M9: =F9/V9*60 -> 1373.5385 | N9: =M9/L9 -> 72.291498 | O9: =L9-I9 -> 0 | P9: =N9-K9 -> -6.6558704 | Q9: =N9/K9 -> 0.91569231 | R9: =Q13 -> 0.91604355 | S9: 0.13055556 | T9: 0.26597222 | V9: =(T9-S9)*24*60 -> 195 | AA9: =M9-J9 -> -126.46154 | AB9: =M9/J9 -> 0.91569231 | AC9: =AB13 -> 0.91604355
A10: 沙拉線一線 | B10: 沙拉 | C10: 青檸烤雞握沙拉(113年) | E10: 39.8 | F10: 2600 | G10: =E10*F10 -> 103480 | H10: 2 | I10: 18 | J10: 1500 | K10: =J10/I10 -> 83.333333 | L10: 18 | M10: =F10/V10*60 -> 1380.531 | N10: =M10/L10 -> 76.696165 | O10: =L10-I10 -> 0 | P10: =N10-K10 -> -6.6371681 | Q10: =N10/K10 -> 0.92035398 | S10: 0.28888889 | T10: 0.36736111 | U10: =(S10-T9)*24*60 -> 33 | V10: =(T10-S10)*24*60 -> 113 | AA10: =M10-J10 -> -119.46903 | AB10: =M10/J10 -> 0.92035398
A11: 沙拉線一線 | B11: 沙拉 | C11: 地瓜瓜握沙拉 | E11: 39.29 | F11: 3835 | G11: =E11*F11 -> 150677.15 | I11: 19 | J11: 1500 | K11: =J11/I11 -> 78.947368 | L11: 19 | M11: =F11/V11*60 -> 1369.6429 | N11: =M11/L11 -> 72.086466 | O11: =L11-I11 -> 0 | P11: =N11-K11 -> -6.8609023 | Q11: =N11/K11 -> 0.91309524 | S11: 0.375 | T11: 0.49166667 | U11: =(S11-T10)*24*60 -> 11 | V11: =(T11-S11)*24*60 -> 168 | AA11: =M11-J11 -> -130.35714 | AB11: =M11/J11 -> 0.91309524
A12: 沙拉線一線 | B12: 沙拉 | C12: 青檸烤雞握沙拉(113年) | E12: 39.8 | F12: 3500 | G12: =E12*F12 -> 139300 | I12: 18 | J12: 1500 | K12: =J12/I12 -> 83.333333 | L12: 18 | M12: =F12/V12*60 -> 1372.549 | N12: =M12/L12 -> 76.252723 | O12: =L12-I12 -> 0 | P12: =N12-K12 -> -7.08061 | Q12: =N12/K12 -> 0.91503268 | S12: 0.53194444 | T12: 0.63819444 | U12: =(S12-T11)*24*60 -> 58 | V12: =(T12-S12)*24*60 -> 153 | AA12: =M12-J12 -> -127.45098 | AB12: =M12/J12 -> 0.91503268
A13: 沙拉線一線 | B13: 平均 | I13: 18.5 | J13: 1500 | K13: =J13/I13 -> 81.081081 | L13: 18.5 | M13: =AVERAGE(M9:M12) -> 1374.0653 | N13: =M13/L13 -> 74.273802 | O13: =L13-I13 -> 0 | P13: =N13-K13 -> -6.8072796 | Q13: =N13/K13 -> 0.91604355 | AA13: =M13-J13 -> -125.93467 | AB13: =M13/J13 -> 0.91604355
A14: 沙拉線二線 | B14: 小菜、微波 | C14: 剝皮辣椒雞湯 | E14: 41 | F14: 1841 | G14: =E14*F14 -> 75481 | I14: 26 | J14: 1286 | K14: =J14/I14 -> 49.461538 | L14: 26 | M14: =F14/V14*60 -> 1175.1064 | N14: =M14/L14 -> 45.196399 | O14: =L14-I14 -> 0 | P14: =N14-K14 -> -4.2651391 | Q14: =N14/K14 -> 0.91376857 | R14: =Q19 -> 0.91419627 | S14: 0.25 | T14: 0.31527778 | V14: =(T14-S14)*24*60 -> 94 | AA14: =M14-J14 -> -110.89362 | AB14: =M14/J14 -> 0.91376857 | AC14: =AB19 -> 0.91419627
A15: 沙拉線二線 | B15: 沙拉 | C15: 厚蛋時蔬握沙拉 | E15: 39.29 | F15: 3307 | G15: =E15*F15 -> 129932.03 | I15: 18 | J15: 1500 | K15: =J15/I15 -> 83.333333 | L15: 18 | M15: =F15/V15*60 -> 1368.4138 | N15: =M15/L15 -> 76.022989 | O15: =L15-I15 -> 0 | P15: =N15-K15 -> -7.3103448 | Q15: =N15/K15 -> 0.91227586 | S15: 0.32638889 | T15: 0.42708333 | U15: =(S15-T14)*24*60 -> 16 | V15: =(T15-S15)*24*60 -> 145 | AA15: =M15-J15 -> -131.58621 | AB15: =M15/J15 -> 0.91227586
A16: 沙拉線二線 | B16: 微波主食 | C16: 二配金咖哩濃厚辛辣咖哩飯 | E16: 50.98 | F16: 2868 | G16: =E16*F16 -> 146210.64 | I16: 17 | J16: 1800 | K16: =J16/I16 -> 105.88235 | L16: 17 | M16: =F16/V16*60 -> 1654.6154 | N16: =M16/L16 -> 97.330317 | O16: =L16-I16 -> 0 | P16: =N16-K16 -> -8.5520362 | Q16: =N16/K16 -> 0.91923077 | S16: 0.70833333 | T16: 0.78055556 | U16: =(S16-T15)*24*60 -> 405 | V16: =(T16-S16)*24*60 -> 104 | AA16: =M16-J16 -> -145.38462 | AB16: =M16/J16 -> 0.91923077
A17: 沙拉線二線 | B17: 微波主食 | C17: 二配粗飽系雞排炒飯 | E17: 57.73 | F17: 1685 | G17: =E17*F17 -> 97275.05 | I17: 16 | J17: 1500 | K17: =J17/I17 -> 93.75 | L17: 16 | M17: =F17/V17*60 -> 1366.2162 | N17: =M17/L17 -> 85.388514 | O17: =L17-I17 -> 0 | P17: =N17-K17 -> -8.3614865 | Q17: =N17/K17 -> 0.91081081 | S17: 0.78472222 | T17: 0.83611111 | U17: =(S17-T16)*24*60 -> 6 | V17: =(T17-S17)*24*60 -> 74 | AA17: =M17-J17 -> -133.78378 | AB17: =M17/J17 -> 0.91081081
A18: 沙拉線二線 | B18: 微波主食 | C18: 二配美味蟹煲 | E18: 51.62 | F18: 3290 | G18: =E18*F18 -> 169829.8 | I18: 20 | J18: 1800 | K18: =J18/I18 -> 90 | L18: 20 | M18: =F18/V18*60 -> 1645 | N18: =M18/L18 -> 82.25 | O18: =L18-I18 -> 0 | P18: =N18-K18 -> -7.75 | Q18: =N18/K18 -> 0.91388889 | S18: 0.87708333 | T18: 0.96041667 | U18: =(S18-T17)*24*60 -> 59 | V18: =(T18-S18)*24*60 -> 120 | AA18: =M18-J18 -> -155 | AB18: =M18/J18 -> 0.91388889
A19: 沙拉線二線 | B19: 平均 | I19: =AVERAGE(I14:I18) -> 19.4 | J19: 1577.2 | K19: =J19/I19 -> 81.298969 | L19: =AVERAGE(L14:L18) -> 19.4 | M19: =AVERAGE(M14:M18) -> 1441.8704 | N19: =M19/L19 -> 74.323214 | O19: =L19-I19 -> 0 | P19: =N19-K19 -> -6.9757549 | Q19: =N19/K19 -> 0.91419627 | AA19: =M19-J19 -> -135.32964 | AB19: =M19/J19 -> 0.91419627
A20: 沙拉線三線 | B20: 小吃 | C20: 古早味炒炊粉 | E20: 43.14 | F20: 1143 | G20: =E20*F20 -> 49309.02 | I20: 17 | J20: 1200 | K20: =J20/I20 -> 70.588235 | L20: 17 | M20: =F20/V20*60 -> 1106.129 | N20: =M20/L20 -> 65.066414 | O20: =L20-I20 -> 0 | P20: =N20-K20 -> -5.5218216 | Q20: =N20/K20 -> 0.92177419 | R20: =Q30 -> 0.92117566 | S20: 0.16666667 | T20: 0.20972222 | V20: =(T20-S20)*24*60 -> 62 | AA20: =M20-J20 -> -93.870968 | AB20: =M20/J20 -> 0.92177419 | AC20: =AB30 -> 0.92117566
A21: 沙拉線三線 | B21: 微波主食 | C21: 鐵板滑蛋炸豬排丼 | E21: 57.73 | F21: 3216 | G21: =E21*F21 -> 185659.68 | I21: 16 | J21: 1800 | K21: =J21/I21 -> 112.5 | L21: 16 | M21: =F21/V21*60 -> 1649.2308 | N21: =M21/L21 -> 103.07692 | O21: =L21-I21 -> 0 | P21: =N21-K21 -> -9.4230769 | Q21: =N21/K21 -> 0.91623932 | S21: 0.22777778 | T21: 0.30902778 | U21: =(S21-T20)*24*60 -> 26 | V21: =(T21-S21)*24*60 -> 117 | AA21: =M21-J21 -> -150.76923 | AB21: =M21/J21 -> 0.91623932
A22: 沙拉線三線 | B22: 微波主食 | C22: 極上炙烤親子丼 | E22: 53.68 | F22: 1964 | G22: =E22*F22 -> 105427.52 | I22: 17 | J22: 1800 | K22: =J22/I22 -> 105.88235 | L22: 17 | M22: =F22/V22*60 -> 1659.7183 | N22: =M22/L22 -> 97.630489 | O22: =L22-I22 -> 0 | P22: =N22-K22 -> -8.2518641 | Q22: =N22/K22 -> 0.92206573 | S22: 0.31319444 | T22: 0.3625 | U22: =(S22-T21)*24*60 -> 6 | V22: =(T22-S22)*24*60 -> 71 | AA22: =M22-J22 -> -140.28169 | AB22: =M22/J22 -> 0.92206573
A23: 沙拉線三線 | B23: 微波主食 | C23: 紅燒纖牛若風味燴飯 | E23: 50.67 | F23: 1083 | G23: =E23*F23 -> 54875.61 | I23: 16 | J23: 1800 | K23: =J23/I23 -> 112.5 | L23: 16 | M23: =F23/V23*60 -> 1666.1538 | N23: =M23/L23 -> 104.13462 | O23: =L23-I23 -> 0 | P23: =N23-K23 -> -8.3653846 | Q23: =N23/K23 -> 0.92564103 | S23: 0.36597222 | T23: 0.39305556 | U23: =(S23-T22)*24*60 -> 5 | V23: =(T23-S23)*24*60 -> 39 | AA23: =M23-J23 -> -133.84615 | AB23: =M23/J23 -> 0.92564103
A24: 沙拉線三線 | B24: 微波主食 | C24: 海老鰻魚丼滋丼 | E24: 58.17 | F24: 3122 | G24: =E24*F24 -> 181606.74 | I24: 18 | J24: 1800 | K24: =J24/I24 -> 100 | L24: 18 | M24: =F24/V24*60 -> 1643.1579 | N24: =M24/L24 -> 91.28655 | O24: =L24-I24 -> 0 | P24: =N24-K24 -> -8.7134503 | Q24: =N24/K24 -> 0.9128655 | S24: 0.39722222 | T24: 0.47638889 | U24: =(S24-T23)*24*60 -> 6 | V24: =(T24-S24)*24*60 -> 114 | AA24: =M24-J24 -> -156.84211 | AB24: =M24/J24 -> 0.9128655
A25: 沙拉線三線 | B25: 微波主食 | C25: 二配金咖哩果香甘口咖哩飯 | E25: 50.92 | F25: 1000 | G25: =E25*F25 -> 50920 | H25: 2 | I25: 16 | J25: 1800 | K25: =J25/I25 -> 112.5 | L25: 16 | M25: =F25/V25*60 -> 1666.6667 | N25: =M25/L25 -> 104.16667 | O25: =L25-I25 -> 0 | P25: =N25-K25 -> -8.3333333 | Q25: =N25/K25 -> 0.92592593 | S25: 0.70833333 | T25: 0.73333333 | U25: =(S25-T24)*24*60 -> 334 | V25: =(T25-S25)*24*60 -> 36 | AA25: =M25-J25 -> -133.33333 | AB25: =M25/J25 -> 0.92592593
