Workbook

Sheet 1130
B1: 屏榮 新豐廠組合室生產人時性分析
B3: 日期 | C3: =TEXT('1130 4度C'!A2,"yyyy.mm.ddaaaa") -> 2025.11.30星期日 | E3: 訂單量 | F3: ='1130 4度C'!D1 -> 193540 | H3: 營業額 | I3: ='1130 4度C'!F1 -> 6409222.4
B4: 人時性 | C4: 項目 | E4: ➀ | G4: ➁ | I4: ➂
C5: 組合室 | E5: 全溫層 | G5: 4度C-各編組展開 | I5: ③三明治-各編組展開
C6: 排關平均 | E6: =AVERAGE(D13:M13) -> 154.81744 | F6: =AVERAGE(D27:O27,D13:J13) -> 160.95277 | G6: =AVERAGE(D13:J13) -> 160.95277 | I6: =AVERAGE(K13:M13) -> 140.50167
C7: 實績平均 | E7: =AVERAGE(D14:M14) -> 148.24561 | F7: =AVERAGE(D28:O28,D14:J14) -> 154.23953 | G7: =AVERAGE(D14:J14) -> 154.23953 | I7: =AVERAGE(K14:M14) -> 134.25979
C8: 達成率平均 | E8: =AVERAGE(D15:M15) -> 0.95758579 | F8: =AVERAGE(D15:J15,D29:O29) -> 0.95844522 | G8: =AVERAGE(D15:J15) -> 0.95844522 | I8: =AVERAGE(K15:M15) -> 0.95558045 | K8: ※現行日本鮮食廠以達成率80%為基本(即為現行KPI)
B10: 溫層 | D10: ➁4度C-各編組展開 | K10: ③三明治-各編組展開
B11: 編組 | D11: 1 | E11: 2 | F11: 3 | G11: 4 | H11: 5 | I11: 6 | J11: 7 | K11: 1 | L11: 2 | M11: 3
D12: 新豐6線 | E12: 新豐2線 | F12: 新豐5線 | G12: 新豐7線 | H12: 新豐3線 | I12: 新豐1線 | J12: 新豐10線 | K12: 新豐8線 | L12: 新豐9線 | M12: 新豐4線
B13: 人時性 | C13: 排關 | D13: =SUMIFS('1130 4度C'!$K:$K,'1130 4度C'!$A:$A,"新豐6線",'1130 4度C'!$B:$B,"平均") -> 137.93103 | E13: =SUMIFS('1130 4度C'!$K:$K,'1130 4度C'!$A:$A,"新豐2線",'1130 4度C'!$B:$B,"平均") -> 88.235294 | F13: =SUMIFS('1130 4度C'!$K:$K,'1130 4度C'!$A:$A,"新豐5線",'1130 4度C'!$B:$B,"平均") -> 97.826087 | G13: =SUMIFS('1130 4度C'!$K:$K,'1130 4度C'!$A:$A,"新豐7線",'1130 4度C'!$B:$B,"平均") -> 114.81481 | H13: =SUMIFS('1130 4度C'!$K:$K,'1130 4度C'!$A:$A,"新豐3線",'1130 4度C'!$B:$B,"平均") -> 283.95062 | I13: =SUMIFS('1130 4度C'!$K:$K,'1130 4度C'!$A:$A,"新豐1線",'1130 4度C'!$B:$B,"平均") -> 112.2449 | J13: =SUMIFS('1130 4度C'!$K:$K,'1130 4度C'!$A:$A,"新豐10線",'1130 4度C'!$B:$B,"平均") -> 291.66667 | K13: =SUMIFS('1130 4度C'!$K:$K,'1130 4度C'!$A:$A,"新豐8線",'1130 4度C'!$B:$B,"平均") -> 134.26573 | L13: =SUMIFS('1130 4度C'!$K:$K,'1130 4度C'!$A:$A,"新豐9線",'1130 4度C'!$B:$B,"平均") -> 140 | M13: =SUMIFS('1130 4度C'!$K:$K,'1130 4度C'!$A:$A,"新豐4線",'1130 4度C'!$B:$B,"平均") -> 147.23926
C14: 實績 | D14: =SUMIFS('1130 4度C'!$N:$N,'1130 4度C'!$A:$A,"新豐6線",'1130 4度C'!$B:$B,"平均") -> 132.73016 | E14: =SUMIFS('1130 4度C'!$N:$N,'1130 4度C'!$A:$A,"新豐2線",'1130 4度C'!$B:$B,"平均") -> 84.046287 | F14: =SUMIFS('1130 4度C'!$N:$N,'1130 4度C'!$A:$A,"新豐5線",'1130 4度C'!$B:$B,"平均") -> 93.827667 | G14: =SUMIFS('1130 4度C'!$N:$N,'1130 4度C'!$A:$A,"新豐7線",'1130 4度C'!$B:$B,"平均") -> 110.34699 | H14: =SUMIFS('1130 4度C'!$N:$N,'1130 4度C'!$A:$A,"新豐3線",'1130 4度C'!$B:$B,"平均") -> 271.23928 | I14: =SUMIFS('1130 4度C'!$N:$N,'1130 4度C'!$A:$A,"新豐1線",'1130 4度C'!$B:$B,"平均") -> 107.71346 | J14: =SUMIFS('1130 4度C'!$N:$N,'1130 4度C'!$A:$A,"新豐10線",'1130 4度C'!$B:$B,"平均") -> 279.7729 | K14: =SUMIFS('1130 4度C'!$N:$N,'1130 4度C'!$A:$A,"新豐8線",'1130 4度C'!$B:$B,"平均") -> 128.4334 | L14: =SUMIFS('1130 4度C'!$N:$N,'1130 4度C'!$A:$A,"新豐9線",'1130 4度C'!$B:$B,"平均") -> 133.58493 | M14: =SUMIFS('1130 4度C'!$N:$N,'1130 4度C'!$A:$A,"新豐4線",'1130 4度C'!$B:$B,"平均") -> 140.76103
C15: 達成率 | D15: =D14/D13 -> 0.96229366 | E15: =E14/E13 -> 0.95252459 | F15: =F14/F13 -> 0.95912727 | G15: =G14/G13 -> 0.96108667 | H15: =H14/H13 -> 0.95523399 | I15: =I14/I13 -> 0.959629 | J15: =J14/J13 -> 0.95922137 | K15: =K14/K13 -> 0.95656129 | ... M15: =M14/M13 -> 0.95600202
B16: 作業 時間 | C16: 開始 | D16: =VLOOKUP("新豐6線",'1130 4度C'!$A:$T,19,0) -> 0.70833333 | E16: =VLOOKUP("新豐2線",'1130 4度C'!$A:$T,19,0) -> 0.20833333 | F16: =VLOOKUP("新豐5線",'1130 4度C'!$A:$T,19,0) -> 0.125 | G16: =VLOOKUP("新豐7線",'1130 4度C'!$A:$T,19,0) -> 0.20833333 | H16: =VLOOKUP("新豐3線",'1130 4度C'!$A:$T,19,0) -> 0.083333333 | I16: =VLOOKUP("新豐1線",'1130 4度C'!$A:$T,19,0) -> 0.20833333 | J16: =VLOOKUP("新豐10線",'1130 4度C'!$A:$T,19,0) -> 0.20833333 | K16: =VLOOKUP("新豐8線",'1130 4度C'!$A:$T,19,0) -> 0.083333333 | L16: =VLOOKUP("新豐9線",'1130 4度C'!$A:$T,19,0) -> 0.083333333 | M16: =VLOOKUP("新豐4線",'1130 4度C'!$A:$T,19,0) -> 0.083333333
C17: 結束 | D17: =LOOKUP(2,1/(('1130 4度C'!$A:$A="新豐6線")*('1130 4度C'!$T:$T<>"")),'1130 4度C'!$T:$T) -> 0.91458333 | E17: =LOOKUP(2,1/(('1130 4度C'!$A:$A="新豐2線")*('1130 4度C'!$T:$T<>"")),'1130 4度C'!$T:$T) -> 0.42013889 | F17: =LOOKUP(2,1/(('1130 4度C'!$A:$A="新豐5線")*('1130 4度C'!$T:$T<>"")),'1130 4度C'!$T:$T) -> 0.86666667 | G17: =LOOKUP(2,1/(('1130 4度C'!$A:$A="新豐7線")*('1130 4度C'!$T:$T<>"")),'1130 4度C'!$T:$T) -> 0.85902778 | H17: =LOOKUP(2,1/(('1130 4度C'!$A:$A="新豐3線")*('1130 4度C'!$T:$T<>"")),'1130 4度C'!$T:$T) -> 0.60208333 | I17: =LOOKUP(2,1/(('1130 4度C'!$A:$A="新豐1線")*('1130 4度C'!$T:$T<>"")),'1130 4度C'!$T:$T) -> 0.95 | J17: =LOOKUP(2,1/(('1130 4度C'!$A:$A="新豐10線")*('1130 4度C'!$T:$T<>"")),'1130 4度C'!$T:$T) -> 0.44375 | K17: =LOOKUP(2,1/(('1130 4度C'!$A:$A="新豐8線")*('1130 4度C'!$T:$T<>"")),'1130 4度C'!$T:$T) -> 0.76180556 | L17: =LOOKUP(2,1/(('1130 4度C'!$A:$A="新豐9線")*('1130 4度C'!$T:$T<>"")),'1130 4度C'!$T:$T) -> 0.73611111 | M17: =LOOKUP(2,1/(('1130 4度C'!$A:$A="新豐4線")*('1130 4度C'!$T:$T<>"")),'1130 4度C'!$T:$T) -> 0.75
B18: 配置人數 | D18: =SUMIFS('1130 4度C'!$I:$I,'1130 4度C'!$A:$A,"新豐6線",'1130 4度C'!$B:$B,"平均") -> 14.5 | E18: =SUMIFS('1130 4度C'!$I:$I,'1130 4度C'!$A:$A,"新豐2線",'1130 4度C'!$B:$B,"平均") -> 17 | F18: =SUMIFS('1130 4度C'!$I:$I,'1130 4度C'!$A:$A,"新豐5線",'1130 4度C'!$B:$B,"平均") -> 18.4 | G18: =SUMIFS('1130 4度C'!$I:$I,'1130 4度C'!$A:$A,"新豐7線",'1130 4度C'!$B:$B,"平均") -> 16.875 | H18: =SUMIFS('1130 4度C'!$I:$I,'1130 4度C'!$A:$A,"新豐3線",'1130 4度C'!$B:$B,"平均") -> 10.125 | I18: =SUMIFS('1130 4度C'!$I:$I,'1130 4度C'!$A:$A,"新豐1線",'1130 4度C'!$B:$B,"平均") -> 16.333333 | J18: =SUMIFS('1130 4度C'!$I:$I,'1130 4度C'!$A:$A,"新豐10線",'1130 4度C'!$B:$B,"平均") -> 9 | K18: =SUMIFS('1130 4度C'!$I:$I,'1130 4度C'!$A:$A,"新豐8線",'1130 4度C'!$B:$B,"平均") -> 17.875 | L18: =SUMIFS('1130 4度C'!$I:$I,'1130 4度C'!$A:$A,"新豐9線",'1130 4度C'!$B:$B,"平均") -> 17.142857 | M18: =SUMIFS('1130 4度C'!$I:$I,'1130 4度C'!$A:$A,"新豐4線",'1130 4度C'!$B:$B,"平均") -> 16.3
B19: 主要應用設備 | D19: ET-55 | E19: 熱縮爐 | F19: L型包裝機 | G19: L型包裝機 | H19: 伺服包裝機 | I19: ET-55 | J19: 伺服包裝機 | K19: 三明治包裝機 | L19: 三明治包裝機 | M19: 三明治包裝機
B20: 次要應用設備 | F20: 圓盤機 | G20: ET-55
B21: 備註 | E21: 握沙拉 | F21: 共用L型包裝機 | H21: 調理麵包 | I21: 炒飯+沙拉 | J21: 調理麵包

Sheet 1130 4度C
A1: 新豐廠四度C日報分析 | C1: 總生產量 | D1: 193540 | E1: 營業額 | F1: 6409222.4 | G1: 出勤人數 | H1: =L9+L11+L52+L59+L17+L64+L35+L43+L26+L75 -> 153.55119 | I1: 產線配置圖 | L1: 生產實績 | O1: 人時性差異分析 | S1: 日報登錄 | Y1: 分析說明 | AA1: 產能差異分析
A2: 45991 | B2: 星期日 | C2: 人時性 | D2: 148.24561 | E2: 平均廠價 | F2: 33.115751 | G2: 多次生產數 | H2: =COUNT(H5:H75) -> 11
A3: 線別 | B3: 品類 | C3: 品名 | E3: 廠價 | F3: 生產量 | G3: 營收 | H3: 多次 生產 | I3: 人數 | J3: 產能/時 | K3: 人時性 | L3: 人數 | M3: 產能/時 | N3: 人時性 | O3: 人數 | P3: 人時性 | Q3: 達成率 | R3: 達成率平均 | S3: 生產時間 | U3: 換線、休息/分 | V3: 稼動時間/分 | W3: 休息時間 | Y3: (新豐回填) | AA3: 產能/時 | AB3: 達成率 | AC3: 達成率平均
S4: 開始 | T4: 結束 | W4: 開始 | X4: 結束
A5: 新豐6線 | B5: 微波主食 | C5: 二配港式香滑嫩蛋牛肉燴飯 | E5: 50.67 | F5: 1767 | G5: =E5*F5 -> 89533.89 | I5: 17 | J5: 2000 | K5: =J5/I5 -> 117.64706 | L5: 17 | M5: =F5/V5*60 -> 1927.6364 | N5: =M5/L5 -> 113.39037 | O5: =L5-I5 -> 0 | P5: =N5-K5 -> -4.2566845 | Q5: =N5/K5 -> 0.96381818 | R5: =Q9 -> 0.96229366 | S5: 0.70833333 | T5: 0.74652778 | V5: =(T5-S5)*24*60 -> 55 | AA5: =M5-J5 -> -72.363636 | AB5: =M5/J5 -> 0.96381818 | AC5: =AB9 -> 0.96229366
A6: 新豐6線 | B6: 微波主食 | C6: 二配川味麻婆燒豆腐燴飯 | E6: 50.49 | F6: 2183 | G6: =E6*F6 -> 110219.67 | I6: 15 | J6: 2000 | K6: =J6/I6 -> 133.33333 | L6: 15 | M6: =F6/V6*60 -> 1926.1765 | N6: =M6/L6 -> 128.41176 | O6: =L6-I6 -> 0 | P6: =N6-K6 -> -4.9215686 | Q6: =N6/K6 -> 0.96308824 | S6: 0.75 | T6: 0.79722222 | U6: =IF(S6=TIME(17,0,0),"",(S6-T5)*24*60) -> 5 | V6: =(T6-S6)*24*60 -> 68 | AA6: =M6-J6 -> -73.823529 | AB6: =M6/J6 -> 0.96308824
A7: 新豐6線 | B7: 微波主食 | C7: 二配厚香料咖哩雞排飯 | E7: 57.3 | F7: 1500 | G7: =E7*F7 -> 85950 | H7: 2 | I7: 13 | J7: 2000 | K7: =J7/I7 -> 153.84615 | L7: 13 | M7: =F7/V7*60 -> 1914.8936 | N7: =M7/L7 -> 147.29951 | O7: =L7-I7 -> 0 | P7: =N7-K7 -> -6.5466448 | Q7: =N7/K7 -> 0.95744681 | S7: 0.80138889 | T7: 0.83402778 | U7: =IF(S7=TIME(17,0,0),"",(S7-T6)*24*60) -> 6 | V7: =(T7-S7)*24*60 -> 47 | W7: =T7 -> 0.83402778 | X7: =S8 -> 0.87569444 | AA7: =M7-J7 -> -85.106383 | AB7: =M7/J7 -> 0.95744681
A8: 新豐6線 | B8: 微波主食 | C8: 二配厚香料咖哩雞排飯 | E8: 57.3 | F8: 1801 | G8: =E8*F8 -> 103197.3 | I8: 13 | J8: 2000 | K8: =J8/I8 -> 153.84615 | L8: 13 | M8: =F8/V8*60 -> 1929.6429 | N8: =M8/L8 -> 148.43407 | O8: =L8-I8 -> 0 | P8: =N8-K8 -> -5.4120879 | Q8: =N8/K8 -> 0.96482143 | S8: 0.87569444 | T8: 0.91458333 | U8: =IF(S8=TIME(17,0,0),"",(S8-T7)*24*60) -> 60 | V8: =(T8-S8)*24*60 -> 56 | AA8: =M8-J8 -> -70.357143 | AB8: =M8/J8 -> 0.96482143
A9: 新豐6線 | B9: 平均 | I9: 14.5 | J9: 2000 | K9: =J9/I9 -> 137.93103 | L9: 14.5 | M9: =AVERAGE(M5:M8) -> 1924.5873 | N9: =M9/L9 -> 132.73016 | O9: =L9-I9 -> 0 | P9: =N9-K9 -> -5.200874 | Q9: =N9/K9 -> 0.96229366 | AA9: =M9-J9 -> -75.412673 | AB9: =M9/J9 -> 0.96229366
A10: 新豐2線 | B10: 沙拉 | C10: 青檸烤雞握沙拉(113年) | E10: 39.8 | F10: 7263 | G10: =E10*F10 -> 289067.4 | I10: 17 | J10: 1500 | K10: =J10/I10 -> 88.235294 | L10: 17 | M10: =F10/V10*60 -> 1428.7869 | N10: =M10/L10 -> 84.046287 | O10: =L10-I10 -> 0 | P10: =N10-K10 -> -4.1890068 | Q10: =N10/K10 -> 0.95252459 | R10: =Q11 -> 0.95252459 | S10: 0.20833333 | T10: 0.42013889 | V10: =(T10-S10)*24*60 -> 305 | AA10: =M10-J10 -> -71.213115 | AB10: =M10/J10 -> 0.95252459 | AC10: =AB11 -> 0.95252459
A11: 新豐2線 | B11: 平均 | I11: 17 | J11: 1500 | K11: =J11/I11 -> 88.235294 | L11: 17 | M11: =AVERAGE(M10:M10) -> 1428.7869 | N11: =M11/L11 -> 84.046287 | O11: =L11-I11 -> 0 | P11: =N11-K11 -> -4.1890068 | Q11: =N11/K11 -> 0.95252459 | AA11: =M11-J11 -> -71.213115 | AB11: =M11/J11 -> 0.95252459
A12: 新豐5線 | B12: 小吃 | C12: 剝皮辣椒雞湯 | E12: 41 | F12: 2392 | G12: =E12*F12 -> 98072 | I12: 26 | J12: 1500 | K12: =J12/I12 -> 57.692308 | L12: 26 | M12: =F12/V12*60 -> 1435.2 | N12: =M12/L12 -> 55.2 | O12: =L12-I12 -> 0 | P12: =N12-K12 -> -2.4923077 | Q12: =N12/K12 -> 0.9568 | R12: =Q17 -> 0.95912727 | S12: 0.125 | T12: 0.19444444 | V12: =(T12-S12)*24*60 -> 100 | W12: =T12 -> 0.19444444 | X12: =S13 -> 0.21458333 | AA12: =M12-J12 -> -64.8 | AB12: =M12/J12 -> 0.9568 | AC12: =AB17 -> 0.95912727
A13: 新豐5線 | B13: 沙拉 | C13: 青醬優格雞肉握沙拉(113年) | E13: 39.62 | F13: 4473 | G13: =E13*F13 -> 177220.26 | I13: 19 | J13: 1500 | K13: =J13/I13 -> 78.947368 | L13: 19 | M13: =F13/V13*60 -> 1435.1872 | N13: =M13/L13 -> 75.536167 | O13: =L13-I13 -> 0 | P13: =N13-K13 -> -3.4112018 | Q13: =N13/K13 -> 0.95679144 | S13: 0.21458333 | T13: 0.34444444 | U13: =IF(S13=TIME(17,0,0),"",(S13-T12)*24*60) -> 29 | V13: =(T13-S13)*24*60 -> 187 | AA13: =M13-J13 -> -64.812834 | AB13: =M13/J13 -> 0.95679144
A14: 新豐5線 | B14: 微波主食 | C14: 二配金咖哩濃厚辛口咖哩飯 | E14: 50.98 | F14: 2893 | G14: =E14*F14 -> 147485.14 | I14: 16 | J14: 2000 | K14: =J14/I14 -> 125 | L14: 16 | M14: =F14/V14*60 -> 1907.4725 | N14: =M14/L14 -> 119.21703 | O14: =L14-I14 -> 0 | P14: =N14-K14 -> -5.782967 | Q14: =N14/K14 -> 0.95373626 | S14: 0.70833333 | T14: 0.77152778 | U14: =IF(S14=TIME(17,0,0),"",(S14-T13)*24*60) | V14: =(T14-S14)*24*60 -> 91 | AA14: =M14-J14 -> -92.527473 | AB14: =M14/J14 -> 0.95373626
A15: 新豐5線 | B15: 微波主食 | C15: 二配金咖哩果香甘口咖哩飯 | E15: 50.92 | F15: 2868 | G15: =E15*F15 -> 146038.56 | I15: 15 | J15: 2000 | K15: =J15/I15 -> 133.33333 | L15: 15 | M15: =F15/V15*60 -> 1912 | N15: =M15/L15 -> 127.46667 | O15: =L15-I15 -> 0 | P15: =N15-K15 -> -5.8666667 | Q15: =N15/K15 -> 0.956 | S15: 0.77569444 | T15: 0.83819444 | U15: =IF(S15=TIME(17,0,0),"",(S15-T14)*24*60) -> 6 | V15: =(T15-S15)*24*60 -> 90 | AA15: =M15-J15 -> -88 | AB15: =M15/J15 -> 0.956
A16: 新豐5線 | B16: 微波主食 | C16: 二配煸椒烘蛋飯 | E16: 46.93 | F16: 1133 | G16: =E16*F16 -> 53171.69 | I16: 16 | J16: 2000 | K16: =J16/I16 -> 125 | L16: 16 | M16: =F16/V16*60 -> 1942.2857 | N16: =M16/L16 -> 121.39286 | O16: =L16-I16 -> 0 | P16: =N16-K16 -> -3.6071429 | Q16: =N16/K16 -> 0.97114286 | S16: 0.84236111 | T16: 0.86666667 | U16: =IF(S16=TIME(17,0,0),"",(S16-T15)*24*60) -> 6 | V16: =(T16-S16)*24*60 -> 35 | AA16: =M16-J16 -> -57.714286 | AB16: =M16/J16 -> 0.97114286
A17: 新豐5線 | B17: 平均 | I17: 18.4 | J17: 1800 | K17: =J17/I17 -> 97.826087 | L17: 18.4 | M17: =AVERAGE(M12:M16) -> 1726.4291 | N17: =M17/L17 -> 93.827667 | O17: =L17-I17 -> 0 | P17: =N17-K17 -> -3.9984195 | Q17: =N17/K17 -> 0.95912727 | AA17: =M17-J17 -> -73.570918 | AB17: =M17/J17 -> 0.95912727
A18: 新豐7線 | B18: 小吃 | C18: 古早味炒炊粉 | E18: 43.14 | F18: 1198 | G18: =E18*F18 -> 51681.72 | I18: 17 | J18: 2000 | K18: =J18/I18 -> 117.64706 | L18: 17 | M18: =F18/V18*60 -> 1942.7027 | N18: =M18/L18 -> 114.27663 | O18: =L18-I18 -> 0 | P18: =N18-K18 -> -3.3704293 | Q18: =N18/K18 -> 0.97135135 | R18: =Q26 -> 0.96108667 | S18: 0.20833333 | T18: 0.23402778 | V18: =(T18-S18)*24*60 -> 37 | AA18: =M18-J18 -> -57.297297 | AB18: =M18/J18 -> 0.97135135 | AC18: =AB26 -> 0.96108667
A19: 新豐7線 | B19: 熱食義麵 | C19: 麻婆豆腐波浪麵 | E19: 49.9 | F19: 2123 | G19: =E19*F19 -> 105937.7 | I19: 19 | J19: 2000 | K19: =J19/I19 -> 105.26316 | L19: 19 | M19: =F19/V19*60 -> 1901.194 | N19: =M19/L19 -> 100.06284 | O19: =L19-I19 -> 0 | P19: =N19-K19 -> -5.2003142 | Q19: =N19/K19 -> 0.95059701 | S19: 0.23819444 | T19: 0.28472222 | U19: =IF(S19=TIME(17,0,0),"",(S19-T18)*24*60) -> 6 | V19: =(T19-S19)*24*60 -> 67 | AA19: =M19-J19 -> -98.80597 | AB19: =M19/J19 -> 0.95059701
A20: 新豐7線 | B20: 微波主食 | C20: 鐵板滑蛋炸豬排丼 | E20: 57.73 | F20: 2865 | G20: =E20*F20 -> 165396.45 | I20: 14 | J20: 2000 | K20: =J20/I20 -> 142.85714 | L20: 14 | M20: =F20/V20*60 -> 1910 | N20: =M20/L20 -> 136.42857 | O20: =L20-I20 -> 0 | P20: =N20-K20 -> -6.4285714 | Q20: =N20/K20 -> 0.955 | S20: 0.28888889 | T20: 0.35138889 | U20: =IF(S20=TIME(17,0,0),"",(S20-T19)*24*60) -> 6 | V20: =(T20-S20)*24*60 -> 90 | AA20: =M20-J20 -> -90 | AB20: =M20/J20 -> 0.955
A21: 新豐7線 | B21: 微波主食 | C21: 極上炙烤親子丼 | E21: 53.68 | F21: 1777 | G21: =E21*F21 -> 95389.36 | I21: 16 | J21: 2000 | K21: =J21/I21 -> 125 | L21: 16 | M21: =F21/V21*60 -> 1938.5455 | N21: =M21/L21 -> 121.15909 | O21: =L21-I21 -> 0 | P21: =N21-K21 -> -3.8409091 | Q21: =N21/K21 -> 0.96927273 | S21: 0.35486111 | T21: 0.39305556 | U21: =IF(S21=TIME(17,0,0),"",(S21-T20)*24*60) -> 5 | V21: =(T21-S21)*24*60 -> 55 | AA21: =M21-J21 -> -61.454545 | AB21: =M21/J21 -> 0.96927273
A22: 新豐7線 | B22: 微波主食 | C22: 日式野菜烘蛋燴飯 | E22: 49.91 | F22: 1804 | G22: =E22*F22 -> 90037.64 | I22: 19 | J22: 2000 | K22: =J22/I22 -> 105.26316 | L22: 19 | M22: =F22/V22*60 -> 1932.8571 | N22: =M22/L22 -> 101.72932 | O22: =L22-I22 -> 0 | P22: =N22-K22 -> -3.5338346 | Q22: =N22/K22 -> 0.96642857 | S22: 0.39791667 | T22: 0.43680556 | U22: =IF(S22=TIME(17,0,0),"",(S22-T21)*24*60) -> 7 | V22: =(T22-S22)*24*60 -> 56 | AA22: =M22-J22 -> -67.142857 | AB22: =M22/J22 -> 0.96642857
A23: 新豐7線 | B23: 微波主食 | C23: 二配美味蟹煲 | E23: 54.09 | F23: 2044 | G23: =E23*F23 -> 110559.96 | I23: 19 | J23: 2000 | K23: =J23/I23 -> 105.26316 | L23: 19 | M23: =F23/V23*60 -> 1916.25 | N23: =M23/L23 -> 100.85526 | O23: =L23-I23 -> 0 | P23: =N23-K23 -> -4.4078947 | Q23: =N23/K23 -> 0.958125 | S23: 0.70833333 | T23: 0.75277778 | U23: =IF(S23=TIME(17,0,0),"",(S23-T22)*24*60) | V23: =(T23-S23)*24*60 -> 64 | AA23: =M23-J23 -> -83.75 | AB23: =M23/J23 -> 0.958125
A24: 新豐7線 | B24: 微波主食 | C24: 二配粗飽系雞排炒飯(114年) | E24: 57.73 | F24: 1716 | G24: =E24*F24 -> 99064.68 | I24: 16 | J24: 1500 | K24: =J24/I24 -> 93.75 | L24: 16 | M24: =F24/V24*60 -> 1430 | N24: =M24/L24 -> 89.375 | O24: =L24-I24 -> 0 | P24: =N24-K24 -> -4.375 | Q24: =N24/K24 -> 0.95333333 | S24: 0.75833333 | T24: 0.80833333 | U24: =IF(S24=TIME(17,0,0),"",(S24-T23)*24*60) -> 8 | V24: =(T24-S24)*24*60 -> 72 | AA24: =M24-J24 -> -70 | AB24: =M24/J24 -> 0.95333333
A25: 新豐7線 | B25: 微波主食 | C25: 二配泰式綠咖哩雞 | E25: 50.67 | F25: 2182 | G25: =E25*F25 -> 110561.94 | I25: 15 | J25: 2000 | K25: =J25/I25 -> 133.33333 | L25: 15 | M25: =F25/V25*60 -> 1925.2941 | N25: =M25/L25 -> 128.35294 | O25: =L25-I25 -> 0 | P25: =N25-K25 -> -4.9803922 | Q25: =N25/K25 -> 0.96264706 | S25: 0.81180556 | T25: 0.85902778 | U25: =IF(S25=TIME(17,0,0),"",(S25-T24)*24*60) -> 5 | V25: =(T25-S25)*24*60 -> 68 | AA25: =M25-J25 -> -74.705882 | AB25: =M25/J25 -> 0.96264706
A26: 新豐7線 | B26: 平均 | I26: 16.875 | J26: 1937.5 | K26: =J26/I26 -> 114.81481 | L26: 16.875 | M26: =AVERAGE(M18:M25) -> 1862.1054 | N26: =M26/L26 -> 110.34699 | O26: =L26-I26 -> 0 | P26: =N26-K26 -> -4.4678263 | Q26: =N26/K26 -> 0.96108667 | AA26: =M26-J26 -> -75.394569 | AB26: =M26/J26 -> 0.96108667
A27: 新豐8線 | B27: 三明治 | C27: 紐奧良風味烤雞鮮蔬三明治 | E27: 31.29 | F27: 4500 | G27: =E27*F27 -> 140805 | H27: 2 | I27: 18 | J27: 2400 | K27: =J27/I27 -> 133.33333 | L27: 18 | M27: =F27/V27*60 -> 2288.1356 | N27: =M27/L27 -> 127.11864 | O27: =L27-I27 -> 0 | P27: =N27-K27 -> -6.2146893 | Q27: =N27/K27 -> 0.95338983 | R27: =Q35 -> 0.95656129 | S27: 0.083333333 | T27: 0.16527778 | V27: =(T27-S27)*24*60 -> 118 | W27: =T27 -> 0.16527778 | X27: =S28 -> 0.18472222 | AA27: =M27-J27 -> -111.86441 | AB27: =M27/J27 -> 0.95338983 | AC27: =AB35 -> 0.95656129
A28: 新豐8線 | B28: 三明治 | C28: 經典總匯三明治 | E28: 26.2 | F28: 3500 | G28: =E28*F28 -> 91700 | H28: 2 | I28: 20 | J28: 2400 | K28: =J28/I28 -> 120 | L28: 20 | M28: =F28/V28*60 -> 2307.6923 | N28: =M28/L28 -> 115.38462 | O28: =L28-I28 -> 0 | P28: =N28-K28 -> -4.6153846 | Q28: =N28/K28 -> 0.96153846 | S28: 0.18472222 | T28: 0.24791667 | U28: =(S28-T27)*24*60 -> 28 | V28: =(T28-S28)*24*60 -> 91 | AA28: =M28-J28 -> -92.307692 | AB28: =M28/J28 -> 0.96153846
A29: 新豐8線 | B29: 三明治 | C29: 雞蛋沙拉三明治(114年) | E29: 25.99 | F29: 3300 | G29: =E29*F29 -> 85767 | H29: 2 | I29: 14 | J29: 2400 | K29: =J29/I29 -> 171.42857 | L29: 14 | M29: =F29/V29*60 -> 2302.3256 | N29: =M29/L29 -> 164.45183 | O29: =L29-I29 -> 0 | P29: =N29-K29 -> -6.9767442 | Q29: =N29/K29 -> 0.95930233 | S29: 0.25277778 | T29: 0.3125 | U29: =(S29-T28)*24*60 -> 7 | V29: =(T29-S29)*24*60 -> 86 | AA29: =M29-J29 -> -97.674419 | AB29: =M29/J29 -> 0.95930233
A30: 新豐8線 | B30: 三明治 | C30: 肉鬆火腿三明治 | E30: 20.52 | F30: 5399 | G30: =E30*F30 -> 110787.48 | I30: 18 | J30: 2400 | K30: =J30/I30 -> 133.33333 | L30: 18 | M30: =F30/V30*60 -> 2281.2676 | N30: =M30/L30 -> 126.73709 | O30: =L30-I30 -> 0 | P30: =N30-K30 -> -6.5962441 | Q30: =N30/K30 -> 0.95052817 | S30: 0.31597222 | T30: 0.41458333 | U30: =(S30-T29)*24*60 -> 5 | V30: =(T30-S30)*24*60 -> 142 | AA30: =M30-J30 -> -118.73239 | AB30: =M30/J30 -> 0.95052817
A31: 新豐8線 | B31: 三明治 | C31: 好多菜三明治(114年) | E31: 25.98 | F31: 5267 | G31: =E31*F31 -> 136836.66 | I31: 21 | J31: 2400 | K31: =J31/I31 -> 114.28571 | L31: 21 | M31: =F31/V31*60 -> 2290 | N31: =M31/L31 -> 109.04762 | O31: =L31-I31 -> 0 | P31: =N31-K31 -> -5.2380952 | Q31: =N31/K31 -> 0.95416667 | S31: 0.41944444 | T31: 0.51527778 | U31: =(S31-T30)*24*60 -> 7 | V31: =(T31-S31)*24*60 -> 138 | W31: =T31 -> 0.51527778 | X31: =S32 -> 0.55625 | AA31: =M31-J31 -> -110 | AB31: =M31/J31 -> 0.95416667
A32: 新豐8線 | B32: 三明治 | C32: 紐奧良風味烤雞鮮蔬三明治 | E32: 31.29 | F32: 6025 | G32: =E32*F32 -> 188522.25 | I32: 18 | J32: 2400 | K32: =J32/I32 -> 133.33333 | L32: 18 | M32: =F32/V32*60 -> 2287.9747 | N32: =M32/L32 -> 127.1097 | O32: =L32-I32 -> 0 | P32: =N32-K32 -> -6.2236287 | Q32: =N32/K32 -> 0.95332278 | S32: 0.55625 | T32: 0.66597222 | U32: =(S32-T31)*24*60 -> 59 | V32: =(T32-S32)*24*60 -> 158 | AA32: =M32-J32 -> -112.02532 | AB32: =M32/J32 -> 0.95332278
A33: 新豐8線 | B33: 三明治 | C33: 經典總匯三明治 | E33: 26.2 | F33: 2445 | G33: =E33*F33 -> 64059 | I33: 20 | J33: 2400 | K33: =J33/I33 -> 120 | L33: 20 | M33: =F33/V33*60 -> 2292.1875 | N33: =M33/L33 -> 114.60938 | O33: =L33-I33 -> 0 | P33: =N33-K33 -> -5.390625 | Q33: =N33/K33 -> 0.95507813 | S33: 0.67013889 | T33: 0.71458333 | U33: =(S33-T32)*24*60 -> 6 | V33: =(T33-S33)*24*60 -> 64 | AA33: =M33-J33 -> -107.8125 | AB33: =M33/J33 -> 0.95507813
A34: 新豐8線 | B34: 三明治 | C34: 雞蛋沙拉三明治(114年) | E34: 25.99 | F34: 2355 | G34: =E34*F34 -> 61206.45 | I34: 14 | J34: 2400 | K34: =J34/I34 -> 171.42857 | L34: 14 | M34: =F34/V34*60 -> 2316.3934 | N34: =M34/L34 -> 165.45667 | O34: =L34-I34 -> 0 | P34: =N34-K34 -> -5.971897 | Q34: =N34/K34 -> 0.96516393 | S34: 0.71944444 | T34: 0.76180556 | U34: =(S34-T33)*24*60 -> 7 | V34: =(T34-S34)*24*60 -> 61 | AA34: =M34-J34 -> -83.606557 | AB34: =M34/J34 -> 0.96516393
A35: 新豐8線 | B35: 平均 | I35: 17.875 | J35: 2400 | K35: =J35/I35 -> 134.26573 | L35: 17.875 | M35: =AVERAGE(M27:M34) -> 2295.7471 | N35: =M35/L35 -> 128.4334 | O35: =L35-I35 -> 0 | P35: =N35-K35 -> -5.8323307 | Q35: =N35/K35 -> 0.95656129 | AA35: =M35-J35 -> -104.25291 | AB35: =M35/J35 -> 0.95656129
A36: 新豐9線 | B36: 三明治 | C36: 火腿起司蛋三明治 | E36: 19.02 | F36: 4300 | G36: =E36*F36 -> 81786 | H36: 2 | I36: 15 | J36: 2400 | K36: =J36/I36 -> 160 | L36: 15 | M36: =F36/V36*60 -> 2283.1858 | N36: =M36/L36 -> 152.21239 | O36: =L36-I36 -> 0 | P36: =N36-K36 -> -7.7876106 | Q36: =N36/K36 -> 0.95132743 | R36: =Q43 -> 0.95417805 | S36: 0.083333333 | T36: 0.16180556 | V36: =(T36-S36)*24*60 -> 113 | W36: =T36 -> 0.16180556 | X36: =S37 -> 0.18194444 | AA36: =M36-J36 -> -116.81416 | AB36: =M36/J36 -> 0.95132743 | AC36: =AB43 -> 0.95417805
A37: 新豐9線 | B37: 三明治 | C37: 鮪魚起司溏心蛋三明治 | E37: 26.2 | F37: 4400 | G37: =E37*F37 -> 115280 | H37: 2 | I37: 18 | J37: 2400 | K37: =J37/I37 -> 133.33333 | L37: 18 | M37: =F37/V37*60 -> 2295.6522 | N37: =M37/L37 -> 127.53623 | O37: =L37-I37 -> 0 | P37: =N37-K37 -> -5.7971014 | Q37: =N37/K37 -> 0.95652174 | S37: 0.18194444 | T37: 0.26180556 | U37: =(S37-T36)*24*60 -> 29 | V37: =(T37-S37)*24*60 -> 115 | AA37: =M37-J37 -> -104.34783 | AB37: =M37/J37 -> 0.95652174
A38: 新豐9線 | B38: 三明治 | C38: 陽光地瓜總匯三明治 | E38: 26.18 | F38: 3141 | G38: =E38*F38 -> 82231.38 | I38: 19 | J38: 2400 | K38: =J38/I38 -> 126.31579 | L38: 19 | M38: =F38/V38*60 -> 2298.2927 | N38: =M38/L38 -> 120.96277 | O38: =L38-I38 -> 0 | P38: =N38-K38 -> -5.3530167 | Q38: =N38/K38 -> 0.95762195 | S38: 0.26527778 | T38: 0.32222222 | U38: =(S38-T37)*24*60 -> 5 | V38: =(T38-S38)*24*60 -> 82 | AA38: =M38-J38 -> -101.70732 | AB38: =M38/J38 -> 0.95762195
A39: 新豐9線 | B39: 三明治 | C39: 醬燒烤雞三明治 | E39: 26.39 | F39: 4500 | G39: =E39*F39 -> 118755 | H39: 2 | I39: 19 | J39: 2400 | K39: =J39/I39 -> 126.31579 | L39: 19 | M39: =F39/V39*60 -> 2288.1356 | N39: =M39/L39 -> 120.42819 | O39: =L39-I39 -> 0 | P39: =N39-K39 -> -5.8876004 | Q39: =N39/K39 -> 0.95338983 | S39: 0.32569444 | T39: 0.40763889 | U39: =(S39-T38)*24*60 -> 5 | V39: =(T39-S39)*24*60 -> 118 | AA39: =M39-J39 -> -111.86441 | AB39: =M39/J39 -> 0.95338983
A40: 新豐9線 | B40: 三明治 | C40: 切達海鮮雙饗三明治 | E40: 28.51 | F40: 5245 | G40: =E40*F40 -> 149534.95 | I40: 16 | J40: 2400 | K40: =J40/I40 -> 150 | L40: 16 | M40: =F40/V40*60 -> 2280.4348 | N40: =M40/L40 -> 142.52717 | O40: =L40-I40 -> 0 | P40: =N40-K40 -> -7.4728261 | Q40: =N40/K40 -> 0.95018116 | S40: 0.41180556 | T40: 0.50763889 | U40: =(S40-T39)*24*60 -> 6 | V40: =(T40-S40)*24*60 -> 138 | W40: =T40 -> 0.50763889 | X40: =S41 -> 0.54722222 | AA40: =M40-J40 -> -119.56522 | AB40: =M40/J40 -> 0.95018116
...

Sheet 1129
B1: 屏榮 新豐廠組合室生產人時性分析
B3: 日期 | C3: =TEXT('1129 4度C'!A2,"yyyy.mm.ddaaaa") -> 2025.11.29星期六 | E3: 訂單量 | F3: ='1129 4度C'!D1 -> 148451 | H3: 營業額 | I3: ='1129 4度C'!F1 -> 5011799.3
B4: 人時性 | C4: 項目 | E4: ➀ | G4: ➁ | I4: ➂
C5: 組合室 | E5: 全溫層 | G5: 4度C-各編組展開 | I5: ③三明治-各編組展開
C6: 排關平均 | E6: =AVERAGE(D13:M13) -> 153.17886 | F6: =AVERAGE(D27:O27,D13:J13) -> 158.951 | G6: =AVERAGE(D13:J13) -> 158.951 | I6: =AVERAGE(K13:M13) -> 139.71052
C7: 實績平均 | E7: =AVERAGE(D14:M14) -> 146.82199 | F7: =AVERAGE(D28:O28,D14:J14) -> 152.41674 | G7: =AVERAGE(D14:J14) -> 152.41674 | I7: =AVERAGE(K14:M14) -> 133.76756
C8: 達成率平均 | E8: =AVERAGE(D15:M15) -> 0.95866219 | F8: =AVERAGE(D15:J15,D29:O29) -> 0.95921772 | G8: =AVERAGE(D15:J15) -> 0.95921772 | I8: =AVERAGE(K15:M15) -> 0.95736596 | K8: ※現行日本鮮食廠以達成率80%為基本(即為現行KPI)
B10: 溫層 | D10: ➁4度C-各編組展開 | K10: ③三明治-各編組展開
B11: 編組 | D11: 1 | E11: 2 | F11: 3 | G11: 4 | H11: 5 | I11: 6 | J11: 7 | K11: 1 | L11: 2 | M11: 3
D12: 新豐6線 | E12: 新豐2線 | F12: 新豐5線 | G12: 新豐7線 | H12: 新豐3線 | I12: 新豐1線 | J12: 新豐10線 | K12: 新豐8線 | L12: 新豐9線 | M12: 新豐4線
B13: 人時性 | C13: 排關 | D13: =SUMIFS('1129 4度C'!$K:$K,'1129 4度C'!$A:$A,"新豐6線",'1129 4度C'!$B:$B,"平均") -> 133.33333 | E13: =SUMIFS('1129 4度C'!$K:$K,'1129 4度C'!$A:$A,"新豐2線",'1129 4度C'!$B:$B,"平均") -> 81.081081 | F13: =SUMIFS('1129 4度C'!$K:$K,'1129 4度C'!$A:$A,"新豐5線",'1129 4度C'!$B:$B,"平均") -> 97.826087 | G13: =SUMIFS('1129 4度C'!$K:$K,'1129 4度C'!$A:$A,"新豐7線",'1129 4度C'!$B:$B,"平均") -> 114.81481 | H13: =SUMIFS('1129 4度C'!$K:$K,'1129 4度C'!$A:$A,"新豐3線",'1129 4度C'!$B:$B,"平均") -> 281.69014 | I13: =SUMIFS('1129 4度C'!$K:$K,'1129 4度C'!$A:$A,"新豐1線",'1129 4度C'!$B:$B,"平均") -> 112.2449 | J13: =SUMIFS('1129 4度C'!$K:$K,'1129 4度C'!$A:$A,"新豐10線",'1129 4度C'!$B:$B,"平均") -> 291.66667 | K13: =SUMIFS('1129 4度C'!$K:$K,'1129 4度C'!$A:$A,"新豐8線",'1129 4度C'!$B:$B,"平均") -> 131.86813 | L13: =SUMIFS('1129 4度C'!$K:$K,'1129 4度C'!$A:$A,"新豐9線",'1129 4度C'!$B:$B,"平均") -> 141.17647 | M13: =SUMIFS('1129 4度C'!$K:$K,'1129 4度C'!$A:$A,"新豐4線",'1129 4度C'!$B:$B,"平均") -> 146.08696
C14: 實績 | D14: =SUMIFS('1129 4度C'!$N:$N,'1129 4度C'!$A:$A,"新豐6線",'1129 4度C'!$B:$B,"平均") -> 127.97414 | E14: =SUMIFS('1129 4度C'!$N:$N,'1129 4度C'!$A:$A,"新豐2線",'1129 4度C'!$B:$B,"平均") -> 77.87338 | F14: =SUMIFS('1129 4度C'!$N:$N,'1129 4度C'!$A:$A,"新豐5線",'1129 4度C'!$B:$B,"平均") -> 93.733428 | G14: =SUMIFS('1129 4度C'!$N:$N,'1129 4度C'!$A:$A,"新豐7線",'1129 4度C'!$B:$B,"平均") -> 110.56693 | H14: =SUMIFS('1129 4度C'!$N:$N,'1129 4度C'!$A:$A,"新豐3線",'1129 4度C'!$B:$B,"平均") -> 270.10424 | I14: =SUMIFS('1129 4度C'!$N:$N,'1129 4度C'!$A:$A,"新豐1線",'1129 4度C'!$B:$B,"平均") -> 107.38664 | J14: =SUMIFS('1129 4度C'!$N:$N,'1129 4度C'!$A:$A,"新豐10線",'1129 4度C'!$B:$B,"平均") -> 279.27843 | K14: =SUMIFS('1129 4度C'!$N:$N,'1129 4度C'!$A:$A,"新豐8線",'1129 4度C'!$B:$B,"平均") -> 125.89148 | L14: =SUMIFS('1129 4度C'!$N:$N,'1129 4度C'!$A:$A,"新豐9線",'1129 4度C'!$B:$B,"平均") -> 135.09506 | M14: =SUMIFS('1129 4度C'!$N:$N,'1129 4度C'!$A:$A,"新豐4線",'1129 4度C'!$B:$B,"平均") -> 140.31615
C15: 達成率 | D15: =D14/D13 -> 0.95980608 | E15: =E14/E13 -> 0.96043836 | F15: =F14/F13 -> 0.95816393 | G15: =G14/G13 -> 0.96300226 | H15: =H14/H13 -> 0.95887005 | I15: =I14/I13 -> 0.95671731 | J15: =J14/J13 -> 0.95752603 | K15: =K14/K13 -> 0.95467706 | ... M15: =M14/M13 -> 0.96049748
B16: 作業 時間 | C16: 開始 | D16: =VLOOKUP("新豐6線",'1129 4度C'!$A:$T,19,0) -> 0.70833333 | E16: =VLOOKUP("新豐2線",'1129 4度C'!$A:$T,19,0) -> 0.20833333 | F16: =VLOOKUP("新豐5線",'1129 4度C'!$A:$T,19,0) -> 0.125 | G16: =VLOOKUP("新豐7線",'1129 4度C'!$A:$T,19,0) -> 0.20833333 | H16: =VLOOKUP("新豐3線",'1129 4度C'!$A:$T,19,0) -> 0.083333333 | I16: =VLOOKUP("新豐1線",'1129 4度C'!$A:$T,19,0) -> 0.20833333 | J16: =VLOOKUP("新豐10線",'1129 4度C'!$A:$T,19,0) -> 0.20833333 | K16: =VLOOKUP("新豐8線",'1129 4度C'!$A:$T,19,0) -> 0.083333333 | L16: =VLOOKUP("新豐9線",'1129 4度C'!$A:$T,19,0) -> 0.083333333 | M16: =VLOOKUP("新豐4線",'1129 4度C'!$A:$T,19,0) -> 0.083333333
C17: 結束 | D17: =LOOKUP(2,1/(('1129 4度C'!$A:$A="新豐6線")*('1129 4度C'!$T:$T<>"")),'1129 4度C'!$T:$T) -> 0.85416667 | E17: =LOOKUP(2,1/(('1129 4度C'!$A:$A="新豐2線")*('1129 4度C'!$T:$T<>"")),'1129 4度C'!$T:$T) -> 0.40069444 | F17: =LOOKUP(2,1/(('1129 4度C'!$A:$A="新豐5線")*('1129 4度C'!$T:$T<>"")),'1129 4度C'!$T:$T) -> 0.84791667 | G17: =LOOKUP(2,1/(('1129 4度C'!$A:$A="新豐7線")*('1129 4度C'!$T:$T<>"")),'1129 4度C'!$T:$T) -> 0.83472222 | H17: =LOOKUP(2,1/(('1129 4度C'!$A:$A="新豐3線")*('1129 4度C'!$T:$T<>"")),'1129 4度C'!$T:$T) -> 0.45625 | I17: =LOOKUP(2,1/(('1129 4度C'!$A:$A="新豐1線")*('1129 4度C'!$T:$T<>"")),'1129 4度C'!$T:$T) -> 0.92638889 | J17: =LOOKUP(2,1/(('1129 4度C'!$A:$A="新豐10線")*('1129 4度C'!$T:$T<>"")),'1129 4度C'!$T:$T) -> 0.40486111 | K17: =LOOKUP(2,1/(('1129 4度C'!$A:$A="新豐8線")*('1129 4度C'!$T:$T<>"")),'1129 4度C'!$T:$T) -> 0.52847222 | L17: =LOOKUP(2,1/(('1129 4度C'!$A:$A="新豐9線")*('1129 4度C'!$T:$T<>"")),'1129 4度C'!$T:$T) -> 0.61388889 | M17: =LOOKUP(2,1/(('1129 4度C'!$A:$A="新豐4線")*('1129 4度C'!$T:$T<>"")),'1129 4度C'!$T:$T) -> 0.52222222
B18: 配置人數 | D18: =SUMIFS('1129 4度C'!$I:$I,'1129 4度C'!$A:$A,"新豐6線",'1129 4度C'!$B:$B,"平均") -> 15 | E18: =SUMIFS('1129 4度C'!$I:$I,'1129 4度C'!$A:$A,"新豐2線",'1129 4度C'!$B:$B,"平均") -> 18.5 | F18: =SUMIFS('1129 4度C'!$I:$I,'1129 4度C'!$A:$A,"新豐5線",'1129 4度C'!$B:$B,"平均") -> 18.4 | G18: =SUMIFS('1129 4度C'!$I:$I,'1129 4度C'!$A:$A,"新豐7線",'1129 4度C'!$B:$B,"平均") -> 16.875 | H18: =SUMIFS('1129 4度C'!$I:$I,'1129 4度C'!$A:$A,"新豐3線",'1129 4度C'!$B:$B,"平均") -> 10.142857 | I18: =SUMIFS('1129 4度C'!$I:$I,'1129 4度C'!$A:$A,"新豐1線",'1129 4度C'!$B:$B,"平均") -> 16.333333 | J18: =SUMIFS('1129 4度C'!$I:$I,'1129 4度C'!$A:$A,"新豐10線",'1129 4度C'!$B:$B,"平均") -> 9 | K18: =SUMIFS('1129 4度C'!$I:$I,'1129 4度C'!$A:$A,"新豐8線",'1129 4度C'!$B:$B,"平均") -> 18.2 | L18: =SUMIFS('1129 4度C'!$I:$I,'1129 4度C'!$A:$A,"新豐9線",'1129 4度C'!$B:$B,"平均") -> 17 | M18: =SUMIFS('1129 4度C'!$I:$I,'1129 4度C'!$A:$A,"新豐4線",'1129 4度C'!$B:$B,"平均") -> 16.428571
B19: 主要應用設備 | D19: ET-55 | E19: 熱縮爐 | F19: L型包裝機 | G19: L型包裝機 | H19: 伺服包裝機 | I19: ET-55 | J19: 伺服包裝機 | K19: 三明治包裝機 | L19: 三明治包裝機 | M19: 三明治包裝機
B20: 次要應用設備 | F20: 圓盤機 | G20: ET-55
B21: 備註 | E21: 握沙拉 | F21: 共用L型包裝機 | H21: 調理麵包 | I21: 炒飯+沙拉 | J21: 調理麵包

Sheet 1129 4度C
A1: 新豐廠四度C日報分析 | C1: 總生產量 | D1: =SUM(F5:F67) -> 148451 | E1: 營業額 | F1: =SUM(G5:G67) -> 5011799.3 | G1: 出勤人數 | H1: =L8+L11+L47+L54+L17+L59+L32+L39+L26+L67 -> 155.87976 | I1: 產線配置圖 | L1: 生產實績 | O1: 人時性差異分析 | S1: 日報登錄 | Y1: 分析說明 | AA1: 產能差異分析
A2: 45990 | B2: 星期六 | C2: 人時性 | D2: =AVERAGE(N8,N11,N47,N54,N17,N59,N26,N32,N39,N67) -> 146.82199 | E2: 平均廠價 | F2: =F1/D1 -> 33.76063 | G2: 多次生產數 | H2: =COUNT(H5:H67) -> 2
A3: 線別 | B3: 品類 | C3: 品名 | E3: 廠價 | F3: 生產量 | G3: 營收 | H3: 多次 生產 | I3: 人數 | J3: 產能/時 | K3: 人時性 | L3: 人數 | M3: 產能/時 | N3: 人時性 | O3: 人數 | P3: 人時性 | Q3: 達成率 | R3: 達成率平均 | S3: 生產時間 | U3: 換線、休息/分 | V3: 稼動時間/分 | W3: 休息時間 | Y3: (新豐回填) | AA3: 產能/時 | AB3: 達成率 | AC3: 達成率平均
S4: 開始 | T4: 結束 | W4: 開始 | X4: 結束
A5: 新豐6線 | B5: 微波主食 | C5: 二配港式香滑嫩蛋牛肉燴飯 | E5: 50.67 | F5: 1550 | G5: =E5*F5 -> 78538.5 | I5: 17 | J5: 2000 | K5: =J5/I5 -> 117.64706 | L5: 17 | M5: =F5/V5*60 -> 1937.5 | N5: =M5/L5 -> 113.97059 | O5: =L5-I5 -> 0 | P5: =N5-K5 -> -3.6764706 | Q5: =N5/K5 -> 0.96875 | R5: =Q8 -> 0.95980608 | S5: 0.70833333 | T5: 0.74166667 | V5: =(T5-S5)*24*60 -> 48 | AA5: =M5-J5 -> -62.5 | AB5: =M5/J5 -> 0.96875 | AC5: =AB8 -> 0.95980608
A6: 新豐6線 | B6: 微波主食 | C6: 二配川味麻婆燒豆腐燴飯 | E6: 50.49 | F6: 1821 | G6: =E6*F6 -> 91942.29 | I6: 15 | J6: 2000 | K6: =J6/I6 -> 133.33333 | L6: 15 | M6: =F6/V6*60 -> 1916.8421 | N6: =M6/L6 -> 127.78947 | O6: =L6-I6 -> 0 | P6: =N6-K6 -> -5.5438596 | Q6: =N6/K6 -> 0.95842105 | S6: 0.74722222 | T6: 0.78680556 | U6: =IF(S6=TIME(17,0,0),"",(S6-T5)*24*60) -> 8 | V6: =(T6-S6)*24*60 -> 57 | AA6: =M6-J6 -> -83.157895 | AB6: =M6/J6 -> 0.95842105
A7: 新豐6線 | B7: 微波主食 | C7: 二配厚香料咖哩雞排飯 | E7: 57.3 | F7: 2825 | G7: =E7*F7 -> 161872.5 | I7: 13 | J7: 2000 | K7: =J7/I7 -> 153.84615 | L7: 13 | M7: =F7/V7*60 -> 1904.4944 | N7: =M7/L7 -> 146.49957 | O7: =L7-I7 -> 0 | P7: =N7-K7 -> -7.346586 | Q7: =N7/K7 -> 0.95224719 | S7: 0.79236111 | T7: 0.85416667 | U7: =IF(S7=TIME(17,0,0),"",(S7-T6)*24*60) -> 8 | V7: =(T7-S7)*24*60 -> 89 | AA7: =M7-J7 -> -95.505618 | AB7: =M7/J7 -> 0.95224719
A8: 新豐6線 | B8: 平均 | I8: 15 | J8: 2000 | K8: =J8/I8 -> 133.33333 | L8: 15 | M8: =AVERAGE(M5:M7) -> 1919.6122 | N8: =M8/L8 -> 127.97414 | O8: =L8-I8 -> 0 | P8: =N8-K8 -> -5.3591892 | Q8: =N8/K8 -> 0.95980608 | AA8: =M8-J8 -> -80.387838 | AB8: =M8/J8 -> 0.95980608
A9: 新豐2線 | B9: 沙拉 | C9: 韓式泡菜豆腐握沙拉 | E9: 39.36 | F9: 1210 | G9: =E9*F9 -> 47625.6 | I9: 20 | J9: 1500 | K9: =J9/I9 -> 75 | L9: 20 | M9: =F9/V9*60 -> 1452 | N9: =M9/L9 -> 72.6 | O9: =L9-I9 -> 0 | P9: =N9-K9 -> -2.4 | Q9: =N9/K9 -> 0.968 | R9: =Q11 -> 0.96043836 | S9: 0.20833333 | T9: 0.24305556 | V9: =(T9-S9)*24*60 -> 50 | AA9: =M9-J9 -> -48 | AB9: =M9/J9 -> 0.968 | AC9: =AB11 -> 0.96043836
A10: 新豐2線 | B10: 沙拉 | C10: 青檸烤雞握沙拉(113年) | E10: 39.8 | F10: 5217 | G10: =E10*F10 -> 207636.6 | I10: 17 | J10: 1500 | K10: =J10/I10 -> 88.235294 | L10: 17 | M10: =F10/V10*60 -> 1429.3151 | N10: =M10/L10 -> 84.077357 | O10: =L10-I10 -> 0 | P10: =N10-K10 -> -4.1579371 | Q10: =N10/K10 -> 0.95287671 | S10: 0.24861111 | T10: 0.40069444 | U10: =IF(S10=TIME(17,0,0),"",(S10-T9)*24*60) -> 8 | V10: =(T10-S10)*24*60 -> 219 | AA10: =M10-J10 -> -70.684932 | AB10: =M10/J10 -> 0.95287671
A11: 新豐2線 | B11: 平均 | I11: 18.5 | J11: 1500 | K11: =J11/I11 -> 81.081081 | L11: 18.5 | M11: =AVERAGE(M9:M10) -> 1440.6575 | N11: =M11/L11 -> 77.87338 | O11: =L11-I11 -> 0 | P11: =N11-K11 -> -3.2077009 | Q11: =N11/K11 -> 0.96043836 | AA11: =M11-J11 -> -59.342466 | AB11: =M11/J11 -> 0.96043836
A12: 新豐5線 | B12: 小吃 | C12: 剝皮辣椒雞湯 | E12: 41 | F12: 2103 | G12: =E12*F12 -> 86223 | I12: 26 | J12: 1500 | K12: =J12/I12 -> 57.692308 | L12: 26 | M12: =F12/V12*60 -> 1433.8636 | N12: =M12/L12 -> 55.148601 | O12: =L12-I12 -> 0 | P12: =N12-K12 -> -2.5437063 | Q12: =N12/K12 -> 0.95590909 | R12: =Q17 -> 0.95816393 | S12: 0.125 | T12: 0.18611111 | V12: =(T12-S12)*24*60 -> 88 | W12: =T12 -> 0.18611111 | X12: =S13 -> 0.20486111 | AA12: =M12-J12 -> -66.136364 | AB12: =M12/J12 -> 0.95590909 | AC12: =AB17 -> 0.95816393
A13: 新豐5線 | B13: 沙拉 | C13: 青醬優格雞肉握沙拉(113年) | E13: 39.62 | F13: 3361 | G13: =E13*F13 -> 133162.82 | I13: 19 | J13: 1500 | K13: =J13/I13 -> 78.947368 | L13: 19 | M13: =F13/V13*60 -> 1430.2128 | N13: =M13/L13 -> 75.274356 | O13: =L13-I13 -> 0 | P13: =N13-K13 -> -3.6730123 | Q13: =N13/K13 -> 0.95347518 | S13: 0.20486111 | T13: 0.30277778 | U13: =IF(S13=TIME(17,0,0),"",(S13-T12)*24*60) -> 27 | V13: =(T13-S13)*24*60 -> 141 | AA13: =M13-J13 -> -69.787234 | AB13: =M13/J13 -> 0.95347518
A14: 新豐5線 | B14: 微波主食 | C14: 二配金咖哩濃厚辛口咖哩飯 | E14: 50.98 | F14: 2594 | G14: =E14*F14 -> 132242.12 | I14: 16 | J14: 2000 | K14: =J14/I14 -> 125 | L14: 16 | M14: =F14/V14*60 -> 1921.4815 | N14: =M14/L14 -> 120.09259 | O14: =L14-I14 -> 0 | P14: =N14-K14 -> -4.9074074 | Q14: =N14/K14 -> 0.96074074 | S14: 0.70833333 | T14: 0.76458333 | U14: =IF(S14=TIME(17,0,0),"",(S14-T13)*24*60) | V14: =(T14-S14)*24*60 -> 81 | AA14: =M14-J14 -> -78.518519 | AB14: =M14/J14 -> 0.96074074
A15: 新豐5線 | B15: 微波主食 | C15: 二配金咖哩果香甘口咖哩飯 | E15: 50.92 | F15: 2618 | G15: =E15*F15 -> 133308.56 | I15: 15 | J15: 2000 | K15: =J15/I15 -> 133.33333 | L15: 15 | M15: =F15/V15*60 -> 1915.6098 | N15: =M15/L15 -> 127.70732 | O15: =L15-I15 -> 0 | P15: =N15-K15 -> -5.6260163 | Q15: =N15/K15 -> 0.95780488 | S15: 0.76944444 | T15: 0.82638889 | U15: =IF(S15=TIME(17,0,0),"",(S15-T14)*24*60) -> 7 | V15: =(T15-S15)*24*60 -> 82 | AA15: =M15-J15 -> -84.390244 | AB15: =M15/J15 -> 0.95780488
A16: 新豐5線 | B16: 微波主食 | C16: 二配煸椒烘蛋飯 | E16: 46.93 | F16: 833 | G16: =E16*F16 -> 39092.69 | I16: 16 | J16: 2000 | K16: =J16/I16 -> 125 | L16: 16 | M16: =F16/V16*60 -> 1922.3077 | N16: =M16/L16 -> 120.14423 | O16: =L16-I16 -> 0 | P16: =N16-K16 -> -4.8557692 | Q16: =N16/K16 -> 0.96115385 | S16: 0.82986111 | T16: 0.84791667 | U16: =IF(S16=TIME(17,0,0),"",(S16-T15)*24*60) -> 5 | V16: =(T16-S16)*24*60 -> 26 | AA16: =M16-J16 -> -77.692308 | AB16: =M16/J16 -> 0.96115385
A17: 新豐5線 | B17: 平均 | I17: 18.4 | J17: 1800 | K17: =J17/I17 -> 97.826087 | L17: 18.4 | M17: =AVERAGE(M12:M16) -> 1724.6951 | N17: =M17/L17 -> 93.733428 | O17: =L17-I17 -> 0 | P17: =N17-K17 -> -4.0926594 | Q17: =N17/K17 -> 0.95816393 | AA17: =M17-J17 -> -75.304934 | AB17: =M17/J17 -> 0.95816393
A18: 新豐7線 | B18: 小吃 | C18: 古早味炒炊粉 | E18: 43.14 | F18: 948 | G18: =E18*F18 -> 40896.72 | I18: 17 | J18: 2000 | K18: =J18/I18 -> 117.64706 | L18: 17 | M18: =F18/V18*60 -> 1961.3793 | N18: =M18/L18 -> 115.37525 | O18: =L18-I18 -> 0 | P18: =N18-K18 -> -2.2718053 | Q18: =N18/K18 -> 0.98068966 | R18: =Q26 -> 0.96300226 | S18: 0.20833333 | T18: 0.22847222 | V18: =(T18-S18)*24*60 -> 29 | AA18: =M18-J18 -> -38.62069 | AB18: =M18/J18 -> 0.98068966 | AC18: =AB26 -> 0.96300226
A19: 新豐7線 | B19: 熱食義麵 | C19: 麻婆豆腐波浪麵 | E19: 49.9 | F19: 1507 | G19: =E19*F19 -> 75199.3 | I19: 19 | J19: 2000 | K19: =J19/I19 -> 105.26316 | L19: 19 | M19: =F19/V19*60 -> 1923.8298 | N19: =M19/L19 -> 101.2542 | O19: =L19-I19 -> 0 | P19: =N19-K19 -> -4.0089586 | Q19: =N19/K19 -> 0.96191489 | S19: 0.23194444 | T19: 0.26458333 | U19: =IF(S19=TIME(17,0,0),"",(S19-T18)*24*60) -> 5 | V19: =(T19-S19)*24*60 -> 47 | AA19: =M19-J19 -> -76.170213 | AB19: =M19/J19 -> 0.96191489
A20: 新豐7線 | B20: 微波主食 | C20: 鐵板滑蛋炸豬排丼 | E20: 57.73 | F20: 2068 | G20: =E20*F20 -> 119385.64 | I20: 14 | J20: 2000 | K20: =J20/I20 -> 142.85714 | L20: 14 | M20: =F20/V20*60 -> 1908.9231 | N20: =M20/L20 -> 136.35165 | O20: =L20-I20 -> 0 | P20: =N20-K20 -> -6.5054945 | Q20: =N20/K20 -> 0.95446154 | S20: 0.26805556 | T20: 0.31319444 | U20: =IF(S20=TIME(17,0,0),"",(S20-T19)*24*60) -> 5 | V20: =(T20-S20)*24*60 -> 65 | AA20: =M20-J20 -> -91.076923 | AB20: =M20/J20 -> 0.95446154
A21: 新豐7線 | B21: 微波主食 | C21: 極上炙烤親子丼 | E21: 53.68 | F21: 1380 | G21: =E21*F21 -> 74078.4 | I21: 16 | J21: 2000 | K21: =J21/I21 -> 125 | L21: 16 | M21: =F21/V21*60 -> 1925.5814 | N21: =M21/L21 -> 120.34884 | O21: =L21-I21 -> 0 | P21: =N21-K21 -> -4.6511628 | Q21: =N21/K21 -> 0.9627907 | S21: 0.31875 | T21: 0.34861111 | U21: =IF(S21=TIME(17,0,0),"",(S21-T20)*24*60) -> 8 | V21: =(T21-S21)*24*60 -> 43 | AA21: =M21-J21 -> -74.418605 | AB21: =M21/J21 -> 0.9627907
A22: 新豐7線 | B22: 微波主食 | C22: 日式野菜烘蛋燴飯 | E22: 49.91 | F22: 1377 | G22: =E22*F22 -> 68726.07 | I22: 19 | J22: 2000 | K22: =J22/I22 -> 105.26316 | L22: 19 | M22: =F22/V22*60 -> 1921.3953 | N22: =M22/L22 -> 101.12607 | O22: =L22-I22 -> 0 | P22: =N22-K22 -> -4.1370869 | Q22: =N22/K22 -> 0.96069767 | S22: 0.35416667 | T22: 0.38402778 | U22: =IF(S22=TIME(17,0,0),"",(S22-T21)*24*60) -> 8 | V22: =(T22-S22)*24*60 -> 43 | AA22: =M22-J22 -> -78.604651 | AB22: =M22/J22 -> 0.96069767
A23: 新豐7線 | B23: 微波主食 | C23: 二配美味蟹煲 | E23: 54.09 | F23: 1833 | G23: =E23*F23 -> 99146.97 | I23: 19 | J23: 2000 | K23: =J23/I23 -> 105.26316 | L23: 19 | M23: =F23/V23*60 -> 1929.4737 | N23: =M23/L23 -> 101.55125 | O23: =L23-I23 -> 0 | P23: =N23-K23 -> -3.7119114 | Q23: =N23/K23 -> 0.96473684 | S23: 0.70833333 | T23: 0.74791667 | U23: =IF(S23=TIME(17,0,0),"",(S23-T22)*24*60) | V23: =(T23-S23)*24*60 -> 57 | AA23: =M23-J23 -> -70.526316 | AB23: =M23/J23 -> 0.96473684
A24: 新豐7線 | B24: 微波主食 | C24: 二配粗飽系雞排炒飯(114年) | E24: 57.73 | F24: 1334 | G24: =E24*F24 -> 77011.82 | I24: 16 | J24: 1500 | K24: =J24/I24 -> 93.75 | L24: 16 | M24: =F24/V24*60 -> 1429.2857 | N24: =M24/L24 -> 89.330357 | O24: =L24-I24 -> 0 | P24: =N24-K24 -> -4.4196429 | Q24: =N24/K24 -> 0.95285714 | S24: 0.75347222 | T24: 0.79236111 | U24: =IF(S24=TIME(17,0,0),"",(S24-T23)*24*60) -> 8 | V24: =(T24-S24)*24*60 -> 56 | AA24: =M24-J24 -> -70.714286 | AB24: =M24/J24 -> 0.95285714
A25: 新豐7線 | B25: 微波主食 | C25: 二配泰式綠咖哩雞 | E25: 50.67 | F25: 1734 | G25: =E25*F25 -> 87861.78 | I25: 15 | J25: 2000 | K25: =J25/I25 -> 133.33333 | L25: 15 | M25: =F25/V25*60 -> 1926.6667 | N25: =M25/L25 -> 128.44444 | O25: =L25-I25 -> 0 | P25: =N25-K25 -> -4.8888889 | Q25: =N25/K25 -> 0.96333333 | S25: 0.79722222 | T25: 0.83472222 | U25: =IF(S25=TIME(17,0,0),"",(S25-T24)*24*60) -> 7 | V25: =(T25-S25)*24*60 -> 54 | AA25: =M25-J25 -> -73.333333 | AB25: =M25/J25 -> 0.96333333
A26: 新豐7線 | B26: 平均 | I26: 16.875 | J26: 1937.5 | K26: =J26/I26 -> 114.81481 | L26: 16.875 | M26: =AVERAGE(M18:M25) -> 1865.8169 | N26: =M26/L26 -> 110.56693 | O26: =L26-I26 -> 0 | P26: =N26-K26 -> -4.247889 | Q26: =N26/K26 -> 0.96300226 | AA26: =M26-J26 -> -71.683127 | AB26: =M26/J26 -> 0.96300226
A27: 新豐8線 | B27: 三明治 | C27: 紐奧良風味烤雞鮮蔬三明治 | E27: 31.29 | F27: 7080 | G27: =E27*F27 -> 221533.2 | I27: 18 | J27: 2400 | K27: =J27/I27 -> 133.33333 | L27: 18 | M27: =F27/V27*60 -> 2296.2162 | N27: =M27/L27 -> 127.56757 | O27: =L27-I27 -> 0 | P27: =N27-K27 -> -5.7657658 | Q27: =N27/K27 -> 0.95675676 | R27: =Q32 -> 0.95467706 | S27: 0.083333333 | T27: 0.21180556 | V27: =(T27-S27)*24*60 -> 185 | W27: =T27 -> 0.21180556 | X27: =S28 -> 0.22986111 | AA27: =M27-J27 -> -103.78378 | AB27: =M27/J27 -> 0.95675676 | AC27: =AB32 -> 0.95467706
A28: 新豐8線 | B28: 三明治 | C28: 經典總匯三明治 | E28: 26.2 | F28: 4151 | G28: =E28*F28 -> 108756.2 | I28: 20 | J28: 2400 | K28: =J28/I28 -> 120 | L28: 20 | M28: =F28/V28*60 -> 2284.9541 | N28: =M28/L28 -> 114.24771 | O28: =L28-I28 -> 0 | P28: =N28-K28 -> -5.7522936 | Q28: =N28/K28 -> 0.95206422 | S28: 0.22986111 | T28: 0.30555556 | U28: =(S28-T27)*24*60 -> 26 | V28: =(T28-S28)*24*60 -> 109 | AA28: =M28-J28 -> -115.04587 | AB28: =M28/J28 -> 0.95206422
A29: 新豐8線 | B29: 三明治 | C29: 雞蛋沙拉三明治(114年) | E29: 25.99 | F29: 4020 | G29: =E29*F29 -> 104479.8 | I29: 14 | J29: 2400 | K29: =J29/I29 -> 171.42857 | L29: 14 | M29: =F29/V29*60 -> 2297.1429 | N29: =M29/L29 -> 164.08163 | O29: =L29-I29 -> 0 | P29: =N29-K29 -> -7.3469388 | Q29: =N29/K29 -> 0.95714286 | S29: 0.30902778 | T29: 0.38194444 | U29: =(S29-T28)*24*60 -> 5 | V29: =(T29-S29)*24*60 -> 105 | AA29: =M29-J29 -> -102.85714 | AB29: =M29/J29 -> 0.95714286
A30: 新豐8線 | B30: 三明治 | C30: 肉鬆火腿三明治 | E30: 20.52 | F30: 3582 | G30: =E30*F30 -> 73502.64 | I30: 18 | J30: 2400 | K30: =J30/I30 -> 133.33333 | L30: 18 | M30: =F30/V30*60 -> 2286.383 | N30: =M30/L30 -> 127.02128 | O30: =L30-I30 -> 0 | P30: =N30-K30 -> -6.3120567 | Q30: =N30/K30 -> 0.95265957 | S30: 0.38541667 | T30: 0.45069444 | U30: =(S30-T29)*24*60 -> 5 | V30: =(T30-S30)*24*60 -> 94 | AA30: =M30-J30 -> -113.61702 | AB30: =M30/J30 -> 0.95265957
A31: 新豐8線 | B31: 三明治 | C31: 好多菜三明治(114年) | E31: 25.98 | F31: 4010 | G31: =E31*F31 -> 104179.8 | I31: 21 | J31: 2400 | K31: =J31/I31 -> 114.28571 | L31: 21 | M31: =F31/V31*60 -> 2291.4286 | N31: =M31/L31 -> 109.11565 | O31: =L31-I31 -> 0 | P31: =N31-K31 -> -5.170068 | Q31: =N31/K31 -> 0.9547619 | S31: 0.45555556 | T31: 0.52847222 | U31: =(S31-T30)*24*60 -> 7 | V31: =(T31-S31)*24*60 -> 105 | AA31: =M31-J31 -> -108.57143 | AB31: =M31/J31 -> 0.9547619
A32: 新豐8線 | B32: 平均 | I32: 18.2 | J32: 2400 | K32: =J32/I32 -> 131.86813 | L32: 18.2 | M32: =AVERAGE(M27:M31) -> 2291.225 | N32: =M32/L32 -> 125.89148 | O32: =L32-I32 -> 0 | P32: =N32-K32 -> -5.9766511 | Q32: =N32/K32 -> 0.95467706 | AA32: =M32-J32 -> -108.77505 | AB32: =M32/J32 -> 0.95467706
A33: 新豐9線 | B33: 三明治 | C33: 火腿起司蛋三明治 | E33: 19.02 | F33: 3500 | G33: =E33*F33 -> 66570 | H33: 2 | I33: 15 | J33: 2400 | K33: =J33/I33 -> 160 | L33: 15 | M33: =F33/V33*60 -> 2307.6923 | N33: =M33/L33 -> 153.84615 | O33: =L33-I33 -> 0 | P33: =N33-K33 -> -6.1538462 | Q33: =N33/K33 -> 0.96153846 | R33: =Q39 -> 0.95692332 | S33: 0.083333333 | T33: 0.14652778 | V33: =(T33-S33)*24*60 -> 91 | W33: =T33 -> 0.14652778 | X33: =S34 -> 0.16666667 | AA33: =M33-J33 -> -92.307692 | AB33: =M33/J33 -> 0.96153846 | AC33: =AB39 -> 0.95692332
A34: 新豐9線 | B34: 三明治 | C34: 鮪魚起司溏心蛋三明治 | E34: 26.2 | F34: 5259 | G34: =E34*F34 -> 137785.8 | I34: 18 | J34: 2400 | K34: =J34/I34 -> 133.33333 | L34: 18 | M34: =F34/V34*60 -> 2286.5217 | N34: =M34/L34 -> 127.02899 | O34: =L34-I34 -> 0 | P34: =N34-K34 -> -6.3043478 | Q34: =N34/K34 -> 0.95271739 | S34: 0.16666667 | T34: 0.2625 | U34: =(S34-T33)*24*60 -> 29 | V34: =(T34-S34)*24*60 -> 138 | AA34: =M34-J34 -> -113.47826 | AB34: =M34/J34 -> 0.95271739
A35: 新豐9線 | B35: 三明治 | C35: 陽光地瓜總匯三明治 | E35: 26.18 | F35: 2229 | G35: =E35*F35 -> 58355.22 | I35: 19 | J35: 2400 | K35: =J35/I35 -> 126.31579 | L35: 19 | M35: =F35/V35*60 -> 2305.8621 | N35: =M35/L35 -> 121.36116 | O35: =L35-I35 -> 0 | P35: =N35-K35 -> -4.9546279 | Q35: =N35/K35 -> 0.96077586 | S35: 0.26805556 | T35: 0.30833333 | U35: =(S35-T34)*24*60 -> 8 | V35: =(T35-S35)*24*60 -> 58 | AA35: =M35-J35 -> -94.137931 | AB35: =M35/J35 -> 0.96077586
A36: 新豐9線 | B36: 三明治 | C36: 醬燒烤雞三明治 | E36: 26.39 | F36: 5148 | G36: =E36*F36 -> 135855.72 | I36: 19 | J36: 2400 | K36: =J36/I36 -> 126.31579 | L36: 19 | M36: =F36/V36*60 -> 2288 | N36: =M36/L36 -> 120.42105 | O36: =L36-I36 -> 0 | P36: =N36-K36 -> -5.8947368 | Q36: =N36/K36 -> 0.95333333 | S36: 0.31180556 | T36: 0.40555556 | U36: =(S36-T35)*24*60 -> 5 | V36: =(T36-S36)*24*60 -> 135 | AA36: =M36-J36 -> -112 | AB36: =M36/J36 -> 0.95333333
A37: 新豐9線 | B37: 三明治 | C37: 切達海鮮雙饗三明治 | E37: 28.51 | F37: 4957 | G37: =E37*F37 -> 141324.07 | I37: 16 | J37: 2400 | K37: =J37/I37 -> 150 | L37: 16 | M37: =F37/V37*60 -> 2287.8462 | N37: =M37/L37 -> 142.99038 | O37: =L37-I37 -> 0 | P37: =N37-K37 -> -7.0096154 | Q37: =N37/K37 -> 0.95326923 | S37: 0.40902778 | T37: 0.49930556 | U37: =(S37-T36)*24*60 -> 5 | V37: =(T37-S37)*24*60 -> 130 | W37: =T37 -> 0.49930556 | X37: =S38 -> 0.54027778 | AA37: =M37-J37 -> -112.15385 | AB37: =M37/J37 -> 0.95326923
A38: 新豐9線 | B38: 三明治 | C38: 火腿起司蛋三明治 | E38: 19.02 | F38: 4070 | G38: =E38*F38 -> 77411.4 | I38: 15 | J38: 2400 | K38: =J38/I38 -> 160 | L38: 15 | M38: =F38/V38*60 -> 2303.7736 | N38: =M38/L38 -> 153.58491 | O38: =L38-I38 -> 0 | P38: =N38-K38 -> -6.4150943 | Q38: =N38/K38 -> 0.95990566 | S38: 0.54027778 | T38: 0.61388889 | U38: =(S38-T37)*24*60 -> 59 | V38: =(T38-S38)*24*60 -> 106 | AA38: =M38-J38 -> -96.226415 | AB38: =M38/J38 -> 0.95990566
A39: 新豐9線 | B39: 平均 | I39: 17 | J39: 2400 | K39: =J39/I39 -> 141.17647 | L39: 17 | M39: =AVERAGE(M33:M38) -> 2296.616 | N39: =M39/L39 -> 135.09506 | O39: =L39-I39 -> 0 | P39: =N39-K39 -> -6.0814132 | Q39: =N39/K39 -> 0.95692332 | AA39: =M39-J39 -> -103.38402 | AB39: =M39/J39 -> 0.95692332
A40: 新豐3線 | B40: 調理麵包 | C40: 豬肉起司堡 | E40: 21.13 | F40: 4250 | G40: =E40*F40 -> 89802.5 | I40: 10 | J40: 3000 | K40: =J40/I40 -> 300 | L40: 10 | M40: =F40/V40*60 -> 2865.1685 | N40: =M40/L40 -> 286.51685 | O40: =L40-I40 -> 0 | P40: =N40-K40 -> -13.483146 | Q40: =N40/K40 -> 0.95505618 | R40: =Q47 -> 0.95887005 | S40: 0.083333333 | T40: 0.14513889 | V40: =(T40-S40)*24*60 -> 89 | W40: =T40 -> 0.14513889 | X40: =S41 -> 0.16458333 | AA40: =M40-J40 -> -134.83146 | AB40: =M40/J40 -> 0.95505618 | AC40: =AB47 -> 0.95887005
...

Sheet 1128
B1: 屏榮 新豐廠組合室生產人時性分析
B3: 日期 | C3: =TEXT('1128 4度C'!A2,"yyyy.mm.ddaaaa") -> 2025.11.28星期五 | E3: 訂單量 | F3: ='1128 4度C'!D1 -> 134709 | H3: 營業額 | I3: ='1128 4度C'!F1 -> 4532055.3
B4: 人時性 | C4: 項目 | E4: ➀ | G4: ➁ | I4: ➂
C5: 組合室 | E5: 全溫層 | G5: 4度C-各編組展開 | I5: ③三明治-各編組展開
C6: 排關平均 | E6: =AVERAGE(D13:M13) -> 152.85431 | F6: =AVERAGE(D27:O27,D13:J13) -> 158.951 | G6: =AVERAGE(D13:J13) -> 158.951 | I6: =AVERAGE(K13:M13) -> 138.62871
C7: 實績平均 | E7: =AVERAGE(D14:M14) -> 146.62226 | F7: =AVERAGE(D28:O28,D14:J14) -> 152.60814 | G7: =AVERAGE(D14:J14) -> 152.60814 | I7: =AVERAGE(K14:M14) -> 132.65521
C8: 達成率平均 | E8: =AVERAGE(D15:M15) -> 0.95927867 | F8: =AVERAGE(D15:J15,D29:O29) -> 0.96031998 | G8: =AVERAGE(D15:J15) -> 0.96031998 | I8: =AVERAGE(K15:M15) -> 0.95684893 | K8: ※現行日本鮮食廠以達成率80%為基本(即為現行KPI)
B10: 溫層 | D10: ➁4度C-各編組展開 | K10: ③三明治-各編組展開
B11: 編組 | D11: 1 | E11: 2 | F11: 3 | G11: 4 | H11: 5 | I11: 6 | J11: 7 | K11: 1 | L11: 2 | M11: 3
D12: 新豐6線 | E12: 新豐2線 | F12: 新豐5線 | G12: 新豐7線 | H12: 新豐3線 | I12: 新豐1線 | J12: 新豐10線 | K12: 新豐8線 | L12: 新豐9線 | M12: 新豐4線
B13: 人時性 | C13: 排關 | D13: =SUMIFS('1128 4度C'!$K:$K,'1128 4度C'!$A:$A,"新豐6線",'1128 4度C'!$B:$B,"平均") -> 133.33333 | E13: =SUMIFS('1128 4度C'!$K:$K,'1128 4度C'!$A:$A,"新豐2線",'1128 4度C'!$B:$B,"平均") -> 81.081081 | F13: =SUMIFS('1128 4度C'!$K:$K,'1128 4度C'!$A:$A,"新豐5線",'1128 4度C'!$B:$B,"平均") -> 97.826087 | G13: =SUMIFS('1128 4度C'!$K:$K,'1128 4度C'!$A:$A,"新豐7線",'1128 4度C'!$B:$B,"平均") -> 114.81481 | H13: =SUMIFS('1128 4度C'!$K:$K,'1128 4度C'!$A:$A,"新豐3線",'1128 4度C'!$B:$B,"平均") -> 281.69014 | I13: =SUMIFS('1128 4度C'!$K:$K,'1128 4度C'!$A:$A,"新豐1線",'1128 4度C'!$B:$B,"平均") -> 112.2449 | J13: =SUMIFS('1128 4度C'!$K:$K,'1128 4度C'!$A:$A,"新豐10線",'1128 4度C'!$B:$B,"平均") -> 291.66667 | K13: =SUMIFS('1128 4度C'!$K:$K,'1128 4度C'!$A:$A,"新豐8線",'1128 4度C'!$B:$B,"平均") -> 131.86813 | L13: =SUMIFS('1128 4度C'!$K:$K,'1128 4度C'!$A:$A,"新豐9線",'1128 4度C'!$B:$B,"平均") -> 137.93103 | M13: =SUMIFS('1128 4度C'!$K:$K,'1128 4度C'!$A:$A,"新豐4線",'1128 4度C'!$B:$B,"平均") -> 146.08696
C14: 實績 | D14: =SUMIFS('1128 4度C'!$N:$N,'1128 4度C'!$A:$A,"新豐6線",'1128 4度C'!$B:$B,"平均") -> 128.19353 | E14: =SUMIFS('1128 4度C'!$N:$N,'1128 4度C'!$A:$A,"新豐2線",'1128 4度C'!$B:$B,"平均") -> 77.961923 | F14: =SUMIFS('1128 4度C'!$N:$N,'1128 4度C'!$A:$A,"新豐5線",'1128 4度C'!$B:$B,"平均") -> 93.643034 | G14: =SUMIFS('1128 4度C'!$N:$N,'1128 4度C'!$A:$A,"新豐7線",'1128 4度C'!$B:$B,"平均") -> 110.1065 | H14: =SUMIFS('1128 4度C'!$N:$N,'1128 4度C'!$A:$A,"新豐3線",'1128 4度C'!$B:$B,"平均") -> 270.36501 | I14: =SUMIFS('1128 4度C'!$N:$N,'1128 4度C'!$A:$A,"新豐1線",'1128 4度C'!$B:$B,"平均") -> 108.19944 | J14: =SUMIFS('1128 4度C'!$N:$N,'1128 4度C'!$A:$A,"新豐10線",'1128 4度C'!$B:$B,"平均") -> 279.78755 | K14: =SUMIFS('1128 4度C'!$N:$N,'1128 4度C'!$A:$A,"新豐8線",'1128 4度C'!$B:$B,"平均") -> 125.96726 | L14: =SUMIFS('1128 4度C'!$N:$N,'1128 4度C'!$A:$A,"新豐9線",'1128 4度C'!$B:$B,"平均") -> 131.93294 | M14: =SUMIFS('1128 4度C'!$N:$N,'1128 4度C'!$A:$A,"新豐4線",'1128 4度C'!$B:$B,"平均") -> 140.06543
C15: 達成率 | D15: =D14/D13 -> 0.96145145 | E15: =E14/E13 -> 0.96153038 | F15: =F14/F13 -> 0.9572399 | G15: =G14/G13 -> 0.95899212 | H15: =H14/H13 -> 0.95979577 | I15: =I14/I13 -> 0.96395864 | J15: =J14/J13 -> 0.95927162 | K15: =K14/K13 -> 0.95525175 | ... M15: =M14/M13 -> 0.95878123
B16: 作業 時間 | C16: 開始 | D16: =VLOOKUP("新豐6線",'1128 4度C'!$A:$T,19,0) -> 0.70833333 | E16: =VLOOKUP("新豐2線",'1128 4度C'!$A:$T,19,0) -> 0.20833333 | F16: =VLOOKUP("新豐5線",'1128 4度C'!$A:$T,19,0) -> 0.125 | G16: =VLOOKUP("新豐7線",'1128 4度C'!$A:$T,19,0) -> 0.20833333 | H16: =VLOOKUP("新豐3線",'1128 4度C'!$A:$T,19,0) -> 0.083333333 | I16: =VLOOKUP("新豐1線",'1128 4度C'!$A:$T,19,0) -> 0.20833333 | J16: =VLOOKUP("新豐10線",'1128 4度C'!$A:$T,19,0) -> 0.20833333 | K16: =VLOOKUP("新豐8線",'1128 4度C'!$A:$T,19,0) -> 0.083333333 | L16: =VLOOKUP("新豐9線",'1128 4度C'!$A:$T,19,0) -> 0.083333333 | M16: =VLOOKUP("新豐4線",'1128 4度C'!$A:$T,19,0) -> 0.083333333
C17: 結束 | D17: =LOOKUP(2,1/(('1128 4度C'!$A:$A="新豐6線")*('1128 4度C'!$T:$T<>"")),'1128 4度C'!$T:$T) -> 0.83680556 | E17: =LOOKUP(2,1/(('1128 4度C'!$A:$A="新豐2線")*('1128 4度C'!$T:$T<>"")),'1128 4度C'!$T:$T) -> 0.38263889 | F17: =LOOKUP(2,1/(('1128 4度C'!$A:$A="新豐5線")*('1128 4度C'!$T:$T<>"")),'1128 4度C'!$T:$T) -> 0.82638889 | G17: =LOOKUP(2,1/(('1128 4度C'!$A:$A="新豐7線")*('1128 4度C'!$T:$T<>"")),'1128 4度C'!$T:$T) -> 0.82569444 | H17: =LOOKUP(2,1/(('1128 4度C'!$A:$A="新豐3線")*('1128 4度C'!$T:$T<>"")),'1128 4度C'!$T:$T) -> 0.43680556 | I17: =LOOKUP(2,1/(('1128 4度C'!$A:$A="新豐1線")*('1128 4度C'!$T:$T<>"")),'1128 4度C'!$T:$T) -> 0.90069444 | J17: =LOOKUP(2,1/(('1128 4度C'!$A:$A="新豐10線")*('1128 4度C'!$T:$T<>"")),'1128 4度C'!$T:$T) -> 0.39166667 | K17: =LOOKUP(2,1/(('1128 4度C'!$A:$A="新豐8線")*('1128 4度C'!$T:$T<>"")),'1128 4度C'!$T:$T) -> 0.50763889 | L17: =LOOKUP(2,1/(('1128 4度C'!$A:$A="新豐9線")*('1128 4度C'!$T:$T<>"")),'1128 4度C'!$T:$T) -> 0.51805556 | M17: =LOOKUP(2,1/(('1128 4度C'!$A:$A="新豐4線")*('1128 4度C'!$T:$T<>"")),'1128 4度C'!$T:$T) -> 0.48333333
B18: 配置人數 | D18: =SUMIFS('1128 4度C'!$I:$I,'1128 4度C'!$A:$A,"新豐6線",'1128 4度C'!$B:$B,"平均") -> 15 | E18: =SUMIFS('1128 4度C'!$I:$I,'1128 4度C'!$A:$A,"新豐2線",'1128 4度C'!$B:$B,"平均") -> 18.5 | F18: =SUMIFS('1128 4度C'!$I:$I,'1128 4度C'!$A:$A,"新豐5線",'1128 4度C'!$B:$B,"平均") -> 18.4 | G18: =SUMIFS('1128 4度C'!$I:$I,'1128 4度C'!$A:$A,"新豐7線",'1128 4度C'!$B:$B,"平均") -> 16.875 | H18: =SUMIFS('1128 4度C'!$I:$I,'1128 4度C'!$A:$A,"新豐3線",'1128 4度C'!$B:$B,"平均") -> 10.142857 | I18: =SUMIFS('1128 4度C'!$I:$I,'1128 4度C'!$A:$A,"新豐1線",'1128 4度C'!$B:$B,"平均") -> 16.333333 | J18: =SUMIFS('1128 4度C'!$I:$I,'1128 4度C'!$A:$A,"新豐10線",'1128 4度C'!$B:$B,"平均") -> 9 | K18: =SUMIFS('1128 4度C'!$I:$I,'1128 4度C'!$A:$A,"新豐8線",'1128 4度C'!$B:$B,"平均") -> 18.2 | L18: =SUMIFS('1128 4度C'!$I:$I,'1128 4度C'!$A:$A,"新豐9線",'1128 4度C'!$B:$B,"平均") -> 17.4 | M18: =SUMIFS('1128 4度C'!$I:$I,'1128 4度C'!$A:$A,"新豐4線",'1128 4度C'!$B:$B,"平均") -> 16.428571
B19: 主要應用設備 | D19: ET-55 | E19: 熱縮爐 | F19: L型包裝機 | G19: L型包裝機 | H19: 伺服包裝機 | I19: ET-55 | J19: 伺服包裝機 | K19: 三明治包裝機 | L19: 三明治包裝機 | M19: 三明治包裝機
B20: 次要應用設備 | F20: 圓盤機 | G20: ET-55
B21: 備註 | E21: 握沙拉 | F21: 共用L型包裝機 | H21: 調理麵包 | I21: 炒飯+沙拉 | J21: 調理麵包

Sheet 1128 4度C
A1: 新豐廠四度C日報分析 | C1: 總生產量 | D1: =SUM(F5:F66) -> 134709 | E1: 營業額 | F1: =SUM(G5:G66) -> 4532055.3 | G1: 出勤人數 | H1: =L8+L11+L46+L53+L17+L58+L32+L38+L26+L66 -> 156.27976 | I1: 產線配置圖 | L1: 生產實績 | O1: 人時性差異分析 | S1: 日報登錄 | Y1: 分析說明 | AA1: 產能差異分析
A2: 45989 | B2: 星期五 | C2: 人時性 | D2: =AVERAGE(N8,N11,N46,N53,N17,N58,N26,N32,N38,N66) -> 146.62226 | E2: 平均廠價 | F2: =F1/D1 -> 33.6433 | G2: 多次生產數 | H2: =COUNT(H5:H66) -> 1
A3: 線別 | B3: 品類 | C3: 品名 | E3: 廠價 | F3: 生產量 | G3: 營收 | H3: 多次 生產 | I3: 人數 | J3: 產能/時 | K3: 人時性 | L3: 人數 | M3: 產能/時 | N3: 人時性 | O3: 人數 | P3: 人時性 | Q3: 達成率 | R3: 達成率平均 | S3: 生產時間 | U3: 換線、休息/分 | V3: 稼動時間/分 | W3: 休息時間 | Y3: (新豐回填) | AA3: 產能/時 | AB3: 達成率 | AC3: 達成率平均
S4: 開始 | T4: 結束 | W4: 開始 | X4: 結束
A5: 新豐6線 | B5: 微波主食 | C5: 二配港式香滑嫩蛋牛肉燴飯 | E5: 50.67 | F5: 1337 | G5: =E5*F5 -> 67745.79 | I5: 17 | J5: 2000 | K5: =J5/I5 -> 117.64706 | L5: 17 | M5: =F5/V5*60 -> 1910 | N5: =M5/L5 -> 112.35294 | O5: =L5-I5 -> 0 | P5: =N5-K5 -> -5.2941176 | Q5: =N5/K5 -> 0.955 | R5: =Q8 -> 0.96145145 | S5: 0.70833333 | T5: 0.7375 | V5: =(T5-S5)*24*60 -> 42 | AA5: =M5-J5 -> -90 | AB5: =M5/J5 -> 0.955 | AC5: =AB8 -> 0.96145145
A6: 新豐6線 | B6: 微波主食 | C6: 二配川味麻婆燒豆腐燴飯 | E6: 50.49 | F6: 1739 | G6: =E6*F6 -> 87802.11 | I6: 15 | J6: 2000 | K6: =J6/I6 -> 133.33333 | L6: 15 | M6: =F6/V6*60 -> 1932.2222 | N6: =M6/L6 -> 128.81481 | O6: =L6-I6 -> 0 | P6: =N6-K6 -> -4.5185185 | Q6: =N6/K6 -> 0.96611111 | S6: 0.74305556 | T6: 0.78055556 | U6: =IF(S6=TIME(17,0,0),"",(S6-T5)*24*60) -> 8 | V6: =(T6-S6)*24*60 -> 54 | AA6: =M6-J6 -> -67.777778 | AB6: =M6/J6 -> 0.96611111
A7: 新豐6線 | B7: 微波主食 | C7: 二配厚香料咖哩雞排飯 | E7: 57.3 | F7: 2376 | G7: =E7*F7 -> 136144.8 | I7: 13 | J7: 2000 | K7: =J7/I7 -> 153.84615 | L7: 13 | M7: =F7/V7*60 -> 1926.4865 | N7: =M7/L7 -> 148.19127 | O7: =L7-I7 -> 0 | P7: =N7-K7 -> -5.6548857 | Q7: =N7/K7 -> 0.96324324 | S7: 0.78541667 | T7: 0.83680556 | U7: =IF(S7=TIME(17,0,0),"",(S7-T6)*24*60) -> 7 | V7: =(T7-S7)*24*60 -> 74 | AA7: =M7-J7 -> -73.513514 | AB7: =M7/J7 -> 0.96324324
A8: 新豐6線 | B8: 平均 | I8: 15 | J8: 2000 | K8: =J8/I8 -> 133.33333 | L8: 15 | M8: =AVERAGE(M5:M7) -> 1922.9029 | N8: =M8/L8 -> 128.19353 | O8: =L8-I8 -> 0 | P8: =N8-K8 -> -5.1398065 | Q8: =N8/K8 -> 0.96145145 | AA8: =M8-J8 -> -77.097097 | AB8: =M8/J8 -> 0.96145145
A9: 新豐2線 | B9: 沙拉 | C9: 韓式泡菜豆腐握沙拉 | E9: 39.36 | F9: 1066 | G9: =E9*F9 -> 41957.76 | I9: 20 | J9: 1500 | K9: =J9/I9 -> 75 | L9: 20 | M9: =F9/V9*60 -> 1453.6364 | N9: =M9/L9 -> 72.681818 | O9: =L9-I9 -> 0 | P9: =N9-K9 -> -2.3181818 | Q9: =N9/K9 -> 0.96909091 | R9: =Q11 -> 0.96153038 | S9: 0.20833333 | T9: 0.23888889 | V9: =(T9-S9)*24*60 -> 44 | AA9: =M9-J9 -> -46.363636 | AB9: =M9/J9 -> 0.96909091 | AC9: =AB11 -> 0.96153038
A10: 新豐2線 | B10: 沙拉 | C10: 青檸烤雞握沙拉(113年) | E10: 39.8 | F10: 4746 | G10: =E10*F10 -> 188890.8 | I10: 17 | J10: 1500 | K10: =J10/I10 -> 88.235294 | L10: 17 | M10: =F10/V10*60 -> 1430.9548 | N10: =M10/L10 -> 84.17381 | O10: =L10-I10 -> 0 | P10: =N10-K10 -> -4.0614839 | Q10: =N10/K10 -> 0.95396985 | S10: 0.24444444 | T10: 0.38263889 | U10: =IF(S10=TIME(17,0,0),"",(S10-T9)*24*60) -> 8 | V10: =(T10-S10)*24*60 -> 199 | AA10: =M10-J10 -> -69.045226 | AB10: =M10/J10 -> 0.95396985
A11: 新豐2線 | B11: 平均 | I11: 18.5 | J11: 1500 | K11: =J11/I11 -> 81.081081 | L11: 18.5 | M11: =AVERAGE(M9:M10) -> 1442.2956 | N11: =M11/L11 -> 77.961923 | O11: =L11-I11 -> 0 | P11: =N11-K11 -> -3.1191584 | Q11: =N11/K11 -> 0.96153038 | AA11: =M11-J11 -> -57.704431 | AB11: =M11/J11 -> 0.96153038
A12: 新豐5線 | B12: 小吃 | C12: 剝皮辣椒雞湯 | E12: 41 | F12: 1919 | G12: =E12*F12 -> 78679 | I12: 26 | J12: 1500 | K12: =J12/I12 -> 57.692308 | L12: 26 | M12: =F12/V12*60 -> 1439.25 | N12: =M12/L12 -> 55.355769 | O12: =L12-I12 -> 0 | P12: =N12-K12 -> -2.3365385 | Q12: =N12/K12 -> 0.9595 | R12: =Q17 -> 0.9572399 | S12: 0.125 | T12: 0.18055556 | V12: =(T12-S12)*24*60 -> 80 | W12: =T12 -> 0.18055556 | X12: =S13 -> 0.2 | AA12: =M12-J12 -> -60.75 | AB12: =M12/J12 -> 0.9595 | AC12: =AB17 -> 0.9572399
A13: 新豐5線 | B13: 沙拉 | C13: 青醬優格雞肉握沙拉(113年) | E13: 39.62 | F13: 3146 | G13: =E13*F13 -> 124644.52 | I13: 19 | J13: 1500 | K13: =J13/I13 -> 78.947368 | L13: 19 | M13: =F13/V13*60 -> 1430 | N13: =M13/L13 -> 75.263158 | O13: =L13-I13 -> 0 | P13: =N13-K13 -> -3.6842105 | Q13: =N13/K13 -> 0.95333333 | S13: 0.2 | T13: 0.29166667 | U13: =IF(S13=TIME(17,0,0),"",(S13-T12)*24*60) -> 28 | V13: =(T13-S13)*24*60 -> 132 | AA13: =M13-J13 -> -70 | AB13: =M13/J13 -> 0.95333333
A14: 新豐5線 | B14: 微波主食 | C14: 二配金咖哩濃厚辛口咖哩飯 | E14: 50.98 | F14: 2064 | G14: =E14*F14 -> 105222.72 | I14: 16 | J14: 2000 | K14: =J14/I14 -> 125 | L14: 16 | M14: =F14/V14*60 -> 1905.2308 | N14: =M14/L14 -> 119.07692 | O14: =L14-I14 -> 0 | P14: =N14-K14 -> -5.9230769 | Q14: =N14/K14 -> 0.95261538 | S14: 0.70833333 | T14: 0.75347222 | U14: =IF(S14=TIME(17,0,0),"",(S14-T13)*24*60) | V14: =(T14-S14)*24*60 -> 65 | AA14: =M14-J14 -> -94.769231 | AB14: =M14/J14 -> 0.95261538
A15: 新豐5線 | B15: 微波主食 | C15: 二配金咖哩果香甘口咖哩飯 | E15: 50.92 | F15: 1959 | G15: =E15*F15 -> 99752.28 | I15: 15 | J15: 2000 | K15: =J15/I15 -> 133.33333 | L15: 15 | M15: =F15/V15*60 -> 1926.8852 | N15: =M15/L15 -> 128.45902 | O15: =L15-I15 -> 0 | P15: =N15-K15 -> -4.8743169 | Q15: =N15/K15 -> 0.96344262 | S15: 0.75902778 | T15: 0.80138889 | U15: =IF(S15=TIME(17,0,0),"",(S15-T14)*24*60) -> 8 | V15: =(T15-S15)*24*60 -> 61 | AA15: =M15-J15 -> -73.114754 | AB15: =M15/J15 -> 0.96344262
A16: 新豐5線 | B16: 微波主食 | C16: 二配煸椒烘蛋飯 | E16: 46.93 | F16: 925 | G16: =E16*F16 -> 43410.25 | I16: 16 | J16: 2000 | K16: =J16/I16 -> 125 | L16: 16 | M16: =F16/V16*60 -> 1913.7931 | N16: =M16/L16 -> 119.61207 | O16: =L16-I16 -> 0 | P16: =N16-K16 -> -5.387931 | Q16: =N16/K16 -> 0.95689655 | S16: 0.80625 | T16: 0.82638889 | U16: =IF(S16=TIME(17,0,0),"",(S16-T15)*24*60) -> 7 | V16: =(T16-S16)*24*60 -> 29 | AA16: =M16-J16 -> -86.206897 | AB16: =M16/J16 -> 0.95689655
A17: 新豐5線 | B17: 平均 | I17: 18.4 | J17: 1800 | K17: =J17/I17 -> 97.826087 | L17: 18.4 | M17: =AVERAGE(M12:M16) -> 1723.0318 | N17: =M17/L17 -> 93.643034 | O17: =L17-I17 -> 0 | P17: =N17-K17 -> -4.1830531 | Q17: =N17/K17 -> 0.9572399 | AA17: =M17-J17 -> -76.968176 | AB17: =M17/J17 -> 0.9572399
A18: 新豐7線 | B18: 小吃 | C18: 古早味炒炊粉 | E18: 43.14 | F18: 892 | G18: =E18*F18 -> 38480.88 | I18: 17 | J18: 2000 | K18: =J18/I18 -> 117.64706 | L18: 17 | M18: =F18/V18*60 -> 1911.4286 | N18: =M18/L18 -> 112.43697 | O18: =L18-I18 -> 0 | P18: =N18-K18 -> -5.210084 | Q18: =N18/K18 -> 0.95571429 | R18: =Q26 -> 0.95899212 | S18: 0.20833333 | T18: 0.22777778 | V18: =(T18-S18)*24*60 -> 28 | AA18: =M18-J18 -> -88.571429 | AB18: =M18/J18 -> 0.95571429 | AC18: =AB26 -> 0.95899212
A19: 新豐7線 | B19: 熱食義麵 | C19: 麻婆豆腐波浪麵 | E19: 49.9 | F19: 1469 | G19: =E19*F19 -> 73303.1 | I19: 19 | J19: 2000 | K19: =J19/I19 -> 105.26316 | L19: 19 | M19: =F19/V19*60 -> 1916.087 | N19: =M19/L19 -> 100.84668 | O19: =L19-I19 -> 0 | P19: =N19-K19 -> -4.416476 | Q19: =N19/K19 -> 0.95804348 | S19: 0.23125 | T19: 0.26319444 | U19: =IF(S19=TIME(17,0,0),"",(S19-T18)*24*60) -> 5 | V19: =(T19-S19)*24*60 -> 46 | AA19: =M19-J19 -> -83.913043 | AB19: =M19/J19 -> 0.95804348
A20: 新豐7線 | B20: 微波主食 | C20: 鐵板滑蛋炸豬排丼 | E20: 57.73 | F20: 1943 | G20: =E20*F20 -> 112169.39 | I20: 14 | J20: 2000 | K20: =J20/I20 -> 142.85714 | L20: 14 | M20: =F20/V20*60 -> 1911.1475 | N20: =M20/L20 -> 136.51054 | O20: =L20-I20 -> 0 | P20: =N20-K20 -> -6.3466042 | Q20: =N20/K20 -> 0.95557377 | S20: 0.26805556 | T20: 0.31041667 | U20: =IF(S20=TIME(17,0,0),"",(S20-T19)*24*60) -> 7 | V20: =(T20-S20)*24*60 -> 61 | AA20: =M20-J20 -> -88.852459 | AB20: =M20/J20 -> 0.95557377
A21: 新豐7線 | B21: 微波主食 | C21: 極上炙烤親子丼 | E21: 53.68 | F21: 1223 | G21: =E21*F21 -> 65650.64 | I21: 16 | J21: 2000 | K21: =J21/I21 -> 125 | L21: 16 | M21: =F21/V21*60 -> 1931.0526 | N21: =M21/L21 -> 120.69079 | O21: =L21-I21 -> 0 | P21: =N21-K21 -> -4.3092105 | Q21: =N21/K21 -> 0.96552632 | S21: 0.31458333 | T21: 0.34097222 | U21: =IF(S21=TIME(17,0,0),"",(S21-T20)*24*60) -> 6 | V21: =(T21-S21)*24*60 -> 38 | AA21: =M21-J21 -> -68.947368 | AB21: =M21/J21 -> 0.96552632
A22: 新豐7線 | B22: 微波主食 | C22: 日式野菜烘蛋燴飯 | E22: 49.91 | F22: 1369 | G22: =E22*F22 -> 68326.79 | I22: 19 | J22: 2000 | K22: =J22/I22 -> 105.26316 | L22: 19 | M22: =F22/V22*60 -> 1910.2326 | N22: =M22/L22 -> 100.53856 | O22: =L22-I22 -> 0 | P22: =N22-K22 -> -4.7246022 | Q22: =N22/K22 -> 0.95511628 | S22: 0.34513889 | T22: 0.375 | U22: =IF(S22=TIME(17,0,0),"",(S22-T21)*24*60) -> 6 | V22: =(T22-S22)*24*60 -> 43 | AA22: =M22-J22 -> -89.767442 | AB22: =M22/J22 -> 0.95511628
