Workbook

Sheet 1031
B1: 屏榮 新豐廠組合室生產人時性分析
B3: 日期 | C3: =TEXT('1031 4度C'!A2,"yyyy.mm.ddaaaa") -> 2025.10.31星期五 | E3: 訂單量 | F3: ='1031 4度C'!D1 -> 145968 | H3: 營業額 | I3: ='1031 4度C'!F1 -> 4853449.6
B4: 人時性 | C4: 項目 | E4: ➀ | G4: ➁ | I4: ➂
C5: 組合室 | E5: 全溫層 | G5: 4度C-各編組展開 | I5: ③三明治-各編組展開
C6: 排關平均 | E6: =AVERAGE(D13:M13) -> 148.80827 | F6: =AVERAGE(D27:O27,D13:J13) -> 153.24268 | G6: =AVERAGE(D13:J13) -> 153.24268 | I6: =AVERAGE(K13:M13) -> 138.46131
C7: 實績平均 | E7: =AVERAGE(D14:M14) -> 142.87663 | F7: =AVERAGE(D28:O28,D14:J14) -> 147.27371 | G7: =AVERAGE(D14:J14) -> 147.27371 | I7: =AVERAGE(K14:M14) -> 132.61677
C8: 達成率平均 | E8: =AVERAGE(D15:M15) -> 0.95971198 | F8: =AVERAGE(D15:J15,D29:O29) -> 0.96054241 | G8: =AVERAGE(D15:J15) -> 0.96054241 | I8: =AVERAGE(K15:M15) -> 0.95777432 | K8: ※現行日本鮮食廠以達成率80%為基本(即為現行KPI)
B10: 溫層 | D10: ➁4度C-各編組展開 | K10: ③三明治-各編組展開
B11: 編組 | D11: 1 | E11: 2 | F11: 3 | G11: 4 | H11: 5 | I11: 6 | J11: 7 | K11: 1 | L11: 2 | M11: 3
D12: 新豐6線 | E12: 新豐2線 | F12: 新豐5線 | G12: 新豐7線 | H12: 新豐3線 | I12: 新豐1線 | J12: 新豐10線 | K12: 新豐8線 | L12: 新豐9線 | M12: 新豐4線
B13: 人時性 | C13: 排關 | D13: =SUMIFS('1031 4度C'!$K:$K,'1031 4度C'!$A:$A,"新豐6線",'1031 4度C'!$B:$B,"平均") -> 125 | E13: =SUMIFS('1031 4度C'!$K:$K,'1031 4度C'!$A:$A,"新豐2線",'1031 4度C'!$B:$B,"平均") -> 81.081081 | F13: =SUMIFS('1031 4度C'!$K:$K,'1031 4度C'!$A:$A,"新豐5線",'1031 4度C'!$B:$B,"平均") -> 91.397849 | G13: =SUMIFS('1031 4度C'!$K:$K,'1031 4度C'!$A:$A,"新豐7線",'1031 4度C'!$B:$B,"平均") -> 121.95122 | H13: =SUMIFS('1031 4度C'!$K:$K,'1031 4度C'!$A:$A,"新豐3線",'1031 4度C'!$B:$B,"平均") -> 261.90476 | I13: =SUMIFS('1031 4度C'!$K:$K,'1031 4度C'!$A:$A,"新豐1線",'1031 4度C'!$B:$B,"平均") -> 115.85366 | J13: =SUMIFS('1031 4度C'!$K:$K,'1031 4度C'!$A:$A,"新豐10線",'1031 4度C'!$B:$B,"平均") -> 275.5102 | K13: =SUMIFS('1031 4度C'!$K:$K,'1031 4度C'!$A:$A,"新豐8線",'1031 4度C'!$B:$B,"平均") -> 135.84906 | L13: =SUMIFS('1031 4度C'!$K:$K,'1031 4度C'!$A:$A,"新豐9線",'1031 4度C'!$B:$B,"平均") -> 139.53488 | M13: =SUMIFS('1031 4度C'!$K:$K,'1031 4度C'!$A:$A,"新豐4線",'1031 4度C'!$B:$B,"平均") -> 140
C14: 實績 | D14: =SUMIFS('1031 4度C'!$N:$N,'1031 4度C'!$A:$A,"新豐6線",'1031 4度C'!$B:$B,"平均") -> 121.02106 | E14: =SUMIFS('1031 4度C'!$N:$N,'1031 4度C'!$A:$A,"新豐2線",'1031 4度C'!$B:$B,"平均") -> 77.457183 | F14: =SUMIFS('1031 4度C'!$N:$N,'1031 4度C'!$A:$A,"新豐5線",'1031 4度C'!$B:$B,"平均") -> 87.484989 | G14: =SUMIFS('1031 4度C'!$N:$N,'1031 4度C'!$A:$A,"新豐7線",'1031 4度C'!$B:$B,"平均") -> 116.84779 | H14: =SUMIFS('1031 4度C'!$N:$N,'1031 4度C'!$A:$A,"新豐3線",'1031 4度C'!$B:$B,"平均") -> 252.0929 | I14: =SUMIFS('1031 4度C'!$N:$N,'1031 4度C'!$A:$A,"新豐1線",'1031 4度C'!$B:$B,"平均") -> 111.48887 | J14: =SUMIFS('1031 4度C'!$N:$N,'1031 4度C'!$A:$A,"新豐10線",'1031 4度C'!$B:$B,"平均") -> 264.52315 | K14: =SUMIFS('1031 4度C'!$N:$N,'1031 4度C'!$A:$A,"新豐8線",'1031 4度C'!$B:$B,"平均") -> 129.89403 | L14: =SUMIFS('1031 4度C'!$N:$N,'1031 4度C'!$A:$A,"新豐9線",'1031 4度C'!$B:$B,"平均") -> 133.77294 | M14: =SUMIFS('1031 4度C'!$N:$N,'1031 4度C'!$A:$A,"新豐4線",'1031 4度C'!$B:$B,"平均") -> 134.18334
C15: 達成率 | D15: =D14/D13 -> 0.96816847 | E15: =E14/E13 -> 0.95530526 | F15: =F14/F13 -> 0.9571887 | G15: =G14/G13 -> 0.95815185 | H15: =H14/H13 -> 0.96253654 | I15: =I14/I13 -> 0.96232502 | J15: =J14/J13 -> 0.96012105 | K15: =K14/K13 -> 0.95616442 | ... M15: =M14/M13 -> 0.95845243
B16: 作業 時間 | C16: 開始 | D16: =VLOOKUP("新豐6線",'1031 4度C'!$A:$T,19,0) -> 0.70833333 | E16: =VLOOKUP("新豐2線",'1031 4度C'!$A:$T,19,0) -> 0.20833333 | F16: =VLOOKUP("新豐5線",'1031 4度C'!$A:$T,19,0) -> 0.125 | G16: =VLOOKUP("新豐7線",'1031 4度C'!$A:$T,19,0) -> 0.20833333 | H16: =VLOOKUP("新豐3線",'1031 4度C'!$A:$T,19,0) -> 0.083333333 | I16: =VLOOKUP("新豐1線",'1031 4度C'!$A:$T,19,0) -> 0.20833333 | J16: =VLOOKUP("新豐10線",'1031 4度C'!$A:$T,19,0) -> 0.20833333 | K16: =VLOOKUP("新豐8線",'1031 4度C'!$A:$T,19,0) -> 0.083333333 | L16: =VLOOKUP("新豐9線",'1031 4度C'!$A:$T,19,0) -> 0.083333333 | M16: =VLOOKUP("新豐4線",'1031 4度C'!$A:$T,19,0) -> 0.083333333
C17: 結束 | D17: =LOOKUP(2,1/(('1031 4度C'!$A:$A="新豐6線")*('1031 4度C'!$T:$T<>"")),'1031 4度C'!$T:$T) -> 0.80555556 | E17: =LOOKUP(2,1/(('1031 4度C'!$A:$A="新豐2線")*('1031 4度C'!$T:$T<>"")),'1031 4度C'!$T:$T) -> 0.41527778 | F17: =LOOKUP(2,1/(('1031 4度C'!$A:$A="新豐5線")*('1031 4度C'!$T:$T<>"")),'1031 4度C'!$T:$T) -> 0.81319444 | G17: =LOOKUP(2,1/(('1031 4度C'!$A:$A="新豐7線")*('1031 4度C'!$T:$T<>"")),'1031 4度C'!$T:$T) -> 0.78958333 | H17: =LOOKUP(2,1/(('1031 4度C'!$A:$A="新豐3線")*('1031 4度C'!$T:$T<>"")),'1031 4度C'!$T:$T) -> 0.58819444 | I17: =LOOKUP(2,1/(('1031 4度C'!$A:$A="新豐1線")*('1031 4度C'!$T:$T<>"")),'1031 4度C'!$T:$T) -> 0.84652778 | J17: =LOOKUP(2,1/(('1031 4度C'!$A:$A="新豐10線")*('1031 4度C'!$T:$T<>"")),'1031 4度C'!$T:$T) -> 0.45694444 | K17: =LOOKUP(2,1/(('1031 4度C'!$A:$A="新豐8線")*('1031 4度C'!$T:$T<>"")),'1031 4度C'!$T:$T) -> 0.56805556 | L17: =LOOKUP(2,1/(('1031 4度C'!$A:$A="新豐9線")*('1031 4度C'!$T:$T<>"")),'1031 4度C'!$T:$T) -> 0.50833333 | M17: =LOOKUP(2,1/(('1031 4度C'!$A:$A="新豐4線")*('1031 4度C'!$T:$T<>"")),'1031 4度C'!$T:$T) -> 0.51527778
B18: 配置人數 | D18: =SUMIFS('1031 4度C'!$I:$I,'1031 4度C'!$A:$A,"新豐6線",'1031 4度C'!$B:$B,"平均") -> 16 | E18: =SUMIFS('1031 4度C'!$I:$I,'1031 4度C'!$A:$A,"新豐2線",'1031 4度C'!$B:$B,"平均") -> 18.5 | F18: =SUMIFS('1031 4度C'!$I:$I,'1031 4度C'!$A:$A,"新豐5線",'1031 4度C'!$B:$B,"平均") -> 18.6 | G18: =SUMIFS('1031 4度C'!$I:$I,'1031 4度C'!$A:$A,"新豐7線",'1031 4度C'!$B:$B,"平均") -> 16.4 | H18: =SUMIFS('1031 4度C'!$I:$I,'1031 4度C'!$A:$A,"新豐3線",'1031 4度C'!$B:$B,"平均") -> 10.5 | I18: =SUMIFS('1031 4度C'!$I:$I,'1031 4度C'!$A:$A,"新豐1線",'1031 4度C'!$B:$B,"平均") -> 16.4 | J18: =SUMIFS('1031 4度C'!$I:$I,'1031 4度C'!$A:$A,"新豐10線",'1031 4度C'!$B:$B,"平均") -> 9.8 | K18: =SUMIFS('1031 4度C'!$I:$I,'1031 4度C'!$A:$A,"新豐8線",'1031 4度C'!$B:$B,"平均") -> 17.666667 | L18: =SUMIFS('1031 4度C'!$I:$I,'1031 4度C'!$A:$A,"新豐9線",'1031 4度C'!$B:$B,"平均") -> 17.2 | M18: =SUMIFS('1031 4度C'!$I:$I,'1031 4度C'!$A:$A,"新豐4線",'1031 4度C'!$B:$B,"平均") -> 17.142857
B19: 主要應用設備 | D19: ET-55 | E19: 熱縮爐 | F19: L型包裝機 | G19: L型包裝機 | H19: 伺服包裝機 | I19: ET-55 | J19: 伺服包裝機 | K19: 三明治包裝機 | L19: 三明治包裝機 | M19: 三明治包裝機
B20: 次要應用設備 | F20: 圓盤機 | G20: ET-55
B21: 備註 | E21: 握沙拉 | F21: 共用L型包裝機 | H21: 調理麵包 | I21: 炒飯+沙拉 | J21: 調理麵包

Sheet 1031 4度C
A1: 新豐廠四度C日報分析 | C1: 總生產量 | D1: =SUM(F5:F65) -> 145968 | E1: 營業額 | F1: =SUM(G5:G65) -> 4853449.6 | G1: 出勤人數 | H1: =L8+L11+L45+L51+L17+L57+L30+L36+L23+L65 -> 158.20952 | I1: 產線配置圖 | L1: 生產實績 | O1: 人時性差異分析 | S1: 日報登錄 | Y1: 分析說明 | AA1: 產能差異分析
A2: 45961 | B2: 星期五 | C2: 人時性 | D2: =AVERAGE(N8,N11,N45,N51,N17,N57,N23,N30,N36,N65) -> 142.87663 | E2: 平均廠價 | F2: =F1/D1 -> 33.250093 | G2: 多次生產數 | H2: =COUNT(H5:H65) -> 2
A3: 線別 | B3: 品類 | C3: 品名 | E3: 廠價 | F3: 生產量 | G3: 營收 | H3: 多次 生產 | I3: 人數 | J3: 產能/時 | K3: 人時性 | L3: 人數 | M3: 產能/時 | N3: 人時性 | O3: 人數 | P3: 人時性 | Q3: 達成率 | R3: 達成率平均 | S3: 生產時間 | U3: 換線、休息/分 | V3: 稼動時間/分 | W3: 休息時間 | Y3: (新豐回填) | AA3: 產能/時 | AB3: 達成率 | AC3: 達成率平均
S4: 開始 | T4: 結束 | W4: 開始 | X4: 結束
A5: 新豐6線 | B5: 微波主食 | C5: 二配煸椒烘蛋飯 | E5: 46.93 | F5: 716 | G5: =E5*F5 -> 33601.88 | I5: 16 | J5: 2000 | K5: =J5/I5 -> 125 | L5: 16 | M5: =F5/V5*60 -> 1952.7273 | N5: =M5/L5 -> 122.04545 | O5: =L5-I5 -> 0 | P5: =N5-K5 -> -2.9545455 | Q5: =N5/K5 -> 0.97636364 | R5: =Q8 -> 0.96816847 | S5: 0.70833333 | T5: 0.72361111 | V5: =(T5-S5)*24*60 -> 22 | AA5: =M5-J5 -> -47.272727 | AB5: =M5/J5 -> 0.97636364 | AC5: =AB8 -> 0.96816847
A6: 新豐6線 | B6: 微波主食 | C6: 二配川味麻婆燒豆腐燴飯 | E6: 50.49 | F6: 1829 | G6: =E6*F6 -> 92346.21 | I6: 15 | J6: 2000 | K6: =J6/I6 -> 133.33333 | L6: 15 | M6: =F6/V6*60 -> 1925.2632 | N6: =M6/L6 -> 128.35088 | O6: =L6-I6 -> 0 | P6: =N6-K6 -> -4.9824561 | Q6: =N6/K6 -> 0.96263158 | S6: 0.72708333 | T6: 0.76666667 | U6: =IF(S6=TIME(17,0,0),"",(S6-T5)*24*60) -> 5 | V6: =(T6-S6)*24*60 -> 57 | AA6: =M6-J6 -> -74.736842 | AB6: =M6/J6 -> 0.96263158
A7: 新豐6線 | B7: 微波主食 | C7: 二配港式香滑嫩蛋牛肉燴飯 | E7: 50.67 | F7: 1577 | G7: =E7*F7 -> 79906.59 | I7: 17 | J7: 2000 | K7: =J7/I7 -> 117.64706 | L7: 17 | M7: =F7/V7*60 -> 1931.0204 | N7: =M7/L7 -> 113.58944 | O7: =L7-I7 -> 0 | P7: =N7-K7 -> -4.057623 | Q7: =N7/K7 -> 0.9655102 | S7: 0.77152778 | T7: 0.80555556 | U7: =IF(S7=TIME(17,0,0),"",(S7-T6)*24*60) -> 7 | V7: =(T7-S7)*24*60 -> 49 | AA7: =M7-J7 -> -68.979592 | AB7: =M7/J7 -> 0.9655102
A8: 新豐6線 | B8: 平均 | I8: 16 | J8: 2000 | K8: =J8/I8 -> 125 | L8: 16 | M8: =AVERAGE(M5:M7) -> 1936.3369 | N8: =M8/L8 -> 121.02106 | O8: =L8-I8 -> 0 | P8: =N8-K8 -> -3.9789409 | Q8: =N8/K8 -> 0.96816847 | AA8: =M8-J8 -> -63.663054 | AB8: =M8/J8 -> 0.96816847
A9: 新豐2線 | B9: 沙拉 | C9: 韓式泡菜豆腐握沙拉 | E9: 39.36 | F9: 1840 | G9: =E9*F9 -> 72422.4 | I9: 20 | J9: 1500 | K9: =J9/I9 -> 75 | L9: 20 | M9: =F9/V9*60 -> 1433.7662 | N9: =M9/L9 -> 71.688312 | O9: =L9-I9 -> 0 | P9: =N9-K9 -> -3.3116883 | Q9: =N9/K9 -> 0.95584416 | R9: =Q11 -> 0.95530526 | S9: 0.20833333 | T9: 0.26180556 | V9: =(T9-S9)*24*60 -> 77 | AA9: =M9-J9 -> -66.233766 | AB9: =M9/J9 -> 0.95584416 | AC9: =AB11 -> 0.95530526
A10: 新豐2線 | B10: 沙拉 | C10: 青檸烤雞握沙拉(113年) | E10: 39.8 | F10: 5108 | G10: =E10*F10 -> 203298.4 | I10: 17 | J10: 1500 | K10: =J10/I10 -> 88.235294 | L10: 17 | M10: =F10/V10*60 -> 1432.1495 | N10: =M10/L10 -> 84.24409 | O10: =L10-I10 -> 0 | P10: =N10-K10 -> -3.991204 | Q10: =N10/K10 -> 0.95476636 | S10: 0.26666667 | T10: 0.41527778 | U10: =IF(S10=TIME(17,0,0),"",(S10-T9)*24*60) -> 7 | V10: =(T10-S10)*24*60 -> 214 | AA10: =M10-J10 -> -67.850467 | AB10: =M10/J10 -> 0.95476636
A11: 新豐2線 | B11: 平均 | I11: 18.5 | J11: 1500 | K11: =J11/I11 -> 81.081081 | L11: 18.5 | M11: =AVERAGE(M9:M10) -> 1432.9579 | N11: =M11/L11 -> 77.457183 | O11: =L11-I11 -> 0 | P11: =N11-K11 -> -3.6238982 | Q11: =N11/K11 -> 0.95530526 | AA11: =M11-J11 -> -67.042117 | AB11: =M11/J11 -> 0.95530526
A12: 新豐5線 | B12: 小吃 | C12: 剝皮辣椒雞湯 | E12: 41 | F12: 2087 | G12: =E12*F12 -> 85567 | I12: 26 | J12: 1500 | K12: =J12/I12 -> 57.692308 | L12: 26 | M12: =F12/V12*60 -> 1439.3103 | N12: =M12/L12 -> 55.35809 | O12: =L12-I12 -> 0 | P12: =N12-K12 -> -2.3342175 | Q12: =N12/K12 -> 0.95954023 | R12: =Q17 -> 0.9571887 | S12: 0.125 | T12: 0.18541667 | V12: =(T12-S12)*24*60 -> 87 | W12: =T12 -> 0.18541667 | X12: =S13 -> 0.20486111 | AA12: =M12-J12 -> -60.689655 | AB12: =M12/J12 -> 0.95954023 | AC12: =AB17 -> 0.9571887
A13: 新豐5線 | B13: 沙拉 | C13: 青醬優格雞肉握沙拉(113年) | E13: 39.62 | F13: 3528 | G13: =E13*F13 -> 139779.36 | I13: 19 | J13: 1500 | K13: =J13/I13 -> 78.947368 | L13: 19 | M13: =F13/V13*60 -> 1430.2703 | N13: =M13/L13 -> 75.277383 | O13: =L13-I13 -> 0 | P13: =N13-K13 -> -3.6699858 | Q13: =N13/K13 -> 0.95351351 | S13: 0.20486111 | T13: 0.30763889 | U13: =IF(S13=TIME(17,0,0),"",(S13-T12)*24*60) -> 28 | V13: =(T13-S13)*24*60 -> 148 | AA13: =M13-J13 -> -69.72973 | AB13: =M13/J13 -> 0.95351351
A14: 新豐5線 | B14: 熱食義麵 | C14: 焗烤明太子筆尖麵 | E14: 57.3 | F14: 1583 | G14: =E14*F14 -> 90705.9 | I14: 17 | J14: 1500 | K14: =J14/I14 -> 88.235294 | L14: 17 | M14: =F14/V14*60 -> 1439.0909 | N14: =M14/L14 -> 84.652406 | O14: =L14-I14 -> 0 | P14: =N14-K14 -> -3.5828877 | Q14: =N14/K14 -> 0.95939394 | S14: 0.3125 | T14: 0.35833333 | U14: =IF(S14=TIME(17,0,0),"",(S14-T13)*24*60) -> 7 | V14: =(T14-S14)*24*60 -> 66 | AA14: =M14-J14 -> -60.909091 | AB14: =M14/J14 -> 0.95939394
A15: 新豐5線 | B15: 微波主食 | C15: 二配金咖哩濃厚辛辣咖哩飯 | E15: 50.98 | F15: 2286 | G15: =E15*F15 -> 116540.28 | I15: 16 | J15: 2000 | K15: =J15/I15 -> 125 | L15: 16 | M15: =F15/V15*60 -> 1905 | N15: =M15/L15 -> 119.0625 | O15: =L15-I15 -> 0 | P15: =N15-K15 -> -5.9375 | Q15: =N15/K15 -> 0.9525 | S15: 0.70833333 | T15: 0.75833333 | U15: =IF(S15=TIME(17,0,0),"",(S15-T14)*24*60) | V15: =(T15-S15)*24*60 -> 72 | AA15: =M15-J15 -> -95 | AB15: =M15/J15 -> 0.9525
A16: 新豐5線 | B16: 微波主食 | C16: 二配金咖哩果香甘口咖哩飯 | E16: 50.92 | F16: 2371 | G16: =E16*F16 -> 120731.32 | I16: 15 | J16: 2000 | K16: =J16/I16 -> 133.33333 | L16: 15 | M16: =F16/V16*60 -> 1922.4324 | N16: =M16/L16 -> 128.16216 | O16: =L16-I16 -> 0 | P16: =N16-K16 -> -5.1711712 | Q16: =N16/K16 -> 0.96121622 | S16: 0.76180556 | T16: 0.81319444 | U16: =IF(S16=TIME(17,0,0),"",(S16-T15)*24*60) -> 5 | V16: =(T16-S16)*24*60 -> 74 | AA16: =M16-J16 -> -77.567568 | AB16: =M16/J16 -> 0.96121622
A17: 新豐5線 | B17: 平均 | I17: 18.6 | J17: 1700 | K17: =J17/I17 -> 91.397849 | L17: 18.6 | M17: =AVERAGE(M12:M16) -> 1627.2208 | N17: =M17/L17 -> 87.484989 | O17: =L17-I17 -> 0 | P17: =N17-K17 -> -3.9128607 | Q17: =N17/K17 -> 0.9571887 | AA17: =M17-J17 -> -72.779209 | AB17: =M17/J17 -> 0.9571887
A18: 新豐7線 | B18: 小吃 | C18: 古早味炒炊粉 | E18: 43.14 | F18: 1068 | G18: =E18*F18 -> 46073.52 | I18: 17 | J18: 2000 | K18: =J18/I18 -> 117.64706 | L18: 17 | M18: =F18/V18*60 -> 1941.8182 | N18: =M18/L18 -> 114.2246 | O18: =L18-I18 -> 0 | P18: =N18-K18 -> -3.4224599 | Q18: =N18/K18 -> 0.97090909 | R18: =Q23 -> 0.95815185 | S18: 0.20833333 | T18: 0.23125 | V18: =(T18-S18)*24*60 -> 33 | AA18: =M18-J18 -> -58.181818 | AB18: =M18/J18 -> 0.97090909 | AC18: =AB23 -> 0.95815185
A19: 新豐7線 | B19: 微波主食 | C19: 極上炙烤親子丼 | E19: 53.68 | F19: 1525 | G19: =E19*F19 -> 81862 | I19: 16 | J19: 2000 | K19: =J19/I19 -> 125 | L19: 16 | M19: =F19/V19*60 -> 1906.25 | N19: =M19/L19 -> 119.14062 | O19: =L19-I19 -> 0 | P19: =N19-K19 -> -5.859375 | Q19: =N19/K19 -> 0.953125 | S19: 0.23680556 | T19: 0.27013889 | U19: =IF(S19=TIME(17,0,0),"",(S19-T18)*24*60) -> 8 | V19: =(T19-S19)*24*60 -> 48 | AA19: =M19-J19 -> -93.75 | AB19: =M19/J19 -> 0.953125
A20: 新豐7線 | B20: 微波主食 | C20: 鐵板滑蛋炸豬排丼 | E20: 57.73 | F20: 2578 | G20: =E20*F20 -> 148827.94 | I20: 15 | J20: 2000 | K20: =J20/I20 -> 133.33333 | L20: 15 | M20: =F20/V20*60 -> 1909.6296 | N20: =M20/L20 -> 127.30864 | O20: =L20-I20 -> 0 | P20: =N20-K20 -> -6.0246914 | Q20: =N20/K20 -> 0.95481481 | S20: 0.275 | T20: 0.33125 | U20: =IF(S20=TIME(17,0,0),"",(S20-T19)*24*60) -> 7 | V20: =(T20-S20)*24*60 -> 81 | AA20: =M20-J20 -> -90.37037 | AB20: =M20/J20 -> 0.95481481
A21: 新豐7線 | B21: 微波主食 | C21: 二配美味蟹煲 | E21: 54.09 | F21: 1948 | G21: =E21*F21 -> 105367.32 | I21: 19 | J21: 2000 | K21: =J21/I21 -> 105.26316 | L21: 19 | M21: =F21/V21*60 -> 1916.0656 | N21: =M21/L21 -> 100.84556 | O21: =L21-I21 -> 0 | P21: =N21-K21 -> -4.4176014 | Q21: =N21/K21 -> 0.95803279 | S21: 0.70833333 | T21: 0.75069444 | U21: =IF(S21=TIME(17,0,0),"",(S21-T20)*24*60) | V21: =(T21-S21)*24*60 -> 61 | AA21: =M21-J21 -> -83.934426 | AB21: =M21/J21 -> 0.95803279
A22: 新豐7線 | B22: 微波主食 | C22: 二配泰式綠咖哩雞 | E22: 50.67 | F22: 1558 | G22: =E22*F22 -> 78943.86 | I22: 15 | J22: 2000 | K22: =J22/I22 -> 133.33333 | L22: 15 | M22: =F22/V22*60 -> 1907.7551 | N22: =M22/L22 -> 127.18367 | O22: =L22-I22 -> 0 | P22: =N22-K22 -> -6.1496599 | Q22: =N22/K22 -> 0.95387755 | S22: 0.75555556 | T22: 0.78958333 | U22: =IF(S22=TIME(17,0,0),"",(S22-T21)*24*60) -> 7 | V22: =(T22-S22)*24*60 -> 49 | AA22: =M22-J22 -> -92.244898 | AB22: =M22/J22 -> 0.95387755
A23: 新豐7線 | B23: 平均 | I23: 16.4 | J23: 2000 | K23: =J23/I23 -> 121.95122 | L23: 16.4 | M23: =AVERAGE(M18:M22) -> 1916.3037 | N23: =M23/L23 -> 116.84779 | O23: =L23-I23 -> 0 | P23: =N23-K23 -> -5.1034331 | Q23: =N23/K23 -> 0.95815185 | AA23: =M23-J23 -> -83.696303 | AB23: =M23/J23 -> 0.95815185
A24: 新豐8線 | B24: 三明治 | C24: 紐奧良風味烤雞鮮蔬三明治 | E24: 31.29 | F24: 6664 | G24: =E24*F24 -> 208516.56 | I24: 18 | J24: 2400 | K24: =J24/I24 -> 133.33333 | L24: 18 | M24: =F24/V24*60 -> 2284.8 | N24: =M24/L24 -> 126.93333 | O24: =L24-I24 -> 0 | P24: =N24-K24 -> -6.4 | Q24: =N24/K24 -> 0.952 | R24: =Q30 -> 0.95616442 | S24: 0.083333333 | T24: 0.20486111 | V24: =(T24-S24)*24*60 -> 175 | W24: =T24 -> 0.20486111 | X24: =S25 -> 0.225 | AA24: =M24-J24 -> -115.2 | AB24: =M24/J24 -> 0.952 | AC24: =AB30 -> 0.95616442
A25: 新豐8線 | B25: 三明治 | C25: 陽光地瓜總匯三明治 | E25: 26.18 | F25: 2844 | G25: =E25*F25 -> 74455.92 | I25: 19 | J25: 2400 | K25: =J25/I25 -> 126.31579 | L25: 19 | M25: =F25/V25*60 -> 2305.9459 | N25: =M25/L25 -> 121.36558 | O25: =L25-I25 -> 0 | P25: =N25-K25 -> -4.9502134 | Q25: =N25/K25 -> 0.96081081 | S25: 0.225 | T25: 0.27638889 | U25: =(S25-T24)*24*60 -> 29 | V25: =(T25-S25)*24*60 -> 74 | AA25: =M25-J25 -> -94.054054 | AB25: =M25/J25 -> 0.96081081
A26: 新豐8線 | B26: 三明治 | C26: 好多菜三明治 | E26: 26.2 | F26: 3563 | G26: =E26*F26 -> 93350.6 | I26: 19 | J26: 2400 | K26: =J26/I26 -> 126.31579 | L26: 19 | M26: =F26/V26*60 -> 2298.7097 | N26: =M26/L26 -> 120.98472 | O26: =L26-I26 -> 0 | P26: =N26-K26 -> -5.3310696 | Q26: =N26/K26 -> 0.9577957 | S26: 0.28125 | T26: 0.34583333 | U26: =(S26-T25)*24*60 -> 7 | V26: =(T26-S26)*24*60 -> 93 | AA26: =M26-J26 -> -101.29032 | AB26: =M26/J26 -> 0.9577957
A27: 新豐8線 | B27: 三明治 | C27: 經典總匯三明治 | E27: 26.2 | F27: 3911 | G27: =E27*F27 -> 102468.2 | I27: 20 | J27: 2400 | K27: =J27/I27 -> 120 | L27: 20 | M27: =F27/V27*60 -> 2300.5882 | N27: =M27/L27 -> 115.02941 | O27: =L27-I27 -> 0 | P27: =N27-K27 -> -4.9705882 | Q27: =N27/K27 -> 0.95857843 | S27: 0.34930556 | T27: 0.42013889 | U27: =(S27-T26)*24*60 -> 5 | V27: =(T27-S27)*24*60 -> 102 | AA27: =M27-J27 -> -99.411765 | AB27: =M27/J27 -> 0.95857843
A28: 新豐8線 | B28: 三明治 | C28: 雞蛋沙拉三明治(114年) | E28: 25.99 | F28: 4500 | G28: =E28*F28 -> 116955 | H28: 2 | I28: 15 | J28: 2400 | K28: =J28/I28 -> 160 | L28: 15 | M28: =F28/V28*60 -> 2288.1356 | N28: =M28/L28 -> 152.54237 | O28: =L28-I28 -> 0 | P28: =N28-K28 -> -7.4576271 | Q28: =N28/K28 -> 0.95338983 | S28: 0.42361111 | T28: 0.50555556 | U28: =(S28-T27)*24*60 -> 5 | V28: =(T28-S28)*24*60 -> 118 | W28: =T28 -> 0.50555556 | X28: =S29 -> 0.54444444 | AA28: =M28-J28 -> -111.86441 | AB28: =M28/J28 -> 0.95338983
A29: 新豐8線 | B29: 三明治 | C29: 雞蛋沙拉三明治(114年) | E29: 25.99 | F29: 1298 | G29: =E29*F29 -> 33735.02 | I29: 15 | J29: 2400 | K29: =J29/I29 -> 160 | L29: 15 | M29: =F29/V29*60 -> 2290.5882 | N29: =M29/L29 -> 152.70588 | O29: =L29-I29 -> 0 | P29: =N29-K29 -> -7.2941176 | Q29: =N29/K29 -> 0.95441176 | S29: 0.54444444 | T29: 0.56805556 | U29: =(S29-T28)*24*60 -> 56 | V29: =(T29-S29)*24*60 -> 34 | AA29: =M29-J29 -> -109.41176 | AB29: =M29/J29 -> 0.95441176
A30: 新豐8線 | B30: 平均 | I30: 17.666667 | J30: 2400 | K30: =J30/I30 -> 135.84906 | L30: 17.666667 | M30: =AVERAGE(M24:M29) -> 2294.7946 | N30: =M30/L30 -> 129.89403 | O30: =L30-I30 -> 0 | P30: =N30-K30 -> -5.9550218 | Q30: =N30/K30 -> 0.95616442 | AA30: =M30-J30 -> -105.20539 | AB30: =M30/J30 -> 0.95616442
A31: 新豐9線 | B31: 三明治 | C31: 鮪魚起司溏心蛋三明治 | E31: 26.2 | F31: 5089 | G31: =E31*F31 -> 133331.8 | I31: 18 | J31: 2400 | K31: =J31/I31 -> 133.33333 | L31: 18 | M31: =F31/V31*60 -> 2295.7895 | N31: =M31/L31 -> 127.54386 | O31: =L31-I31 -> 0 | P31: =N31-K31 -> -5.7894737 | Q31: =N31/K31 -> 0.95657895 | R31: =Q36 -> 0.9587061 | S31: 0.083333333 | T31: 0.17569444 | V31: =(T31-S31)*24*60 -> 133 | W31: =T31 -> 0.17569444 | X31: =S32 -> 0.19513889 | AA31: =M31-J31 -> -104.21053 | AB31: =M31/J31 -> 0.95657895 | AC31: =AB36 -> 0.9587061
A32: 新豐9線 | B32: 三明治 | C32: 醬燒烤雞三明治 | E32: 26.39 | F32: 4806 | G32: =E32*F32 -> 126830.34 | I32: 19 | J32: 2400 | K32: =J32/I32 -> 126.31579 | L32: 19 | M32: =F32/V32*60 -> 2288.5714 | N32: =M32/L32 -> 120.45113 | O32: =L32-I32 -> 0 | P32: =N32-K32 -> -5.8646617 | Q32: =N32/K32 -> 0.95357143 | S32: 0.19513889 | T32: 0.28263889 | U32: =(S32-T31)*24*60 -> 28 | V32: =(T32-S32)*24*60 -> 126 | AA32: =M32-J32 -> -111.42857 | AB32: =M32/J32 -> 0.95357143
A33: 新豐9線 | B33: 三明治 | C33: 肉鬆火腿三明治 | E33: 20.52 | F33: 3605 | G33: =E33*F33 -> 73974.6 | I33: 18 | J33: 2400 | K33: =J33/I33 -> 133.33333 | L33: 18 | M33: =F33/V33*60 -> 2301.0638 | N33: =M33/L33 -> 127.83688 | O33: =L33-I33 -> 0 | P33: =N33-K33 -> -5.4964539 | Q33: =N33/K33 -> 0.9587766 | S33: 0.28680556 | T33: 0.35208333 | U33: =(S33-T32)*24*60 -> 6 | V33: =(T33-S33)*24*60 -> 94 | AA33: =M33-J33 -> -98.93617 | AB33: =M33/J33 -> 0.9587766
A34: 新豐9線 | B34: 三明治 | C34: 藍莓優格三明治(114年) | E34: 22.35 | F34: 1517 | G34: =E34*F34 -> 33904.95 | I34: 16 | J34: 2400 | K34: =J34/I34 -> 150 | L34: 16 | M34: =F34/V34*60 -> 2333.8462 | N34: =M34/L34 -> 145.86538 | O34: =L34-I34 -> 0 | P34: =N34-K34 -> -4.1346154 | Q34: =N34/K34 -> 0.9724359 | S34: 0.35625 | T34: 0.38333333 | U34: =(S34-T33)*24*60 -> 6 | V34: =(T34-S34)*24*60 -> 39 | AA34: =M34-J34 -> -66.153846 | AB34: =M34/J34 -> 0.9724359
A35: 新豐9線 | B35: 三明治 | C35: 經典火腿玉米蛋三明治 | E35: 24.43 | F35: 6589 | G35: =E35*F35 -> 160969.27 | I35: 15 | J35: 2400 | K35: =J35/I35 -> 160 | L35: 15 | M35: =F35/V35*60 -> 2285.2023 | N35: =M35/L35 -> 152.34682 | O35: =L35-I35 -> 0 | P35: =N35-K35 -> -7.6531792 | Q35: =N35/K35 -> 0.95216763 | S35: 0.38819444 | T35: 0.50833333 | U35: =(S35-T34)*24*60 -> 7 | V35: =(T35-S35)*24*60 -> 173 | AA35: =M35-J35 -> -114.79769 | AB35: =M35/J35 -> 0.95216763
A36: 新豐9線 | B36: 平均 | I36: 17.2 | J36: 2400 | K36: =J36/I36 -> 139.53488 | L36: 17.2 | M36: =AVERAGE(M31:M35) -> 2300.8946 | N36: =M36/L36 -> 133.77294 | O36: =L36-I36 -> 0 | P36: =N36-K36 -> -5.7619396 | Q36: =N36/K36 -> 0.9587061 | AA36: =M36-J36 -> -99.10536 | AB36: =M36/J36 -> 0.9587061
A37: 新豐3線 | B37: 調理麵包 | C37: 豬肉起司堡 | E37: 21.13 | F37: 3960 | G37: =E37*F37 -> 83674.8 | I37: 10 | J37: 3000 | K37: =J37/I37 -> 300 | L37: 10 | M37: =F37/V37*60 -> 2862.6506 | N37: =M37/L37 -> 286.26506 | O37: =L37-I37 -> 0 | P37: =N37-K37 -> -13.73494 | Q37: =N37/K37 -> 0.95421687 | R37: =Q45 -> 0.96253654 | S37: 0.083333333 | T37: 0.14097222 | V37: =(T37-S37)*24*60 -> 83 | W37: =T37 -> 0.14097222 | X37: =S38 -> 0.15972222 | AA37: =M37-J37 -> -137.3494 | AB37: =M37/J37 -> 0.95421687 | AC37: =AB45 -> 0.96253654
A38: 新豐3線 | B38: 調理麵包 | C38: 豬肉起司蛋堡 | E38: 27.17 | F38: 4940 | G38: =E38*F38 -> 134219.8 | I38: 10 | J38: 3000 | K38: =J38/I38 -> 300 | L38: 10 | M38: =F38/V38*60 -> 2877.6699 | N38: =M38/L38 -> 287.76699 | O38: =L38-I38 -> 0 | P38: =N38-K38 -> -12.23301 | Q38: =N38/K38 -> 0.9592233 | S38: 0.15972222 | T38: 0.23125 | U38: =(S38-T37)*24*60 -> 27 | V38: =(T38-S38)*24*60 -> 103 | AA38: =M38-J38 -> -122.3301 | AB38: =M38/J38 -> 0.9592233
A39: 新豐3線 | B39: 調理麵包 | C39: 經典雙牛起司堡(113年) | E39: 35.12 | F39: 3535 | G39: =E39*F39 -> 124149.2 | I39: 10 | J39: 3000 | K39: =J39/I39 -> 300 | L39: 10 | M39: =F39/V39*60 -> 2866.2162 | N39: =M39/L39 -> 286.62162 | O39: =L39-I39 -> 0 | P39: =N39-K39 -> -13.378378 | Q39: =N39/K39 -> 0.95540541 | S39: 0.23472222 | T39: 0.28611111 | U39: =(S39-T38)*24*60 -> 5 | V39: =(T39-S39)*24*60 -> 74 | AA39: =M39-J39 -> -133.78378 | AB39: =M39/J39 -> 0.95540541
A40: 新豐3線 | B40: 調理麵包 | C40: 美式雞腿堡 | E40: 35.87 | F40: 2318 | G40: =E40*F40 -> 83146.66 | I40: 10 | J40: 3000 | K40: =J40/I40 -> 300 | L40: 10 | M40: =F40/V40*60 -> 2897.5 | N40: =M40/L40 -> 289.75 | O40: =L40-I40 -> 0 | P40: =N40-K40 -> -10.25 | Q40: =N40/K40 -> 0.96583333 | S40: 0.28958333 | T40: 0.32291667 | U40: =(S40-T39)*24*60 -> 5 | V40: =(T40-S40)*24*60 -> 48 | AA40: =M40-J40 -> -102.5 | AB40: =M40/J40 -> 0.96583333
...

Sheet 1030
B1: 屏榮 新豐廠組合室生產人時性分析
B3: 日期 | C3: =TEXT('1030 4度C'!A2,"yyyy.mm.ddaaaa") -> 2025.10.30星期四 | E3: 訂單量 | F3: ='1030 4度C'!D1 -> 184956 | H3: 營業額 | I3: ='1030 4度C'!F1 -> 6088234.8
B4: 人時性 | C4: 項目 | E4: ➀ | G4: ➁ | I4: ➂
C5: 組合室 | E5: 全溫層 | G5: 4度C-各編組展開 | I5: ③三明治-各編組展開
C6: 排關平均 | E6: =AVERAGE(D13:M13) -> 149.1102 | F6: =AVERAGE(D27:O27,D13:J13) -> 153.77372 | G6: =AVERAGE(D13:J13) -> 153.77372 | I6: =AVERAGE(K13:M13) -> 138.22866
C7: 實績平均 | E7: =AVERAGE(D14:M14) -> 142.89567 | F7: =AVERAGE(D28:O28,D14:J14) -> 147.44439 | G7: =AVERAGE(D14:J14) -> 147.44439 | I7: =AVERAGE(K14:M14) -> 132.28199
C8: 達成率平均 | E8: =AVERAGE(D15:M15) -> 0.95795517 | F8: =AVERAGE(D15:J15,D29:O29) -> 0.95838205 | G8: =AVERAGE(D15:J15) -> 0.95838205 | I8: =AVERAGE(K15:M15) -> 0.95695912 | K8: ※現行日本鮮食廠以達成率80%為基本(即為現行KPI)
B10: 溫層 | D10: ➁4度C-各編組展開 | K10: ③三明治-各編組展開
B11: 編組 | D11: 1 | E11: 2 | F11: 3 | G11: 4 | H11: 5 | I11: 6 | J11: 7 | K11: 1 | L11: 2 | M11: 3
D12: 新豐6線 | E12: 新豐2線 | F12: 新豐5線 | G12: 新豐7線 | H12: 新豐3線 | I12: 新豐1線 | J12: 新豐10線 | K12: 新豐8線 | L12: 新豐9線 | M12: 新豐4線
B13: 人時性 | C13: 排關 | D13: =SUMIFS('1030 4度C'!$K:$K,'1030 4度C'!$A:$A,"新豐6線",'1030 4度C'!$B:$B,"平均") -> 125 | E13: =SUMIFS('1030 4度C'!$K:$K,'1030 4度C'!$A:$A,"新豐2線",'1030 4度C'!$B:$B,"平均") -> 81.081081 | F13: =SUMIFS('1030 4度C'!$K:$K,'1030 4度C'!$A:$A,"新豐5線",'1030 4度C'!$B:$B,"平均") -> 91.397849 | G13: =SUMIFS('1030 4度C'!$K:$K,'1030 4度C'!$A:$A,"新豐7線",'1030 4度C'!$B:$B,"平均") -> 121.95122 | H13: =SUMIFS('1030 4度C'!$K:$K,'1030 4度C'!$A:$A,"新豐3線",'1030 4度C'!$B:$B,"平均") -> 269.23077 | I13: =SUMIFS('1030 4度C'!$K:$K,'1030 4度C'!$A:$A,"新豐1線",'1030 4度C'!$B:$B,"平均") -> 112.2449 | J13: =SUMIFS('1030 4度C'!$K:$K,'1030 4度C'!$A:$A,"新豐10線",'1030 4度C'!$B:$B,"平均") -> 275.5102 | K13: =SUMIFS('1030 4度C'!$K:$K,'1030 4度C'!$A:$A,"新豐8線",'1030 4度C'!$B:$B,"平均") -> 133.33333 | L13: =SUMIFS('1030 4度C'!$K:$K,'1030 4度C'!$A:$A,"新豐9線",'1030 4度C'!$B:$B,"平均") -> 139.13043 | M13: =SUMIFS('1030 4度C'!$K:$K,'1030 4度C'!$A:$A,"新豐4線",'1030 4度C'!$B:$B,"平均") -> 142.22222
C14: 實績 | D14: =SUMIFS('1030 4度C'!$N:$N,'1030 4度C'!$A:$A,"新豐6線",'1030 4度C'!$B:$B,"平均") -> 120.30862 | E14: =SUMIFS('1030 4度C'!$N:$N,'1030 4度C'!$A:$A,"新豐2線",'1030 4度C'!$B:$B,"平均") -> 77.598849 | F14: =SUMIFS('1030 4度C'!$N:$N,'1030 4度C'!$A:$A,"新豐5線",'1030 4度C'!$B:$B,"平均") -> 87.417694 | G14: =SUMIFS('1030 4度C'!$N:$N,'1030 4度C'!$A:$A,"新豐7線",'1030 4度C'!$B:$B,"平均") -> 116.56581 | H14: =SUMIFS('1030 4度C'!$N:$N,'1030 4度C'!$A:$A,"新豐3線",'1030 4度C'!$B:$B,"平均") -> 257.98936 | I14: =SUMIFS('1030 4度C'!$N:$N,'1030 4度C'!$A:$A,"新豐1線",'1030 4度C'!$B:$B,"平均") -> 107.50266 | J14: =SUMIFS('1030 4度C'!$N:$N,'1030 4度C'!$A:$A,"新豐10線",'1030 4度C'!$B:$B,"平均") -> 264.72773 | K14: =SUMIFS('1030 4度C'!$N:$N,'1030 4度C'!$A:$A,"新豐8線",'1030 4度C'!$B:$B,"平均") -> 127.42695 | L14: =SUMIFS('1030 4度C'!$N:$N,'1030 4度C'!$A:$A,"新豐9線",'1030 4度C'!$B:$B,"平均") -> 133.26591 | M14: =SUMIFS('1030 4度C'!$N:$N,'1030 4度C'!$A:$A,"新豐4線",'1030 4度C'!$B:$B,"平均") -> 136.1531
C15: 達成率 | D15: =D14/D13 -> 0.96246898 | E15: =E14/E13 -> 0.95705247 | F15: =F14/F13 -> 0.95645241 | G15: =G14/G13 -> 0.95583967 | H15: =H14/H13 -> 0.9582462 | I15: =I14/I13 -> 0.957751 | J15: =J14/J13 -> 0.9608636 | K15: =K14/K13 -> 0.95570213 | ... M15: =M14/M13 -> 0.95732649
B16: 作業 時間 | C16: 開始 | D16: =VLOOKUP("新豐6線",'1030 4度C'!$A:$T,19,0) -> 0.70833333 | E16: =VLOOKUP("新豐2線",'1030 4度C'!$A:$T,19,0) -> 0.20833333 | F16: =VLOOKUP("新豐5線",'1030 4度C'!$A:$T,19,0) -> 0.125 | G16: =VLOOKUP("新豐7線",'1030 4度C'!$A:$T,19,0) -> 0.20833333 | H16: =VLOOKUP("新豐3線",'1030 4度C'!$A:$T,19,0) -> 0.083333333 | I16: =VLOOKUP("新豐1線",'1030 4度C'!$A:$T,19,0) -> 0.20833333 | J16: =VLOOKUP("新豐10線",'1030 4度C'!$A:$T,19,0) -> 0.20833333 | K16: =VLOOKUP("新豐8線",'1030 4度C'!$A:$T,19,0) -> 0.083333333 | L16: =VLOOKUP("新豐9線",'1030 4度C'!$A:$T,19,0) -> 0.083333333 | M16: =VLOOKUP("新豐4線",'1030 4度C'!$A:$T,19,0) -> 0.083333333
C17: 結束 | D17: =LOOKUP(2,1/(('1030 4度C'!$A:$A="新豐6線")*('1030 4度C'!$T:$T<>"")),'1030 4度C'!$T:$T) -> 0.8125 | E17: =LOOKUP(2,1/(('1030 4度C'!$A:$A="新豐2線")*('1030 4度C'!$T:$T<>"")),'1030 4度C'!$T:$T) -> 0.45486111 | F17: =LOOKUP(2,1/(('1030 4度C'!$A:$A="新豐5線")*('1030 4度C'!$T:$T<>"")),'1030 4度C'!$T:$T) -> 0.82847222 | G17: =LOOKUP(2,1/(('1030 4度C'!$A:$A="新豐7線")*('1030 4度C'!$T:$T<>"")),'1030 4度C'!$T:$T) -> 0.83958333 | H17: =LOOKUP(2,1/(('1030 4度C'!$A:$A="新豐3線")*('1030 4度C'!$T:$T<>"")),'1030 4度C'!$T:$T) -> 0.65555556 | I17: =LOOKUP(2,1/(('1030 4度C'!$A:$A="新豐1線")*('1030 4度C'!$T:$T<>"")),'1030 4度C'!$T:$T) -> 0.92986111 | J17: =LOOKUP(2,1/(('1030 4度C'!$A:$A="新豐10線")*('1030 4度C'!$T:$T<>"")),'1030 4度C'!$T:$T) -> 0.51527778 | K17: =LOOKUP(2,1/(('1030 4度C'!$A:$A="新豐8線")*('1030 4度C'!$T:$T<>"")),'1030 4度C'!$T:$T) -> 0.70833333 | L17: =LOOKUP(2,1/(('1030 4度C'!$A:$A="新豐9線")*('1030 4度C'!$T:$T<>"")),'1030 4度C'!$T:$T) -> 0.69027778 | M17: =LOOKUP(2,1/(('1030 4度C'!$A:$A="新豐4線")*('1030 4度C'!$T:$T<>"")),'1030 4度C'!$T:$T) -> 0.67361111
B18: 配置人數 | D18: =SUMIFS('1030 4度C'!$I:$I,'1030 4度C'!$A:$A,"新豐6線",'1030 4度C'!$B:$B,"平均") -> 16 | E18: =SUMIFS('1030 4度C'!$I:$I,'1030 4度C'!$A:$A,"新豐2線",'1030 4度C'!$B:$B,"平均") -> 18.5 | F18: =SUMIFS('1030 4度C'!$I:$I,'1030 4度C'!$A:$A,"新豐5線",'1030 4度C'!$B:$B,"平均") -> 18.6 | G18: =SUMIFS('1030 4度C'!$I:$I,'1030 4度C'!$A:$A,"新豐7線",'1030 4度C'!$B:$B,"平均") -> 16.4 | H18: =SUMIFS('1030 4度C'!$I:$I,'1030 4度C'!$A:$A,"新豐3線",'1030 4度C'!$B:$B,"平均") -> 10.4 | I18: =SUMIFS('1030 4度C'!$I:$I,'1030 4度C'!$A:$A,"新豐1線",'1030 4度C'!$B:$B,"平均") -> 16.333333 | J18: =SUMIFS('1030 4度C'!$I:$I,'1030 4度C'!$A:$A,"新豐10線",'1030 4度C'!$B:$B,"平均") -> 9.8 | K18: =SUMIFS('1030 4度C'!$I:$I,'1030 4度C'!$A:$A,"新豐8線",'1030 4度C'!$B:$B,"平均") -> 18 | L18: =SUMIFS('1030 4度C'!$I:$I,'1030 4度C'!$A:$A,"新豐9線",'1030 4度C'!$B:$B,"平均") -> 17.25 | M18: =SUMIFS('1030 4度C'!$I:$I,'1030 4度C'!$A:$A,"新豐4線",'1030 4度C'!$B:$B,"平均") -> 16.875
B19: 主要應用設備 | D19: ET-55 | E19: 熱縮爐 | F19: L型包裝機 | G19: L型包裝機 | H19: 伺服包裝機 | I19: ET-55 | J19: 伺服包裝機 | K19: 三明治包裝機 | L19: 三明治包裝機 | M19: 三明治包裝機
B20: 次要應用設備 | F20: 圓盤機 | G20: ET-55
B21: 備註 | E21: 握沙拉 | F21: 共用L型包裝機 | H21: 調理麵包 | I21: 炒飯+沙拉 | J21: 調理麵包

Sheet 1030 4度C
A1: 新豐廠四度C日報分析 | C1: 總生產量 | D1: =SUM(F5:F74) -> 184956 | E1: 營業額 | F1: =SUM(G5:G74) -> 6088234.8 | G1: 出勤人數 | H1: =L8+L11+L52+L59+L17+L65+L32+L41+L23+L74 -> 158.15833 | I1: 產線配置圖 | L1: 生產實績 | O1: 人時性差異分析 | S1: 日報登錄 | Y1: 分析說明 | AA1: 產能差異分析
A2: 45960 | B2: 星期四 | C2: 人時性 | D2: =AVERAGE(N8,N11,N52,N59,N17,N65,N23,N32,N41,N74) -> 142.89567 | E2: 平均廠價 | F2: =F1/D1 -> 32.917206 | G2: 多次生產數 | H2: =COUNT(H5:H74) -> 11
A3: 線別 | B3: 品類 | C3: 品名 | E3: 廠價 | F3: 生產量 | G3: 營收 | H3: 多次 生產 | I3: 人數 | J3: 產能/時 | K3: 人時性 | L3: 人數 | M3: 產能/時 | N3: 人時性 | O3: 人數 | P3: 人時性 | Q3: 達成率 | R3: 達成率平均 | S3: 生產時間 | U3: 換線、休息/分 | V3: 稼動時間/分 | W3: 休息時間 | Y3: (新豐回填) | AA3: 產能/時 | AB3: 達成率 | AC3: 達成率平均
S4: 開始 | T4: 結束 | W4: 開始 | X4: 結束
A5: 新豐6線 | B5: 微波主食 | C5: 二配煸椒烘蛋飯 | E5: 46.93 | F5: 838 | G5: =E5*F5 -> 39327.34 | I5: 16 | J5: 2000 | K5: =J5/I5 -> 125 | L5: 16 | M5: =F5/V5*60 -> 1933.8462 | N5: =M5/L5 -> 120.86538 | O5: =L5-I5 -> 0 | P5: =N5-K5 -> -4.1346154 | Q5: =N5/K5 -> 0.96692308 | R5: =Q8 -> 0.96246898 | S5: 0.70833333 | T5: 0.72638889 | V5: =(T5-S5)*24*60 -> 26 | AA5: =M5-J5 -> -66.153846 | AB5: =M5/J5 -> 0.96692308 | AC5: =AB8 -> 0.96246898
A6: 新豐6線 | B6: 微波主食 | C6: 二配川味麻婆燒豆腐燴飯 | E6: 50.49 | F6: 1985 | G6: =E6*F6 -> 100222.65 | I6: 15 | J6: 2000 | K6: =J6/I6 -> 133.33333 | L6: 15 | M6: =F6/V6*60 -> 1920.9677 | N6: =M6/L6 -> 128.06452 | O6: =L6-I6 -> 0 | P6: =N6-K6 -> -5.2688172 | Q6: =N6/K6 -> 0.96048387 | S6: 0.72986111 | T6: 0.77291667 | U6: =IF(S6=TIME(17,0,0),"",(S6-T5)*24*60) -> 5 | V6: =(T6-S6)*24*60 -> 62 | AA6: =M6-J6 -> -79.032258 | AB6: =M6/J6 -> 0.96048387
A7: 新豐6線 | B7: 微波主食 | C7: 二配港式香滑嫩蛋牛肉燴飯 | E7: 50.67 | F7: 1664 | G7: =E7*F7 -> 84314.88 | I7: 17 | J7: 2000 | K7: =J7/I7 -> 117.64706 | L7: 17 | M7: =F7/V7*60 -> 1920 | N7: =M7/L7 -> 112.94118 | O7: =L7-I7 -> 0 | P7: =N7-K7 -> -4.7058824 | Q7: =N7/K7 -> 0.96 | S7: 0.77638889 | T7: 0.8125 | U7: =IF(S7=TIME(17,0,0),"",(S7-T6)*24*60) -> 5 | V7: =(T7-S7)*24*60 -> 52 | AA7: =M7-J7 -> -80 | AB7: =M7/J7 -> 0.96
A8: 新豐6線 | B8: 平均 | I8: 16 | J8: 2000 | K8: =J8/I8 -> 125 | L8: 16 | M8: =AVERAGE(M5:M7) -> 1924.938 | N8: =M8/L8 -> 120.30862 | O8: =L8-I8 -> 0 | P8: =N8-K8 -> -4.6913772 | Q8: =N8/K8 -> 0.96246898 | AA8: =M8-J8 -> -75.062035 | AB8: =M8/J8 -> 0.96246898
A9: 新豐2線 | B9: 沙拉 | C9: 韓式泡菜豆腐握沙拉 | E9: 39.36 | F9: 2115 | G9: =E9*F9 -> 83246.4 | I9: 20 | J9: 1500 | K9: =J9/I9 -> 75 | L9: 20 | M9: =F9/V9*60 -> 1442.0455 | N9: =M9/L9 -> 72.102273 | O9: =L9-I9 -> 0 | P9: =N9-K9 -> -2.8977273 | Q9: =N9/K9 -> 0.96136364 | R9: =Q11 -> 0.95705247 | S9: 0.20833333 | T9: 0.26944444 | V9: =(T9-S9)*24*60 -> 88 | AA9: =M9-J9 -> -57.954545 | AB9: =M9/J9 -> 0.96136364 | AC9: =AB11 -> 0.95705247
A10: 新豐2線 | B10: 沙拉 | C10: 青檸烤雞握沙拉(113年) | E10: 39.8 | F10: 6169 | G10: =E10*F10 -> 245526.2 | I10: 17 | J10: 1500 | K10: =J10/I10 -> 88.235294 | L10: 17 | M10: =F10/V10*60 -> 1429.112 | N10: =M10/L10 -> 84.06541 | O10: =L10-I10 -> 0 | P10: =N10-K10 -> -4.1698842 | Q10: =N10/K10 -> 0.95274131 | S10: 0.275 | T10: 0.45486111 | U10: =IF(S10=TIME(17,0,0),"",(S10-T9)*24*60) -> 8 | V10: =(T10-S10)*24*60 -> 259 | AA10: =M10-J10 -> -70.888031 | AB10: =M10/J10 -> 0.95274131
A11: 新豐2線 | B11: 平均 | I11: 18.5 | J11: 1500 | K11: =J11/I11 -> 81.081081 | L11: 18.5 | M11: =AVERAGE(M9:M10) -> 1435.5787 | N11: =M11/L11 -> 77.598849 | O11: =L11-I11 -> 0 | P11: =N11-K11 -> -3.4822318 | Q11: =N11/K11 -> 0.95705247 | AA11: =M11-J11 -> -64.421288 | AB11: =M11/J11 -> 0.95705247
A12: 新豐5線 | B12: 小吃 | C12: 剝皮辣椒雞湯 | E12: 41 | F12: 2578 | G12: =E12*F12 -> 105698 | I12: 26 | J12: 1500 | K12: =J12/I12 -> 57.692308 | L12: 26 | M12: =F12/V12*60 -> 1432.2222 | N12: =M12/L12 -> 55.08547 | O12: =L12-I12 -> 0 | P12: =N12-K12 -> -2.6068376 | Q12: =N12/K12 -> 0.95481481 | R12: =Q17 -> 0.95645241 | S12: 0.125 | T12: 0.2 | V12: =(T12-S12)*24*60 -> 108 | W12: =T12 -> 0.2 | X12: =S13 -> 0.21944444 | AA12: =M12-J12 -> -67.777778 | AB12: =M12/J12 -> 0.95481481 | AC12: =AB17 -> 0.95645241
A13: 新豐5線 | B13: 沙拉 | C13: 青醬優格雞肉握沙拉(113年) | E13: 39.62 | F13: 4226 | G13: =E13*F13 -> 167434.12 | I13: 19 | J13: 1500 | K13: =J13/I13 -> 78.947368 | L13: 19 | M13: =F13/V13*60 -> 1432.5424 | N13: =M13/L13 -> 75.396967 | O13: =L13-I13 -> 0 | P13: =N13-K13 -> -3.5504014 | Q13: =N13/K13 -> 0.95502825 | S13: 0.21944444 | T13: 0.34236111 | U13: =IF(S13=TIME(17,0,0),"",(S13-T12)*24*60) -> 28 | V13: =(T13-S13)*24*60 -> 177 | AA13: =M13-J13 -> -67.457627 | AB13: =M13/J13 -> 0.95502825
A14: 新豐5線 | B14: 熱食義麵 | C14: 焗烤明太子筆尖麵 | E14: 57.3 | F14: 1649 | G14: =E14*F14 -> 94487.7 | I14: 17 | J14: 1500 | K14: =J14/I14 -> 88.235294 | L14: 17 | M14: =F14/V14*60 -> 1433.913 | N14: =M14/L14 -> 84.347826 | O14: =L14-I14 -> 0 | P14: =N14-K14 -> -3.887468 | Q14: =N14/K14 -> 0.95594203 | S14: 0.34791667 | T14: 0.39583333 | U14: =IF(S14=TIME(17,0,0),"",(S14-T13)*24*60) -> 8 | V14: =(T14-S14)*24*60 -> 69 | AA14: =M14-J14 -> -66.086957 | AB14: =M14/J14 -> 0.95594203
A15: 新豐5線 | B15: 微波主食 | C15: 二配金咖哩濃厚辛辣咖哩飯 | E15: 50.98 | F15: 2610 | G15: =E15*F15 -> 133057.8 | I15: 16 | J15: 2000 | K15: =J15/I15 -> 125 | L15: 16 | M15: =F15/V15*60 -> 1909.7561 | N15: =M15/L15 -> 119.35976 | O15: =L15-I15 -> 0 | P15: =N15-K15 -> -5.6402439 | Q15: =N15/K15 -> 0.95487805 | S15: 0.70833333 | T15: 0.76527778 | U15: =IF(S15=TIME(17,0,0),"",(S15-T14)*24*60) | V15: =(T15-S15)*24*60 -> 82 | AA15: =M15-J15 -> -90.243902 | AB15: =M15/J15 -> 0.95487805
A16: 新豐5線 | B16: 微波主食 | C16: 二配金咖哩果香甘口咖哩飯 | E16: 50.92 | F16: 2722 | G16: =E16*F16 -> 138604.24 | I16: 15 | J16: 2000 | K16: =J16/I16 -> 133.33333 | L16: 15 | M16: =F16/V16*60 -> 1921.4118 | N16: =M16/L16 -> 128.09412 | O16: =L16-I16 -> 0 | P16: =N16-K16 -> -5.2392157 | Q16: =N16/K16 -> 0.96070588 | S16: 0.76944444 | T16: 0.82847222 | U16: =IF(S16=TIME(17,0,0),"",(S16-T15)*24*60) -> 6 | V16: =(T16-S16)*24*60 -> 85 | AA16: =M16-J16 -> -78.588235 | AB16: =M16/J16 -> 0.96070588
A17: 新豐5線 | B17: 平均 | I17: 18.6 | J17: 1700 | K17: =J17/I17 -> 91.397849 | L17: 18.6 | M17: =AVERAGE(M12:M16) -> 1625.9691 | N17: =M17/L17 -> 87.417694 | O17: =L17-I17 -> 0 | P17: =N17-K17 -> -3.9801559 | Q17: =N17/K17 -> 0.95645241 | AA17: =M17-J17 -> -74.0309 | AB17: =M17/J17 -> 0.95645241
A18: 新豐7線 | B18: 小吃 | C18: 古早味炒炊粉 | E18: 43.14 | F18: 1494 | G18: =E18*F18 -> 64451.16 | I18: 17 | J18: 2000 | K18: =J18/I18 -> 117.64706 | L18: 17 | M18: =F18/V18*60 -> 1907.234 | N18: =M18/L18 -> 112.19024 | O18: =L18-I18 -> 0 | P18: =N18-K18 -> -5.456821 | Q18: =N18/K18 -> 0.95361702 | R18: =Q23 -> 0.95583967 | S18: 0.20833333 | T18: 0.24097222 | V18: =(T18-S18)*24*60 -> 47 | AA18: =M18-J18 -> -92.765957 | AB18: =M18/J18 -> 0.95361702 | AC18: =AB23 -> 0.95583967
A19: 新豐7線 | B19: 微波主食 | C19: 極上炙烤親子丼 | E19: 53.68 | F19: 1826 | G19: =E19*F19 -> 98019.68 | I19: 16 | J19: 2000 | K19: =J19/I19 -> 125 | L19: 16 | M19: =F19/V19*60 -> 1922.1053 | N19: =M19/L19 -> 120.13158 | O19: =L19-I19 -> 0 | P19: =N19-K19 -> -4.8684211 | Q19: =N19/K19 -> 0.96105263 | S19: 0.24652778 | T19: 0.28611111 | U19: =IF(S19=TIME(17,0,0),"",(S19-T18)*24*60) -> 8 | V19: =(T19-S19)*24*60 -> 57 | AA19: =M19-J19 -> -77.894737 | AB19: =M19/J19 -> 0.96105263
A20: 新豐7線 | B20: 微波主食 | C20: 鐵板滑蛋炸豬排丼 | E20: 57.73 | F20: 3185 | G20: =E20*F20 -> 183870.05 | I20: 15 | J20: 2000 | K20: =J20/I20 -> 133.33333 | L20: 15 | M20: =F20/V20*60 -> 1911 | N20: =M20/L20 -> 127.4 | O20: =L20-I20 -> 0 | P20: =N20-K20 -> -5.9333333 | Q20: =N20/K20 -> 0.9555 | S20: 0.29097222 | T20: 0.36041667 | U20: =IF(S20=TIME(17,0,0),"",(S20-T19)*24*60) -> 7 | V20: =(T20-S20)*24*60 -> 100 | AA20: =M20-J20 -> -89 | AB20: =M20/J20 -> 0.9555
A21: 新豐7線 | B21: 微波主食 | C21: 二配美味蟹煲 | E21: 54.09 | F21: 2070 | G21: =E21*F21 -> 111966.3 | I21: 19 | J21: 2000 | K21: =J21/I21 -> 105.26316 | L21: 19 | M21: =F21/V21*60 -> 1910.7692 | N21: =M21/L21 -> 100.5668 | O21: =L21-I21 -> 0 | P21: =N21-K21 -> -4.6963563 | Q21: =N21/K21 -> 0.95538462 | S21: 0.70833333 | T21: 0.75347222 | U21: =IF(S21=TIME(17,0,0),"",(S21-T20)*24*60) | V21: =(T21-S21)*24*60 -> 65 | AA21: =M21-J21 -> -89.230769 | AB21: =M21/J21 -> 0.95538462
A22: 新豐7線 | B22: 微波主食 | C22: 二配泰式綠咖哩雞 | E22: 50.67 | F22: 3751 | G22: =E22*F22 -> 190063.17 | I22: 15 | J22: 2000 | K22: =J22/I22 -> 133.33333 | L22: 15 | M22: =F22/V22*60 -> 1907.2881 | N22: =M22/L22 -> 127.15254 | O22: =L22-I22 -> 0 | P22: =N22-K22 -> -6.180791 | Q22: =N22/K22 -> 0.95364407 | S22: 0.75763889 | T22: 0.83958333 | U22: =IF(S22=TIME(17,0,0),"",(S22-T21)*24*60) -> 6 | V22: =(T22-S22)*24*60 -> 118 | AA22: =M22-J22 -> -92.711864 | AB22: =M22/J22 -> 0.95364407
A23: 新豐7線 | B23: 平均 | I23: 16.4 | J23: 2000 | K23: =J23/I23 -> 121.95122 | L23: 16.4 | M23: =AVERAGE(M18:M22) -> 1911.6793 | N23: =M23/L23 -> 116.56581 | O23: =L23-I23 -> 0 | P23: =N23-K23 -> -5.3854064 | Q23: =N23/K23 -> 0.95583967 | AA23: =M23-J23 -> -88.320666 | AB23: =M23/J23 -> 0.95583967
A24: 新豐8線 | B24: 三明治 | C24: 紐奧良風味烤雞鮮蔬三明治 | E24: 31.29 | F24: 6200 | G24: =E24*F24 -> 193998 | H24: 2 | I24: 18 | J24: 2400 | K24: =J24/I24 -> 133.33333 | L24: 18 | M24: =F24/V24*60 -> 2282.2086 | N24: =M24/L24 -> 126.78937 | O24: =L24-I24 -> 0 | P24: =N24-K24 -> -6.5439673 | Q24: =N24/K24 -> 0.95092025 | R24: =Q32 -> 0.95570213 | S24: 0.083333333 | T24: 0.19652778 | V24: =(T24-S24)*24*60 -> 163 | W24: =T24 -> 0.19652778 | X24: =S25 -> 0.21388889 | AA24: =M24-J24 -> -117.79141 | AB24: =M24/J24 -> 0.95092025 | AC24: =AB32 -> 0.95570213
A25: 新豐8線 | B25: 三明治 | C25: 陽光地瓜總匯三明治 | E25: 26.18 | F25: 3593 | G25: =E25*F25 -> 94064.74 | I25: 19 | J25: 2400 | K25: =J25/I25 -> 126.31579 | L25: 19 | M25: =F25/V25*60 -> 2293.4043 | N25: =M25/L25 -> 120.70549 | O25: =L25-I25 -> 0 | P25: =N25-K25 -> -5.6103024 | Q25: =N25/K25 -> 0.95558511 | S25: 0.21388889 | T25: 0.27916667 | U25: =(S25-T24)*24*60 -> 25 | V25: =(T25-S25)*24*60 -> 94 | AA25: =M25-J25 -> -106.59574 | AB25: =M25/J25 -> 0.95558511
A26: 新豐8線 | B26: 三明治 | C26: 好多菜三明治 | E26: 26.2 | F26: 4561 | G26: =E26*F26 -> 119498.2 | I26: 19 | J26: 2400 | K26: =J26/I26 -> 126.31579 | L26: 19 | M26: =F26/V26*60 -> 2299.6639 | N26: =M26/L26 -> 121.03494 | O26: =L26-I26 -> 0 | P26: =N26-K26 -> -5.2808492 | Q26: =N26/K26 -> 0.95819328 | S26: 0.28263889 | T26: 0.36527778 | U26: =(S26-T25)*24*60 -> 5 | V26: =(T26-S26)*24*60 -> 119 | AA26: =M26-J26 -> -100.33613 | AB26: =M26/J26 -> 0.95819328
A27: 新豐8線 | B27: 三明治 | C27: 經典總匯三明治 | E27: 26.2 | F27: 3300 | G27: =E27*F27 -> 86460 | H27: 2 | I27: 20 | J27: 2400 | K27: =J27/I27 -> 120 | L27: 20 | M27: =F27/V27*60 -> 2302.3256 | N27: =M27/L27 -> 115.11628 | O27: =L27-I27 -> 0 | P27: =N27-K27 -> -4.8837209 | Q27: =N27/K27 -> 0.95930233 | S27: 0.36944444 | T27: 0.42916667 | U27: =(S27-T26)*24*60 -> 6 | V27: =(T27-S27)*24*60 -> 86 | AA27: =M27-J27 -> -97.674419 | AB27: =M27/J27 -> 0.95930233
A28: 新豐8線 | B28: 三明治 | C28: 雞蛋沙拉三明治(114年) | E28: 24.83 | F28: 4500 | G28: =E28*F28 -> 111735 | H28: 2 | I28: 15 | J28: 2400 | K28: =J28/I28 -> 160 | L28: 15 | M28: =F28/V28*60 -> 2288.1356 | N28: =M28/L28 -> 152.54237 | O28: =L28-I28 -> 0 | P28: =N28-K28 -> -7.4576271 | Q28: =N28/K28 -> 0.95338983 | S28: 0.43472222 | T28: 0.51666667 | U28: =(S28-T27)*24*60 -> 8 | V28: =(T28-S28)*24*60 -> 118 | W28: =T28 -> 0.51666667 | X28: =S29 -> 0.55486111 | AA28: =M28-J28 -> -111.86441 | AB28: =M28/J28 -> 0.95338983
A29: 新豐8線 | B29: 三明治 | C29: 雞蛋沙拉三明治(114年) | E29: 24.83 | F29: 3249 | G29: =E29*F29 -> 80672.67 | I29: 15 | J29: 2400 | K29: =J29/I29 -> 160 | L29: 15 | M29: =F29/V29*60 -> 2293.4118 | N29: =M29/L29 -> 152.89412 | O29: =L29-I29 -> 0 | P29: =N29-K29 -> -7.1058824 | Q29: =N29/K29 -> 0.95558824 | S29: 0.55486111 | T29: 0.61388889 | U29: =(S29-T28)*24*60 -> 55 | V29: =(T29-S29)*24*60 -> 85 | AA29: =M29-J29 -> -106.58824 | AB29: =M29/J29 -> 0.95558824
A30: 新豐8線 | B30: 三明治 | C30: 紐奧良風味烤雞鮮蔬三明治 | E30: 31.29 | F30: 3010 | G30: =E30*F30 -> 94182.9 | I30: 18 | J30: 2400 | K30: =J30/I30 -> 133.33333 | L30: 18 | M30: =F30/V30*60 -> 2286.0759 | N30: =M30/L30 -> 127.00422 | O30: =L30-I30 -> 0 | P30: =N30-K30 -> -6.3291139 | Q30: =N30/K30 -> 0.95253165 | S30: 0.61736111 | T30: 0.67222222 | U30: =(S30-T29)*24*60 -> 5 | V30: =(T30-S30)*24*60 -> 79 | AA30: =M30-J30 -> -113.92405 | AB30: =M30/J30 -> 0.95253165
A31: 新豐8線 | B31: 三明治 | C31: 經典總匯三明治 | E31: 26.2 | F31: 1805 | G31: =E31*F31 -> 47291 | I31: 20 | J31: 2400 | K31: =J31/I31 -> 120 | L31: 20 | M31: =F31/V31*60 -> 2304.2553 | N31: =M31/L31 -> 115.21277 | O31: =L31-I31 -> 0 | P31: =N31-K31 -> -4.787234 | Q31: =N31/K31 -> 0.96010638 | S31: 0.67569444 | T31: 0.70833333 | U31: =(S31-T30)*24*60 -> 5 | V31: =(T31-S31)*24*60 -> 47 | AA31: =M31-J31 -> -95.744681 | AB31: =M31/J31 -> 0.96010638
A32: 新豐8線 | B32: 平均 | I32: 18 | J32: 2400 | K32: =J32/I32 -> 133.33333 | L32: 18 | M32: =AVERAGE(M24:M31) -> 2293.6851 | N32: =M32/L32 -> 127.42695 | O32: =L32-I32 -> 0 | P32: =N32-K32 -> -5.9063825 | Q32: =N32/K32 -> 0.95570213 | AA32: =M32-J32 -> -106.31489 | AB32: =M32/J32 -> 0.95570213
A33: 新豐9線 | B33: 三明治 | C33: 鮪魚起司溏心蛋三明治 | E33: 26.2 | F33: 5000 | G33: =E33*F33 -> 131000 | H33: 2 | I33: 18 | J33: 2400 | K33: =J33/I33 -> 133.33333 | L33: 18 | M33: =F33/V33*60 -> 2290.0763 | N33: =M33/L33 -> 127.22646 | O33: =L33-I33 -> 0 | P33: =N33-K33 -> -6.1068702 | Q33: =N33/K33 -> 0.95419847 | R33: =Q41 -> 0.95784873 | S33: 0.083333333 | T33: 0.17430556 | V33: =(T33-S33)*24*60 -> 131 | W33: =T33 -> 0.17430556 | X33: =S34 -> 0.19305556 | AA33: =M33-J33 -> -109.92366 | AB33: =M33/J33 -> 0.95419847 | AC33: =AB41 -> 0.95784873
A34: 新豐9線 | B34: 三明治 | C34: 醬燒烤雞三明治 | E34: 26.39 | F34: 4500 | G34: =E34*F34 -> 118755 | H34: 2 | I34: 19 | J34: 2400 | K34: =J34/I34 -> 126.31579 | L34: 19 | M34: =F34/V34*60 -> 2288.1356 | N34: =M34/L34 -> 120.42819 | O34: =L34-I34 -> 0 | P34: =N34-K34 -> -5.8876004 | Q34: =N34/K34 -> 0.95338983 | S34: 0.19305556 | T34: 0.275 | U34: =(S34-T33)*24*60 -> 27 | V34: =(T34-S34)*24*60 -> 118 | AA34: =M34-J34 -> -111.86441 | AB34: =M34/J34 -> 0.95338983
A35: 新豐9線 | B35: 三明治 | C35: 肉鬆火腿三明治 | E35: 20.52 | F35: 4930 | G35: =E35*F35 -> 101163.6 | I35: 18 | J35: 2400 | K35: =J35/I35 -> 133.33333 | L35: 18 | M35: =F35/V35*60 -> 2293.0233 | N35: =M35/L35 -> 127.39018 | O35: =L35-I35 -> 0 | P35: =N35-K35 -> -5.9431525 | Q35: =N35/K35 -> 0.95542636 | S35: 0.27986111 | T35: 0.36944444 | U35: =(S35-T34)*24*60 -> 7 | V35: =(T35-S35)*24*60 -> 129 | AA35: =M35-J35 -> -106.97674 | AB35: =M35/J35 -> 0.95542636
A36: 新豐9線 | B36: 三明治 | C36: 藍莓優格三明治(114年) | E36: 22.35 | F36: 2003 | G36: =E36*F36 -> 44767.05 | I36: 16 | J36: 2400 | K36: =J36/I36 -> 150 | L36: 16 | M36: =F36/V36*60 -> 2311.1538 | N36: =M36/L36 -> 144.44712 | O36: =L36-I36 -> 0 | P36: =N36-K36 -> -5.5528846 | Q36: =N36/K36 -> 0.96298077 | S36: 0.375 | T36: 0.41111111 | U36: =(S36-T35)*24*60 -> 8 | V36: =(T36-S36)*24*60 -> 52 | AA36: =M36-J36 -> -88.846154 | AB36: =M36/J36 -> 0.96298077
A37: 新豐9線 | B37: 三明治 | C37: 經典火腿玉米蛋三明治 | E37: 24.43 | F37: 4000 | G37: =E37*F37 -> 97720 | H37: 2 | I37: 15 | J37: 2400 | K37: =J37/I37 -> 160 | L37: 15 | M37: =F37/V37*60 -> 2285.7143 | N37: =M37/L37 -> 152.38095 | O37: =L37-I37 -> 0 | P37: =N37-K37 -> -7.6190476 | Q37: =N37/K37 -> 0.95238095 | S37: 0.41666667 | T37: 0.48958333 | U37: =(S37-T36)*24*60 -> 8 | V37: =(T37-S37)*24*60 -> 105 | W37: =T37 -> 0.48958333 | X37: =S38 -> 0.53055556 | AA37: =M37-J37 -> -114.28571 | AB37: =M37/J37 -> 0.95238095
A38: 新豐9線 | B38: 三明治 | C38: 經典火腿玉米蛋三明治 | E38: 24.43 | F38: 4475 | G38: =E38*F38 -> 109324.25 | I38: 15 | J38: 2400 | K38: =J38/I38 -> 160 | L38: 15 | M38: =F38/V38*60 -> 2294.8718 | N38: =M38/L38 -> 152.99145 | O38: =L38-I38 -> 0 | P38: =N38-K38 -> -7.008547 | Q38: =N38/K38 -> 0.95619658 | S38: 0.53055556 | T38: 0.61180556 | U38: =(S38-T37)*24*60 -> 59 | V38: =(T38-S38)*24*60 -> 117 | AA38: =M38-J38 -> -105.12821 | AB38: =M38/J38 -> 0.95619658
A39: 新豐9線 | B39: 三明治 | C39: 鮪魚起司溏心蛋三明治 | E39: 26.2 | F39: 1849 | G39: =E39*F39 -> 48443.8 | I39: 18 | J39: 2400 | K39: =J39/I39 -> 133.33333 | L39: 18 | M39: =F39/V39*60 -> 2311.25 | N39: =M39/L39 -> 128.40278 | O39: =L39-I39 -> 0 | P39: =N39-K39 -> -4.9305556 | Q39: =N39/K39 -> 0.96302083 | S39: 0.61736111 | T39: 0.65069444 | U39: =(S39-T38)*24*60 -> 8 | V39: =(T39-S39)*24*60 -> 48 | AA39: =M39-J39 -> -88.75 | AB39: =M39/J39 -> 0.96302083
A40: 新豐9線 | B40: 三明治 | C40: 醬燒烤雞三明治 | E40: 26.39 | F40: 1969 | G40: =E40*F40 -> 51961.91 | I40: 19 | J40: 2400 | K40: =J40/I40 -> 126.31579 | L40: 19 | M40: =F40/V40*60 -> 2316.4706 | N40: =M40/L40 -> 121.9195 | O40: =L40-I40 -> 0 | P40: =N40-K40 -> -4.3962848 | Q40: =N40/K40 -> 0.96519608 | S40: 0.65486111 | T40: 0.69027778 | U40: =(S40-T39)*24*60 -> 6 | V40: =(T40-S40)*24*60 -> 51 | AA40: =M40-J40 -> -83.529412 | AB40: =M40/J40 -> 0.96519608
...

Sheet 1029
B1: 屏榮 新豐廠組合室生產人時性分析
B3: 日期 | C3: =TEXT('1029 4度C'!A2,"yyyy.mm.ddaaaa") -> 2025.10.29星期三 | E3: 訂單量 | F3: ='1029 4度C'!D1 -> 200992 | H3: 營業額 | I3: ='1029 4度C'!F1 -> 6670578.6
B4: 人時性 | C4: 項目 | E4: ➀ | G4: ➁ | I4: ➂
C5: 組合室 | E5: 全溫層 | G5: 4度C-各編組展開 | I5: ③三明治-各編組展開
C6: 排關平均 | E6: =AVERAGE(D13:M13) -> 149.56696 | F6: =AVERAGE(D27:O27,D13:J13) -> 154.61814 | G6: =AVERAGE(D13:J13) -> 154.61814 | I6: =AVERAGE(K13:M13) -> 137.78088
C7: 實績平均 | E7: =AVERAGE(D14:M14) -> 143.27931 | F7: =AVERAGE(D28:O28,D14:J14) -> 148.21817 | G7: =AVERAGE(D14:J14) -> 148.21817 | I7: =AVERAGE(K14:M14) -> 131.7553
C8: 達成率平均 | E8: =AVERAGE(D15:M15) -> 0.95760069 | F8: =AVERAGE(D15:J15,D29:O29) -> 0.95817409 | G8: =AVERAGE(D15:J15) -> 0.95817409 | I8: =AVERAGE(K15:M15) -> 0.95626277 | K8: ※現行日本鮮食廠以達成率80%為基本(即為現行KPI)
B10: 溫層 | D10: ➁4度C-各編組展開 | K10: ③三明治-各編組展開
B11: 編組 | D11: 1 | E11: 2 | F11: 3 | G11: 4 | H11: 5 | I11: 6 | J11: 7 | K11: 1 | L11: 2 | M11: 3
D12: 新豐6線 | E12: 新豐2線 | F12: 新豐5線 | G12: 新豐7線 | H12: 新豐3線 | I12: 新豐1線 | J12: 新豐10線 | K12: 新豐8線 | L12: 新豐9線 | M12: 新豐4線
B13: 人時性 | C13: 排關 | D13: =SUMIFS('1029 4度C'!$K:$K,'1029 4度C'!$A:$A,"新豐6線",'1029 4度C'!$B:$B,"平均") -> 125 | E13: =SUMIFS('1029 4度C'!$K:$K,'1029 4度C'!$A:$A,"新豐2線",'1029 4度C'!$B:$B,"平均") -> 81.081081 | F13: =SUMIFS('1029 4度C'!$K:$K,'1029 4度C'!$A:$A,"新豐5線",'1029 4度C'!$B:$B,"平均") -> 91.397849 | G13: =SUMIFS('1029 4度C'!$K:$K,'1029 4度C'!$A:$A,"新豐7線",'1029 4度C'!$B:$B,"平均") -> 123.71134 | H13: =SUMIFS('1029 4度C'!$K:$K,'1029 4度C'!$A:$A,"新豐3線",'1029 4度C'!$B:$B,"平均") -> 269.23077 | I13: =SUMIFS('1029 4度C'!$K:$K,'1029 4度C'!$A:$A,"新豐1線",'1029 4度C'!$B:$B,"平均") -> 112.2449 | J13: =SUMIFS('1029 4度C'!$K:$K,'1029 4度C'!$A:$A,"新豐10線",'1029 4度C'!$B:$B,"平均") -> 279.66102 | K13: =SUMIFS('1029 4度C'!$K:$K,'1029 4度C'!$A:$A,"新豐8線",'1029 4度C'!$B:$B,"平均") -> 135.48387 | L13: =SUMIFS('1029 4度C'!$K:$K,'1029 4度C'!$A:$A,"新豐9線",'1029 4度C'!$B:$B,"平均") -> 139.13043 | M13: =SUMIFS('1029 4度C'!$K:$K,'1029 4度C'!$A:$A,"新豐4線",'1029 4度C'!$B:$B,"平均") -> 138.72832
C14: 實績 | D14: =SUMIFS('1029 4度C'!$N:$N,'1029 4度C'!$A:$A,"新豐6線",'1029 4度C'!$B:$B,"平均") -> 119.95148 | E14: =SUMIFS('1029 4度C'!$N:$N,'1029 4度C'!$A:$A,"新豐2線",'1029 4度C'!$B:$B,"平均") -> 77.523442 | F14: =SUMIFS('1029 4度C'!$N:$N,'1029 4度C'!$A:$A,"新豐5線",'1029 4度C'!$B:$B,"平均") -> 87.346881 | G14: =SUMIFS('1029 4度C'!$N:$N,'1029 4度C'!$A:$A,"新豐7線",'1029 4度C'!$B:$B,"平均") -> 118.85256 | H14: =SUMIFS('1029 4度C'!$N:$N,'1029 4度C'!$A:$A,"新豐3線",'1029 4度C'!$B:$B,"平均") -> 257.87056 | I14: =SUMIFS('1029 4度C'!$N:$N,'1029 4度C'!$A:$A,"新豐1線",'1029 4度C'!$B:$B,"平均") -> 107.4104 | J14: =SUMIFS('1029 4度C'!$N:$N,'1029 4度C'!$A:$A,"新豐10線",'1029 4度C'!$B:$B,"平均") -> 268.57187 | K14: =SUMIFS('1029 4度C'!$N:$N,'1029 4度C'!$A:$A,"新豐8線",'1029 4度C'!$B:$B,"平均") -> 129.47626 | L14: =SUMIFS('1029 4度C'!$N:$N,'1029 4度C'!$A:$A,"新豐9線",'1029 4度C'!$B:$B,"平均") -> 132.96707 | M14: =SUMIFS('1029 4度C'!$N:$N,'1029 4度C'!$A:$A,"新豐4線",'1029 4度C'!$B:$B,"平均") -> 132.82258
C15: 達成率 | D15: =D14/D13 -> 0.95961187 | E15: =E14/E13 -> 0.95612245 | F15: =F14/F13 -> 0.95567764 | G15: =G14/G13 -> 0.96072483 | H15: =H14/H13 -> 0.95780493 | I15: =I14/I13 -> 0.95692901 | J15: =J14/J13 -> 0.9603479 | K15: =K14/K13 -> 0.95565807 | ... M15: =M14/M13 -> 0.95742941
B16: 作業 時間 | C16: 開始 | D16: =VLOOKUP("新豐6線",'1029 4度C'!$A:$T,19,0) -> 0.70833333 | E16: =VLOOKUP("新豐2線",'1029 4度C'!$A:$T,19,0) -> 0.20833333 | F16: =VLOOKUP("新豐5線",'1029 4度C'!$A:$T,19,0) -> 0.125 | G16: =VLOOKUP("新豐7線",'1029 4度C'!$A:$T,19,0) -> 0.20833333 | H16: =VLOOKUP("新豐3線",'1029 4度C'!$A:$T,19,0) -> 0.083333333 | I16: =VLOOKUP("新豐1線",'1029 4度C'!$A:$T,19,0) -> 0.20833333 | J16: =VLOOKUP("新豐10線",'1029 4度C'!$A:$T,19,0) -> 0.20833333 | K16: =VLOOKUP("新豐8線",'1029 4度C'!$A:$T,19,0) -> 0.083333333 | L16: =VLOOKUP("新豐9線",'1029 4度C'!$A:$T,19,0) -> 0.083333333 | M16: =VLOOKUP("新豐4線",'1029 4度C'!$A:$T,19,0) -> 0.083333333
C17: 結束 | D17: =LOOKUP(2,1/(('1029 4度C'!$A:$A="新豐6線")*('1029 4度C'!$T:$T<>"")),'1029 4度C'!$T:$T) -> 0.83194444 | E17: =LOOKUP(2,1/(('1029 4度C'!$A:$A="新豐2線")*('1029 4度C'!$T:$T<>"")),'1029 4度C'!$T:$T) -> 0.48125 | F17: =LOOKUP(2,1/(('1029 4度C'!$A:$A="新豐5線")*('1029 4度C'!$T:$T<>"")),'1029 4度C'!$T:$T) -> 0.84166667 | G17: =LOOKUP(2,1/(('1029 4度C'!$A:$A="新豐7線")*('1029 4度C'!$T:$T<>"")),'1029 4度C'!$T:$T) -> 0.91388889 | H17: =LOOKUP(2,1/(('1029 4度C'!$A:$A="新豐3線")*('1029 4度C'!$T:$T<>"")),'1029 4度C'!$T:$T) -> 0.67847222 | I17: =LOOKUP(2,1/(('1029 4度C'!$A:$A="新豐1線")*('1029 4度C'!$T:$T<>"")),'1029 4度C'!$T:$T) -> 0.99097222 | J17: =LOOKUP(2,1/(('1029 4度C'!$A:$A="新豐10線")*('1029 4度C'!$T:$T<>"")),'1029 4度C'!$T:$T) -> 0.57638889 | K17: =LOOKUP(2,1/(('1029 4度C'!$A:$A="新豐8線")*('1029 4度C'!$T:$T<>"")),'1029 4度C'!$T:$T) -> 0.70486111 | L17: =LOOKUP(2,1/(('1029 4度C'!$A:$A="新豐9線")*('1029 4度C'!$T:$T<>"")),'1029 4度C'!$T:$T) -> 0.73888889 | M17: =LOOKUP(2,1/(('1029 4度C'!$A:$A="新豐4線")*('1029 4度C'!$T:$T<>"")),'1029 4度C'!$T:$T) -> 0.73819444
B18: 配置人數 | D18: =SUMIFS('1029 4度C'!$I:$I,'1029 4度C'!$A:$A,"新豐6線",'1029 4度C'!$B:$B,"平均") -> 16 | E18: =SUMIFS('1029 4度C'!$I:$I,'1029 4度C'!$A:$A,"新豐2線",'1029 4度C'!$B:$B,"平均") -> 18.5 | F18: =SUMIFS('1029 4度C'!$I:$I,'1029 4度C'!$A:$A,"新豐5線",'1029 4度C'!$B:$B,"平均") -> 18.6 | G18: =SUMIFS('1029 4度C'!$I:$I,'1029 4度C'!$A:$A,"新豐7線",'1029 4度C'!$B:$B,"平均") -> 16.166667 | H18: =SUMIFS('1029 4度C'!$I:$I,'1029 4度C'!$A:$A,"新豐3線",'1029 4度C'!$B:$B,"平均") -> 10.4 | I18: =SUMIFS('1029 4度C'!$I:$I,'1029 4度C'!$A:$A,"新豐1線",'1029 4度C'!$B:$B,"平均") -> 16.333333 | J18: =SUMIFS('1029 4度C'!$I:$I,'1029 4度C'!$A:$A,"新豐10線",'1029 4度C'!$B:$B,"平均") -> 9.8333333 | K18: =SUMIFS('1029 4度C'!$I:$I,'1029 4度C'!$A:$A,"新豐8線",'1029 4度C'!$B:$B,"平均") -> 17.714286 | L18: =SUMIFS('1029 4度C'!$I:$I,'1029 4度C'!$A:$A,"新豐9線",'1029 4度C'!$B:$B,"平均") -> 17.25 | M18: =SUMIFS('1029 4度C'!$I:$I,'1029 4度C'!$A:$A,"新豐4線",'1029 4度C'!$B:$B,"平均") -> 17.3
B19: 主要應用設備 | D19: ET-55 | E19: 熱縮爐 | F19: L型包裝機 | G19: L型包裝機 | H19: 伺服包裝機 | I19: ET-55 | J19: 伺服包裝機 | K19: 三明治包裝機 | L19: 三明治包裝機 | M19: 三明治包裝機
B20: 次要應用設備 | F20: 圓盤機 | G20: ET-55
B21: 備註 | E21: 握沙拉 | F21: 共用L型包裝機 | H21: 調理麵包 | I21: 炒飯+沙拉 | J21: 調理麵包

Sheet 1029 4度C
A1: 新豐廠四度C日報分析 | C1: 總生產量 | D1: =SUM(F5:F77) -> 200992 | E1: 營業額 | F1: =SUM(G5:G77) -> 6670578.6 | G1: 出勤人數 | H1: =L8+L11+L52+L59+L17+L66+L32+L41+L24+L77 -> 158.09762 | I1: 產線配置圖 | L1: 生產實績 | O1: 人時性差異分析 | S1: 日報登錄 | Y1: 分析說明 | AA1: 產能差異分析
A2: 45959 | B2: 星期三 | C2: 人時性 | D2: =AVERAGE(N8,N11,N52,N59,N17,N66,N24,N32,N41,N77) -> 143.27931 | E2: 平均廠價 | F2: =F1/D1 -> 33.188279 | G2: 多次生產數 | H2: =COUNT(H5:H77) -> 14
A3: 線別 | B3: 品類 | C3: 品名 | E3: 廠價 | F3: 生產量 | G3: 營收 | H3: 多次 生產 | I3: 人數 | J3: 產能/時 | K3: 人時性 | L3: 人數 | M3: 產能/時 | N3: 人時性 | O3: 人數 | P3: 人時性 | Q3: 達成率 | R3: 達成率平均 | S3: 生產時間 | U3: 換線、休息/分 | V3: 稼動時間/分 | W3: 休息時間 | Y3: (新豐回填) | AA3: 產能/時 | AB3: 達成率 | AC3: 達成率平均
S4: 開始 | T4: 結束 | W4: 開始 | X4: 結束
A5: 新豐6線 | B5: 微波主食 | C5: 二配煸椒烘蛋飯 | E5: 46.93 | F5: 1032 | G5: =E5*F5 -> 48431.76 | I5: 16 | J5: 2000 | K5: =J5/I5 -> 125 | L5: 16 | M5: =F5/V5*60 -> 1935 | N5: =M5/L5 -> 120.9375 | O5: =L5-I5 -> 0 | P5: =N5-K5 -> -4.0625 | Q5: =N5/K5 -> 0.9675 | R5: =Q8 -> 0.95961187 | S5: 0.70833333 | T5: 0.73055556 | V5: =(T5-S5)*24*60 -> 32 | AA5: =M5-J5 -> -65 | AB5: =M5/J5 -> 0.9675 | AC5: =AB8 -> 0.95961187
A6: 新豐6線 | B6: 微波主食 | C6: 二配川味麻婆燒豆腐燴飯 | E6: 50.49 | F6: 2321 | G6: =E6*F6 -> 117187.29 | I6: 15 | J6: 2000 | K6: =J6/I6 -> 133.33333 | L6: 15 | M6: =F6/V6*60 -> 1907.6712 | N6: =M6/L6 -> 127.17808 | O6: =L6-I6 -> 0 | P6: =N6-K6 -> -6.1552511 | Q6: =N6/K6 -> 0.95383562 | S6: 0.73541667 | T6: 0.78611111 | U6: =IF(S6=TIME(17,0,0),"",(S6-T5)*24*60) -> 7 | V6: =(T6-S6)*24*60 -> 73 | AA6: =M6-J6 -> -92.328767 | AB6: =M6/J6 -> 0.95383562
A7: 新豐6線 | B7: 微波主食 | C7: 二配港式香滑嫩蛋牛肉燴飯 | E7: 50.67 | F7: 1915 | G7: =E7*F7 -> 97033.05 | I7: 17 | J7: 2000 | K7: =J7/I7 -> 117.64706 | L7: 17 | M7: =F7/V7*60 -> 1915 | N7: =M7/L7 -> 112.64706 | O7: =L7-I7 -> 0 | P7: =N7-K7 -> -5 | Q7: =N7/K7 -> 0.9575 | S7: 0.79027778 | T7: 0.83194444 | U7: =IF(S7=TIME(17,0,0),"",(S7-T6)*24*60) -> 6 | V7: =(T7-S7)*24*60 -> 60 | AA7: =M7-J7 -> -85 | AB7: =M7/J7 -> 0.9575
A8: 新豐6線 | B8: 平均 | I8: 16 | J8: 2000 | K8: =J8/I8 -> 125 | L8: 16 | M8: =AVERAGE(M5:M7) -> 1919.2237 | N8: =M8/L8 -> 119.95148 | O8: =L8-I8 -> 0 | P8: =N8-K8 -> -5.048516 | Q8: =N8/K8 -> 0.95961187 | AA8: =M8-J8 -> -80.776256 | AB8: =M8/J8 -> 0.95961187
A9: 新豐2線 | B9: 沙拉 | C9: 韓式泡菜豆腐握沙拉 | E9: 39.36 | F9: 2347 | G9: =E9*F9 -> 92377.92 | I9: 20 | J9: 1500 | K9: =J9/I9 -> 75 | L9: 20 | M9: =F9/V9*60 -> 1436.9388 | N9: =M9/L9 -> 71.846939 | O9: =L9-I9 -> 0 | P9: =N9-K9 -> -3.1530612 | Q9: =N9/K9 -> 0.95795918 | R9: =Q11 -> 0.95612245 | S9: 0.20833333 | T9: 0.27638889 | V9: =(T9-S9)*24*60 -> 98 | AA9: =M9-J9 -> -63.061224 | AB9: =M9/J9 -> 0.95795918 | AC9: =AB11 -> 0.95612245
A10: 新豐2線 | B10: 沙拉 | C10: 青檸烤雞握沙拉(113年) | E10: 39.8 | F10: 6847 | G10: =E10*F10 -> 272510.6 | I10: 17 | J10: 1500 | K10: =J10/I10 -> 88.235294 | L10: 17 | M10: =F10/V10*60 -> 1431.4286 | N10: =M10/L10 -> 84.201681 | O10: =L10-I10 -> 0 | P10: =N10-K10 -> -4.0336134 | Q10: =N10/K10 -> 0.95428571 | S10: 0.28194444 | T10: 0.48125 | U10: =IF(S10=TIME(17,0,0),"",(S10-T9)*24*60) -> 8 | V10: =(T10-S10)*24*60 -> 287 | AA10: =M10-J10 -> -68.571429 | AB10: =M10/J10 -> 0.95428571
A11: 新豐2線 | B11: 平均 | I11: 18.5 | J11: 1500 | K11: =J11/I11 -> 81.081081 | L11: 18.5 | M11: =AVERAGE(M9:M10) -> 1434.1837 | N11: =M11/L11 -> 77.523442 | O11: =L11-I11 -> 0 | P11: =N11-K11 -> -3.5576393 | Q11: =N11/K11 -> 0.95612245 | AA11: =M11-J11 -> -65.816327 | AB11: =M11/J11 -> 0.95612245
A12: 新豐5線 | B12: 小吃 | C12: 剝皮辣椒雞湯 | E12: 41 | F12: 2707 | G12: =E12*F12 -> 110987 | I12: 26 | J12: 1500 | K12: =J12/I12 -> 57.692308 | L12: 26 | M12: =F12/V12*60 -> 1437.3451 | N12: =M12/L12 -> 55.282505 | O12: =L12-I12 -> 0 | P12: =N12-K12 -> -2.4098026 | Q12: =N12/K12 -> 0.95823009 | R12: =Q17 -> 0.95567764 | S12: 0.125 | T12: 0.20347222 | V12: =(T12-S12)*24*60 -> 113 | W12: =T12 -> 0.20347222 | X12: =S13 -> 0.22430556 | AA12: =M12-J12 -> -62.654867 | AB12: =M12/J12 -> 0.95823009 | AC12: =AB17 -> 0.95567764
A13: 新豐5線 | B13: 沙拉 | C13: 青醬優格雞肉握沙拉(113年) | E13: 39.62 | F13: 4624 | G13: =E13*F13 -> 183202.88 | I13: 19 | J13: 1500 | K13: =J13/I13 -> 78.947368 | L13: 19 | M13: =F13/V13*60 -> 1430.1031 | N13: =M13/L13 -> 75.268584 | O13: =L13-I13 -> 0 | P13: =N13-K13 -> -3.6787846 | Q13: =N13/K13 -> 0.95340206 | S13: 0.22430556 | T13: 0.35902778 | U13: =IF(S13=TIME(17,0,0),"",(S13-T12)*24*60) -> 30 | V13: =(T13-S13)*24*60 -> 194 | AA13: =M13-J13 -> -69.896907 | AB13: =M13/J13 -> 0.95340206
A14: 新豐5線 | B14: 熱食義麵 | C14: 焗烤明太子筆尖麵 | E14: 57.3 | F14: 1381 | G14: =E14*F14 -> 79131.3 | I14: 17 | J14: 1500 | K14: =J14/I14 -> 88.235294 | L14: 17 | M14: =F14/V14*60 -> 1428.6207 | N14: =M14/L14 -> 84.036511 | O14: =L14-I14 -> 0 | P14: =N14-K14 -> -4.198783 | Q14: =N14/K14 -> 0.95241379 | S14: 0.36319444 | T14: 0.40347222 | U14: =IF(S14=TIME(17,0,0),"",(S14-T13)*24*60) -> 6 | V14: =(T14-S14)*24*60 -> 58 | AA14: =M14-J14 -> -71.37931 | AB14: =M14/J14 -> 0.95241379
A15: 新豐5線 | B15: 微波主食 | C15: 二配金咖哩濃厚辛辣咖哩飯 | E15: 50.98 | F15: 2829 | G15: =E15*F15 -> 144222.42 | I15: 16 | J15: 2000 | K15: =J15/I15 -> 125 | L15: 16 | M15: =F15/V15*60 -> 1907.191 | N15: =M15/L15 -> 119.19944 | O15: =L15-I15 -> 0 | P15: =N15-K15 -> -5.8005618 | Q15: =N15/K15 -> 0.95359551 | S15: 0.70833333 | T15: 0.77013889 | U15: =IF(S15=TIME(17,0,0),"",(S15-T14)*24*60) | V15: =(T15-S15)*24*60 -> 89 | AA15: =M15-J15 -> -92.808989 | AB15: =M15/J15 -> 0.95359551
A16: 新豐5線 | B16: 微波主食 | C16: 二配金咖哩果香甘口咖哩飯 | E16: 50.92 | F16: 3040 | G16: =E16*F16 -> 154796.8 | I16: 15 | J16: 2000 | K16: =J16/I16 -> 133.33333 | L16: 15 | M16: =F16/V16*60 -> 1920 | N16: =M16/L16 -> 128 | O16: =L16-I16 -> 0 | P16: =N16-K16 -> -5.3333333 | Q16: =N16/K16 -> 0.96 | S16: 0.77569444 | T16: 0.84166667 | U16: =IF(S16=TIME(17,0,0),"",(S16-T15)*24*60) -> 8 | V16: =(T16-S16)*24*60 -> 95 | AA16: =M16-J16 -> -80 | AB16: =M16/J16 -> 0.96
A17: 新豐5線 | B17: 平均 | I17: 18.6 | J17: 1700 | K17: =J17/I17 -> 91.397849 | L17: 18.6 | M17: =AVERAGE(M12:M16) -> 1624.652 | N17: =M17/L17 -> 87.346881 | O17: =L17-I17 -> 0 | P17: =N17-K17 -> -4.0509685 | Q17: =N17/K17 -> 0.95567764 | AA17: =M17-J17 -> -75.348015 | AB17: =M17/J17 -> 0.95567764
A18: 新豐7線 | B18: 小吃 | C18: 古早味炒炊粉 | E18: 43.14 | F18: 1487 | G18: =E18*F18 -> 64149.18 | I18: 17 | J18: 2000 | K18: =J18/I18 -> 117.64706 | L18: 17 | M18: =F18/V18*60 -> 1939.5652 | N18: =M18/L18 -> 114.09207 | O18: =L18-I18 -> 0 | P18: =N18-K18 -> -3.5549872 | Q18: =N18/K18 -> 0.96978261 | R18: =Q24 -> 0.96072483 | S18: 0.20833333 | T18: 0.24027778 | V18: =(T18-S18)*24*60 -> 46 | AA18: =M18-J18 -> -60.434783 | AB18: =M18/J18 -> 0.96978261 | AC18: =AB24 -> 0.96072483
A19: 新豐7線 | B19: 微波主食 | C19: 極上炙烤親子丼 | E19: 53.68 | F19: 2003 | G19: =E19*F19 -> 107521.04 | I19: 16 | J19: 2000 | K19: =J19/I19 -> 125 | L19: 16 | M19: =F19/V19*60 -> 1907.619 | N19: =M19/L19 -> 119.22619 | O19: =L19-I19 -> 0 | P19: =N19-K19 -> -5.7738095 | Q19: =N19/K19 -> 0.95380952 | S19: 0.24375 | T19: 0.2875 | U19: =IF(S19=TIME(17,0,0),"",(S19-T18)*24*60) -> 5 | V19: =(T19-S19)*24*60 -> 63 | AA19: =M19-J19 -> -92.380952 | AB19: =M19/J19 -> 0.95380952
A20: 新豐7線 | B20: 微波主食 | C20: 鐵板滑蛋炸豬排丼 | E20: 57.73 | F20: 3314 | G20: =E20*F20 -> 191317.22 | I20: 15 | J20: 2000 | K20: =J20/I20 -> 133.33333 | L20: 15 | M20: =F20/V20*60 -> 1911.9231 | N20: =M20/L20 -> 127.46154 | O20: =L20-I20 -> 0 | P20: =N20-K20 -> -5.8717949 | Q20: =N20/K20 -> 0.95596154 | S20: 0.29166667 | T20: 0.36388889 | U20: =IF(S20=TIME(17,0,0),"",(S20-T19)*24*60) -> 6 | V20: =(T20-S20)*24*60 -> 104 | AA20: =M20-J20 -> -88.076923 | AB20: =M20/J20 -> 0.95596154
A21: 新豐7線 | B21: 微波主食 | C21: 二配美味蟹煲 | E21: 54.09 | F21: 2314 | G21: =E21*F21 -> 125164.26 | I21: 19 | J21: 2000 | K21: =J21/I21 -> 105.26316 | L21: 19 | M21: =F21/V21*60 -> 1928.3333 | N21: =M21/L21 -> 101.49123 | O21: =L21-I21 -> 0 | P21: =N21-K21 -> -3.7719298 | Q21: =N21/K21 -> 0.96416667 | S21: 0.70833333 | T21: 0.75833333 | U21: =IF(S21=TIME(17,0,0),"",(S21-T20)*24*60) | V21: =(T21-S21)*24*60 -> 72 | AA21: =M21-J21 -> -71.666667 | AB21: =M21/J21 -> 0.96416667
A22: 新豐7線 | B22: 微波主食 | C22: 二配泰式綠咖哩雞 | E22: 48.36 | F22: 3000 | G22: =E22*F22 -> 145080 | H22: 2 | I22: 15 | J22: 2000 | K22: =J22/I22 -> 133.33333 | L22: 15 | M22: =F22/V22*60 -> 1914.8936 | N22: =M22/L22 -> 127.65957 | O22: =L22-I22 -> 0 | P22: =N22-K22 -> -5.6737589 | Q22: =N22/K22 -> 0.95744681 | S22: 0.76180556 | T22: 0.82708333 | U22: =IF(S22=TIME(17,0,0),"",(S22-T21)*24*60) -> 5 | V22: =(T22-S22)*24*60 -> 94 | W22: =T22 -> 0.82708333 | X22: =S23 -> 0.86805556 | AA22: =M22-J22 -> -85.106383 | AB22: =M22/J22 -> 0.95744681
A23: 新豐7線 | B23: 微波主食 | C23: 二配泰式綠咖哩雞 | E23: 48.36 | F23: 2119 | G23: =E23*F23 -> 102474.84 | I23: 15 | J23: 2000 | K23: =J23/I23 -> 133.33333 | L23: 15 | M23: =F23/V23*60 -> 1926.3636 | N23: =M23/L23 -> 128.42424 | O23: =L23-I23 -> 0 | P23: =N23-K23 -> -4.9090909 | Q23: =N23/K23 -> 0.96318182 | S23: 0.86805556 | T23: 0.91388889 | U23: =IF(S23=TIME(17,0,0),"",(S23-T22)*24*60) -> 59 | V23: =(T23-S23)*24*60 -> 66 | AA23: =M23-J23 -> -73.636364 | AB23: =M23/J23 -> 0.96318182
