Workbook

Sheet 0331
B1: 屏榮 新豐廠組合室生產人時性分析
B3: 日期 | C3: =TEXT('0331 4度C'!A2,"yyyy.mm.ddaaaa") -> 2026.03.31星期二 | E3: 訂單量 | F3: ='0331 4度C'!D1 -> 165261 | H3: 營業額 | I3: ='0331 4度C'!F1 -> 5479936.7
B4: 人時性 | C4: 項目 | E4: ➀ | G4: ➁ | I4: ➂ | K4: 異常停線 | M4: 短暫停線
C5: 組合室 | E5: 全溫層 | G5: 4度C-各編組展開 | I5: ③三明治-各編組展開 | K5: 合計次數 | L5: 時間 | M5: 合計次數 | N5: 設備次數
C6: 排關平均 | E6: =AVERAGE(D13:M13) -> 155.66761 | F6: =AVERAGE(D31:O31,D13:J13) -> 161.87503 | G6: =AVERAGE(D13:J13) -> 161.87503 | I6: =AVERAGE(K13:M13) -> 141.18362 | K6: ='0331 4度C'!Y2 -> 0 | L6: ='0331 4度C'!Z2 -> 0 | M6: ='0331 4度C'!AC2 -> 54 | N6: ='0331 4度C'!AD2 -> 0
C7: 實績平均 | E7: =AVERAGE(D14:M14) -> 148.95757 | F7: =AVERAGE(D32:O32,D14:J14) -> 154.97333 | G7: =AVERAGE(D14:J14) -> 154.97333 | I7: =AVERAGE(K14:M14) -> 134.9208
C8: 達成率平均 | E8: =AVERAGE(D15:M15) -> 0.95623965 | F8: =AVERAGE(D15:J15,D33:O33) -> 0.95649514 | G8: =AVERAGE(D15:J15) -> 0.95649514 | I8: =AVERAGE(K15:M15) -> 0.95564349
K9: ※現行日本鮮食廠以達成率80%為基本(即為現行KPI)
B10: 溫層 | D10: ➁4度C-各編組展開 | K10: ③三明治-各編組展開
B11: 編組 | D11: 1 | E11: 2 | F11: 3 | G11: 4 | H11: 5 | I11: 6 | J11: 7 | K11: 1 | L11: 2 | M11: 3
D12: 新豐6線 | E12: 新豐2線 | F12: 新豐5線 | G12: 新豐7線 | H12: 新豐3線 | I12: 新豐1線 | J12: 新豐10線 | K12: 新豐8線 | L12: 新豐9線 | M12: 新豐4線
B13: 人時性 | C13: 排關 | D13: =SUMIFS('0331 4度C'!$K:$K,'0331 4度C'!$A:$A,"新豐6線",'0331 4度C'!$B:$B,"平均") -> 111.11111 | E13: =SUMIFS('0331 4度C'!$K:$K,'0331 4度C'!$A:$A,"新豐2線",'0331 4度C'!$B:$B,"平均") -> 84.90566 | F13: =SUMIFS('0331 4度C'!$K:$K,'0331 4度C'!$A:$A,"新豐5線",'0331 4度C'!$B:$B,"平均") -> 102.73973 | G13: =SUMIFS('0331 4度C'!$K:$K,'0331 4度C'!$A:$A,"新豐7線",'0331 4度C'!$B:$B,"平均") -> 127.77778 | H13: =SUMIFS('0331 4度C'!$K:$K,'0331 4度C'!$A:$A,"新豐3線",'0331 4度C'!$B:$B,"平均") -> 333.33333 | I13: =SUMIFS('0331 4度C'!$K:$K,'0331 4度C'!$A:$A,"新豐1線",'0331 4度C'!$B:$B,"平均") -> 104.02685 | J13: =SUMIFS('0331 4度C'!$K:$K,'0331 4度C'!$A:$A,"新豐10線",'0331 4度C'!$B:$B,"平均") -> 269.23077 | K13: =SUMIFS('0331 4度C'!$K:$K,'0331 4度C'!$A:$A,"新豐8線",'0331 4度C'!$B:$B,"平均") -> 130.90909 | L13: =SUMIFS('0331 4度C'!$K:$K,'0331 4度C'!$A:$A,"新豐9線",'0331 4度C'!$B:$B,"平均") -> 134.4 | M13: =SUMIFS('0331 4度C'!$K:$K,'0331 4度C'!$A:$A,"新豐4線",'0331 4度C'!$B:$B,"平均") -> 158.24176
C14: 實績 | D14: =SUMIFS('0331 4度C'!$N:$N,'0331 4度C'!$A:$A,"新豐6線",'0331 4度C'!$B:$B,"平均") -> 105.59434 | E14: =SUMIFS('0331 4度C'!$N:$N,'0331 4度C'!$A:$A,"新豐2線",'0331 4度C'!$B:$B,"平均") -> 81.063563 | F14: =SUMIFS('0331 4度C'!$N:$N,'0331 4度C'!$A:$A,"新豐5線",'0331 4度C'!$B:$B,"平均") -> 97.53126 | G14: =SUMIFS('0331 4度C'!$N:$N,'0331 4度C'!$A:$A,"新豐7線",'0331 4度C'!$B:$B,"平均") -> 122.67097 | H14: =SUMIFS('0331 4度C'!$N:$N,'0331 4度C'!$A:$A,"新豐3線",'0331 4度C'!$B:$B,"平均") -> 318.83926 | I14: =SUMIFS('0331 4度C'!$N:$N,'0331 4度C'!$A:$A,"新豐1線",'0331 4度C'!$B:$B,"平均") -> 100.13546 | J14: =SUMIFS('0331 4度C'!$N:$N,'0331 4度C'!$A:$A,"新豐10線",'0331 4度C'!$B:$B,"平均") -> 258.97846 | K14: =SUMIFS('0331 4度C'!$N:$N,'0331 4度C'!$A:$A,"新豐8線",'0331 4度C'!$B:$B,"平均") -> 125.03287 | L14: =SUMIFS('0331 4度C'!$N:$N,'0331 4度C'!$A:$A,"新豐9線",'0331 4度C'!$B:$B,"平均") -> 128.52713 | M14: =SUMIFS('0331 4度C'!$N:$N,'0331 4度C'!$A:$A,"新豐4線",'0331 4度C'!$B:$B,"平均") -> 151.20241
C15: 達成率 | D15: =D14/D13 -> 0.95034909 | E15: =E14/E13 -> 0.95474863 | F15: =F14/F13 -> 0.94930427 | G15: =G14/G13 -> 0.96003371 | H15: =H14/H13 -> 0.95651778 | I15: =I14/I13 -> 0.9625925 | J15: =J14/J13 -> 0.96192001 | K15: =K14/K13 -> 0.95511217 | ... M15: =M14/M13 -> 0.95551523
B16: 作業 時間 | C16: 開始 | D16: =VLOOKUP("新豐6線",'0331 4度C'!$A:$T,19,0) -> 0.70833333 | E16: =VLOOKUP("新豐2線",'0331 4度C'!$A:$T,19,0) -> 0.20833333 | F16: =VLOOKUP("新豐5線",'0331 4度C'!$A:$T,19,0) -> 0.20833333 | G16: =VLOOKUP("新豐7線",'0331 4度C'!$A:$T,19,0) -> 0.20833333 | H16: =VLOOKUP("新豐3線",'0331 4度C'!$A:$T,19,0) -> 0.083333333 | I16: =VLOOKUP("新豐1線",'0331 4度C'!$A:$T,19,0) -> 0.20833333 | J16: =VLOOKUP("新豐10線",'0331 4度C'!$A:$T,19,0) -> 0.20833333 | K16: =VLOOKUP("新豐8線",'0331 4度C'!$A:$T,19,0) -> 0.083333333 | L16: =VLOOKUP("新豐9線",'0331 4度C'!$A:$T,19,0) -> 0.083333333 | M16: =VLOOKUP("新豐4線",'0331 4度C'!$A:$T,19,0) -> 0.083333333
C17: 結束 | D17: =LOOKUP(2,1/(('0331 4度C'!$A:$A="新豐6線")*('0331 4度C'!$T:$T<>"")),'0331 4度C'!$T:$T) -> 0.82569444 | E17: =LOOKUP(2,1/(('0331 4度C'!$A:$A="新豐2線")*('0331 4度C'!$T:$T<>"")),'0331 4度C'!$T:$T) -> 0.66527778 | F17: =LOOKUP(2,1/(('0331 4度C'!$A:$A="新豐5線")*('0331 4度C'!$T:$T<>"")),'0331 4度C'!$T:$T) -> 0.82847222 | G17: =LOOKUP(2,1/(('0331 4度C'!$A:$A="新豐7線")*('0331 4度C'!$T:$T<>"")),'0331 4度C'!$T:$T) -> 0.84375 | H17: =LOOKUP(2,1/(('0331 4度C'!$A:$A="新豐3線")*('0331 4度C'!$T:$T<>"")),'0331 4度C'!$T:$T) -> 0.43958333 | I17: =LOOKUP(2,1/(('0331 4度C'!$A:$A="新豐1線")*('0331 4度C'!$T:$T<>"")),'0331 4度C'!$T:$T) -> 0.90069444 | J17: =LOOKUP(2,1/(('0331 4度C'!$A:$A="新豐10線")*('0331 4度C'!$T:$T<>"")),'0331 4度C'!$T:$T) -> 0.44375 | K17: =LOOKUP(2,1/(('0331 4度C'!$A:$A="新豐8線")*('0331 4度C'!$T:$T<>"")),'0331 4度C'!$T:$T) -> 0.62222222 | L17: =LOOKUP(2,1/(('0331 4度C'!$A:$A="新豐9線")*('0331 4度C'!$T:$T<>"")),'0331 4度C'!$T:$T) -> 0.63819444 | M17: =LOOKUP(2,1/(('0331 4度C'!$A:$A="新豐4線")*('0331 4度C'!$T:$T<>"")),'0331 4度C'!$T:$T) -> 0.62361111
B18: 產線異常 (5分鐘以上) | C18: 次數 | D18: =SUMIFS('0331 4度C'!$Y:$Y,'0331 4度C'!$A:$A,"新豐6線",'0331 4度C'!$B:$B,"平均") -> 0 | E18: =SUMIFS('0331 4度C'!$Y:$Y,'0331 4度C'!$A:$A,"新豐2線",'0331 4度C'!$B:$B,"平均") -> 0 | F18: =SUMIFS('0331 4度C'!$Y:$Y,'0331 4度C'!$A:$A,"新豐5線",'0331 4度C'!$B:$B,"平均") -> 0 | G18: =SUMIFS('0331 4度C'!$Y:$Y,'0331 4度C'!$A:$A,"新豐7線",'0331 4度C'!$B:$B,"平均") -> 0 | H18: =SUMIFS('0331 4度C'!$Y:$Y,'0331 4度C'!$A:$A,"新豐3線",'0331 4度C'!$B:$B,"平均") -> 0 | I18: =SUMIFS('0331 4度C'!$Y:$Y,'0331 4度C'!$A:$A,"新豐1線",'0331 4度C'!$B:$B,"平均") -> 0 | J18: =SUMIFS('0331 4度C'!$Y:$Y,'0331 4度C'!$A:$A,"新豐10線",'0331 4度C'!$B:$B,"平均") -> 0 | K18: =SUMIFS('0331 4度C'!$Y:$Y,'0331 4度C'!$A:$A,"新豐8線",'0331 4度C'!$B:$B,"平均") -> 0 | L18: =SUMIFS('0331 4度C'!$Y:$Y,'0331 4度C'!$A:$A,"新豐9線",'0331 4度C'!$B:$B,"平均") -> 0 | M18: =SUMIFS('0331 4度C'!$Y:$Y,'0331 4度C'!$A:$A,"新豐4線",'0331 4度C'!$B:$B,"平均") -> 0
C19: 時間/分 | D19: =SUMIFS('0331 4度C'!$Z:$Z,'0331 4度C'!$A:$A,"新豐6線",'0331 4度C'!$B:$B,"平均") -> 0 | E19: =SUMIFS('0331 4度C'!$Z:$Z,'0331 4度C'!$A:$A,"新豐2線",'0331 4度C'!$B:$B,"平均") -> 0 | F19: =SUMIFS('0331 4度C'!$Z:$Z,'0331 4度C'!$A:$A,"新豐5線",'0331 4度C'!$B:$B,"平均") -> 0 | G19: =SUMIFS('0331 4度C'!$Z:$Z,'0331 4度C'!$A:$A,"新豐7線",'0331 4度C'!$B:$B,"平均") -> 0 | H19: =SUMIFS('0331 4度C'!$Z:$Z,'0331 4度C'!$A:$A,"新豐3線",'0331 4度C'!$B:$B,"平均") -> 0 | I19: =SUMIFS('0331 4度C'!$Z:$Z,'0331 4度C'!$A:$A,"新豐1線",'0331 4度C'!$B:$B,"平均") -> 0 | J19: =SUMIFS('0331 4度C'!$Z:$Z,'0331 4度C'!$A:$A,"新豐10線",'0331 4度C'!$B:$B,"平均") -> 0 | K19: =SUMIFS('0331 4度C'!$Z:$Z,'0331 4度C'!$A:$A,"新豐8線",'0331 4度C'!$B:$B,"平均") -> 0 | L19: =SUMIFS('0331 4度C'!$Z:$Z,'0331 4度C'!$A:$A,"新豐9線",'0331 4度C'!$B:$B,"平均") -> 0 | M19: =SUMIFS('0331 4度C'!$Z:$Z,'0331 4度C'!$A:$A,"新豐4線",'0331 4度C'!$B:$B,"平均") -> 0
B20: 短暫停線 (5分鐘以下) | C20: 次數 | D20: =SUMIFS('0331 4度C'!$AC:$AC,'0331 4度C'!$A:$A,"新豐6線",'0331 4度C'!$B:$B,"平均") -> 4 | E20: =SUMIFS('0331 4度C'!$AC:$AC,'0331 4度C'!$A:$A,"新豐2線",'0331 4度C'!$B:$B,"平均") -> 3 | F20: =SUMIFS('0331 4度C'!$AC:$AC,'0331 4度C'!$A:$A,"新豐5線",'0331 4度C'!$B:$B,"平均") -> 4 | G20: =SUMIFS('0331 4度C'!$AC:$AC,'0331 4度C'!$A:$A,"新豐7線",'0331 4度C'!$B:$B,"平均") -> 6 | H20: =SUMIFS('0331 4度C'!$AC:$AC,'0331 4度C'!$A:$A,"新豐3線",'0331 4度C'!$B:$B,"平均") -> 5 | I20: =SUMIFS('0331 4度C'!$AC:$AC,'0331 4度C'!$A:$A,"新豐1線",'0331 4度C'!$B:$B,"平均") -> 8 | J20: =SUMIFS('0331 4度C'!$AC:$AC,'0331 4度C'!$A:$A,"新豐10線",'0331 4度C'!$B:$B,"平均") -> 5 | K20: =SUMIFS('0331 4度C'!$AC:$AC,'0331 4度C'!$A:$A,"新豐8線",'0331 4度C'!$B:$B,"平均") -> 6 | L20: =SUMIFS('0331 4度C'!$AC:$AC,'0331 4度C'!$A:$A,"新豐9線",'0331 4度C'!$B:$B,"平均") -> 7 | M20: =SUMIFS('0331 4度C'!$AC:$AC,'0331 4度C'!$A:$A,"新豐4線",'0331 4度C'!$B:$B,"平均") -> 6
C21: 設備次數 | D21: =SUMIFS('0331 4度C'!$AD:$AD,'0331 4度C'!$A:$A,"新豐6線",'0331 4度C'!$B:$B,"平均") -> 0 | E21: =SUMIFS('0331 4度C'!$AD:$AD,'0331 4度C'!$A:$A,"新豐2線",'0331 4度C'!$B:$B,"平均") -> 0 | F21: =SUMIFS('0331 4度C'!$AD:$AD,'0331 4度C'!$A:$A,"新豐5線",'0331 4度C'!$B:$B,"平均") -> 0 | G21: =SUMIFS('0331 4度C'!$AD:$AD,'0331 4度C'!$A:$A,"新豐7線",'0331 4度C'!$B:$B,"平均") -> 0 | H21: =SUMIFS('0331 4度C'!$AD:$AD,'0331 4度C'!$A:$A,"新豐3線",'0331 4度C'!$B:$B,"平均") -> 0 | I21: =SUMIFS('0331 4度C'!$AD:$AD,'0331 4度C'!$A:$A,"新豐1線",'0331 4度C'!$B:$B,"平均") -> 0 | J21: =SUMIFS('0331 4度C'!$AD:$AD,'0331 4度C'!$A:$A,"新豐10線",'0331 4度C'!$B:$B,"平均") -> 0 | K21: =SUMIFS('0331 4度C'!$AD:$AD,'0331 4度C'!$A:$A,"新豐8線",'0331 4度C'!$B:$B,"平均") -> 0 | L21: =SUMIFS('0331 4度C'!$AD:$AD,'0331 4度C'!$A:$A,"新豐9線",'0331 4度C'!$B:$B,"平均") -> 0 | M21: =SUMIFS('0331 4度C'!$AD:$AD,'0331 4度C'!$A:$A,"新豐4線",'0331 4度C'!$B:$B,"平均") -> 0
B22: 配置人數 | D22: =SUMIFS('0331 4度C'!$I:$I,'0331 4度C'!$A:$A,"新豐6線",'0331 4度C'!$B:$B,"平均") -> 18 | E22: =SUMIFS('0331 4度C'!$I:$I,'0331 4度C'!$A:$A,"新豐2線",'0331 4度C'!$B:$B,"平均") -> 17.666667 | F22: =SUMIFS('0331 4度C'!$I:$I,'0331 4度C'!$A:$A,"新豐5線",'0331 4度C'!$B:$B,"平均") -> 18.25 | G22: =SUMIFS('0331 4度C'!$I:$I,'0331 4度C'!$A:$A,"新豐7線",'0331 4度C'!$B:$B,"平均") -> 15 | H22: =SUMIFS('0331 4度C'!$I:$I,'0331 4度C'!$A:$A,"新豐3線",'0331 4度C'!$B:$B,"平均") -> 9 | I22: =SUMIFS('0331 4度C'!$I:$I,'0331 4度C'!$A:$A,"新豐1線",'0331 4度C'!$B:$B,"平均") -> 18.625 | J22: =SUMIFS('0331 4度C'!$I:$I,'0331 4度C'!$A:$A,"新豐10線",'0331 4度C'!$B:$B,"平均") -> 10.4 | K22: =SUMIFS('0331 4度C'!$I:$I,'0331 4度C'!$A:$A,"新豐8線",'0331 4度C'!$B:$B,"平均") -> 18.333333 | L22: =SUMIFS('0331 4度C'!$I:$I,'0331 4度C'!$A:$A,"新豐9線",'0331 4度C'!$B:$B,"平均") -> 17.857143 | M22: =SUMIFS('0331 4度C'!$I:$I,'0331 4度C'!$A:$A,"新豐4線",'0331 4度C'!$B:$B,"平均") -> 15.166667
B23: 主要應用設備 | D23: ET-55 | E23: 熱縮爐 | F23: L型包裝機 | G23: L型包裝機 | H23: 伺服包裝機 | I23: ET-55 | J23: 伺服包裝機 | K23: 三明治包裝機 | L23: 三明治包裝機 | M23: 三明治包裝機
B24: 次要應用設備 | F24: 圓盤機 | G24: ET-55
B25: 備註 | E25: 握沙拉 | F25: 共用L型包裝機 | H25: 調理麵包 | I25: 炒飯+沙拉 | J25: 調理麵包

Sheet 0331 4度C
A1: 新豐廠四度C日報分析 | C1: 總生產量 | D1: =SUM(F5:F68) -> 165261 | E1: 營業額 | F1: =SUM(G5:G68) -> 5479936.7 | G1: 出勤人數 | H1: =L9+L13+L46+L55+L18+L61+L32+L40+L25+L68 -> 158.29881 | I1: 產線配置圖 | L1: 生產實績 | O1: 人時性差異分析 | S1: 日報登錄 | Y1: 合計 次數 | Z1: 合計 時間/分 | AA1: 產線異常 分析說明(5分鐘以上) | AC1: 合計 次數 | AD1: 合計 設備次數 | AE1: 產能差異分析
A2: 46112 | B2: 星期二 | C2: 人時性 | D2: =AVERAGE(N9,N13,N46,N55,N18,N61,N25,N32,N40,N68) -> 148.95757 | E2: 平均廠價 | F2: =F1/D1 -> 33.159286 | G2: 多次生產數 | H2: =COUNT(H5:H68) -> 6 | Y2: =SUM(Y9+Y13+Y18+Y25+Y32+Y40+Y46+Y55+Y61+Y68) -> 0 | Z2: =SUM(Z9+Z13+Z18+Z25+Z32+Z40+Z46+Z55+Z61+Z68) -> 0 | AC2: 54 | AD2: =SUM(AD9+AD13+AD18+AD25+AD32+AD40+AD46+AD55+AD61+AD68) -> 0
A3: 線別 | B3: 品類 | C3: 品名 | E3: 廠價 | F3: 生產量 | G3: 營收 | H3: 多次 生產 | I3: 人數 | J3: 產能/時 | K3: 人時性 | L3: 人數 | M3: 產能/時 | N3: 人時性 | O3: 人數 | P3: 人時性 | Q3: 達成率 | R3: 達成率平均 | S3: 生產時間 | U3: 換線、休息/分 | V3: 稼動時間/分 | W3: 休息時間 | Y3: 產線異常統計 (5分鐘以上) | AA3: (新豐回填) | AC3: 短暫停線統計 (5分鐘以下) | AE3: 產能/時 | AF3: 達成率 | AG3: 達成率平均
S4: 開始 | T4: 結束 | W4: 開始 | X4: 結束 | Y4: 次數 | Z4: 時間/分 | AC4: 總次數 | AD4: 設備因素(次數)
A5: 新豐6線 | B5: 微波主食 | C5: 二配港式香滑嫩蛋牛肉燴飯 | E5: 50.67 | F5: 1531 | G5: =E5*F5 -> 77575.77 | I5: 17 | J5: 2000 | K5: =J5/I5 -> 117.64706 | L5: 17 | M5: =F5/V5*60 -> 1913.75 | N5: =M5/L5 -> 112.57353 | O5: =L5-I5 -> 0 | P5: =N5-K5 -> -5.0735294 | Q5: =N5/K5 -> 0.956875 | R5: =Q9 -> 0.95034909 | S5: 0.70833333 | T5: 0.74166667 | V5: =(T5-S5)*24*60 -> 48 | AC5: 4 | AE5: =M5-J5 -> -86.25 | AF5: =M5/J5 -> 0.956875 | AG5: =AF9 -> 0.95034909
A6: 新豐6線 | B6: 微波主食 | C6: 二配美味蟹煲 | E6: 54.09 | F6: 1239 | G6: =E6*F6 -> 67017.51 | I6: 19 | J6: 2000 | K6: =J6/I6 -> 105.26316 | L6: 19 | M6: =F6/V6*60 -> 1906.1538 | N6: =M6/L6 -> 100.32389 | O6: =L6-I6 -> 0 | P6: =N6-K6 -> -4.9392713 | Q6: =N6/K6 -> 0.95307692 | S6: 0.74583333 | T6: 0.77291667 | U6: =IF(S6=TIME(17,0,0),"",(S6-T5)*24*60) -> 6 | V6: =(T6-S6)*24*60 -> 39 | AE6: =M6-J6 -> -93.846154 | AF6: =M6/J6 -> 0.95307692
A7: 新豐6線 | B7: 微波主食 | C7: 二配濃蕃茄火腿蛋包飯 | E7: 50.67 | F7: 309 | G7: =E7*F7 -> 15657.03 | I7: 21 | J7: 2000 | K7: =J7/I7 -> 95.238095 | L7: 21 | M7: =F7/V7*60 -> 1854 | N7: =M7/L7 -> 88.285714 | O7: =L7-I7 -> 0 | P7: =N7-K7 -> -6.952381 | Q7: =N7/K7 -> 0.927 | S7: 0.77847222 | T7: 0.78541667 | U7: =IF(S7=TIME(17,0,0),"",(S7-T6)*24*60) -> 8 | V7: =(T7-S7)*24*60 -> 10 | AE7: =M7-J7 -> -146 | AF7: =M7/J7 -> 0.927
A8: 新豐6線 | B8: 微波主食 | C8: 二配泰式綠咖哩雞 | E8: 50.67 | F8: 1736 | G8: =E8*F8 -> 87963.12 | I8: 15 | J8: 2000 | K8: =J8/I8 -> 133.33333 | L8: 15 | M8: =F8/V8*60 -> 1928.8889 | N8: =M8/L8 -> 128.59259 | O8: =L8-I8 -> 0 | P8: =N8-K8 -> -4.7407407 | Q8: =N8/K8 -> 0.96444444 | S8: 0.78819444 | T8: 0.82569444 | U8: =IF(S8=TIME(17,0,0),"",(S8-T7)*24*60) -> 4 | V8: =(T8-S8)*24*60 -> 54 | AE8: =M8-J8 -> -71.111111 | AF8: =M8/J8 -> 0.96444444
A9: 新豐6線 | B9: 平均 | I9: 18 | J9: 2000 | K9: =J9/I9 -> 111.11111 | L9: 18 | M9: =AVERAGE(M5:M8) -> 1900.6982 | N9: =M9/L9 -> 105.59434 | O9: =L9-I9 -> 0 | P9: =N9-K9 -> -5.5167676 | Q9: =N9/K9 -> 0.95034909 | Y9: =SUM(Y5:Y8) -> 0 | Z9: =SUM(Z5:Z8) -> 0 | AC9: 4 | AD9: =SUM(AD5:AD8) -> 0 | AE9: =M9-J9 -> -99.301816 | AF9: =M9/J9 -> 0.95034909
A10: 新豐2線 | B10: 沙拉 | C10: 青醬優格雞肉握沙拉(113年) | E10: 39.62 | F10: 5591 | G10: =E10*F10 -> 221515.42 | I10: 19 | J10: 1500 | K10: =J10/I10 -> 78.947368 | L10: 19 | M10: =F10/V10*60 -> 1433.5897 | N10: =M10/L10 -> 75.452092 | O10: =L10-I10 -> 0 | P10: =N10-K10 -> -3.4952767 | Q10: =N10/K10 -> 0.9557265 | R10: =Q13 -> 0.95474863 | S10: 0.20833333 | T10: 0.37083333 | V10: =(T10-S10)*24*60 -> 234 | AC10: 3 | AE10: =M10-J10 -> -66.410256 | AF10: =M10/J10 -> 0.9557265 | AG10: =AF13 -> 0.95474863
A11: 新豐2線 | B11: 沙拉 | C11: 青檸烤雞握沙拉(113年) | E11: 39.8 | F11: 4600 | G11: =E11*F11 -> 183080 | H11: 2 | I11: 17 | J11: 1500 | K11: =J11/I11 -> 88.235294 | L11: 17 | M11: =F11/V11*60 -> 1430.0518 | N11: =M11/L11 -> 84.120695 | O11: =L11-I11 -> 0 | P11: =N11-K11 -> -4.1145992 | Q11: =N11/K11 -> 0.95336788 | S11: 0.37638889 | T11: 0.51041667 | U11: =IF(S11=TIME(17,0,0),"",(S11-T10)*24*60) -> 8 | V11: =(T11-S11)*24*60 -> 193 | W11: =T11 -> 0.51041667 | X11: =S12 -> 0.55069444 | AE11: =M11-J11 -> -69.948187 | AF11: =M11/J11 -> 0.95336788
A12: 新豐2線 | B12: 沙拉 | C12: 青檸烤雞握沙拉(113年) | E12: 39.8 | F12: 3940 | G12: =E12*F12 -> 156812 | I12: 17 | J12: 1500 | K12: =J12/I12 -> 88.235294 | L12: 17 | M12: =F12/V12*60 -> 1432.7273 | N12: =M12/L12 -> 84.278075 | O12: =L12-I12 -> 0 | P12: =N12-K12 -> -3.9572193 | Q12: =N12/K12 -> 0.95515152 | S12: 0.55069444 | T12: 0.66527778 | U12: =IF(S12=TIME(17,0,0),"",(S12-T11)*24*60) -> 58 | V12: =(T12-S12)*24*60 -> 165 | AE12: =M12-J12 -> -67.272727 | AF12: =M12/J12 -> 0.95515152
A13: 新豐2線 | B13: 平均 | I13: 17.666667 | J13: 1500 | K13: =J13/I13 -> 84.90566 | L13: 17.666667 | M13: =AVERAGE(M10:M12) -> 1432.1229 | N13: =M13/L13 -> 81.063563 | O13: =L13-I13 -> 0 | P13: =N13-K13 -> -3.8420976 | Q13: =N13/K13 -> 0.95474863 | Y13: =SUM(Y10:Y12) -> 0 | Z13: =SUM(Z10:Z12) -> 0 | AC13: 3 | AD13: =SUM(AD10:AD12) -> 0 | AE13: =M13-J13 -> -67.877057 | AF13: =M13/J13 -> 0.95474863
A14: 新豐5線 | B14: 小吃 | C14: 剝皮辣椒雞湯 | E14: 41 | F14: 2519 | G14: =E14*F14 -> 103279 | I14: 26 | J14: 1500 | K14: =J14/I14 -> 57.692308 | L14: 26 | M14: =F14/V14*60 -> 1439.4286 | N14: =M14/L14 -> 55.362637 | O14: =L14-I14 -> 0 | P14: =N14-K14 -> -2.3296703 | Q14: =N14/K14 -> 0.95961905 | R14: =Q18 -> 0.94930427 | S14: 0.20833333 | T14: 0.28125 | V14: =(T14-S14)*24*60 -> 105 | AC14: 4 | AE14: =M14-J14 -> -60.571429 | AF14: =M14/J14 -> 0.95961905 | AG14: =AF18 -> 0.94930427
A15: 新豐5線 | B15: 微波主食 | C15: 二配金咖哩濃厚辛口咖哩飯 | E15: 50.98 | F15: 2481 | G15: =E15*F15 -> 126481.38 | I15: 16 | J15: 2000 | K15: =J15/I15 -> 125 | L15: 16 | M15: =F15/V15*60 -> 1908.4615 | N15: =M15/L15 -> 119.27885 | O15: =L15-I15 -> 0 | P15: =N15-K15 -> -5.7211538 | Q15: =N15/K15 -> 0.95423077 | S15: 0.70833333 | T15: 0.7625 | U15: =IF(S15=TIME(17,0,0),"",(S15-T14)*24*60) | V15: =(T15-S15)*24*60 -> 78 | AE15: =M15-J15 -> -91.538462 | AF15: =M15/J15 -> 0.95423077
A16: 新豐5線 | B16: 微波主食 | C16: 二配香炒沙茶豬肉飯 | E16: 50.67 | F16: 310 | G16: =E16*F16 -> 15707.7 | I16: 16 | J16: 2000 | K16: =J16/I16 -> 125 | L16: 16 | M16: =F16/V16*60 -> 1860 | N16: =M16/L16 -> 116.25 | O16: =L16-I16 -> 0 | P16: =N16-K16 -> -8.75 | Q16: =N16/K16 -> 0.93 | S16: 0.76597222 | T16: 0.77291667 | U16: =IF(S16=TIME(17,0,0),"",(S16-T15)*24*60) -> 5 | V16: =(T16-S16)*24*60 -> 10 | AE16: =M16-J16 -> -140 | AF16: =M16/J16 -> 0.93
A17: 新豐5線 | B17: 微波主食 | C17: 二配金咖哩果香甘口咖哩飯 | E17: 50.92 | F17: 2358 | G17: =E17*F17 -> 120069.36 | I17: 15 | J17: 2000 | K17: =J17/I17 -> 133.33333 | L17: 15 | M17: =F17/V17*60 -> 1911.8919 | N17: =M17/L17 -> 127.45946 | O17: =L17-I17 -> 0 | P17: =N17-K17 -> -5.8738739 | Q17: =N17/K17 -> 0.95594595 | S17: 0.77708333 | T17: 0.82847222 | U17: =IF(S17=TIME(17,0,0),"",(S17-T16)*24*60) -> 6 | V17: =(T17-S17)*24*60 -> 74 | AE17: =M17-J17 -> -88.108108 | AF17: =M17/J17 -> 0.95594595
A18: 新豐5線 | B18: 平均 | I18: 18.25 | J18: 1875 | K18: =J18/I18 -> 102.73973 | L18: 18.25 | M18: =AVERAGE(M14:M17) -> 1779.9455 | N18: =M18/L18 -> 97.53126 | O18: =L18-I18 -> 0 | P18: =N18-K18 -> -5.2084657 | Q18: =N18/K18 -> 0.94930427 | Y18: =SUM(Y14:Y17) -> 0 | Z18: =SUM(Z14:Z17) -> 0 | AC18: 4 | AD18: =SUM(AD14:AD17) -> 0 | AE18: =M18-J18 -> -95.0545 | AF18: =M18/J18 -> 0.94930427
A19: 新豐7線 | B19: 微波主食 | C19: 鐵板滑蛋炸豬排丼 | E19: 57.73 | F19: 2486 | G19: =E19*F19 -> 143516.78 | I19: 14 | J19: 2000 | K19: =J19/I19 -> 142.85714 | L19: 14 | M19: =F19/V19*60 -> 1912.3077 | N19: =M19/L19 -> 136.59341 | O19: =L19-I19 -> 0 | P19: =N19-K19 -> -6.2637363 | Q19: =N19/K19 -> 0.95615385 | R19: =Q25 -> 0.96003371 | S19: 0.20833333 | T19: 0.2625 | V19: =(T19-S19)*24*60 -> 78 | AC19: 6 | AE19: =M19-J19 -> -87.692308 | AF19: =M19/J19 -> 0.95615385 | AG19: =AF25 -> 0.96003371
A20: 新豐7線 | B20: 微波主食 | C20: 極上炙烤親子丼 | E20: 53.68 | F20: 1434 | G20: =E20*F20 -> 76977.12 | I20: 16 | J20: 2000 | K20: =J20/I20 -> 125 | L20: 16 | M20: =F20/V20*60 -> 1912 | N20: =M20/L20 -> 119.5 | O20: =L20-I20 -> 0 | P20: =N20-K20 -> -5.5 | Q20: =N20/K20 -> 0.956 | S20: 0.26666667 | T20: 0.29791667 | U20: =IF(S20=TIME(17,0,0),"",(S20-T19)*24*60) -> 6 | V20: =(T20-S20)*24*60 -> 45 | AE20: =M20-J20 -> -88 | AF20: =M20/J20 -> 0.956
A21: 新豐7線 | B21: 微波主食 | C21: 韓式泡菜豬肉豆腐丼飯 | E21: 50.67 | F21: 2936 | G21: =E21*F21 -> 148767.12 | I21: 16 | J21: 2000 | K21: =J21/I21 -> 125 | L21: 16 | M21: =F21/V21*60 -> 1914.7826 | N21: =M21/L21 -> 119.67391 | O21: =L21-I21 -> 0 | P21: =N21-K21 -> -5.326087 | Q21: =N21/K21 -> 0.9573913 | S21: 0.30208333 | T21: 0.36597222 | U21: =IF(S21=TIME(17,0,0),"",(S21-T20)*24*60) -> 6 | V21: =(T21-S21)*24*60 -> 92 | AE21: =M21-J21 -> -85.217391 | AF21: =M21/J21 -> 0.9573913
A22: 新豐7線 | B22: 微波主食 | C22: 二配厚香料咖哩雞排飯 | E22: 57.3 | F22: 1770 | G22: =E22*F22 -> 101421 | I22: 13 | J22: 2000 | K22: =J22/I22 -> 153.84615 | L22: 13 | M22: =F22/V22*60 -> 1930.9091 | N22: =M22/L22 -> 148.53147 | O22: =L22-I22 -> 0 | P22: =N22-K22 -> -5.3146853 | Q22: =N22/K22 -> 0.96545455 | S22: 0.70833333 | T22: 0.74652778 | U22: =IF(S22=TIME(17,0,0),"",(S22-T21)*24*60) | V22: =(T22-S22)*24*60 -> 55 | AE22: =M22-J22 -> -69.090909 | AF22: =M22/J22 -> 0.96545455
A23: 新豐7線 | B23: 微波主食 | C23: 二配起司控培根白醬焗烤飯 | E23: 53.68 | F23: 1563 | G23: =E23*F23 -> 83901.84 | I23: 16 | J23: 1500 | K23: =J23/I23 -> 93.75 | L23: 16 | M23: =F23/V23*60 -> 1442.7692 | N23: =M23/L23 -> 90.173077 | O23: =L23-I23 -> 0 | P23: =N23-K23 -> -3.5769231 | Q23: =N23/K23 -> 0.96184615 | S23: 0.75 | T23: 0.79513889 | U23: =IF(S23=TIME(17,0,0),"",(S23-T22)*24*60) -> 5 | V23: =(T23-S23)*24*60 -> 65 | AE23: =M23-J23 -> -57.230769 | AF23: =M23/J23 -> 0.96184615
A24: 新豐7線 | B24: 微波主食 | C24: 二配川味麻婆燒豆腐燴飯 | E24: 50.49 | F24: 2024 | G24: =E24*F24 -> 102191.76 | I24: 15 | J24: 2000 | K24: =J24/I24 -> 133.33333 | L24: 15 | M24: =F24/V24*60 -> 1927.619 | N24: =M24/L24 -> 128.50794 | O24: =L24-I24 -> 0 | P24: =N24-K24 -> -4.8253968 | Q24: =N24/K24 -> 0.96380952 | S24: 0.8 | T24: 0.84375 | U24: =IF(S24=TIME(17,0,0),"",(S24-T23)*24*60) -> 7 | V24: =(T24-S24)*24*60 -> 63 | AE24: =M24-J24 -> -72.380952 | AF24: =M24/J24 -> 0.96380952
A25: 新豐7線 | B25: 平均 | I25: 15 | J25: 1916.6667 | K25: =J25/I25 -> 127.77778 | L25: 15 | M25: =AVERAGE(M19:M24) -> 1840.0646 | N25: =M25/L25 -> 122.67097 | O25: =L25-I25 -> 0 | P25: =N25-K25 -> -5.1068037 | Q25: =N25/K25 -> 0.96003371 | Y25: =SUM(Y19:Y24) -> 0 | Z25: =SUM(Z19:Z24) -> 0 | AC25: 6 | AD25: =SUM(AD19:AD24) -> 0 | AE25: =M25-J25 -> -76.602055 | AF25: =M25/J25 -> 0.96003371
A26: 新豐8線 | B26: 三明治 | C26: 紐奧良風味烤雞鮮蔬三明治 | E26: 31.29 | F26: 6600 | G26: =E26*F26 -> 206514 | H26: 2 | I26: 18 | J26: 2400 | K26: =J26/I26 -> 133.33333 | L26: 18 | M26: =F26/V26*60 -> 2289.0173 | N26: =M26/L26 -> 127.16763 | O26: =L26-I26 -> 0 | P26: =N26-K26 -> -6.1657033 | Q26: =N26/K26 -> 0.95375723 | R26: =Q32 -> 0.95511217 | S26: 0.083333333 | T26: 0.20347222 | V26: =(T26-S26)*24*60 -> 173 | W26: =T26 -> 0.20347222 | X26: =S27 -> 0.22361111 | AC26: 6 | AE26: =M26-J26 -> -110.98266 | AF26: =M26/J26 -> 0.95375723 | AG26: =AF32 -> 0.95511217
A27: 新豐8線 | B27: 三明治 | C27: 好多菜三明治(114年) | E27: 25.98 | F27: 3346 | G27: =E27*F27 -> 86929.08 | I27: 21 | J27: 2400 | K27: =J27/I27 -> 114.28571 | L27: 21 | M27: =F27/V27*60 -> 2281.3636 | N27: =M27/L27 -> 108.63636 | O27: =L27-I27 -> 0 | P27: =N27-K27 -> -5.6493506 | Q27: =N27/K27 -> 0.95056818 | S27: 0.22361111 | T27: 0.28472222 | U27: =(S27-T26)*24*60 -> 29 | V27: =(T27-S27)*24*60 -> 88 | AE27: =M27-J27 -> -118.63636 | AF27: =M27/J27 -> 0.95056818
A28: 新豐8線 | B28: 三明治 | C28: 經典總匯三明治 | E28: 26.2 | F28: 5703 | G28: =E28*F28 -> 149418.6 | I28: 20 | J28: 2400 | K28: =J28/I28 -> 120 | L28: 20 | M28: =F28/V28*60 -> 2296.5101 | N28: =M28/L28 -> 114.8255 | O28: =L28-I28 -> 0 | P28: =N28-K28 -> -5.1744966 | Q28: =N28/K28 -> 0.95687919 | S28: 0.28958333 | T28: 0.39305556 | U28: =(S28-T27)*24*60 -> 7 | V28: =(T28-S28)*24*60 -> 149 | AE28: =M28-J28 -> -103.48993 | AF28: =M28/J28 -> 0.95687919
A29: 新豐8線 | B29: 三明治 | C29: 雞蛋沙拉三明治(114年) | E29: 25.99 | F29: 4421 | G29: =E29*F29 -> 114901.79 | I29: 14 | J29: 2400 | K29: =J29/I29 -> 171.42857 | L29: 14 | M29: =F29/V29*60 -> 2286.7241 | N29: =M29/L29 -> 163.33744 | O29: =L29-I29 -> 0 | P29: =N29-K29 -> -8.091133 | Q29: =N29/K29 -> 0.95280172 | S29: 0.39722222 | T29: 0.47777778 | U29: =(S29-T28)*24*60 -> 6 | V29: =(T29-S29)*24*60 -> 116 | AE29: =M29-J29 -> -113.27586 | AF29: =M29/J29 -> 0.95280172
A30: 新豐8線 | B30: 三明治 | C30: 陽光地瓜總匯三明治 | E30: 26.18 | F30: 1847 | G30: =E30*F30 -> 48354.46 | I30: 19 | J30: 2400 | K30: =J30/I30 -> 126.31579 | L30: 19 | M30: =F30/V30*60 -> 2308.75 | N30: =M30/L30 -> 121.51316 | O30: =L30-I30 -> 0 | P30: =N30-K30 -> -4.8026316 | Q30: =N30/K30 -> 0.96197917 | S30: 0.48333333 | T30: 0.51666667 | U30: =(S30-T29)*24*60 -> 8 | V30: =(T30-S30)*24*60 -> 48 | W30: =T30 -> 0.51666667 | X30: =S31 -> 0.55555556 | AE30: =M30-J30 -> -91.25 | AF30: =M30/J30 -> 0.96197917
A31: 新豐8線 | B31: 三明治 | C31: 紐奧良風味烤雞鮮蔬三明治 | E31: 31.29 | F31: 3666 | G31: =E31*F31 -> 114709.14 | I31: 18 | J31: 2400 | K31: =J31/I31 -> 133.33333 | L31: 18 | M31: =F31/V31*60 -> 2291.25 | N31: =M31/L31 -> 127.29167 | O31: =L31-I31 -> 0 | P31: =N31-K31 -> -6.0416667 | Q31: =N31/K31 -> 0.9546875 | S31: 0.55555556 | T31: 0.62222222 | U31: =(S31-T30)*24*60 -> 56 | V31: =(T31-S31)*24*60 -> 96 | AE31: =M31-J31 -> -108.75 | AF31: =M31/J31 -> 0.9546875
A32: 新豐8線 | B32: 平均 | I32: 18.333333 | J32: 2400 | K32: =J32/I32 -> 130.90909 | L32: 18.333333 | M32: =AVERAGE(M26:M31) -> 2292.2692 | N32: =M32/L32 -> 125.03287 | O32: =L32-I32 -> 0 | P32: =N32-K32 -> -5.8762256 | Q32: =N32/K32 -> 0.95511217 | Y32: =SUM(Y26:Y31) -> 0 | Z32: =SUM(Z26:Z31) -> 0 | AC32: 6 | AD32: =SUM(AD26:AD31) -> 0 | AE32: =M32-J32 -> -107.7308 | AF32: =M32/J32 -> 0.95511217
A33: 新豐9線 | B33: 三明治 | C33: 鮪魚起司溏心蛋三明治 | E33: 26.2 | F33: 4700 | G33: =E33*F33 -> 123140 | H33: 2 | I33: 18 | J33: 2400 | K33: =J33/I33 -> 133.33333 | L33: 18 | M33: =F33/V33*60 -> 2292.6829 | N33: =M33/L33 -> 127.37127 | O33: =L33-I33 -> 0 | P33: =N33-K33 -> -5.9620596 | Q33: =N33/K33 -> 0.95528455 | R33: =Q40 -> 0.95630308 | S33: 0.083333333 | T33: 0.16875 | V33: =(T33-S33)*24*60 -> 123 | W33: =T33 -> 0.16875 | X33: =S34 -> 0.18680556 | AC33: 7 | AE33: =M33-J33 -> -107.31707 | AF33: =M33/J33 -> 0.95528455 | AG33: =AF40 -> 0.95630308
A34: 新豐9線 | B34: 三明治 | C34: 肉鬆火腿三明治 | E34: 20.52 | F34: 4136 | G34: =E34*F34 -> 84870.72 | I34: 18 | J34: 2400 | K34: =J34/I34 -> 133.33333 | L34: 18 | M34: =F34/V34*60 -> 2297.7778 | N34: =M34/L34 -> 127.65432 | O34: =L34-I34 -> 0 | P34: =N34-K34 -> -5.6790123 | Q34: =N34/K34 -> 0.95740741 | S34: 0.18680556 | T34: 0.26180556 | U34: =(S34-T33)*24*60 -> 26 | V34: =(T34-S34)*24*60 -> 108 | AE34: =M34-J34 -> -102.22222 | AF34: =M34/J34 -> 0.95740741
A35: 新豐9線 | B35: 三明治 | C35: 醬燒烤雞三明治 | E35: 26.39 | F35: 4200 | G35: =E35*F35 -> 110838 | H35: 2 | I35: 19 | J35: 2400 | K35: =J35/I35 -> 126.31579 | L35: 19 | M35: =F35/V35*60 -> 2290.9091 | N35: =M35/L35 -> 120.57416 | O35: =L35-I35 -> 0 | P35: =N35-K35 -> -5.7416268 | Q35: =N35/K35 -> 0.95454545 | S35: 0.26736111 | T35: 0.34375 | U35: =(S35-T34)*24*60 -> 8 | V35: =(T35-S35)*24*60 -> 110 | AE35: =M35-J35 -> -109.09091 | AF35: =M35/J35 -> 0.95454545
A36: 新豐9線 | B36: 三明治 | C36: 輕乳酪巧克力三明治 | E36: 20.52 | F36: 2949 | G36: =E36*F36 -> 60513.48 | I36: 18 | J36: 2400 | K36: =J36/I36 -> 133.33333 | L36: 18 | M36: =F36/V36*60 -> 2297.9221 | N36: =M36/L36 -> 127.66234 | O36: =L36-I36 -> 0 | P36: =N36-K36 -> -5.6709957 | Q36: =N36/K36 -> 0.95746753 | S36: 0.34791667 | T36: 0.40138889 | U36: =(S36-T35)*24*60 -> 6 | V36: =(T36-S36)*24*60 -> 77 | AE36: =M36-J36 -> -102.07792 | AF36: =M36/J36 -> 0.95746753
A37: 新豐9線 | B37: 三明治 | C37: 香蕉可可三明治 | E37: 22.69 | F37: 5744 | G37: =E37*F37 -> 130331.36 | I37: 15 | J37: 2400 | K37: =J37/I37 -> 160 | L37: 15 | M37: =F37/V37*60 -> 2282.3841 | N37: =M37/L37 -> 152.15894 | O37: =L37-I37 -> 0 | P37: =N37-K37 -> -7.8410596 | Q37: =N37/K37 -> 0.95099338 | S37: 0.40486111 | T37: 0.50972222 | U37: =(S37-T36)*24*60 -> 5 | V37: =(T37-S37)*24*60 -> 151 | W37: =T37 -> 0.50972222 | X37: =S38 -> 0.54930556 | AE37: =M37-J37 -> -117.61589 | AF37: =M37/J37 -> 0.95099338
A38: 新豐9線 | B38: 三明治 | C38: 鮪魚起司溏心蛋三明治 | E38: 26.2 | F38: 2585 | G38: =E38*F38 -> 67727 | I38: 18 | J38: 2400 | K38: =J38/I38 -> 133.33333 | L38: 18 | M38: =F38/V38*60 -> 2280.8824 | N38: =M38/L38 -> 126.71569 | O38: =L38-I38 -> 0 | P38: =N38-K38 -> -6.6176471 | Q38: =N38/K38 -> 0.95036765 | S38: 0.54930556 | T38: 0.59652778 | U38: =(S38-T37)*24*60 -> 57 | V38: =(T38-S38)*24*60 -> 68 | AE38: =M38-J38 -> -119.11765 | AF38: =M38/J38 -> 0.95036765
A39: 新豐9線 | B39: 三明治 | C39: 醬燒烤雞三明治 | E39: 26.39 | F39: 2091 | G39: =E39*F39 -> 55181.49 | I39: 19 | J39: 2400 | K39: =J39/I39 -> 126.31579 | L39: 19 | M39: =F39/V39*60 -> 2323.3333 | N39: =M39/L39 -> 122.2807 | O39: =L39-I39 -> 0 | P39: =N39-K39 -> -4.0350877 | Q39: =N39/K39 -> 0.96805556 | S39: 0.60069444 | T39: 0.63819444 | U39: =(S39-T38)*24*60 -> 6 | V39: =(T39-S39)*24*60 -> 54 | AE39: =M39-J39 -> -76.666667 | AF39: =M39/J39 -> 0.96805556
A40: 新豐9線 | B40: 平均 | I40: 17.857143 | J40: 2400 | K40: =J40/I40 -> 134.4 | L40: 17.857143 | M40: =AVERAGE(M33:M39) -> 2295.1274 | N40: =M40/L40 -> 128.52713 | O40: =L40-I40 -> 0 | P40: =N40-K40 -> -5.8728667 | Q40: =N40/K40 -> 0.95630308 | Y40: =SUM(Y33:Y39) -> 0 | Z40: =SUM(Z33:Z39) -> 0 | AC40: 7 | AD40: =SUM(AD33:AD39) -> 0 | AE40: =M40-J40 -> -104.87262 | AF40: =M40/J40 -> 0.95630308
...

Sheet 0330
B1: 屏榮 新豐廠組合室生產人時性分析
B3: 日期 | C3: =TEXT('0330 4度C'!A2,"yyyy.mm.ddaaaa") -> 2026.03.30星期一 | E3: 訂單量 | F3: ='0330 4度C'!D1 -> 168199 | H3: 營業額 | I3: ='0330 4度C'!F1 -> 5588964.2
B4: 人時性 | C4: 項目 | E4: ➀ | G4: ➁ | I4: ➂ | K4: 異常停線 | M4: 短暫停線
C5: 組合室 | E5: 全溫層 | G5: 4度C-各編組展開 | I5: ③三明治-各編組展開 | K5: 合計次數 | L5: 時間 | M5: 合計次數 | N5: 設備次數
C6: 排關平均 | E6: =AVERAGE(D13:M13) -> 155.66761 | F6: =AVERAGE(D31:O31,D13:J13) -> 161.87503 | G6: =AVERAGE(D13:J13) -> 161.87503 | I6: =AVERAGE(K13:M13) -> 141.18362 | K6: ='0330 4度C'!Y2 -> 0 | L6: ='0330 4度C'!Z2 -> 0 | M6: ='0330 4度C'!AC2 -> 54 | N6: ='0330 4度C'!AD2 -> 0
C7: 實績平均 | E7: =AVERAGE(D14:M14) -> 149.21971 | F7: =AVERAGE(D32:O32,D14:J14) -> 155.40356 | G7: =AVERAGE(D14:J14) -> 155.40356 | I7: =AVERAGE(K14:M14) -> 134.79074
C8: 達成率平均 | E8: =AVERAGE(D15:M15) -> 0.95827783 | F8: =AVERAGE(D15:J15,D33:O33) -> 0.95975142 | G8: =AVERAGE(D15:J15) -> 0.95975142 | I8: =AVERAGE(K15:M15) -> 0.95483947
K9: ※現行日本鮮食廠以達成率80%為基本(即為現行KPI)
B10: 溫層 | D10: ➁4度C-各編組展開 | K10: ③三明治-各編組展開
B11: 編組 | D11: 1 | E11: 2 | F11: 3 | G11: 4 | H11: 5 | I11: 6 | J11: 7 | K11: 1 | L11: 2 | M11: 3
D12: 新豐6線 | E12: 新豐2線 | F12: 新豐5線 | G12: 新豐7線 | H12: 新豐3線 | I12: 新豐1線 | J12: 新豐10線 | K12: 新豐8線 | L12: 新豐9線 | M12: 新豐4線
B13: 人時性 | C13: 排關 | D13: =SUMIFS('0330 4度C'!$K:$K,'0330 4度C'!$A:$A,"新豐6線",'0330 4度C'!$B:$B,"平均") -> 111.11111 | E13: =SUMIFS('0330 4度C'!$K:$K,'0330 4度C'!$A:$A,"新豐2線",'0330 4度C'!$B:$B,"平均") -> 84.90566 | F13: =SUMIFS('0330 4度C'!$K:$K,'0330 4度C'!$A:$A,"新豐5線",'0330 4度C'!$B:$B,"平均") -> 102.73973 | G13: =SUMIFS('0330 4度C'!$K:$K,'0330 4度C'!$A:$A,"新豐7線",'0330 4度C'!$B:$B,"平均") -> 127.77778 | H13: =SUMIFS('0330 4度C'!$K:$K,'0330 4度C'!$A:$A,"新豐3線",'0330 4度C'!$B:$B,"平均") -> 333.33333 | I13: =SUMIFS('0330 4度C'!$K:$K,'0330 4度C'!$A:$A,"新豐1線",'0330 4度C'!$B:$B,"平均") -> 104.02685 | J13: =SUMIFS('0330 4度C'!$K:$K,'0330 4度C'!$A:$A,"新豐10線",'0330 4度C'!$B:$B,"平均") -> 269.23077 | K13: =SUMIFS('0330 4度C'!$K:$K,'0330 4度C'!$A:$A,"新豐8線",'0330 4度C'!$B:$B,"平均") -> 130.90909 | L13: =SUMIFS('0330 4度C'!$K:$K,'0330 4度C'!$A:$A,"新豐9線",'0330 4度C'!$B:$B,"平均") -> 134.4 | M13: =SUMIFS('0330 4度C'!$K:$K,'0330 4度C'!$A:$A,"新豐4線",'0330 4度C'!$B:$B,"平均") -> 158.24176
C14: 實績 | D14: =SUMIFS('0330 4度C'!$N:$N,'0330 4度C'!$A:$A,"新豐6線",'0330 4度C'!$B:$B,"平均") -> 107.5928 | E14: =SUMIFS('0330 4度C'!$N:$N,'0330 4度C'!$A:$A,"新豐2線",'0330 4度C'!$B:$B,"平均") -> 80.99009 | F14: =SUMIFS('0330 4度C'!$N:$N,'0330 4度C'!$A:$A,"新豐5線",'0330 4度C'!$B:$B,"平均") -> 98.502521 | G14: =SUMIFS('0330 4度C'!$N:$N,'0330 4度C'!$A:$A,"新豐7線",'0330 4度C'!$B:$B,"平均") -> 122.59424 | H14: =SUMIFS('0330 4度C'!$N:$N,'0330 4度C'!$A:$A,"新豐3線",'0330 4度C'!$B:$B,"平均") -> 319.18008 | I14: =SUMIFS('0330 4度C'!$N:$N,'0330 4度C'!$A:$A,"新豐1線",'0330 4度C'!$B:$B,"平均") -> 99.516691 | J14: =SUMIFS('0330 4度C'!$N:$N,'0330 4度C'!$A:$A,"新豐10線",'0330 4度C'!$B:$B,"平均") -> 259.44848 | K14: =SUMIFS('0330 4度C'!$N:$N,'0330 4度C'!$A:$A,"新豐8線",'0330 4度C'!$B:$B,"平均") -> 125.02277 | L14: =SUMIFS('0330 4度C'!$N:$N,'0330 4度C'!$A:$A,"新豐9線",'0330 4度C'!$B:$B,"平均") -> 128.58694 | M14: =SUMIFS('0330 4度C'!$N:$N,'0330 4度C'!$A:$A,"新豐4線",'0330 4度C'!$B:$B,"平均") -> 150.76252
C15: 達成率 | D15: =D14/D13 -> 0.96833523 | E15: =E14/E13 -> 0.95388328 | F15: =F14/F13 -> 0.95875787 | G15: =G14/G13 -> 0.95943318 | H15: =H14/H13 -> 0.95754024 | I15: =I14/I13 -> 0.95664432 | J15: =J14/J13 -> 0.96366579 | K15: =K14/K13 -> 0.95503501 | ... M15: =M14/M13 -> 0.95273534
B16: 作業 時間 | C16: 開始 | D16: =VLOOKUP("新豐6線",'0330 4度C'!$A:$T,19,0) -> 0.70833333 | E16: =VLOOKUP("新豐2線",'0330 4度C'!$A:$T,19,0) -> 0.20833333 | F16: =VLOOKUP("新豐5線",'0330 4度C'!$A:$T,19,0) -> 0.20833333 | G16: =VLOOKUP("新豐7線",'0330 4度C'!$A:$T,19,0) -> 0.20833333 | H16: =VLOOKUP("新豐3線",'0330 4度C'!$A:$T,19,0) -> 0.083333333 | I16: =VLOOKUP("新豐1線",'0330 4度C'!$A:$T,19,0) -> 0.20833333 | J16: =VLOOKUP("新豐10線",'0330 4度C'!$A:$T,19,0) -> 0.20833333 | K16: =VLOOKUP("新豐8線",'0330 4度C'!$A:$T,19,0) -> 0.083333333 | L16: =VLOOKUP("新豐9線",'0330 4度C'!$A:$T,19,0) -> 0.083333333 | M16: =VLOOKUP("新豐4線",'0330 4度C'!$A:$T,19,0) -> 0.083333333
C17: 結束 | D17: =LOOKUP(2,1/(('0330 4度C'!$A:$A="新豐6線")*('0330 4度C'!$T:$T<>"")),'0330 4度C'!$T:$T) -> 0.82777778 | E17: =LOOKUP(2,1/(('0330 4度C'!$A:$A="新豐2線")*('0330 4度C'!$T:$T<>"")),'0330 4度C'!$T:$T) -> 0.61180556 | F17: =LOOKUP(2,1/(('0330 4度C'!$A:$A="新豐5線")*('0330 4度C'!$T:$T<>"")),'0330 4度C'!$T:$T) -> 0.84375 | G17: =LOOKUP(2,1/(('0330 4度C'!$A:$A="新豐7線")*('0330 4度C'!$T:$T<>"")),'0330 4度C'!$T:$T) -> 0.85069444 | H17: =LOOKUP(2,1/(('0330 4度C'!$A:$A="新豐3線")*('0330 4度C'!$T:$T<>"")),'0330 4度C'!$T:$T) -> 0.47222222 | I17: =LOOKUP(2,1/(('0330 4度C'!$A:$A="新豐1線")*('0330 4度C'!$T:$T<>"")),'0330 4度C'!$T:$T) -> 0.90208333 | J17: =LOOKUP(2,1/(('0330 4度C'!$A:$A="新豐10線")*('0330 4度C'!$T:$T<>"")),'0330 4度C'!$T:$T) -> 0.45347222 | K17: =LOOKUP(2,1/(('0330 4度C'!$A:$A="新豐8線")*('0330 4度C'!$T:$T<>"")),'0330 4度C'!$T:$T) -> 0.61805556 | L17: =LOOKUP(2,1/(('0330 4度C'!$A:$A="新豐9線")*('0330 4度C'!$T:$T<>"")),'0330 4度C'!$T:$T) -> 0.65347222 | M17: =LOOKUP(2,1/(('0330 4度C'!$A:$A="新豐4線")*('0330 4度C'!$T:$T<>"")),'0330 4度C'!$T:$T) -> 0.62777778
B18: 產線異常 (5分鐘以上) | C18: 次數 | D18: =SUMIFS('0330 4度C'!$Y:$Y,'0330 4度C'!$A:$A,"新豐6線",'0330 4度C'!$B:$B,"平均") -> 0 | E18: =SUMIFS('0330 4度C'!$Y:$Y,'0330 4度C'!$A:$A,"新豐2線",'0330 4度C'!$B:$B,"平均") -> 0 | F18: =SUMIFS('0330 4度C'!$Y:$Y,'0330 4度C'!$A:$A,"新豐5線",'0330 4度C'!$B:$B,"平均") -> 0 | G18: =SUMIFS('0330 4度C'!$Y:$Y,'0330 4度C'!$A:$A,"新豐7線",'0330 4度C'!$B:$B,"平均") -> 0 | H18: =SUMIFS('0330 4度C'!$Y:$Y,'0330 4度C'!$A:$A,"新豐3線",'0330 4度C'!$B:$B,"平均") -> 0 | I18: =SUMIFS('0330 4度C'!$Y:$Y,'0330 4度C'!$A:$A,"新豐1線",'0330 4度C'!$B:$B,"平均") -> 0 | J18: =SUMIFS('0330 4度C'!$Y:$Y,'0330 4度C'!$A:$A,"新豐10線",'0330 4度C'!$B:$B,"平均") -> 0 | K18: =SUMIFS('0330 4度C'!$Y:$Y,'0330 4度C'!$A:$A,"新豐8線",'0330 4度C'!$B:$B,"平均") -> 0 | L18: =SUMIFS('0330 4度C'!$Y:$Y,'0330 4度C'!$A:$A,"新豐9線",'0330 4度C'!$B:$B,"平均") -> 0 | M18: =SUMIFS('0330 4度C'!$Y:$Y,'0330 4度C'!$A:$A,"新豐4線",'0330 4度C'!$B:$B,"平均") -> 0
C19: 時間/分 | D19: =SUMIFS('0330 4度C'!$Z:$Z,'0330 4度C'!$A:$A,"新豐6線",'0330 4度C'!$B:$B,"平均") -> 0 | E19: =SUMIFS('0330 4度C'!$Z:$Z,'0330 4度C'!$A:$A,"新豐2線",'0330 4度C'!$B:$B,"平均") -> 0 | F19: =SUMIFS('0330 4度C'!$Z:$Z,'0330 4度C'!$A:$A,"新豐5線",'0330 4度C'!$B:$B,"平均") -> 0 | G19: =SUMIFS('0330 4度C'!$Z:$Z,'0330 4度C'!$A:$A,"新豐7線",'0330 4度C'!$B:$B,"平均") -> 0 | H19: =SUMIFS('0330 4度C'!$Z:$Z,'0330 4度C'!$A:$A,"新豐3線",'0330 4度C'!$B:$B,"平均") -> 0 | I19: =SUMIFS('0330 4度C'!$Z:$Z,'0330 4度C'!$A:$A,"新豐1線",'0330 4度C'!$B:$B,"平均") -> 0 | J19: =SUMIFS('0330 4度C'!$Z:$Z,'0330 4度C'!$A:$A,"新豐10線",'0330 4度C'!$B:$B,"平均") -> 0 | K19: =SUMIFS('0330 4度C'!$Z:$Z,'0330 4度C'!$A:$A,"新豐8線",'0330 4度C'!$B:$B,"平均") -> 0 | L19: =SUMIFS('0330 4度C'!$Z:$Z,'0330 4度C'!$A:$A,"新豐9線",'0330 4度C'!$B:$B,"平均") -> 0 | M19: =SUMIFS('0330 4度C'!$Z:$Z,'0330 4度C'!$A:$A,"新豐4線",'0330 4度C'!$B:$B,"平均") -> 0
B20: 短暫停線 (5分鐘以下) | C20: 次數 | D20: =SUMIFS('0330 4度C'!$AC:$AC,'0330 4度C'!$A:$A,"新豐6線",'0330 4度C'!$B:$B,"平均") -> 4 | E20: =SUMIFS('0330 4度C'!$AC:$AC,'0330 4度C'!$A:$A,"新豐2線",'0330 4度C'!$B:$B,"平均") -> 3 | F20: =SUMIFS('0330 4度C'!$AC:$AC,'0330 4度C'!$A:$A,"新豐5線",'0330 4度C'!$B:$B,"平均") -> 4 | G20: =SUMIFS('0330 4度C'!$AC:$AC,'0330 4度C'!$A:$A,"新豐7線",'0330 4度C'!$B:$B,"平均") -> 6 | H20: =SUMIFS('0330 4度C'!$AC:$AC,'0330 4度C'!$A:$A,"新豐3線",'0330 4度C'!$B:$B,"平均") -> 5 | I20: =SUMIFS('0330 4度C'!$AC:$AC,'0330 4度C'!$A:$A,"新豐1線",'0330 4度C'!$B:$B,"平均") -> 8 | J20: =SUMIFS('0330 4度C'!$AC:$AC,'0330 4度C'!$A:$A,"新豐10線",'0330 4度C'!$B:$B,"平均") -> 5 | K20: =SUMIFS('0330 4度C'!$AC:$AC,'0330 4度C'!$A:$A,"新豐8線",'0330 4度C'!$B:$B,"平均") -> 6 | L20: =SUMIFS('0330 4度C'!$AC:$AC,'0330 4度C'!$A:$A,"新豐9線",'0330 4度C'!$B:$B,"平均") -> 7 | M20: =SUMIFS('0330 4度C'!$AC:$AC,'0330 4度C'!$A:$A,"新豐4線",'0330 4度C'!$B:$B,"平均") -> 6
C21: 設備次數 | D21: =SUMIFS('0330 4度C'!$AD:$AD,'0330 4度C'!$A:$A,"新豐6線",'0330 4度C'!$B:$B,"平均") -> 0 | E21: =SUMIFS('0330 4度C'!$AD:$AD,'0330 4度C'!$A:$A,"新豐2線",'0330 4度C'!$B:$B,"平均") -> 0 | F21: =SUMIFS('0330 4度C'!$AD:$AD,'0330 4度C'!$A:$A,"新豐5線",'0330 4度C'!$B:$B,"平均") -> 0 | G21: =SUMIFS('0330 4度C'!$AD:$AD,'0330 4度C'!$A:$A,"新豐7線",'0330 4度C'!$B:$B,"平均") -> 0 | H21: =SUMIFS('0330 4度C'!$AD:$AD,'0330 4度C'!$A:$A,"新豐3線",'0330 4度C'!$B:$B,"平均") -> 0 | I21: =SUMIFS('0330 4度C'!$AD:$AD,'0330 4度C'!$A:$A,"新豐1線",'0330 4度C'!$B:$B,"平均") -> 0 | J21: =SUMIFS('0330 4度C'!$AD:$AD,'0330 4度C'!$A:$A,"新豐10線",'0330 4度C'!$B:$B,"平均") -> 0 | K21: =SUMIFS('0330 4度C'!$AD:$AD,'0330 4度C'!$A:$A,"新豐8線",'0330 4度C'!$B:$B,"平均") -> 0 | L21: =SUMIFS('0330 4度C'!$AD:$AD,'0330 4度C'!$A:$A,"新豐9線",'0330 4度C'!$B:$B,"平均") -> 0 | M21: =SUMIFS('0330 4度C'!$AD:$AD,'0330 4度C'!$A:$A,"新豐4線",'0330 4度C'!$B:$B,"平均") -> 0
B22: 配置人數 | D22: =SUMIFS('0330 4度C'!$I:$I,'0330 4度C'!$A:$A,"新豐6線",'0330 4度C'!$B:$B,"平均") -> 18 | E22: =SUMIFS('0330 4度C'!$I:$I,'0330 4度C'!$A:$A,"新豐2線",'0330 4度C'!$B:$B,"平均") -> 17.666667 | F22: =SUMIFS('0330 4度C'!$I:$I,'0330 4度C'!$A:$A,"新豐5線",'0330 4度C'!$B:$B,"平均") -> 18.25 | G22: =SUMIFS('0330 4度C'!$I:$I,'0330 4度C'!$A:$A,"新豐7線",'0330 4度C'!$B:$B,"平均") -> 15 | H22: =SUMIFS('0330 4度C'!$I:$I,'0330 4度C'!$A:$A,"新豐3線",'0330 4度C'!$B:$B,"平均") -> 9 | I22: =SUMIFS('0330 4度C'!$I:$I,'0330 4度C'!$A:$A,"新豐1線",'0330 4度C'!$B:$B,"平均") -> 18.625 | J22: =SUMIFS('0330 4度C'!$I:$I,'0330 4度C'!$A:$A,"新豐10線",'0330 4度C'!$B:$B,"平均") -> 10.4 | K22: =SUMIFS('0330 4度C'!$I:$I,'0330 4度C'!$A:$A,"新豐8線",'0330 4度C'!$B:$B,"平均") -> 18.333333 | L22: =SUMIFS('0330 4度C'!$I:$I,'0330 4度C'!$A:$A,"新豐9線",'0330 4度C'!$B:$B,"平均") -> 17.857143 | M22: =SUMIFS('0330 4度C'!$I:$I,'0330 4度C'!$A:$A,"新豐4線",'0330 4度C'!$B:$B,"平均") -> 15.166667
B23: 主要應用設備 | D23: ET-55 | E23: 熱縮爐 | F23: L型包裝機 | G23: L型包裝機 | H23: 伺服包裝機 | I23: ET-55 | J23: 伺服包裝機 | K23: 三明治包裝機 | L23: 三明治包裝機 | M23: 三明治包裝機
B24: 次要應用設備 | F24: 圓盤機 | G24: ET-55
B25: 備註 | E25: 握沙拉 | F25: 共用L型包裝機 | H25: 調理麵包 | I25: 炒飯+沙拉 | J25: 調理麵包

Sheet 0330 4度C
A1: 新豐廠四度C日報分析 | C1: 總生產量 | D1: =SUM(F5:F68) -> 168199 | E1: 營業額 | F1: =SUM(G5:G68) -> 5588964.2 | G1: 出勤人數 | H1: =L9+L13+L46+L55+L18+L61+L32+L40+L25+L68 -> 158.29881 | I1: 產線配置圖 | L1: 生產實績 | O1: 人時性差異分析 | S1: 日報登錄 | Y1: 合計 次數 | Z1: 合計 時間/分 | AA1: 產線異常 分析說明(5分鐘以上) | AC1: 合計 次數 | AD1: 合計 設備次數 | AE1: 產能差異分析
A2: 46111 | B2: 星期一 | C2: 人時性 | D2: =AVERAGE(N9,N13,N46,N55,N18,N61,N25,N32,N40,N68) -> 149.21971 | E2: 平均廠價 | F2: =F1/D1 -> 33.228285 | G2: 多次生產數 | H2: =COUNT(H5:H68) -> 6 | Y2: =SUM(Y9+Y13+Y18+Y25+Y32+Y40+Y46+Y55+Y61+Y68) -> 0 | Z2: =SUM(Z9+Z13+Z18+Z25+Z32+Z40+Z46+Z55+Z61+Z68) -> 0 | AC2: 54 | AD2: =SUM(AD9+AD13+AD18+AD25+AD32+AD40+AD46+AD55+AD61+AD68) -> 0
A3: 線別 | B3: 品類 | C3: 品名 | E3: 廠價 | F3: 生產量 | G3: 營收 | H3: 多次 生產 | I3: 人數 | J3: 產能/時 | K3: 人時性 | L3: 人數 | M3: 產能/時 | N3: 人時性 | O3: 人數 | P3: 人時性 | Q3: 達成率 | R3: 達成率平均 | S3: 生產時間 | U3: 換線、休息/分 | V3: 稼動時間/分 | W3: 休息時間 | Y3: 產線異常統計 (5分鐘以上) | AA3: (新豐回填) | AC3: 短暫停線統計 (5分鐘以下) | AE3: 產能/時 | AF3: 達成率 | AG3: 達成率平均
S4: 開始 | T4: 結束 | W4: 開始 | X4: 結束 | Y4: 次數 | Z4: 時間/分 | AC4: 總次數 | AD4: 設備因素(次數)
A5: 新豐6線 | B5: 微波主食 | C5: 二配港式香滑嫩蛋牛肉燴飯 | E5: 50.67 | F5: 1548 | G5: =E5*F5 -> 78437.16 | I5: 17 | J5: 2000 | K5: =J5/I5 -> 117.64706 | L5: 17 | M5: =F5/V5*60 -> 1935 | N5: =M5/L5 -> 113.82353 | O5: =L5-I5 -> 0 | P5: =N5-K5 -> -3.8235294 | Q5: =N5/K5 -> 0.9675 | R5: =Q9 -> 0.96833523 | S5: 0.70833333 | T5: 0.74166667 | V5: =(T5-S5)*24*60 -> 48 | AC5: 4 | AE5: =M5-J5 -> -65 | AF5: =M5/J5 -> 0.9675 | AG5: =AF9 -> 0.96833523
A6: 新豐6線 | B6: 微波主食 | C6: 二配美味蟹煲 | E6: 54.09 | F6: 1273 | G6: =E6*F6 -> 68856.57 | I6: 19 | J6: 2000 | K6: =J6/I6 -> 105.26316 | L6: 19 | M6: =F6/V6*60 -> 1909.5 | N6: =M6/L6 -> 100.5 | O6: =L6-I6 -> 0 | P6: =N6-K6 -> -4.7631579 | Q6: =N6/K6 -> 0.95475 | S6: 0.74583333 | T6: 0.77361111 | U6: =IF(S6=TIME(17,0,0),"",(S6-T5)*24*60) -> 6 | V6: =(T6-S6)*24*60 -> 40 | AE6: =M6-J6 -> -90.5 | AF6: =M6/J6 -> 0.95475
A7: 新豐6線 | B7: 微波主食 | C7: 二配濃蕃茄火腿蛋包飯 | E7: 50.67 | F7: 330 | G7: =E7*F7 -> 16721.1 | I7: 21 | J7: 2000 | K7: =J7/I7 -> 95.238095 | L7: 21 | M7: =F7/V7*60 -> 1980 | N7: =M7/L7 -> 94.285714 | O7: =L7-I7 -> 0 | P7: =N7-K7 -> -0.95238095 | Q7: =N7/K7 -> 0.99 | S7: 0.77708333 | T7: 0.78402778 | U7: =IF(S7=TIME(17,0,0),"",(S7-T6)*24*60) -> 5 | V7: =(T7-S7)*24*60 -> 10 | AE7: =M7-J7 -> -20 | AF7: =M7/J7 -> 0.99
A8: 新豐6線 | B8: 微波主食 | C8: 二配泰式綠咖哩雞 | E8: 50.67 | F8: 1762 | G8: =E8*F8 -> 89280.54 | I8: 15 | J8: 2000 | K8: =J8/I8 -> 133.33333 | L8: 15 | M8: =F8/V8*60 -> 1922.1818 | N8: =M8/L8 -> 128.14545 | O8: =L8-I8 -> 0 | P8: =N8-K8 -> -5.1878788 | Q8: =N8/K8 -> 0.96109091 | S8: 0.78958333 | T8: 0.82777778 | U8: =IF(S8=TIME(17,0,0),"",(S8-T7)*24*60) -> 8 | V8: =(T8-S8)*24*60 -> 55 | AE8: =M8-J8 -> -77.818182 | AF8: =M8/J8 -> 0.96109091
A9: 新豐6線 | B9: 平均 | I9: 18 | J9: 2000 | K9: =J9/I9 -> 111.11111 | L9: 18 | M9: =AVERAGE(M5:M8) -> 1936.6705 | N9: =M9/L9 -> 107.5928 | O9: =L9-I9 -> 0 | P9: =N9-K9 -> -3.5183081 | Q9: =N9/K9 -> 0.96833523 | Y9: =SUM(Y5:Y8) -> 0 | Z9: =SUM(Z5:Z8) -> 0 | AC9: 4 | AD9: =SUM(AD5:AD8) -> 0 | AE9: =M9-J9 -> -63.329545 | AF9: =M9/J9 -> 0.96833523
A10: 新豐2線 | B10: 沙拉 | C10: 青醬優格雞肉握沙拉(113年) | E10: 39.62 | F10: 4766 | G10: =E10*F10 -> 188828.92 | I10: 19 | J10: 1500 | K10: =J10/I10 -> 78.947368 | L10: 19 | M10: =F10/V10*60 -> 1429.8 | N10: =M10/L10 -> 75.252632 | O10: =L10-I10 -> 0 | P10: =N10-K10 -> -3.6947368 | Q10: =N10/K10 -> 0.9532 | R10: =Q13 -> 0.95388328 | S10: 0.20833333 | T10: 0.34722222 | V10: =(T10-S10)*24*60 -> 200 | AC10: 3 | AE10: =M10-J10 -> -70.2 | AF10: =M10/J10 -> 0.9532 | AG10: =AF13 -> 0.95388328
A11: 新豐2線 | B11: 沙拉 | C11: 青檸烤雞握沙拉(113年) | E11: 39.8 | F11: 4600 | G11: =E11*F11 -> 183080 | H11: 2 | I11: 17 | J11: 1500 | K11: =J11/I11 -> 88.235294 | L11: 17 | M11: =F11/V11*60 -> 1430.0518 | N11: =M11/L11 -> 84.120695 | O11: =L11-I11 -> 0 | P11: =N11-K11 -> -4.1145992 | Q11: =N11/K11 -> 0.95336788 | S11: 0.35277778 | T11: 0.48680556 | U11: =IF(S11=TIME(17,0,0),"",(S11-T10)*24*60) -> 8 | V11: =(T11-S11)*24*60 -> 193 | W11: =T11 -> 0.48680556 | X11: =S12 -> 0.52708333 | AE11: =M11-J11 -> -69.948187 | AF11: =M11/J11 -> 0.95336788
A12: 新豐2線 | B12: 沙拉 | C12: 青檸烤雞握沙拉(113年) | E12: 39.8 | F12: 2913 | G12: =E12*F12 -> 115937.4 | I12: 17 | J12: 1500 | K12: =J12/I12 -> 88.235294 | L12: 17 | M12: =F12/V12*60 -> 1432.623 | N12: =M12/L12 -> 84.271938 | O12: =L12-I12 -> 0 | P12: =N12-K12 -> -3.9633558 | Q12: =N12/K12 -> 0.95508197 | S12: 0.52708333 | T12: 0.61180556 | U12: =IF(S12=TIME(17,0,0),"",(S12-T11)*24*60) -> 58 | V12: =(T12-S12)*24*60 -> 122 | AE12: =M12-J12 -> -67.377049 | AF12: =M12/J12 -> 0.95508197
A13: 新豐2線 | B13: 平均 | I13: 17.666667 | J13: 1500 | K13: =J13/I13 -> 84.90566 | L13: 17.666667 | M13: =AVERAGE(M10:M12) -> 1430.8249 | N13: =M13/L13 -> 80.99009 | O13: =L13-I13 -> 0 | P13: =N13-K13 -> -3.9155705 | Q13: =N13/K13 -> 0.95388328 | Y13: =SUM(Y10:Y12) -> 0 | Z13: =SUM(Z10:Z12) -> 0 | AC13: 3 | AD13: =SUM(AD10:AD12) -> 0 | AE13: =M13-J13 -> -69.175079 | AF13: =M13/J13 -> 0.95388328
A14: 新豐5線 | B14: 小吃 | C14: 剝皮辣椒雞湯 | E14: 41 | F14: 2590 | G14: =E14*F14 -> 106190 | I14: 26 | J14: 1500 | K14: =J14/I14 -> 57.692308 | L14: 26 | M14: =F14/V14*60 -> 1425.6881 | N14: =M14/L14 -> 54.834157 | O14: =L14-I14 -> 0 | P14: =N14-K14 -> -2.858151 | Q14: =N14/K14 -> 0.95045872 | R14: =Q18 -> 0.95875787 | S14: 0.20833333 | T14: 0.28402778 | V14: =(T14-S14)*24*60 -> 109 | AC14: 4 | AE14: =M14-J14 -> -74.311927 | AF14: =M14/J14 -> 0.95045872 | AG14: =AF18 -> 0.95875787
A15: 新豐5線 | B15: 微波主食 | C15: 二配金咖哩濃厚辛口咖哩飯 | E15: 50.98 | F15: 2608 | G15: =E15*F15 -> 132955.84 | I15: 16 | J15: 2000 | K15: =J15/I15 -> 125 | L15: 16 | M15: =F15/V15*60 -> 1908.2927 | N15: =M15/L15 -> 119.26829 | O15: =L15-I15 -> 0 | P15: =N15-K15 -> -5.7317073 | Q15: =N15/K15 -> 0.95414634 | S15: 0.70833333 | T15: 0.76527778 | U15: =IF(S15=TIME(17,0,0),"",(S15-T14)*24*60) | V15: =(T15-S15)*24*60 -> 82 | AE15: =M15-J15 -> -91.707317 | AF15: =M15/J15 -> 0.95414634
A16: 新豐5線 | B16: 微波主食 | C16: 二配香炒沙茶豬肉飯 | E16: 50.67 | F16: 680 | G16: =E16*F16 -> 34455.6 | I16: 16 | J16: 2000 | K16: =J16/I16 -> 125 | L16: 16 | M16: =F16/V16*60 -> 1942.8571 | N16: =M16/L16 -> 121.42857 | O16: =L16-I16 -> 0 | P16: =N16-K16 -> -3.5714286 | Q16: =N16/K16 -> 0.97142857 | S16: 0.77013889 | T16: 0.78472222 | U16: =IF(S16=TIME(17,0,0),"",(S16-T15)*24*60) -> 7 | V16: =(T16-S16)*24*60 -> 21 | AE16: =M16-J16 -> -57.142857 | AF16: =M16/J16 -> 0.97142857
A17: 新豐5線 | B17: 微波主食 | C17: 二配金咖哩果香甘口咖哩飯 | E17: 50.92 | F17: 2488 | G17: =E17*F17 -> 126688.96 | I17: 15 | J17: 2000 | K17: =J17/I17 -> 133.33333 | L17: 15 | M17: =F17/V17*60 -> 1913.8462 | N17: =M17/L17 -> 127.58974 | O17: =L17-I17 -> 0 | P17: =N17-K17 -> -5.7435897 | Q17: =N17/K17 -> 0.95692308 | S17: 0.78958333 | T17: 0.84375 | U17: =IF(S17=TIME(17,0,0),"",(S17-T16)*24*60) -> 7 | V17: =(T17-S17)*24*60 -> 78 | AE17: =M17-J17 -> -86.153846 | AF17: =M17/J17 -> 0.95692308
A18: 新豐5線 | B18: 平均 | I18: 18.25 | J18: 1875 | K18: =J18/I18 -> 102.73973 | L18: 18.25 | M18: =AVERAGE(M14:M17) -> 1797.671 | N18: =M18/L18 -> 98.502521 | O18: =L18-I18 -> 0 | P18: =N18-K18 -> -4.2372048 | Q18: =N18/K18 -> 0.95875787 | Y18: =SUM(Y14:Y17) -> 0 | Z18: =SUM(Z14:Z17) -> 0 | AC18: 4 | AD18: =SUM(AD14:AD17) -> 0 | AE18: =M18-J18 -> -77.328987 | AF18: =M18/J18 -> 0.95875787
A19: 新豐7線 | B19: 微波主食 | C19: 鐵板滑蛋炸豬排丼 | E19: 57.73 | F19: 2806 | G19: =E19*F19 -> 161990.38 | I19: 14 | J19: 2000 | K19: =J19/I19 -> 142.85714 | L19: 14 | M19: =F19/V19*60 -> 1913.1818 | N19: =M19/L19 -> 136.65584 | O19: =L19-I19 -> 0 | P19: =N19-K19 -> -6.2012987 | Q19: =N19/K19 -> 0.95659091 | R19: =Q25 -> 0.95943318 | S19: 0.20833333 | T19: 0.26944444 | V19: =(T19-S19)*24*60 -> 88 | AC19: 6 | AE19: =M19-J19 -> -86.818182 | AF19: =M19/J19 -> 0.95659091 | AG19: =AF25 -> 0.95943318
A20: 新豐7線 | B20: 微波主食 | C20: 極上炙烤親子丼 | E20: 53.68 | F20: 1601 | G20: =E20*F20 -> 85941.68 | I20: 16 | J20: 2000 | K20: =J20/I20 -> 125 | L20: 16 | M20: =F20/V20*60 -> 1921.2 | N20: =M20/L20 -> 120.075 | O20: =L20-I20 -> 0 | P20: =N20-K20 -> -4.925 | Q20: =N20/K20 -> 0.9606 | S20: 0.275 | T20: 0.30972222 | U20: =IF(S20=TIME(17,0,0),"",(S20-T19)*24*60) -> 8 | V20: =(T20-S20)*24*60 -> 50 | AE20: =M20-J20 -> -78.8 | AF20: =M20/J20 -> 0.9606
A21: 新豐7線 | B21: 微波主食 | C21: 韓式泡菜豬肉豆腐丼飯 | E21: 50.67 | F21: 3227 | G21: =E21*F21 -> 163512.09 | I21: 16 | J21: 2000 | K21: =J21/I21 -> 125 | L21: 16 | M21: =F21/V21*60 -> 1917.0297 | N21: =M21/L21 -> 119.81436 | O21: =L21-I21 -> 0 | P21: =N21-K21 -> -5.1856436 | Q21: =N21/K21 -> 0.95851485 | S21: 0.31527778 | T21: 0.38541667 | U21: =IF(S21=TIME(17,0,0),"",(S21-T20)*24*60) -> 8 | V21: =(T21-S21)*24*60 -> 101 | AE21: =M21-J21 -> -82.970297 | AF21: =M21/J21 -> 0.95851485
A22: 新豐7線 | B22: 微波主食 | C22: 二配厚香料咖哩雞排飯 | E22: 57.3 | F22: 1765 | G22: =E22*F22 -> 101134.5 | I22: 13 | J22: 2000 | K22: =J22/I22 -> 153.84615 | L22: 13 | M22: =F22/V22*60 -> 1925.4545 | N22: =M22/L22 -> 148.11189 | O22: =L22-I22 -> 0 | P22: =N22-K22 -> -5.7342657 | Q22: =N22/K22 -> 0.96272727 | S22: 0.70833333 | T22: 0.74652778 | U22: =IF(S22=TIME(17,0,0),"",(S22-T21)*24*60) | V22: =(T22-S22)*24*60 -> 55 | AE22: =M22-J22 -> -74.545455 | AF22: =M22/J22 -> 0.96272727
A23: 新豐7線 | B23: 微波主食 | C23: 二配起司控培根白醬焗烤飯 | E23: 53.68 | F23: 1619 | G23: =E23*F23 -> 86907.92 | I23: 16 | J23: 1500 | K23: =J23/I23 -> 93.75 | L23: 16 | M23: =F23/V23*60 -> 1449.8507 | N23: =M23/L23 -> 90.615672 | O23: =L23-I23 -> 0 | P23: =N23-K23 -> -3.1343284 | Q23: =N23/K23 -> 0.96656716 | S23: 0.75208333 | T23: 0.79861111 | U23: =IF(S23=TIME(17,0,0),"",(S23-T22)*24*60) -> 8 | V23: =(T23-S23)*24*60 -> 67 | AE23: =M23-J23 -> -50.149254 | AF23: =M23/J23 -> 0.96656716
A24: 新豐7線 | B24: 微波主食 | C24: 二配川味麻婆燒豆腐燴飯 | E24: 50.49 | F24: 2161 | G24: =E24*F24 -> 109108.89 | I24: 15 | J24: 2000 | K24: =J24/I24 -> 133.33333 | L24: 15 | M24: =F24/V24*60 -> 1906.7647 | N24: =M24/L24 -> 127.11765 | O24: =L24-I24 -> 0 | P24: =N24-K24 -> -6.2156863 | Q24: =N24/K24 -> 0.95338235 | S24: 0.80347222 | T24: 0.85069444 | U24: =IF(S24=TIME(17,0,0),"",(S24-T23)*24*60) -> 7 | V24: =(T24-S24)*24*60 -> 68 | AE24: =M24-J24 -> -93.235294 | AF24: =M24/J24 -> 0.95338235
A25: 新豐7線 | B25: 平均 | I25: 15 | J25: 1916.6667 | K25: =J25/I25 -> 127.77778 | L25: 15 | M25: =AVERAGE(M19:M24) -> 1838.9136 | N25: =M25/L25 -> 122.59424 | O25: =L25-I25 -> 0 | P25: =N25-K25 -> -5.1835387 | Q25: =N25/K25 -> 0.95943318 | Y25: =SUM(Y19:Y24) -> 0 | Z25: =SUM(Z19:Z24) -> 0 | AC25: 6 | AD25: =SUM(AD19:AD24) -> 0 | AE25: =M25-J25 -> -77.75308 | AF25: =M25/J25 -> 0.95943318
A26: 新豐8線 | B26: 三明治 | C26: 紐奧良風味烤雞鮮蔬三明治 | E26: 31.29 | F26: 6600 | G26: =E26*F26 -> 206514 | H26: 2 | I26: 18 | J26: 2400 | K26: =J26/I26 -> 133.33333 | L26: 18 | M26: =F26/V26*60 -> 2289.0173 | N26: =M26/L26 -> 127.16763 | O26: =L26-I26 -> 0 | P26: =N26-K26 -> -6.1657033 | Q26: =N26/K26 -> 0.95375723 | R26: =Q32 -> 0.95503501 | S26: 0.083333333 | T26: 0.20347222 | V26: =(T26-S26)*24*60 -> 173 | W26: =T26 -> 0.20347222 | X26: =S27 -> 0.22430556 | AC26: 6 | AE26: =M26-J26 -> -110.98266 | AF26: =M26/J26 -> 0.95375723 | AG26: =AF32 -> 0.95503501
A27: 新豐8線 | B27: 三明治 | C27: 好多菜三明治(114年) | E27: 25.98 | F27: 3280 | G27: =E27*F27 -> 85214.4 | I27: 21 | J27: 2400 | K27: =J27/I27 -> 114.28571 | L27: 21 | M27: =F27/V27*60 -> 2288.3721 | N27: =M27/L27 -> 108.9701 | O27: =L27-I27 -> 0 | P27: =N27-K27 -> -5.3156146 | Q27: =N27/K27 -> 0.95348837 | S27: 0.22430556 | T27: 0.28402778 | U27: =(S27-T26)*24*60 -> 30 | V27: =(T27-S27)*24*60 -> 86 | AE27: =M27-J27 -> -111.62791 | AF27: =M27/J27 -> 0.95348837
A28: 新豐8線 | B28: 三明治 | C28: 經典總匯三明治 | E28: 26.2 | F28: 5676 | G28: =E28*F28 -> 148711.2 | I28: 20 | J28: 2400 | K28: =J28/I28 -> 120 | L28: 20 | M28: =F28/V28*60 -> 2285.6376 | N28: =M28/L28 -> 114.28188 | O28: =L28-I28 -> 0 | P28: =N28-K28 -> -5.7181208 | Q28: =N28/K28 -> 0.95234899 | S28: 0.2875 | T28: 0.39097222 | U28: =(S28-T27)*24*60 -> 5 | V28: =(T28-S28)*24*60 -> 149 | AE28: =M28-J28 -> -114.36242 | AF28: =M28/J28 -> 0.95234899
A29: 新豐8線 | B29: 三明治 | C29: 雞蛋沙拉三明治(114年) | E29: 25.99 | F29: 4430 | G29: =E29*F29 -> 115135.7 | I29: 14 | J29: 2400 | K29: =J29/I29 -> 171.42857 | L29: 14 | M29: =F29/V29*60 -> 2291.3793 | N29: =M29/L29 -> 163.66995 | O29: =L29-I29 -> 0 | P29: =N29-K29 -> -7.7586207 | Q29: =N29/K29 -> 0.95474138 | S29: 0.39444444 | T29: 0.475 | U29: =(S29-T28)*24*60 -> 5 | V29: =(T29-S29)*24*60 -> 116 | AE29: =M29-J29 -> -108.62069 | AF29: =M29/J29 -> 0.95474138
A30: 新豐8線 | B30: 三明治 | C30: 陽光地瓜總匯三明治 | E30: 26.18 | F30: 1831 | G30: =E30*F30 -> 47935.58 | I30: 19 | J30: 2400 | K30: =J30/I30 -> 126.31579 | L30: 19 | M30: =F30/V30*60 -> 2288.75 | N30: =M30/L30 -> 120.46053 | O30: =L30-I30 -> 0 | P30: =N30-K30 -> -5.8552632 | Q30: =N30/K30 -> 0.95364583 | S30: 0.47916667 | T30: 0.5125 | U30: =(S30-T29)*24*60 -> 6 | V30: =(T30-S30)*24*60 -> 48 | W30: =T30 -> 0.5125 | X30: =S31 -> 0.55416667 | AE30: =M30-J30 -> -111.25 | AF30: =M30/J30 -> 0.95364583
A31: 新豐8線 | B31: 三明治 | C31: 紐奧良風味烤雞鮮蔬三明治 | E31: 31.29 | F31: 3541 | G31: =E31*F31 -> 110797.89 | I31: 18 | J31: 2400 | K31: =J31/I31 -> 133.33333 | L31: 18 | M31: =F31/V31*60 -> 2309.3478 | N31: =M31/L31 -> 128.2971 | O31: =L31-I31 -> 0 | P31: =N31-K31 -> -5.0362319 | Q31: =N31/K31 -> 0.96222826 | S31: 0.55416667 | T31: 0.61805556 | U31: =(S31-T30)*24*60 -> 60 | V31: =(T31-S31)*24*60 -> 92 | AE31: =M31-J31 -> -90.652174 | AF31: =M31/J31 -> 0.96222826
A32: 新豐8線 | B32: 平均 | I32: 18.333333 | J32: 2400 | K32: =J32/I32 -> 130.90909 | L32: 18.333333 | M32: =AVERAGE(M26:M31) -> 2292.084 | N32: =M32/L32 -> 125.02277 | O32: =L32-I32 -> 0 | P32: =N32-K32 -> -5.8863259 | Q32: =N32/K32 -> 0.95503501 | Y32: =SUM(Y26:Y31) -> 0 | Z32: =SUM(Z26:Z31) -> 0 | AC32: 6 | AD32: =SUM(AD26:AD31) -> 0 | AE32: =M32-J32 -> -107.91597 | AF32: =M32/J32 -> 0.95503501
A33: 新豐9線 | B33: 三明治 | C33: 鮪魚起司溏心蛋三明治 | E33: 26.2 | F33: 4700 | G33: =E33*F33 -> 123140 | H33: 2 | I33: 18 | J33: 2400 | K33: =J33/I33 -> 133.33333 | L33: 18 | M33: =F33/V33*60 -> 2292.6829 | N33: =M33/L33 -> 127.37127 | O33: =L33-I33 -> 0 | P33: =N33-K33 -> -5.9620596 | Q33: =N33/K33 -> 0.95528455 | R33: =Q40 -> 0.95674807 | S33: 0.083333333 | T33: 0.16875 | V33: =(T33-S33)*24*60 -> 123 | W33: =T33 -> 0.16875 | X33: =S34 -> 0.18819444 | AC33: 7 | AE33: =M33-J33 -> -107.31707 | AF33: =M33/J33 -> 0.95528455 | AG33: =AF40 -> 0.95674807
A34: 新豐9線 | B34: 三明治 | C34: 肉鬆火腿三明治 | E34: 20.52 | F34: 4374 | G34: =E34*F34 -> 89754.48 | I34: 18 | J34: 2400 | K34: =J34/I34 -> 133.33333 | L34: 18 | M34: =F34/V34*60 -> 2302.1053 | N34: =M34/L34 -> 127.89474 | O34: =L34-I34 -> 0 | P34: =N34-K34 -> -5.4385965 | Q34: =N34/K34 -> 0.95921053 | S34: 0.18819444 | T34: 0.26736111 | U34: =(S34-T33)*24*60 -> 28 | V34: =(T34-S34)*24*60 -> 114 | AE34: =M34-J34 -> -97.894737 | AF34: =M34/J34 -> 0.95921053
A35: 新豐9線 | B35: 三明治 | C35: 醬燒烤雞三明治 | E35: 26.39 | F35: 4200 | G35: =E35*F35 -> 110838 | H35: 2 | I35: 19 | J35: 2400 | K35: =J35/I35 -> 126.31579 | L35: 19 | M35: =F35/V35*60 -> 2290.9091 | N35: =M35/L35 -> 120.57416 | O35: =L35-I35 -> 0 | P35: =N35-K35 -> -5.7416268 | Q35: =N35/K35 -> 0.95454545 | S35: 0.27222222 | T35: 0.34861111 | U35: =(S35-T34)*24*60 -> 7 | V35: =(T35-S35)*24*60 -> 110 | AE35: =M35-J35 -> -109.09091 | AF35: =M35/J35 -> 0.95454545
A36: 新豐9線 | B36: 三明治 | C36: 輕乳酪巧克力三明治 | E36: 20.52 | F36: 2915 | G36: =E36*F36 -> 59815.8 | I36: 18 | J36: 2400 | K36: =J36/I36 -> 133.33333 | L36: 18 | M36: =F36/V36*60 -> 2301.3158 | N36: =M36/L36 -> 127.85088 | O36: =L36-I36 -> 0 | P36: =N36-K36 -> -5.4824561 | Q36: =N36/K36 -> 0.95888158 | S36: 0.35277778 | T36: 0.40555556 | U36: =(S36-T35)*24*60 -> 6 | V36: =(T36-S36)*24*60 -> 76 | AE36: =M36-J36 -> -98.684211 | AF36: =M36/J36 -> 0.95888158
A37: 新豐9線 | B37: 三明治 | C37: 香蕉可可三明治 | E37: 22.69 | F37: 6026 | G37: =E37*F37 -> 136729.94 | I37: 15 | J37: 2400 | K37: =J37/I37 -> 160 | L37: 15 | M37: =F37/V37*60 -> 2288.3544 | N37: =M37/L37 -> 152.55696 | O37: =L37-I37 -> 0 | P37: =N37-K37 -> -7.443038 | Q37: =N37/K37 -> 0.95348101 | S37: 0.40972222 | T37: 0.51944444 | U37: =(S37-T36)*24*60 -> 6 | V37: =(T37-S37)*24*60 -> 158 | W37: =T37 -> 0.51944444 | X37: =S38 -> 0.55833333 | AE37: =M37-J37 -> -111.64557 | AF37: =M37/J37 -> 0.95348101
A38: 新豐9線 | B38: 三明治 | C38: 鮪魚起司溏心蛋三明治 | E38: 26.2 | F38: 2660 | G38: =E38*F38 -> 69692 | I38: 18 | J38: 2400 | K38: =J38/I38 -> 133.33333 | L38: 18 | M38: =F38/V38*60 -> 2280 | N38: =M38/L38 -> 126.66667 | O38: =L38-I38 -> 0 | P38: =N38-K38 -> -6.6666667 | Q38: =N38/K38 -> 0.95 | S38: 0.55833333 | T38: 0.60694444 | U38: =(S38-T37)*24*60 -> 56 | V38: =(T38-S38)*24*60 -> 70 | AE38: =M38-J38 -> -120 | AF38: =M38/J38 -> 0.95
A39: 新豐9線 | B39: 三明治 | C39: 醬燒烤雞三明治 | E39: 26.39 | F39: 2318 | G39: =E39*F39 -> 61172.02 | I39: 19 | J39: 2400 | K39: =J39/I39 -> 126.31579 | L39: 19 | M39: =F39/V39*60 -> 2318 | N39: =M39/L39 -> 122 | O39: =L39-I39 -> 0 | P39: =N39-K39 -> -4.3157895 | Q39: =N39/K39 -> 0.96583333 | S39: 0.61180556 | T39: 0.65347222 | U39: =(S39-T38)*24*60 -> 7 | V39: =(T39-S39)*24*60 -> 60 | AE39: =M39-J39 -> -82 | AF39: =M39/J39 -> 0.96583333
A40: 新豐9線 | B40: 平均 | I40: 17.857143 | J40: 2400 | K40: =J40/I40 -> 134.4 | L40: 17.857143 | M40: =AVERAGE(M33:M39) -> 2296.1954 | N40: =M40/L40 -> 128.58694 | O40: =L40-I40 -> 0 | P40: =N40-K40 -> -5.81306 | Q40: =N40/K40 -> 0.95674807 | Y40: =SUM(Y33:Y39) -> 0 | Z40: =SUM(Z33:Z39) -> 0 | AC40: 7 | AD40: =SUM(AD33:AD39) -> 0 | AE40: =M40-J40 -> -103.80464 | AF40: =M40/J40 -> 0.95674807
...

Sheet 0329
B1: 屏榮 新豐廠組合室生產人時性分析
B3: 日期 | C3: =TEXT('0329 4度C'!A2,"yyyy.mm.ddaaaa") -> 2026.03.29星期日 | E3: 訂單量 | F3: ='0329 4度C'!D1 -> 182495 | H3: 營業額 | I3: ='0329 4度C'!F1 -> 6071846.3
B4: 人時性 | C4: 項目 | E4: ➀ | G4: ➁ | I4: ➂ | K4: 異常停線 | M4: 短暫停線
C5: 組合室 | E5: 全溫層 | G5: 4度C-各編組展開 | I5: ③三明治-各編組展開 | K5: 合計次數 | L5: 時間 | M5: 合計次數 | N5: 設備次數
C6: 排關平均 | E6: =AVERAGE(D13:M13) -> 156.55073 | F6: =AVERAGE(D31:O31,D13:J13) -> 162.73338 | G6: =AVERAGE(D13:J13) -> 162.73338 | I6: =AVERAGE(K13:M13) -> 142.12454 | K6: ='0329 4度C'!Y2 -> 0 | L6: ='0329 4度C'!Z2 -> 0 | M6: ='0329 4度C'!AC2 -> 59 | N6: ='0329 4度C'!AD2 -> 0
C7: 實績平均 | E7: =AVERAGE(D14:M14) -> 149.98135 | F7: =AVERAGE(D32:O32,D14:J14) -> 155.91748 | G7: =AVERAGE(D14:J14) -> 155.91748 | I7: =AVERAGE(K14:M14) -> 136.13036
C8: 達成率平均 | E8: =AVERAGE(D15:M15) -> 0.95729894 | F8: =AVERAGE(D15:J15,D33:O33) -> 0.95707329 | G8: =AVERAGE(D15:J15) -> 0.95707329 | I8: =AVERAGE(K15:M15) -> 0.95782548
K9: ※現行日本鮮食廠以達成率80%為基本(即為現行KPI)
B10: 溫層 | D10: ➁4度C-各編組展開 | K10: ③三明治-各編組展開
B11: 編組 | D11: 1 | E11: 2 | F11: 3 | G11: 4 | H11: 5 | I11: 6 | J11: 7 | K11: 1 | L11: 2 | M11: 3
D12: 新豐6線 | E12: 新豐2線 | F12: 新豐5線 | G12: 新豐7線 | H12: 新豐3線 | I12: 新豐1線 | J12: 新豐10線 | K12: 新豐8線 | L12: 新豐9線 | M12: 新豐4線
B13: 人時性 | C13: 排關 | D13: =SUMIFS('0329 4度C'!$K:$K,'0329 4度C'!$A:$A,"新豐6線",'0329 4度C'!$B:$B,"平均") -> 111.11111 | E13: =SUMIFS('0329 4度C'!$K:$K,'0329 4度C'!$A:$A,"新豐2線",'0329 4度C'!$B:$B,"平均") -> 84.90566 | F13: =SUMIFS('0329 4度C'!$K:$K,'0329 4度C'!$A:$A,"新豐5線",'0329 4度C'!$B:$B,"平均") -> 107.95455 | G13: =SUMIFS('0329 4度C'!$K:$K,'0329 4度C'!$A:$A,"新豐7線",'0329 4度C'!$B:$B,"平均") -> 128.57143 | H13: =SUMIFS('0329 4度C'!$K:$K,'0329 4度C'!$A:$A,"新豐3線",'0329 4度C'!$B:$B,"平均") -> 333.33333 | I13: =SUMIFS('0329 4度C'!$K:$K,'0329 4度C'!$A:$A,"新豐1線",'0329 4度C'!$B:$B,"平均") -> 104.02685 | J13: =SUMIFS('0329 4度C'!$K:$K,'0329 4度C'!$A:$A,"新豐10線",'0329 4度C'!$B:$B,"平均") -> 269.23077 | K13: =SUMIFS('0329 4度C'!$K:$K,'0329 4度C'!$A:$A,"新豐8線",'0329 4度C'!$B:$B,"平均") -> 129.23077 | L13: =SUMIFS('0329 4度C'!$K:$K,'0329 4度C'!$A:$A,"新豐9線",'0329 4度C'!$B:$B,"平均") -> 137.14286 | M13: =SUMIFS('0329 4度C'!$K:$K,'0329 4度C'!$A:$A,"新豐4線",'0329 4度C'!$B:$B,"平均") -> 160
C14: 實績 | D14: =SUMIFS('0329 4度C'!$N:$N,'0329 4度C'!$A:$A,"新豐6線",'0329 4度C'!$B:$B,"平均") -> 105.60013 | E14: =SUMIFS('0329 4度C'!$N:$N,'0329 4度C'!$A:$A,"新豐2線",'0329 4度C'!$B:$B,"平均") -> 80.99807 | F14: =SUMIFS('0329 4度C'!$N:$N,'0329 4度C'!$A:$A,"新豐5線",'0329 4度C'!$B:$B,"平均") -> 103.23809 | G14: =SUMIFS('0329 4度C'!$N:$N,'0329 4度C'!$A:$A,"新豐7線",'0329 4度C'!$B:$B,"平均") -> 123.53321 | H14: =SUMIFS('0329 4度C'!$N:$N,'0329 4度C'!$A:$A,"新豐3線",'0329 4度C'!$B:$B,"平均") -> 319.16285 | I14: =SUMIFS('0329 4度C'!$N:$N,'0329 4度C'!$A:$A,"新豐1線",'0329 4度C'!$B:$B,"平均") -> 99.599829 | J14: =SUMIFS('0329 4度C'!$N:$N,'0329 4度C'!$A:$A,"新豐10線",'0329 4度C'!$B:$B,"平均") -> 259.2902 | K14: =SUMIFS('0329 4度C'!$N:$N,'0329 4度C'!$A:$A,"新豐8線",'0329 4度C'!$B:$B,"平均") -> 123.79288 | L14: =SUMIFS('0329 4度C'!$N:$N,'0329 4度C'!$A:$A,"新豐9線",'0329 4度C'!$B:$B,"平均") -> 131.34397 | M14: =SUMIFS('0329 4度C'!$N:$N,'0329 4度C'!$A:$A,"新豐4線",'0329 4度C'!$B:$B,"平均") -> 153.25422
C15: 達成率 | D15: =D14/D13 -> 0.9504012 | E15: =E14/E13 -> 0.95397727 | F15: =F14/F13 -> 0.95631073 | G15: =G14/G13 -> 0.96081386 | H15: =H14/H13 -> 0.95748855 | I15: =I14/I13 -> 0.95744352 | J15: =J14/J13 -> 0.96307788 | K15: =K14/K13 -> 0.95792113 | ... M15: =M14/M13 -> 0.95783884
B16: 作業 時間 | C16: 開始 | D16: =VLOOKUP("新豐6線",'0329 4度C'!$A:$T,19,0) -> 0.70833333 | E16: =VLOOKUP("新豐2線",'0329 4度C'!$A:$T,19,0) -> 0.20833333 | F16: =VLOOKUP("新豐5線",'0329 4度C'!$A:$T,19,0) -> 0.20833333 | G16: =VLOOKUP("新豐7線",'0329 4度C'!$A:$T,19,0) -> 0.20833333 | H16: =VLOOKUP("新豐3線",'0329 4度C'!$A:$T,19,0) -> 0.083333333 | I16: =VLOOKUP("新豐1線",'0329 4度C'!$A:$T,19,0) -> 0.20833333 | J16: =VLOOKUP("新豐10線",'0329 4度C'!$A:$T,19,0) -> 0.20833333 | K16: =VLOOKUP("新豐8線",'0329 4度C'!$A:$T,19,0) -> 0.083333333 | L16: =VLOOKUP("新豐9線",'0329 4度C'!$A:$T,19,0) -> 0.083333333 | M16: =VLOOKUP("新豐4線",'0329 4度C'!$A:$T,19,0) -> 0.083333333
C17: 結束 | D17: =LOOKUP(2,1/(('0329 4度C'!$A:$A="新豐6線")*('0329 4度C'!$T:$T<>"")),'0329 4度C'!$T:$T) -> 0.83958333 | E17: =LOOKUP(2,1/(('0329 4度C'!$A:$A="新豐2線")*('0329 4度C'!$T:$T<>"")),'0329 4度C'!$T:$T) -> 0.63333333 | F17: =LOOKUP(2,1/(('0329 4度C'!$A:$A="新豐5線")*('0329 4度C'!$T:$T<>"")),'0329 4度C'!$T:$T) -> 0.89513889 | G17: =LOOKUP(2,1/(('0329 4度C'!$A:$A="新豐7線")*('0329 4度C'!$T:$T<>"")),'0329 4度C'!$T:$T) -> 0.90277778 | H17: =LOOKUP(2,1/(('0329 4度C'!$A:$A="新豐3線")*('0329 4度C'!$T:$T<>"")),'0329 4度C'!$T:$T) -> 0.49444444 | I17: =LOOKUP(2,1/(('0329 4度C'!$A:$A="新豐1線")*('0329 4度C'!$T:$T<>"")),'0329 4度C'!$T:$T) -> 0.91666667 | J17: =LOOKUP(2,1/(('0329 4度C'!$A:$A="新豐10線")*('0329 4度C'!$T:$T<>"")),'0329 4度C'!$T:$T) -> 0.45069444 | K17: =LOOKUP(2,1/(('0329 4度C'!$A:$A="新豐8線")*('0329 4度C'!$T:$T<>"")),'0329 4度C'!$T:$T) -> 0.67361111 | L17: =LOOKUP(2,1/(('0329 4度C'!$A:$A="新豐9線")*('0329 4度C'!$T:$T<>"")),'0329 4度C'!$T:$T) -> 0.7 | M17: =LOOKUP(2,1/(('0329 4度C'!$A:$A="新豐4線")*('0329 4度C'!$T:$T<>"")),'0329 4度C'!$T:$T) -> 0.67291667
B18: 產線異常 (5分鐘以上) | C18: 次數 | D18: =SUMIFS('0329 4度C'!$Y:$Y,'0329 4度C'!$A:$A,"新豐6線",'0329 4度C'!$B:$B,"平均") -> 0 | E18: =SUMIFS('0329 4度C'!$Y:$Y,'0329 4度C'!$A:$A,"新豐2線",'0329 4度C'!$B:$B,"平均") -> 0 | F18: =SUMIFS('0329 4度C'!$Y:$Y,'0329 4度C'!$A:$A,"新豐5線",'0329 4度C'!$B:$B,"平均") -> 0 | G18: =SUMIFS('0329 4度C'!$Y:$Y,'0329 4度C'!$A:$A,"新豐7線",'0329 4度C'!$B:$B,"平均") -> 0 | H18: =SUMIFS('0329 4度C'!$Y:$Y,'0329 4度C'!$A:$A,"新豐3線",'0329 4度C'!$B:$B,"平均") -> 0 | I18: =SUMIFS('0329 4度C'!$Y:$Y,'0329 4度C'!$A:$A,"新豐1線",'0329 4度C'!$B:$B,"平均") -> 0 | J18: =SUMIFS('0329 4度C'!$Y:$Y,'0329 4度C'!$A:$A,"新豐10線",'0329 4度C'!$B:$B,"平均") -> 0 | K18: =SUMIFS('0329 4度C'!$Y:$Y,'0329 4度C'!$A:$A,"新豐8線",'0329 4度C'!$B:$B,"平均") -> 0 | L18: =SUMIFS('0329 4度C'!$Y:$Y,'0329 4度C'!$A:$A,"新豐9線",'0329 4度C'!$B:$B,"平均") -> 0 | M18: =SUMIFS('0329 4度C'!$Y:$Y,'0329 4度C'!$A:$A,"新豐4線",'0329 4度C'!$B:$B,"平均") -> 0
