Workbook

Sheet 0731
B1: 屏榮 新豐廠組合室生產人時性分析
B3: 日期 | C3: =TEXT('0731 4度C'!A2,"yyyy.mm.ddaaaa") -> 2026.07.31星期五 | E3: 訂單量 | F3: ='0731 4度C'!D1 -> 144931 | H3: 營業額 | I3: ='0731 4度C'!F1 -> 5031860
B4: 人時性 | C4: 項目 | E4: ➀ | G4: ➁ | I4: ➂ | K4: 異常停線 | M4: 短暫停線
C5: 組合室 | E5: 全溫層 | G5: 4度C-各編組展開 | I5: ③三明治-各編組展開 | K5: 合計次數 | L5: 時間 | M5: 合計次數 | N5: 設備次數
C6: 排關平均 | E6: =AVERAGE(D13:M13) -> 157.66603 | F6: =AVERAGE(D31:O31,D13:J13) -> 166.61988 | G6: =AVERAGE(D13:J13) -> 166.61988 | I6: =AVERAGE(K13:M13) -> 136.77372 | K6: ='0731 4度C'!Y2 -> 0 | L6: ='0731 4度C'!Z2 -> 0 | M6: ='0731 4度C'!AC2 -> 55 | N6: ='0731 4度C'!AD2 -> 0
C7: 實績平均 | E7: =AVERAGE(D14:M14) -> 151.29095 | F7: =AVERAGE(D32:O32,D14:J14) -> 160.00617 | G7: =AVERAGE(D14:J14) -> 160.00617 | I7: =AVERAGE(K14:M14) -> 130.95544
C8: 達成率平均 | E8: =AVERAGE(D15:M15) -> 0.95984242 | F8: =AVERAGE(D15:J15,D33:O33) -> 0.96084861 | G8: =AVERAGE(D15:J15) -> 0.96084861 | I8: =AVERAGE(K15:M15) -> 0.95749463
K9: ※現行日本鮮食廠以達成率80%為基本(即為現行KPI)
B10: 溫層 | D10: ➁4度C-各編組展開 | K10: ③三明治-各編組展開
B11: 編組 | D11: 1 | E11: 2 | F11: 3 | G11: 4 | H11: 5 | I11: 6 | J11: 7 | K11: 1 | L11: 2 | M11: 3
D12: 新豐6線 | E12: 新豐2線 | F12: 新豐5線 | G12: 新豐7線 | H12: 新豐3線 | I12: 新豐1線 | J12: 新豐10線 | K12: 新豐8線 | L12: 新豐9線 | M12: 新豐4線
B13: 人時性 | C13: 排關 | D13: =SUMIFS('0731 4度C'!$K:$K,'0731 4度C'!$A:$A,"新豐6線",'0731 4度C'!$B:$B,"平均") -> 130.43478 | E13: =SUMIFS('0731 4度C'!$K:$K,'0731 4度C'!$A:$A,"新豐2線",'0731 4度C'!$B:$B,"平均") -> 85.714286 | F13: =SUMIFS('0731 4度C'!$K:$K,'0731 4度C'!$A:$A,"新豐5線",'0731 4度C'!$B:$B,"平均") -> 93.023256 | G13: =SUMIFS('0731 4度C'!$K:$K,'0731 4度C'!$A:$A,"新豐7線",'0731 4度C'!$B:$B,"平均") -> 127.65957 | H13: =SUMIFS('0731 4度C'!$K:$K,'0731 4度C'!$A:$A,"新豐3線",'0731 4度C'!$B:$B,"平均") -> 324.32432 | I13: =SUMIFS('0731 4度C'!$K:$K,'0731 4度C'!$A:$A,"新豐1線",'0731 4度C'!$B:$B,"平均") -> 112.5 | J13: =SUMIFS('0731 4度C'!$K:$K,'0731 4度C'!$A:$A,"新豐10線",'0731 4度C'!$B:$B,"平均") -> 292.68293 | K13: =SUMIFS('0731 4度C'!$K:$K,'0731 4度C'!$A:$A,"新豐8線",'0731 4度C'!$B:$B,"平均") -> 137.70492 | L13: =SUMIFS('0731 4度C'!$K:$K,'0731 4度C'!$A:$A,"新豐9線",'0731 4度C'!$B:$B,"平均") -> 123.94366 | M13: =SUMIFS('0731 4度C'!$K:$K,'0731 4度C'!$A:$A,"新豐4線",'0731 4度C'!$B:$B,"平均") -> 148.67257
C14: 實績 | D14: =SUMIFS('0731 4度C'!$N:$N,'0731 4度C'!$A:$A,"新豐6線",'0731 4度C'!$B:$B,"平均") -> 125.89127 | E14: =SUMIFS('0731 4度C'!$N:$N,'0731 4度C'!$A:$A,"新豐2線",'0731 4度C'!$B:$B,"平均") -> 82.04632 | F14: =SUMIFS('0731 4度C'!$N:$N,'0731 4度C'!$A:$A,"新豐5線",'0731 4度C'!$B:$B,"平均") -> 89.392938 | G14: =SUMIFS('0731 4度C'!$N:$N,'0731 4度C'!$A:$A,"新豐7線",'0731 4度C'!$B:$B,"平均") -> 122.83842 | H14: =SUMIFS('0731 4度C'!$N:$N,'0731 4度C'!$A:$A,"新豐3線",'0731 4度C'!$B:$B,"平均") -> 310.74788 | I14: =SUMIFS('0731 4度C'!$N:$N,'0731 4度C'!$A:$A,"新豐1線",'0731 4度C'!$B:$B,"平均") -> 108.3114 | J14: =SUMIFS('0731 4度C'!$N:$N,'0731 4度C'!$A:$A,"新豐10線",'0731 4度C'!$B:$B,"平均") -> 280.81497 | K14: =SUMIFS('0731 4度C'!$N:$N,'0731 4度C'!$A:$A,"新豐8線",'0731 4度C'!$B:$B,"平均") -> 132.16654 | L14: =SUMIFS('0731 4度C'!$N:$N,'0731 4度C'!$A:$A,"新豐9線",'0731 4度C'!$B:$B,"平均") -> 118.61973 | M14: =SUMIFS('0731 4度C'!$N:$N,'0731 4度C'!$A:$A,"新豐4線",'0731 4度C'!$B:$B,"平均") -> 142.08006
C15: 達成率 | D15: =D14/D13 -> 0.96516642 | E15: =E14/E13 -> 0.95720707 | F15: =F14/F13 -> 0.96097409 | G15: =G14/G13 -> 0.9622343 | H15: =H14/H13 -> 0.95813931 | I15: =I14/I13 -> 0.96276797 | J15: =J14/J13 -> 0.95945114 | K15: =K14/K13 -> 0.95978079 | ... M15: =M14/M13 -> 0.95565754
B16: 作業 時間 | C16: 開始 | D16: =VLOOKUP("新豐6線",'0731 4度C'!$A:$T,19,0) -> 0.70833333 | E16: =VLOOKUP("新豐2線",'0731 4度C'!$A:$T,19,0) -> 0.083333333 | F16: =VLOOKUP("新豐5線",'0731 4度C'!$A:$T,19,0) -> 0.083333333 | G16: =VLOOKUP("新豐7線",'0731 4度C'!$A:$T,19,0) -> 0.20833333 | H16: =VLOOKUP("新豐3線",'0731 4度C'!$A:$T,19,0) -> 0.20833333 | I16: =VLOOKUP("新豐1線",'0731 4度C'!$A:$T,19,0) -> 0.083333333 | J16: =VLOOKUP("新豐10線",'0731 4度C'!$A:$T,19,0) -> 0.20833333 | K16: =VLOOKUP("新豐8線",'0731 4度C'!$A:$T,19,0) -> 0.083333333 | L16: =VLOOKUP("新豐9線",'0731 4度C'!$A:$T,19,0) -> 0.083333333 | M16: =VLOOKUP("新豐4線",'0731 4度C'!$A:$T,19,0) -> 0.083333333
C17: 結束 | D17: =LOOKUP(2,1/(('0731 4度C'!$A:$A="新豐6線")*('0731 4度C'!$T:$T<>"")),'0731 4度C'!$T:$T) -> 0.81041667 | E17: =LOOKUP(2,1/(('0731 4度C'!$A:$A="新豐2線")*('0731 4度C'!$T:$T<>"")),'0731 4度C'!$T:$T) -> 0.49236111 | F17: =LOOKUP(2,1/(('0731 4度C'!$A:$A="新豐5線")*('0731 4度C'!$T:$T<>"")),'0731 4度C'!$T:$T) -> 0.81944444 | G17: =LOOKUP(2,1/(('0731 4度C'!$A:$A="新豐7線")*('0731 4度C'!$T:$T<>"")),'0731 4度C'!$T:$T) -> 0.82083333 | H17: =LOOKUP(2,1/(('0731 4度C'!$A:$A="新豐3線")*('0731 4度C'!$T:$T<>"")),'0731 4度C'!$T:$T) -> 0.36875 | I17: =LOOKUP(2,1/(('0731 4度C'!$A:$A="新豐1線")*('0731 4度C'!$T:$T<>"")),'0731 4度C'!$T:$T) -> 0.83888889 | J17: =LOOKUP(2,1/(('0731 4度C'!$A:$A="新豐10線")*('0731 4度C'!$T:$T<>"")),'0731 4度C'!$T:$T) -> 0.37361111 | K17: =LOOKUP(2,1/(('0731 4度C'!$A:$A="新豐8線")*('0731 4度C'!$T:$T<>"")),'0731 4度C'!$T:$T) -> 0.58333333 | L17: =LOOKUP(2,1/(('0731 4度C'!$A:$A="新豐9線")*('0731 4度C'!$T:$T<>"")),'0731 4度C'!$T:$T) -> 0.48055556 | M17: =LOOKUP(2,1/(('0731 4度C'!$A:$A="新豐4線")*('0731 4度C'!$T:$T<>"")),'0731 4度C'!$T:$T) -> 0.63680556
B18: 產線異常 (5分鐘以上) | C18: 次數 | D18: =SUMIFS('0731 4度C'!$Y:$Y,'0731 4度C'!$A:$A,"新豐6線",'0731 4度C'!$B:$B,"平均") -> 0 | E18: =SUMIFS('0731 4度C'!$Y:$Y,'0731 4度C'!$A:$A,"新豐2線",'0731 4度C'!$B:$B,"平均") -> 0 | F18: =SUMIFS('0731 4度C'!$Y:$Y,'0731 4度C'!$A:$A,"新豐5線",'0731 4度C'!$B:$B,"平均") -> 0 | G18: =SUMIFS('0731 4度C'!$Y:$Y,'0731 4度C'!$A:$A,"新豐7線",'0731 4度C'!$B:$B,"平均") -> 0 | H18: =SUMIFS('0731 4度C'!$Y:$Y,'0731 4度C'!$A:$A,"新豐3線",'0731 4度C'!$B:$B,"平均") -> 0 | I18: =SUMIFS('0731 4度C'!$Y:$Y,'0731 4度C'!$A:$A,"新豐1線",'0731 4度C'!$B:$B,"平均") -> 0 | J18: =SUMIFS('0731 4度C'!$Y:$Y,'0731 4度C'!$A:$A,"新豐10線",'0731 4度C'!$B:$B,"平均") -> 0 | K18: =SUMIFS('0731 4度C'!$Y:$Y,'0731 4度C'!$A:$A,"新豐8線",'0731 4度C'!$B:$B,"平均") -> 0 | L18: =SUMIFS('0731 4度C'!$Y:$Y,'0731 4度C'!$A:$A,"新豐9線",'0731 4度C'!$B:$B,"平均") -> 0 | M18: =SUMIFS('0731 4度C'!$Y:$Y,'0731 4度C'!$A:$A,"新豐4線",'0731 4度C'!$B:$B,"平均") -> 0
C19: 時間/分 | D19: =SUMIFS('0731 4度C'!$Z:$Z,'0731 4度C'!$A:$A,"新豐6線",'0731 4度C'!$B:$B,"平均") -> 0 | E19: =SUMIFS('0731 4度C'!$Z:$Z,'0731 4度C'!$A:$A,"新豐2線",'0731 4度C'!$B:$B,"平均") -> 0 | F19: =SUMIFS('0731 4度C'!$Z:$Z,'0731 4度C'!$A:$A,"新豐5線",'0731 4度C'!$B:$B,"平均") -> 0 | G19: =SUMIFS('0731 4度C'!$Z:$Z,'0731 4度C'!$A:$A,"新豐7線",'0731 4度C'!$B:$B,"平均") -> 0 | H19: =SUMIFS('0731 4度C'!$Z:$Z,'0731 4度C'!$A:$A,"新豐3線",'0731 4度C'!$B:$B,"平均") -> 0 | I19: =SUMIFS('0731 4度C'!$Z:$Z,'0731 4度C'!$A:$A,"新豐1線",'0731 4度C'!$B:$B,"平均") -> 0 | J19: =SUMIFS('0731 4度C'!$Z:$Z,'0731 4度C'!$A:$A,"新豐10線",'0731 4度C'!$B:$B,"平均") -> 0 | K19: =SUMIFS('0731 4度C'!$Z:$Z,'0731 4度C'!$A:$A,"新豐8線",'0731 4度C'!$B:$B,"平均") -> 0 | L19: =SUMIFS('0731 4度C'!$Z:$Z,'0731 4度C'!$A:$A,"新豐9線",'0731 4度C'!$B:$B,"平均") -> 0 | M19: =SUMIFS('0731 4度C'!$Z:$Z,'0731 4度C'!$A:$A,"新豐4線",'0731 4度C'!$B:$B,"平均") -> 0
B20: 短暫停線 (5分鐘以下) | C20: 次數 | D20: =SUMIFS('0731 4度C'!$AC:$AC,'0731 4度C'!$A:$A,"新豐6線",'0731 4度C'!$B:$B,"平均") -> 3 | E20: =SUMIFS('0731 4度C'!$AC:$AC,'0731 4度C'!$A:$A,"新豐2線",'0731 4度C'!$B:$B,"平均") -> 4 | F20: =SUMIFS('0731 4度C'!$AC:$AC,'0731 4度C'!$A:$A,"新豐5線",'0731 4度C'!$B:$B,"平均") -> 7 | G20: =SUMIFS('0731 4度C'!$AC:$AC,'0731 4度C'!$A:$A,"新豐7線",'0731 4度C'!$B:$B,"平均") -> 6 | H20: =SUMIFS('0731 4度C'!$AC:$AC,'0731 4度C'!$A:$A,"新豐3線",'0731 4度C'!$B:$B,"平均") -> 4 | I20: =SUMIFS('0731 4度C'!$AC:$AC,'0731 4度C'!$A:$A,"新豐1線",'0731 4度C'!$B:$B,"平均") -> 9 | J20: =SUMIFS('0731 4度C'!$AC:$AC,'0731 4度C'!$A:$A,"新豐10線",'0731 4度C'!$B:$B,"平均") -> 4 | K20: =SUMIFS('0731 4度C'!$AC:$AC,'0731 4度C'!$A:$A,"新豐8線",'0731 4度C'!$B:$B,"平均") -> 7 | L20: =SUMIFS('0731 4度C'!$AC:$AC,'0731 4度C'!$A:$A,"新豐9線",'0731 4度C'!$B:$B,"平均") -> 4 | M20: =SUMIFS('0731 4度C'!$AC:$AC,'0731 4度C'!$A:$A,"新豐4線",'0731 4度C'!$B:$B,"平均") -> 7
C21: 設備次數 | D21: =SUMIFS('0731 4度C'!$AD:$AD,'0731 4度C'!$A:$A,"新豐6線",'0731 4度C'!$B:$B,"平均") -> 0 | E21: =SUMIFS('0731 4度C'!$AD:$AD,'0731 4度C'!$A:$A,"新豐2線",'0731 4度C'!$B:$B,"平均") -> 0 | F21: =SUMIFS('0731 4度C'!$AD:$AD,'0731 4度C'!$A:$A,"新豐5線",'0731 4度C'!$B:$B,"平均") -> 0 | G21: =SUMIFS('0731 4度C'!$AD:$AD,'0731 4度C'!$A:$A,"新豐7線",'0731 4度C'!$B:$B,"平均") -> 0 | H21: =SUMIFS('0731 4度C'!$AD:$AD,'0731 4度C'!$A:$A,"新豐3線",'0731 4度C'!$B:$B,"平均") -> 0 | I21: =SUMIFS('0731 4度C'!$AD:$AD,'0731 4度C'!$A:$A,"新豐1線",'0731 4度C'!$B:$B,"平均") -> 0 | J21: =SUMIFS('0731 4度C'!$AD:$AD,'0731 4度C'!$A:$A,"新豐10線",'0731 4度C'!$B:$B,"平均") -> 0 | K21: =SUMIFS('0731 4度C'!$AD:$AD,'0731 4度C'!$A:$A,"新豐8線",'0731 4度C'!$B:$B,"平均") -> 0 | L21: =SUMIFS('0731 4度C'!$AD:$AD,'0731 4度C'!$A:$A,"新豐9線",'0731 4度C'!$B:$B,"平均") -> 0 | M21: =SUMIFS('0731 4度C'!$AD:$AD,'0731 4度C'!$A:$A,"新豐4線",'0731 4度C'!$B:$B,"平均") -> 0
B22: 配置人數 | D22: =SUMIFS('0731 4度C'!$I:$I,'0731 4度C'!$A:$A,"新豐6線",'0731 4度C'!$B:$B,"平均") -> 15.333333 | E22: =SUMIFS('0731 4度C'!$I:$I,'0731 4度C'!$A:$A,"新豐2線",'0731 4度C'!$B:$B,"平均") -> 17.5 | F22: =SUMIFS('0731 4度C'!$I:$I,'0731 4度C'!$A:$A,"新豐5線",'0731 4度C'!$B:$B,"平均") -> 18.428571 | G22: =SUMIFS('0731 4度C'!$I:$I,'0731 4度C'!$A:$A,"新豐7線",'0731 4度C'!$B:$B,"平均") -> 15.666667 | H22: =SUMIFS('0731 4度C'!$I:$I,'0731 4度C'!$A:$A,"新豐3線",'0731 4度C'!$B:$B,"平均") -> 9.25 | I22: =SUMIFS('0731 4度C'!$I:$I,'0731 4度C'!$A:$A,"新豐1線",'0731 4度C'!$B:$B,"平均") -> 17.777778 | J22: =SUMIFS('0731 4度C'!$I:$I,'0731 4度C'!$A:$A,"新豐10線",'0731 4度C'!$B:$B,"平均") -> 10.25 | K22: =SUMIFS('0731 4度C'!$I:$I,'0731 4度C'!$A:$A,"新豐8線",'0731 4度C'!$B:$B,"平均") -> 17.428571 | L22: =SUMIFS('0731 4度C'!$I:$I,'0731 4度C'!$A:$A,"新豐9線",'0731 4度C'!$B:$B,"平均") -> 17.75 | M22: =SUMIFS('0731 4度C'!$I:$I,'0731 4度C'!$A:$A,"新豐4線",'0731 4度C'!$B:$B,"平均") -> 16.142857
B23: 主要應用設備 | D23: ET-55 | E23: 熱縮爐 | F23: L型包裝機 | G23: L型包裝機 | H23: 伺服包裝機 | I23: ET-55 | J23: 伺服包裝機 | K23: 三明治包裝機 | L23: 三明治包裝機 | M23: 三明治包裝機
B24: 次要應用設備 | F24: 圓盤機 | G24: ET-55
B25: 備註 | E25: 握沙拉 | F25: 共用L型包裝機 | H25: 調理麵包 | I25: 炒飯+沙拉 | J25: 調理麵包

Sheet 0731 4度C
A1: 新豐廠四度C日報分析 | C1: 總生產量 | D1: =SUM(F5:F69) -> 144931 | E1: 營業額 | F1: =SUM(G5:G69) -> 5031860 | G1: 出勤人數 | H1: =L8+L13+L46+L56+L21+L61+L36+L41+L28+L69 -> 155.52778 | I1: 產線配置圖 | L1: 生產實績 | O1: 人時性差異分析 | S1: 日報登錄 | Y1: 合計 次數 | Z1: 合計 時間/分 | AA1: 產線異常 分析說明(5分鐘以上) | AC1: 合計 次數 | AD1: 合計 設備次數 | AE1: 產能差異分析
A2: 46234 | B2: 星期五 | C2: 人時性 | D2: =AVERAGE(N8,N13,N46,N56,N21,N61,N28,N36,N41,N69) -> 151.29095 | E2: 平均廠價 | F2: =F1/D1 -> 34.719004 | G2: 多次生產數 | H2: =COUNT(H5:H69) -> 2 | Y2: =SUM(Y8+Y13+Y21+Y28+Y36+Y41+Y46+Y56+Y61+Y69) -> 0 | Z2: =SUM(Z8+Z13+Z21+Z28+Z36+Z41+Z46+Z56+Z61+Z69) -> 0 | AC2: 55 | AD2: =SUM(AD8+AD13+AD21+AD28+AD36+AD41+AD46+AD56+AD61+AD69) -> 0
A3: 線別 | B3: 品類 | C3: 品名 | E3: 廠價 | F3: 生產量 | G3: 營收 | H3: 多次 生產 | I3: 人數 | J3: 產能/時 | K3: 人時性 | L3: 人數 | M3: 產能/時 | N3: 人時性 | O3: 人數 | P3: 人時性 | Q3: 達成率 | R3: 達成率平均 | S3: 生產時間 | U3: 換線、休息/分 | V3: 稼動時間/分 | W3: 休息時間 | Y3: 產線異常統計 (5分鐘以上) | AA3: (新豐回填) | AC3: 短暫停線統計 (5分鐘以下) | AE3: 產能/時 | AF3: 達成率 | AG3: 達成率平均
S4: 開始 | T4: 結束 | W4: 開始 | X4: 結束 | Y4: 次數 | Z4: 時間/分 | AC4: 總次數 | AD4: 設備因素(次數)
A5: 新豐6線 | B5: 微波主食 | C5: 二配金咖哩果香甘口咖哩飯 | E5: 50.92 | F5: 1631 | G5: =E5*F5 -> 83050.52 | I5: 15 | J5: 2000 | K5: =J5/I5 -> 133.33333 | L5: 15 | M5: =F5/V5*60 -> 1918.8235 | N5: =M5/L5 -> 127.92157 | O5: =L5-I5 -> 0 | P5: =N5-K5 -> -5.4117647 | Q5: =N5/K5 -> 0.95941176 | R5: =Q8 -> 0.96516642 | S5: 0.70833333 | T5: 0.74375 | V5: =(T5-S5)*24*60 -> 51 | AC5: 3 | AE5: =M5-J5 -> -81.176471 | AF5: =M5/J5 -> 0.95941176 | AG5: =AF8 -> 0.96516642
A6: 新豐6線 | B6: 微波主食 | C6: 二配金咖哩濃厚辛口咖哩飯 | E6: 50.98 | F6: 1619 | G6: =E6*F6 -> 82536.62 | I6: 16 | J6: 2000 | K6: =J6/I6 -> 125 | L6: 16 | M6: =F6/V6*60 -> 1942.8 | N6: =M6/L6 -> 121.425 | O6: =L6-I6 -> 0 | P6: =N6-K6 -> -3.575 | Q6: =N6/K6 -> 0.9714 | S6: 0.74930556 | T6: 0.78402778 | U6: =IF(S6=TIME(17,0,0),"",(S6-T5)*24*60) -> 8 | V6: =(T6-S6)*24*60 -> 50 | AE6: =M6-J6 -> -57.2 | AF6: =M6/J6 -> 0.9714
A7: 新豐6線 | B7: 微波主食 | C7: 二配泰式綠咖哩雞 | E7: 50.67 | F7: 1029 | G7: =E7*F7 -> 52139.43 | I7: 15 | J7: 2000 | K7: =J7/I7 -> 133.33333 | L7: 15 | M7: =F7/V7*60 -> 1929.375 | N7: =M7/L7 -> 128.625 | O7: =L7-I7 -> 0 | P7: =N7-K7 -> -4.7083333 | Q7: =N7/K7 -> 0.9646875 | S7: 0.78819444 | T7: 0.81041667 | U7: =IF(S7=TIME(17,0,0),"",(S7-T6)*24*60) -> 6 | V7: =(T7-S7)*24*60 -> 32 | AE7: =M7-J7 -> -70.625 | AF7: =M7/J7 -> 0.9646875
A8: 新豐6線 | B8: 平均 | I8: 15.333333 | J8: 2000 | K8: =J8/I8 -> 130.43478 | L8: 15.333333 | M8: =AVERAGE(M5:M7) -> 1930.3328 | N8: =M8/L8 -> 125.89127 | O8: =L8-I8 -> 0 | P8: =N8-K8 -> -4.5435102 | Q8: =N8/K8 -> 0.96516642 | Y8: =SUM(Y5:Y7) -> 0 | Z8: =SUM(Z5:Z7) -> 0 | AC8: 3 | AD8: =SUM(AD5:AD7) -> 0 | AE8: =M8-J8 -> -69.667157 | AF8: =M8/J8 -> 0.96516642
A9: 新豐2線 | B9: 沙拉 | C9: 青檸烤雞握沙拉(113年) | E9: 39.8 | F9: 5213 | G9: =E9*F9 -> 207477.4 | I9: 17 | J9: 1500 | K9: =J9/I9 -> 88.235294 | L9: 17 | M9: =F9/V9*60 -> 1434.7706 | N9: =M9/L9 -> 84.398273 | O9: =L9-I9 -> 0 | P9: =N9-K9 -> -3.837021 | Q9: =N9/K9 -> 0.95651376 | R9: =Q13 -> 0.95720707 | S9: 0.083333333 | T9: 0.23472222 | V9: =(T9-S9)*24*60 -> 218 | W9: =T9 -> 0.23472222 | X9: =S10 -> 0.25486111 | AC9: 4 | AE9: =M9-J9 -> -65.229358 | AF9: =M9/J9 -> 0.95651376 | AG9: =AF13 -> 0.95720707
A10: 新豐2線 | B10: 沙拉 | C10: 厚蛋時蔬握沙拉 | E10: 39.46 | F10: 2301 | G10: =E10*F10 -> 90797.46 | I10: 15 | J10: 1500 | K10: =J10/I10 -> 100 | L10: 15 | M10: =F10/V10*60 -> 1438.125 | N10: =M10/L10 -> 95.875 | O10: =L10-I10 -> 0 | P10: =N10-K10 -> -4.125 | Q10: =N10/K10 -> 0.95875 | S10: 0.25486111 | T10: 0.32152778 | U10: =IF(S10=TIME(17,0,0),"",(S10-T9)*24*60) -> 29 | V10: =(T10-S10)*24*60 -> 96 | AE10: =M10-J10 -> -61.875 | AF10: =M10/J10 -> 0.95875
A11: 新豐2線 | B11: 沙拉 | C11: 地瓜瓜握沙拉 | E11: 39.52 | F11: 1919 | G11: =E11*F11 -> 75838.88 | I11: 19 | J11: 1500 | K11: =J11/I11 -> 78.947368 | L11: 19 | M11: =F11/V11*60 -> 1439.25 | N11: =M11/L11 -> 75.75 | O11: =L11-I11 -> 0 | P11: =N11-K11 -> -3.1973684 | Q11: =N11/K11 -> 0.9595 | S11: 0.32569444 | T11: 0.38125 | U11: =IF(S11=TIME(17,0,0),"",(S11-T10)*24*60) -> 6 | V11: =(T11-S11)*24*60 -> 80 | AE11: =M11-J11 -> -60.75 | AF11: =M11/J11 -> 0.9595
A12: 新豐2線 | B12: 沙拉 | C12: 青醬優格雞肉握沙拉(113年) | E12: 39.62 | F12: 3697 | G12: =E12*F12 -> 146475.14 | I12: 19 | J12: 1500 | K12: =J12/I12 -> 78.947368 | L12: 19 | M12: =F12/V12*60 -> 1431.0968 | N12: =M12/L12 -> 75.320883 | O12: =L12-I12 -> 0 | P12: =N12-K12 -> -3.6264856 | Q12: =N12/K12 -> 0.95406452 | S12: 0.38472222 | T12: 0.49236111 | U12: =IF(S12=TIME(17,0,0),"",(S12-T11)*24*60) -> 5 | V12: =(T12-S12)*24*60 -> 155 | AE12: =M12-J12 -> -68.903226 | AF12: =M12/J12 -> 0.95406452
A13: 新豐2線 | B13: 平均 | I13: 17.5 | J13: 1500 | K13: =J13/I13 -> 85.714286 | L13: 17.5 | M13: =AVERAGE(M9:M12) -> 1435.8106 | N13: =M13/L13 -> 82.04632 | O13: =L13-I13 -> 0 | P13: =N13-K13 -> -3.6679655 | Q13: =N13/K13 -> 0.95720707 | Y13: =SUM(Y9:Y12) -> 0 | Z13: =SUM(Z9:Z12) -> 0 | AC13: 4 | AD13: =SUM(AD9:AD12) -> 0 | AE13: =M13-J13 -> -64.189396 | AF13: =M13/J13 -> 0.95720707
A14: 新豐5線 | B14: 季節調理麵 | C14: 台式麻醬涼麵(115年) | E14: 31.11 | F14: 3126 | G14: =E14*F14 -> 97249.86 | I14: 14 | J14: 2000 | K14: =J14/I14 -> 142.85714 | L14: 14 | M14: =F14/V14*60 -> 1913.8776 | N14: =M14/L14 -> 136.70554 | O14: =L14-I14 -> 0 | P14: =N14-K14 -> -6.1516035 | Q14: =N14/K14 -> 0.95693878 | R14: =Q21 -> 0.96097409 | S14: 0.083333333 | T14: 0.15138889 | V14: =(T14-S14)*24*60 -> 98 | W14: =T14 -> 0.15138889 | X14: =S15 -> 0.17013889 | AC14: 7 | AE14: =M14-J14 -> -86.122449 | AF14: =M14/J14 -> 0.95693878 | AG14: =AF21 -> 0.96097409
A15: 新豐5線 | B15: 小吃 | C15: 香菇雞燉湯 | E15: 38.62 | F15: 1862 | G15: =E15*F15 -> 71910.44 | I15: 24 | J15: 1500 | K15: =J15/I15 -> 62.5 | L15: 24 | M15: =F15/V15*60 -> 1432.3077 | N15: =M15/L15 -> 59.679487 | O15: =L15-I15 -> 0 | P15: =N15-K15 -> -2.8205128 | Q15: =N15/K15 -> 0.95487179 | S15: 0.17013889 | T15: 0.22430556 | U15: =IF(S15=TIME(17,0,0),"",(S15-T14)*24*60) -> 27 | V15: =(T15-S15)*24*60 -> 78 | AE15: =M15-J15 -> -67.692308 | AF15: =M15/J15 -> 0.95487179
A16: 新豐5線 | B16: 小吃 | C16: 剝皮辣椒雞湯 | E16: 41 | F16: 1537 | G16: =E16*F16 -> 63017 | I16: 26 | J16: 1500 | K16: =J16/I16 -> 57.692308 | L16: 26 | M16: =F16/V16*60 -> 1440.9375 | N16: =M16/L16 -> 55.420673 | O16: =L16-I16 -> 0 | P16: =N16-K16 -> -2.2716346 | Q16: =N16/K16 -> 0.960625 | S16: 0.22986111 | T16: 0.27430556 | U16: =IF(S16=TIME(17,0,0),"",(S16-T15)*24*60) -> 8 | V16: =(T16-S16)*24*60 -> 64 | AE16: =M16-J16 -> -59.0625 | AF16: =M16/J16 -> 0.960625
A17: 新豐5線 | B17: 微波主食 | C17: 香菇雞粥 | E17: 37.03 | F17: 2893 | G17: =E17*F17 -> 107127.79 | I17: 13 | J17: 1500 | K17: =J17/I17 -> 115.38462 | L17: 13 | M17: =F17/V17*60 -> 1434.5455 | N17: =M17/L17 -> 110.34965 | O17: =L17-I17 -> 0 | P17: =N17-K17 -> -5.034965 | Q17: =N17/K17 -> 0.95636364 | S17: 0.27916667 | T17: 0.36319444 | U17: =IF(S17=TIME(17,0,0),"",(S17-T16)*24*60) -> 7 | V17: =(T17-S17)*24*60 -> 121 | AE17: =M17-J17 -> -65.454545 | AF17: =M17/J17 -> 0.95636364
A18: 新豐5線 | B18: 微波主食 | C18: 二配港式香滑嫩蛋牛肉燴飯 | E18: 50.67 | F18: 1164 | G18: =E18*F18 -> 58979.88 | I18: 17 | J18: 2000 | K18: =J18/I18 -> 117.64706 | L18: 17 | M18: =F18/V18*60 -> 1940 | N18: =M18/L18 -> 114.11765 | O18: =L18-I18 -> 0 | P18: =N18-K18 -> -3.5294118 | Q18: =N18/K18 -> 0.97 | S18: 0.70833333 | T18: 0.73333333 | U18: =IF(S18=TIME(17,0,0),"",(S18-T17)*24*60) | V18: =(T18-S18)*24*60 -> 36 | AE18: =M18-J18 -> -60 | AF18: =M18/J18 -> 0.97
A19: 新豐5線 | B19: 微波主食 | C19: 二配玉米濃湯焗烤飯 | E19: 54.5 | F19: 1541 | G19: =E19*F19 -> 83984.5 | I19: 20 | J19: 1500 | K19: =J19/I19 -> 75 | L19: 20 | M19: =F19/V19*60 -> 1444.6875 | N19: =M19/L19 -> 72.234375 | O19: =L19-I19 -> 0 | P19: =N19-K19 -> -2.765625 | Q19: =N19/K19 -> 0.963125 | S19: 0.73819444 | T19: 0.78263889 | U19: =IF(S19=TIME(17,0,0),"",(S19-T18)*24*60) -> 7 | V19: =(T19-S19)*24*60 -> 64 | AE19: =M19-J19 -> -55.3125 | AF19: =M19/J19 -> 0.963125
A20: 新豐5線 | B20: 微波主食 | C20: 二配川味麻婆燒豆腐燴飯 | E20: 50.49 | F20: 1444 | G20: =E20*F20 -> 72907.56 | I20: 15 | J20: 2000 | K20: =J20/I20 -> 133.33333 | L20: 15 | M20: =F20/V20*60 -> 1925.3333 | N20: =M20/L20 -> 128.35556 | O20: =L20-I20 -> 0 | P20: =N20-K20 -> -4.9777778 | Q20: =N20/K20 -> 0.96266667 | S20: 0.78819444 | T20: 0.81944444 | U20: =IF(S20=TIME(17,0,0),"",(S20-T19)*24*60) -> 8 | V20: =(T20-S20)*24*60 -> 45 | AE20: =M20-J20 -> -74.666667 | AF20: =M20/J20 -> 0.96266667
A21: 新豐5線 | B21: 平均 | I21: 18.428571 | J21: 1714.2857 | K21: =J21/I21 -> 93.023256 | L21: 18.428571 | M21: =AVERAGE(M14:M20) -> 1647.3841 | N21: =M21/L21 -> 89.392938 | O21: =L21-I21 -> 0 | P21: =N21-K21 -> -3.6303176 | Q21: =N21/K21 -> 0.96097409 | Y21: =SUM(Y14:Y20) -> 0 | Z21: =SUM(Z14:Z20) -> 0 | AC21: 7 | AD21: =SUM(AD14:AD20) -> 0 | AE21: =M21-J21 -> -66.901567 | AF21: =M21/J21 -> 0.96097409
A22: 新豐7線 | B22: 微波主食 | C22: 韓式泡菜豬肉豆腐丼飯 | E22: 50.67 | F22: 1296 | G22: =E22*F22 -> 65668.32 | I22: 17 | J22: 2000 | K22: =J22/I22 -> 117.64706 | L22: 17 | M22: =F22/V22*60 -> 1944 | N22: =M22/L22 -> 114.35294 | O22: =L22-I22 -> 0 | P22: =N22-K22 -> -3.2941176 | Q22: =N22/K22 -> 0.972 | R22: =Q28 -> 0.9622343 | S22: 0.20833333 | T22: 0.23611111 | V22: =(T22-S22)*24*60 -> 40 | AC22: 6 | AE22: =M22-J22 -> -56 | AF22: =M22/J22 -> 0.972 | AG22: =AF28 -> 0.9622343
A23: 新豐7線 | B23: 微波主食 | C23: 鐵板滑蛋炸豬排丼 | E23: 57.73 | F23: 1857 | G23: =E23*F23 -> 107204.61 | I23: 14 | J23: 2000 | K23: =J23/I23 -> 142.85714 | L23: 14 | M23: =F23/V23*60 -> 1921.0345 | N23: =M23/L23 -> 137.21675 | O23: =L23-I23 -> 0 | P23: =N23-K23 -> -5.6403941 | Q23: =N23/K23 -> 0.96051724 | S23: 0.24097222 | T23: 0.28125 | U23: =IF(S23=TIME(17,0,0),"",(S23-T22)*24*60) -> 7 | V23: =(T23-S23)*24*60 -> 58 | AE23: =M23-J23 -> -78.965517 | AF23: =M23/J23 -> 0.96051724
A24: 新豐7線 | B24: 微波主食 | C24: 日式炙烤親子丼 | E24: 53.27 | F24: 1086 | G24: =E24*F24 -> 57851.22 | I24: 16 | J24: 2000 | K24: =J24/I24 -> 125 | L24: 16 | M24: =F24/V24*60 -> 1916.4706 | N24: =M24/L24 -> 119.77941 | O24: =L24-I24 -> 0 | P24: =N24-K24 -> -5.2205882 | Q24: =N24/K24 -> 0.95823529 | S24: 0.28541667 | T24: 0.30902778 | U24: =IF(S24=TIME(17,0,0),"",(S24-T23)*24*60) -> 6 | V24: =(T24-S24)*24*60 -> 34 | AE24: =M24-J24 -> -83.529412 | AF24: =M24/J24 -> 0.95823529
A25: 新豐7線 | B25: 微波主食 | C25: 二配厚香料優格咖哩雞排飯 | E25: 56.43 | F25: 1157 | G25: =E25*F25 -> 65289.51 | I25: 13 | J25: 2000 | K25: =J25/I25 -> 153.84615 | L25: 13 | M25: =F25/V25*60 -> 1928.3333 | N25: =M25/L25 -> 148.33333 | O25: =L25-I25 -> 0 | P25: =N25-K25 -> -5.5128205 | Q25: =N25/K25 -> 0.96416667 | S25: 0.70833333 | T25: 0.73333333 | U25: =IF(S25=TIME(17,0,0),"",(S25-T24)*24*60) | V25: =(T25-S25)*24*60 -> 36 | AE25: =M25-J25 -> -71.666667 | AF25: =M25/J25 -> 0.96416667
A26: 新豐7線 | B26: 微波主食 | C26: 二配美味蟹煲 | E26: 54.09 | F26: 1852 | G26: =E26*F26 -> 100174.68 | I26: 18 | J26: 2000 | K26: =J26/I26 -> 111.11111 | L26: 18 | M26: =F26/V26*60 -> 1915.8621 | N26: =M26/L26 -> 106.43678 | O26: =L26-I26 -> 0 | P26: =N26-K26 -> -4.6743295 | Q26: =N26/K26 -> 0.95793103 | S26: 0.73888889 | T26: 0.77916667 | U26: =IF(S26=TIME(17,0,0),"",(S26-T25)*24*60) -> 8 | V26: =(T26-S26)*24*60 -> 58 | AE26: =M26-J26 -> -84.137931 | AF26: =M26/J26 -> 0.95793103
A27: 新豐7線 | B27: 微波主食 | C27: 二配泰式檸檬魚飯 | E27: 57.3 | F27: 1729 | G27: =E27*F27 -> 99071.7 | I27: 16 | J27: 2000 | K27: =J27/I27 -> 125 | L27: 16 | M27: =F27/V27*60 -> 1921.1111 | N27: =M27/L27 -> 120.06944 | O27: =L27-I27 -> 0 | P27: =N27-K27 -> -4.9305556 | Q27: =N27/K27 -> 0.96055556 | S27: 0.78333333 | T27: 0.82083333 | U27: =IF(S27=TIME(17,0,0),"",(S27-T26)*24*60) -> 6 | V27: =(T27-S27)*24*60 -> 54 | AE27: =M27-J27 -> -78.888889 | AF27: =M27/J27 -> 0.96055556
A28: 新豐7線 | B28: 平均 | I28: 15.666667 | J28: 2000 | K28: =J28/I28 -> 127.65957 | L28: 15.666667 | M28: =AVERAGE(M22:M27) -> 1924.4686 | N28: =M28/L28 -> 122.83842 | O28: =L28-I28 -> 0 | P28: =N28-K28 -> -4.8211534 | Q28: =N28/K28 -> 0.9622343 | Y28: =SUM(Y22:Y27) -> 0 | Z28: =SUM(Z22:Z27) -> 0 | AC28: 6 | AD28: =SUM(AD22:AD27) -> 0 | AE28: =M28-J28 -> -75.531403 | AF28: =M28/J28 -> 0.9622343
A29: 新豐8線 | B29: 三明治 | C29: 紐奧良風味烤雞鮮蔬三明治 | E29: 31.29 | F29: 6590 | G29: =E29*F29 -> 206201.1 | I29: 18 | J29: 2400 | K29: =J29/I29 -> 133.33333 | L29: 18 | M29: =F29/V29*60 -> 2285.5491 | N29: =M29/L29 -> 126.97495 | O29: =L29-I29 -> 0 | P29: =N29-K29 -> -6.3583815 | Q29: =N29/K29 -> 0.95231214 | R29: =Q36 -> 0.95978079 | S29: 0.083333333 | T29: 0.20347222 | V29: =(T29-S29)*24*60 -> 173 | W29: =T29 -> 0.20347222 | X29: =S30 -> 0.22361111 | AC29: 7 | AE29: =M29-J29 -> -114.45087 | AF29: =M29/J29 -> 0.95231214 | AG29: =AF36 -> 0.95978079
A30: 新豐8線 | B30: 三明治 | C30: 醬燒烤雞三明治(115年) | E30: 26.37 | F30: 4918 | G30: =E30*F30 -> 129687.66 | I30: 18 | J30: 2400 | K30: =J30/I30 -> 133.33333 | L30: 18 | M30: =F30/V30*60 -> 2287.4419 | N30: =M30/L30 -> 127.0801 | O30: =L30-I30 -> 0 | P30: =N30-K30 -> -6.25323 | Q30: =N30/K30 -> 0.95310078 | S30: 0.22361111 | T30: 0.31319444 | U30: =(S30-T29)*24*60 -> 29 | V30: =(T30-S30)*24*60 -> 129 | AE30: =M30-J30 -> -112.55814 | AF30: =M30/J30 -> 0.95310078
A31: 新豐8線 | B31: 三明治 | C31: 鮪魚起司溏心蛋三明治(115年) | E31: 26.18 | F31: 3500 | G31: =E31*F31 -> 91630 | H31: 2 | I31: 18 | J31: 2400 | K31: =J31/I31 -> 133.33333 | L31: 18 | M31: =F31/V31*60 -> 2307.6923 | N31: =M31/L31 -> 128.20513 | O31: =L31-I31 -> 0 | P31: =N31-K31 -> -5.1282051 | Q31: =N31/K31 -> 0.96153846 | S31: 0.31666667 | T31: 0.37986111 | U31: =(S31-T30)*24*60 -> 5 | V31: =(T31-S31)*24*60 -> 91 | AE31: =M31-J31 -> -92.307692 | AF31: =M31/J31 -> 0.96153846
A32: 新豐8線 | B32: 三明治 | C32: 茄汁厚起司三明治 | E32: 25.99 | F32: 931 | G32: =E32*F32 -> 24196.69 | I32: 18 | J32: 2400 | K32: =J32/I32 -> 133.33333 | L32: 18 | M32: =F32/V32*60 -> 2327.5 | N32: =M32/L32 -> 129.30556 | O32: =L32-I32 -> 0 | P32: =N32-K32 -> -4.0277778 | Q32: =N32/K32 -> 0.96979167 | S32: 0.38402778 | T32: 0.40069444 | U32: =(S32-T31)*24*60 -> 6 | V32: =(T32-S32)*24*60 -> 24 | AE32: =M32-J32 -> -72.5 | AF32: =M32/J32 -> 0.96979167
A33: 新豐8線 | B33: 三明治 | C33: 雞蛋沙拉三明治(114年) | E33: 25.99 | F33: 3070 | G33: =E33*F33 -> 79789.3 | I33: 14 | J33: 2400 | K33: =J33/I33 -> 171.42857 | L33: 14 | M33: =F33/V33*60 -> 2302.5 | N33: =M33/L33 -> 164.46429 | O33: =L33-I33 -> 0 | P33: =N33-K33 -> -6.9642857 | Q33: =N33/K33 -> 0.959375 | S33: 0.40416667 | T33: 0.45972222 | U33: =(S33-T32)*24*60 -> 5 | V33: =(T33-S33)*24*60 -> 80 | AE33: =M33-J33 -> -97.5 | AF33: =M33/J33 -> 0.959375
A34: 新豐8線 | B34: 三明治 | C34: 榛果摩卡脆脆三明治 | E34: 20.21 | F34: 1785 | G34: =E34*F34 -> 36074.85 | I34: 18 | J34: 2400 | K34: =J34/I34 -> 133.33333 | L34: 18 | M34: =F34/V34*60 -> 2328.2609 | N34: =M34/L34 -> 129.34783 | O34: =L34-I34 -> 0 | P34: =N34-K34 -> -3.9855072 | Q34: =N34/K34 -> 0.9701087 | S34: 0.46388889 | T34: 0.49583333 | U34: =(S34-T33)*24*60 -> 6 | V34: =(T34-S34)*24*60 -> 46 | W34: =T34 -> 0.49583333 | X34: =S35 -> 0.53680556 | AE34: =M34-J34 -> -71.73913 | AF34: =M34/J34 -> 0.9701087
A35: 新豐8線 | B35: 三明治 | C35: 鮪魚起司溏心蛋三明治(115年) | E35: 26.18 | F35: 2552 | G35: =E35*F35 -> 66811.36 | I35: 18 | J35: 2400 | K35: =J35/I35 -> 133.33333 | L35: 18 | M35: =F35/V35*60 -> 2285.3731 | N35: =M35/L35 -> 126.96517 | O35: =L35-I35 -> 0 | P35: =N35-K35 -> -6.3681592 | Q35: =N35/K35 -> 0.95223881 | S35: 0.53680556 | T35: 0.58333333 | U35: =(S35-T34)*24*60 -> 59 | V35: =(T35-S35)*24*60 -> 67 | AE35: =M35-J35 -> -114.62687 | AF35: =M35/J35 -> 0.95223881
A36: 新豐8線 | B36: 平均 | I36: 17.428571 | J36: 2400 | K36: =J36/I36 -> 137.70492 | L36: 17.428571 | M36: =AVERAGE(M29:M35) -> 2303.4739 | N36: =M36/L36 -> 132.16654 | O36: =L36-I36 -> 0 | P36: =N36-K36 -> -5.5383827 | Q36: =N36/K36 -> 0.95978079 | Y36: =SUM(Y29:Y35) -> 0 | Z36: =SUM(Z29:Z35) -> 0 | AC36: 7 | AD36: =SUM(AD29:AD35) -> 0 | AE36: =M36-J36 -> -96.526099 | AF36: =M36/J36 -> 0.95978079
A37: 新豐9線 | B37: 三明治 | C37: 經典總匯三明治(115年) | E37: 26.18 | F37: 4645 | G37: =E37*F37 -> 121606.1 | I37: 20 | J37: 2400 | K37: =J37/I37 -> 120 | L37: 20 | M37: =F37/V37*60 -> 2284.4262 | N37: =M37/L37 -> 114.22131 | O37: =L37-I37 -> 0 | P37: =N37-K37 -> -5.7786885 | Q37: =N37/K37 -> 0.95184426 | R37: =Q41 -> 0.95704557 | S37: 0.083333333 | T37: 0.16805556 | V37: =(T37-S37)*24*60 -> 122 | W37: =T37 -> 0.16805556 | X37: =S38 -> 0.18680556 | AC37: 4 | AE37: =M37-J37 -> -115.57377 | AF37: =M37/J37 -> 0.95184426 | AG37: =AF41 -> 0.95704557
A38: 新豐9線 | B38: 三明治 | C38: 經典火腿玉米蛋三明治 | E38: 24.43 | F38: 5498 | G38: =E38*F38 -> 134316.14 | I38: 14 | J38: 2400 | K38: =J38/I38 -> 171.42857 | L38: 14 | M38: =F38/V38*60 -> 2290.8333 | N38: =M38/L38 -> 163.63095 | O38: =L38-I38 -> 0 | P38: =N38-K38 -> -7.797619 | Q38: =N38/K38 -> 0.95451389 | S38: 0.18680556 | T38: 0.28680556 | U38: =(S38-T37)*24*60 -> 27 | V38: =(T38-S38)*24*60 -> 144 | AE38: =M38-J38 -> -109.16667 | AF38: =M38/J38 -> 0.95451389
A39: 新豐9線 | B39: 三明治 | C39: 五彩鮮蔬三明治 | E39: 25.98 | F39: 2817 | G39: =E39*F39 -> 73185.66 | I39: 20 | J39: 2400 | K39: =J39/I39 -> 120 | L39: 20 | M39: =F39/V39*60 -> 2315.3425 | N39: =M39/L39 -> 115.76712 | O39: =L39-I39 -> 0 | P39: =N39-K39 -> -4.2328767 | Q39: =N39/K39 -> 0.96472603 | S39: 0.29097222 | T39: 0.34166667 | U39: =(S39-T38)*24*60 -> 6 | V39: =(T39-S39)*24*60 -> 73 | AE39: =M39-J39 -> -84.657534 | AF39: =M39/J39 -> 0.96472603
A40: 新豐9線 | B40: 三明治 | C40: 好多蛋三明治 | E40: 34.1 | F40: 4926 | G40: =E40*F40 -> 167976.6 | I40: 17 | J40: 1600 | K40: =J40/I40 -> 94.117647 | L40: 17 | M40: =F40/V40*60 -> 1531.399 | N40: =M40/L40 -> 90.082292 | O40: =L40-I40 -> 0 | P40: =N40-K40 -> -4.0353551 | Q40: =N40/K40 -> 0.95712435 | S40: 0.34652778 | T40: 0.48055556 | U40: =(S40-T39)*24*60 -> 7 | V40: =(T40-S40)*24*60 -> 193 | AE40: =M40-J40 -> -68.601036 | AF40: =M40/J40 -> 0.95712435
...

Sheet 0730
B1: 屏榮 新豐廠組合室生產人時性分析
B3: 日期 | C3: =TEXT('0730 4度C'!A2,"yyyy.mm.ddaaaa") -> 2026.07.30星期四 | E3: 訂單量 | F3: ='0730 4度C'!D1 -> 172118 | H3: 營業額 | I3: ='0730 4度C'!F1 -> 5885033.6
B4: 人時性 | C4: 項目 | E4: ➀ | G4: ➁ | I4: ➂ | K4: 異常停線 | M4: 短暫停線
C5: 組合室 | E5: 全溫層 | G5: 4度C-各編組展開 | I5: ③三明治-各編組展開 | K5: 合計次數 | L5: 時間 | M5: 合計次數 | N5: 設備次數
C6: 排關平均 | E6: =AVERAGE(D13:M13) -> 158.79229 | F6: =AVERAGE(D31:O31,D13:J13) -> 166.69025 | G6: =AVERAGE(D13:J13) -> 166.69025 | I6: =AVERAGE(K13:M13) -> 140.36372 | K6: ='0730 4度C'!Y2 -> 0 | L6: ='0730 4度C'!Z2 -> 0 | M6: ='0730 4度C'!AC2 -> 62 | N6: ='0730 4度C'!AD2 -> 0
C7: 實績平均 | E7: =AVERAGE(D14:M14) -> 152.47129 | F7: =AVERAGE(D32:O32,D14:J14) -> 160.19018 | G7: =AVERAGE(D14:J14) -> 160.19018 | I7: =AVERAGE(K14:M14) -> 134.46054
C8: 達成率平均 | E8: =AVERAGE(D15:M15) -> 0.96014685 | F8: =AVERAGE(D15:J15,D33:O33) -> 0.96110053 | G8: =AVERAGE(D15:J15) -> 0.96110053 | I8: =AVERAGE(K15:M15) -> 0.95792159
K9: ※現行日本鮮食廠以達成率80%為基本(即為現行KPI)
B10: 溫層 | D10: ➁4度C-各編組展開 | K10: ③三明治-各編組展開
B11: 編組 | D11: 1 | E11: 2 | F11: 3 | G11: 4 | H11: 5 | I11: 6 | J11: 7 | K11: 1 | L11: 2 | M11: 3
D12: 新豐6線 | E12: 新豐2線 | F12: 新豐5線 | G12: 新豐7線 | H12: 新豐3線 | I12: 新豐1線 | J12: 新豐10線 | K12: 新豐8線 | L12: 新豐9線 | M12: 新豐4線
B13: 人時性 | C13: 排關 | D13: =SUMIFS('0730 4度C'!$K:$K,'0730 4度C'!$A:$A,"新豐6線",'0730 4度C'!$B:$B,"平均") -> 130.43478 | E13: =SUMIFS('0730 4度C'!$K:$K,'0730 4度C'!$A:$A,"新豐2線",'0730 4度C'!$B:$B,"平均") -> 86.206897 | F13: =SUMIFS('0730 4度C'!$K:$K,'0730 4度C'!$A:$A,"新豐5線",'0730 4度C'!$B:$B,"平均") -> 93.023256 | G13: =SUMIFS('0730 4度C'!$K:$K,'0730 4度C'!$A:$A,"新豐7線",'0730 4度C'!$B:$B,"平均") -> 127.65957 | H13: =SUMIFS('0730 4度C'!$K:$K,'0730 4度C'!$A:$A,"新豐3線",'0730 4度C'!$B:$B,"平均") -> 324.32432 | I13: =SUMIFS('0730 4度C'!$K:$K,'0730 4度C'!$A:$A,"新豐1線",'0730 4度C'!$B:$B,"平均") -> 112.5 | J13: =SUMIFS('0730 4度C'!$K:$K,'0730 4度C'!$A:$A,"新豐10線",'0730 4度C'!$B:$B,"平均") -> 292.68293 | K13: =SUMIFS('0730 4度C'!$K:$K,'0730 4度C'!$A:$A,"新豐8線",'0730 4度C'!$B:$B,"平均") -> 136.70886 | L13: =SUMIFS('0730 4度C'!$K:$K,'0730 4度C'!$A:$A,"新豐9線",'0730 4度C'!$B:$B,"平均") -> 133.33333 | M13: =SUMIFS('0730 4度C'!$K:$K,'0730 4度C'!$A:$A,"新豐4線",'0730 4度C'!$B:$B,"平均") -> 151.04895
C14: 實績 | D14: =SUMIFS('0730 4度C'!$N:$N,'0730 4度C'!$A:$A,"新豐6線",'0730 4度C'!$B:$B,"平均") -> 125.54973 | E14: =SUMIFS('0730 4度C'!$N:$N,'0730 4度C'!$A:$A,"新豐2線",'0730 4度C'!$B:$B,"平均") -> 82.363281 | F14: =SUMIFS('0730 4度C'!$N:$N,'0730 4度C'!$A:$A,"新豐5線",'0730 4度C'!$B:$B,"平均") -> 89.466159 | G14: =SUMIFS('0730 4度C'!$N:$N,'0730 4度C'!$A:$A,"新豐7線",'0730 4度C'!$B:$B,"平均") -> 123.34369 | H14: =SUMIFS('0730 4度C'!$N:$N,'0730 4度C'!$A:$A,"新豐3線",'0730 4度C'!$B:$B,"平均") -> 311.47519 | I14: =SUMIFS('0730 4度C'!$N:$N,'0730 4度C'!$A:$A,"新豐1線",'0730 4度C'!$B:$B,"平均") -> 108.15862 | J14: =SUMIFS('0730 4度C'!$N:$N,'0730 4度C'!$A:$A,"新豐10線",'0730 4度C'!$B:$B,"平均") -> 280.97456 | K14: =SUMIFS('0730 4度C'!$N:$N,'0730 4度C'!$A:$A,"新豐8線",'0730 4度C'!$B:$B,"平均") -> 131.28405 | L14: =SUMIFS('0730 4度C'!$N:$N,'0730 4度C'!$A:$A,"新豐9線",'0730 4度C'!$B:$B,"平均") -> 127.39397 | M14: =SUMIFS('0730 4度C'!$N:$N,'0730 4度C'!$A:$A,"新豐4線",'0730 4度C'!$B:$B,"平均") -> 144.70361
C15: 達成率 | D15: =D14/D13 -> 0.96254795 | E15: =E14/E13 -> 0.95541407 | F15: =F14/F13 -> 0.96176121 | G15: =G14/G13 -> 0.96619225 | H15: =H14/H13 -> 0.96038184 | I15: =I14/I13 -> 0.96140997 | J15: =J14/J13 -> 0.9599964 | K15: =K14/K13 -> 0.96031849 | ... M15: =M14/M13 -> 0.95799149
B16: 作業 時間 | C16: 開始 | D16: =VLOOKUP("新豐6線",'0730 4度C'!$A:$T,19,0) -> 0.70833333 | E16: =VLOOKUP("新豐2線",'0730 4度C'!$A:$T,19,0) -> 0.083333333 | F16: =VLOOKUP("新豐5線",'0730 4度C'!$A:$T,19,0) -> 0.083333333 | G16: =VLOOKUP("新豐7線",'0730 4度C'!$A:$T,19,0) -> 0.20833333 | H16: =VLOOKUP("新豐3線",'0730 4度C'!$A:$T,19,0) -> 0.20833333 | I16: =VLOOKUP("新豐1線",'0730 4度C'!$A:$T,19,0) -> 0.083333333 | J16: =VLOOKUP("新豐10線",'0730 4度C'!$A:$T,19,0) -> 0.20833333 | K16: =VLOOKUP("新豐8線",'0730 4度C'!$A:$T,19,0) -> 0.083333333 | L16: =VLOOKUP("新豐9線",'0730 4度C'!$A:$T,19,0) -> 0.083333333 | M16: =VLOOKUP("新豐4線",'0730 4度C'!$A:$T,19,0) -> 0.083333333
C17: 結束 | D17: =LOOKUP(2,1/(('0730 4度C'!$A:$A="新豐6線")*('0730 4度C'!$T:$T<>"")),'0730 4度C'!$T:$T) -> 0.81666667 | E17: =LOOKUP(2,1/(('0730 4度C'!$A:$A="新豐2線")*('0730 4度C'!$T:$T<>"")),'0730 4度C'!$T:$T) -> 0.57638889 | F17: =LOOKUP(2,1/(('0730 4度C'!$A:$A="新豐5線")*('0730 4度C'!$T:$T<>"")),'0730 4度C'!$T:$T) -> 0.81736111 | G17: =LOOKUP(2,1/(('0730 4度C'!$A:$A="新豐7線")*('0730 4度C'!$T:$T<>"")),'0730 4度C'!$T:$T) -> 0.82638889 | H17: =LOOKUP(2,1/(('0730 4度C'!$A:$A="新豐3線")*('0730 4度C'!$T:$T<>"")),'0730 4度C'!$T:$T) -> 0.40555556 | I17: =LOOKUP(2,1/(('0730 4度C'!$A:$A="新豐1線")*('0730 4度C'!$T:$T<>"")),'0730 4度C'!$T:$T) -> 0.84791667 | J17: =LOOKUP(2,1/(('0730 4度C'!$A:$A="新豐10線")*('0730 4度C'!$T:$T<>"")),'0730 4度C'!$T:$T) -> 0.41527778 | K17: =LOOKUP(2,1/(('0730 4度C'!$A:$A="新豐8線")*('0730 4度C'!$T:$T<>"")),'0730 4度C'!$T:$T) -> 0.68402778 | L17: =LOOKUP(2,1/(('0730 4度C'!$A:$A="新豐9線")*('0730 4度C'!$T:$T<>"")),'0730 4度C'!$T:$T) -> 0.63125 | M17: =LOOKUP(2,1/(('0730 4度C'!$A:$A="新豐4線")*('0730 4度C'!$T:$T<>"")),'0730 4度C'!$T:$T) -> 0.74444444
B18: 產線異常 (5分鐘以上) | C18: 次數 | D18: =SUMIFS('0730 4度C'!$Y:$Y,'0730 4度C'!$A:$A,"新豐6線",'0730 4度C'!$B:$B,"平均") -> 0 | E18: =SUMIFS('0730 4度C'!$Y:$Y,'0730 4度C'!$A:$A,"新豐2線",'0730 4度C'!$B:$B,"平均") -> 0 | F18: =SUMIFS('0730 4度C'!$Y:$Y,'0730 4度C'!$A:$A,"新豐5線",'0730 4度C'!$B:$B,"平均") -> 0 | G18: =SUMIFS('0730 4度C'!$Y:$Y,'0730 4度C'!$A:$A,"新豐7線",'0730 4度C'!$B:$B,"平均") -> 0 | H18: =SUMIFS('0730 4度C'!$Y:$Y,'0730 4度C'!$A:$A,"新豐3線",'0730 4度C'!$B:$B,"平均") -> 0 | I18: =SUMIFS('0730 4度C'!$Y:$Y,'0730 4度C'!$A:$A,"新豐1線",'0730 4度C'!$B:$B,"平均") -> 0 | J18: =SUMIFS('0730 4度C'!$Y:$Y,'0730 4度C'!$A:$A,"新豐10線",'0730 4度C'!$B:$B,"平均") -> 0 | K18: =SUMIFS('0730 4度C'!$Y:$Y,'0730 4度C'!$A:$A,"新豐8線",'0730 4度C'!$B:$B,"平均") -> 0 | L18: =SUMIFS('0730 4度C'!$Y:$Y,'0730 4度C'!$A:$A,"新豐9線",'0730 4度C'!$B:$B,"平均") -> 0 | M18: =SUMIFS('0730 4度C'!$Y:$Y,'0730 4度C'!$A:$A,"新豐4線",'0730 4度C'!$B:$B,"平均") -> 0
C19: 時間/分 | D19: =SUMIFS('0730 4度C'!$Z:$Z,'0730 4度C'!$A:$A,"新豐6線",'0730 4度C'!$B:$B,"平均") -> 0 | E19: =SUMIFS('0730 4度C'!$Z:$Z,'0730 4度C'!$A:$A,"新豐2線",'0730 4度C'!$B:$B,"平均") -> 0 | F19: =SUMIFS('0730 4度C'!$Z:$Z,'0730 4度C'!$A:$A,"新豐5線",'0730 4度C'!$B:$B,"平均") -> 0 | G19: =SUMIFS('0730 4度C'!$Z:$Z,'0730 4度C'!$A:$A,"新豐7線",'0730 4度C'!$B:$B,"平均") -> 0 | H19: =SUMIFS('0730 4度C'!$Z:$Z,'0730 4度C'!$A:$A,"新豐3線",'0730 4度C'!$B:$B,"平均") -> 0 | I19: =SUMIFS('0730 4度C'!$Z:$Z,'0730 4度C'!$A:$A,"新豐1線",'0730 4度C'!$B:$B,"平均") -> 0 | J19: =SUMIFS('0730 4度C'!$Z:$Z,'0730 4度C'!$A:$A,"新豐10線",'0730 4度C'!$B:$B,"平均") -> 0 | K19: =SUMIFS('0730 4度C'!$Z:$Z,'0730 4度C'!$A:$A,"新豐8線",'0730 4度C'!$B:$B,"平均") -> 0 | L19: =SUMIFS('0730 4度C'!$Z:$Z,'0730 4度C'!$A:$A,"新豐9線",'0730 4度C'!$B:$B,"平均") -> 0 | M19: =SUMIFS('0730 4度C'!$Z:$Z,'0730 4度C'!$A:$A,"新豐4線",'0730 4度C'!$B:$B,"平均") -> 0
B20: 短暫停線 (5分鐘以下) | C20: 次數 | D20: =SUMIFS('0730 4度C'!$AC:$AC,'0730 4度C'!$A:$A,"新豐6線",'0730 4度C'!$B:$B,"平均") -> 3 | E20: =SUMIFS('0730 4度C'!$AC:$AC,'0730 4度C'!$A:$A,"新豐2線",'0730 4度C'!$B:$B,"平均") -> 5 | F20: =SUMIFS('0730 4度C'!$AC:$AC,'0730 4度C'!$A:$A,"新豐5線",'0730 4度C'!$B:$B,"平均") -> 7 | G20: =SUMIFS('0730 4度C'!$AC:$AC,'0730 4度C'!$A:$A,"新豐7線",'0730 4度C'!$B:$B,"平均") -> 6 | H20: =SUMIFS('0730 4度C'!$AC:$AC,'0730 4度C'!$A:$A,"新豐3線",'0730 4度C'!$B:$B,"平均") -> 4 | I20: =SUMIFS('0730 4度C'!$AC:$AC,'0730 4度C'!$A:$A,"新豐1線",'0730 4度C'!$B:$B,"平均") -> 9 | J20: =SUMIFS('0730 4度C'!$AC:$AC,'0730 4度C'!$A:$A,"新豐10線",'0730 4度C'!$B:$B,"平均") -> 4 | K20: =SUMIFS('0730 4度C'!$AC:$AC,'0730 4度C'!$A:$A,"新豐8線",'0730 4度C'!$B:$B,"平均") -> 9 | L20: =SUMIFS('0730 4度C'!$AC:$AC,'0730 4度C'!$A:$A,"新豐9線",'0730 4度C'!$B:$B,"平均") -> 6 | M20: =SUMIFS('0730 4度C'!$AC:$AC,'0730 4度C'!$A:$A,"新豐4線",'0730 4度C'!$B:$B,"平均") -> 9
C21: 設備次數 | D21: =SUMIFS('0730 4度C'!$AD:$AD,'0730 4度C'!$A:$A,"新豐6線",'0730 4度C'!$B:$B,"平均") -> 0 | E21: =SUMIFS('0730 4度C'!$AD:$AD,'0730 4度C'!$A:$A,"新豐2線",'0730 4度C'!$B:$B,"平均") -> 0 | F21: =SUMIFS('0730 4度C'!$AD:$AD,'0730 4度C'!$A:$A,"新豐5線",'0730 4度C'!$B:$B,"平均") -> 0 | G21: =SUMIFS('0730 4度C'!$AD:$AD,'0730 4度C'!$A:$A,"新豐7線",'0730 4度C'!$B:$B,"平均") -> 0 | H21: =SUMIFS('0730 4度C'!$AD:$AD,'0730 4度C'!$A:$A,"新豐3線",'0730 4度C'!$B:$B,"平均") -> 0 | I21: =SUMIFS('0730 4度C'!$AD:$AD,'0730 4度C'!$A:$A,"新豐1線",'0730 4度C'!$B:$B,"平均") -> 0 | J21: =SUMIFS('0730 4度C'!$AD:$AD,'0730 4度C'!$A:$A,"新豐10線",'0730 4度C'!$B:$B,"平均") -> 0 | K21: =SUMIFS('0730 4度C'!$AD:$AD,'0730 4度C'!$A:$A,"新豐8線",'0730 4度C'!$B:$B,"平均") -> 0 | L21: =SUMIFS('0730 4度C'!$AD:$AD,'0730 4度C'!$A:$A,"新豐9線",'0730 4度C'!$B:$B,"平均") -> 0 | M21: =SUMIFS('0730 4度C'!$AD:$AD,'0730 4度C'!$A:$A,"新豐4線",'0730 4度C'!$B:$B,"平均") -> 0
B22: 配置人數 | D22: =SUMIFS('0730 4度C'!$I:$I,'0730 4度C'!$A:$A,"新豐6線",'0730 4度C'!$B:$B,"平均") -> 15.333333 | E22: =SUMIFS('0730 4度C'!$I:$I,'0730 4度C'!$A:$A,"新豐2線",'0730 4度C'!$B:$B,"平均") -> 17.4 | F22: =SUMIFS('0730 4度C'!$I:$I,'0730 4度C'!$A:$A,"新豐5線",'0730 4度C'!$B:$B,"平均") -> 18.428571 | G22: =SUMIFS('0730 4度C'!$I:$I,'0730 4度C'!$A:$A,"新豐7線",'0730 4度C'!$B:$B,"平均") -> 15.666667 | H22: =SUMIFS('0730 4度C'!$I:$I,'0730 4度C'!$A:$A,"新豐3線",'0730 4度C'!$B:$B,"平均") -> 9.25 | I22: =SUMIFS('0730 4度C'!$I:$I,'0730 4度C'!$A:$A,"新豐1線",'0730 4度C'!$B:$B,"平均") -> 17.777778 | J22: =SUMIFS('0730 4度C'!$I:$I,'0730 4度C'!$A:$A,"新豐10線",'0730 4度C'!$B:$B,"平均") -> 10.25 | K22: =SUMIFS('0730 4度C'!$I:$I,'0730 4度C'!$A:$A,"新豐8線",'0730 4度C'!$B:$B,"平均") -> 17.555556 | L22: =SUMIFS('0730 4度C'!$I:$I,'0730 4度C'!$A:$A,"新豐9線",'0730 4度C'!$B:$B,"平均") -> 17 | M22: =SUMIFS('0730 4度C'!$I:$I,'0730 4度C'!$A:$A,"新豐4線",'0730 4度C'!$B:$B,"平均") -> 15.888889
B23: 主要應用設備 | D23: ET-55 | E23: 熱縮爐 | F23: L型包裝機 | G23: L型包裝機 | H23: 伺服包裝機 | I23: ET-55 | J23: 伺服包裝機 | K23: 三明治包裝機 | L23: 三明治包裝機 | M23: 三明治包裝機
B24: 次要應用設備 | F24: 圓盤機 | G24: ET-55
B25: 備註 | E25: 握沙拉 | F25: 共用L型包裝機 | H25: 調理麵包 | I25: 炒飯+沙拉 | J25: 調理麵包

Sheet 0730 4度C
A1: 新豐廠四度C日報分析 | C1: 總生產量 | D1: =SUM(F5:F76) -> 172118 | E1: 營業額 | F1: =SUM(G5:G76) -> 5885033.6 | G1: 出勤人數 | H1: =L8+L14+L51+L61+L22+L66+L39+L46+L29+L76 -> 154.55079 | I1: 產線配置圖 | L1: 生產實績 | O1: 人時性差異分析 | S1: 日報登錄 | Y1: 合計 次數 | Z1: 合計 時間/分 | AA1: 產線異常 分析說明(5分鐘以上) | AC1: 合計 次數 | AD1: 合計 設備次數 | AE1: 產能差異分析
A2: 46233 | B2: 星期四 | C2: 人時性 | D2: =AVERAGE(N8,N14,N51,N61,N22,N66,N29,N39,N46,N76) -> 152.47129 | E2: 平均廠價 | F2: =F1/D1 -> 34.191854 | G2: 多次生產數 | H2: =COUNT(H5:H76) -> 9 | Y2: =SUM(Y8+Y14+Y22+Y29+Y39+Y46+Y51+Y61+Y66+Y76) -> 0 | Z2: =SUM(Z8+Z14+Z22+Z29+Z39+Z46+Z51+Z61+Z66+Z76) -> 0 | AC2: 62 | AD2: =SUM(AD8+AD14+AD22+AD29+AD39+AD46+AD51+AD61+AD66+AD76) -> 0
A3: 線別 | B3: 品類 | C3: 品名 | E3: 廠價 | F3: 生產量 | G3: 營收 | H3: 多次 生產 | I3: 人數 | J3: 產能/時 | K3: 人時性 | L3: 人數 | M3: 產能/時 | N3: 人時性 | O3: 人數 | P3: 人時性 | Q3: 達成率 | R3: 達成率平均 | S3: 生產時間 | U3: 換線、休息/分 | V3: 稼動時間/分 | W3: 休息時間 | Y3: 產線異常統計 (5分鐘以上) | AA3: (新豐回填) | AC3: 短暫停線統計 (5分鐘以下) | AE3: 產能/時 | AF3: 達成率 | AG3: 達成率平均
S4: 開始 | T4: 結束 | W4: 開始 | X4: 結束 | Y4: 次數 | Z4: 時間/分 | AC4: 總次數 | AD4: 設備因素(次數)
A5: 新豐6線 | B5: 微波主食 | C5: 二配金咖哩果香甘口咖哩飯 | E5: 50.92 | F5: 1708 | G5: =E5*F5 -> 86971.36 | I5: 15 | J5: 2000 | K5: =J5/I5 -> 133.33333 | L5: 15 | M5: =F5/V5*60 -> 1933.5849 | N5: =M5/L5 -> 128.90566 | O5: =L5-I5 -> 0 | P5: =N5-K5 -> -4.427673 | Q5: =N5/K5 -> 0.96679245 | R5: =Q8 -> 0.96254795 | S5: 0.70833333 | T5: 0.74513889 | V5: =(T5-S5)*24*60 -> 53 | AC5: 3 | AE5: =M5-J5 -> -66.415094 | AF5: =M5/J5 -> 0.96679245 | AG5: =AF8 -> 0.96254795
A6: 新豐6線 | B6: 微波主食 | C6: 二配金咖哩濃厚辛口咖哩飯 | E6: 50.98 | F6: 1834 | G6: =E6*F6 -> 93497.32 | I6: 16 | J6: 2000 | K6: =J6/I6 -> 125 | L6: 16 | M6: =F6/V6*60 -> 1930.5263 | N6: =M6/L6 -> 120.65789 | O6: =L6-I6 -> 0 | P6: =N6-K6 -> -4.3421053 | Q6: =N6/K6 -> 0.96526316 | S6: 0.75 | T6: 0.78958333 | U6: =IF(S6=TIME(17,0,0),"",(S6-T5)*24*60) -> 7 | V6: =(T6-S6)*24*60 -> 57 | AE6: =M6-J6 -> -69.473684 | AF6: =M6/J6 -> 0.96526316
A7: 新豐6線 | B7: 微波主食 | C7: 二配泰式綠咖哩雞 | E7: 50.67 | F7: 1083 | G7: =E7*F7 -> 54875.61 | I7: 15 | J7: 2000 | K7: =J7/I7 -> 133.33333 | L7: 15 | M7: =F7/V7*60 -> 1911.1765 | N7: =M7/L7 -> 127.41176 | O7: =L7-I7 -> 0 | P7: =N7-K7 -> -5.9215686 | Q7: =N7/K7 -> 0.95558824 | S7: 0.79305556 | T7: 0.81666667 | U7: =IF(S7=TIME(17,0,0),"",(S7-T6)*24*60) -> 5 | V7: =(T7-S7)*24*60 -> 34 | AE7: =M7-J7 -> -88.823529 | AF7: =M7/J7 -> 0.95558824
A8: 新豐6線 | B8: 平均 | I8: 15.333333 | J8: 2000 | K8: =J8/I8 -> 130.43478 | L8: 15.333333 | M8: =AVERAGE(M5:M7) -> 1925.0959 | N8: =M8/L8 -> 125.54973 | O8: =L8-I8 -> 0 | P8: =N8-K8 -> -4.8850502 | Q8: =N8/K8 -> 0.96254795 | Y8: =SUM(Y5:Y7) -> 0 | Z8: =SUM(Z5:Z7) -> 0 | AC8: 3 | AD8: =SUM(AD5:AD7) -> 0 | AE8: =M8-J8 -> -74.904103 | AF8: =M8/J8 -> 0.96254795
A9: 新豐2線 | B9: 沙拉 | C9: 青檸烤雞握沙拉(113年) | E9: 39.8 | F9: 3700 | G9: =E9*F9 -> 147260 | H9: 2 | I9: 17 | J9: 1500 | K9: =J9/I9 -> 88.235294 | L9: 17 | M9: =F9/V9*60 -> 1432.2581 | N9: =M9/L9 -> 84.250474 | O9: =L9-I9 -> 0 | P9: =N9-K9 -> -3.9848197 | Q9: =N9/K9 -> 0.95483871 | R9: =Q14 -> 0.95541407 | S9: 0.083333333 | T9: 0.19097222 | V9: =(T9-S9)*24*60 -> 155 | W9: =T9 -> 0.19097222 | X9: =S10 -> 0.20972222 | AC9: 5 | AE9: =M9-J9 -> -67.741935 | AF9: =M9/J9 -> 0.95483871 | AG9: =AF14 -> 0.95541407
A10: 新豐2線 | B10: 沙拉 | C10: 厚蛋時蔬握沙拉 | E10: 39.46 | F10: 2654 | G10: =E10*F10 -> 104726.84 | I10: 15 | J10: 1500 | K10: =J10/I10 -> 100 | L10: 15 | M10: =F10/V10*60 -> 1434.5946 | N10: =M10/L10 -> 95.63964 | O10: =L10-I10 -> 0 | P10: =N10-K10 -> -4.3603604 | Q10: =N10/K10 -> 0.9563964 | S10: 0.20972222 | T10: 0.28680556 | U10: =IF(S10=TIME(17,0,0),"",(S10-T9)*24*60) -> 27 | V10: =(T10-S10)*24*60 -> 111 | AE10: =M10-J10 -> -65.405405 | AF10: =M10/J10 -> 0.9563964
A11: 新豐2線 | B11: 沙拉 | C11: 地瓜瓜握沙拉 | E11: 39.52 | F11: 2311 | G11: =E11*F11 -> 91330.72 | I11: 19 | J11: 1500 | K11: =J11/I11 -> 78.947368 | L11: 19 | M11: =F11/V11*60 -> 1429.4845 | N11: =M11/L11 -> 75.236028 | O11: =L11-I11 -> 0 | P11: =N11-K11 -> -3.7113402 | Q11: =N11/K11 -> 0.95298969 | S11: 0.29027778 | T11: 0.35763889 | U11: =IF(S11=TIME(17,0,0),"",(S11-T10)*24*60) -> 5 | V11: =(T11-S11)*24*60 -> 97 | AE11: =M11-J11 -> -70.515464 | AF11: =M11/J11 -> 0.95298969
A12: 新豐2線 | B12: 沙拉 | C12: 青醬優格雞肉握沙拉(113年) | E12: 39.62 | F12: 4004 | G12: =E12*F12 -> 158638.48 | I12: 19 | J12: 1500 | K12: =J12/I12 -> 78.947368 | L12: 19 | M12: =F12/V12*60 -> 1430 | N12: =M12/L12 -> 75.263158 | O12: =L12-I12 -> 0 | P12: =N12-K12 -> -3.6842105 | Q12: =N12/K12 -> 0.95333333 | S12: 0.3625 | T12: 0.47916667 | U12: =IF(S12=TIME(17,0,0),"",(S12-T11)*24*60) -> 7 | V12: =(T12-S12)*24*60 -> 168 | W12: =T12 -> 0.47916667 | X12: =S13 -> 0.51944444 | AE12: =M12-J12 -> -70 | AF12: =M12/J12 -> 0.95333333
A13: 新豐2線 | B13: 沙拉 | C13: 青檸烤雞握沙拉(113年) | E13: 39.8 | F13: 1967 | G13: =E13*F13 -> 78286.6 | I13: 17 | J13: 1500 | K13: =J13/I13 -> 88.235294 | L13: 17 | M13: =F13/V13*60 -> 1439.2683 | N13: =M13/L13 -> 84.662841 | O13: =L13-I13 -> 0 | P13: =N13-K13 -> -3.5724534 | Q13: =N13/K13 -> 0.9595122 | S13: 0.51944444 | T13: 0.57638889 | U13: =IF(S13=TIME(17,0,0),"",(S13-T12)*24*60) -> 58 | V13: =(T13-S13)*24*60 -> 82 | AE13: =M13-J13 -> -60.731707 | AF13: =M13/J13 -> 0.9595122
A14: 新豐2線 | B14: 平均 | I14: 17.4 | J14: 1500 | K14: =J14/I14 -> 86.206897 | L14: 17.4 | M14: =AVERAGE(M9:M13) -> 1433.1211 | N14: =M14/L14 -> 82.363281 | O14: =L14-I14 -> 0 | P14: =N14-K14 -> -3.8436151 | Q14: =N14/K14 -> 0.95541407 | Y14: =SUM(Y9:Y13) -> 0 | Z14: =SUM(Z9:Z13) -> 0 | AC14: 5 | AD14: =SUM(AD9:AD13) -> 0 | AE14: =M14-J14 -> -66.878902 | AF14: =M14/J14 -> 0.95541407
A15: 新豐5線 | B15: 季節調理麵 | C15: 台式麻醬涼麵(115年) | E15: 31.11 | F15: 3138 | G15: =E15*F15 -> 97623.18 | I15: 14 | J15: 2000 | K15: =J15/I15 -> 142.85714 | L15: 14 | M15: =F15/V15*60 -> 1921.2245 | N15: =M15/L15 -> 137.23032 | O15: =L15-I15 -> 0 | P15: =N15-K15 -> -5.6268222 | Q15: =N15/K15 -> 0.96061224 | R15: =Q22 -> 0.96176121 | S15: 0.083333333 | T15: 0.15138889 | V15: =(T15-S15)*24*60 -> 98 | W15: =T15 -> 0.15138889 | X15: =S16 -> 0.17222222 | AC15: 7 | AE15: =M15-J15 -> -78.77551 | AF15: =M15/J15 -> 0.96061224 | AG15: =AF22 -> 0.96176121
A16: 新豐5線 | B16: 小吃 | C16: 香菇雞燉湯 | E16: 38.62 | F16: 2110 | G16: =E16*F16 -> 81488.2 | I16: 24 | J16: 1500 | K16: =J16/I16 -> 62.5 | L16: 24 | M16: =F16/V16*60 -> 1438.6364 | N16: =M16/L16 -> 59.943182 | O16: =L16-I16 -> 0 | P16: =N16-K16 -> -2.5568182 | Q16: =N16/K16 -> 0.95909091 | S16: 0.17222222 | T16: 0.23333333 | U16: =IF(S16=TIME(17,0,0),"",(S16-T15)*24*60) -> 30 | V16: =(T16-S16)*24*60 -> 88 | AE16: =M16-J16 -> -61.363636 | AF16: =M16/J16 -> 0.95909091
A17: 新豐5線 | B17: 小吃 | C17: 剝皮辣椒雞湯 | E17: 41 | F17: 1802 | G17: =E17*F17 -> 73882 | I17: 26 | J17: 1500 | K17: =J17/I17 -> 57.692308 | L17: 26 | M17: =F17/V17*60 -> 1441.6 | N17: =M17/L17 -> 55.446154 | O17: =L17-I17 -> 0 | P17: =N17-K17 -> -2.2461538 | Q17: =N17/K17 -> 0.96106667 | S17: 0.23888889 | T17: 0.29097222 | U17: =IF(S17=TIME(17,0,0),"",(S17-T16)*24*60) -> 8 | V17: =(T17-S17)*24*60 -> 75 | AE17: =M17-J17 -> -58.4 | AF17: =M17/J17 -> 0.96106667
A18: 新豐5線 | B18: 微波主食 | C18: 香菇雞粥 | E18: 37.03 | F18: 3232 | G18: =E18*F18 -> 119680.96 | I18: 13 | J18: 1500 | K18: =J18/I18 -> 115.38462 | L18: 13 | M18: =F18/V18*60 -> 1436.4444 | N18: =M18/L18 -> 110.49573 | O18: =L18-I18 -> 0 | P18: =N18-K18 -> -4.8888889 | Q18: =N18/K18 -> 0.95762963 | S18: 0.29652778 | T18: 0.39027778 | U18: =IF(S18=TIME(17,0,0),"",(S18-T17)*24*60) -> 8 | V18: =(T18-S18)*24*60 -> 135 | AE18: =M18-J18 -> -63.555556 | AF18: =M18/J18 -> 0.95762963
A19: 新豐5線 | B19: 微波主食 | C19: 二配港式香滑嫩蛋牛肉燴飯 | E19: 50.67 | F19: 1171 | G19: =E19*F19 -> 59334.57 | I19: 17 | J19: 2000 | K19: =J19/I19 -> 117.64706 | L19: 17 | M19: =F19/V19*60 -> 1951.6667 | N19: =M19/L19 -> 114.80392 | O19: =L19-I19 -> 0 | P19: =N19-K19 -> -2.8431373 | Q19: =N19/K19 -> 0.97583333 | S19: 0.70833333 | T19: 0.73333333 | U19: =IF(S19=TIME(17,0,0),"",(S19-T18)*24*60) | V19: =(T19-S19)*24*60 -> 36 | AE19: =M19-J19 -> -48.333333 | AF19: =M19/J19 -> 0.97583333
A20: 新豐5線 | B20: 微波主食 | C20: 二配玉米濃湯焗烤飯 | E20: 54.5 | F20: 1527 | G20: =E20*F20 -> 83221.5 | I20: 20 | J20: 1500 | K20: =J20/I20 -> 75 | L20: 20 | M20: =F20/V20*60 -> 1431.5625 | N20: =M20/L20 -> 71.578125 | O20: =L20-I20 -> 0 | P20: =N20-K20 -> -3.421875 | Q20: =N20/K20 -> 0.954375 | S20: 0.73819444 | T20: 0.78263889 | U20: =IF(S20=TIME(17,0,0),"",(S20-T19)*24*60) -> 7 | V20: =(T20-S20)*24*60 -> 64 | AE20: =M20-J20 -> -68.4375 | AF20: =M20/J20 -> 0.954375
A21: 新豐5線 | B21: 微波主食 | C21: 二配川味麻婆燒豆腐燴飯 | E21: 50.49 | F21: 1440 | G21: =E21*F21 -> 72705.6 | I21: 15 | J21: 2000 | K21: =J21/I21 -> 133.33333 | L21: 15 | M21: =F21/V21*60 -> 1920 | N21: =M21/L21 -> 128 | O21: =L21-I21 -> 0 | P21: =N21-K21 -> -5.3333333 | Q21: =N21/K21 -> 0.96 | S21: 0.78611111 | T21: 0.81736111 | U21: =IF(S21=TIME(17,0,0),"",(S21-T20)*24*60) -> 5 | V21: =(T21-S21)*24*60 -> 45 | AE21: =M21-J21 -> -80 | AF21: =M21/J21 -> 0.96
A22: 新豐5線 | B22: 平均 | I22: 18.428571 | J22: 1714.2857 | K22: =J22/I22 -> 93.023256 | L22: 18.428571 | M22: =AVERAGE(M15:M21) -> 1648.7335 | N22: =M22/L22 -> 89.466159 | O22: =L22-I22 -> 0 | P22: =N22-K22 -> -3.5570972 | Q22: =N22/K22 -> 0.96176121 | Y22: =SUM(Y15:Y21) -> 0 | Z22: =SUM(Z15:Z21) -> 0 | AC22: 7 | AD22: =SUM(AD15:AD21) -> 0 | AE22: =M22-J22 -> -65.552219 | AF22: =M22/J22 -> 0.96176121
A23: 新豐7線 | B23: 微波主食 | C23: 韓式泡菜豬肉豆腐丼飯 | E23: 50.67 | F23: 1710 | G23: =E23*F23 -> 86645.7 | I23: 17 | J23: 2000 | K23: =J23/I23 -> 117.64706 | L23: 17 | M23: =F23/V23*60 -> 1935.8491 | N23: =M23/L23 -> 113.87347 | O23: =L23-I23 -> 0 | P23: =N23-K23 -> -3.7735849 | Q23: =N23/K23 -> 0.96792453 | R23: =Q29 -> 0.96619225 | S23: 0.20833333 | T23: 0.24513889 | V23: =(T23-S23)*24*60 -> 53 | AC23: 6 | AE23: =M23-J23 -> -64.150943 | AF23: =M23/J23 -> 0.96792453 | AG23: =AF29 -> 0.96619225
A24: 新豐7線 | B24: 微波主食 | C24: 鐵板滑蛋炸豬排丼 | E24: 57.73 | F24: 2047 | G24: =E24*F24 -> 118173.31 | I24: 14 | J24: 2000 | K24: =J24/I24 -> 142.85714 | L24: 14 | M24: =F24/V24*60 -> 1919.0625 | N24: =M24/L24 -> 137.07589 | O24: =L24-I24 -> 0 | P24: =N24-K24 -> -5.78125 | Q24: =N24/K24 -> 0.95953125 | S24: 0.25 | T24: 0.29444444 | U24: =IF(S24=TIME(17,0,0),"",(S24-T23)*24*60) -> 7 | V24: =(T24-S24)*24*60 -> 64 | AE24: =M24-J24 -> -80.9375 | AF24: =M24/J24 -> 0.95953125
A25: 新豐7線 | B25: 微波主食 | C25: 日式炙烤親子丼 | E25: 53.27 | F25: 1427 | G25: =E25*F25 -> 76016.29 | I25: 16 | J25: 2000 | K25: =J25/I25 -> 125 | L25: 16 | M25: =F25/V25*60 -> 1945.9091 | N25: =M25/L25 -> 121.61932 | O25: =L25-I25 -> 0 | P25: =N25-K25 -> -3.3806818 | Q25: =N25/K25 -> 0.97295455 | S25: 0.3 | T25: 0.33055556 | U25: =IF(S25=TIME(17,0,0),"",(S25-T24)*24*60) -> 8 | V25: =(T25-S25)*24*60 -> 44 | AE25: =M25-J25 -> -54.090909 | AF25: =M25/J25 -> 0.97295455
A26: 新豐7線 | B26: 微波主食 | C26: 二配厚香料優格咖哩雞排飯 | E26: 56.43 | F26: 1165 | G26: =E26*F26 -> 65740.95 | I26: 13 | J26: 2000 | K26: =J26/I26 -> 153.84615 | L26: 13 | M26: =F26/V26*60 -> 1941.6667 | N26: =M26/L26 -> 149.35897 | O26: =L26-I26 -> 0 | P26: =N26-K26 -> -4.4871795 | Q26: =N26/K26 -> 0.97083333 | S26: 0.70833333 | T26: 0.73333333 | U26: =IF(S26=TIME(17,0,0),"",(S26-T25)*24*60) | V26: =(T26-S26)*24*60 -> 36 | AE26: =M26-J26 -> -58.333333 | AF26: =M26/J26 -> 0.97083333
A27: 新豐7線 | B27: 微波主食 | C27: 二配美味蟹煲 | E27: 54.09 | F27: 1921 | G27: =E27*F27 -> 103906.89 | I27: 18 | J27: 2000 | K27: =J27/I27 -> 111.11111 | L27: 18 | M27: =F27/V27*60 -> 1921 | N27: =M27/L27 -> 106.72222 | O27: =L27-I27 -> 0 | P27: =N27-K27 -> -4.3888889 | Q27: =N27/K27 -> 0.9605 | S27: 0.73888889 | T27: 0.78055556 | U27: =IF(S27=TIME(17,0,0),"",(S27-T26)*24*60) -> 8 | V27: =(T27-S27)*24*60 -> 60 | AE27: =M27-J27 -> -79 | AF27: =M27/J27 -> 0.9605
A28: 新豐7線 | B28: 微波主食 | C28: 二配泰式檸檬魚飯 | E28: 57.3 | F28: 1963 | G28: =E28*F28 -> 112479.9 | I28: 16 | J28: 2000 | K28: =J28/I28 -> 125 | L28: 16 | M28: =F28/V28*60 -> 1930.8197 | N28: =M28/L28 -> 120.67623 | O28: =L28-I28 -> 0 | P28: =N28-K28 -> -4.3237705 | Q28: =N28/K28 -> 0.96540984 | S28: 0.78402778 | T28: 0.82638889 | U28: =IF(S28=TIME(17,0,0),"",(S28-T27)*24*60) -> 5 | V28: =(T28-S28)*24*60 -> 61 | AE28: =M28-J28 -> -69.180328 | AF28: =M28/J28 -> 0.96540984
A29: 新豐7線 | B29: 平均 | I29: 15.666667 | J29: 2000 | K29: =J29/I29 -> 127.65957 | L29: 15.666667 | M29: =AVERAGE(M23:M28) -> 1932.3845 | N29: =M29/L29 -> 123.34369 | O29: =L29-I29 -> 0 | P29: =N29-K29 -> -4.3158831 | Q29: =N29/K29 -> 0.96619225 | Y29: =SUM(Y23:Y28) -> 0 | Z29: =SUM(Z23:Z28) -> 0 | AC29: 6 | AD29: =SUM(AD23:AD28) -> 0 | AE29: =M29-J29 -> -67.615502 | AF29: =M29/J29 -> 0.96619225
A30: 新豐8線 | B30: 三明治 | C30: 紐奧良風味烤雞鮮蔬三明治 | E30: 31.29 | F30: 4700 | G30: =E30*F30 -> 147063 | H30: 2 | I30: 18 | J30: 2400 | K30: =J30/I30 -> 133.33333 | L30: 18 | M30: =F30/V30*60 -> 2292.6829 | N30: =M30/L30 -> 127.37127 | O30: =L30-I30 -> 0 | P30: =N30-K30 -> -5.9620596 | Q30: =N30/K30 -> 0.95528455 | R30: =Q39 -> 0.96031849 | S30: 0.083333333 | T30: 0.16875 | V30: =(T30-S30)*24*60 -> 123 | W30: =T30 -> 0.16875 | X30: =S31 -> 0.18819444 | AC30: 9 | AE30: =M30-J30 -> -107.31707 | AF30: =M30/J30 -> 0.95528455 | AG30: =AF39 -> 0.96031849
A31: 新豐8線 | B31: 三明治 | C31: 醬燒烤雞三明治(115年) | E31: 26.37 | F31: 3500 | G31: =E31*F31 -> 92295 | H31: 2 | I31: 18 | J31: 2400 | K31: =J31/I31 -> 133.33333 | L31: 18 | M31: =F31/V31*60 -> 2307.6923 | N31: =M31/L31 -> 128.20513 | O31: =L31-I31 -> 0 | P31: =N31-K31 -> -5.1282051 | Q31: =N31/K31 -> 0.96153846 | S31: 0.18819444 | T31: 0.25138889 | U31: =(S31-T30)*24*60 -> 28 | V31: =(T31-S31)*24*60 -> 91 | AE31: =M31-J31 -> -92.307692 | AF31: =M31/J31 -> 0.96153846
A32: 新豐8線 | B32: 三明治 | C32: 鮪魚起司溏心蛋三明治(115年) | E32: 26.18 | F32: 4200 | G32: =E32*F32 -> 109956 | H32: 2 | I32: 18 | J32: 2400 | K32: =J32/I32 -> 133.33333 | L32: 18 | M32: =F32/V32*60 -> 2290.9091 | N32: =M32/L32 -> 127.27273 | O32: =L32-I32 -> 0 | P32: =N32-K32 -> -6.0606061 | Q32: =N32/K32 -> 0.95454545 | S32: 0.25625 | T32: 0.33263889 | U32: =(S32-T31)*24*60 -> 7 | V32: =(T32-S32)*24*60 -> 110 | AE32: =M32-J32 -> -109.09091 | AF32: =M32/J32 -> 0.95454545
A33: 新豐8線 | B33: 三明治 | C33: 茄汁厚起司三明治 | E33: 25.99 | F33: 1212 | G33: =E33*F33 -> 31499.88 | I33: 18 | J33: 2400 | K33: =J33/I33 -> 133.33333 | L33: 18 | M33: =F33/V33*60 -> 2345.8065 | N33: =M33/L33 -> 130.32258 | O33: =L33-I33 -> 0 | P33: =N33-K33 -> -3.0107527 | Q33: =N33/K33 -> 0.97741935 | S33: 0.33680556 | T33: 0.35833333 | U33: =(S33-T32)*24*60 -> 6 | V33: =(T33-S33)*24*60 -> 31 | AE33: =M33-J33 -> -54.193548 | AF33: =M33/J33 -> 0.97741935
A34: 新豐8線 | B34: 三明治 | C34: 雞蛋沙拉三明治(114年) | E34: 25.99 | F34: 3638 | G34: =E34*F34 -> 94551.62 | I34: 14 | J34: 2400 | K34: =J34/I34 -> 171.42857 | L34: 14 | M34: =F34/V34*60 -> 2297.6842 | N34: =M34/L34 -> 164.1203 | O34: =L34-I34 -> 0 | P34: =N34-K34 -> -7.3082707 | Q34: =N34/K34 -> 0.95736842 | S34: 0.36388889 | T34: 0.42986111 | U34: =(S34-T33)*24*60 -> 8 | V34: =(T34-S34)*24*60 -> 95 | AE34: =M34-J34 -> -102.31579 | AF34: =M34/J34 -> 0.95736842
A35: 新豐8線 | B35: 三明治 | C35: 榛果摩卡脆脆三明治 | E35: 20.21 | F35: 2358 | G35: =E35*F35 -> 47655.18 | I35: 18 | J35: 2400 | K35: =J35/I35 -> 133.33333 | L35: 18 | M35: =F35/V35*60 -> 2319.3443 | N35: =M35/L35 -> 128.85246 | O35: =L35-I35 -> 0 | P35: =N35-K35 -> -4.4808743 | Q35: =N35/K35 -> 0.96639344 | S35: 0.43333333 | T35: 0.47569444 | U35: =(S35-T34)*24*60 -> 5 | V35: =(T35-S35)*24*60 -> 61 | W35: =T35 -> 0.47569444 | X35: =S36 -> 0.51458333 | AE35: =M35-J35 -> -80.655738 | AF35: =M35/J35 -> 0.96639344
A36: 新豐8線 | B36: 三明治 | C36: 紐奧良風味烤雞鮮蔬三明治 | E36: 31.29 | F36: 3339 | G36: =E36*F36 -> 104477.31 | I36: 18 | J36: 2400 | K36: =J36/I36 -> 133.33333 | L36: 18 | M36: =F36/V36*60 -> 2302.7586 | N36: =M36/L36 -> 127.93103 | O36: =L36-I36 -> 0 | P36: =N36-K36 -> -5.4022989 | Q36: =N36/K36 -> 0.95948276 | S36: 0.51458333 | T36: 0.575 | U36: =(S36-T35)*24*60 -> 56 | V36: =(T36-S36)*24*60 -> 87 | AE36: =M36-J36 -> -97.241379 | AF36: =M36/J36 -> 0.95948276
A37: 新豐8線 | B37: 三明治 | C37: 鮪魚起司溏心蛋三明治(115年) | E37: 26.18 | F37: 3177 | G37: =E37*F37 -> 83173.86 | I37: 18 | J37: 2400 | K37: =J37/I37 -> 133.33333 | L37: 18 | M37: =F37/V37*60 -> 2296.6265 | N37: =M37/L37 -> 127.59036 | O37: =L37-I37 -> 0 | P37: =N37-K37 -> -5.7429719 | Q37: =N37/K37 -> 0.95692771 | S37: 0.57847222 | T37: 0.63611111 | U37: =(S37-T36)*24*60 -> 5 | V37: =(T37-S37)*24*60 -> 83 | AE37: =M37-J37 -> -103.37349 | AF37: =M37/J37 -> 0.95692771
A38: 新豐8線 | B38: 三明治 | C38: 醬燒烤雞三明治(115年) | E38: 26.37 | F38: 2442 | G38: =E38*F38 -> 64395.54 | I38: 18 | J38: 2400 | K38: =J38/I38 -> 133.33333 | L38: 18 | M38: =F38/V38*60 -> 2289.375 | N38: =M38/L38 -> 127.1875 | O38: =L38-I38 -> 0 | P38: =N38-K38 -> -6.1458333 | Q38: =N38/K38 -> 0.95390625 | S38: 0.63958333 | T38: 0.68402778 | U38: =(S38-T37)*24*60 -> 5 | V38: =(T38-S38)*24*60 -> 64 | AE38: =M38-J38 -> -110.625 | AF38: =M38/J38 -> 0.95390625
A39: 新豐8線 | B39: 平均 | I39: 17.555556 | J39: 2400 | K39: =J39/I39 -> 136.70886 | L39: 17.555556 | M39: =AVERAGE(M30:M38) -> 2304.7644 | N39: =M39/L39 -> 131.28405 | O39: =L39-I39 -> 0 | P39: =N39-K39 -> -5.4248141 | Q39: =N39/K39 -> 0.96031849 | Y39: =SUM(Y30:Y38) -> 0 | Z39: =SUM(Z30:Z38) -> 0 | AC39: 9 | AD39: =SUM(AD30:AD38) -> 0 | AE39: =M39-J39 -> -95.235625 | AF39: =M39/J39 -> 0.96031849
A40: 新豐9線 | B40: 三明治 | C40: 經典總匯三明治(115年) | E40: 26.18 | F40: 5671 | G40: =E40*F40 -> 148466.78 | I40: 20 | J40: 2400 | K40: =J40/I40 -> 120 | L40: 20 | M40: =F40/V40*60 -> 2283.6242 | N40: =M40/L40 -> 114.18121 | O40: =L40-I40 -> 0 | P40: =N40-K40 -> -5.8187919 | Q40: =N40/K40 -> 0.95151007 | R40: =Q46 -> 0.95545479 | S40: 0.083333333 | T40: 0.18680556 | V40: =(T40-S40)*24*60 -> 149 | W40: =T40 -> 0.18680556 | X40: =S41 -> 0.20555556 | AC40: 6 | AE40: =M40-J40 -> -116.37584 | AF40: =M40/J40 -> 0.95151007 | AG40: =AF46 -> 0.95545479
...

Sheet 0729
B1: 屏榮 新豐廠組合室生產人時性分析
B3: 日期 | C3: =TEXT('0729 4度C'!A2,"yyyy.mm.ddaaaa") -> 2026.07.29星期三 | E3: 訂單量 | F3: ='0729 4度C'!D1 -> 184768 | H3: 營業額 | I3: ='0729 4度C'!F1 -> 6407406.5
B4: 人時性 | C4: 項目 | E4: ➀ | G4: ➁ | I4: ➂ | K4: 異常停線 | M4: 短暫停線
C5: 組合室 | E5: 全溫層 | G5: 4度C-各編組展開 | I5: ③三明治-各編組展開 | K5: 合計次數 | L5: 時間 | M5: 合計次數 | N5: 設備次數
C6: 排關平均 | E6: =AVERAGE(D13:M13) -> 158.22539 | F6: =AVERAGE(D31:O31,D13:J13) -> 166.70561 | G6: =AVERAGE(D13:J13) -> 166.70561 | I6: =AVERAGE(K13:M13) -> 138.43823 | K6: ='0729 4度C'!Y2 -> 0 | L6: ='0729 4度C'!Z2 -> 0 | M6: ='0729 4度C'!AC2 -> 66 | N6: ='0729 4度C'!AD2 -> 0
C7: 實績平均 | E7: =AVERAGE(D14:M14) -> 151.64966 | F7: =AVERAGE(D32:O32,D14:J14) -> 159.8658 | G7: =AVERAGE(D14:J14) -> 159.8658 | I7: =AVERAGE(K14:M14) -> 132.47865
C8: 達成率平均 | E8: =AVERAGE(D15:M15) -> 0.95818156 | F8: =AVERAGE(D15:J15,D33:O33) -> 0.95869706 | G8: =AVERAGE(D15:J15) -> 0.95869706 | I8: =AVERAGE(K15:M15) -> 0.95697873
K9: ※現行日本鮮食廠以達成率80%為基本(即為現行KPI)
B10: 溫層 | D10: ➁4度C-各編組展開 | K10: ③三明治-各編組展開
B11: 編組 | D11: 1 | E11: 2 | F11: 3 | G11: 4 | H11: 5 | I11: 6 | J11: 7 | K11: 1 | L11: 2 | M11: 3
D12: 新豐6線 | E12: 新豐2線 | F12: 新豐5線 | G12: 新豐7線 | H12: 新豐3線 | I12: 新豐1線 | J12: 新豐10線 | K12: 新豐8線 | L12: 新豐9線 | M12: 新豐4線
B13: 人時性 | C13: 排關 | D13: =SUMIFS('0729 4度C'!$K:$K,'0729 4度C'!$A:$A,"新豐6線",'0729 4度C'!$B:$B,"平均") -> 130.43478 | E13: =SUMIFS('0729 4度C'!$K:$K,'0729 4度C'!$A:$A,"新豐2線",'0729 4度C'!$B:$B,"平均") -> 86.206897 | F13: =SUMIFS('0729 4度C'!$K:$K,'0729 4度C'!$A:$A,"新豐5線",'0729 4度C'!$B:$B,"平均") -> 93.023256 | G13: =SUMIFS('0729 4度C'!$K:$K,'0729 4度C'!$A:$A,"新豐7線",'0729 4度C'!$B:$B,"平均") -> 127.27273 | H13: =SUMIFS('0729 4度C'!$K:$K,'0729 4度C'!$A:$A,"新豐3線",'0729 4度C'!$B:$B,"平均") -> 324.32432 | I13: =SUMIFS('0729 4度C'!$K:$K,'0729 4度C'!$A:$A,"新豐1線",'0729 4度C'!$B:$B,"平均") -> 112.99435 | J13: =SUMIFS('0729 4度C'!$K:$K,'0729 4度C'!$A:$A,"新豐10線",'0729 4度C'!$B:$B,"平均") -> 292.68293 | K13: =SUMIFS('0729 4度C'!$K:$K,'0729 4度C'!$A:$A,"新豐8線",'0729 4度C'!$B:$B,"平均") -> 134.26573 | L13: =SUMIFS('0729 4度C'!$K:$K,'0729 4度C'!$A:$A,"新豐9線",'0729 4度C'!$B:$B,"平均") -> 130 | M13: =SUMIFS('0729 4度C'!$K:$K,'0729 4度C'!$A:$A,"新豐4線",'0729 4度C'!$B:$B,"平均") -> 151.04895
C14: 實績 | D14: =SUMIFS('0729 4度C'!$N:$N,'0729 4度C'!$A:$A,"新豐6線",'0729 4度C'!$B:$B,"平均") -> 124.88264 | E14: =SUMIFS('0729 4度C'!$N:$N,'0729 4度C'!$A:$A,"新豐2線",'0729 4度C'!$B:$B,"平均") -> 82.485956 | F14: =SUMIFS('0729 4度C'!$N:$N,'0729 4度C'!$A:$A,"新豐5線",'0729 4度C'!$B:$B,"平均") -> 88.997965 | G14: =SUMIFS('0729 4度C'!$N:$N,'0729 4度C'!$A:$A,"新豐7線",'0729 4度C'!$B:$B,"平均") -> 122.47938 | H14: =SUMIFS('0729 4度C'!$N:$N,'0729 4度C'!$A:$A,"新豐3線",'0729 4度C'!$B:$B,"平均") -> 311.67074 | I14: =SUMIFS('0729 4度C'!$N:$N,'0729 4度C'!$A:$A,"新豐1線",'0729 4度C'!$B:$B,"平均") -> 108.41093 | J14: =SUMIFS('0729 4度C'!$N:$N,'0729 4度C'!$A:$A,"新豐10線",'0729 4度C'!$B:$B,"平均") -> 280.13301 | K14: =SUMIFS('0729 4度C'!$N:$N,'0729 4度C'!$A:$A,"新豐8線",'0729 4度C'!$B:$B,"平均") -> 128.27402 | L14: =SUMIFS('0729 4度C'!$N:$N,'0729 4度C'!$A:$A,"新豐9線",'0729 4度C'!$B:$B,"平均") -> 124.6437 | M14: =SUMIFS('0729 4度C'!$N:$N,'0729 4度C'!$A:$A,"新豐4線",'0729 4度C'!$B:$B,"平均") -> 144.51825
C15: 達成率 | D15: =D14/D13 -> 0.95743357 | E15: =E14/E13 -> 0.95683709 | F15: =F14/F13 -> 0.95672812 | G15: =G14/G13 -> 0.96233801 | H15: =H14/H13 -> 0.96098477 | I15: =I14/I13 -> 0.95943673 | J15: =J14/J13 -> 0.95712112 | K15: =K14/K13 -> 0.95537422 | ... M15: =M14/M13 -> 0.95676432
B16: 作業 時間 | C16: 開始 | D16: =VLOOKUP("新豐6線",'0729 4度C'!$A:$T,19,0) -> 0.70833333 | E16: =VLOOKUP("新豐2線",'0729 4度C'!$A:$T,19,0) -> 0.083333333 | F16: =VLOOKUP("新豐5線",'0729 4度C'!$A:$T,19,0) -> 0.083333333 | G16: =VLOOKUP("新豐7線",'0729 4度C'!$A:$T,19,0) -> 0.20833333 | H16: =VLOOKUP("新豐3線",'0729 4度C'!$A:$T,19,0) -> 0.20833333 | I16: =VLOOKUP("新豐1線",'0729 4度C'!$A:$T,19,0) -> 0.083333333 | J16: =VLOOKUP("新豐10線",'0729 4度C'!$A:$T,19,0) -> 0.20833333 | K16: =VLOOKUP("新豐8線",'0729 4度C'!$A:$T,19,0) -> 0.083333333 | L16: =VLOOKUP("新豐9線",'0729 4度C'!$A:$T,19,0) -> 0.083333333 | M16: =VLOOKUP("新豐4線",'0729 4度C'!$A:$T,19,0) -> 0.083333333
C17: 結束 | D17: =LOOKUP(2,1/(('0729 4度C'!$A:$A="新豐6線")*('0729 4度C'!$T:$T<>"")),'0729 4度C'!$T:$T) -> 0.84930556 | E17: =LOOKUP(2,1/(('0729 4度C'!$A:$A="新豐2線")*('0729 4度C'!$T:$T<>"")),'0729 4度C'!$T:$T) -> 0.59305556 | F17: =LOOKUP(2,1/(('0729 4度C'!$A:$A="新豐5線")*('0729 4度C'!$T:$T<>"")),'0729 4度C'!$T:$T) -> 0.84861111 | G17: =LOOKUP(2,1/(('0729 4度C'!$A:$A="新豐7線")*('0729 4度C'!$T:$T<>"")),'0729 4度C'!$T:$T) -> 0.90277778 | H17: =LOOKUP(2,1/(('0729 4度C'!$A:$A="新豐3線")*('0729 4度C'!$T:$T<>"")),'0729 4度C'!$T:$T) -> 0.41666667 | I17: =LOOKUP(2,1/(('0729 4度C'!$A:$A="新豐1線")*('0729 4度C'!$T:$T<>"")),'0729 4度C'!$T:$T) -> 0.90208333 | J17: =LOOKUP(2,1/(('0729 4度C'!$A:$A="新豐10線")*('0729 4度C'!$T:$T<>"")),'0729 4度C'!$T:$T) -> 0.43055556 | K17: =LOOKUP(2,1/(('0729 4度C'!$A:$A="新豐8線")*('0729 4度C'!$T:$T<>"")),'0729 4度C'!$T:$T) -> 0.69930556 | L17: =LOOKUP(2,1/(('0729 4度C'!$A:$A="新豐9線")*('0729 4度C'!$T:$T<>"")),'0729 4度C'!$T:$T) -> 0.70416667 | M17: =LOOKUP(2,1/(('0729 4度C'!$A:$A="新豐4線")*('0729 4度C'!$T:$T<>"")),'0729 4度C'!$T:$T) -> 0.72222222
