Workbook

Sheet 1005
B1: 屏榮 新豐廠組合室生產人時性分析
B3: 日期 | C3: =TEXT('1005 4度C'!A2,"yyyy.mm.ddaaaa") -> 2026.10.05星期一 | E3: 訂單量 | F3: ='1005 4度C'!D1 -> 188817 | H3: 營業額 | I3: ='1005 4度C'!F1 -> 6372151.5
B4: 人時性 | C4: 項目 | E4: ➀ | G4: ➁ | I4: ➂ | K4: 異常停線 | M4: 短暫停線
C5: 組合室 | E5: 全溫層 | G5: 4度C-各編組展開 | I5: ③三明治-各編組展開 | K5: 合計次數 | L5: 時間 | M5: 合計次數 | N5: 設備次數
C6: 排關平均 | E6: =AVERAGE(D13:M13) -> 151.02341 | F6: =AVERAGE(D31:O31,D13:J13) -> 155.81982 | G6: =AVERAGE(D13:J13) -> 155.81982 | I6: =AVERAGE(K13:M13) -> 139.83176 | K6: ='1005 4度C'!Y2 -> 0 | L6: ='1005 4度C'!Z2 -> 0 | M6: ='1005 4度C'!AC2 -> 62 | N6: ='1005 4度C'!AD2 -> 0
C7: 實績平均 | E7: =AVERAGE(D14:M14) -> 144.78124 | F7: =AVERAGE(D32:O32,D14:J14) -> 149.47834 | G7: =AVERAGE(D14:J14) -> 149.47834 | I7: =AVERAGE(K14:M14) -> 133.82132
C8: 達成率平均 | E8: =AVERAGE(D15:M15) -> 0.95816976 | F8: =AVERAGE(D15:J15,D33:O33) -> 0.95873505 | G8: =AVERAGE(D15:J15) -> 0.95873505 | I8: =AVERAGE(K15:M15) -> 0.95685074
K9: ※現行日本鮮食廠以達成率80%為基本(即為現行KPI)
B10: 溫層 | D10: ➁4度C-各編組展開 | K10: ③三明治-各編組展開
B11: 編組 | D11: 1 | E11: 2 | F11: 3 | G11: 4 | H11: 5 | I11: 6 | J11: 7 | K11: 1 | L11: 2 | M11: 3
D12: 新豐6線 | E12: 新豐2線 | F12: 新豐5線 | G12: 新豐7線 | H12: 新豐3線 | I12: 新豐1線 | J12: 新豐10線 | K12: 新豐8線 | L12: 新豐9線 | M12: 新豐4線
B13: 人時性 | C13: 排關 | D13: =SUMIFS('1005 4度C'!$K:$K,'1005 4度C'!$A:$A,"新豐6線",'1005 4度C'!$B:$B,"平均") -> 133.33333 | E13: =SUMIFS('1005 4度C'!$K:$K,'1005 4度C'!$A:$A,"新豐2線",'1005 4度C'!$B:$B,"平均") -> 83.333333 | F13: =SUMIFS('1005 4度C'!$K:$K,'1005 4度C'!$A:$A,"新豐5線",'1005 4度C'!$B:$B,"平均") -> 102.94118 | G13: =SUMIFS('1005 4度C'!$K:$K,'1005 4度C'!$A:$A,"新豐7線",'1005 4度C'!$B:$B,"平均") -> 125 | H13: =SUMIFS('1005 4度C'!$K:$K,'1005 4度C'!$A:$A,"新豐3線",'1005 4度C'!$B:$B,"平均") -> 242.42424 | I13: =SUMIFS('1005 4度C'!$K:$K,'1005 4度C'!$A:$A,"新豐1線",'1005 4度C'!$B:$B,"平均") -> 109.58904 | J13: =SUMIFS('1005 4度C'!$K:$K,'1005 4度C'!$A:$A,"新豐10線",'1005 4度C'!$B:$B,"平均") -> 294.11765 | K13: =SUMIFS('1005 4度C'!$K:$K,'1005 4度C'!$A:$A,"新豐8線",'1005 4度C'!$B:$B,"平均") -> 135.84906 | L13: =SUMIFS('1005 4度C'!$K:$K,'1005 4度C'!$A:$A,"新豐9線",'1005 4度C'!$B:$B,"平均") -> 124.8227 | M13: =SUMIFS('1005 4度C'!$K:$K,'1005 4度C'!$A:$A,"新豐4線",'1005 4度C'!$B:$B,"平均") -> 158.82353
C14: 實績 | D14: =SUMIFS('1005 4度C'!$N:$N,'1005 4度C'!$A:$A,"新豐6線",'1005 4度C'!$B:$B,"平均") -> 128.1203 | E14: =SUMIFS('1005 4度C'!$N:$N,'1005 4度C'!$A:$A,"新豐2線",'1005 4度C'!$B:$B,"平均") -> 79.455595 | F14: =SUMIFS('1005 4度C'!$N:$N,'1005 4度C'!$A:$A,"新豐5線",'1005 4度C'!$B:$B,"平均") -> 98.822809 | G14: =SUMIFS('1005 4度C'!$N:$N,'1005 4度C'!$A:$A,"新豐7線",'1005 4度C'!$B:$B,"平均") -> 119.8445 | H14: =SUMIFS('1005 4度C'!$N:$N,'1005 4度C'!$A:$A,"新豐3線",'1005 4度C'!$B:$B,"平均") -> 231.01639 | I14: =SUMIFS('1005 4度C'!$N:$N,'1005 4度C'!$A:$A,"新豐1線",'1005 4度C'!$B:$B,"平均") -> 105.1847 | J14: =SUMIFS('1005 4度C'!$N:$N,'1005 4度C'!$A:$A,"新豐10線",'1005 4度C'!$B:$B,"平均") -> 283.9041 | K14: =SUMIFS('1005 4度C'!$N:$N,'1005 4度C'!$A:$A,"新豐8線",'1005 4度C'!$B:$B,"平均") -> 130.10174 | L14: =SUMIFS('1005 4度C'!$N:$N,'1005 4度C'!$A:$A,"新豐9線",'1005 4度C'!$B:$B,"平均") -> 119.11013 | M14: =SUMIFS('1005 4度C'!$N:$N,'1005 4度C'!$A:$A,"新豐4線",'1005 4度C'!$B:$B,"平均") -> 152.25209
C15: 達成率 | D15: =D14/D13 -> 0.96090228 | E15: =E14/E13 -> 0.95346715 | F15: =F14/F13 -> 0.959993 | G15: =G14/G13 -> 0.95875602 | H15: =H14/H13 -> 0.95294261 | I15: =I14/I13 -> 0.95981037 | J15: =J14/J13 -> 0.96527392 | K15: =K14/K13 -> 0.95769335 | ... M15: =M14/M13 -> 0.9586243
B16: 作業 時間 | C16: 開始 | D16: =VLOOKUP("新豐6線",'1005 4度C'!$A:$T,19,0) -> 0.70833333 | E16: =VLOOKUP("新豐2線",'1005 4度C'!$A:$T,19,0) -> 0.083333333 | F16: =VLOOKUP("新豐5線",'1005 4度C'!$A:$T,19,0) -> 0.25 | G16: =VLOOKUP("新豐7線",'1005 4度C'!$A:$T,19,0) -> 0.29166667 | H16: =VLOOKUP("新豐3線",'1005 4度C'!$A:$T,19,0) -> 0.20833333 | I16: =VLOOKUP("新豐1線",'1005 4度C'!$A:$T,19,0) -> 0.20833333 | J16: =VLOOKUP("新豐10線",'1005 4度C'!$A:$T,19,0) -> 0.20833333 | K16: =VLOOKUP("新豐8線",'1005 4度C'!$A:$T,19,0) -> 0.083333333 | L16: =VLOOKUP("新豐9線",'1005 4度C'!$A:$T,19,0) -> 0.083333333 | M16: =VLOOKUP("新豐4線",'1005 4度C'!$A:$T,19,0) -> 0.083333333
C17: 結束 | D17: =LOOKUP(2,1/(('1005 4度C'!$A:$A="新豐6線")*('1005 4度C'!$T:$T<>"")),'1005 4度C'!$T:$T) -> 0.91041667 | E17: =LOOKUP(2,1/(('1005 4度C'!$A:$A="新豐2線")*('1005 4度C'!$T:$T<>"")),'1005 4度C'!$T:$T) -> 0.46666667 | F17: =LOOKUP(2,1/(('1005 4度C'!$A:$A="新豐5線")*('1005 4度C'!$T:$T<>"")),'1005 4度C'!$T:$T) -> 0.84513889 | G17: =LOOKUP(2,1/(('1005 4度C'!$A:$A="新豐7線")*('1005 4度C'!$T:$T<>"")),'1005 4度C'!$T:$T) -> 0.91666667 | H17: =LOOKUP(2,1/(('1005 4度C'!$A:$A="新豐3線")*('1005 4度C'!$T:$T<>"")),'1005 4度C'!$T:$T) -> 0.4875 | I17: =LOOKUP(2,1/(('1005 4度C'!$A:$A="新豐1線")*('1005 4度C'!$T:$T<>"")),'1005 4度C'!$T:$T) -> 0.84861111 | J17: =LOOKUP(2,1/(('1005 4度C'!$A:$A="新豐10線")*('1005 4度C'!$T:$T<>"")),'1005 4度C'!$T:$T) -> 0.46736111 | K17: =LOOKUP(2,1/(('1005 4度C'!$A:$A="新豐8線")*('1005 4度C'!$T:$T<>"")),'1005 4度C'!$T:$T) -> 0.75694444 | L17: =LOOKUP(2,1/(('1005 4度C'!$A:$A="新豐9線")*('1005 4度C'!$T:$T<>"")),'1005 4度C'!$T:$T) -> 0.77847222 | M17: =LOOKUP(2,1/(('1005 4度C'!$A:$A="新豐4線")*('1005 4度C'!$T:$T<>"")),'1005 4度C'!$T:$T) -> 0.74583333
B18: 產線異常 (5分鐘以上) | C18: 次數 | D18: =SUMIFS('1005 4度C'!$Y:$Y,'1005 4度C'!$A:$A,"新豐6線",'1005 4度C'!$B:$B,"平均") -> 0 | E18: =SUMIFS('1005 4度C'!$Y:$Y,'1005 4度C'!$A:$A,"新豐2線",'1005 4度C'!$B:$B,"平均") -> 0 | F18: =SUMIFS('1005 4度C'!$Y:$Y,'1005 4度C'!$A:$A,"新豐5線",'1005 4度C'!$B:$B,"平均") -> 0 | G18: =SUMIFS('1005 4度C'!$Y:$Y,'1005 4度C'!$A:$A,"新豐7線",'1005 4度C'!$B:$B,"平均") -> 0 | H18: =SUMIFS('1005 4度C'!$Y:$Y,'1005 4度C'!$A:$A,"新豐3線",'1005 4度C'!$B:$B,"平均") -> 0 | I18: =SUMIFS('1005 4度C'!$Y:$Y,'1005 4度C'!$A:$A,"新豐1線",'1005 4度C'!$B:$B,"平均") -> 0 | J18: =SUMIFS('1005 4度C'!$Y:$Y,'1005 4度C'!$A:$A,"新豐10線",'1005 4度C'!$B:$B,"平均") -> 0 | K18: =SUMIFS('1005 4度C'!$Y:$Y,'1005 4度C'!$A:$A,"新豐8線",'1005 4度C'!$B:$B,"平均") -> 0 | L18: =SUMIFS('1005 4度C'!$Y:$Y,'1005 4度C'!$A:$A,"新豐9線",'1005 4度C'!$B:$B,"平均") -> 0 | M18: =SUMIFS('1005 4度C'!$Y:$Y,'1005 4度C'!$A:$A,"新豐4線",'1005 4度C'!$B:$B,"平均") -> 0
C19: 時間/分 | D19: =SUMIFS('1005 4度C'!$Z:$Z,'1005 4度C'!$A:$A,"新豐6線",'1005 4度C'!$B:$B,"平均") -> 0 | E19: =SUMIFS('1005 4度C'!$Z:$Z,'1005 4度C'!$A:$A,"新豐2線",'1005 4度C'!$B:$B,"平均") -> 0 | F19: =SUMIFS('1005 4度C'!$Z:$Z,'1005 4度C'!$A:$A,"新豐5線",'1005 4度C'!$B:$B,"平均") -> 0 | G19: =SUMIFS('1005 4度C'!$Z:$Z,'1005 4度C'!$A:$A,"新豐7線",'1005 4度C'!$B:$B,"平均") -> 0 | H19: =SUMIFS('1005 4度C'!$Z:$Z,'1005 4度C'!$A:$A,"新豐3線",'1005 4度C'!$B:$B,"平均") -> 0 | I19: =SUMIFS('1005 4度C'!$Z:$Z,'1005 4度C'!$A:$A,"新豐1線",'1005 4度C'!$B:$B,"平均") -> 0 | J19: =SUMIFS('1005 4度C'!$Z:$Z,'1005 4度C'!$A:$A,"新豐10線",'1005 4度C'!$B:$B,"平均") -> 0 | K19: =SUMIFS('1005 4度C'!$Z:$Z,'1005 4度C'!$A:$A,"新豐8線",'1005 4度C'!$B:$B,"平均") -> 0 | L19: =SUMIFS('1005 4度C'!$Z:$Z,'1005 4度C'!$A:$A,"新豐9線",'1005 4度C'!$B:$B,"平均") -> 0 | M19: =SUMIFS('1005 4度C'!$Z:$Z,'1005 4度C'!$A:$A,"新豐4線",'1005 4度C'!$B:$B,"平均") -> 0
B20: 短暫停線 (5分鐘以下) | C20: 次數 | D20: =SUMIFS('1005 4度C'!$AC:$AC,'1005 4度C'!$A:$A,"新豐6線",'1005 4度C'!$B:$B,"平均") -> 4 | E20: =SUMIFS('1005 4度C'!$AC:$AC,'1005 4度C'!$A:$A,"新豐2線",'1005 4度C'!$B:$B,"平均") -> 2 | F20: =SUMIFS('1005 4度C'!$AC:$AC,'1005 4度C'!$A:$A,"新豐5線",'1005 4度C'!$B:$B,"平均") -> 6 | G20: =SUMIFS('1005 4度C'!$AC:$AC,'1005 4度C'!$A:$A,"新豐7線",'1005 4度C'!$B:$B,"平均") -> 8 | H20: =SUMIFS('1005 4度C'!$AC:$AC,'1005 4度C'!$A:$A,"新豐3線",'1005 4度C'!$B:$B,"平均") -> 3 | I20: =SUMIFS('1005 4度C'!$AC:$AC,'1005 4度C'!$A:$A,"新豐1線",'1005 4度C'!$B:$B,"平均") -> 8 | J20: =SUMIFS('1005 4度C'!$AC:$AC,'1005 4度C'!$A:$A,"新豐10線",'1005 4度C'!$B:$B,"平均") -> 5 | K20: =SUMIFS('1005 4度C'!$AC:$AC,'1005 4度C'!$A:$A,"新豐8線",'1005 4度C'!$B:$B,"平均") -> 9 | L20: =SUMIFS('1005 4度C'!$AC:$AC,'1005 4度C'!$A:$A,"新豐9線",'1005 4度C'!$B:$B,"平均") -> 8 | M20: =SUMIFS('1005 4度C'!$AC:$AC,'1005 4度C'!$A:$A,"新豐4線",'1005 4度C'!$B:$B,"平均") -> 9
C21: 設備次數 | D21: =SUMIFS('1005 4度C'!$AD:$AD,'1005 4度C'!$A:$A,"新豐6線",'1005 4度C'!$B:$B,"平均") -> 0 | E21: =SUMIFS('1005 4度C'!$AD:$AD,'1005 4度C'!$A:$A,"新豐2線",'1005 4度C'!$B:$B,"平均") -> 0 | F21: =SUMIFS('1005 4度C'!$AD:$AD,'1005 4度C'!$A:$A,"新豐5線",'1005 4度C'!$B:$B,"平均") -> 0 | G21: =SUMIFS('1005 4度C'!$AD:$AD,'1005 4度C'!$A:$A,"新豐7線",'1005 4度C'!$B:$B,"平均") -> 0 | H21: =SUMIFS('1005 4度C'!$AD:$AD,'1005 4度C'!$A:$A,"新豐3線",'1005 4度C'!$B:$B,"平均") -> 0 | I21: =SUMIFS('1005 4度C'!$AD:$AD,'1005 4度C'!$A:$A,"新豐1線",'1005 4度C'!$B:$B,"平均") -> 0 | J21: =SUMIFS('1005 4度C'!$AD:$AD,'1005 4度C'!$A:$A,"新豐10線",'1005 4度C'!$B:$B,"平均") -> 0 | K21: =SUMIFS('1005 4度C'!$AD:$AD,'1005 4度C'!$A:$A,"新豐8線",'1005 4度C'!$B:$B,"平均") -> 0 | L21: =SUMIFS('1005 4度C'!$AD:$AD,'1005 4度C'!$A:$A,"新豐9線",'1005 4度C'!$B:$B,"平均") -> 0 | M21: =SUMIFS('1005 4度C'!$AD:$AD,'1005 4度C'!$A:$A,"新豐4線",'1005 4度C'!$B:$B,"平均") -> 0
B22: 配置人數 | D22: =SUMIFS('1005 4度C'!$I:$I,'1005 4度C'!$A:$A,"新豐6線",'1005 4度C'!$B:$B,"平均") -> 15 | E22: =SUMIFS('1005 4度C'!$I:$I,'1005 4度C'!$A:$A,"新豐2線",'1005 4度C'!$B:$B,"平均") -> 18 | F22: =SUMIFS('1005 4度C'!$I:$I,'1005 4度C'!$A:$A,"新豐5線",'1005 4度C'!$B:$B,"平均") -> 17 | G22: =SUMIFS('1005 4度C'!$I:$I,'1005 4度C'!$A:$A,"新豐7線",'1005 4度C'!$B:$B,"平均") -> 16 | H22: =SUMIFS('1005 4度C'!$I:$I,'1005 4度C'!$A:$A,"新豐3線",'1005 4度C'!$B:$B,"平均") -> 11 | I22: =SUMIFS('1005 4度C'!$I:$I,'1005 4度C'!$A:$A,"新豐1線",'1005 4度C'!$B:$B,"平均") -> 18.25 | J22: =SUMIFS('1005 4度C'!$I:$I,'1005 4度C'!$A:$A,"新豐10線",'1005 4度C'!$B:$B,"平均") -> 10.2 | K22: =SUMIFS('1005 4度C'!$I:$I,'1005 4度C'!$A:$A,"新豐8線",'1005 4度C'!$B:$B,"平均") -> 17.666667 | L22: =SUMIFS('1005 4度C'!$I:$I,'1005 4度C'!$A:$A,"新豐9線",'1005 4度C'!$B:$B,"平均") -> 17.625 | M22: =SUMIFS('1005 4度C'!$I:$I,'1005 4度C'!$A:$A,"新豐4線",'1005 4度C'!$B:$B,"平均") -> 15.111111
B23: 主要應用設備 | D23: ET-55 | E23: 熱縮爐 | F23: L型包裝機 | G23: L型包裝機 | H23: 伺服包裝機 | I23: ET-55 | J23: 伺服包裝機 | K23: 三明治包裝機 | L23: 三明治包裝機 | M23: 三明治包裝機
B24: 次要應用設備 | F24: 圓盤機 | G24: ET-55
B25: 備註 | E25: 握沙拉 | F25: 共用L型包裝機 | H25: 調理麵包 | I25: 炒飯+沙拉 | J25: 調理麵包

Sheet 1005 4度C
A1: 新豐廠四度C日報分析 | C1: 總生產量 | D1: =SUM(F5:F76) -> 188817 | E1: 營業額 | F1: =SUM(G5:G76) -> 6372151.5 | G1: 出勤人數 | H1: =L9+L12+L51+L60+L19+L66+L38+L47+L28+L76 -> 155.85278 | I1: 產線配置圖 | L1: 生產實績 | O1: 人時性差異分析 | S1: 日報登錄 | Y1: 合計 次數 | Z1: 合計 時間/分 | AA1: 產線異常 分析說明(5分鐘以上) | AC1: 合計 次數 | AD1: 合計 設備次數 | AE1: 產能差異分析
A2: 46300 | B2: 星期一 | C2: 人時性 | D2: =AVERAGE(N9,N12,N51,N60,N19,N66,N28,N38,N47,N76) -> 144.78124 | E2: 平均廠價 | F2: =F1/D1 -> 33.747764 | G2: 多次生產數 | H2: =COUNT(H5:H76) -> 11 | Y2: =SUM(Y9+Y12+Y19+Y28+Y38+Y47+Y51+Y60+Y66+Y76) -> 0 | Z2: =SUM(Z9+Z12+Z19+Z28+Z38+Z47+Z51+Z60+Z66+Z76) -> 0 | AC2: 62 | AD2: =SUM(AD9+AD12+AD19+AD28+AD38+AD47+AD51+AD60+AD66+AD76) -> 0
A3: 線別 | B3: 品類 | C3: 品名 | E3: 廠價 | F3: 生產量 | G3: 營收 | H3: 多次 生產 | I3: 人數 | J3: 產能/時 | K3: 人時性 | L3: 人數 | M3: 產能/時 | N3: 人時性 | O3: 人數 | P3: 人時性 | Q3: 達成率 | R3: 達成率平均 | S3: 生產時間 | U3: 換線、休息/分 | V3: 稼動時間/分 | W3: 休息時間 | Y3: 產線異常統計 (5分鐘以上) | AA3: (新豐回填) | AC3: 短暫停線統計 (5分鐘以下) | AE3: 產能/時 | AF3: 達成率 | AG3: 達成率平均
S4: 開始 | T4: 結束 | W4: 開始 | X4: 結束 | Y4: 次數 | Z4: 時間/分 | AC4: 總次數 | AD4: 設備因素(次數)
A5: 新豐6線 | B5: 微波主食 | C5: 二配金咖哩果香甘口咖哩飯 | E5: 50.92 | F5: 2723 | G5: =E5*F5 -> 138655.16 | I5: 15 | J5: 2000 | K5: =J5/I5 -> 133.33333 | L5: 15 | M5: =F5/V5*60 -> 1922.1176 | N5: =M5/L5 -> 128.14118 | O5: =L5-I5 -> 0 | P5: =N5-K5 -> -5.1921569 | Q5: =N5/K5 -> 0.96105882 | R5: =Q9 -> 0.96090228 | S5: 0.70833333 | T5: 0.76736111 | V5: =(T5-S5)*24*60 -> 85 | AC5: 4 | AE5: =M5-J5 -> -77.882353 | AF5: =M5/J5 -> 0.96105882 | AG5: =AF9 -> 0.96090228
A6: 新豐6線 | B6: 微波主食 | C6: 二配金咖哩濃厚辛口咖哩飯 | E6: 50.98 | F6: 1000 | G6: =E6*F6 -> 50980 | H6: 2 | I6: 16 | J6: 2000 | K6: =J6/I6 -> 125 | L6: 16 | M6: =F6/V6*60 -> 1935.4839 | N6: =M6/L6 -> 120.96774 | O6: =L6-I6 -> 0 | P6: =N6-K6 -> -4.0322581 | Q6: =N6/K6 -> 0.96774194 | S6: 0.77152778 | T6: 0.79305556 | U6: =IF(S6=TIME(17,0,0),"",(S6-T5)*24*60) -> 6 | V6: =(T6-S6)*24*60 -> 31 | AE6: =M6-J6 -> -64.516129 | AF6: =M6/J6 -> 0.96774194
A7: 新豐6線 | B7: 微波主食 | C7: 二配厚香料優格咖哩雞排飯 | E7: 56.43 | F7: 1301 | G7: =E7*F7 -> 73415.43 | I7: 13 | J7: 2000 | K7: =J7/I7 -> 153.84615 | L7: 13 | M7: =F7/V7*60 -> 1903.9024 | N7: =M7/L7 -> 146.45403 | O7: =L7-I7 -> 0 | P7: =N7-K7 -> -7.3921201 | Q7: =N7/K7 -> 0.95195122 | S7: 0.79791667 | T7: 0.82638889 | U7: =IF(S7=TIME(17,0,0),"",(S7-T6)*24*60) -> 7 | V7: =(T7-S7)*24*60 -> 41 | W7: =T7 -> 0.82638889 | X7: =S8 -> 0.86666667 | AE7: =M7-J7 -> -96.097561 | AF7: =M7/J7 -> 0.95195122
A8: 新豐6線 | B8: 微波主食 | C8: 二配金咖哩濃厚辛口咖哩飯 | E8: 50.98 | F8: 2022 | G8: =E8*F8 -> 103081.56 | I8: 16 | J8: 2000 | K8: =J8/I8 -> 125 | L8: 16 | M8: =F8/V8*60 -> 1925.7143 | N8: =M8/L8 -> 120.35714 | O8: =L8-I8 -> 0 | P8: =N8-K8 -> -4.6428571 | Q8: =N8/K8 -> 0.96285714 | S8: 0.86666667 | T8: 0.91041667 | U8: =IF(S8=TIME(17,0,0),"",(S8-T7)*24*60) -> 58 | V8: =(T8-S8)*24*60 -> 63 | AE8: =M8-J8 -> -74.285714 | AF8: =M8/J8 -> 0.96285714
A9: 新豐6線 | B9: 平均 | I9: 15 | J9: 2000 | K9: =J9/I9 -> 133.33333 | L9: 15 | M9: =AVERAGE(M5:M8) -> 1921.8046 | N9: =M9/L9 -> 128.1203 | O9: =L9-I9 -> 0 | P9: =N9-K9 -> -5.2130293 | Q9: =N9/K9 -> 0.96090228 | Y9: =SUM(Y5:Y8) -> 0 | Z9: =SUM(Z5:Z8) -> 0 | AC9: 4 | AD9: =SUM(AD5:AD8) -> 0 | AE9: =M9-J9 -> -78.195439 | AF9: =M9/J9 -> 0.96090228
A10: 新豐2線 | B10: 沙拉 | C10: 青醬優格雞肉握沙拉(113年) | E10: 39.62 | F10: 4909 | G10: =E10*F10 -> 194494.58 | I10: 19 | J10: 1500 | K10: =J10/I10 -> 78.947368 | L10: 19 | M10: =F10/V10*60 -> 1429.8058 | N10: =M10/L10 -> 75.252938 | O10: =L10-I10 -> 0 | P10: =N10-K10 -> -3.6944303 | Q10: =N10/K10 -> 0.95320388 | R10: =Q12 -> 0.95346715 | S10: 0.083333333 | T10: 0.22638889 | V10: =(T10-S10)*24*60 -> 206 | W10: =T10 -> 0.22638889 | X10: =S11 -> 0.24513889 | AC10: 2 | AE10: =M10-J10 -> -70.194175 | AF10: =M10/J10 -> 0.95320388 | AG10: =AF12 -> 0.95346715
A11: 新豐2線 | B11: 沙拉 | C11: 青檸烤雞握沙拉(113年) | E11: 39.8 | F11: 7606 | G11: =E11*F11 -> 302718.8 | I11: 17 | J11: 1500 | K11: =J11/I11 -> 88.235294 | L11: 17 | M11: =F11/V11*60 -> 1430.5956 | N11: =M11/L11 -> 84.152683 | O11: =L11-I11 -> 0 | P11: =N11-K11 -> -4.0826111 | Q11: =N11/K11 -> 0.95373041 | S11: 0.24513889 | T11: 0.46666667 | U11: =IF(S11=TIME(17,0,0),"",(S11-T10)*24*60) -> 27 | V11: =(T11-S11)*24*60 -> 319 | AE11: =M11-J11 -> -69.404389 | AF11: =M11/J11 -> 0.95373041
A12: 新豐2線 | B12: 平均 | I12: 18 | J12: 1500 | K12: =J12/I12 -> 83.333333 | L12: 18 | M12: =AVERAGE(M10:M11) -> 1430.2007 | N12: =M12/L12 -> 79.455595 | O12: =L12-I12 -> 0 | P12: =N12-K12 -> -3.8777379 | Q12: =N12/K12 -> 0.95346715 | Y12: =SUM(Y10:Y11) -> 0 | Z12: =SUM(Z10:Z11) -> 0 | AC12: 2 | AD12: =SUM(AD10:AD11) -> 0 | AE12: =M12-J12 -> -69.799282 | AF12: =M12/J12 -> 0.95346715
A13: 新豐5線 | B13: 季節調理麵 | C13: 台式麻醬涼麵(115年) | E13: 31.11 | F13: 2097 | G13: =E13*F13 -> 65237.67 | I13: 14 | J13: 2000 | K13: =J13/I13 -> 142.85714 | L13: 14 | M13: =F13/V13*60 -> 1906.3636 | N13: =M13/L13 -> 136.16883 | O13: =L13-I13 -> 0 | P13: =N13-K13 -> -6.6883117 | Q13: =N13/K13 -> 0.95318182 | R13: =Q19 -> 0.959993 | S13: 0.25 | T13: 0.29583333 | V13: =(T13-S13)*24*60 -> 66 | AC13: 6 | AE13: =M13-J13 -> -93.636364 | AF13: =M13/J13 -> 0.95318182 | AG13: =AF19 -> 0.959993
A14: 新豐5線 | B14: 小吃 | C14: 剝皮辣椒雞湯 | E14: 41 | F14: 2033 | G14: =E14*F14 -> 83353 | I14: 26 | J14: 1500 | K14: =J14/I14 -> 57.692308 | L14: 26 | M14: =F14/V14*60 -> 1435.0588 | N14: =M14/L14 -> 55.19457 | O14: =L14-I14 -> 0 | P14: =N14-K14 -> -2.4977376 | Q14: =N14/K14 -> 0.95670588 | S14: 0.3 | T14: 0.35902778 | U14: =IF(S14=TIME(17,0,0),"",(S14-T13)*24*60) -> 6 | V14: =(T14-S14)*24*60 -> 85 | AE14: =M14-J14 -> -64.941176 | AF14: =M14/J14 -> 0.95670588
A15: 新豐5線 | B15: 沙拉 | C15: 厚蛋時蔬握沙拉 | E15: 39.46 | F15: 2394 | G15: =E15*F15 -> 94467.24 | I15: 15 | J15: 1500 | K15: =J15/I15 -> 100 | L15: 15 | M15: =F15/V15*60 -> 1436.4 | N15: =M15/L15 -> 95.76 | O15: =L15-I15 -> 0 | P15: =N15-K15 -> -4.24 | Q15: =N15/K15 -> 0.9576 | S15: 0.36458333 | T15: 0.43402778 | U15: =IF(S15=TIME(17,0,0),"",(S15-T14)*24*60) -> 8 | V15: =(T15-S15)*24*60 -> 100 | AE15: =M15-J15 -> -63.6 | AF15: =M15/J15 -> 0.9576
A16: 新豐5線 | B16: 微波主食 | C16: 二配玉米濃湯焗烤飯 | E16: 54.5 | F16: 730 | G16: =E16*F16 -> 39785 | I16: 19 | J16: 1500 | K16: =J16/I16 -> 78.947368 | L16: 19 | M16: =F16/V16*60 -> 1460 | N16: =M16/L16 -> 76.842105 | O16: =L16-I16 -> 0 | P16: =N16-K16 -> -2.1052632 | Q16: =N16/K16 -> 0.97333333 | S16: 0.70833333 | T16: 0.72916667 | U16: =IF(S16=TIME(17,0,0),"",(S16-T15)*24*60) | V16: =(T16-S16)*24*60 -> 30 | AE16: =M16-J16 -> -40 | AF16: =M16/J16 -> 0.97333333
A17: 新豐5線 | B17: 微波主食 | C17: 二配泰式綠咖哩雞 | E17: 50.67 | F17: 1700 | G17: =E17*F17 -> 86139 | I17: 15 | J17: 2000 | K17: =J17/I17 -> 133.33333 | L17: 15 | M17: =F17/V17*60 -> 1924.5283 | N17: =M17/L17 -> 128.30189 | O17: =L17-I17 -> 0 | P17: =N17-K17 -> -5.0314465 | Q17: =N17/K17 -> 0.96226415 | S17: 0.73472222 | T17: 0.77152778 | U17: =IF(S17=TIME(17,0,0),"",(S17-T16)*24*60) -> 8 | V17: =(T17-S17)*24*60 -> 53 | AE17: =M17-J17 -> -75.471698 | AF17: =M17/J17 -> 0.96226415
A18: 新豐5線 | B18: 微波主食 | C18: 二配打拋風味豬肉飯 | E18: 51.06 | F18: 3164 | G18: =E18*F18 -> 161553.84 | I18: 13 | J18: 2000 | K18: =J18/I18 -> 153.84615 | L18: 13 | M18: =F18/V18*60 -> 1917.5758 | N18: =M18/L18 -> 147.50583 | O18: =L18-I18 -> 0 | P18: =N18-K18 -> -6.3403263 | Q18: =N18/K18 -> 0.95878788 | S18: 0.77638889 | T18: 0.84513889 | U18: =IF(S18=TIME(17,0,0),"",(S18-T17)*24*60) -> 7 | V18: =(T18-S18)*24*60 -> 99 | AE18: =M18-J18 -> -82.424242 | AF18: =M18/J18 -> 0.95878788
A19: 新豐5線 | B19: 平均 | I19: 17 | J19: 1750 | K19: =J19/I19 -> 102.94118 | L19: 17 | M19: =AVERAGE(M13:M18) -> 1679.9878 | N19: =M19/L19 -> 98.822809 | O19: =L19-I19 -> 0 | P19: =N19-K19 -> -4.1183675 | Q19: =N19/K19 -> 0.959993 | Y19: =SUM(Y13:Y18) -> 0 | Z19: =SUM(Z13:Z18) -> 0 | AC19: 6 | AD19: =SUM(AD13:AD18) -> 0 | AE19: =M19-J19 -> -70.012247 | AF19: =M19/J19 -> 0.959993
A20: 新豐7線 | B20: 微波主食 | C20: 韓式泡菜豬肉豆腐丼飯 | E20: 50.67 | F20: 1815 | G20: =E20*F20 -> 91966.05 | I20: 17 | J20: 2000 | K20: =J20/I20 -> 117.64706 | L20: 17 | M20: =F20/V20*60 -> 1910.5263 | N20: =M20/L20 -> 112.3839 | O20: =L20-I20 -> 0 | P20: =N20-K20 -> -5.2631579 | Q20: =N20/K20 -> 0.95526316 | R20: =Q28 -> 0.95875602 | S20: 0.29166667 | T20: 0.33125 | V20: =(T20-S20)*24*60 -> 57 | AC20: 8 | AE20: =M20-J20 -> -89.473684 | AF20: =M20/J20 -> 0.95526316 | AG20: =AF28 -> 0.95875602
A21: 新豐7線 | B21: 微波主食 | C21: 鐵板滑蛋炸豬排丼 | E21: 57.73 | F21: 2967 | G21: =E21*F21 -> 171284.91 | I21: 14 | J21: 2000 | K21: =J21/I21 -> 142.85714 | L21: 14 | M21: =F21/V21*60 -> 1914.1935 | N21: =M21/L21 -> 136.72811 | O21: =L21-I21 -> 0 | P21: =N21-K21 -> -6.1290323 | Q21: =N21/K21 -> 0.95709677 | S21: 0.33541667 | T21: 0.4 | U21: =IF(S21=TIME(17,0,0),"",(S21-T20)*24*60) -> 6 | V21: =(T21-S21)*24*60 -> 93 | AE21: =M21-J21 -> -85.806452 | AF21: =M21/J21 -> 0.95709677
A22: 新豐7線 | B22: 微波主食 | C22: 日式炙烤親子丼 | E22: 53.27 | F22: 1690 | G22: =E22*F22 -> 90026.3 | I22: 16 | J22: 2000 | K22: =J22/I22 -> 125 | L22: 16 | M22: =F22/V22*60 -> 1913.2075 | N22: =M22/L22 -> 119.57547 | O22: =L22-I22 -> 0 | P22: =N22-K22 -> -5.4245283 | Q22: =N22/K22 -> 0.95660377 | S22: 0.40347222 | T22: 0.44027778 | U22: =IF(S22=TIME(17,0,0),"",(S22-T21)*24*60) -> 5 | V22: =(T22-S22)*24*60 -> 53 | AE22: =M22-J22 -> -86.792453 | AF22: =M22/J22 -> 0.95660377
A23: 新豐7線 | B23: 微波主食 | C23: 熊本麥味噌炸豬排丼飯 | E23: 57.3 | F23: 2088 | G23: =E23*F23 -> 119642.4 | I23: 16 | J23: 2000 | K23: =J23/I23 -> 125 | L23: 16 | M23: =F23/V23*60 -> 1927.3846 | N23: =M23/L23 -> 120.46154 | O23: =L23-I23 -> 0 | P23: =N23-K23 -> -4.5384615 | Q23: =N23/K23 -> 0.96369231 | S23: 0.44444444 | T23: 0.48958333 | U23: =IF(S23=TIME(17,0,0),"",(S23-T22)*24*60) -> 6 | V23: =(T23-S23)*24*60 -> 65 | AE23: =M23-J23 -> -72.615385 | AF23: =M23/J23 -> 0.96369231
A24: 新豐7線 | B24: 微波主食 | C24: 二配川味麻婆燒豆腐燴飯 | E24: 50.49 | F24: 2349 | G24: =E24*F24 -> 118601.01 | I24: 15 | J24: 2000 | K24: =J24/I24 -> 133.33333 | L24: 15 | M24: =F24/V24*60 -> 1904.5946 | N24: =M24/L24 -> 126.97297 | O24: =L24-I24 -> 0 | P24: =N24-K24 -> -6.3603604 | Q24: =N24/K24 -> 0.9522973 | S24: 0.70833333 | T24: 0.75972222 | U24: =IF(S24=TIME(17,0,0),"",(S24-T23)*24*60) | V24: =(T24-S24)*24*60 -> 74 | AE24: =M24-J24 -> -95.405405 | AF24: =M24/J24 -> 0.9522973
A25: 新豐7線 | B25: 微波主食 | C25: 二配港式滑蛋牛肉燴飯 | E25: 50.67 | F25: 1000 | G25: =E25*F25 -> 50670 | H25: 2 | I25: 16 | J25: 2000 | K25: =J25/I25 -> 125 | L25: 16 | M25: =F25/V25*60 -> 1935.4839 | N25: =M25/L25 -> 120.96774 | O25: =L25-I25 -> 0 | P25: =N25-K25 -> -4.0322581 | Q25: =N25/K25 -> 0.96774194 | S25: 0.76319444 | T25: 0.78472222 | U25: =IF(S25=TIME(17,0,0),"",(S25-T24)*24*60) -> 5 | V25: =(T25-S25)*24*60 -> 31 | AE25: =M25-J25 -> -64.516129 | AF25: =M25/J25 -> 0.96774194
A26: 新豐7線 | B26: 微波主食 | C26: 二配美味蟹煲 | E26: 54.09 | F26: 2170 | G26: =E26*F26 -> 117375.3 | I26: 18 | J26: 2000 | K26: =J26/I26 -> 111.11111 | L26: 18 | M26: =F26/V26*60 -> 1914.7059 | N26: =M26/L26 -> 106.37255 | O26: =L26-I26 -> 0 | P26: =N26-K26 -> -4.7385621 | Q26: =N26/K26 -> 0.95735294 | S26: 0.79027778 | T26: 0.8375 | U26: =IF(S26=TIME(17,0,0),"",(S26-T25)*24*60) -> 8 | V26: =(T26-S26)*24*60 -> 68 | W26: =T26 -> 0.8375 | X26: =S27 -> 0.87569444 | AE26: =M26-J26 -> -85.294118 | AF26: =M26/J26 -> 0.95735294
A27: 新豐7線 | B27: 微波主食 | C27: 二配港式滑蛋牛肉燴飯 | E27: 50.67 | F27: 1888 | G27: =E27*F27 -> 95664.96 | I27: 16 | J27: 2000 | K27: =J27/I27 -> 125 | L27: 16 | M27: =F27/V27*60 -> 1920 | N27: =M27/L27 -> 120 | O27: =L27-I27 -> 0 | P27: =N27-K27 -> -5 | Q27: =N27/K27 -> 0.96 | S27: 0.87569444 | T27: 0.91666667 | U27: =IF(S27=TIME(17,0,0),"",(S27-T26)*24*60) -> 55 | V27: =(T27-S27)*24*60 -> 59 | AE27: =M27-J27 -> -80 | AF27: =M27/J27 -> 0.96
A28: 新豐7線 | B28: 平均 | I28: 16 | J28: 2000 | K28: =J28/I28 -> 125 | L28: 16 | M28: =AVERAGE(M20:M27) -> 1917.512 | N28: =M28/L28 -> 119.8445 | O28: =L28-I28 -> 0 | P28: =N28-K28 -> -5.1554971 | Q28: =N28/K28 -> 0.95875602 | Y28: =SUM(Y20:Y27) -> 0 | Z28: =SUM(Z20:Z27) -> 0 | AC28: 8 | AD28: =SUM(AD20:AD27) -> 0 | AE28: =M28-J28 -> -82.487953 | AF28: =M28/J28 -> 0.95875602
A29: 新豐8線 | B29: 三明治 | C29: 紐奧良風味烤雞鮮蔬三明治 | E29: 31.29 | F29: 6200 | G29: =E29*F29 -> 193998 | H29: 2 | I29: 18 | J29: 2400 | K29: =J29/I29 -> 133.33333 | L29: 18 | M29: =F29/V29*60 -> 2296.2963 | N29: =M29/L29 -> 127.57202 | O29: =L29-I29 -> 0 | P29: =N29-K29 -> -5.7613169 | Q29: =N29/K29 -> 0.95679012 | R29: =Q38 -> 0.95769335 | S29: 0.083333333 | T29: 0.19583333 | V29: =(T29-S29)*24*60 -> 162 | W29: =T29 -> 0.19583333 | X29: =S30 -> 0.21597222 | AC29: 9 | AE29: =M29-J29 -> -103.7037 | AF29: =M29/J29 -> 0.95679012 | AG29: =AF38 -> 0.95769335
A30: 新豐8線 | B30: 三明治 | C30: 醬燒烤雞三明治(115年) | E30: 26.37 | F30: 4400 | G30: =E30*F30 -> 116028 | H30: 2 | I30: 18 | J30: 2400 | K30: =J30/I30 -> 133.33333 | L30: 18 | M30: =F30/V30*60 -> 2295.6522 | N30: =M30/L30 -> 127.53623 | O30: =L30-I30 -> 0 | P30: =N30-K30 -> -5.7971014 | Q30: =N30/K30 -> 0.95652174 | S30: 0.21597222 | T30: 0.29583333 | U30: =(S30-T29)*24*60 -> 29 | V30: =(T30-S30)*24*60 -> 115 | AE30: =M30-J30 -> -104.34783 | AF30: =M30/J30 -> 0.95652174
A31: 新豐8線 | B31: 三明治 | C31: 水果聖代三明治 | E31: 28.29 | F31: 2528 | G31: =E31*F31 -> 71517.12 | I31: 19 | J31: 2400 | K31: =J31/I31 -> 126.31579 | L31: 19 | M31: =F31/V31*60 -> 2298.1818 | N31: =M31/L31 -> 120.95694 | O31: =L31-I31 -> 0 | P31: =N31-K31 -> -5.3588517 | Q31: =N31/K31 -> 0.95757576 | S31: 0.30138889 | T31: 0.34722222 | U31: =(S31-T30)*24*60 -> 8 | V31: =(T31-S31)*24*60 -> 66 | AE31: =M31-J31 -> -101.81818 | AF31: =M31/J31 -> 0.95757576
A32: 新豐8線 | B32: 三明治 | C32: 好多菜三明治 | E32: 25.98 | F32: 4057 | G32: =E32*F32 -> 105400.86 | I32: 19 | J32: 2400 | K32: =J32/I32 -> 126.31579 | L32: 19 | M32: =F32/V32*60 -> 2296.4151 | N32: =M32/L32 -> 120.86395 | O32: =L32-I32 -> 0 | P32: =N32-K32 -> -5.4518371 | Q32: =N32/K32 -> 0.95683962 | S32: 0.35208333 | T32: 0.42569444 | U32: =(S32-T31)*24*60 -> 7 | V32: =(T32-S32)*24*60 -> 106 | AE32: =M32-J32 -> -103.58491 | AF32: =M32/J32 -> 0.95683962
A33: 新豐8線 | B33: 三明治 | C33: 茄汁厚起司三明治 | E33: 25.99 | F33: 1527 | G33: =E33*F33 -> 39686.73 | I33: 18 | J33: 2400 | K33: =J33/I33 -> 133.33333 | L33: 18 | M33: =F33/V33*60 -> 2290.5 | N33: =M33/L33 -> 127.25 | O33: =L33-I33 -> 0 | P33: =N33-K33 -> -6.0833333 | Q33: =N33/K33 -> 0.954375 | S33: 0.43055556 | T33: 0.45833333 | U33: =(S33-T32)*24*60 -> 7 | V33: =(T33-S33)*24*60 -> 40 | AE33: =M33-J33 -> -109.5 | AF33: =M33/J33 -> 0.954375
A34: 新豐8線 | B34: 三明治 | C34: 起司芋見肉鬆三明治 | E34: 25.98 | F34: 1733 | G34: =E34*F34 -> 45023.34 | I34: 17 | J34: 2400 | K34: =J34/I34 -> 141.17647 | L34: 17 | M34: =F34/V34*60 -> 2310.6667 | N34: =M34/L34 -> 135.92157 | O34: =L34-I34 -> 0 | P34: =N34-K34 -> -5.254902 | Q34: =N34/K34 -> 0.96277778 | S34: 0.46319444 | T34: 0.49444444 | U34: =(S34-T33)*24*60 -> 7 | V34: =(T34-S34)*24*60 -> 45 | W34: =T34 -> 0.49444444 | X34: =S35 -> 0.53541667 | AE34: =M34-J34 -> -89.333333 | AF34: =M34/J34 -> 0.96277778
A35: 新豐8線 | B35: 三明治 | C35: 經典火腿玉米蛋三明治 | E35: 24.43 | F35: 3936 | G35: =E35*F35 -> 96156.48 | I35: 14 | J35: 2400 | K35: =J35/I35 -> 171.42857 | L35: 14 | M35: =F35/V35*60 -> 2292.8155 | N35: =M35/L35 -> 163.77254 | O35: =L35-I35 -> 0 | P35: =N35-K35 -> -7.6560333 | Q35: =N35/K35 -> 0.95533981 | S35: 0.53541667 | T35: 0.60694444 | U35: =(S35-T34)*24*60 -> 59 | V35: =(T35-S35)*24*60 -> 103 | AE35: =M35-J35 -> -107.18447 | AF35: =M35/J35 -> 0.95533981
A36: 新豐8線 | B36: 三明治 | C36: 醬燒烤雞三明治(115年) | E36: 26.37 | F36: 3146 | G36: =E36*F36 -> 82960.02 | I36: 18 | J36: 2400 | K36: =J36/I36 -> 133.33333 | L36: 18 | M36: =F36/V36*60 -> 2301.9512 | N36: =M36/L36 -> 127.88618 | O36: =L36-I36 -> 0 | P36: =N36-K36 -> -5.4471545 | Q36: =N36/K36 -> 0.95914634 | S36: 0.6125 | T36: 0.66944444 | U36: =(S36-T35)*24*60 -> 8 | V36: =(T36-S36)*24*60 -> 82 | AE36: =M36-J36 -> -98.04878 | AF36: =M36/J36 -> 0.95914634
A37: 新豐8線 | B37: 三明治 | C37: 紐奧良風味烤雞鮮蔬三明治 | E37: 31.29 | F37: 4569 | G37: =E37*F37 -> 142964.01 | I37: 18 | J37: 2400 | K37: =J37/I37 -> 133.33333 | L37: 18 | M37: =F37/V37*60 -> 2303.6975 | N37: =M37/L37 -> 127.98319 | O37: =L37-I37 -> 0 | P37: =N37-K37 -> -5.3501401 | Q37: =N37/K37 -> 0.95987395 | S37: 0.67430556 | T37: 0.75694444 | U37: =(S37-T36)*24*60 -> 7 | V37: =(T37-S37)*24*60 -> 119 | AE37: =M37-J37 -> -96.302521 | AF37: =M37/J37 -> 0.95987395
A38: 新豐8線 | B38: 平均 | I38: 17.666667 | J38: 2400 | K38: =J38/I38 -> 135.84906 | L38: 17.666667 | M38: =AVERAGE(M29:M37) -> 2298.464 | N38: =M38/L38 -> 130.10174 | O38: =L38-I38 -> 0 | P38: =N38-K38 -> -5.747319 | Q38: =N38/K38 -> 0.95769335 | Y38: =SUM(Y29:Y37) -> 0 | Z38: =SUM(Z29:Z37) -> 0 | AC38: 9 | AD38: =SUM(AD29:AD37) -> 0 | AE38: =M38-J38 -> -101.53597 | AF38: =M38/J38 -> 0.95769335
A39: 新豐9線 | B39: 三明治 | C39: 經典總匯三明治(115年) | E39: 26.18 | F39: 4000 | G39: =E39*F39 -> 104720 | H39: 2 | I39: 20 | J39: 2400 | K39: =J39/I39 -> 120 | L39: 20 | M39: =F39/V39*60 -> 2285.7143 | N39: =M39/L39 -> 114.28571 | O39: =L39-I39 -> 0 | P39: =N39-K39 -> -5.7142857 | Q39: =N39/K39 -> 0.95238095 | R39: =Q47 -> 0.95423459 | S39: 0.083333333 | T39: 0.15625 | V39: =(T39-S39)*24*60 -> 105 | W39: =T39 -> 0.15625 | X39: =S40 -> 0.17708333 | AC39: 8 | AE39: =M39-J39 -> -114.28571 | AF39: =M39/J39 -> 0.95238095 | AG39: =AF47 -> 0.95423459
A40: 新豐9線 | B40: 三明治 | C40: 鮪魚起司溏心蛋三明治(115年) | E40: 26.18 | F40: 5300 | G40: =E40*F40 -> 138754 | H40: 2 | I40: 18 | J40: 2400 | K40: =J40/I40 -> 133.33333 | L40: 18 | M40: =F40/V40*60 -> 2287.7698 | N40: =M40/L40 -> 127.09832 | O40: =L40-I40 -> 0 | P40: =N40-K40 -> -6.235012 | Q40: =N40/K40 -> 0.95323741 | S40: 0.17708333 | T40: 0.27361111 | U40: =(S40-T39)*24*60 -> 30 | V40: =(T40-S40)*24*60 -> 139 | AE40: =M40-J40 -> -112.23022 | AF40: =M40/J40 -> 0.95323741
...

Sheet 1004
B1: 屏榮 新豐廠組合室生產人時性分析
B3: 日期 | C3: =TEXT('1004 4度C'!A2,"yyyy.mm.ddaaaa") -> 2026.10.04星期日 | E3: 訂單量 | F3: ='1004 4度C'!D1 -> 198735 | H3: 營業額 | I3: ='1004 4度C'!F1 -> 6690404.5
B4: 人時性 | C4: 項目 | E4: ➀ | G4: ➁ | I4: ➂ | K4: 異常停線 | M4: 短暫停線
C5: 組合室 | E5: 全溫層 | G5: 4度C-各編組展開 | I5: ③三明治-各編組展開 | K5: 合計次數 | L5: 時間 | M5: 合計次數 | N5: 設備次數
C6: 排關平均 | E6: =AVERAGE(D13:M13) -> 151.18064 | F6: =AVERAGE(D31:O31,D13:J13) -> 156.04444 | G6: =AVERAGE(D13:J13) -> 156.04444 | I6: =AVERAGE(K13:M13) -> 139.83176 | K6: ='1004 4度C'!Y2 -> 0 | L6: ='1004 4度C'!Z2 -> 0 | M6: ='1004 4度C'!AC2 -> 64 | N6: ='1004 4度C'!AD2 -> 0
C7: 實績平均 | E7: =AVERAGE(D14:M14) -> 145.01448 | F7: =AVERAGE(D32:O32,D14:J14) -> 149.86526 | G7: =AVERAGE(D14:J14) -> 149.86526 | I7: =AVERAGE(K14:M14) -> 133.69599
C8: 達成率平均 | E8: =AVERAGE(D15:M15) -> 0.95900352 | F8: =AVERAGE(D15:J15,D33:O33) -> 0.96022262 | G8: =AVERAGE(D15:J15) -> 0.96022262 | I8: =AVERAGE(K15:M15) -> 0.95615895
K9: ※現行日本鮮食廠以達成率80%為基本(即為現行KPI)
B10: 溫層 | D10: ➁4度C-各編組展開 | K10: ③三明治-各編組展開
B11: 編組 | D11: 1 | E11: 2 | F11: 3 | G11: 4 | H11: 5 | I11: 6 | J11: 7 | K11: 1 | L11: 2 | M11: 3
D12: 新豐6線 | E12: 新豐2線 | F12: 新豐5線 | G12: 新豐7線 | H12: 新豐3線 | I12: 新豐1線 | J12: 新豐10線 | K12: 新豐8線 | L12: 新豐9線 | M12: 新豐4線
B13: 人時性 | C13: 排關 | D13: =SUMIFS('1004 4度C'!$K:$K,'1004 4度C'!$A:$A,"新豐6線",'1004 4度C'!$B:$B,"平均") -> 133.33333 | E13: =SUMIFS('1004 4度C'!$K:$K,'1004 4度C'!$A:$A,"新豐2線",'1004 4度C'!$B:$B,"平均") -> 84.90566 | F13: =SUMIFS('1004 4度C'!$K:$K,'1004 4度C'!$A:$A,"新豐5線",'1004 4度C'!$B:$B,"平均") -> 102.94118 | G13: =SUMIFS('1004 4度C'!$K:$K,'1004 4度C'!$A:$A,"新豐7線",'1004 4度C'!$B:$B,"平均") -> 125 | H13: =SUMIFS('1004 4度C'!$K:$K,'1004 4度C'!$A:$A,"新豐3線",'1004 4度C'!$B:$B,"平均") -> 242.42424 | I13: =SUMIFS('1004 4度C'!$K:$K,'1004 4度C'!$A:$A,"新豐1線",'1004 4度C'!$B:$B,"平均") -> 109.58904 | J13: =SUMIFS('1004 4度C'!$K:$K,'1004 4度C'!$A:$A,"新豐10線",'1004 4度C'!$B:$B,"平均") -> 294.11765 | K13: =SUMIFS('1004 4度C'!$K:$K,'1004 4度C'!$A:$A,"新豐8線",'1004 4度C'!$B:$B,"平均") -> 135.84906 | L13: =SUMIFS('1004 4度C'!$K:$K,'1004 4度C'!$A:$A,"新豐9線",'1004 4度C'!$B:$B,"平均") -> 124.8227 | M13: =SUMIFS('1004 4度C'!$K:$K,'1004 4度C'!$A:$A,"新豐4線",'1004 4度C'!$B:$B,"平均") -> 158.82353
C14: 實績 | D14: =SUMIFS('1004 4度C'!$N:$N,'1004 4度C'!$A:$A,"新豐6線",'1004 4度C'!$B:$B,"平均") -> 128.58981 | E14: =SUMIFS('1004 4度C'!$N:$N,'1004 4度C'!$A:$A,"新豐2線",'1004 4度C'!$B:$B,"平均") -> 80.961737 | F14: =SUMIFS('1004 4度C'!$N:$N,'1004 4度C'!$A:$A,"新豐5線",'1004 4度C'!$B:$B,"平均") -> 98.582174 | G14: =SUMIFS('1004 4度C'!$N:$N,'1004 4度C'!$A:$A,"新豐7線",'1004 4度C'!$B:$B,"平均") -> 120.3928 | H14: =SUMIFS('1004 4度C'!$N:$N,'1004 4度C'!$A:$A,"新豐3線",'1004 4度C'!$B:$B,"平均") -> 231.43028 | I14: =SUMIFS('1004 4度C'!$N:$N,'1004 4度C'!$A:$A,"新豐1線",'1004 4度C'!$B:$B,"平均") -> 105.71139 | J14: =SUMIFS('1004 4度C'!$N:$N,'1004 4度C'!$A:$A,"新豐10線",'1004 4度C'!$B:$B,"平均") -> 283.38861 | K14: =SUMIFS('1004 4度C'!$N:$N,'1004 4度C'!$A:$A,"新豐8線",'1004 4度C'!$B:$B,"平均") -> 130.10702 | L14: =SUMIFS('1004 4度C'!$N:$N,'1004 4度C'!$A:$A,"新豐9線",'1004 4度C'!$B:$B,"平均") -> 119.27705 | M14: =SUMIFS('1004 4度C'!$N:$N,'1004 4度C'!$A:$A,"新豐4線",'1004 4度C'!$B:$B,"平均") -> 151.7039
C15: 達成率 | D15: =D14/D13 -> 0.96442358 | E15: =E14/E13 -> 0.95354934 | F15: =F14/F13 -> 0.9576554 | G15: =G14/G13 -> 0.9631424 | H15: =H14/H13 -> 0.95464992 | I15: =I14/I13 -> 0.96461641 | J15: =J14/J13 -> 0.96352129 | K15: =K14/K13 -> 0.95773225 | ... M15: =M14/M13 -> 0.95517273
B16: 作業 時間 | C16: 開始 | D16: =VLOOKUP("新豐6線",'1004 4度C'!$A:$T,19,0) -> 0.70833333 | E16: =VLOOKUP("新豐2線",'1004 4度C'!$A:$T,19,0) -> 0.16666667 | F16: =VLOOKUP("新豐5線",'1004 4度C'!$A:$T,19,0) -> 0.25 | G16: =VLOOKUP("新豐7線",'1004 4度C'!$A:$T,19,0) -> 0.29166667 | H16: =VLOOKUP("新豐3線",'1004 4度C'!$A:$T,19,0) -> 0.20833333 | I16: =VLOOKUP("新豐1線",'1004 4度C'!$A:$T,19,0) -> 0.20833333 | J16: =VLOOKUP("新豐10線",'1004 4度C'!$A:$T,19,0) -> 0.20833333 | K16: =VLOOKUP("新豐8線",'1004 4度C'!$A:$T,19,0) -> 0.083333333 | L16: =VLOOKUP("新豐9線",'1004 4度C'!$A:$T,19,0) -> 0.083333333 | M16: =VLOOKUP("新豐4線",'1004 4度C'!$A:$T,19,0) -> 0.083333333
C17: 結束 | D17: =LOOKUP(2,1/(('1004 4度C'!$A:$A="新豐6線")*('1004 4度C'!$T:$T<>"")),'1004 4度C'!$T:$T) -> 0.91458333 | E17: =LOOKUP(2,1/(('1004 4度C'!$A:$A="新豐2線")*('1004 4度C'!$T:$T<>"")),'1004 4度C'!$T:$T) -> 0.64861111 | F17: =LOOKUP(2,1/(('1004 4度C'!$A:$A="新豐5線")*('1004 4度C'!$T:$T<>"")),'1004 4度C'!$T:$T) -> 0.85694444 | G17: =LOOKUP(2,1/(('1004 4度C'!$A:$A="新豐7線")*('1004 4度C'!$T:$T<>"")),'1004 4度C'!$T:$T) -> 0.91388889 | H17: =LOOKUP(2,1/(('1004 4度C'!$A:$A="新豐3線")*('1004 4度C'!$T:$T<>"")),'1004 4度C'!$T:$T) -> 0.49583333 | I17: =LOOKUP(2,1/(('1004 4度C'!$A:$A="新豐1線")*('1004 4度C'!$T:$T<>"")),'1004 4度C'!$T:$T) -> 0.86180556 | J17: =LOOKUP(2,1/(('1004 4度C'!$A:$A="新豐10線")*('1004 4度C'!$T:$T<>"")),'1004 4度C'!$T:$T) -> 0.45972222 | K17: =LOOKUP(2,1/(('1004 4度C'!$A:$A="新豐8線")*('1004 4度C'!$T:$T<>"")),'1004 4度C'!$T:$T) -> 0.78402778 | L17: =LOOKUP(2,1/(('1004 4度C'!$A:$A="新豐9線")*('1004 4度C'!$T:$T<>"")),'1004 4度C'!$T:$T) -> 0.77916667 | M17: =LOOKUP(2,1/(('1004 4度C'!$A:$A="新豐4線")*('1004 4度C'!$T:$T<>"")),'1004 4度C'!$T:$T) -> 0.79027778
B18: 產線異常 (5分鐘以上) | C18: 次數 | D18: =SUMIFS('1004 4度C'!$Y:$Y,'1004 4度C'!$A:$A,"新豐6線",'1004 4度C'!$B:$B,"平均") -> 0 | E18: =SUMIFS('1004 4度C'!$Y:$Y,'1004 4度C'!$A:$A,"新豐2線",'1004 4度C'!$B:$B,"平均") -> 0 | F18: =SUMIFS('1004 4度C'!$Y:$Y,'1004 4度C'!$A:$A,"新豐5線",'1004 4度C'!$B:$B,"平均") -> 0 | G18: =SUMIFS('1004 4度C'!$Y:$Y,'1004 4度C'!$A:$A,"新豐7線",'1004 4度C'!$B:$B,"平均") -> 0 | H18: =SUMIFS('1004 4度C'!$Y:$Y,'1004 4度C'!$A:$A,"新豐3線",'1004 4度C'!$B:$B,"平均") -> 0 | I18: =SUMIFS('1004 4度C'!$Y:$Y,'1004 4度C'!$A:$A,"新豐1線",'1004 4度C'!$B:$B,"平均") -> 0 | J18: =SUMIFS('1004 4度C'!$Y:$Y,'1004 4度C'!$A:$A,"新豐10線",'1004 4度C'!$B:$B,"平均") -> 0 | K18: =SUMIFS('1004 4度C'!$Y:$Y,'1004 4度C'!$A:$A,"新豐8線",'1004 4度C'!$B:$B,"平均") -> 0 | L18: =SUMIFS('1004 4度C'!$Y:$Y,'1004 4度C'!$A:$A,"新豐9線",'1004 4度C'!$B:$B,"平均") -> 0 | M18: =SUMIFS('1004 4度C'!$Y:$Y,'1004 4度C'!$A:$A,"新豐4線",'1004 4度C'!$B:$B,"平均") -> 0
C19: 時間/分 | D19: =SUMIFS('1004 4度C'!$Z:$Z,'1004 4度C'!$A:$A,"新豐6線",'1004 4度C'!$B:$B,"平均") -> 0 | E19: =SUMIFS('1004 4度C'!$Z:$Z,'1004 4度C'!$A:$A,"新豐2線",'1004 4度C'!$B:$B,"平均") -> 0 | F19: =SUMIFS('1004 4度C'!$Z:$Z,'1004 4度C'!$A:$A,"新豐5線",'1004 4度C'!$B:$B,"平均") -> 0 | G19: =SUMIFS('1004 4度C'!$Z:$Z,'1004 4度C'!$A:$A,"新豐7線",'1004 4度C'!$B:$B,"平均") -> 0 | H19: =SUMIFS('1004 4度C'!$Z:$Z,'1004 4度C'!$A:$A,"新豐3線",'1004 4度C'!$B:$B,"平均") -> 0 | I19: =SUMIFS('1004 4度C'!$Z:$Z,'1004 4度C'!$A:$A,"新豐1線",'1004 4度C'!$B:$B,"平均") -> 0 | J19: =SUMIFS('1004 4度C'!$Z:$Z,'1004 4度C'!$A:$A,"新豐10線",'1004 4度C'!$B:$B,"平均") -> 0 | K19: =SUMIFS('1004 4度C'!$Z:$Z,'1004 4度C'!$A:$A,"新豐8線",'1004 4度C'!$B:$B,"平均") -> 0 | L19: =SUMIFS('1004 4度C'!$Z:$Z,'1004 4度C'!$A:$A,"新豐9線",'1004 4度C'!$B:$B,"平均") -> 0 | M19: =SUMIFS('1004 4度C'!$Z:$Z,'1004 4度C'!$A:$A,"新豐4線",'1004 4度C'!$B:$B,"平均") -> 0
B20: 短暫停線 (5分鐘以下) | C20: 次數 | D20: =SUMIFS('1004 4度C'!$AC:$AC,'1004 4度C'!$A:$A,"新豐6線",'1004 4度C'!$B:$B,"平均") -> 4 | E20: =SUMIFS('1004 4度C'!$AC:$AC,'1004 4度C'!$A:$A,"新豐2線",'1004 4度C'!$B:$B,"平均") -> 3 | F20: =SUMIFS('1004 4度C'!$AC:$AC,'1004 4度C'!$A:$A,"新豐5線",'1004 4度C'!$B:$B,"平均") -> 6 | G20: =SUMIFS('1004 4度C'!$AC:$AC,'1004 4度C'!$A:$A,"新豐7線",'1004 4度C'!$B:$B,"平均") -> 9 | H20: =SUMIFS('1004 4度C'!$AC:$AC,'1004 4度C'!$A:$A,"新豐3線",'1004 4度C'!$B:$B,"平均") -> 3 | I20: =SUMIFS('1004 4度C'!$AC:$AC,'1004 4度C'!$A:$A,"新豐1線",'1004 4度C'!$B:$B,"平均") -> 8 | J20: =SUMIFS('1004 4度C'!$AC:$AC,'1004 4度C'!$A:$A,"新豐10線",'1004 4度C'!$B:$B,"平均") -> 5 | K20: =SUMIFS('1004 4度C'!$AC:$AC,'1004 4度C'!$A:$A,"新豐8線",'1004 4度C'!$B:$B,"平均") -> 9 | L20: =SUMIFS('1004 4度C'!$AC:$AC,'1004 4度C'!$A:$A,"新豐9線",'1004 4度C'!$B:$B,"平均") -> 8 | M20: =SUMIFS('1004 4度C'!$AC:$AC,'1004 4度C'!$A:$A,"新豐4線",'1004 4度C'!$B:$B,"平均") -> 9
C21: 設備次數 | D21: =SUMIFS('1004 4度C'!$AD:$AD,'1004 4度C'!$A:$A,"新豐6線",'1004 4度C'!$B:$B,"平均") -> 0 | E21: =SUMIFS('1004 4度C'!$AD:$AD,'1004 4度C'!$A:$A,"新豐2線",'1004 4度C'!$B:$B,"平均") -> 0 | F21: =SUMIFS('1004 4度C'!$AD:$AD,'1004 4度C'!$A:$A,"新豐5線",'1004 4度C'!$B:$B,"平均") -> 0 | G21: =SUMIFS('1004 4度C'!$AD:$AD,'1004 4度C'!$A:$A,"新豐7線",'1004 4度C'!$B:$B,"平均") -> 0 | H21: =SUMIFS('1004 4度C'!$AD:$AD,'1004 4度C'!$A:$A,"新豐3線",'1004 4度C'!$B:$B,"平均") -> 0 | I21: =SUMIFS('1004 4度C'!$AD:$AD,'1004 4度C'!$A:$A,"新豐1線",'1004 4度C'!$B:$B,"平均") -> 0 | J21: =SUMIFS('1004 4度C'!$AD:$AD,'1004 4度C'!$A:$A,"新豐10線",'1004 4度C'!$B:$B,"平均") -> 0 | K21: =SUMIFS('1004 4度C'!$AD:$AD,'1004 4度C'!$A:$A,"新豐8線",'1004 4度C'!$B:$B,"平均") -> 0 | L21: =SUMIFS('1004 4度C'!$AD:$AD,'1004 4度C'!$A:$A,"新豐9線",'1004 4度C'!$B:$B,"平均") -> 0 | M21: =SUMIFS('1004 4度C'!$AD:$AD,'1004 4度C'!$A:$A,"新豐4線",'1004 4度C'!$B:$B,"平均") -> 0
B22: 配置人數 | D22: =SUMIFS('1004 4度C'!$I:$I,'1004 4度C'!$A:$A,"新豐6線",'1004 4度C'!$B:$B,"平均") -> 15 | E22: =SUMIFS('1004 4度C'!$I:$I,'1004 4度C'!$A:$A,"新豐2線",'1004 4度C'!$B:$B,"平均") -> 17.666667 | F22: =SUMIFS('1004 4度C'!$I:$I,'1004 4度C'!$A:$A,"新豐5線",'1004 4度C'!$B:$B,"平均") -> 17 | G22: =SUMIFS('1004 4度C'!$I:$I,'1004 4度C'!$A:$A,"新豐7線",'1004 4度C'!$B:$B,"平均") -> 16 | H22: =SUMIFS('1004 4度C'!$I:$I,'1004 4度C'!$A:$A,"新豐3線",'1004 4度C'!$B:$B,"平均") -> 11 | I22: =SUMIFS('1004 4度C'!$I:$I,'1004 4度C'!$A:$A,"新豐1線",'1004 4度C'!$B:$B,"平均") -> 18.25 | J22: =SUMIFS('1004 4度C'!$I:$I,'1004 4度C'!$A:$A,"新豐10線",'1004 4度C'!$B:$B,"平均") -> 10.2 | K22: =SUMIFS('1004 4度C'!$I:$I,'1004 4度C'!$A:$A,"新豐8線",'1004 4度C'!$B:$B,"平均") -> 17.666667 | L22: =SUMIFS('1004 4度C'!$I:$I,'1004 4度C'!$A:$A,"新豐9線",'1004 4度C'!$B:$B,"平均") -> 17.625 | M22: =SUMIFS('1004 4度C'!$I:$I,'1004 4度C'!$A:$A,"新豐4線",'1004 4度C'!$B:$B,"平均") -> 15.111111
B23: 主要應用設備 | D23: ET-55 | E23: 熱縮爐 | F23: L型包裝機 | G23: L型包裝機 | H23: 伺服包裝機 | I23: ET-55 | J23: 伺服包裝機 | K23: 三明治包裝機 | L23: 三明治包裝機 | M23: 三明治包裝機
B24: 次要應用設備 | F24: 圓盤機 | G24: ET-55
B25: 備註 | E25: 握沙拉 | F25: 共用L型包裝機 | H25: 調理麵包 | I25: 炒飯+沙拉 | J25: 調理麵包

Sheet 1004 4度C
A1: 新豐廠四度C日報分析 | C1: 總生產量 | D1: =SUM(F5:F78) -> 198735 | E1: 營業額 | F1: =SUM(G5:G78) -> 6690404.5 | G1: 出勤人數 | H1: =L9+L13+L53+L62+L20+L68+L40+L49+L30+L78 -> 155.51944 | I1: 產線配置圖 | L1: 生產實績 | O1: 人時性差異分析 | S1: 日報登錄 | Y1: 合計 次數 | Z1: 合計 時間/分 | AA1: 產線異常 分析說明(5分鐘以上) | AC1: 合計 次數 | AD1: 合計 設備次數 | AE1: 產能差異分析
A2: 46299 | B2: 星期日 | C2: 人時性 | D2: =AVERAGE(N9,N13,N53,N62,N20,N68,N30,N40,N49,N78) -> 145.01448 | E2: 平均廠價 | F2: =F1/D1 -> 33.664953 | G2: 多次生產數 | H2: =COUNT(H5:H78) -> 13 | Y2: =SUM(Y9+Y13+Y20+Y30+Y40+Y49+Y53+Y62+Y68+Y78) -> 0 | Z2: =SUM(Z9+Z13+Z20+Z30+Z40+Z49+Z53+Z62+Z68+Z78) -> 0 | AC2: =SUM(AC9+AC13+AC20+AC30+AC40+AC49+AC53+AC62+AC68+AC78) -> 64 | AD2: =SUM(AD9+AD13+AD20+AD30+AD40+AD49+AD53+AD62+AD68+AD78) -> 0
A3: 線別 | B3: 品類 | C3: 品名 | E3: 廠價 | F3: 生產量 | G3: 營收 | H3: 多次 生產 | I3: 人數 | J3: 產能/時 | K3: 人時性 | L3: 人數 | M3: 產能/時 | N3: 人時性 | O3: 人數 | P3: 人時性 | Q3: 達成率 | R3: 達成率平均 | S3: 生產時間 | U3: 換線、休息/分 | V3: 稼動時間/分 | W3: 休息時間 | Y3: 產線異常統計 (5分鐘以上) | AA3: (新豐回填) | AC3: 短暫停線統計 (5分鐘以下) | AE3: 產能/時 | AF3: 達成率 | AG3: 達成率平均
S4: 開始 | T4: 結束 | W4: 開始 | X4: 結束 | Y4: 次數 | Z4: 時間/分 | AC4: 總次數 | AD4: 設備因素(次數)
A5: 新豐6線 | B5: 微波主食 | C5: 二配金咖哩果香甘口咖哩飯 | E5: 50.92 | F5: 2694 | G5: =E5*F5 -> 137178.48 | I5: 15 | J5: 2000 | K5: =J5/I5 -> 133.33333 | L5: 15 | M5: =F5/V5*60 -> 1924.2857 | N5: =M5/L5 -> 128.28571 | O5: =L5-I5 -> 0 | P5: =N5-K5 -> -5.047619 | Q5: =N5/K5 -> 0.96214286 | R5: =Q9 -> 0.96442358 | S5: 0.70833333 | T5: 0.76666667 | V5: =(T5-S5)*24*60 -> 84 | AC5: 4 | AE5: =M5-J5 -> -75.714286 | AF5: =M5/J5 -> 0.96214286 | AG5: =AF9 -> 0.96442358
A6: 新豐6線 | B6: 微波主食 | C6: 二配金咖哩濃厚辛口咖哩飯 | E6: 50.98 | F6: 1000 | G6: =E6*F6 -> 50980 | H6: 2 | I6: 16 | J6: 2000 | K6: =J6/I6 -> 125 | L6: 16 | M6: =F6/V6*60 -> 1935.4839 | N6: =M6/L6 -> 120.96774 | O6: =L6-I6 -> 0 | P6: =N6-K6 -> -4.0322581 | Q6: =N6/K6 -> 0.96774194 | S6: 0.77222222 | T6: 0.79375 | U6: =IF(S6=TIME(17,0,0),"",(S6-T5)*24*60) -> 8 | V6: =(T6-S6)*24*60 -> 31 | AE6: =M6-J6 -> -64.516129 | AF6: =M6/J6 -> 0.96774194
A7: 新豐6線 | B7: 微波主食 | C7: 二配厚香料優格咖哩雞排飯 | E7: 56.43 | F7: 1446 | G7: =E7*F7 -> 81597.78 | I7: 13 | J7: 2000 | K7: =J7/I7 -> 153.84615 | L7: 13 | M7: =F7/V7*60 -> 1928 | N7: =M7/L7 -> 148.30769 | O7: =L7-I7 -> 0 | P7: =N7-K7 -> -5.5384615 | Q7: =N7/K7 -> 0.964 | S7: 0.79930556 | T7: 0.83055556 | U7: =IF(S7=TIME(17,0,0),"",(S7-T6)*24*60) -> 8 | V7: =(T7-S7)*24*60 -> 45 | W7: =T7 -> 0.83055556 | X7: =S8 -> 0.87083333 | AE7: =M7-J7 -> -72 | AF7: =M7/J7 -> 0.964
A8: 新豐6線 | B8: 微波主食 | C8: 二配金咖哩濃厚辛口咖哩飯 | E8: 50.98 | F8: 2024 | G8: =E8*F8 -> 103183.52 | I8: 16 | J8: 2000 | K8: =J8/I8 -> 125 | L8: 16 | M8: =F8/V8*60 -> 1927.619 | N8: =M8/L8 -> 120.47619 | O8: =L8-I8 -> 0 | P8: =N8-K8 -> -4.5238095 | Q8: =N8/K8 -> 0.96380952 | S8: 0.87083333 | T8: 0.91458333 | U8: =IF(S8=TIME(17,0,0),"",(S8-T7)*24*60) -> 58 | V8: =(T8-S8)*24*60 -> 63 | AE8: =M8-J8 -> -72.380952 | AF8: =M8/J8 -> 0.96380952
A9: 新豐6線 | B9: 平均 | I9: 15 | J9: 2000 | K9: =J9/I9 -> 133.33333 | L9: 15 | M9: =AVERAGE(M5:M8) -> 1928.8472 | N9: =M9/L9 -> 128.58981 | O9: =L9-I9 -> 0 | P9: =N9-K9 -> -4.7435228 | Q9: =N9/K9 -> 0.96442358 | Y9: =SUM(Y5:Y8) -> 0 | Z9: =SUM(Z5:Z8) -> 0 | AC9: 4 | AD9: =SUM(AD5:AD8) -> 0 | AE9: =M9-J9 -> -71.152842 | AF9: =M9/J9 -> 0.96442358
A10: 新豐2線 | B10: 沙拉 | C10: 青醬優格雞肉握沙拉(113年) | E10: 39.62 | F10: 5035 | G10: =E10*F10 -> 199486.7 | I10: 19 | J10: 1500 | K10: =J10/I10 -> 78.947368 | L10: 19 | M10: =F10/V10*60 -> 1431.7536 | N10: =M10/L10 -> 75.35545 | O10: =L10-I10 -> 0 | P10: =N10-K10 -> -3.5919182 | Q10: =N10/K10 -> 0.95450237 | R10: =Q13 -> 0.95354934 | S10: 0.16666667 | T10: 0.31319444 | V10: =(T10-S10)*24*60 -> 211 | W10: =T10 -> 0.31319444 | X10: =S11 -> 0.33333333 | AC10: 3 | AE10: =M10-J10 -> -68.246445 | AF10: =M10/J10 -> 0.95450237 | AG10: =AF13 -> 0.95354934
A11: 新豐2線 | B11: 沙拉 | C11: 青檸烤雞握沙拉(113年) | E11: 39.8 | F11: 4600 | G11: =E11*F11 -> 183080 | H11: 2 | I11: 17 | J11: 1500 | K11: =J11/I11 -> 88.235294 | L11: 17 | M11: =F11/V11*60 -> 1430.0518 | N11: =M11/L11 -> 84.120695 | O11: =L11-I11 -> 0 | P11: =N11-K11 -> -4.1145992 | Q11: =N11/K11 -> 0.95336788 | S11: 0.33333333 | T11: 0.46736111 | U11: =IF(S11=TIME(17,0,0),"",(S11-T10)*24*60) -> 29 | V11: =(T11-S11)*24*60 -> 193 | W11: =T11 -> 0.46736111 | X11: =S12 -> 0.54861111 | AE11: =M11-J11 -> -69.948187 | AF11: =M11/J11 -> 0.95336788
A12: 新豐2線 | B12: 沙拉 | C12: 青檸烤雞握沙拉(113年) | E12: 39.8 | F12: 3430 | G12: =E12*F12 -> 136514 | I12: 17 | J12: 1500 | K12: =J12/I12 -> 88.235294 | L12: 17 | M12: =F12/V12*60 -> 1429.1667 | N12: =M12/L12 -> 84.068627 | O12: =L12-I12 -> 0 | P12: =N12-K12 -> -4.1666667 | Q12: =N12/K12 -> 0.95277778 | S12: 0.54861111 | T12: 0.64861111 | U12: =IF(S12=TIME(17,0,0),"",(S12-T11)*24*60) -> 117 | V12: =(T12-S12)*24*60 -> 144 | AE12: =M12-J12 -> -70.833333 | AF12: =M12/J12 -> 0.95277778
A13: 新豐2線 | B13: 平均 | I13: 17.666667 | J13: 1500 | K13: =J13/I13 -> 84.90566 | L13: 17.666667 | M13: =AVERAGE(M10:M12) -> 1430.324 | N13: =M13/L13 -> 80.961737 | O13: =L13-I13 -> 0 | P13: =N13-K13 -> -3.9439239 | Q13: =N13/K13 -> 0.95354934 | Y13: =SUM(Y10:Y12) -> 0 | Z13: =SUM(Z10:Z12) -> 0 | AC13: 3 | AD13: =SUM(AD10:AD12) -> 0 | AE13: =M13-J13 -> -69.675988 | AF13: =M13/J13 -> 0.95354934
A14: 新豐5線 | B14: 季節調理麵 | C14: 台式麻醬涼麵(115年) | E14: 31.11 | F14: 2096 | G14: =E14*F14 -> 65206.56 | I14: 14 | J14: 2000 | K14: =J14/I14 -> 142.85714 | L14: 14 | M14: =F14/V14*60 -> 1905.4545 | N14: =M14/L14 -> 136.1039 | O14: =L14-I14 -> 0 | P14: =N14-K14 -> -6.7532468 | Q14: =N14/K14 -> 0.95272727 | R14: =Q20 -> 0.9576554 | S14: 0.25 | T14: 0.29583333 | V14: =(T14-S14)*24*60 -> 66 | AC14: 6 | AE14: =M14-J14 -> -94.545455 | AF14: =M14/J14 -> 0.95272727 | AG14: =AF20 -> 0.9576554
A15: 新豐5線 | B15: 小吃 | C15: 剝皮辣椒雞湯 | E15: 41 | F15: 1747 | G15: =E15*F15 -> 71627 | I15: 26 | J15: 1500 | K15: =J15/I15 -> 57.692308 | L15: 26 | M15: =F15/V15*60 -> 1435.8904 | N15: =M15/L15 -> 55.226554 | O15: =L15-I15 -> 0 | P15: =N15-K15 -> -2.4657534 | Q15: =N15/K15 -> 0.95726027 | S15: 0.30138889 | T15: 0.35208333 | U15: =IF(S15=TIME(17,0,0),"",(S15-T14)*24*60) -> 8 | V15: =(T15-S15)*24*60 -> 73 | AE15: =M15-J15 -> -64.109589 | AF15: =M15/J15 -> 0.95726027
A16: 新豐5線 | B16: 沙拉 | C16: 厚蛋時蔬握沙拉 | E16: 39.46 | F16: 2370 | G16: =E16*F16 -> 93520.2 | I16: 15 | J16: 1500 | K16: =J16/I16 -> 100 | L16: 15 | M16: =F16/V16*60 -> 1436.3636 | N16: =M16/L16 -> 95.757576 | O16: =L16-I16 -> 0 | P16: =N16-K16 -> -4.2424242 | Q16: =N16/K16 -> 0.95757576 | S16: 0.35625 | T16: 0.425 | U16: =IF(S16=TIME(17,0,0),"",(S16-T15)*24*60) -> 6 | V16: =(T16-S16)*24*60 -> 99 | AE16: =M16-J16 -> -63.636364 | AF16: =M16/J16 -> 0.95757576
A17: 新豐5線 | B17: 微波主食 | C17: 二配玉米濃湯焗烤飯 | E17: 54.5 | F17: 872 | G17: =E17*F17 -> 47524 | I17: 19 | J17: 1500 | K17: =J17/I17 -> 78.947368 | L17: 19 | M17: =F17/V17*60 -> 1453.3333 | N17: =M17/L17 -> 76.491228 | O17: =L17-I17 -> 0 | P17: =N17-K17 -> -2.4561404 | Q17: =N17/K17 -> 0.96888889 | S17: 0.70833333 | T17: 0.73333333 | U17: =IF(S17=TIME(17,0,0),"",(S17-T16)*24*60) | V17: =(T17-S17)*24*60 -> 36 | AE17: =M17-J17 -> -46.666667 | AF17: =M17/J17 -> 0.96888889
A18: 新豐5線 | B18: 微波主食 | C18: 二配泰式綠咖哩雞 | E18: 50.67 | F18: 2269 | G18: =E18*F18 -> 114970.23 | I18: 15 | J18: 2000 | K18: =J18/I18 -> 133.33333 | L18: 15 | M18: =F18/V18*60 -> 1917.4648 | N18: =M18/L18 -> 127.83099 | O18: =L18-I18 -> 0 | P18: =N18-K18 -> -5.5023474 | Q18: =N18/K18 -> 0.95873239 | S18: 0.73680556 | T18: 0.78611111 | U18: =IF(S18=TIME(17,0,0),"",(S18-T17)*24*60) -> 5 | V18: =(T18-S18)*24*60 -> 71 | AE18: =M18-J18 -> -82.535211 | AF18: =M18/J18 -> 0.95873239
A19: 新豐5線 | B19: 微波主食 | C19: 二配打拋風味豬肉飯 | E19: 51.06 | F19: 3051 | G19: =E19*F19 -> 155784.06 | I19: 13 | J19: 2000 | K19: =J19/I19 -> 153.84615 | L19: 13 | M19: =F19/V19*60 -> 1906.875 | N19: =M19/L19 -> 146.68269 | O19: =L19-I19 -> 0 | P19: =N19-K19 -> -7.1634615 | Q19: =N19/K19 -> 0.9534375 | S19: 0.79027778 | T19: 0.85694444 | U19: =IF(S19=TIME(17,0,0),"",(S19-T18)*24*60) -> 6 | V19: =(T19-S19)*24*60 -> 96 | AE19: =M19-J19 -> -93.125 | AF19: =M19/J19 -> 0.9534375
A20: 新豐5線 | B20: 平均 | I20: 17 | J20: 1750 | K20: =J20/I20 -> 102.94118 | L20: 17 | M20: =AVERAGE(M14:M19) -> 1675.897 | N20: =M20/L20 -> 98.582174 | O20: =L20-I20 -> 0 | P20: =N20-K20 -> -4.3590028 | Q20: =N20/K20 -> 0.9576554 | Y20: =SUM(Y14:Y19) -> 0 | Z20: =SUM(Z14:Z19) -> 0 | AC20: 6 | AD20: =SUM(AD14:AD19) -> 0 | AE20: =M20-J20 -> -74.103048 | AF20: =M20/J20 -> 0.9576554
A21: 新豐7線 | B21: 微波主食 | C21: 韓式泡菜豬肉豆腐丼飯 | E21: 50.67 | F21: 1788 | G21: =E21*F21 -> 90597.96 | I21: 17 | J21: 2000 | K21: =J21/I21 -> 117.64706 | L21: 17 | M21: =F21/V21*60 -> 1915.7143 | N21: =M21/L21 -> 112.68908 | O21: =L21-I21 -> 0 | P21: =N21-K21 -> -4.9579832 | Q21: =N21/K21 -> 0.95785714 | R21: =Q30 -> 0.9631424 | S21: 0.29166667 | T21: 0.33055556 | V21: =(T21-S21)*24*60 -> 56 | AC21: 9 | AE21: =M21-J21 -> -84.285714 | AF21: =M21/J21 -> 0.95785714 | AG21: =AF30 -> 0.9631424
A22: 新豐7線 | B22: 微波主食 | C22: 鐵板滑蛋炸豬排丼 | E22: 57.73 | F22: 2987 | G22: =E22*F22 -> 172439.51 | I22: 14 | J22: 2000 | K22: =J22/I22 -> 142.85714 | L22: 14 | M22: =F22/V22*60 -> 1906.5957 | N22: =M22/L22 -> 136.18541 | O22: =L22-I22 -> 0 | P22: =N22-K22 -> -6.6717325 | Q22: =N22/K22 -> 0.95329787 | S22: 0.33611111 | T22: 0.40138889 | U22: =IF(S22=TIME(17,0,0),"",(S22-T21)*24*60) -> 8 | V22: =(T22-S22)*24*60 -> 94 | AE22: =M22-J22 -> -93.404255 | AF22: =M22/J22 -> 0.95329787
A23: 新豐7線 | B23: 微波主食 | C23: 日式炙烤親子丼 | E23: 53.27 | F23: 1584 | G23: =E23*F23 -> 84379.68 | I23: 16 | J23: 2000 | K23: =J23/I23 -> 125 | L23: 16 | M23: =F23/V23*60 -> 1939.5918 | N23: =M23/L23 -> 121.22449 | O23: =L23-I23 -> 0 | P23: =N23-K23 -> -3.7755102 | Q23: =N23/K23 -> 0.96979592 | S23: 0.40555556 | T23: 0.43958333 | U23: =IF(S23=TIME(17,0,0),"",(S23-T22)*24*60) -> 6 | V23: =(T23-S23)*24*60 -> 49 | AE23: =M23-J23 -> -60.408163 | AF23: =M23/J23 -> 0.96979592
A24: 新豐7線 | B24: 微波主食 | C24: 熊本麥味噌炸豬排丼飯 | E24: 57.3 | F24: 1100 | G24: =E24*F24 -> 63030 | H24: 2 | I24: 16 | J24: 2000 | K24: =J24/I24 -> 125 | L24: 16 | M24: =F24/V24*60 -> 1941.1765 | N24: =M24/L24 -> 121.32353 | O24: =L24-I24 -> 0 | P24: =N24-K24 -> -3.6764706 | Q24: =N24/K24 -> 0.97058824 | S24: 0.44513889 | T24: 0.46875 | U24: =IF(S24=TIME(17,0,0),"",(S24-T23)*24*60) -> 8 | V24: =(T24-S24)*24*60 -> 34 | W24: =T24 -> 0.46875 | X24: =S25 -> 0.55277778 | AE24: =M24-J24 -> -58.823529 | AF24: =M24/J24 -> 0.97058824
A25: 新豐7線 | B25: 微波主食 | C25: 熊本麥味噌炸豬排丼飯 | E25: 57.3 | F25: 2658 | G25: =E25*F25 -> 152303.4 | I25: 16 | J25: 2000 | K25: =J25/I25 -> 125 | L25: 16 | M25: =F25/V25*60 -> 1921.4458 | N25: =M25/L25 -> 120.09036 | O25: =L25-I25 -> 0 | P25: =N25-K25 -> -4.9096386 | Q25: =N25/K25 -> 0.96072289 | S25: 0.55277778 | T25: 0.61041667 | U25: =IF(S25=TIME(17,0,0),"",(S25-T24)*24*60) -> 121 | V25: =(T25-S25)*24*60 -> 83 | AE25: =M25-J25 -> -78.554217 | AF25: =M25/J25 -> 0.96072289
A26: 新豐7線 | B26: 微波主食 | C26: 二配川味麻婆燒豆腐燴飯 | E26: 50.49 | F26: 2487 | G26: =E26*F26 -> 125568.63 | I26: 15 | J26: 2000 | K26: =J26/I26 -> 133.33333 | L26: 15 | M26: =F26/V26*60 -> 1913.0769 | N26: =M26/L26 -> 127.53846 | O26: =L26-I26 -> 0 | P26: =N26-K26 -> -5.7948718 | Q26: =N26/K26 -> 0.95653846 | S26: 0.70833333 | T26: 0.7625 | U26: =IF(S26=TIME(17,0,0),"",(S26-T25)*24*60) | V26: =(T26-S26)*24*60 -> 78 | AE26: =M26-J26 -> -86.923077 | AF26: =M26/J26 -> 0.95653846
A27: 新豐7線 | B27: 微波主食 | C27: 二配美味蟹煲 | E27: 54.09 | F27: 2214 | G27: =E27*F27 -> 119755.26 | I27: 18 | J27: 2000 | K27: =J27/I27 -> 111.11111 | L27: 18 | M27: =F27/V27*60 -> 1925.2174 | N27: =M27/L27 -> 106.95652 | O27: =L27-I27 -> 0 | P27: =N27-K27 -> -4.1545894 | Q27: =N27/K27 -> 0.9626087 | S27: 0.76666667 | T27: 0.81458333 | U27: =IF(S27=TIME(17,0,0),"",(S27-T26)*24*60) -> 6 | V27: =(T27-S27)*24*60 -> 69 | AE27: =M27-J27 -> -74.782609 | AF27: =M27/J27 -> 0.9626087
A28: 新豐7線 | B28: 微波主食 | C28: 二配港式滑蛋牛肉燴飯 | E28: 50.67 | F28: 1000 | G28: =E28*F28 -> 50670 | H28: 2 | I28: 16 | J28: 2000 | K28: =J28/I28 -> 125 | L28: 16 | M28: =F28/V28*60 -> 1935.4839 | N28: =M28/L28 -> 120.96774 | O28: =L28-I28 -> 0 | P28: =N28-K28 -> -4.0322581 | Q28: =N28/K28 -> 0.96774194 | S28: 0.81944444 | T28: 0.84097222 | U28: =IF(S28=TIME(17,0,0),"",(S28-T27)*24*60) -> 7 | V28: =(T28-S28)*24*60 -> 31 | AE28: =M28-J28 -> -64.516129 | AF28: =M28/J28 -> 0.96774194
A29: 新豐7線 | B29: 微波主食 | C29: 二配港式滑蛋牛肉燴飯 | E29: 50.67 | F29: 1486 | G29: =E29*F29 -> 75295.62 | I29: 16 | J29: 2000 | K29: =J29/I29 -> 125 | L29: 16 | M29: =F29/V29*60 -> 1938.2609 | N29: =M29/L29 -> 121.1413 | O29: =L29-I29 -> 0 | P29: =N29-K29 -> -3.8586957 | Q29: =N29/K29 -> 0.96913043 | S29: 0.88194444 | T29: 0.91388889 | U29: =IF(S29=TIME(17,0,0),"",(S29-T28)*24*60) -> 59 | V29: =(T29-S29)*24*60 -> 46 | AE29: =M29-J29 -> -61.73913 | AF29: =M29/J29 -> 0.96913043
A30: 新豐7線 | B30: 平均 | I30: 16 | J30: 2000 | K30: =J30/I30 -> 125 | L30: 16 | M30: =AVERAGE(M21:M29) -> 1926.2848 | N30: =M30/L30 -> 120.3928 | O30: =L30-I30 -> 0 | P30: =N30-K30 -> -4.6072002 | Q30: =N30/K30 -> 0.9631424 | Y30: =SUM(Y21:Y29) -> 0 | Z30: =SUM(Z21:Z29) -> 0 | AC30: 9 | AD30: =SUM(AD21:AD29) -> 0 | AE30: =M30-J30 -> -73.715203 | AF30: =M30/J30 -> 0.9631424
A31: 新豐8線 | B31: 三明治 | C31: 紐奧良風味烤雞鮮蔬三明治 | E31: 31.29 | F31: 6500 | G31: =E31*F31 -> 203385 | H31: 2 | I31: 18 | J31: 2400 | K31: =J31/I31 -> 133.33333 | L31: 18 | M31: =F31/V31*60 -> 2294.1176 | N31: =M31/L31 -> 127.45098 | O31: =L31-I31 -> 0 | P31: =N31-K31 -> -5.8823529 | Q31: =N31/K31 -> 0.95588235 | R31: =Q40 -> 0.95773225 | S31: 0.083333333 | T31: 0.20138889 | V31: =(T31-S31)*24*60 -> 170 | W31: =T31 -> 0.20138889 | X31: =S32 -> 0.22291667 | AC31: 9 | AE31: =M31-J31 -> -105.88235 | AF31: =M31/J31 -> 0.95588235 | AG31: =AF40 -> 0.95773225
A32: 新豐8線 | B32: 三明治 | C32: 醬燒烤雞三明治(115年) | E32: 26.37 | F32: 4700 | G32: =E32*F32 -> 123939 | H32: 2 | I32: 18 | J32: 2400 | K32: =J32/I32 -> 133.33333 | L32: 18 | M32: =F32/V32*60 -> 2292.6829 | N32: =M32/L32 -> 127.37127 | O32: =L32-I32 -> 0 | P32: =N32-K32 -> -5.9620596 | Q32: =N32/K32 -> 0.95528455 | S32: 0.22291667 | T32: 0.30833333 | U32: =(S32-T31)*24*60 -> 31 | V32: =(T32-S32)*24*60 -> 123 | AE32: =M32-J32 -> -107.31707 | AF32: =M32/J32 -> 0.95528455
A33: 新豐8線 | B33: 三明治 | C33: 水果聖代三明治 | E33: 28.29 | F33: 2592 | G33: =E33*F33 -> 73327.68 | I33: 19 | J33: 2400 | K33: =J33/I33 -> 126.31579 | L33: 19 | M33: =F33/V33*60 -> 2287.0588 | N33: =M33/L33 -> 120.37152 | O33: =L33-I33 -> 0 | P33: =N33-K33 -> -5.9442724 | Q33: =N33/K33 -> 0.95294118 | S33: 0.31180556 | T33: 0.35902778 | U33: =(S33-T32)*24*60 -> 5 | V33: =(T33-S33)*24*60 -> 68 | AE33: =M33-J33 -> -112.94118 | AF33: =M33/J33 -> 0.95294118
A34: 新豐8線 | B34: 三明治 | C34: 好多菜三明治 | E34: 25.98 | F34: 4429 | G34: =E34*F34 -> 115065.42 | I34: 19 | J34: 2400 | K34: =J34/I34 -> 126.31579 | L34: 19 | M34: =F34/V34*60 -> 2290.8621 | N34: =M34/L34 -> 120.57169 | O34: =L34-I34 -> 0 | P34: =N34-K34 -> -5.7441016 | Q34: =N34/K34 -> 0.95452586 | S34: 0.36388889 | T34: 0.44444444 | U34: =(S34-T33)*24*60 -> 7 | V34: =(T34-S34)*24*60 -> 116 | AE34: =M34-J34 -> -109.13793 | AF34: =M34/J34 -> 0.95452586
A35: 新豐8線 | B35: 三明治 | C35: 茄汁厚起司三明治 | E35: 25.99 | F35: 1783 | G35: =E35*F35 -> 46340.17 | I35: 18 | J35: 2400 | K35: =J35/I35 -> 133.33333 | L35: 18 | M35: =F35/V35*60 -> 2325.6522 | N35: =M35/L35 -> 129.2029 | O35: =L35-I35 -> 0 | P35: =N35-K35 -> -4.1304348 | Q35: =N35/K35 -> 0.96902174 | S35: 0.44861111 | T35: 0.48055556 | U35: =(S35-T34)*24*60 -> 6 | V35: =(T35-S35)*24*60 -> 46 | AE35: =M35-J35 -> -74.347826 | AF35: =M35/J35 -> 0.96902174
A36: 新豐8線 | B36: 三明治 | C36: 起司芋見肉鬆三明治 | E36: 25.98 | F36: 1921 | G36: =E36*F36 -> 49907.58 | I36: 17 | J36: 2400 | K36: =J36/I36 -> 141.17647 | L36: 17 | M36: =F36/V36*60 -> 2305.2 | N36: =M36/L36 -> 135.6 | O36: =L36-I36 -> 0 | P36: =N36-K36 -> -5.5764706 | Q36: =N36/K36 -> 0.9605 | S36: 0.48611111 | T36: 0.52083333 | U36: =(S36-T35)*24*60 -> 8 | V36: =(T36-S36)*24*60 -> 50 | AE36: =M36-J36 -> -94.8 | AF36: =M36/J36 -> 0.9605
A37: 新豐8線 | B37: 三明治 | C37: 經典火腿玉米蛋三明治 | E37: 24.43 | F37: 5678 | G37: =E37*F37 -> 138713.54 | I37: 14 | J37: 2400 | K37: =J37/I37 -> 171.42857 | L37: 14 | M37: =F37/V37*60 -> 2286.443 | N37: =M37/L37 -> 163.31735 | O37: =L37-I37 -> 0 | P37: =N37-K37 -> -8.1112176 | Q37: =N37/K37 -> 0.95268456 | S37: 0.52638889 | T37: 0.62986111 | U37: =(S37-T36)*24*60 -> 8 | V37: =(T37-S37)*24*60 -> 149 | AE37: =M37-J37 -> -113.55705 | AF37: =M37/J37 -> 0.95268456
A38: 新豐8線 | B38: 三明治 | C38: 醬燒烤雞三明治(115年) | E38: 26.37 | F38: 3229 | G38: =E38*F38 -> 85148.73 | I38: 18 | J38: 2400 | K38: =J38/I38 -> 133.33333 | L38: 18 | M38: =F38/V38*60 -> 2306.4286 | N38: =M38/L38 -> 128.13492 | O38: =L38-I38 -> 0 | P38: =N38-K38 -> -5.1984127 | Q38: =N38/K38 -> 0.9610119 | S38: 0.63333333 | T38: 0.69166667 | U38: =(S38-T37)*24*60 -> 5 | V38: =(T38-S38)*24*60 -> 84 | AE38: =M38-J38 -> -93.571429 | AF38: =M38/J38 -> 0.9610119
A39: 新豐8線 | B39: 三明治 | C39: 紐奧良風味烤雞鮮蔬三明治 | E39: 31.29 | F39: 4827 | G39: =E39*F39 -> 151036.83 | I39: 18 | J39: 2400 | K39: =J39/I39 -> 133.33333 | L39: 18 | M39: =F39/V39*60 -> 2298.5714 | N39: =M39/L39 -> 127.69841 | O39: =L39-I39 -> 0 | P39: =N39-K39 -> -5.6349206 | Q39: =N39/K39 -> 0.9577381 | S39: 0.69652778 | T39: 0.78402778 | U39: =(S39-T38)*24*60 -> 7 | V39: =(T39-S39)*24*60 -> 126 | AE39: =M39-J39 -> -101.42857 | AF39: =M39/J39 -> 0.9577381
A40: 新豐8線 | B40: 平均 | I40: 17.666667 | J40: 2400 | K40: =J40/I40 -> 135.84906 | L40: 17.666667 | M40: =AVERAGE(M31:M39) -> 2298.5574 | N40: =M40/L40 -> 130.10702 | O40: =L40-I40 -> 0 | P40: =N40-K40 -> -5.742034 | Q40: =N40/K40 -> 0.95773225 | Y40: =SUM(Y31:Y39) -> 0 | Z40: =SUM(Z31:Z39) -> 0 | AC40: 9 | AD40: =SUM(AD31:AD39) -> 0 | AE40: =M40-J40 -> -101.4426 | AF40: =M40/J40 -> 0.95773225
...

Sheet 1003
B1: 屏榮 新豐廠組合室生產人時性分析
B3: 日期 | C3: =TEXT('1003 4度C'!A2,"yyyy.mm.ddaaaa") -> 2026.10.03星期六 | E3: 訂單量 | F3: ='1003 4度C'!D1 -> 143879 | H3: 營業額 | I3: ='1003 4度C'!F1 -> 4856868.4
B4: 人時性 | C4: 項目 | E4: ➀ | G4: ➁ | I4: ➂ | K4: 異常停線 | M4: 短暫停線
C5: 組合室 | E5: 全溫層 | G5: 4度C-各編組展開 | I5: ③三明治-各編組展開 | K5: 合計次數 | L5: 時間 | M5: 合計次數 | N5: 設備次數
C6: 排關平均 | E6: =AVERAGE(D13:M13) -> 151.08626 | F6: =AVERAGE(D31:O31,D13:J13) -> 155.69986 | G6: =AVERAGE(D13:J13) -> 155.69986 | I6: =AVERAGE(K13:M13) -> 140.32119 | K6: ='1003 4度C'!Y2 -> 0 | L6: ='1003 4度C'!Z2 -> 0 | M6: ='1003 4度C'!AC2 -> 54 | N6: ='1003 4度C'!AD2 -> 0
C7: 實績平均 | E7: =AVERAGE(D14:M14) -> 145.00115 | F7: =AVERAGE(D32:O32,D14:J14) -> 149.51933 | G7: =AVERAGE(D14:J14) -> 149.51933 | I7: =AVERAGE(K14:M14) -> 134.45874
C8: 達成率平均 | E8: =AVERAGE(D15:M15) -> 0.95961218 | F8: =AVERAGE(D15:J15,D33:O33) -> 0.96024165 | G8: =AVERAGE(D15:J15) -> 0.96024165 | I8: =AVERAGE(K15:M15) -> 0.95814341
K9: ※現行日本鮮食廠以達成率80%為基本(即為現行KPI)
B10: 溫層 | D10: ➁4度C-各編組展開 | K10: ③三明治-各編組展開
B11: 編組 | D11: 1 | E11: 2 | F11: 3 | G11: 4 | H11: 5 | I11: 6 | J11: 7 | K11: 1 | L11: 2 | M11: 3
D12: 新豐6線 | E12: 新豐2線 | F12: 新豐5線 | G12: 新豐7線 | H12: 新豐3線 | I12: 新豐1線 | J12: 新豐10線 | K12: 新豐8線 | L12: 新豐9線 | M12: 新豐4線
B13: 人時性 | C13: 排關 | D13: =SUMIFS('1003 4度C'!$K:$K,'1003 4度C'!$A:$A,"新豐6線",'1003 4度C'!$B:$B,"平均") -> 130.43478 | E13: =SUMIFS('1003 4度C'!$K:$K,'1003 4度C'!$A:$A,"新豐2線",'1003 4度C'!$B:$B,"平均") -> 83.333333 | F13: =SUMIFS('1003 4度C'!$K:$K,'1003 4度C'!$A:$A,"新豐5線",'1003 4度C'!$B:$B,"平均") -> 105 | G13: =SUMIFS('1003 4度C'!$K:$K,'1003 4度C'!$A:$A,"新豐7線",'1003 4度C'!$B:$B,"平均") -> 125 | H13: =SUMIFS('1003 4度C'!$K:$K,'1003 4度C'!$A:$A,"新豐3線",'1003 4度C'!$B:$B,"平均") -> 242.42424 | I13: =SUMIFS('1003 4度C'!$K:$K,'1003 4度C'!$A:$A,"新豐1線",'1003 4度C'!$B:$B,"平均") -> 109.58904 | J13: =SUMIFS('1003 4度C'!$K:$K,'1003 4度C'!$A:$A,"新豐10線",'1003 4度C'!$B:$B,"平均") -> 294.11765 | K13: =SUMIFS('1003 4度C'!$K:$K,'1003 4度C'!$A:$A,"新豐8線",'1003 4度C'!$B:$B,"平均") -> 138.84298 | L13: =SUMIFS('1003 4度C'!$K:$K,'1003 4度C'!$A:$A,"新豐9線",'1003 4度C'!$B:$B,"平均") -> 130.76923 | M13: =SUMIFS('1003 4度C'!$K:$K,'1003 4度C'!$A:$A,"新豐4線",'1003 4度C'!$B:$B,"平均") -> 151.35135
C14: 實績 | D14: =SUMIFS('1003 4度C'!$N:$N,'1003 4度C'!$A:$A,"新豐6線",'1003 4度C'!$B:$B,"平均") -> 124.91531 | E14: =SUMIFS('1003 4度C'!$N:$N,'1003 4度C'!$A:$A,"新豐2線",'1003 4度C'!$B:$B,"平均") -> 79.419138 | F14: =SUMIFS('1003 4度C'!$N:$N,'1003 4度C'!$A:$A,"新豐5線",'1003 4度C'!$B:$B,"平均") -> 101.38425 | G14: =SUMIFS('1003 4度C'!$N:$N,'1003 4度C'!$A:$A,"新豐7線",'1003 4度C'!$B:$B,"平均") -> 120.14584 | H14: =SUMIFS('1003 4度C'!$N:$N,'1003 4度C'!$A:$A,"新豐3線",'1003 4度C'!$B:$B,"平均") -> 231.59501 | I14: =SUMIFS('1003 4度C'!$N:$N,'1003 4度C'!$A:$A,"新豐1線",'1003 4度C'!$B:$B,"平均") -> 105.8026 | J14: =SUMIFS('1003 4度C'!$N:$N,'1003 4度C'!$A:$A,"新豐10線",'1003 4度C'!$B:$B,"平均") -> 283.37316 | K14: =SUMIFS('1003 4度C'!$N:$N,'1003 4度C'!$A:$A,"新豐8線",'1003 4度C'!$B:$B,"平均") -> 133.37622 | L14: =SUMIFS('1003 4度C'!$N:$N,'1003 4度C'!$A:$A,"新豐9線",'1003 4度C'!$B:$B,"平均") -> 124.89014 | M14: =SUMIFS('1003 4度C'!$N:$N,'1003 4度C'!$A:$A,"新豐4線",'1003 4度C'!$B:$B,"平均") -> 145.10986
C15: 達成率 | D15: =D14/D13 -> 0.95768407 | E15: =E14/E13 -> 0.95302965 | F15: =F14/F13 -> 0.96556428 | G15: =G14/G13 -> 0.96116669 | H15: =H14/H13 -> 0.9553294 | I15: =I14/I13 -> 0.96544873 | J15: =J14/J13 -> 0.96346875 | K15: =K14/K13 -> 0.96062636 | ... M15: =M14/M13 -> 0.95876158
B16: 作業 時間 | C16: 開始 | D16: =VLOOKUP("新豐6線",'1003 4度C'!$A:$T,19,0) -> 0.70833333 | E16: =VLOOKUP("新豐2線",'1003 4度C'!$A:$T,19,0) -> 0.083333333 | F16: =VLOOKUP("新豐5線",'1003 4度C'!$A:$T,19,0) -> 0.25 | G16: =VLOOKUP("新豐7線",'1003 4度C'!$A:$T,19,0) -> 0.25 | H16: =VLOOKUP("新豐3線",'1003 4度C'!$A:$T,19,0) -> 0.20833333 | I16: =VLOOKUP("新豐1線",'1003 4度C'!$A:$T,19,0) -> 0.20833333 | J16: =VLOOKUP("新豐10線",'1003 4度C'!$A:$T,19,0) -> 0.20833333 | K16: =VLOOKUP("新豐8線",'1003 4度C'!$A:$T,19,0) -> 0.083333333 | L16: =VLOOKUP("新豐9線",'1003 4度C'!$A:$T,19,0) -> 0.083333333 | M16: =VLOOKUP("新豐4線",'1003 4度C'!$A:$T,19,0) -> 0.083333333
C17: 結束 | D17: =LOOKUP(2,1/(('1003 4度C'!$A:$A="新豐6線")*('1003 4度C'!$T:$T<>"")),'1003 4度C'!$T:$T) -> 0.84861111 | E17: =LOOKUP(2,1/(('1003 4度C'!$A:$A="新豐2線")*('1003 4度C'!$T:$T<>"")),'1003 4度C'!$T:$T) -> 0.39375 | F17: =LOOKUP(2,1/(('1003 4度C'!$A:$A="新豐5線")*('1003 4度C'!$T:$T<>"")),'1003 4度C'!$T:$T) -> 0.81666667 | G17: =LOOKUP(2,1/(('1003 4度C'!$A:$A="新豐7線")*('1003 4度C'!$T:$T<>"")),'1003 4度C'!$T:$T) -> 0.82152778 | H17: =LOOKUP(2,1/(('1003 4度C'!$A:$A="新豐3線")*('1003 4度C'!$T:$T<>"")),'1003 4度C'!$T:$T) -> 0.42430556 | I17: =LOOKUP(2,1/(('1003 4度C'!$A:$A="新豐1線")*('1003 4度C'!$T:$T<>"")),'1003 4度C'!$T:$T) -> 0.83333333 | J17: =LOOKUP(2,1/(('1003 4度C'!$A:$A="新豐10線")*('1003 4度C'!$T:$T<>"")),'1003 4度C'!$T:$T) -> 0.40138889 | K17: =LOOKUP(2,1/(('1003 4度C'!$A:$A="新豐8線")*('1003 4度C'!$T:$T<>"")),'1003 4度C'!$T:$T) -> 0.61458333 | L17: =LOOKUP(2,1/(('1003 4度C'!$A:$A="新豐9線")*('1003 4度C'!$T:$T<>"")),'1003 4度C'!$T:$T) -> 0.61041667 | M17: =LOOKUP(2,1/(('1003 4度C'!$A:$A="新豐4線")*('1003 4度C'!$T:$T<>"")),'1003 4度C'!$T:$T) -> 0.59722222
