Workbook

Sheet 0802
B1: 屏榮 新豐廠組合室生產人時性分析
B3: 日期 | C3: =TEXT('0802 4度C'!A2,"yyyy.mm.ddaaaa") -> 2026.08.02星期日 | E3: 訂單量 | F3: ='0802 4度C'!D1 -> 206437 | H3: 營業額 | I3: ='0802 4度C'!F1 -> 7189068.7
B4: 人時性 | C4: 項目 | E4: ➀ | G4: ➁ | I4: ➂ | K4: 異常停線 | M4: 短暫停線
C5: 組合室 | E5: 全溫層 | G5: 4度C-各編組展開 | I5: ③三明治-各編組展開 | K5: 合計次數 | L5: 時間 | M5: 合計次數 | N5: 設備次數
C6: 排關平均 | E6: =AVERAGE(D13:M13) -> 157.46137 | F6: =AVERAGE(D31:O31,D13:J13) -> 166.4876 | G6: =AVERAGE(D13:J13) -> 166.4876 | I6: =AVERAGE(K13:M13) -> 136.40017 | K6: ='0802 4度C'!Y2 -> 0 | L6: ='0802 4度C'!Z2 -> 0 | M6: ='0802 4度C'!AC2 -> 70 | N6: ='0802 4度C'!AD2 -> 0
C7: 實績平均 | E7: =AVERAGE(D14:M14) -> 150.89847 | F7: =AVERAGE(D32:O32,D14:J14) -> 159.63869 | G7: =AVERAGE(D14:J14) -> 159.63869 | I7: =AVERAGE(K14:M14) -> 130.50463
C8: 達成率平均 | E8: =AVERAGE(D15:M15) -> 0.9589047 | F8: =AVERAGE(D15:J15,D33:O33) -> 0.95982976 | G8: =AVERAGE(D15:J15) -> 0.95982976 | I8: =AVERAGE(K15:M15) -> 0.95674622
K9: ※現行日本鮮食廠以達成率80%為基本(即為現行KPI)
B10: 溫層 | D10: ➁4度C-各編組展開 | K10: ③三明治-各編組展開
B11: 編組 | D11: 1 | E11: 2 | F11: 3 | G11: 4 | H11: 5 | I11: 6 | J11: 7 | K11: 1 | L11: 2 | M11: 3
D12: 新豐6線 | E12: 新豐2線 | F12: 新豐5線 | G12: 新豐7線 | H12: 新豐3線 | I12: 新豐1線 | J12: 新豐10線 | K12: 新豐8線 | L12: 新豐9線 | M12: 新豐4線
B13: 人時性 | C13: 排關 | D13: =SUMIFS('0802 4度C'!$K:$K,'0802 4度C'!$A:$A,"新豐6線",'0802 4度C'!$B:$B,"平均") -> 129.87013 | E13: =SUMIFS('0802 4度C'!$K:$K,'0802 4度C'!$A:$A,"新豐2線",'0802 4度C'!$B:$B,"平均") -> 84.90566 | F13: =SUMIFS('0802 4度C'!$K:$K,'0802 4度C'!$A:$A,"新豐5線",'0802 4度C'!$B:$B,"平均") -> 93.023256 | G13: =SUMIFS('0802 4度C'!$K:$K,'0802 4度C'!$A:$A,"新豐7線",'0802 4度C'!$B:$B,"平均") -> 125 | H13: =SUMIFS('0802 4度C'!$K:$K,'0802 4度C'!$A:$A,"新豐3線",'0802 4度C'!$B:$B,"平均") -> 324.32432 | I13: =SUMIFS('0802 4度C'!$K:$K,'0802 4度C'!$A:$A,"新豐1線",'0802 4度C'!$B:$B,"平均") -> 115.60694 | J13: =SUMIFS('0802 4度C'!$K:$K,'0802 4度C'!$A:$A,"新豐10線",'0802 4度C'!$B:$B,"平均") -> 292.68293 | K13: =SUMIFS('0802 4度C'!$K:$K,'0802 4度C'!$A:$A,"新豐8線",'0802 4度C'!$B:$B,"平均") -> 144.96644 | L13: =SUMIFS('0802 4度C'!$K:$K,'0802 4度C'!$A:$A,"新豐9線",'0802 4度C'!$B:$B,"平均") -> 122.22222 | M13: =SUMIFS('0802 4度C'!$K:$K,'0802 4度C'!$A:$A,"新豐4線",'0802 4度C'!$B:$B,"平均") -> 142.01183
C14: 實績 | D14: =SUMIFS('0802 4度C'!$N:$N,'0802 4度C'!$A:$A,"新豐6線",'0802 4度C'!$B:$B,"平均") -> 125.4631 | E14: =SUMIFS('0802 4度C'!$N:$N,'0802 4度C'!$A:$A,"新豐2線",'0802 4度C'!$B:$B,"平均") -> 81.119657 | F14: =SUMIFS('0802 4度C'!$N:$N,'0802 4度C'!$A:$A,"新豐5線",'0802 4度C'!$B:$B,"平均") -> 89.254118 | G14: =SUMIFS('0802 4度C'!$N:$N,'0802 4度C'!$A:$A,"新豐7線",'0802 4度C'!$B:$B,"平均") -> 120.38702 | H14: =SUMIFS('0802 4度C'!$N:$N,'0802 4度C'!$A:$A,"新豐3線",'0802 4度C'!$B:$B,"平均") -> 309.24854 | I14: =SUMIFS('0802 4度C'!$N:$N,'0802 4度C'!$A:$A,"新豐1線",'0802 4度C'!$B:$B,"平均") -> 111.19321 | J14: =SUMIFS('0802 4度C'!$N:$N,'0802 4度C'!$A:$A,"新豐10線",'0802 4度C'!$B:$B,"平均") -> 280.80517 | K14: =SUMIFS('0802 4度C'!$N:$N,'0802 4度C'!$A:$A,"新豐8線",'0802 4度C'!$B:$B,"平均") -> 138.69663 | L14: =SUMIFS('0802 4度C'!$N:$N,'0802 4度C'!$A:$A,"新豐9線",'0802 4度C'!$B:$B,"平均") -> 116.85627 | M14: =SUMIFS('0802 4度C'!$N:$N,'0802 4度C'!$A:$A,"新豐4線",'0802 4度C'!$B:$B,"平均") -> 135.961
C15: 達成率 | D15: =D14/D13 -> 0.96606586 | E15: =E14/E13 -> 0.95540929 | F15: =F14/F13 -> 0.95948177 | G15: =G14/G13 -> 0.9630962 | H15: =H14/H13 -> 0.95351632 | I15: =I14/I13 -> 0.96182123 | J15: =J14/J13 -> 0.95941765 | K15: =K14/K13 -> 0.95674989 | ... M15: =M14/M13 -> 0.95739202
B16: 作業 時間 | C16: 開始 | D16: =VLOOKUP("新豐6線",'0802 4度C'!$A:$T,19,0) -> 0.70833333 | E16: =VLOOKUP("新豐2線",'0802 4度C'!$A:$T,19,0) -> 0.083333333 | F16: =VLOOKUP("新豐5線",'0802 4度C'!$A:$T,19,0) -> 0.083333333 | G16: =VLOOKUP("新豐7線",'0802 4度C'!$A:$T,19,0) -> 0.20833333 | H16: =VLOOKUP("新豐3線",'0802 4度C'!$A:$T,19,0) -> 0.20833333 | I16: =VLOOKUP("新豐1線",'0802 4度C'!$A:$T,19,0) -> 0.083333333 | J16: =VLOOKUP("新豐10線",'0802 4度C'!$A:$T,19,0) -> 0.20833333 | K16: =VLOOKUP("新豐8線",'0802 4度C'!$A:$T,19,0) -> 0.083333333 | L16: =VLOOKUP("新豐9線",'0802 4度C'!$A:$T,19,0) -> 0.083333333 | M16: =VLOOKUP("新豐4線",'0802 4度C'!$A:$T,19,0) -> 0.083333333
C17: 結束 | D17: =LOOKUP(2,1/(('0802 4度C'!$A:$A="新豐6線")*('0802 4度C'!$T:$T<>"")),'0802 4度C'!$T:$T) -> 0.91666667 | E17: =LOOKUP(2,1/(('0802 4度C'!$A:$A="新豐2線")*('0802 4度C'!$T:$T<>"")),'0802 4度C'!$T:$T) -> 0.68888889 | F17: =LOOKUP(2,1/(('0802 4度C'!$A:$A="新豐5線")*('0802 4度C'!$T:$T<>"")),'0802 4度C'!$T:$T) -> 0.85347222 | G17: =LOOKUP(2,1/(('0802 4度C'!$A:$A="新豐7線")*('0802 4度C'!$T:$T<>"")),'0802 4度C'!$T:$T) -> 0.90486111 | H17: =LOOKUP(2,1/(('0802 4度C'!$A:$A="新豐3線")*('0802 4度C'!$T:$T<>"")),'0802 4度C'!$T:$T) -> 0.44027778 | I17: =LOOKUP(2,1/(('0802 4度C'!$A:$A="新豐1線")*('0802 4度C'!$T:$T<>"")),'0802 4度C'!$T:$T) -> 0.92152778 | J17: =LOOKUP(2,1/(('0802 4度C'!$A:$A="新豐10線")*('0802 4度C'!$T:$T<>"")),'0802 4度C'!$T:$T) -> 0.45486111 | K17: =LOOKUP(2,1/(('0802 4度C'!$A:$A="新豐8線")*('0802 4度C'!$T:$T<>"")),'0802 4度C'!$T:$T) -> 0.76875 | L17: =LOOKUP(2,1/(('0802 4度C'!$A:$A="新豐9線")*('0802 4度C'!$T:$T<>"")),'0802 4度C'!$T:$T) -> 0.76458333 | M17: =LOOKUP(2,1/(('0802 4度C'!$A:$A="新豐4線")*('0802 4度C'!$T:$T<>"")),'0802 4度C'!$T:$T) -> 0.76180556
B18: 產線異常 (5分鐘以上) | C18: 次數 | D18: =SUMIFS('0802 4度C'!$Y:$Y,'0802 4度C'!$A:$A,"新豐6線",'0802 4度C'!$B:$B,"平均") -> 0 | E18: =SUMIFS('0802 4度C'!$Y:$Y,'0802 4度C'!$A:$A,"新豐2線",'0802 4度C'!$B:$B,"平均") -> 0 | F18: =SUMIFS('0802 4度C'!$Y:$Y,'0802 4度C'!$A:$A,"新豐5線",'0802 4度C'!$B:$B,"平均") -> 0 | G18: =SUMIFS('0802 4度C'!$Y:$Y,'0802 4度C'!$A:$A,"新豐7線",'0802 4度C'!$B:$B,"平均") -> 0 | H18: =SUMIFS('0802 4度C'!$Y:$Y,'0802 4度C'!$A:$A,"新豐3線",'0802 4度C'!$B:$B,"平均") -> 0 | I18: =SUMIFS('0802 4度C'!$Y:$Y,'0802 4度C'!$A:$A,"新豐1線",'0802 4度C'!$B:$B,"平均") -> 0 | J18: =SUMIFS('0802 4度C'!$Y:$Y,'0802 4度C'!$A:$A,"新豐10線",'0802 4度C'!$B:$B,"平均") -> 0 | K18: =SUMIFS('0802 4度C'!$Y:$Y,'0802 4度C'!$A:$A,"新豐8線",'0802 4度C'!$B:$B,"平均") -> 0 | L18: =SUMIFS('0802 4度C'!$Y:$Y,'0802 4度C'!$A:$A,"新豐9線",'0802 4度C'!$B:$B,"平均") -> 0 | M18: =SUMIFS('0802 4度C'!$Y:$Y,'0802 4度C'!$A:$A,"新豐4線",'0802 4度C'!$B:$B,"平均") -> 0
C19: 時間/分 | D19: =SUMIFS('0802 4度C'!$Z:$Z,'0802 4度C'!$A:$A,"新豐6線",'0802 4度C'!$B:$B,"平均") -> 0 | E19: =SUMIFS('0802 4度C'!$Z:$Z,'0802 4度C'!$A:$A,"新豐2線",'0802 4度C'!$B:$B,"平均") -> 0 | F19: =SUMIFS('0802 4度C'!$Z:$Z,'0802 4度C'!$A:$A,"新豐5線",'0802 4度C'!$B:$B,"平均") -> 0 | G19: =SUMIFS('0802 4度C'!$Z:$Z,'0802 4度C'!$A:$A,"新豐7線",'0802 4度C'!$B:$B,"平均") -> 0 | H19: =SUMIFS('0802 4度C'!$Z:$Z,'0802 4度C'!$A:$A,"新豐3線",'0802 4度C'!$B:$B,"平均") -> 0 | I19: =SUMIFS('0802 4度C'!$Z:$Z,'0802 4度C'!$A:$A,"新豐1線",'0802 4度C'!$B:$B,"平均") -> 0 | J19: =SUMIFS('0802 4度C'!$Z:$Z,'0802 4度C'!$A:$A,"新豐10線",'0802 4度C'!$B:$B,"平均") -> 0 | K19: =SUMIFS('0802 4度C'!$Z:$Z,'0802 4度C'!$A:$A,"新豐8線",'0802 4度C'!$B:$B,"平均") -> 0 | L19: =SUMIFS('0802 4度C'!$Z:$Z,'0802 4度C'!$A:$A,"新豐9線",'0802 4度C'!$B:$B,"平均") -> 0 | M19: =SUMIFS('0802 4度C'!$Z:$Z,'0802 4度C'!$A:$A,"新豐4線",'0802 4度C'!$B:$B,"平均") -> 0
B20: 短暫停線 (5分鐘以下) | C20: 次數 | D20: =SUMIFS('0802 4度C'!$AC:$AC,'0802 4度C'!$A:$A,"新豐6線",'0802 4度C'!$B:$B,"平均") -> 5 | E20: =SUMIFS('0802 4度C'!$AC:$AC,'0802 4度C'!$A:$A,"新豐2線",'0802 4度C'!$B:$B,"平均") -> 6 | F20: =SUMIFS('0802 4度C'!$AC:$AC,'0802 4度C'!$A:$A,"新豐5線",'0802 4度C'!$B:$B,"平均") -> 7 | G20: =SUMIFS('0802 4度C'!$AC:$AC,'0802 4度C'!$A:$A,"新豐7線",'0802 4度C'!$B:$B,"平均") -> 7 | H20: =SUMIFS('0802 4度C'!$AC:$AC,'0802 4度C'!$A:$A,"新豐3線",'0802 4度C'!$B:$B,"平均") -> 4 | I20: =SUMIFS('0802 4度C'!$AC:$AC,'0802 4度C'!$A:$A,"新豐1線",'0802 4度C'!$B:$B,"平均") -> 10 | J20: =SUMIFS('0802 4度C'!$AC:$AC,'0802 4度C'!$A:$A,"新豐10線",'0802 4度C'!$B:$B,"平均") -> 4 | K20: =SUMIFS('0802 4度C'!$AC:$AC,'0802 4度C'!$A:$A,"新豐8線",'0802 4度C'!$B:$B,"平均") -> 9 | L20: =SUMIFS('0802 4度C'!$AC:$AC,'0802 4度C'!$A:$A,"新豐9線",'0802 4度C'!$B:$B,"平均") -> 8 | M20: =SUMIFS('0802 4度C'!$AC:$AC,'0802 4度C'!$A:$A,"新豐4線",'0802 4度C'!$B:$B,"平均") -> 10
C21: 設備次數 | D21: =SUMIFS('0802 4度C'!$AD:$AD,'0802 4度C'!$A:$A,"新豐6線",'0802 4度C'!$B:$B,"平均") -> 0 | E21: =SUMIFS('0802 4度C'!$AD:$AD,'0802 4度C'!$A:$A,"新豐2線",'0802 4度C'!$B:$B,"平均") -> 0 | F21: =SUMIFS('0802 4度C'!$AD:$AD,'0802 4度C'!$A:$A,"新豐5線",'0802 4度C'!$B:$B,"平均") -> 0 | G21: =SUMIFS('0802 4度C'!$AD:$AD,'0802 4度C'!$A:$A,"新豐7線",'0802 4度C'!$B:$B,"平均") -> 0 | H21: =SUMIFS('0802 4度C'!$AD:$AD,'0802 4度C'!$A:$A,"新豐3線",'0802 4度C'!$B:$B,"平均") -> 0 | I21: =SUMIFS('0802 4度C'!$AD:$AD,'0802 4度C'!$A:$A,"新豐1線",'0802 4度C'!$B:$B,"平均") -> 0 | J21: =SUMIFS('0802 4度C'!$AD:$AD,'0802 4度C'!$A:$A,"新豐10線",'0802 4度C'!$B:$B,"平均") -> 0 | K21: =SUMIFS('0802 4度C'!$AD:$AD,'0802 4度C'!$A:$A,"新豐8線",'0802 4度C'!$B:$B,"平均") -> 0 | L21: =SUMIFS('0802 4度C'!$AD:$AD,'0802 4度C'!$A:$A,"新豐9線",'0802 4度C'!$B:$B,"平均") -> 0 | M21: =SUMIFS('0802 4度C'!$AD:$AD,'0802 4度C'!$A:$A,"新豐4線",'0802 4度C'!$B:$B,"平均") -> 0
B22: 配置人數 | D22: =SUMIFS('0802 4度C'!$I:$I,'0802 4度C'!$A:$A,"新豐6線",'0802 4度C'!$B:$B,"平均") -> 15.4 | E22: =SUMIFS('0802 4度C'!$I:$I,'0802 4度C'!$A:$A,"新豐2線",'0802 4度C'!$B:$B,"平均") -> 17.666667 | F22: =SUMIFS('0802 4度C'!$I:$I,'0802 4度C'!$A:$A,"新豐5線",'0802 4度C'!$B:$B,"平均") -> 18.428571 | G22: =SUMIFS('0802 4度C'!$I:$I,'0802 4度C'!$A:$A,"新豐7線",'0802 4度C'!$B:$B,"平均") -> 16 | H22: =SUMIFS('0802 4度C'!$I:$I,'0802 4度C'!$A:$A,"新豐3線",'0802 4度C'!$B:$B,"平均") -> 9.25 | I22: =SUMIFS('0802 4度C'!$I:$I,'0802 4度C'!$A:$A,"新豐1線",'0802 4度C'!$B:$B,"平均") -> 17.3 | J22: =SUMIFS('0802 4度C'!$I:$I,'0802 4度C'!$A:$A,"新豐10線",'0802 4度C'!$B:$B,"平均") -> 10.25 | K22: =SUMIFS('0802 4度C'!$I:$I,'0802 4度C'!$A:$A,"新豐8線",'0802 4度C'!$B:$B,"平均") -> 16.555556 | L22: =SUMIFS('0802 4度C'!$I:$I,'0802 4度C'!$A:$A,"新豐9線",'0802 4度C'!$B:$B,"平均") -> 18 | M22: =SUMIFS('0802 4度C'!$I:$I,'0802 4度C'!$A:$A,"新豐4線",'0802 4度C'!$B:$B,"平均") -> 16.9
B23: 主要應用設備 | D23: ET-55 | E23: 熱縮爐 | F23: L型包裝機 | G23: L型包裝機 | H23: 伺服包裝機 | I23: ET-55 | J23: 伺服包裝機 | K23: 三明治包裝機 | L23: 三明治包裝機 | M23: 三明治包裝機
B24: 次要應用設備 | F24: 圓盤機 | G24: ET-55
B25: 備註 | E25: 握沙拉 | F25: 共用L型包裝機 | H25: 調理麵包 | I25: 炒飯+沙拉 | J25: 調理麵包

Sheet 0802 4度C
A1: 新豐廠四度C日報分析 | C1: 總生產量 | D1: =SUM(F5:F84) -> 206437 | E1: 營業額 | F1: =SUM(G5:G84) -> 7189068.7 | G1: 出勤人數 | H1: =L10+L17+L57+L68+L25+L73+L43+L52+L33+L84 -> 155.75079 | I1: 產線配置圖 | L1: 生產實績 | O1: 人時性差異分析 | S1: 日報登錄 | Y1: 合計 次數 | Z1: 合計 時間/分 | AA1: 產線異常 分析說明(5分鐘以上) | AC1: 合計 次數 | AD1: 合計 設備次數 | AE1: 產能差異分析
A2: 46236 | B2: 星期日 | C2: 人時性 | D2: =AVERAGE(N10,N17,N57,N68,N25,N73,N33,N43,N52,N84) -> 150.89847 | E2: 平均廠價 | F2: =F1/D1 -> 34.824517 | G2: 多次生產數 | H2: =COUNT(H5:H84) -> 17 | Y2: =SUM(Y10+Y17+Y25+Y33+Y43+Y52+Y57+Y68+Y73+Y84) -> 0 | Z2: =SUM(Z10+Z17+Z25+Z33+Z43+Z52+Z57+Z68+Z73+Z84) -> 0 | AC2: =SUM(AC10+AC17+AC25+AC33+AC43+AC52+AC57+AC68+AC73+AC84) -> 70 | AD2: =SUM(AD10+AD17+AD25+AD33+AD43+AD52+AD57+AD68+AD73+AD84) -> 0
A3: 線別 | B3: 品類 | C3: 品名 | E3: 廠價 | F3: 生產量 | G3: 營收 | H3: 多次 生產 | I3: 人數 | J3: 產能/時 | K3: 人時性 | L3: 人數 | M3: 產能/時 | N3: 人時性 | O3: 人數 | P3: 人時性 | Q3: 達成率 | R3: 達成率平均 | S3: 生產時間 | U3: 換線、休息/分 | V3: 稼動時間/分 | W3: 休息時間 | Y3: 產線異常統計 (5分鐘以上) | AA3: (新豐回填) | AC3: 短暫停線統計 (5分鐘以下) | AE3: 產能/時 | AF3: 達成率 | AG3: 達成率平均
S4: 開始 | T4: 結束 | W4: 開始 | X4: 結束 | Y4: 次數 | Z4: 時間/分 | AC4: 總次數 | AD4: 設備因素(次數)
A5: 新豐6線 | B5: 微波主食 | C5: 二配金咖哩果香甘口咖哩飯 | E5: 50.92 | F5: 1200 | G5: =E5*F5 -> 61104 | H5: 2 | I5: 15 | J5: 2000 | K5: =J5/I5 -> 133.33333 | L5: 15 | M5: =F5/V5*60 -> 1945.9459 | N5: =M5/L5 -> 129.72973 | O5: =L5-I5 -> 0 | P5: =N5-K5 -> -3.6036036 | Q5: =N5/K5 -> 0.97297297 | R5: =Q10 -> 0.96606586 | S5: 0.70833333 | T5: 0.73402778 | V5: =(T5-S5)*24*60 -> 37 | AC5: 5 | AE5: =M5-J5 -> -54.054054 | AF5: =M5/J5 -> 0.97297297 | AG5: =AF10 -> 0.96606586
A6: 新豐6線 | B6: 微波主食 | C6: 二配金咖哩濃厚辛口咖哩飯 | E6: 50.98 | F6: 1200 | G6: =E6*F6 -> 61176 | H6: 2 | I6: 16 | J6: 2000 | K6: =J6/I6 -> 125 | L6: 16 | M6: =F6/V6*60 -> 1945.9459 | N6: =M6/L6 -> 121.62162 | O6: =L6-I6 -> 0 | P6: =N6-K6 -> -3.3783784 | Q6: =N6/K6 -> 0.97297297 | S6: 0.73819444 | T6: 0.76388889 | U6: =IF(S6=TIME(17,0,0),"",(S6-T5)*24*60) -> 6 | V6: =(T6-S6)*24*60 -> 37 | AE6: =M6-J6 -> -54.054054 | AF6: =M6/J6 -> 0.97297297
A7: 新豐6線 | B7: 微波主食 | C7: 二配川味麻婆燒豆腐燴飯 | E7: 50.49 | F7: 2140 | G7: =E7*F7 -> 108048.6 | I7: 15 | J7: 2000 | K7: =J7/I7 -> 133.33333 | L7: 15 | M7: =F7/V7*60 -> 1916.4179 | N7: =M7/L7 -> 127.76119 | O7: =L7-I7 -> 0 | P7: =N7-K7 -> -5.5721393 | Q7: =N7/K7 -> 0.95820896 | S7: 0.76736111 | T7: 0.81388889 | U7: =IF(S7=TIME(17,0,0),"",(S7-T6)*24*60) -> 5 | V7: =(T7-S7)*24*60 -> 67 | W7: =T7 -> 0.81388889 | X7: =S8 -> 0.85347222 | AE7: =M7-J7 -> -83.58209 | AF7: =M7/J7 -> 0.95820896
A8: 新豐6線 | B8: 微波主食 | C8: 二配金咖哩濃厚辛口咖哩飯 | E8: 50.98 | F8: 1387 | G8: =E8*F8 -> 70709.26 | I8: 16 | J8: 2000 | K8: =J8/I8 -> 125 | L8: 16 | M8: =F8/V8*60 -> 1935.3488 | N8: =M8/L8 -> 120.9593 | O8: =L8-I8 -> 0 | P8: =N8-K8 -> -4.0406977 | Q8: =N8/K8 -> 0.96767442 | S8: 0.85347222 | T8: 0.88333333 | U8: =IF(S8=TIME(17,0,0),"",(S8-T7)*24*60) -> 57 | V8: =(T8-S8)*24*60 -> 43 | AE8: =M8-J8 -> -64.651163 | AF8: =M8/J8 -> 0.96767442
A9: 新豐6線 | B9: 微波主食 | C9: 二配金咖哩果香甘口咖哩飯 | E9: 50.92 | F9: 1278 | G9: =E9*F9 -> 65075.76 | I9: 15 | J9: 2000 | K9: =J9/I9 -> 133.33333 | L9: 15 | M9: =F9/V9*60 -> 1917 | N9: =M9/L9 -> 127.8 | O9: =L9-I9 -> 0 | P9: =N9-K9 -> -5.5333333 | Q9: =N9/K9 -> 0.9585 | S9: 0.88888889 | T9: 0.91666667 | U9: =IF(S9=TIME(17,0,0),"",(S9-T8)*24*60) -> 8 | V9: =(T9-S9)*24*60 -> 40 | AE9: =M9-J9 -> -83 | AF9: =M9/J9 -> 0.9585
A10: 新豐6線 | B10: 平均 | I10: 15.4 | J10: 2000 | K10: =J10/I10 -> 129.87013 | L10: 15.4 | M10: =AVERAGE(M5:M9) -> 1932.1317 | N10: =M10/L10 -> 125.4631 | O10: =L10-I10 -> 0 | P10: =N10-K10 -> -4.4070307 | Q10: =N10/K10 -> 0.96606586 | Y10: =SUM(Y5:Y9) -> 0 | Z10: =SUM(Z5:Z9) -> 0 | AC10: 5 | AD10: =SUM(AD5:AD9) -> 0 | AE10: =M10-J10 -> -67.868272 | AF10: =M10/J10 -> 0.96606586
A11: 新豐2線 | B11: 沙拉 | C11: 青檸烤雞握沙拉(113年) | E11: 39.8 | F11: 4100 | G11: =E11*F11 -> 163180 | H11: 2 | I11: 17 | J11: 1500 | K11: =J11/I11 -> 88.235294 | L11: 17 | M11: =F11/V11*60 -> 1430.2326 | N11: =M11/L11 -> 84.131327 | O11: =L11-I11 -> 0 | P11: =N11-K11 -> -4.1039672 | Q11: =N11/K11 -> 0.95348837 | R11: =Q17 -> 0.95540929 | S11: 0.083333333 | T11: 0.20277778 | V11: =(T11-S11)*24*60 -> 172 | W11: =T11 -> 0.20277778 | X11: =S12 -> 0.22222222 | AC11: 6 | AE11: =M11-J11 -> -69.767442 | AF11: =M11/J11 -> 0.95348837 | AG11: =AF17 -> 0.95540929
A12: 新豐2線 | B12: 沙拉 | C12: 厚蛋時蔬握沙拉 | E12: 39.46 | F12: 3063 | G12: =E12*F12 -> 120865.98 | I12: 15 | J12: 1500 | K12: =J12/I12 -> 100 | L12: 15 | M12: =F12/V12*60 -> 1435.7813 | N12: =M12/L12 -> 95.71875 | O12: =L12-I12 -> 0 | P12: =N12-K12 -> -4.28125 | Q12: =N12/K12 -> 0.9571875 | S12: 0.22222222 | T12: 0.31111111 | U12: =IF(S12=TIME(17,0,0),"",(S12-T11)*24*60) -> 28 | V12: =(T12-S12)*24*60 -> 128 | AE12: =M12-J12 -> -64.21875 | AF12: =M12/J12 -> 0.9571875
A13: 新豐2線 | B13: 沙拉 | C13: 地瓜瓜握沙拉 | E13: 39.52 | F13: 2512 | G13: =E13*F13 -> 99274.24 | I13: 19 | J13: 1500 | K13: =J13/I13 -> 78.947368 | L13: 19 | M13: =F13/V13*60 -> 1435.4286 | N13: =M13/L13 -> 75.548872 | O13: =L13-I13 -> 0 | P13: =N13-K13 -> -3.3984962 | Q13: =N13/K13 -> 0.95695238 | S13: 0.31458333 | T13: 0.3875 | U13: =IF(S13=TIME(17,0,0),"",(S13-T12)*24*60) -> 5 | V13: =(T13-S13)*24*60 -> 105 | AE13: =M13-J13 -> -64.571429 | AF13: =M13/J13 -> 0.95695238
A14: 新豐2線 | B14: 沙拉 | C14: 青醬優格雞肉握沙拉(113年) | E14: 39.62 | F14: 2900 | G14: =E14*F14 -> 114898 | H14: 2 | I14: 19 | J14: 1500 | K14: =J14/I14 -> 78.947368 | L14: 19 | M14: =F14/V14*60 -> 1426.2295 | N14: =M14/L14 -> 75.064711 | O14: =L14-I14 -> 0 | P14: =N14-K14 -> -3.8826575 | Q14: =N14/K14 -> 0.95081967 | S14: 0.39305556 | T14: 0.47777778 | U14: =IF(S14=TIME(17,0,0),"",(S14-T13)*24*60) -> 8 | V14: =(T14-S14)*24*60 -> 122 | W14: =T14 -> 0.47777778 | X14: =S15 -> 0.51875 | AE14: =M14-J14 -> -73.770492 | AF14: =M14/J14 -> 0.95081967
A15: 新豐2線 | B15: 沙拉 | C15: 青醬優格雞肉握沙拉(113年) | E15: 39.62 | F15: 2354 | G15: =E15*F15 -> 93265.48 | I15: 19 | J15: 1500 | K15: =J15/I15 -> 78.947368 | L15: 19 | M15: =F15/V15*60 -> 1441.2245 | N15: =M15/L15 -> 75.853921 | O15: =L15-I15 -> 0 | P15: =N15-K15 -> -3.0934479 | Q15: =N15/K15 -> 0.96081633 | S15: 0.51875 | T15: 0.58680556 | U15: =IF(S15=TIME(17,0,0),"",(S15-T14)*24*60) -> 59 | V15: =(T15-S15)*24*60 -> 98 | AE15: =M15-J15 -> -58.77551 | AF15: =M15/J15 -> 0.96081633
A16: 新豐2線 | B16: 沙拉 | C16: 青檸烤雞握沙拉(113年) | E16: 39.8 | F16: 3360 | G16: =E16*F16 -> 133728 | I16: 17 | J16: 1500 | K16: =J16/I16 -> 88.235294 | L16: 17 | M16: =F16/V16*60 -> 1429.7872 | N16: =M16/L16 -> 84.105131 | O16: =L16-I16 -> 0 | P16: =N16-K16 -> -4.1301627 | Q16: =N16/K16 -> 0.95319149 | S16: 0.59097222 | T16: 0.68888889 | U16: =IF(S16=TIME(17,0,0),"",(S16-T15)*24*60) -> 6 | V16: =(T16-S16)*24*60 -> 141 | AE16: =M16-J16 -> -70.212766 | AF16: =M16/J16 -> 0.95319149
A17: 新豐2線 | B17: 平均 | I17: 17.666667 | J17: 1500 | K17: =J17/I17 -> 84.90566 | L17: 17.666667 | M17: =AVERAGE(M11:M16) -> 1433.1139 | N17: =M17/L17 -> 81.119657 | O17: =L17-I17 -> 0 | P17: =N17-K17 -> -3.7860037 | Q17: =N17/K17 -> 0.95540929 | Y17: =SUM(Y11:Y16) -> 0 | Z17: =SUM(Z11:Z16) -> 0 | AC17: 6 | AD17: =SUM(AD11:AD16) -> 0 | AE17: =M17-J17 -> -66.886065 | AF17: =M17/J17 -> 0.95540929
A18: 新豐5線 | B18: 季節調理麵 | C18: 台式麻醬涼麵(115年) | E18: 31.11 | F18: 3829 | G18: =E18*F18 -> 119120.19 | I18: 14 | J18: 2000 | K18: =J18/I18 -> 142.85714 | L18: 14 | M18: =F18/V18*60 -> 1914.5 | N18: =M18/L18 -> 136.75 | O18: =L18-I18 -> 0 | P18: =N18-K18 -> -6.1071429 | Q18: =N18/K18 -> 0.95725 | R18: =Q25 -> 0.95948177 | S18: 0.083333333 | T18: 0.16666667 | V18: =(T18-S18)*24*60 -> 120 | W18: =T18 -> 0.16666667 | X18: =S19 -> 0.18611111 | AC18: 7 | AE18: =M18-J18 -> -85.5 | AF18: =M18/J18 -> 0.95725 | AG18: =AF25 -> 0.95948177
A19: 新豐5線 | B19: 小吃 | C19: 香菇雞燉湯 | E19: 38.62 | F19: 2295 | G19: =E19*F19 -> 88632.9 | I19: 24 | J19: 1500 | K19: =J19/I19 -> 62.5 | L19: 24 | M19: =F19/V19*60 -> 1434.375 | N19: =M19/L19 -> 59.765625 | O19: =L19-I19 -> 0 | P19: =N19-K19 -> -2.734375 | Q19: =N19/K19 -> 0.95625 | S19: 0.18611111 | T19: 0.25277778 | U19: =IF(S19=TIME(17,0,0),"",(S19-T18)*24*60) -> 28 | V19: =(T19-S19)*24*60 -> 96 | AE19: =M19-J19 -> -65.625 | AF19: =M19/J19 -> 0.95625
A20: 新豐5線 | B20: 小吃 | C20: 剝皮辣椒雞湯 | E20: 41 | F20: 1898 | G20: =E20*F20 -> 77818 | I20: 26 | J20: 1500 | K20: =J20/I20 -> 57.692308 | L20: 26 | M20: =F20/V20*60 -> 1441.519 | N20: =M20/L20 -> 55.443038 | O20: =L20-I20 -> 0 | P20: =N20-K20 -> -2.2492697 | Q20: =N20/K20 -> 0.96101266 | S20: 0.25694444 | T20: 0.31180556 | U20: =IF(S20=TIME(17,0,0),"",(S20-T19)*24*60) -> 6 | V20: =(T20-S20)*24*60 -> 79 | AE20: =M20-J20 -> -58.481013 | AF20: =M20/J20 -> 0.96101266
A21: 新豐5線 | B21: 微波主食 | C21: 香菇雞粥 | E21: 37.03 | F21: 3372 | G21: =E21*F21 -> 124865.16 | I21: 13 | J21: 1500 | K21: =J21/I21 -> 115.38462 | L21: 13 | M21: =F21/V21*60 -> 1434.8936 | N21: =M21/L21 -> 110.37643 | O21: =L21-I21 -> 0 | P21: =N21-K21 -> -5.0081833 | Q21: =N21/K21 -> 0.95659574 | S21: 0.31666667 | T21: 0.41458333 | U21: =IF(S21=TIME(17,0,0),"",(S21-T20)*24*60) -> 7 | V21: =(T21-S21)*24*60 -> 141 | AE21: =M21-J21 -> -65.106383 | AF21: =M21/J21 -> 0.95659574
A22: 新豐5線 | B22: 微波主食 | C22: 二配玉米濃湯焗烤飯 | E22: 54.5 | F22: 2082 | G22: =E22*F22 -> 113469 | I22: 20 | J22: 1500 | K22: =J22/I22 -> 75 | L22: 20 | M22: =F22/V22*60 -> 1435.8621 | N22: =M22/L22 -> 71.793103 | O22: =L22-I22 -> 0 | P22: =N22-K22 -> -3.2068966 | Q22: =N22/K22 -> 0.95724138 | S22: 0.70833333 | T22: 0.76875 | U22: =IF(S22=TIME(17,0,0),"",(S22-T21)*24*60) | V22: =(T22-S22)*24*60 -> 87 | AE22: =M22-J22 -> -64.137931 | AF22: =M22/J22 -> 0.95724138
A23: 新豐5線 | B23: 微波主食 | C23: 二配港式香滑嫩蛋牛肉燴飯 | E23: 50.67 | F23: 1836 | G23: =E23*F23 -> 93030.12 | I23: 17 | J23: 2000 | K23: =J23/I23 -> 117.64706 | L23: 17 | M23: =F23/V23*60 -> 1932.6316 | N23: =M23/L23 -> 113.68421 | O23: =L23-I23 -> 0 | P23: =N23-K23 -> -3.9628483 | Q23: =N23/K23 -> 0.96631579 | S23: 0.77430556 | T23: 0.81388889 | U23: =IF(S23=TIME(17,0,0),"",(S23-T22)*24*60) -> 8 | V23: =(T23-S23)*24*60 -> 57 | AE23: =M23-J23 -> -67.368421 | AF23: =M23/J23 -> 0.96631579
A24: 新豐5線 | B24: 微波主食 | C24: 二配泰式綠咖哩雞 | E24: 50.67 | F24: 1568 | G24: =E24*F24 -> 79450.56 | I24: 15 | J24: 2000 | K24: =J24/I24 -> 133.33333 | L24: 15 | M24: =F24/V24*60 -> 1920 | N24: =M24/L24 -> 128 | O24: =L24-I24 -> 0 | P24: =N24-K24 -> -5.3333333 | Q24: =N24/K24 -> 0.96 | S24: 0.81944444 | T24: 0.85347222 | U24: =IF(S24=TIME(17,0,0),"",(S24-T23)*24*60) -> 8 | V24: =(T24-S24)*24*60 -> 49 | AE24: =M24-J24 -> -80 | AF24: =M24/J24 -> 0.96
A25: 新豐5線 | B25: 平均 | I25: 18.428571 | J25: 1714.2857 | K25: =J25/I25 -> 93.023256 | L25: 18.428571 | M25: =AVERAGE(M18:M24) -> 1644.8259 | N25: =M25/L25 -> 89.254118 | O25: =L25-I25 -> 0 | P25: =N25-K25 -> -3.7691376 | Q25: =N25/K25 -> 0.95948177 | Y25: =SUM(Y18:Y24) -> 0 | Z25: =SUM(Z18:Z24) -> 0 | AC25: 7 | AD25: =SUM(AD18:AD24) -> 0 | AE25: =M25-J25 -> -69.459821 | AF25: =M25/J25 -> 0.95948177
A26: 新豐7線 | B26: 微波主食 | C26: 韓式泡菜豬肉豆腐丼飯 | E26: 50.67 | F26: 1964 | G26: =E26*F26 -> 99515.88 | I26: 17 | J26: 2000 | K26: =J26/I26 -> 117.64706 | L26: 17 | M26: =F26/V26*60 -> 1931.8033 | N26: =M26/L26 -> 113.63549 | O26: =L26-I26 -> 0 | P26: =N26-K26 -> -4.0115718 | Q26: =N26/K26 -> 0.96590164 | R26: =Q33 -> 0.9630962 | S26: 0.20833333 | T26: 0.25069444 | V26: =(T26-S26)*24*60 -> 61 | AC26: 7 | AE26: =M26-J26 -> -68.196721 | AF26: =M26/J26 -> 0.96590164 | AG26: =AF33 -> 0.9630962
A27: 新豐7線 | B27: 微波主食 | C27: 鐵板滑蛋炸豬排丼 | E27: 57.73 | F27: 2748 | G27: =E27*F27 -> 158642.04 | I27: 14 | J27: 2000 | K27: =J27/I27 -> 142.85714 | L27: 14 | M27: =F27/V27*60 -> 1917.2093 | N27: =M27/L27 -> 136.94352 | O27: =L27-I27 -> 0 | P27: =N27-K27 -> -5.9136213 | Q27: =N27/K27 -> 0.95860465 | S27: 0.25625 | T27: 0.31597222 | U27: =IF(S27=TIME(17,0,0),"",(S27-T26)*24*60) -> 8 | V27: =(T27-S27)*24*60 -> 86 | AE27: =M27-J27 -> -82.790698 | AF27: =M27/J27 -> 0.95860465
A28: 新豐7線 | B28: 微波主食 | C28: 日式炙烤親子丼 | E28: 53.27 | F28: 1643 | G28: =E28*F28 -> 87522.61 | I28: 16 | J28: 2000 | K28: =J28/I28 -> 125 | L28: 16 | M28: =F28/V28*60 -> 1932.9412 | N28: =M28/L28 -> 120.80882 | O28: =L28-I28 -> 0 | P28: =N28-K28 -> -4.1911765 | Q28: =N28/K28 -> 0.96647059 | S28: 0.32013889 | T28: 0.35555556 | U28: =IF(S28=TIME(17,0,0),"",(S28-T27)*24*60) -> 6 | V28: =(T28-S28)*24*60 -> 51 | AE28: =M28-J28 -> -67.058824 | AF28: =M28/J28 -> 0.96647059
A29: 新豐7線 | B29: 微波主食 | C29: 二配厚香料優格咖哩雞排飯 | E29: 56.43 | F29: 1710 | G29: =E29*F29 -> 96495.3 | I29: 13 | J29: 2000 | K29: =J29/I29 -> 153.84615 | L29: 13 | M29: =F29/V29*60 -> 1935.8491 | N29: =M29/L29 -> 148.91147 | O29: =L29-I29 -> 0 | P29: =N29-K29 -> -4.934688 | Q29: =N29/K29 -> 0.96792453 | S29: 0.70833333 | T29: 0.74513889 | U29: =IF(S29=TIME(17,0,0),"",(S29-T28)*24*60) | V29: =(T29-S29)*24*60 -> 53 | AE29: =M29-J29 -> -64.150943 | AF29: =M29/J29 -> 0.96792453
A30: 新豐7線 | B30: 微波主食 | C30: 二配美味蟹煲 | E30: 54.09 | F30: 1000 | G30: =E30*F30 -> 54090 | H30: 2 | I30: 18 | J30: 2000 | K30: =J30/I30 -> 111.11111 | L30: 18 | M30: =F30/V30*60 -> 1935.4839 | N30: =M30/L30 -> 107.52688 | O30: =L30-I30 -> 0 | P30: =N30-K30 -> -3.5842294 | Q30: =N30/K30 -> 0.96774194 | S30: 0.75069444 | T30: 0.77222222 | U30: =IF(S30=TIME(17,0,0),"",(S30-T29)*24*60) -> 8 | V30: =(T30-S30)*24*60 -> 31 | AE30: =M30-J30 -> -64.516129 | AF30: =M30/J30 -> 0.96774194
A31: 新豐7線 | B31: 微波主食 | C31: 二配泰式檸檬魚飯 | E31: 57.3 | F31: 2353 | G31: =E31*F31 -> 134826.9 | I31: 16 | J31: 2000 | K31: =J31/I31 -> 125 | L31: 16 | M31: =F31/V31*60 -> 1907.8378 | N31: =M31/L31 -> 119.23986 | O31: =L31-I31 -> 0 | P31: =N31-K31 -> -5.7601351 | Q31: =N31/K31 -> 0.95391892 | S31: 0.77638889 | T31: 0.82777778 | U31: =IF(S31=TIME(17,0,0),"",(S31-T30)*24*60) -> 6 | V31: =(T31-S31)*24*60 -> 74 | W31: =T31 -> 0.82777778 | X31: =S32 -> 0.86736111 | AE31: =M31-J31 -> -92.162162 | AF31: =M31/J31 -> 0.95391892
A32: 新豐7線 | B32: 微波主食 | C32: 二配美味蟹煲 | E32: 54.09 | F32: 1730 | G32: =E32*F32 -> 93575.7 | I32: 18 | J32: 2000 | K32: =J32/I32 -> 111.11111 | L32: 18 | M32: =F32/V32*60 -> 1922.2222 | N32: =M32/L32 -> 106.79012 | O32: =L32-I32 -> 0 | P32: =N32-K32 -> -4.3209877 | Q32: =N32/K32 -> 0.96111111 | S32: 0.86736111 | T32: 0.90486111 | U32: =IF(S32=TIME(17,0,0),"",(S32-T31)*24*60) -> 57 | V32: =(T32-S32)*24*60 -> 54 | AE32: =M32-J32 -> -77.777778 | AF32: =M32/J32 -> 0.96111111
A33: 新豐7線 | B33: 平均 | I33: 16 | J33: 2000 | K33: =J33/I33 -> 125 | L33: 16 | M33: =AVERAGE(M26:M32) -> 1926.1924 | N33: =M33/L33 -> 120.38702 | O33: =L33-I33 -> 0 | P33: =N33-K33 -> -4.6129755 | Q33: =N33/K33 -> 0.9630962 | Y33: =SUM(Y26:Y32) -> 0 | Z33: =SUM(Z26:Z32) -> 0 | AC33: 7 | AD33: =SUM(AD26:AD32) -> 0 | AE33: =M33-J33 -> -73.807608 | AF33: =M33/J33 -> 0.9630962
A34: 新豐8線 | B34: 三明治 | C34: 紐奧良風味烤雞鮮蔬三明治 | E34: 31.29 | F34: 5800 | G34: =E34*F34 -> 181482 | H34: 2 | I34: 18 | J34: 2400 | K34: =J34/I34 -> 133.33333 | L34: 18 | M34: =F34/V34*60 -> 2289.4737 | N34: =M34/L34 -> 127.19298 | O34: =L34-I34 -> 0 | P34: =N34-K34 -> -6.1403509 | Q34: =N34/K34 -> 0.95394737 | R34: =Q43 -> 0.95674989 | S34: 0.083333333 | T34: 0.18888889 | V34: =(T34-S34)*24*60 -> 152 | W34: =T34 -> 0.18888889 | X34: =S35 -> 0.20902778 | AC34: 9 | AE34: =M34-J34 -> -110.52632 | AF34: =M34/J34 -> 0.95394737 | AG34: =AF43 -> 0.95674989
A35: 新豐8線 | B35: 三明治 | C35: 醬燒烤雞三明治(115年) | E35: 26.37 | F35: 4200 | G35: =E35*F35 -> 110754 | H35: 2 | I35: 18 | J35: 2400 | K35: =J35/I35 -> 133.33333 | L35: 18 | M35: =F35/V35*60 -> 2290.9091 | N35: =M35/L35 -> 127.27273 | O35: =L35-I35 -> 0 | P35: =N35-K35 -> -6.0606061 | Q35: =N35/K35 -> 0.95454545 | S35: 0.20902778 | T35: 0.28541667 | U35: =(S35-T34)*24*60 -> 29 | V35: =(T35-S35)*24*60 -> 110 | AE35: =M35-J35 -> -109.09091 | AF35: =M35/J35 -> 0.95454545
A36: 新豐8線 | B36: 三明治 | C36: 經典火腿玉米蛋三明治 | E36: 24.43 | F36: 5800 | G36: =E36*F36 -> 141694 | H36: 2 | I36: 14 | J36: 2400 | K36: =J36/I36 -> 171.42857 | L36: 14 | M36: =F36/V36*60 -> 2289.4737 | N36: =M36/L36 -> 163.53383 | O36: =L36-I36 -> 0 | P36: =N36-K36 -> -7.8947368 | Q36: =N36/K36 -> 0.95394737 | S36: 0.29027778 | T36: 0.39583333 | U36: =(S36-T35)*24*60 -> 7 | V36: =(T36-S36)*24*60 -> 152 | AE36: =M36-J36 -> -110.52632 | AF36: =M36/J36 -> 0.95394737
A37: 新豐8線 | B37: 三明治 | C37: 起司芋見肉鬆三明治 | E37: 25.98 | F37: 3283 | G37: =E37*F37 -> 85292.34 | I37: 17 | J37: 2400 | K37: =J37/I37 -> 141.17647 | L37: 17 | M37: =F37/V37*60 -> 2290.4651 | N37: =M37/L37 -> 134.73324 | O37: =L37-I37 -> 0 | P37: =N37-K37 -> -6.4432285 | Q37: =N37/K37 -> 0.95436047 | S37: 0.39930556 | T37: 0.45902778 | U37: =(S37-T36)*24*60 -> 5 | V37: =(T37-S37)*24*60 -> 86 | AE37: =M37-J37 -> -109.53488 | AF37: =M37/J37 -> 0.95436047
A38: 新豐8線 | B38: 三明治 | C38: 榛果摩卡脆脆三明治 | E38: 20.21 | F38: 2457 | G38: =E38*F38 -> 49655.97 | I38: 18 | J38: 2400 | K38: =J38/I38 -> 133.33333 | L38: 18 | M38: =F38/V38*60 -> 2303.4375 | N38: =M38/L38 -> 127.96875 | O38: =L38-I38 -> 0 | P38: =N38-K38 -> -5.3645833 | Q38: =N38/K38 -> 0.95976562 | S38: 0.4625 | T38: 0.50694444 | U38: =(S38-T37)*24*60 -> 5 | V38: =(T38-S38)*24*60 -> 64 | W38: =T38 -> 0.50694444 | X38: =S39 -> 0.54652778 | AE38: =M38-J38 -> -96.5625 | AF38: =M38/J38 -> 0.95976562
A39: 新豐8線 | B39: 三明治 | C39: 雞蛋沙拉三明治(114年) | E39: 25.99 | F39: 1949 | G39: =E39*F39 -> 50654.51 | I39: 14 | J39: 2400 | K39: =J39/I39 -> 171.42857 | L39: 14 | M39: =F39/V39*60 -> 2292.9412 | N39: =M39/L39 -> 163.78151 | O39: =L39-I39 -> 0 | P39: =N39-K39 -> -7.6470588 | Q39: =N39/K39 -> 0.95539216 | S39: 0.54652778 | T39: 0.58194444 | U39: =(S39-T38)*24*60 -> 57 | V39: =(T39-S39)*24*60 -> 51 | AE39: =M39-J39 -> -107.05882 | AF39: =M39/J39 -> 0.95539216
A40: 新豐8線 | B40: 三明治 | C40: 醬燒烤雞三明治(115年) | E40: 26.37 | F40: 2962 | G40: =E40*F40 -> 78107.94 | I40: 18 | J40: 2400 | K40: =J40/I40 -> 133.33333 | L40: 18 | M40: =F40/V40*60 -> 2308.0519 | N40: =M40/L40 -> 128.22511 | O40: =L40-I40 -> 0 | P40: =N40-K40 -> -5.1082251 | Q40: =N40/K40 -> 0.96168831 | S40: 0.58611111 | T40: 0.63958333 | U40: =(S40-T39)*24*60 -> 6 | V40: =(T40-S40)*24*60 -> 77 | AE40: =M40-J40 -> -91.948052 | AF40: =M40/J40 -> 0.96168831
...

Sheet 0801
B1: 屏榮 新豐廠組合室生產人時性分析
B3: 日期 | C3: =TEXT('0801 4度C'!A2,"yyyy.mm.ddaaaa") -> 2026.08.01星期六 | E3: 訂單量 | F3: ='0801 4度C'!D1 -> 162409 | H3: 營業額 | I3: ='0801 4度C'!F1 -> 5699318.4
B4: 人時性 | C4: 項目 | E4: ➀ | G4: ➁ | I4: ➂ | K4: 異常停線 | M4: 短暫停線
C5: 組合室 | E5: 全溫層 | G5: 4度C-各編組展開 | I5: ③三明治-各編組展開 | K5: 合計次數 | L5: 時間 | M5: 合計次數 | N5: 設備次數
C6: 排關平均 | E6: =AVERAGE(D13:M13) -> 157.89241 | F6: =AVERAGE(D31:O31,D13:J13) -> 166.4135 | G6: =AVERAGE(D13:J13) -> 166.4135 | I6: =AVERAGE(K13:M13) -> 138.00984 | K6: ='0801 4度C'!Y2 -> 0 | L6: ='0801 4度C'!Z2 -> 0 | M6: ='0801 4度C'!AC2 -> 57 | N6: ='0801 4度C'!AD2 -> 0
C7: 實績平均 | E7: =AVERAGE(D14:M14) -> 151.38653 | F7: =AVERAGE(D32:O32,D14:J14) -> 159.63047 | G7: =AVERAGE(D14:J14) -> 159.63047 | I7: =AVERAGE(K14:M14) -> 132.15069
C8: 達成率平均 | E8: =AVERAGE(D15:M15) -> 0.95847739 | F8: =AVERAGE(D15:J15,D33:O33) -> 0.95884124 | G8: =AVERAGE(D15:J15) -> 0.95884124 | I8: =AVERAGE(K15:M15) -> 0.9576284
K9: ※現行日本鮮食廠以達成率80%為基本(即為現行KPI)
B10: 溫層 | D10: ➁4度C-各編組展開 | K10: ③三明治-各編組展開
B11: 編組 | D11: 1 | E11: 2 | F11: 3 | G11: 4 | H11: 5 | I11: 6 | J11: 7 | K11: 1 | L11: 2 | M11: 3
D12: 新豐6線 | E12: 新豐2線 | F12: 新豐5線 | G12: 新豐7線 | H12: 新豐3線 | I12: 新豐1線 | J12: 新豐10線 | K12: 新豐8線 | L12: 新豐9線 | M12: 新豐4線
B13: 人時性 | C13: 排關 | D13: =SUMIFS('0801 4度C'!$K:$K,'0801 4度C'!$A:$A,"新豐6線",'0801 4度C'!$B:$B,"平均") -> 130.43478 | E13: =SUMIFS('0801 4度C'!$K:$K,'0801 4度C'!$A:$A,"新豐2線",'0801 4度C'!$B:$B,"平均") -> 84.269663 | F13: =SUMIFS('0801 4度C'!$K:$K,'0801 4度C'!$A:$A,"新豐5線",'0801 4度C'!$B:$B,"平均") -> 93.023256 | G13: =SUMIFS('0801 4度C'!$K:$K,'0801 4度C'!$A:$A,"新豐7線",'0801 4度C'!$B:$B,"平均") -> 127.65957 | H13: =SUMIFS('0801 4度C'!$K:$K,'0801 4度C'!$A:$A,"新豐3線",'0801 4度C'!$B:$B,"平均") -> 324.32432 | I13: =SUMIFS('0801 4度C'!$K:$K,'0801 4度C'!$A:$A,"新豐1線",'0801 4度C'!$B:$B,"平均") -> 112.5 | J13: =SUMIFS('0801 4度C'!$K:$K,'0801 4度C'!$A:$A,"新豐10線",'0801 4度C'!$B:$B,"平均") -> 292.68293 | K13: =SUMIFS('0801 4度C'!$K:$K,'0801 4度C'!$A:$A,"新豐8線",'0801 4度C'!$B:$B,"平均") -> 137.70492 | L13: =SUMIFS('0801 4度C'!$K:$K,'0801 4度C'!$A:$A,"新豐9線",'0801 4度C'!$B:$B,"平均") -> 123.94366 | M13: =SUMIFS('0801 4度C'!$K:$K,'0801 4度C'!$A:$A,"新豐4線",'0801 4度C'!$B:$B,"平均") -> 152.38095
C14: 實績 | D14: =SUMIFS('0801 4度C'!$N:$N,'0801 4度C'!$A:$A,"新豐6線",'0801 4度C'!$B:$B,"平均") -> 124.64955 | E14: =SUMIFS('0801 4度C'!$N:$N,'0801 4度C'!$A:$A,"新豐2線",'0801 4度C'!$B:$B,"平均") -> 80.691233 | F14: =SUMIFS('0801 4度C'!$N:$N,'0801 4度C'!$A:$A,"新豐5線",'0801 4度C'!$B:$B,"平均") -> 88.980413 | G14: =SUMIFS('0801 4度C'!$N:$N,'0801 4度C'!$A:$A,"新豐7線",'0801 4度C'!$B:$B,"平均") -> 122.27707 | H14: =SUMIFS('0801 4度C'!$N:$N,'0801 4度C'!$A:$A,"新豐3線",'0801 4度C'!$B:$B,"平均") -> 311.51593 | I14: =SUMIFS('0801 4度C'!$N:$N,'0801 4度C'!$A:$A,"新豐1線",'0801 4度C'!$B:$B,"平均") -> 108.4965 | J14: =SUMIFS('0801 4度C'!$N:$N,'0801 4度C'!$A:$A,"新豐10線",'0801 4度C'!$B:$B,"平均") -> 280.80259 | K14: =SUMIFS('0801 4度C'!$N:$N,'0801 4度C'!$A:$A,"新豐8線",'0801 4度C'!$B:$B,"平均") -> 132.2181 | L14: =SUMIFS('0801 4度C'!$N:$N,'0801 4度C'!$A:$A,"新豐9線",'0801 4度C'!$B:$B,"平均") -> 118.6802 | M14: =SUMIFS('0801 4度C'!$N:$N,'0801 4度C'!$A:$A,"新豐4線",'0801 4度C'!$B:$B,"平均") -> 145.55376
C15: 達成率 | D15: =D14/D13 -> 0.95564655 | E15: =E14/E13 -> 0.95753597 | F15: =F14/F13 -> 0.95653944 | G15: =G14/G13 -> 0.95783708 | H15: =H14/H13 -> 0.96050745 | I15: =I14/I13 -> 0.96441335 | J15: =J14/J13 -> 0.95940885 | K15: =K14/K13 -> 0.96015522 | ... M15: =M14/M13 -> 0.95519652
B16: 作業 時間 | C16: 開始 | D16: =VLOOKUP("新豐6線",'0801 4度C'!$A:$T,19,0) -> 0.70833333 | E16: =VLOOKUP("新豐2線",'0801 4度C'!$A:$T,19,0) -> 0.083333333 | F16: =VLOOKUP("新豐5線",'0801 4度C'!$A:$T,19,0) -> 0.083333333 | G16: =VLOOKUP("新豐7線",'0801 4度C'!$A:$T,19,0) -> 0.20833333 | H16: =VLOOKUP("新豐3線",'0801 4度C'!$A:$T,19,0) -> 0.20833333 | I16: =VLOOKUP("新豐1線",'0801 4度C'!$A:$T,19,0) -> 0.083333333 | J16: =VLOOKUP("新豐10線",'0801 4度C'!$A:$T,19,0) -> 0.20833333 | K16: =VLOOKUP("新豐8線",'0801 4度C'!$A:$T,19,0) -> 0.083333333 | L16: =VLOOKUP("新豐9線",'0801 4度C'!$A:$T,19,0) -> 0.083333333 | M16: =VLOOKUP("新豐4線",'0801 4度C'!$A:$T,19,0) -> 0.083333333
C17: 結束 | D17: =LOOKUP(2,1/(('0801 4度C'!$A:$A="新豐6線")*('0801 4度C'!$T:$T<>"")),'0801 4度C'!$T:$T) -> 0.84375 | E17: =LOOKUP(2,1/(('0801 4度C'!$A:$A="新豐2線")*('0801 4度C'!$T:$T<>"")),'0801 4度C'!$T:$T) -> 0.58055556 | F17: =LOOKUP(2,1/(('0801 4度C'!$A:$A="新豐5線")*('0801 4度C'!$T:$T<>"")),'0801 4度C'!$T:$T) -> 0.84930556 | G17: =LOOKUP(2,1/(('0801 4度C'!$A:$A="新豐7線")*('0801 4度C'!$T:$T<>"")),'0801 4度C'!$T:$T) -> 0.84652778 | H17: =LOOKUP(2,1/(('0801 4度C'!$A:$A="新豐3線")*('0801 4度C'!$T:$T<>"")),'0801 4度C'!$T:$T) -> 0.38541667 | I17: =LOOKUP(2,1/(('0801 4度C'!$A:$A="新豐1線")*('0801 4度C'!$T:$T<>"")),'0801 4度C'!$T:$T) -> 0.85625 | J17: =LOOKUP(2,1/(('0801 4度C'!$A:$A="新豐10線")*('0801 4度C'!$T:$T<>"")),'0801 4度C'!$T:$T) -> 0.39375 | K17: =LOOKUP(2,1/(('0801 4度C'!$A:$A="新豐8線")*('0801 4度C'!$T:$T<>"")),'0801 4度C'!$T:$T) -> 0.62291667 | L17: =LOOKUP(2,1/(('0801 4度C'!$A:$A="新豐9線")*('0801 4度C'!$T:$T<>"")),'0801 4度C'!$T:$T) -> 0.50833333 | M17: =LOOKUP(2,1/(('0801 4度C'!$A:$A="新豐4線")*('0801 4度C'!$T:$T<>"")),'0801 4度C'!$T:$T) -> 0.68402778
B18: 產線異常 (5分鐘以上) | C18: 次數 | D18: =SUMIFS('0801 4度C'!$Y:$Y,'0801 4度C'!$A:$A,"新豐6線",'0801 4度C'!$B:$B,"平均") -> 0 | E18: =SUMIFS('0801 4度C'!$Y:$Y,'0801 4度C'!$A:$A,"新豐2線",'0801 4度C'!$B:$B,"平均") -> 0 | F18: =SUMIFS('0801 4度C'!$Y:$Y,'0801 4度C'!$A:$A,"新豐5線",'0801 4度C'!$B:$B,"平均") -> 0 | G18: =SUMIFS('0801 4度C'!$Y:$Y,'0801 4度C'!$A:$A,"新豐7線",'0801 4度C'!$B:$B,"平均") -> 0 | H18: =SUMIFS('0801 4度C'!$Y:$Y,'0801 4度C'!$A:$A,"新豐3線",'0801 4度C'!$B:$B,"平均") -> 0 | I18: =SUMIFS('0801 4度C'!$Y:$Y,'0801 4度C'!$A:$A,"新豐1線",'0801 4度C'!$B:$B,"平均") -> 0 | J18: =SUMIFS('0801 4度C'!$Y:$Y,'0801 4度C'!$A:$A,"新豐10線",'0801 4度C'!$B:$B,"平均") -> 0 | K18: =SUMIFS('0801 4度C'!$Y:$Y,'0801 4度C'!$A:$A,"新豐8線",'0801 4度C'!$B:$B,"平均") -> 0 | L18: =SUMIFS('0801 4度C'!$Y:$Y,'0801 4度C'!$A:$A,"新豐9線",'0801 4度C'!$B:$B,"平均") -> 0 | M18: =SUMIFS('0801 4度C'!$Y:$Y,'0801 4度C'!$A:$A,"新豐4線",'0801 4度C'!$B:$B,"平均") -> 0
C19: 時間/分 | D19: =SUMIFS('0801 4度C'!$Z:$Z,'0801 4度C'!$A:$A,"新豐6線",'0801 4度C'!$B:$B,"平均") -> 0 | E19: =SUMIFS('0801 4度C'!$Z:$Z,'0801 4度C'!$A:$A,"新豐2線",'0801 4度C'!$B:$B,"平均") -> 0 | F19: =SUMIFS('0801 4度C'!$Z:$Z,'0801 4度C'!$A:$A,"新豐5線",'0801 4度C'!$B:$B,"平均") -> 0 | G19: =SUMIFS('0801 4度C'!$Z:$Z,'0801 4度C'!$A:$A,"新豐7線",'0801 4度C'!$B:$B,"平均") -> 0 | H19: =SUMIFS('0801 4度C'!$Z:$Z,'0801 4度C'!$A:$A,"新豐3線",'0801 4度C'!$B:$B,"平均") -> 0 | I19: =SUMIFS('0801 4度C'!$Z:$Z,'0801 4度C'!$A:$A,"新豐1線",'0801 4度C'!$B:$B,"平均") -> 0 | J19: =SUMIFS('0801 4度C'!$Z:$Z,'0801 4度C'!$A:$A,"新豐10線",'0801 4度C'!$B:$B,"平均") -> 0 | K19: =SUMIFS('0801 4度C'!$Z:$Z,'0801 4度C'!$A:$A,"新豐8線",'0801 4度C'!$B:$B,"平均") -> 0 | L19: =SUMIFS('0801 4度C'!$Z:$Z,'0801 4度C'!$A:$A,"新豐9線",'0801 4度C'!$B:$B,"平均") -> 0 | M19: =SUMIFS('0801 4度C'!$Z:$Z,'0801 4度C'!$A:$A,"新豐4線",'0801 4度C'!$B:$B,"平均") -> 0
B20: 短暫停線 (5分鐘以下) | C20: 次數 | D20: =SUMIFS('0801 4度C'!$AC:$AC,'0801 4度C'!$A:$A,"新豐6線",'0801 4度C'!$B:$B,"平均") -> 3 | E20: =SUMIFS('0801 4度C'!$AC:$AC,'0801 4度C'!$A:$A,"新豐2線",'0801 4度C'!$B:$B,"平均") -> 5 | F20: =SUMIFS('0801 4度C'!$AC:$AC,'0801 4度C'!$A:$A,"新豐5線",'0801 4度C'!$B:$B,"平均") -> 7 | G20: =SUMIFS('0801 4度C'!$AC:$AC,'0801 4度C'!$A:$A,"新豐7線",'0801 4度C'!$B:$B,"平均") -> 6 | H20: =SUMIFS('0801 4度C'!$AC:$AC,'0801 4度C'!$A:$A,"新豐3線",'0801 4度C'!$B:$B,"平均") -> 4 | I20: =SUMIFS('0801 4度C'!$AC:$AC,'0801 4度C'!$A:$A,"新豐1線",'0801 4度C'!$B:$B,"平均") -> 9 | J20: =SUMIFS('0801 4度C'!$AC:$AC,'0801 4度C'!$A:$A,"新豐10線",'0801 4度C'!$B:$B,"平均") -> 4 | K20: =SUMIFS('0801 4度C'!$AC:$AC,'0801 4度C'!$A:$A,"新豐8線",'0801 4度C'!$B:$B,"平均") -> 7 | L20: =SUMIFS('0801 4度C'!$AC:$AC,'0801 4度C'!$A:$A,"新豐9線",'0801 4度C'!$B:$B,"平均") -> 4 | M20: =SUMIFS('0801 4度C'!$AC:$AC,'0801 4度C'!$A:$A,"新豐4線",'0801 4度C'!$B:$B,"平均") -> 8
C21: 設備次數 | D21: =SUMIFS('0801 4度C'!$AD:$AD,'0801 4度C'!$A:$A,"新豐6線",'0801 4度C'!$B:$B,"平均") -> 0 | E21: =SUMIFS('0801 4度C'!$AD:$AD,'0801 4度C'!$A:$A,"新豐2線",'0801 4度C'!$B:$B,"平均") -> 0 | F21: =SUMIFS('0801 4度C'!$AD:$AD,'0801 4度C'!$A:$A,"新豐5線",'0801 4度C'!$B:$B,"平均") -> 0 | G21: =SUMIFS('0801 4度C'!$AD:$AD,'0801 4度C'!$A:$A,"新豐7線",'0801 4度C'!$B:$B,"平均") -> 0 | H21: =SUMIFS('0801 4度C'!$AD:$AD,'0801 4度C'!$A:$A,"新豐3線",'0801 4度C'!$B:$B,"平均") -> 0 | I21: =SUMIFS('0801 4度C'!$AD:$AD,'0801 4度C'!$A:$A,"新豐1線",'0801 4度C'!$B:$B,"平均") -> 0 | J21: =SUMIFS('0801 4度C'!$AD:$AD,'0801 4度C'!$A:$A,"新豐10線",'0801 4度C'!$B:$B,"平均") -> 0 | K21: =SUMIFS('0801 4度C'!$AD:$AD,'0801 4度C'!$A:$A,"新豐8線",'0801 4度C'!$B:$B,"平均") -> 0 | L21: =SUMIFS('0801 4度C'!$AD:$AD,'0801 4度C'!$A:$A,"新豐9線",'0801 4度C'!$B:$B,"平均") -> 0 | M21: =SUMIFS('0801 4度C'!$AD:$AD,'0801 4度C'!$A:$A,"新豐4線",'0801 4度C'!$B:$B,"平均") -> 0
B22: 配置人數 | D22: =SUMIFS('0801 4度C'!$I:$I,'0801 4度C'!$A:$A,"新豐6線",'0801 4度C'!$B:$B,"平均") -> 15.333333 | E22: =SUMIFS('0801 4度C'!$I:$I,'0801 4度C'!$A:$A,"新豐2線",'0801 4度C'!$B:$B,"平均") -> 17.8 | F22: =SUMIFS('0801 4度C'!$I:$I,'0801 4度C'!$A:$A,"新豐5線",'0801 4度C'!$B:$B,"平均") -> 18.428571 | G22: =SUMIFS('0801 4度C'!$I:$I,'0801 4度C'!$A:$A,"新豐7線",'0801 4度C'!$B:$B,"平均") -> 15.666667 | H22: =SUMIFS('0801 4度C'!$I:$I,'0801 4度C'!$A:$A,"新豐3線",'0801 4度C'!$B:$B,"平均") -> 9.25 | I22: =SUMIFS('0801 4度C'!$I:$I,'0801 4度C'!$A:$A,"新豐1線",'0801 4度C'!$B:$B,"平均") -> 17.777778 | J22: =SUMIFS('0801 4度C'!$I:$I,'0801 4度C'!$A:$A,"新豐10線",'0801 4度C'!$B:$B,"平均") -> 10.25 | K22: =SUMIFS('0801 4度C'!$I:$I,'0801 4度C'!$A:$A,"新豐8線",'0801 4度C'!$B:$B,"平均") -> 17.428571 | L22: =SUMIFS('0801 4度C'!$I:$I,'0801 4度C'!$A:$A,"新豐9線",'0801 4度C'!$B:$B,"平均") -> 17.75 | M22: =SUMIFS('0801 4度C'!$I:$I,'0801 4度C'!$A:$A,"新豐4線",'0801 4度C'!$B:$B,"平均") -> 15.75
B23: 主要應用設備 | D23: ET-55 | E23: 熱縮爐 | F23: L型包裝機 | G23: L型包裝機 | H23: 伺服包裝機 | I23: ET-55 | J23: 伺服包裝機 | K23: 三明治包裝機 | L23: 三明治包裝機 | M23: 三明治包裝機
B24: 次要應用設備 | F24: 圓盤機 | G24: ET-55
B25: 備註 | E25: 握沙拉 | F25: 共用L型包裝機 | H25: 調理麵包 | I25: 炒飯+沙拉 | J25: 調理麵包

Sheet 0801 4度C
A1: 新豐廠四度C日報分析 | C1: 總生產量 | D1: =SUM(F5:F71) -> 162409 | E1: 營業額 | F1: =SUM(G5:G71) -> 5699318.4 | G1: 出勤人數 | H1: =L8+L14+L47+L57+L22+L62+L37+L42+L29+L71 -> 155.43492 | I1: 產線配置圖 | L1: 生產實績 | O1: 人時性差異分析 | S1: 日報登錄 | Y1: 合計 次數 | Z1: 合計 時間/分 | AA1: 產線異常 分析說明(5分鐘以上) | AC1: 合計 次數 | AD1: 合計 設備次數 | AE1: 產能差異分析
A2: 46235 | B2: 星期六 | C2: 人時性 | D2: =AVERAGE(N8,N14,N47,N57,N22,N62,N29,N37,N42,N71) -> 151.38653 | E2: 平均廠價 | F2: =F1/D1 -> 35.09238 | G2: 多次生產數 | H2: =COUNT(H5:H71) -> 4 | Y2: =SUM(Y8+Y14+Y22+Y29+Y37+Y42+Y47+Y57+Y62+Y71) -> 0 | Z2: =SUM(Z8+Z14+Z22+Z29+Z37+Z42+Z47+Z57+Z62+Z71) -> 0 | AC2: 57 | AD2: =SUM(AD8+AD14+AD22+AD29+AD37+AD42+AD47+AD57+AD62+AD71) -> 0
A3: 線別 | B3: 品類 | C3: 品名 | E3: 廠價 | F3: 生產量 | G3: 營收 | H3: 多次 生產 | I3: 人數 | J3: 產能/時 | K3: 人時性 | L3: 人數 | M3: 產能/時 | N3: 人時性 | O3: 人數 | P3: 人時性 | Q3: 達成率 | R3: 達成率平均 | S3: 生產時間 | U3: 換線、休息/分 | V3: 稼動時間/分 | W3: 休息時間 | Y3: 產線異常統計 (5分鐘以上) | AA3: (新豐回填) | AC3: 短暫停線統計 (5分鐘以下) | AE3: 產能/時 | AF3: 達成率 | AG3: 達成率平均
S4: 開始 | T4: 結束 | W4: 開始 | X4: 結束 | Y4: 次數 | Z4: 時間/分 | AC4: 總次數 | AD4: 設備因素(次數)
A5: 新豐6線 | B5: 微波主食 | C5: 二配金咖哩果香甘口咖哩飯 | E5: 50.92 | F5: 2223 | G5: =E5*F5 -> 113195.16 | I5: 15 | J5: 2000 | K5: =J5/I5 -> 133.33333 | L5: 15 | M5: =F5/V5*60 -> 1905.4286 | N5: =M5/L5 -> 127.02857 | O5: =L5-I5 -> 0 | P5: =N5-K5 -> -6.3047619 | Q5: =N5/K5 -> 0.95271429 | R5: =Q8 -> 0.95564655 | S5: 0.70833333 | T5: 0.75694444 | V5: =(T5-S5)*24*60 -> 70 | AC5: 3 | AE5: =M5-J5 -> -94.571429 | AF5: =M5/J5 -> 0.95271429 | AG5: =AF8 -> 0.95564655
A6: 新豐6線 | B6: 微波主食 | C6: 二配金咖哩濃厚辛口咖哩飯 | E6: 50.98 | F6: 2282 | G6: =E6*F6 -> 116336.36 | I6: 16 | J6: 2000 | K6: =J6/I6 -> 125 | L6: 16 | M6: =F6/V6*60 -> 1928.4507 | N6: =M6/L6 -> 120.52817 | O6: =L6-I6 -> 0 | P6: =N6-K6 -> -4.471831 | Q6: =N6/K6 -> 0.96422535 | S6: 0.76111111 | T6: 0.81041667 | U6: =IF(S6=TIME(17,0,0),"",(S6-T5)*24*60) -> 6 | V6: =(T6-S6)*24*60 -> 71 | AE6: =M6-J6 -> -71.549296 | AF6: =M6/J6 -> 0.96422535
A7: 新豐6線 | B7: 微波主食 | C7: 二配泰式綠咖哩雞 | E7: 50.67 | F7: 1330 | G7: =E7*F7 -> 67391.1 | I7: 15 | J7: 2000 | K7: =J7/I7 -> 133.33333 | L7: 15 | M7: =F7/V7*60 -> 1900 | N7: =M7/L7 -> 126.66667 | O7: =L7-I7 -> 0 | P7: =N7-K7 -> -6.6666667 | Q7: =N7/K7 -> 0.95 | S7: 0.81458333 | T7: 0.84375 | U7: =IF(S7=TIME(17,0,0),"",(S7-T6)*24*60) -> 6 | V7: =(T7-S7)*24*60 -> 42 | AE7: =M7-J7 -> -100 | AF7: =M7/J7 -> 0.95
A8: 新豐6線 | B8: 平均 | I8: 15.333333 | J8: 2000 | K8: =J8/I8 -> 130.43478 | L8: 15.333333 | M8: =AVERAGE(M5:M7) -> 1911.2931 | N8: =M8/L8 -> 124.64955 | O8: =L8-I8 -> 0 | P8: =N8-K8 -> -5.7852331 | Q8: =N8/K8 -> 0.95564655 | Y8: =SUM(Y5:Y7) -> 0 | Z8: =SUM(Z5:Z7) -> 0 | AC8: 3 | AD8: 0 | AE8: =M8-J8 -> -88.706908 | AF8: =M8/J8 -> 0.95564655
A9: 新豐2線 | B9: 沙拉 | C9: 青檸烤雞握沙拉(113年) | E9: 39.8 | F9: 6002 | G9: =E9*F9 -> 238879.6 | I9: 17 | J9: 1500 | K9: =J9/I9 -> 88.235294 | L9: 17 | M9: =F9/V9*60 -> 1429.0476 | N9: =M9/L9 -> 84.061625 | O9: =L9-I9 -> 0 | P9: =N9-K9 -> -4.1736695 | Q9: =N9/K9 -> 0.95269841 | R9: =Q14 -> 0.95753597 | S9: 0.083333333 | T9: 0.25833333 | V9: =(T9-S9)*24*60 -> 252 | W9: =T9 -> 0.25833333 | X9: =S10 -> 0.27777778 | AC9: 5 | AE9: =M9-J9 -> -70.952381 | AF9: =M9/J9 -> 0.95269841 | AG9: =AF14 -> 0.95753597
A10: 新豐2線 | B10: 沙拉 | C10: 厚蛋時蔬握沙拉 | E10: 39.46 | F10: 2427 | G10: =E10*F10 -> 95769.42 | I10: 15 | J10: 1500 | K10: =J10/I10 -> 100 | L10: 15 | M10: =F10/V10*60 -> 1441.7822 | N10: =M10/L10 -> 96.118812 | O10: =L10-I10 -> 0 | P10: =N10-K10 -> -3.8811881 | Q10: =N10/K10 -> 0.96118812 | S10: 0.27777778 | T10: 0.34791667 | U10: =IF(S10=TIME(17,0,0),"",(S10-T9)*24*60) -> 28 | V10: =(T10-S10)*24*60 -> 101 | AE10: =M10-J10 -> -58.217822 | AF10: =M10/J10 -> 0.96118812
A11: 新豐2線 | B11: 沙拉 | C11: 地瓜瓜握沙拉 | E11: 39.52 | F11: 2036 | G11: =E11*F11 -> 80462.72 | I11: 19 | J11: 1500 | K11: =J11/I11 -> 78.947368 | L11: 19 | M11: =F11/V11*60 -> 1437.1765 | N11: =M11/L11 -> 75.640867 | O11: =L11-I11 -> 0 | P11: =N11-K11 -> -3.3065015 | Q11: =N11/K11 -> 0.95811765 | S11: 0.35347222 | T11: 0.4125 | U11: =IF(S11=TIME(17,0,0),"",(S11-T10)*24*60) -> 8 | V11: =(T11-S11)*24*60 -> 85 | AE11: =M11-J11 -> -62.823529 | AF11: =M11/J11 -> 0.95811765
A12: 新豐2線 | B12: 沙拉 | C12: 青醬優格雞肉握沙拉(113年) | E12: 39.62 | F12: 2400 | G12: =E12*F12 -> 95088 | H12: 2 | I12: 19 | J12: 1500 | K12: =J12/I12 -> 78.947368 | L12: 19 | M12: =F12/V12*60 -> 1440 | N12: =M12/L12 -> 75.789474 | O12: =L12-I12 -> 0 | P12: =N12-K12 -> -3.1578947 | Q12: =N12/K12 -> 0.96 | S12: 0.41805556 | T12: 0.4875 | U12: =IF(S12=TIME(17,0,0),"",(S12-T11)*24*60) -> 8 | V12: =(T12-S12)*24*60 -> 100 | W12: =T12 -> 0.4875 | X12: =S13 -> 0.52916667 | AE12: =M12-J12 -> -60 | AF12: =M12/J12 -> 0.96
A13: 新豐2線 | B13: 沙拉 | C13: 青醬優格雞肉握沙拉(113年) | E13: 39.62 | F13: 1768 | G13: =E13*F13 -> 70048.16 | I13: 19 | J13: 1500 | K13: =J13/I13 -> 78.947368 | L13: 19 | M13: =F13/V13*60 -> 1433.5135 | N13: =M13/L13 -> 75.44808 | O13: =L13-I13 -> 0 | P13: =N13-K13 -> -3.4992888 | Q13: =N13/K13 -> 0.95567568 | S13: 0.52916667 | T13: 0.58055556 | U13: =IF(S13=TIME(17,0,0),"",(S13-T12)*24*60) -> 60 | V13: =(T13-S13)*24*60 -> 74 | AE13: =M13-J13 -> -66.486486 | AF13: =M13/J13 -> 0.95567568
A14: 新豐2線 | B14: 平均 | I14: 17.8 | J14: 1500 | K14: =J14/I14 -> 84.269663 | L14: 17.8 | M14: =AVERAGE(M9:M13) -> 1436.304 | N14: =M14/L14 -> 80.691233 | O14: =L14-I14 -> 0 | P14: =N14-K14 -> -3.5784294 | Q14: =N14/K14 -> 0.95753597 | Y14: =SUM(Y9:Y13) -> 0 | Z14: =SUM(Z9:Z13) -> 0 | AC14: 5 | AD14: 0 | AE14: =M14-J14 -> -63.696044 | AF14: =M14/J14 -> 0.95753597
A15: 新豐5線 | B15: 季節調理麵 | C15: 台式麻醬涼麵(115年) | E15: 31.11 | F15: 3398 | G15: =E15*F15 -> 105711.78 | I15: 14 | J15: 2000 | K15: =J15/I15 -> 142.85714 | L15: 14 | M15: =F15/V15*60 -> 1905.4206 | N15: =M15/L15 -> 136.10147 | O15: =L15-I15 -> 0 | P15: =N15-K15 -> -6.7556742 | Q15: =N15/K15 -> 0.95271028 | R15: =Q22 -> 0.95653944 | S15: 0.083333333 | T15: 0.15763889 | V15: =(T15-S15)*24*60 -> 107 | W15: =T15 -> 0.15763889 | X15: =S16 -> 0.17638889 | AC15: 7 | AE15: =M15-J15 -> -94.579439 | AF15: =M15/J15 -> 0.95271028 | AG15: =AF22 -> 0.95653944
A16: 新豐5線 | B16: 小吃 | C16: 香菇雞燉湯 | E16: 38.62 | F16: 1857 | G16: =E16*F16 -> 71717.34 | I16: 24 | J16: 1500 | K16: =J16/I16 -> 62.5 | L16: 24 | M16: =F16/V16*60 -> 1428.4615 | N16: =M16/L16 -> 59.519231 | O16: =L16-I16 -> 0 | P16: =N16-K16 -> -2.9807692 | Q16: =N16/K16 -> 0.95230769 | S16: 0.17638889 | T16: 0.23055556 | U16: =IF(S16=TIME(17,0,0),"",(S16-T15)*24*60) -> 27 | V16: =(T16-S16)*24*60 -> 78 | AE16: =M16-J16 -> -71.538462 | AF16: =M16/J16 -> 0.95230769
A17: 新豐5線 | B17: 小吃 | C17: 剝皮辣椒雞湯 | E17: 41 | F17: 1447 | G17: =E17*F17 -> 59327 | I17: 26 | J17: 1500 | K17: =J17/I17 -> 57.692308 | L17: 26 | M17: =F17/V17*60 -> 1447 | N17: =M17/L17 -> 55.653846 | O17: =L17-I17 -> 0 | P17: =N17-K17 -> -2.0384615 | Q17: =N17/K17 -> 0.96466667 | S17: 0.23541667 | T17: 0.27708333 | U17: =IF(S17=TIME(17,0,0),"",(S17-T16)*24*60) -> 7 | V17: =(T17-S17)*24*60 -> 60 | AE17: =M17-J17 -> -53 | AF17: =M17/J17 -> 0.96466667
A18: 新豐5線 | B18: 微波主食 | C18: 香菇雞粥 | E18: 37.03 | F18: 2599 | G18: =E18*F18 -> 96240.97 | I18: 13 | J18: 1500 | K18: =J18/I18 -> 115.38462 | L18: 13 | M18: =F18/V18*60 -> 1430.6422 | N18: =M18/L18 -> 110.0494 | O18: =L18-I18 -> 0 | P18: =N18-K18 -> -5.3352152 | Q18: =N18/K18 -> 0.95376147 | S18: 0.28125 | T18: 0.35694444 | U18: =IF(S18=TIME(17,0,0),"",(S18-T17)*24*60) -> 6 | V18: =(T18-S18)*24*60 -> 109 | AE18: =M18-J18 -> -69.357798 | AF18: =M18/J18 -> 0.95376147
A19: 新豐5線 | B19: 微波主食 | C19: 二配港式香滑嫩蛋牛肉燴飯 | E19: 50.67 | F19: 1570 | G19: =E19*F19 -> 79551.9 | I19: 17 | J19: 2000 | K19: =J19/I19 -> 117.64706 | L19: 17 | M19: =F19/V19*60 -> 1922.449 | N19: =M19/L19 -> 113.08523 | O19: =L19-I19 -> 0 | P19: =N19-K19 -> -4.5618247 | Q19: =N19/K19 -> 0.96122449 | S19: 0.70833333 | T19: 0.74236111 | U19: =IF(S19=TIME(17,0,0),"",(S19-T18)*24*60) | V19: =(T19-S19)*24*60 -> 49 | AE19: =M19-J19 -> -77.55102 | AF19: =M19/J19 -> 0.96122449
A20: 新豐5線 | B20: 微波主食 | C20: 二配玉米濃湯焗烤飯 | E20: 54.5 | F20: 1906 | G20: =E20*F20 -> 103877 | I20: 20 | J20: 1500 | K20: =J20/I20 -> 75 | L20: 20 | M20: =F20/V20*60 -> 1429.5 | N20: =M20/L20 -> 71.475 | O20: =L20-I20 -> 0 | P20: =N20-K20 -> -3.525 | Q20: =N20/K20 -> 0.953 | S20: 0.74722222 | T20: 0.80277778 | U20: =IF(S20=TIME(17,0,0),"",(S20-T19)*24*60) -> 7 | V20: =(T20-S20)*24*60 -> 80 | AE20: =M20-J20 -> -70.5 | AF20: =M20/J20 -> 0.953
A21: 新豐5線 | B21: 微波主食 | C21: 二配川味麻婆燒豆腐燴飯 | E21: 50.49 | F21: 1915 | G21: =E21*F21 -> 96688.35 | I21: 15 | J21: 2000 | K21: =J21/I21 -> 133.33333 | L21: 15 | M21: =F21/V21*60 -> 1915 | N21: =M21/L21 -> 127.66667 | O21: =L21-I21 -> 0 | P21: =N21-K21 -> -5.6666667 | Q21: =N21/K21 -> 0.9575 | S21: 0.80763889 | T21: 0.84930556 | U21: =IF(S21=TIME(17,0,0),"",(S21-T20)*24*60) -> 7 | V21: =(T21-S21)*24*60 -> 60 | AE21: =M21-J21 -> -85 | AF21: =M21/J21 -> 0.9575
A22: 新豐5線 | B22: 平均 | I22: 18.428571 | J22: 1714.2857 | K22: =J22/I22 -> 93.023256 | L22: 18.428571 | M22: =AVERAGE(M15:M21) -> 1639.7819 | N22: =M22/L22 -> 88.980413 | O22: =L22-I22 -> 0 | P22: =N22-K22 -> -4.0428428 | Q22: =N22/K22 -> 0.95653944 | Y22: =SUM(Y15:Y21) -> 0 | Z22: =SUM(Z15:Z21) -> 0 | AC22: 7 | AD22: 0 | AE22: =M22-J22 -> -74.503817 | AF22: =M22/J22 -> 0.95653944
A23: 新豐7線 | B23: 微波主食 | C23: 韓式泡菜豬肉豆腐丼飯 | E23: 50.67 | F23: 1455 | G23: =E23*F23 -> 73724.85 | I23: 17 | J23: 2000 | K23: =J23/I23 -> 117.64706 | L23: 17 | M23: =F23/V23*60 -> 1940 | N23: =M23/L23 -> 114.11765 | O23: =L23-I23 -> 0 | P23: =N23-K23 -> -3.5294118 | Q23: =N23/K23 -> 0.97 | R23: =Q29 -> 0.95783708 | S23: 0.20833333 | T23: 0.23958333 | V23: =(T23-S23)*24*60 -> 45 | AC23: 6 | AE23: =M23-J23 -> -60 | AF23: =M23/J23 -> 0.97 | AG23: =AF29 -> 0.95783708
A24: 新豐7線 | B24: 微波主食 | C24: 鐵板滑蛋炸豬排丼 | E24: 57.73 | F24: 2069 | G24: =E24*F24 -> 119443.37 | I24: 14 | J24: 2000 | K24: =J24/I24 -> 142.85714 | L24: 14 | M24: =F24/V24*60 -> 1909.8462 | N24: =M24/L24 -> 136.41758 | O24: =L24-I24 -> 0 | P24: =N24-K24 -> -6.4395604 | Q24: =N24/K24 -> 0.95492308 | S24: 0.24375 | T24: 0.28888889 | U24: =IF(S24=TIME(17,0,0),"",(S24-T23)*24*60) -> 6 | V24: =(T24-S24)*24*60 -> 65 | AE24: =M24-J24 -> -90.153846 | AF24: =M24/J24 -> 0.95492308
A25: 新豐7線 | B25: 微波主食 | C25: 日式炙烤親子丼 | E25: 53.27 | F25: 1121 | G25: =E25*F25 -> 59715.67 | I25: 16 | J25: 2000 | K25: =J25/I25 -> 125 | L25: 16 | M25: =F25/V25*60 -> 1921.7143 | N25: =M25/L25 -> 120.10714 | O25: =L25-I25 -> 0 | P25: =N25-K25 -> -4.8928571 | Q25: =N25/K25 -> 0.96085714 | S25: 0.29444444 | T25: 0.31875 | U25: =IF(S25=TIME(17,0,0),"",(S25-T24)*24*60) -> 8 | V25: =(T25-S25)*24*60 -> 35 | AE25: =M25-J25 -> -78.285714 | AF25: =M25/J25 -> 0.96085714
A26: 新豐7線 | B26: 微波主食 | C26: 二配厚香料優格咖哩雞排飯 | E26: 56.43 | F26: 1400 | G26: =E26*F26 -> 79002 | I26: 13 | J26: 2000 | K26: =J26/I26 -> 153.84615 | L26: 13 | M26: =F26/V26*60 -> 1909.0909 | N26: =M26/L26 -> 146.85315 | O26: =L26-I26 -> 0 | P26: =N26-K26 -> -6.993007 | Q26: =N26/K26 -> 0.95454545 | S26: 0.70833333 | T26: 0.73888889 | U26: =IF(S26=TIME(17,0,0),"",(S26-T25)*24*60) | V26: =(T26-S26)*24*60 -> 44 | AE26: =M26-J26 -> -90.909091 | AF26: =M26/J26 -> 0.95454545
A27: 新豐7線 | B27: 微波主食 | C27: 二配美味蟹煲 | E27: 54.09 | F27: 2503 | G27: =E27*F27 -> 135387.27 | I27: 18 | J27: 2000 | K27: =J27/I27 -> 111.11111 | L27: 18 | M27: =F27/V27*60 -> 1901.0127 | N27: =M27/L27 -> 105.61181 | O27: =L27-I27 -> 0 | P27: =N27-K27 -> -5.4992968 | Q27: =N27/K27 -> 0.95050633 | S27: 0.74236111 | T27: 0.79722222 | U27: =IF(S27=TIME(17,0,0),"",(S27-T26)*24*60) -> 5 | V27: =(T27-S27)*24*60 -> 79 | AE27: =M27-J27 -> -98.987342 | AF27: =M27/J27 -> 0.95050633
A28: 新豐7線 | B28: 微波主食 | C28: 二配泰式檸檬魚飯 | E28: 57.3 | F28: 2008 | G28: =E28*F28 -> 115058.4 | I28: 16 | J28: 2000 | K28: =J28/I28 -> 125 | L28: 16 | M28: =F28/V28*60 -> 1912.381 | N28: =M28/L28 -> 119.52381 | O28: =L28-I28 -> 0 | P28: =N28-K28 -> -5.4761905 | Q28: =N28/K28 -> 0.95619048 | S28: 0.80277778 | T28: 0.84652778 | U28: =IF(S28=TIME(17,0,0),"",(S28-T27)*24*60) -> 8 | V28: =(T28-S28)*24*60 -> 63 | AE28: =M28-J28 -> -87.619048 | AF28: =M28/J28 -> 0.95619048
A29: 新豐7線 | B29: 平均 | I29: 15.666667 | J29: 2000 | K29: =J29/I29 -> 127.65957 | L29: 15.666667 | M29: =AVERAGE(M23:M28) -> 1915.6742 | N29: =M29/L29 -> 122.27707 | O29: =L29-I29 -> 0 | P29: =N29-K29 -> -5.3825004 | Q29: =N29/K29 -> 0.95783708 | Y29: =SUM(Y23:Y28) -> 0 | Z29: =SUM(Z23:Z28) -> 0 | AC29: 6 | AD29: 0 | AE29: =M29-J29 -> -84.32584 | AF29: =M29/J29 -> 0.95783708
A30: 新豐8線 | B30: 三明治 | C30: 紐奧良風味烤雞鮮蔬三明治 | E30: 31.29 | F30: 4500 | G30: =E30*F30 -> 140805 | H30: 2 | I30: 18 | J30: 2400 | K30: =J30/I30 -> 133.33333 | L30: 18 | M30: =F30/V30*60 -> 2288.1356 | N30: =M30/L30 -> 127.11864 | O30: =L30-I30 -> 0 | P30: =N30-K30 -> -6.2146893 | Q30: =N30/K30 -> 0.95338983 | R30: =Q37 -> 0.96015522 | S30: 0.083333333 | T30: 0.16527778 | V30: =(T30-S30)*24*60 -> 118 | W30: =T30 -> 0.16527778 | X30: =S31 -> 0.18333333 | AC30: 7 | AE30: =M30-J30 -> -111.86441 | AF30: =M30/J30 -> 0.95338983 | AG30: =AF37 -> 0.96015522
A31: 新豐8線 | B31: 三明治 | C31: 醬燒烤雞三明治(115年) | E31: 26.37 | F31: 5311 | G31: =E31*F31 -> 140051.07 | I31: 18 | J31: 2400 | K31: =J31/I31 -> 133.33333 | L31: 18 | M31: =F31/V31*60 -> 2292.518 | N31: =M31/L31 -> 127.36211 | O31: =L31-I31 -> 0 | P31: =N31-K31 -> -5.971223 | Q31: =N31/K31 -> 0.95521583 | S31: 0.18333333 | T31: 0.27986111 | U31: =(S31-T30)*24*60 -> 26 | V31: =(T31-S31)*24*60 -> 139 | AE31: =M31-J31 -> -107.48201 | AF31: =M31/J31 -> 0.95521583
A32: 新豐8線 | B32: 三明治 | C32: 鮪魚起司溏心蛋三明治(115年) | E32: 26.18 | F32: 6803 | G32: =E32*F32 -> 178102.54 | I32: 18 | J32: 2400 | K32: =J32/I32 -> 133.33333 | L32: 18 | M32: =F32/V32*60 -> 2293.1461 | N32: =M32/L32 -> 127.397 | O32: =L32-I32 -> 0 | P32: =N32-K32 -> -5.9363296 | Q32: =N32/K32 -> 0.95547753 | S32: 0.28333333 | T32: 0.40694444 | U32: =(S32-T31)*24*60 -> 5 | V32: =(T32-S32)*24*60 -> 178 | AE32: =M32-J32 -> -106.85393 | AF32: =M32/J32 -> 0.95547753
A33: 新豐8線 | B33: 三明治 | C33: 茄汁厚起司三明治 | E33: 25.99 | F33: 908 | G33: =E33*F33 -> 23598.92 | I33: 18 | J33: 2400 | K33: =J33/I33 -> 133.33333 | L33: 18 | M33: =F33/V33*60 -> 2368.6957 | N33: =M33/L33 -> 131.5942 | O33: =L33-I33 -> 0 | P33: =N33-K33 -> -1.7391304 | Q33: =N33/K33 -> 0.98695652 | S33: 0.41041667 | T33: 0.42638889 | U33: =(S33-T32)*24*60 -> 5 | V33: =(T33-S33)*24*60 -> 23 | AE33: =M33-J33 -> -31.304348 | AF33: =M33/J33 -> 0.98695652
A34: 新豐8線 | B34: 三明治 | C34: 雞蛋沙拉三明治(114年) | E34: 25.99 | F34: 3100 | G34: =E34*F34 -> 80569 | I34: 14 | J34: 2400 | K34: =J34/I34 -> 171.42857 | L34: 14 | M34: =F34/V34*60 -> 2296.2963 | N34: =M34/L34 -> 164.02116 | O34: =L34-I34 -> 0 | P34: =N34-K34 -> -7.4074074 | Q34: =N34/K34 -> 0.95679012 | S34: 0.42986111 | T34: 0.48611111 | U34: =(S34-T33)*24*60 -> 5 | V34: =(T34-S34)*24*60 -> 81 | AE34: =M34-J34 -> -103.7037 | AF34: =M34/J34 -> 0.95679012
A35: 新豐8線 | B35: 三明治 | C35: 榛果摩卡脆脆三明治 | E35: 20.21 | F35: 1723 | G35: =E35*F35 -> 34821.83 | I35: 18 | J35: 2400 | K35: =J35/I35 -> 133.33333 | L35: 18 | M35: =F35/V35*60 -> 2297.3333 | N35: =M35/L35 -> 127.62963 | O35: =L35-I35 -> 0 | P35: =N35-K35 -> -5.7037037 | Q35: =N35/K35 -> 0.95722222 | S35: 0.48958333 | T35: 0.52083333 | U35: =(S35-T34)*24*60 -> 5 | V35: =(T35-S35)*24*60 -> 45 | W35: =T35 -> 0.52083333 | X35: =S36 -> 0.5625 | AE35: =M35-J35 -> -102.66667 | AF35: =M35/J35 -> 0.95722222
A36: 新豐8線 | B36: 三明治 | C36: 紐奧良風味烤雞鮮蔬三明治 | E36: 31.29 | F36: 3327 | G36: =E36*F36 -> 104101.83 | I36: 18 | J36: 2400 | K36: =J36/I36 -> 133.33333 | L36: 18 | M36: =F36/V36*60 -> 2294.4828 | N36: =M36/L36 -> 127.47126 | O36: =L36-I36 -> 0 | P36: =N36-K36 -> -5.862069 | Q36: =N36/K36 -> 0.95603448 | S36: 0.5625 | T36: 0.62291667 | U36: =(S36-T35)*24*60 -> 60 | V36: =(T36-S36)*24*60 -> 87 | AE36: =M36-J36 -> -105.51724 | AF36: =M36/J36 -> 0.95603448
A37: 新豐8線 | B37: 平均 | I37: 17.428571 | J37: 2400 | K37: =J37/I37 -> 137.70492 | L37: 17.428571 | M37: =AVERAGE(M30:M36) -> 2304.3725 | N37: =M37/L37 -> 132.2181 | O37: =L37-I37 -> 0 | P37: =N37-K37 -> -5.4868222 | Q37: =N37/K37 -> 0.96015522 | Y37: =SUM(Y30:Y36) -> 0 | Z37: =SUM(Z30:Z36) -> 0 | AC37: 7 | AD37: 0 | AE37: =M37-J37 -> -95.627473 | AF37: =M37/J37 -> 0.96015522
A38: 新豐9線 | B38: 三明治 | C38: 經典總匯三明治(115年) | E38: 26.18 | F38: 5011 | G38: =E38*F38 -> 131187.98 | I38: 20 | J38: 2400 | K38: =J38/I38 -> 120 | L38: 20 | M38: =F38/V38*60 -> 2295.1145 | N38: =M38/L38 -> 114.75573 | O38: =L38-I38 -> 0 | P38: =N38-K38 -> -5.2442748 | Q38: =N38/K38 -> 0.95629771 | R38: =Q42 -> 0.95753346 | S38: 0.083333333 | T38: 0.17430556 | V38: =(T38-S38)*24*60 -> 131 | W38: =T38 -> 0.17430556 | X38: =S39 -> 0.19444444 | AC38: 4 | AE38: =M38-J38 -> -104.8855 | AF38: =M38/J38 -> 0.95629771 | AG38: =AF42 -> 0.95753346
A39: 新豐9線 | B39: 三明治 | C39: 經典火腿玉米蛋三明治 | E39: 24.43 | F39: 6013 | G39: =E39*F39 -> 146897.59 | I39: 14 | J39: 2400 | K39: =J39/I39 -> 171.42857 | L39: 14 | M39: =F39/V39*60 -> 2297.9618 | N39: =M39/L39 -> 164.14013 | O39: =L39-I39 -> 0 | P39: =N39-K39 -> -7.288444 | Q39: =N39/K39 -> 0.95748408 | S39: 0.19444444 | T39: 0.30347222 | U39: =(S39-T38)*24*60 -> 29 | V39: =(T39-S39)*24*60 -> 157 | AE39: =M39-J39 -> -102.03822 | AF39: =M39/J39 -> 0.95748408
A40: 新豐9線 | B40: 三明治 | C40: 五彩鮮蔬三明治 | E40: 25.98 | F40: 2800 | G40: =E40*F40 -> 72744 | I40: 20 | J40: 2400 | K40: =J40/I40 -> 120 | L40: 20 | M40: =F40/V40*60 -> 2301.3699 | N40: =M40/L40 -> 115.06849 | O40: =L40-I40 -> 0 | P40: =N40-K40 -> -4.9315068 | Q40: =N40/K40 -> 0.95890411 | S40: 0.30763889 | T40: 0.35833333 | U40: =(S40-T39)*24*60 -> 6 | V40: =(T40-S40)*24*60 -> 73 | AE40: =M40-J40 -> -98.630137 | AF40: =M40/J40 -> 0.95890411
...
