Workbook

Sheet 0831
B1: 屏榮 新豐廠組合室生產人時性分析
B3: 日期 | C3: =TEXT('0831 4度C'!A2,"yyyy.mm.ddaaaa") -> 2026.08.31星期一 | E3: 訂單量 | F3: ='0831 4度C'!D1 -> 188787 | H3: 營業額 | I3: ='0831 4度C'!F1 -> 6748732.9
B4: 人時性 | C4: 項目 | E4: ➀ | G4: ➁ | I4: ➂ | K4: 異常停線 | M4: 短暫停線
C5: 組合室 | E5: 全溫層 | G5: 4度C-各編組展開 | I5: ③三明治-各編組展開 | K5: 合計次數 | L5: 時間 | M5: 合計次數 | N5: 設備次數
C6: 排關平均 | E6: =AVERAGE(D13:M13) -> 156.32947 | F6: =AVERAGE(D31:O31,D13:J13) -> 163.93399 | G6: =AVERAGE(D13:J13) -> 163.93399 | I6: =AVERAGE(K13:M13) -> 138.58559 | K6: ='0831 4度C'!Y2 -> 0 | L6: ='0831 4度C'!Z2 -> 0 | M6: ='0831 4度C'!AC2 -> 61 | N6: ='0831 4度C'!AD2 -> 0
C7: 實績平均 | E7: =AVERAGE(D14:M14) -> 149.73016 | F7: =AVERAGE(D32:O32,D14:J14) -> 157.04748 | G7: =AVERAGE(D14:J14) -> 157.04748 | I7: =AVERAGE(K14:M14) -> 132.65642
C8: 達成率平均 | E8: =AVERAGE(D15:M15) -> 0.95811089 | F8: =AVERAGE(D15:J15,D33:O33) -> 0.95854161 | G8: =AVERAGE(D15:J15) -> 0.95854161 | I8: =AVERAGE(K15:M15) -> 0.95710587
K9: ※現行日本鮮食廠以達成率80%為基本(即為現行KPI)
B10: 溫層 | D10: ➁4度C-各編組展開 | K10: ③三明治-各編組展開
B11: 編組 | D11: 1 | E11: 2 | F11: 3 | G11: 4 | H11: 5 | I11: 6 | J11: 7 | K11: 1 | L11: 2 | M11: 3
D12: 新豐6線 | E12: 新豐2線 | F12: 新豐5線 | G12: 新豐7線 | H12: 新豐3線 | I12: 新豐1線 | J12: 新豐10線 | K12: 新豐8線 | L12: 新豐9線 | M12: 新豐4線
B13: 人時性 | C13: 排關 | D13: =SUMIFS('0831 4度C'!$K:$K,'0831 4度C'!$A:$A,"新豐6線",'0831 4度C'!$B:$B,"平均") -> 135.59322 | E13: =SUMIFS('0831 4度C'!$K:$K,'0831 4度C'!$A:$A,"新豐2線",'0831 4度C'!$B:$B,"平均") -> 81.081081 | F13: =SUMIFS('0831 4度C'!$K:$K,'0831 4度C'!$A:$A,"新豐5線",'0831 4度C'!$B:$B,"平均") -> 106.61765 | G13: =SUMIFS('0831 4度C'!$K:$K,'0831 4度C'!$A:$A,"新豐7線",'0831 4度C'!$B:$B,"平均") -> 128 | H13: =SUMIFS('0831 4度C'!$K:$K,'0831 4度C'!$A:$A,"新豐3線",'0831 4度C'!$B:$B,"平均") -> 300 | I13: =SUMIFS('0831 4度C'!$K:$K,'0831 4度C'!$A:$A,"新豐1線",'0831 4度C'!$B:$B,"平均") -> 107.78443 | J13: =SUMIFS('0831 4度C'!$K:$K,'0831 4度C'!$A:$A,"新豐10線",'0831 4度C'!$B:$B,"平均") -> 288.46154 | K13: =SUMIFS('0831 4度C'!$K:$K,'0831 4度C'!$A:$A,"新豐8線",'0831 4度C'!$B:$B,"平均") -> 125.4902 | L13: =SUMIFS('0831 4度C'!$K:$K,'0831 4度C'!$A:$A,"新豐9線",'0831 4度C'!$B:$B,"平均") -> 147.69231 | M13: =SUMIFS('0831 4度C'!$K:$K,'0831 4度C'!$A:$A,"新豐4線",'0831 4度C'!$B:$B,"平均") -> 142.57426
C14: 實績 | D14: =SUMIFS('0831 4度C'!$N:$N,'0831 4度C'!$A:$A,"新豐6線",'0831 4度C'!$B:$B,"平均") -> 130.48099 | E14: =SUMIFS('0831 4度C'!$N:$N,'0831 4度C'!$A:$A,"新豐2線",'0831 4度C'!$B:$B,"平均") -> 77.595821 | F14: =SUMIFS('0831 4度C'!$N:$N,'0831 4度C'!$A:$A,"新豐5線",'0831 4度C'!$B:$B,"平均") -> 102.11329 | G14: =SUMIFS('0831 4度C'!$N:$N,'0831 4度C'!$A:$A,"新豐7線",'0831 4度C'!$B:$B,"平均") -> 122.72052 | H14: =SUMIFS('0831 4度C'!$N:$N,'0831 4度C'!$A:$A,"新豐3線",'0831 4度C'!$B:$B,"平均") -> 286.93747 | I14: =SUMIFS('0831 4度C'!$N:$N,'0831 4度C'!$A:$A,"新豐1線",'0831 4度C'!$B:$B,"平均") -> 103.5893 | J14: =SUMIFS('0831 4度C'!$N:$N,'0831 4度C'!$A:$A,"新豐10線",'0831 4度C'!$B:$B,"平均") -> 275.89494 | K14: =SUMIFS('0831 4度C'!$N:$N,'0831 4度C'!$A:$A,"新豐8線",'0831 4度C'!$B:$B,"平均") -> 119.83564 | L14: =SUMIFS('0831 4度C'!$N:$N,'0831 4度C'!$A:$A,"新豐9線",'0831 4度C'!$B:$B,"平均") -> 141.61739 | M14: =SUMIFS('0831 4度C'!$N:$N,'0831 4度C'!$A:$A,"新豐4線",'0831 4度C'!$B:$B,"平均") -> 136.51622
C15: 達成率 | D15: =D14/D13 -> 0.96229733 | E15: =E14/E13 -> 0.95701512 | F15: =F14/F13 -> 0.95775227 | G15: =G14/G13 -> 0.95875408 | H15: =H14/H13 -> 0.95645822 | I15: =I14/I13 -> 0.96107848 | J15: =J14/J13 -> 0.95643579 | K15: =K14/K13 -> 0.95494026 | ... M15: =M14/M13 -> 0.95750962
B16: 作業 時間 | C16: 開始 | D16: =VLOOKUP("新豐6線",'0831 4度C'!$A:$T,19,0) -> 0.70833333 | E16: =VLOOKUP("新豐2線",'0831 4度C'!$A:$T,19,0) -> 0.083333333 | F16: =VLOOKUP("新豐5線",'0831 4度C'!$A:$T,19,0) -> 0.20833333 | G16: =VLOOKUP("新豐7線",'0831 4度C'!$A:$T,19,0) -> 0.20833333 | H16: =VLOOKUP("新豐3線",'0831 4度C'!$A:$T,19,0) -> 0.20833333 | I16: =VLOOKUP("新豐1線",'0831 4度C'!$A:$T,19,0) -> 0.20833333 | J16: =VLOOKUP("新豐10線",'0831 4度C'!$A:$T,19,0) -> 0.20833333 | K16: =VLOOKUP("新豐8線",'0831 4度C'!$A:$T,19,0) -> 0.083333333 | L16: =VLOOKUP("新豐9線",'0831 4度C'!$A:$T,19,0) -> 0.083333333 | M16: =VLOOKUP("新豐4線",'0831 4度C'!$A:$T,19,0) -> 0.083333333
C17: 結束 | D17: =LOOKUP(2,1/(('0831 4度C'!$A:$A="新豐6線")*('0831 4度C'!$T:$T<>"")),'0831 4度C'!$T:$T) -> 0.92291667 | E17: =LOOKUP(2,1/(('0831 4度C'!$A:$A="新豐2線")*('0831 4度C'!$T:$T<>"")),'0831 4度C'!$T:$T) -> 0.56875 | F17: =LOOKUP(2,1/(('0831 4度C'!$A:$A="新豐5線")*('0831 4度C'!$T:$T<>"")),'0831 4度C'!$T:$T) -> 0.95277778 | G17: =LOOKUP(2,1/(('0831 4度C'!$A:$A="新豐7線")*('0831 4度C'!$T:$T<>"")),'0831 4度C'!$T:$T) -> 0.93125 | H17: =LOOKUP(2,1/(('0831 4度C'!$A:$A="新豐3線")*('0831 4度C'!$T:$T<>"")),'0831 4度C'!$T:$T) -> 0.44930556 | I17: =LOOKUP(2,1/(('0831 4度C'!$A:$A="新豐1線")*('0831 4度C'!$T:$T<>"")),'0831 4度C'!$T:$T) -> 0.90486111 | J17: =LOOKUP(2,1/(('0831 4度C'!$A:$A="新豐10線")*('0831 4度C'!$T:$T<>"")),'0831 4度C'!$T:$T) -> 0.46805556 | K17: =LOOKUP(2,1/(('0831 4度C'!$A:$A="新豐8線")*('0831 4度C'!$T:$T<>"")),'0831 4度C'!$T:$T) -> 0.72083333 | L17: =LOOKUP(2,1/(('0831 4度C'!$A:$A="新豐9線")*('0831 4度C'!$T:$T<>"")),'0831 4度C'!$T:$T) -> 0.69444444 | M17: =LOOKUP(2,1/(('0831 4度C'!$A:$A="新豐4線")*('0831 4度C'!$T:$T<>"")),'0831 4度C'!$T:$T) -> 0.62222222
B18: 產線異常 (5分鐘以上) | C18: 次數 | D18: =SUMIFS('0831 4度C'!$Y:$Y,'0831 4度C'!$A:$A,"新豐6線",'0831 4度C'!$B:$B,"平均") -> 0 | E18: =SUMIFS('0831 4度C'!$Y:$Y,'0831 4度C'!$A:$A,"新豐2線",'0831 4度C'!$B:$B,"平均") -> 0 | F18: =SUMIFS('0831 4度C'!$Y:$Y,'0831 4度C'!$A:$A,"新豐5線",'0831 4度C'!$B:$B,"平均") -> 0 | G18: =SUMIFS('0831 4度C'!$Y:$Y,'0831 4度C'!$A:$A,"新豐7線",'0831 4度C'!$B:$B,"平均") -> 0 | H18: =SUMIFS('0831 4度C'!$Y:$Y,'0831 4度C'!$A:$A,"新豐3線",'0831 4度C'!$B:$B,"平均") -> 0 | I18: =SUMIFS('0831 4度C'!$Y:$Y,'0831 4度C'!$A:$A,"新豐1線",'0831 4度C'!$B:$B,"平均") -> 0 | J18: =SUMIFS('0831 4度C'!$Y:$Y,'0831 4度C'!$A:$A,"新豐10線",'0831 4度C'!$B:$B,"平均") -> 0 | K18: =SUMIFS('0831 4度C'!$Y:$Y,'0831 4度C'!$A:$A,"新豐8線",'0831 4度C'!$B:$B,"平均") -> 0 | L18: =SUMIFS('0831 4度C'!$Y:$Y,'0831 4度C'!$A:$A,"新豐9線",'0831 4度C'!$B:$B,"平均") -> 0 | M18: =SUMIFS('0831 4度C'!$Y:$Y,'0831 4度C'!$A:$A,"新豐4線",'0831 4度C'!$B:$B,"平均") -> 0
C19: 時間/分 | D19: =SUMIFS('0831 4度C'!$Z:$Z,'0831 4度C'!$A:$A,"新豐6線",'0831 4度C'!$B:$B,"平均") -> 0 | E19: =SUMIFS('0831 4度C'!$Z:$Z,'0831 4度C'!$A:$A,"新豐2線",'0831 4度C'!$B:$B,"平均") -> 0 | F19: =SUMIFS('0831 4度C'!$Z:$Z,'0831 4度C'!$A:$A,"新豐5線",'0831 4度C'!$B:$B,"平均") -> 0 | G19: =SUMIFS('0831 4度C'!$Z:$Z,'0831 4度C'!$A:$A,"新豐7線",'0831 4度C'!$B:$B,"平均") -> 0 | H19: =SUMIFS('0831 4度C'!$Z:$Z,'0831 4度C'!$A:$A,"新豐3線",'0831 4度C'!$B:$B,"平均") -> 0 | I19: =SUMIFS('0831 4度C'!$Z:$Z,'0831 4度C'!$A:$A,"新豐1線",'0831 4度C'!$B:$B,"平均") -> 0 | J19: =SUMIFS('0831 4度C'!$Z:$Z,'0831 4度C'!$A:$A,"新豐10線",'0831 4度C'!$B:$B,"平均") -> 0 | K19: =SUMIFS('0831 4度C'!$Z:$Z,'0831 4度C'!$A:$A,"新豐8線",'0831 4度C'!$B:$B,"平均") -> 0 | L19: =SUMIFS('0831 4度C'!$Z:$Z,'0831 4度C'!$A:$A,"新豐9線",'0831 4度C'!$B:$B,"平均") -> 0 | M19: =SUMIFS('0831 4度C'!$Z:$Z,'0831 4度C'!$A:$A,"新豐4線",'0831 4度C'!$B:$B,"平均") -> 0
B20: 短暫停線 (5分鐘以下) | C20: 次數 | D20: =SUMIFS('0831 4度C'!$AC:$AC,'0831 4度C'!$A:$A,"新豐6線",'0831 4度C'!$B:$B,"平均") -> 4 | E20: =SUMIFS('0831 4度C'!$AC:$AC,'0831 4度C'!$A:$A,"新豐2線",'0831 4度C'!$B:$B,"平均") -> 4 | F20: =SUMIFS('0831 4度C'!$AC:$AC,'0831 4度C'!$A:$A,"新豐5線",'0831 4度C'!$B:$B,"平均") -> 8 | G20: =SUMIFS('0831 4度C'!$AC:$AC,'0831 4度C'!$A:$A,"新豐7線",'0831 4度C'!$B:$B,"平均") -> 8 | H20: =SUMIFS('0831 4度C'!$AC:$AC,'0831 4度C'!$A:$A,"新豐3線",'0831 4度C'!$B:$B,"平均") -> 3 | I20: =SUMIFS('0831 4度C'!$AC:$AC,'0831 4度C'!$A:$A,"新豐1線",'0831 4度C'!$B:$B,"平均") -> 9 | J20: =SUMIFS('0831 4度C'!$AC:$AC,'0831 4度C'!$A:$A,"新豐10線",'0831 4度C'!$B:$B,"平均") -> 5 | K20: =SUMIFS('0831 4度C'!$AC:$AC,'0831 4度C'!$A:$A,"新豐8線",'0831 4度C'!$B:$B,"平均") -> 6 | L20: =SUMIFS('0831 4度C'!$AC:$AC,'0831 4度C'!$A:$A,"新豐9線",'0831 4度C'!$B:$B,"平均") -> 8 | M20: =SUMIFS('0831 4度C'!$AC:$AC,'0831 4度C'!$A:$A,"新豐4線",'0831 4度C'!$B:$B,"平均") -> 6
C21: 設備次數 | D21: =SUMIFS('0831 4度C'!$AD:$AD,'0831 4度C'!$A:$A,"新豐6線",'0831 4度C'!$B:$B,"平均") -> 0 | E21: =SUMIFS('0831 4度C'!$AD:$AD,'0831 4度C'!$A:$A,"新豐2線",'0831 4度C'!$B:$B,"平均") -> 0 | F21: =SUMIFS('0831 4度C'!$AD:$AD,'0831 4度C'!$A:$A,"新豐5線",'0831 4度C'!$B:$B,"平均") -> 0 | G21: =SUMIFS('0831 4度C'!$AD:$AD,'0831 4度C'!$A:$A,"新豐7線",'0831 4度C'!$B:$B,"平均") -> 0 | H21: =SUMIFS('0831 4度C'!$AD:$AD,'0831 4度C'!$A:$A,"新豐3線",'0831 4度C'!$B:$B,"平均") -> 0 | I21: =SUMIFS('0831 4度C'!$AD:$AD,'0831 4度C'!$A:$A,"新豐1線",'0831 4度C'!$B:$B,"平均") -> 0 | J21: =SUMIFS('0831 4度C'!$AD:$AD,'0831 4度C'!$A:$A,"新豐10線",'0831 4度C'!$B:$B,"平均") -> 0 | K21: =SUMIFS('0831 4度C'!$AD:$AD,'0831 4度C'!$A:$A,"新豐8線",'0831 4度C'!$B:$B,"平均") -> 0 | L21: =SUMIFS('0831 4度C'!$AD:$AD,'0831 4度C'!$A:$A,"新豐9線",'0831 4度C'!$B:$B,"平均") -> 0 | M21: =SUMIFS('0831 4度C'!$AD:$AD,'0831 4度C'!$A:$A,"新豐4線",'0831 4度C'!$B:$B,"平均") -> 0
B22: 配置人數 | D22: =SUMIFS('0831 4度C'!$I:$I,'0831 4度C'!$A:$A,"新豐6線",'0831 4度C'!$B:$B,"平均") -> 14.75 | E22: =SUMIFS('0831 4度C'!$I:$I,'0831 4度C'!$A:$A,"新豐2線",'0831 4度C'!$B:$B,"平均") -> 18.5 | F22: =SUMIFS('0831 4度C'!$I:$I,'0831 4度C'!$A:$A,"新豐5線",'0831 4度C'!$B:$B,"平均") -> 17 | G22: =SUMIFS('0831 4度C'!$I:$I,'0831 4度C'!$A:$A,"新豐7線",'0831 4度C'!$B:$B,"平均") -> 15.625 | H22: =SUMIFS('0831 4度C'!$I:$I,'0831 4度C'!$A:$A,"新豐3線",'0831 4度C'!$B:$B,"平均") -> 10 | I22: =SUMIFS('0831 4度C'!$I:$I,'0831 4度C'!$A:$A,"新豐1線",'0831 4度C'!$B:$B,"平均") -> 18.555556 | J22: =SUMIFS('0831 4度C'!$I:$I,'0831 4度C'!$A:$A,"新豐10線",'0831 4度C'!$B:$B,"平均") -> 10.4 | K22: =SUMIFS('0831 4度C'!$I:$I,'0831 4度C'!$A:$A,"新豐8線",'0831 4度C'!$B:$B,"平均") -> 17 | L22: =SUMIFS('0831 4度C'!$I:$I,'0831 4度C'!$A:$A,"新豐9線",'0831 4度C'!$B:$B,"平均") -> 16.25 | M22: =SUMIFS('0831 4度C'!$I:$I,'0831 4度C'!$A:$A,"新豐4線",'0831 4度C'!$B:$B,"平均") -> 16.833333
B23: 主要應用設備 | D23: ET-55 | E23: 熱縮爐 | F23: L型包裝機 | G23: L型包裝機 | H23: 伺服包裝機 | I23: ET-55 | J23: 伺服包裝機 | K23: 三明治包裝機 | L23: 三明治包裝機 | M23: 三明治包裝機
B24: 次要應用設備 | F24: 圓盤機 | G24: ET-55
B25: 備註 | E25: 握沙拉 | F25: 共用L型包裝機 | H25: 調理麵包 | I25: 炒飯+沙拉 | J25: 調理麵包

Sheet 0831 4度C
A1: 新豐廠四度C日報分析 | C1: 總生產量 | D1: =SUM(F5:F75) -> 188787 | E1: 營業額 | F1: =SUM(G5:G75) -> 6748732.9 | G1: 出勤人數 | H1: =L9+L14+L52+L62+L23+L68+L39+L48+L32+L75 -> 154.91389 | I1: 產線配置圖 | L1: 生產實績 | O1: 人時性差異分析 | S1: 日報登錄 | Y1: 合計 次數 | Z1: 合計 時間/分 | AA1: 產線異常 分析說明(5分鐘以上) | AC1: 合計 次數 | AD1: 合計 設備次數 | AE1: 產能差異分析
A2: 46265 | B2: 星期一 | C2: 人時性 | D2: =AVERAGE(N9,N14,N52,N62,N23,N68,N32,N39,N48,N75) -> 149.73016 | E2: 平均廠價 | F2: =F1/D1 -> 35.747869 | G2: 多次生產數 | H2: =COUNT(H5:H75) -> 10 | Y2: =SUM(Y9+Y14+Y23+Y32+Y39+Y48+Y52+Y62+Y68+Y75) -> 0 | Z2: =SUM(Z9+Z14+Z23+Z32+Z39+Z48+Z52+Z62+Z68+Z75) -> 0 | AC2: 61 | AD2: =SUM(AD9+AD14+AD23+AD32+AD39+AD48+AD52+AD62+AD68+AD75) -> 0
A3: 線別 | B3: 品類 | C3: 品名 | E3: 廠價 | F3: 生產量 | G3: 營收 | H3: 多次 生產 | I3: 人數 | J3: 產能/時 | K3: 人時性 | L3: 人數 | M3: 產能/時 | N3: 人時性 | O3: 人數 | P3: 人時性 | Q3: 達成率 | R3: 達成率平均 | S3: 生產時間 | U3: 換線、休息/分 | V3: 稼動時間/分 | W3: 休息時間 | Y3: 產線異常統計 (5分鐘以上) | AA3: (新豐回填) | AC3: 短暫停線統計 (5分鐘以下) | AE3: 產能/時 | AF3: 達成率 | AG3: 達成率平均
S4: 開始 | T4: 結束 | W4: 開始 | X4: 結束 | Y4: 次數 | Z4: 時間/分 | AC4: 總次數 | AD4: 設備因素(次數)
A5: 新豐6線 | B5: 微波主食 | C5: 二配金咖哩果香甘口咖哩飯 | E5: 50.92 | F5: 1000 | G5: =E5*F5 -> 50920 | H5: 2 | I5: 15 | J5: 2000 | K5: =J5/I5 -> 133.33333 | L5: 15 | M5: =F5/V5*60 -> 1935.4839 | N5: =M5/L5 -> 129.03226 | O5: =L5-I5 -> 0 | P5: =N5-K5 -> -4.3010753 | Q5: =N5/K5 -> 0.96774194 | R5: =Q9 -> 0.96229733 | S5: 0.70833333 | T5: 0.72986111 | V5: =(T5-S5)*24*60 -> 31 | AC5: 4 | AE5: =M5-J5 -> -64.516129 | AF5: =M5/J5 -> 0.96774194 | AG5: =AF9 -> 0.96229733
A6: 新豐6線 | B6: 微波主食 | C6: 二配金咖哩濃厚辛口咖哩飯 | E6: 50.98 | F6: 3644 | G6: =E6*F6 -> 185771.12 | I6: 16 | J6: 2000 | K6: =J6/I6 -> 125 | L6: 16 | M6: =F6/V6*60 -> 1917.8947 | N6: =M6/L6 -> 119.86842 | O6: =L6-I6 -> 0 | P6: =N6-K6 -> -5.1315789 | Q6: =N6/K6 -> 0.95894737 | S6: 0.73402778 | T6: 0.81319444 | U6: =IF(S6=TIME(17,0,0),"",(S6-T5)*24*60) -> 6 | V6: =(T6-S6)*24*60 -> 114 | AE6: =M6-J6 -> -82.105263 | AF6: =M6/J6 -> 0.95894737
A7: 新豐6線 | B7: 微波主食 | C7: 二配厚香料優格咖哩雞排飯 | E7: 56.43 | F7: 1419 | G7: =E7*F7 -> 80074.17 | I7: 13 | J7: 2000 | K7: =J7/I7 -> 153.84615 | L7: 13 | M7: =F7/V7*60 -> 1935 | N7: =M7/L7 -> 148.84615 | O7: =L7-I7 -> 0 | P7: =N7-K7 -> -5 | Q7: =N7/K7 -> 0.9675 | S7: 0.81666667 | T7: 0.84722222 | U7: =IF(S7=TIME(17,0,0),"",(S7-T6)*24*60) -> 5 | V7: =(T7-S7)*24*60 -> 44 | W7: =T7 -> 0.84722222 | X7: =S8 -> 0.88541667 | AE7: =M7-J7 -> -65 | AF7: =M7/J7 -> 0.9675
A8: 新豐6線 | B8: 微波主食 | C8: 二配金咖哩果香甘口咖哩飯 | E8: 50.92 | F8: 1719 | G8: =E8*F8 -> 87531.48 | I8: 15 | J8: 2000 | K8: =J8/I8 -> 133.33333 | L8: 15 | M8: =F8/V8*60 -> 1910 | N8: =M8/L8 -> 127.33333 | O8: =L8-I8 -> 0 | P8: =N8-K8 -> -6 | Q8: =N8/K8 -> 0.955 | S8: 0.88541667 | T8: 0.92291667 | U8: =IF(S8=TIME(17,0,0),"",(S8-T7)*24*60) -> 55 | V8: =(T8-S8)*24*60 -> 54 | AE8: =M8-J8 -> -90 | AF8: =M8/J8 -> 0.955
A9: 新豐6線 | B9: 平均 | I9: 14.75 | J9: 2000 | K9: =J9/I9 -> 135.59322 | L9: 14.75 | M9: =AVERAGE(M5:M8) -> 1924.5947 | N9: =M9/L9 -> 130.48099 | O9: =L9-I9 -> 0 | P9: =N9-K9 -> -5.112227 | Q9: =N9/K9 -> 0.96229733 | Y9: =SUM(Y5:Y8) -> 0 | Z9: =SUM(Z5:Z8) -> 0 | AC9: 4 | AD9: =SUM(AD5:AD8) -> 0 | AE9: =M9-J9 -> -75.405348 | AF9: =M9/J9 -> 0.96229733
A10: 新豐2線 | B10: 沙拉 | C10: 青醬優格雞肉握沙拉(113年) | E10: 39.62 | F10: 2800 | G10: =E10*F10 -> 110936 | H10: 2 | I10: 19 | J10: 1500 | K10: =J10/I10 -> 78.947368 | L10: 19 | M10: =F10/V10*60 -> 1435.8974 | N10: =M10/L10 -> 75.573549 | O10: =L10-I10 -> 0 | P10: =N10-K10 -> -3.3738192 | Q10: =N10/K10 -> 0.95726496 | R10: =Q14 -> 0.95701512 | S10: 0.083333333 | T10: 0.16458333 | V10: =(T10-S10)*24*60 -> 117 | W10: =T10 -> 0.16458333 | X10: =S11 -> 0.18402778 | AC10: 4 | AE10: =M10-J10 -> -64.102564 | AF10: =M10/J10 -> 0.95726496 | AG10: =AF14 -> 0.95701512
A11: 新豐2線 | B11: 沙拉 | C11: 青檸烤雞握沙拉(113年) | E11: 39.8 | F11: 7169 | G11: =E11*F11 -> 285326.2 | I11: 17 | J11: 1500 | K11: =J11/I11 -> 88.235294 | L11: 17 | M11: =F11/V11*60 -> 1433.8 | N11: =M11/L11 -> 84.341176 | O11: =L11-I11 -> 0 | P11: =N11-K11 -> -3.8941176 | Q11: =N11/K11 -> 0.95586667 | S11: 0.18402778 | T11: 0.39236111 | U11: =IF(S11=TIME(17,0,0),"",(S11-T10)*24*60) -> 28 | V11: =(T11-S11)*24*60 -> 300 | AE11: =M11-J11 -> -66.2 | AF11: =M11/J11 -> 0.95586667
A12: 新豐2線 | B12: 沙拉 | C12: 地瓜瓜握沙拉 | E12: 39.52 | F12: 2417 | G12: =E12*F12 -> 95519.84 | I12: 19 | J12: 1500 | K12: =J12/I12 -> 78.947368 | L12: 19 | M12: =F12/V12*60 -> 1435.8416 | N12: =M12/L12 -> 75.57061 | O12: =L12-I12 -> 0 | P12: =N12-K12 -> -3.3767587 | Q12: =N12/K12 -> 0.95722772 | S12: 0.39791667 | T12: 0.46805556 | U12: =IF(S12=TIME(17,0,0),"",(S12-T11)*24*60) -> 8 | V12: =(T12-S12)*24*60 -> 101 | W12: =T12 -> 0.46805556 | X12: =S13 -> 0.50833333 | AE12: =M12-J12 -> -64.158416 | AF12: =M12/J12 -> 0.95722772
A13: 新豐2線 | B13: 沙拉 | C13: 青醬優格雞肉握沙拉(113年) | E13: 39.62 | F13: 2083 | G13: =E13*F13 -> 82528.46 | I13: 19 | J13: 1500 | K13: =J13/I13 -> 78.947368 | L13: 19 | M13: =F13/V13*60 -> 1436.5517 | N13: =M13/L13 -> 75.607985 | O13: =L13-I13 -> 0 | P13: =N13-K13 -> -3.3393829 | Q13: =N13/K13 -> 0.95770115 | S13: 0.50833333 | T13: 0.56875 | U13: =IF(S13=TIME(17,0,0),"",(S13-T12)*24*60) -> 58 | V13: =(T13-S13)*24*60 -> 87 | AE13: =M13-J13 -> -63.448276 | AF13: =M13/J13 -> 0.95770115
A14: 新豐2線 | B14: 平均 | I14: 18.5 | J14: 1500 | K14: =J14/I14 -> 81.081081 | L14: 18.5 | M14: =AVERAGE(M10:M13) -> 1435.5227 | N14: =M14/L14 -> 77.595821 | O14: =L14-I14 -> 0 | P14: =N14-K14 -> -3.4852602 | Q14: =N14/K14 -> 0.95701512 | Y14: =SUM(Y10:Y13) -> 0 | Z14: =SUM(Z10:Z13) -> 0 | AC14: 4 | AD14: =SUM(AD10:AD13) -> 0 | AE14: =M14-J14 -> -64.477314 | AF14: =M14/J14 -> 0.95701512
A15: 新豐5線 | B15: 季節調理麵 | C15: 台式麻醬涼麵(115年) | E15: 31.11 | F15: 3253 | G15: =E15*F15 -> 101200.83 | I15: 14 | J15: 2000 | K15: =J15/I15 -> 142.85714 | L15: 14 | M15: =F15/V15*60 -> 1913.5294 | N15: =M15/L15 -> 136.68067 | O15: =L15-I15 -> 0 | P15: =N15-K15 -> -6.1764706 | Q15: =N15/K15 -> 0.95676471 | R15: =Q23 -> 0.95775227 | S15: 0.20833333 | T15: 0.27916667 | V15: =(T15-S15)*24*60 -> 102 | AC15: 8 | AE15: =M15-J15 -> -86.470588 | AF15: =M15/J15 -> 0.95676471 | AG15: =AF23 -> 0.95775227
A16: 新豐5線 | B16: 小吃 | C16: 剝皮辣椒雞湯 | E16: 41 | F16: 2010 | G16: =E16*F16 -> 82410 | I16: 26 | J16: 1500 | K16: =J16/I16 -> 57.692308 | L16: 26 | M16: =F16/V16*60 -> 1435.7143 | N16: =M16/L16 -> 55.21978 | O16: =L16-I16 -> 0 | P16: =N16-K16 -> -2.4725275 | Q16: =N16/K16 -> 0.95714286 | S16: 0.28333333 | T16: 0.34166667 | U16: =IF(S16=TIME(17,0,0),"",(S16-T15)*24*60) -> 6 | V16: =(T16-S16)*24*60 -> 84 | AE16: =M16-J16 -> -64.285714 | AF16: =M16/J16 -> 0.95714286
A17: 新豐5線 | B17: 季節調理麵 | C17: 嫩烤魚排佐花椰菜義大利麵 | E17: 68.88 | F17: 1885 | G17: =E17*F17 -> 129838.8 | I17: 16 | J17: 2000 | K17: =J17/I17 -> 125 | L17: 16 | M17: =F17/V17*60 -> 1916.9492 | N17: =M17/L17 -> 119.80932 | O17: =L17-I17 -> 0 | P17: =N17-K17 -> -5.190678 | Q17: =N17/K17 -> 0.95847458 | S17: 0.34513889 | T17: 0.38611111 | U17: =IF(S17=TIME(17,0,0),"",(S17-T16)*24*60) -> 5 | V17: =(T17-S17)*24*60 -> 59 | AE17: =M17-J17 -> -83.050847 | AF17: =M17/J17 -> 0.95847458
A18: 新豐5線 | B18: 沙拉 | C18: 厚蛋時蔬握沙拉 | E18: 39.46 | F18: 2571 | G18: =E18*F18 -> 101451.66 | I18: 15 | J18: 1500 | K18: =J18/I18 -> 100 | L18: 15 | M18: =F18/V18*60 -> 1428.3333 | N18: =M18/L18 -> 95.222222 | O18: =L18-I18 -> 0 | P18: =N18-K18 -> -4.7777778 | Q18: =N18/K18 -> 0.95222222 | S18: 0.39027778 | T18: 0.46527778 | U18: =IF(S18=TIME(17,0,0),"",(S18-T17)*24*60) -> 6 | V18: =(T18-S18)*24*60 -> 108 | AE18: =M18-J18 -> -71.666667 | AF18: =M18/J18 -> 0.95222222
A19: 新豐5線 | B19: 微波主食 | C19: 二配玉米濃湯焗烤飯 | E19: 54.5 | F19: 1260 | G19: =E19*F19 -> 68670 | I19: 19 | J19: 1500 | K19: =J19/I19 -> 78.947368 | L19: 19 | M19: =F19/V19*60 -> 1426.4151 | N19: =M19/L19 -> 75.074479 | O19: =L19-I19 -> 0 | P19: =N19-K19 -> -3.8728898 | Q19: =N19/K19 -> 0.9509434 | S19: 0.70833333 | T19: 0.74513889 | U19: =IF(S19=TIME(17,0,0),"",(S19-T18)*24*60) | V19: =(T19-S19)*24*60 -> 53 | AE19: =M19-J19 -> -73.584906 | AF19: =M19/J19 -> 0.9509434
A20: 新豐5線 | B20: 微波主食 | C20: 二配港式香滑嫩蛋牛肉燴飯 | E20: 50.67 | F20: 1794 | G20: =E20*F20 -> 90901.98 | I20: 17 | J20: 2000 | K20: =J20/I20 -> 117.64706 | L20: 17 | M20: =F20/V20*60 -> 1922.1429 | N20: =M20/L20 -> 113.06723 | O20: =L20-I20 -> 0 | P20: =N20-K20 -> -4.5798319 | Q20: =N20/K20 -> 0.96107143 | S20: 0.74861111 | T20: 0.7875 | U20: =IF(S20=TIME(17,0,0),"",(S20-T19)*24*60) -> 5 | V20: =(T20-S20)*24*60 -> 56 | AE20: =M20-J20 -> -77.857143 | AF20: =M20/J20 -> 0.96107143
A21: 新豐5線 | B21: 微波主食 | C21: 二配泰式綠咖哩雞 | E21: 50.67 | F21: 1604 | G21: =E21*F21 -> 81274.68 | I21: 15 | J21: 2000 | K21: =J21/I21 -> 133.33333 | L21: 15 | M21: =F21/V21*60 -> 1924.8 | N21: =M21/L21 -> 128.32 | O21: =L21-I21 -> 0 | P21: =N21-K21 -> -5.0133333 | Q21: =N21/K21 -> 0.9624 | S21: 0.79097222 | T21: 0.82569444 | U21: =IF(S21=TIME(17,0,0),"",(S21-T20)*24*60) -> 5 | V21: =(T21-S21)*24*60 -> 50 | W21: =T21 -> 0.82569444 | X21: =S22 -> 0.86527778 | AE21: =M21-J21 -> -75.2 | AF21: =M21/J21 -> 0.9624
A22: 新豐5線 | B22: 微波主食 | C22: 二配叉燒蛋炒飯 | E22: 54.09 | F22: 4031 | G22: =E22*F22 -> 218036.79 | I22: 14 | J22: 2000 | K22: =J22/I22 -> 142.85714 | L22: 14 | M22: =F22/V22*60 -> 1919.5238 | N22: =M22/L22 -> 137.10884 | O22: =L22-I22 -> 0 | P22: =N22-K22 -> -5.7482993 | Q22: =N22/K22 -> 0.9597619 | S22: 0.86527778 | T22: 0.95277778 | U22: =IF(S22=TIME(17,0,0),"",(S22-T21)*24*60) -> 57 | V22: =(T22-S22)*24*60 -> 126 | AE22: =M22-J22 -> -80.47619 | AF22: =M22/J22 -> 0.9597619
A23: 新豐5線 | B23: 平均 | I23: 17 | J23: 1812.5 | K23: =J23/I23 -> 106.61765 | L23: 17 | M23: =AVERAGE(M15:M22) -> 1735.926 | N23: =M23/L23 -> 102.11329 | O23: =L23-I23 -> 0 | P23: =N23-K23 -> -4.5043534 | Q23: =N23/K23 -> 0.95775227 | Y23: =SUM(Y15:Y22) -> 0 | Z23: =SUM(Z15:Z22) -> 0 | AC23: 8 | AD23: =SUM(AD15:AD22) -> 0 | AE23: =M23-J23 -> -76.574007 | AF23: =M23/J23 -> 0.95775227
A24: 新豐7線 | B24: 微波主食 | C24: 韓式泡菜豬肉豆腐丼飯 | E24: 50.67 | F24: 2032 | G24: =E24*F24 -> 102961.44 | I24: 17 | J24: 2000 | K24: =J24/I24 -> 117.64706 | L24: 17 | M24: =F24/V24*60 -> 1905 | N24: =M24/L24 -> 112.05882 | O24: =L24-I24 -> 0 | P24: =N24-K24 -> -5.5882353 | Q24: =N24/K24 -> 0.9525 | R24: =Q32 -> 0.95875408 | S24: 0.20833333 | T24: 0.25277778 | V24: =(T24-S24)*24*60 -> 64 | AC24: 8 | AE24: =M24-J24 -> -95 | AF24: =M24/J24 -> 0.9525 | AG24: =AF32 -> 0.95875408
A25: 新豐7線 | B25: 微波主食 | C25: 鐵板滑蛋炸豬排丼 | E25: 57.73 | F25: 3138 | G25: =E25*F25 -> 181156.74 | I25: 14 | J25: 2000 | K25: =J25/I25 -> 142.85714 | L25: 14 | M25: =F25/V25*60 -> 1901.8182 | N25: =M25/L25 -> 135.84416 | O25: =L25-I25 -> 0 | P25: =N25-K25 -> -7.012987 | Q25: =N25/K25 -> 0.95090909 | S25: 0.25625 | T25: 0.325 | U25: =IF(S25=TIME(17,0,0),"",(S25-T24)*24*60) -> 5 | V25: =(T25-S25)*24*60 -> 99 | AE25: =M25-J25 -> -98.181818 | AF25: =M25/J25 -> 0.95090909
A26: 新豐7線 | B26: 微波主食 | C26: 日式炙烤親子丼 | E26: 53.27 | F26: 1906 | G26: =E26*F26 -> 101532.62 | I26: 16 | J26: 2000 | K26: =J26/I26 -> 125 | L26: 16 | M26: =F26/V26*60 -> 1906 | N26: =M26/L26 -> 119.125 | O26: =L26-I26 -> 0 | P26: =N26-K26 -> -5.875 | Q26: =N26/K26 -> 0.953 | S26: 0.32916667 | T26: 0.37083333 | U26: =IF(S26=TIME(17,0,0),"",(S26-T25)*24*60) -> 6 | V26: =(T26-S26)*24*60 -> 60 | AE26: =M26-J26 -> -94 | AF26: =M26/J26 -> 0.953
A27: 新豐7線 | B27: 微波主食 | C27: 爆炒雞丁飯 | E27: 59.04 | F27: 1599 | G27: =E27*F27 -> 94404.96 | I27: 19 | J27: 2000 | K27: =J27/I27 -> 105.26316 | L27: 19 | M27: =F27/V27*60 -> 1918.8 | N27: =M27/L27 -> 100.98947 | O27: =L27-I27 -> 0 | P27: =N27-K27 -> -4.2736842 | Q27: =N27/K27 -> 0.9594 | S27: 0.37430556 | T27: 0.40902778 | U27: =IF(S27=TIME(17,0,0),"",(S27-T26)*24*60) -> 5 | V27: =(T27-S27)*24*60 -> 50 | AE27: =M27-J27 -> -81.2 | AF27: =M27/J27 -> 0.9594
A28: 新豐7線 | B28: 微波主食 | C28: 二配川味麻婆燒豆腐燴飯 | E28: 50.49 | F28: 2316 | G28: =E28*F28 -> 116934.84 | I28: 15 | J28: 2000 | K28: =J28/I28 -> 133.33333 | L28: 15 | M28: =F28/V28*60 -> 1930 | N28: =M28/L28 -> 128.66667 | O28: =L28-I28 -> 0 | P28: =N28-K28 -> -4.6666667 | Q28: =N28/K28 -> 0.965 | S28: 0.70833333 | T28: 0.75833333 | U28: =IF(S28=TIME(17,0,0),"",(S28-T27)*24*60) | V28: =(T28-S28)*24*60 -> 72 | AE28: =M28-J28 -> -70 | AF28: =M28/J28 -> 0.965
A29: 新豐7線 | B29: 微波主食 | C29: 二配美味蟹煲 | E29: 54.09 | F29: 2330 | G29: =E29*F29 -> 126029.7 | I29: 18 | J29: 2000 | K29: =J29/I29 -> 111.11111 | L29: 18 | M29: =F29/V29*60 -> 1915.0685 | N29: =M29/L29 -> 106.39269 | O29: =L29-I29 -> 0 | P29: =N29-K29 -> -4.718417 | Q29: =N29/K29 -> 0.95753425 | S29: 0.7625 | T29: 0.81319444 | U29: =IF(S29=TIME(17,0,0),"",(S29-T28)*24*60) -> 6 | V29: =(T29-S29)*24*60 -> 73 | AE29: =M29-J29 -> -84.931507 | AF29: =M29/J29 -> 0.95753425
A30: 新豐7線 | B30: 微波主食 | C30: 二配打拋風味豬肉飯 | E30: 51.06 | F30: 1000 | G30: =E30*F30 -> 51060 | H30: 2 | I30: 13 | J30: 2000 | K30: =J30/I30 -> 153.84615 | L30: 13 | M30: =F30/V30*60 -> 1935.4839 | N30: =M30/L30 -> 148.88337 | O30: =L30-I30 -> 0 | P30: =N30-K30 -> -4.9627792 | Q30: =N30/K30 -> 0.96774194 | S30: 0.81736111 | T30: 0.83888889 | U30: =IF(S30=TIME(17,0,0),"",(S30-T29)*24*60) -> 6 | V30: =(T30-S30)*24*60 -> 31 | W30: =T30 -> 0.83888889 | X30: =S31 -> 0.87847222 | AE30: =M30-J30 -> -64.516129 | AF30: =M30/J30 -> 0.96774194
A31: 新豐7線 | B31: 微波主食 | C31: 二配打拋風味豬肉飯 | E31: 51.06 | F31: 2442 | G31: =E31*F31 -> 124688.52 | I31: 13 | J31: 2000 | K31: =J31/I31 -> 153.84615 | L31: 13 | M31: =F31/V31*60 -> 1927.8947 | N31: =M31/L31 -> 148.2996 | O31: =L31-I31 -> 0 | P31: =N31-K31 -> -5.5465587 | Q31: =N31/K31 -> 0.96394737 | S31: 0.87847222 | T31: 0.93125 | U31: =IF(S31=TIME(17,0,0),"",(S31-T30)*24*60) -> 57 | V31: =(T31-S31)*24*60 -> 76 | AE31: =M31-J31 -> -72.105263 | AF31: =M31/J31 -> 0.96394737
A32: 新豐7線 | B32: 平均 | I32: 15.625 | J32: 2000 | K32: =J32/I32 -> 128 | L32: 15.625 | M32: =AVERAGE(M24:M31) -> 1917.5082 | N32: =M32/L32 -> 122.72052 | O32: =L32-I32 -> 0 | P32: =N32-K32 -> -5.2794777 | Q32: =N32/K32 -> 0.95875408 | Y32: =SUM(Y24:Y31) -> 0 | Z32: =SUM(Z24:Z31) -> 0 | AC32: 8 | AD32: =SUM(AD24:AD31) -> 0 | AE32: =M32-J32 -> -82.49184 | AF32: =M32/J32 -> 0.95875408
A33: 新豐8線 | B33: 三明治 | C33: 紐奧良風味烤雞鮮蔬三明治 | E33: 31.29 | F33: 5600 | G33: =E33*F33 -> 175224 | H33: 2 | I33: 18 | J33: 2400 | K33: =J33/I33 -> 133.33333 | L33: 18 | M33: =F33/V33*60 -> 2285.7143 | N33: =M33/L33 -> 126.98413 | O33: =L33-I33 -> 0 | P33: =N33-K33 -> -6.3492063 | Q33: =N33/K33 -> 0.95238095 | R33: =Q39 -> 0.95494026 | S33: 0.083333333 | T33: 0.18541667 | V33: =(T33-S33)*24*60 -> 147 | W33: =T33 -> 0.18541667 | X33: =S34 -> 0.20277778 | AC33: 6 | AE33: =M33-J33 -> -114.28571 | AF33: =M33/J33 -> 0.95238095 | AG33: =AF39 -> 0.95494026
A34: 新豐8線 | B34: 三明治 | C34: 醬燒烤雞三明治(115年) | E34: 26.37 | F34: 6818 | G34: =E34*F34 -> 179790.66 | I34: 18 | J34: 2400 | K34: =J34/I34 -> 133.33333 | L34: 18 | M34: =F34/V34*60 -> 2285.3631 | N34: =M34/L34 -> 126.96462 | O34: =L34-I34 -> 0 | P34: =N34-K34 -> -6.3687151 | Q34: =N34/K34 -> 0.95223464 | S34: 0.20277778 | T34: 0.32708333 | U34: =(S34-T33)*24*60 -> 25 | V34: =(T34-S34)*24*60 -> 179 | AE34: =M34-J34 -> -114.63687 | AF34: =M34/J34 -> 0.95223464
A35: 新豐8線 | B35: 三明治 | C35: 經典火腿玉米蛋三明治 | E35: 24.43 | F35: 4200 | G35: =E35*F35 -> 102606 | H35: 2 | I35: 14 | J35: 2400 | K35: =J35/I35 -> 171.42857 | L35: 14 | M35: =F35/V35*60 -> 2290.9091 | N35: =M35/L35 -> 163.63636 | O35: =L35-I35 -> 0 | P35: =N35-K35 -> -7.7922078 | Q35: =N35/K35 -> 0.95454545 | S35: 0.33194444 | T35: 0.40833333 | U35: =(S35-T34)*24*60 -> 7 | V35: =(T35-S35)*24*60 -> 110 | AE35: =M35-J35 -> -109.09091 | AF35: =M35/J35 -> 0.95454545
A36: 新豐8線 | B36: 三明治 | C36: 好多蛋三明治 | E36: 34.1 | F36: 3700 | G36: =E36*F36 -> 126170 | H36: 2 | I36: 17 | J36: 1600 | K36: =J36/I36 -> 94.117647 | L36: 17 | M36: =F36/V36*60 -> 1531.0345 | N36: =M36/L36 -> 90.060852 | O36: =L36-I36 -> 0 | P36: =N36-K36 -> -4.0567951 | Q36: =N36/K36 -> 0.95689655 | S36: 0.41180556 | T36: 0.5125 | U36: =(S36-T35)*24*60 -> 5 | V36: =(T36-S36)*24*60 -> 145 | W36: =T36 -> 0.5125 | X36: =S37 -> 0.55486111 | AE36: =M36-J36 -> -68.965517 | AF36: =M36/J36 -> 0.95689655
A37: 新豐8線 | B37: 三明治 | C37: 紐奧良風味烤雞鮮蔬三明治 | E37: 31.29 | F37: 4290 | G37: =E37*F37 -> 134234.1 | I37: 18 | J37: 2400 | K37: =J37/I37 -> 133.33333 | L37: 18 | M37: =F37/V37*60 -> 2298.2143 | N37: =M37/L37 -> 127.67857 | O37: =L37-I37 -> 0 | P37: =N37-K37 -> -5.6547619 | Q37: =N37/K37 -> 0.95758929 | S37: 0.55486111 | T37: 0.63263889 | U37: =(S37-T36)*24*60 -> 61 | V37: =(T37-S37)*24*60 -> 112 | AE37: =M37-J37 -> -101.78571 | AF37: =M37/J37 -> 0.95758929
A38: 新豐8線 | B38: 三明治 | C38: 好多蛋三明治 | E38: 34.1 | F38: 3064 | G38: =E38*F38 -> 104482.4 | I38: 17 | J38: 1600 | K38: =J38/I38 -> 94.117647 | L38: 17 | M38: =F38/V38*60 -> 1532 | N38: =M38/L38 -> 90.117647 | O38: =L38-I38 -> 0 | P38: =N38-K38 -> -4 | Q38: =N38/K38 -> 0.9575 | S38: 0.6375 | T38: 0.72083333 | U38: =(S38-T37)*24*60 -> 7 | V38: =(T38-S38)*24*60 -> 120 | AE38: =M38-J38 -> -68 | AF38: =M38/J38 -> 0.9575
A39: 新豐8線 | B39: 平均 | I39: 17 | J39: 2133.3333 | K39: =J39/I39 -> 125.4902 | L39: 17 | M39: =AVERAGE(M33:M38) -> 2037.2059 | N39: =M39/L39 -> 119.83564 | O39: =L39-I39 -> 0 | P39: =N39-K39 -> -5.6545561 | Q39: =N39/K39 -> 0.95494026 | Y39: =SUM(Y33:Y38) -> 0 | Z39: =SUM(Z33:Z38) -> 0 | AC39: 6 | AD39: =SUM(AD33:AD38) -> 0 | AE39: =M39-J39 -> -96.127454 | AF39: =M39/J39 -> 0.95494026
A40: 新豐9線 | B40: 三明治 | C40: 經典總匯三明治(115年) | E40: 26.18 | F40: 6369 | G40: =E40*F40 -> 166740.42 | I40: 20 | J40: 2400 | K40: =J40/I40 -> 120 | L40: 20 | M40: =F40/V40*60 -> 2288.2635 | N40: =M40/L40 -> 114.41317 | O40: =L40-I40 -> 0 | P40: =N40-K40 -> -5.5868263 | Q40: =N40/K40 -> 0.95344311 | R40: =Q48 -> 0.95886773 | S40: 0.083333333 | T40: 0.19930556 | V40: =(T40-S40)*24*60 -> 167 | W40: =T40 -> 0.19930556 | X40: =S41 -> 0.21805556 | AC40: 8 | AE40: =M40-J40 -> -111.73653 | AF40: =M40/J40 -> 0.95344311 | AG40: =AF48 -> 0.95886773
...

Sheet 0830
B1: 屏榮 新豐廠組合室生產人時性分析
B3: 日期 | C3: =TEXT('0830 4度C'!A2,"yyyy.mm.ddaaaa") -> 2026.08.30星期日 | E3: 訂單量 | F3: ='0830 4度C'!D1 -> 194783 | H3: 營業額 | I3: ='0830 4度C'!F1 -> 6882608.3
B4: 人時性 | C4: 項目 | E4: ➀ | G4: ➁ | I4: ➂ | K4: 異常停線 | M4: 短暫停線
C5: 組合室 | E5: 全溫層 | G5: 4度C-各編組展開 | I5: ③三明治-各編組展開 | K5: 合計次數 | L5: 時間 | M5: 合計次數 | N5: 設備次數
C6: 排關平均 | E6: =AVERAGE(D13:M13) -> 154.72243 | F6: =AVERAGE(D31:O31,D13:J13) -> 162.18489 | G6: =AVERAGE(D13:J13) -> 162.18489 | I6: =AVERAGE(K13:M13) -> 137.31003 | K6: ='0830 4度C'!Y2 -> 0 | L6: ='0830 4度C'!Z2 -> 0 | M6: ='0830 4度C'!AC2 -> 61 | N6: ='0830 4度C'!AD2 -> 0
C7: 實績平均 | E7: =AVERAGE(D14:M14) -> 148.14679 | F7: =AVERAGE(D32:O32,D14:J14) -> 155.3606 | G7: =AVERAGE(D14:J14) -> 155.3606 | I7: =AVERAGE(K14:M14) -> 131.31454
C8: 達成率平均 | E8: =AVERAGE(D15:M15) -> 0.95759611 | F8: =AVERAGE(D15:J15,D33:O33) -> 0.95814174 | G8: =AVERAGE(D15:J15) -> 0.95814174 | I8: =AVERAGE(K15:M15) -> 0.95632296
K9: ※現行日本鮮食廠以達成率80%為基本(即為現行KPI)
B10: 溫層 | D10: ➁4度C-各編組展開 | K10: ③三明治-各編組展開
B11: 編組 | D11: 1 | E11: 2 | F11: 3 | G11: 4 | H11: 5 | I11: 6 | J11: 7 | K11: 1 | L11: 2 | M11: 3
D12: 新豐6線 | E12: 新豐2線 | F12: 新豐5線 | G12: 新豐7線 | H12: 新豐3線 | I12: 新豐1線 | J12: 新豐10線 | K12: 新豐8線 | L12: 新豐9線 | M12: 新豐4線
B13: 人時性 | C13: 排關 | D13: =SUMIFS('0830 4度C'!$K:$K,'0830 4度C'!$A:$A,"新豐6線",'0830 4度C'!$B:$B,"平均") -> 131.14754 | E13: =SUMIFS('0830 4度C'!$K:$K,'0830 4度C'!$A:$A,"新豐2線",'0830 4度C'!$B:$B,"平均") -> 81.081081 | F13: =SUMIFS('0830 4度C'!$K:$K,'0830 4度C'!$A:$A,"新豐5線",'0830 4度C'!$B:$B,"平均") -> 102.45902 | G13: =SUMIFS('0830 4度C'!$K:$K,'0830 4度C'!$A:$A,"新豐7線",'0830 4度C'!$B:$B,"平均") -> 123.71134 | H13: =SUMIFS('0830 4度C'!$K:$K,'0830 4度C'!$A:$A,"新豐3線",'0830 4度C'!$B:$B,"平均") -> 300 | I13: =SUMIFS('0830 4度C'!$K:$K,'0830 4度C'!$A:$A,"新豐1線",'0830 4度C'!$B:$B,"平均") -> 108.43373 | J13: =SUMIFS('0830 4度C'!$K:$K,'0830 4度C'!$A:$A,"新豐10線",'0830 4度C'!$B:$B,"平均") -> 288.46154 | K13: =SUMIFS('0830 4度C'!$K:$K,'0830 4度C'!$A:$A,"新豐8線",'0830 4度C'!$B:$B,"平均") -> 134.45378 | L13: =SUMIFS('0830 4度C'!$K:$K,'0830 4度C'!$A:$A,"新豐9線",'0830 4度C'!$B:$B,"平均") -> 138.34586 | M13: =SUMIFS('0830 4度C'!$K:$K,'0830 4度C'!$A:$A,"新豐4線",'0830 4度C'!$B:$B,"平均") -> 139.13043
C14: 實績 | D14: =SUMIFS('0830 4度C'!$N:$N,'0830 4度C'!$A:$A,"新豐6線",'0830 4度C'!$B:$B,"平均") -> 125.85224 | E14: =SUMIFS('0830 4度C'!$N:$N,'0830 4度C'!$A:$A,"新豐2線",'0830 4度C'!$B:$B,"平均") -> 77.64463 | F14: =SUMIFS('0830 4度C'!$N:$N,'0830 4度C'!$A:$A,"新豐5線",'0830 4度C'!$B:$B,"平均") -> 98.230454 | G14: =SUMIFS('0830 4度C'!$N:$N,'0830 4度C'!$A:$A,"新豐7線",'0830 4度C'!$B:$B,"平均") -> 118.53031 | H14: =SUMIFS('0830 4度C'!$N:$N,'0830 4度C'!$A:$A,"新豐3線",'0830 4度C'!$B:$B,"平均") -> 286.34925 | I14: =SUMIFS('0830 4度C'!$N:$N,'0830 4度C'!$A:$A,"新豐1線",'0830 4度C'!$B:$B,"平均") -> 103.88077 | J14: =SUMIFS('0830 4度C'!$N:$N,'0830 4度C'!$A:$A,"新豐10線",'0830 4度C'!$B:$B,"平均") -> 277.03658 | K14: =SUMIFS('0830 4度C'!$N:$N,'0830 4度C'!$A:$A,"新豐8線",'0830 4度C'!$B:$B,"平均") -> 128.4221 | L14: =SUMIFS('0830 4度C'!$N:$N,'0830 4度C'!$A:$A,"新豐9線",'0830 4度C'!$B:$B,"平均") -> 132.32219 | M14: =SUMIFS('0830 4度C'!$N:$N,'0830 4度C'!$A:$A,"新豐4線",'0830 4度C'!$B:$B,"平均") -> 133.19934
C15: 達成率 | D15: =D14/D13 -> 0.95962334 | E15: =E14/E13 -> 0.9576171 | F15: =F14/F13 -> 0.95872924 | G15: =G14/G13 -> 0.95812003 | H15: =H14/H13 -> 0.95449749 | I15: =I14/I13 -> 0.95801152 | J15: =J14/J13 -> 0.96039348 | K15: =K14/K13 -> 0.95513937 | ... M15: =M14/M13 -> 0.95737023
B16: 作業 時間 | C16: 開始 | D16: =VLOOKUP("新豐6線",'0830 4度C'!$A:$T,19,0) -> 0.70833333 | E16: =VLOOKUP("新豐2線",'0830 4度C'!$A:$T,19,0) -> 0.083333333 | F16: =VLOOKUP("新豐5線",'0830 4度C'!$A:$T,19,0) -> 0.20833333 | G16: =VLOOKUP("新豐7線",'0830 4度C'!$A:$T,19,0) -> 0.20833333 | H16: =VLOOKUP("新豐3線",'0830 4度C'!$A:$T,19,0) -> 0.20833333 | I16: =VLOOKUP("新豐1線",'0830 4度C'!$A:$T,19,0) -> 0.20833333 | J16: =VLOOKUP("新豐10線",'0830 4度C'!$A:$T,19,0) -> 0.20833333 | K16: =VLOOKUP("新豐8線",'0830 4度C'!$A:$T,19,0) -> 0.083333333 | L16: =VLOOKUP("新豐9線",'0830 4度C'!$A:$T,19,0) -> 0.083333333 | M16: =VLOOKUP("新豐4線",'0830 4度C'!$A:$T,19,0) -> 0.083333333
C17: 結束 | D17: =LOOKUP(2,1/(('0830 4度C'!$A:$A="新豐6線")*('0830 4度C'!$T:$T<>"")),'0830 4度C'!$T:$T) -> 0.90833333 | E17: =LOOKUP(2,1/(('0830 4度C'!$A:$A="新豐2線")*('0830 4度C'!$T:$T<>"")),'0830 4度C'!$T:$T) -> 0.58680556 | F17: =LOOKUP(2,1/(('0830 4度C'!$A:$A="新豐5線")*('0830 4度C'!$T:$T<>"")),'0830 4度C'!$T:$T) -> 0.84583333 | G17: =LOOKUP(2,1/(('0830 4度C'!$A:$A="新豐7線")*('0830 4度C'!$T:$T<>"")),'0830 4度C'!$T:$T) -> 0.83680556 | H17: =LOOKUP(2,1/(('0830 4度C'!$A:$A="新豐3線")*('0830 4度C'!$T:$T<>"")),'0830 4度C'!$T:$T) -> 0.45486111 | I17: =LOOKUP(2,1/(('0830 4度C'!$A:$A="新豐1線")*('0830 4度C'!$T:$T<>"")),'0830 4度C'!$T:$T) -> 0.90625 | J17: =LOOKUP(2,1/(('0830 4度C'!$A:$A="新豐10線")*('0830 4度C'!$T:$T<>"")),'0830 4度C'!$T:$T) -> 0.46736111 | K17: =LOOKUP(2,1/(('0830 4度C'!$A:$A="新豐8線")*('0830 4度C'!$T:$T<>"")),'0830 4度C'!$T:$T) -> 0.74236111 | L17: =LOOKUP(2,1/(('0830 4度C'!$A:$A="新豐9線")*('0830 4度C'!$T:$T<>"")),'0830 4度C'!$T:$T) -> 0.71180556 | M17: =LOOKUP(2,1/(('0830 4度C'!$A:$A="新豐4線")*('0830 4度C'!$T:$T<>"")),'0830 4度C'!$T:$T) -> 0.73541667
B18: 產線異常 (5分鐘以上) | C18: 次數 | D18: =SUMIFS('0830 4度C'!$Y:$Y,'0830 4度C'!$A:$A,"新豐6線",'0830 4度C'!$B:$B,"平均") -> 0 | E18: =SUMIFS('0830 4度C'!$Y:$Y,'0830 4度C'!$A:$A,"新豐2線",'0830 4度C'!$B:$B,"平均") -> 0 | F18: =SUMIFS('0830 4度C'!$Y:$Y,'0830 4度C'!$A:$A,"新豐5線",'0830 4度C'!$B:$B,"平均") -> 0 | G18: =SUMIFS('0830 4度C'!$Y:$Y,'0830 4度C'!$A:$A,"新豐7線",'0830 4度C'!$B:$B,"平均") -> 0 | H18: =SUMIFS('0830 4度C'!$Y:$Y,'0830 4度C'!$A:$A,"新豐3線",'0830 4度C'!$B:$B,"平均") -> 0 | I18: =SUMIFS('0830 4度C'!$Y:$Y,'0830 4度C'!$A:$A,"新豐1線",'0830 4度C'!$B:$B,"平均") -> 0 | J18: =SUMIFS('0830 4度C'!$Y:$Y,'0830 4度C'!$A:$A,"新豐10線",'0830 4度C'!$B:$B,"平均") -> 0 | K18: =SUMIFS('0830 4度C'!$Y:$Y,'0830 4度C'!$A:$A,"新豐8線",'0830 4度C'!$B:$B,"平均") -> 0 | L18: =SUMIFS('0830 4度C'!$Y:$Y,'0830 4度C'!$A:$A,"新豐9線",'0830 4度C'!$B:$B,"平均") -> 0 | M18: =SUMIFS('0830 4度C'!$Y:$Y,'0830 4度C'!$A:$A,"新豐4線",'0830 4度C'!$B:$B,"平均") -> 0
C19: 時間/分 | D19: =SUMIFS('0830 4度C'!$Z:$Z,'0830 4度C'!$A:$A,"新豐6線",'0830 4度C'!$B:$B,"平均") -> 0 | E19: =SUMIFS('0830 4度C'!$Z:$Z,'0830 4度C'!$A:$A,"新豐2線",'0830 4度C'!$B:$B,"平均") -> 0 | F19: =SUMIFS('0830 4度C'!$Z:$Z,'0830 4度C'!$A:$A,"新豐5線",'0830 4度C'!$B:$B,"平均") -> 0 | G19: =SUMIFS('0830 4度C'!$Z:$Z,'0830 4度C'!$A:$A,"新豐7線",'0830 4度C'!$B:$B,"平均") -> 0 | H19: =SUMIFS('0830 4度C'!$Z:$Z,'0830 4度C'!$A:$A,"新豐3線",'0830 4度C'!$B:$B,"平均") -> 0 | I19: =SUMIFS('0830 4度C'!$Z:$Z,'0830 4度C'!$A:$A,"新豐1線",'0830 4度C'!$B:$B,"平均") -> 0 | J19: =SUMIFS('0830 4度C'!$Z:$Z,'0830 4度C'!$A:$A,"新豐10線",'0830 4度C'!$B:$B,"平均") -> 0 | K19: =SUMIFS('0830 4度C'!$Z:$Z,'0830 4度C'!$A:$A,"新豐8線",'0830 4度C'!$B:$B,"平均") -> 0 | L19: =SUMIFS('0830 4度C'!$Z:$Z,'0830 4度C'!$A:$A,"新豐9線",'0830 4度C'!$B:$B,"平均") -> 0 | M19: =SUMIFS('0830 4度C'!$Z:$Z,'0830 4度C'!$A:$A,"新豐4線",'0830 4度C'!$B:$B,"平均") -> 0
B20: 短暫停線 (5分鐘以下) | C20: 次數 | D20: =SUMIFS('0830 4度C'!$AC:$AC,'0830 4度C'!$A:$A,"新豐6線",'0830 4度C'!$B:$B,"平均") -> 4 | E20: =SUMIFS('0830 4度C'!$AC:$AC,'0830 4度C'!$A:$A,"新豐2線",'0830 4度C'!$B:$B,"平均") -> 4 | F20: =SUMIFS('0830 4度C'!$AC:$AC,'0830 4度C'!$A:$A,"新豐5線",'0830 4度C'!$B:$B,"平均") -> 7 | G20: =SUMIFS('0830 4度C'!$AC:$AC,'0830 4度C'!$A:$A,"新豐7線",'0830 4度C'!$B:$B,"平均") -> 6 | H20: =SUMIFS('0830 4度C'!$AC:$AC,'0830 4度C'!$A:$A,"新豐3線",'0830 4度C'!$B:$B,"平均") -> 3 | I20: =SUMIFS('0830 4度C'!$AC:$AC,'0830 4度C'!$A:$A,"新豐1線",'0830 4度C'!$B:$B,"平均") -> 9 | J20: =SUMIFS('0830 4度C'!$AC:$AC,'0830 4度C'!$A:$A,"新豐10線",'0830 4度C'!$B:$B,"平均") -> 5 | K20: =SUMIFS('0830 4度C'!$AC:$AC,'0830 4度C'!$A:$A,"新豐8線",'0830 4度C'!$B:$B,"平均") -> 7 | L20: =SUMIFS('0830 4度C'!$AC:$AC,'0830 4度C'!$A:$A,"新豐9線",'0830 4度C'!$B:$B,"平均") -> 8 | M20: =SUMIFS('0830 4度C'!$AC:$AC,'0830 4度C'!$A:$A,"新豐4線",'0830 4度C'!$B:$B,"平均") -> 8
C21: 設備次數 | D21: =SUMIFS('0830 4度C'!$AD:$AD,'0830 4度C'!$A:$A,"新豐6線",'0830 4度C'!$B:$B,"平均") -> 0 | E21: =SUMIFS('0830 4度C'!$AD:$AD,'0830 4度C'!$A:$A,"新豐2線",'0830 4度C'!$B:$B,"平均") -> 0 | F21: =SUMIFS('0830 4度C'!$AD:$AD,'0830 4度C'!$A:$A,"新豐5線",'0830 4度C'!$B:$B,"平均") -> 0 | G21: =SUMIFS('0830 4度C'!$AD:$AD,'0830 4度C'!$A:$A,"新豐7線",'0830 4度C'!$B:$B,"平均") -> 0 | H21: =SUMIFS('0830 4度C'!$AD:$AD,'0830 4度C'!$A:$A,"新豐3線",'0830 4度C'!$B:$B,"平均") -> 0 | I21: =SUMIFS('0830 4度C'!$AD:$AD,'0830 4度C'!$A:$A,"新豐1線",'0830 4度C'!$B:$B,"平均") -> 0 | J21: =SUMIFS('0830 4度C'!$AD:$AD,'0830 4度C'!$A:$A,"新豐10線",'0830 4度C'!$B:$B,"平均") -> 0 | K21: =SUMIFS('0830 4度C'!$AD:$AD,'0830 4度C'!$A:$A,"新豐8線",'0830 4度C'!$B:$B,"平均") -> 0 | L21: =SUMIFS('0830 4度C'!$AD:$AD,'0830 4度C'!$A:$A,"新豐9線",'0830 4度C'!$B:$B,"平均") -> 0 | M21: =SUMIFS('0830 4度C'!$AD:$AD,'0830 4度C'!$A:$A,"新豐4線",'0830 4度C'!$B:$B,"平均") -> 0
B22: 配置人數 | D22: =SUMIFS('0830 4度C'!$I:$I,'0830 4度C'!$A:$A,"新豐6線",'0830 4度C'!$B:$B,"平均") -> 15.25 | E22: =SUMIFS('0830 4度C'!$I:$I,'0830 4度C'!$A:$A,"新豐2線",'0830 4度C'!$B:$B,"平均") -> 18.5 | F22: =SUMIFS('0830 4度C'!$I:$I,'0830 4度C'!$A:$A,"新豐5線",'0830 4度C'!$B:$B,"平均") -> 17.428571 | G22: =SUMIFS('0830 4度C'!$I:$I,'0830 4度C'!$A:$A,"新豐7線",'0830 4度C'!$B:$B,"平均") -> 16.166667 | H22: =SUMIFS('0830 4度C'!$I:$I,'0830 4度C'!$A:$A,"新豐3線",'0830 4度C'!$B:$B,"平均") -> 10 | I22: =SUMIFS('0830 4度C'!$I:$I,'0830 4度C'!$A:$A,"新豐1線",'0830 4度C'!$B:$B,"平均") -> 18.444444 | J22: =SUMIFS('0830 4度C'!$I:$I,'0830 4度C'!$A:$A,"新豐10線",'0830 4度C'!$B:$B,"平均") -> 10.4 | K22: =SUMIFS('0830 4度C'!$I:$I,'0830 4度C'!$A:$A,"新豐8線",'0830 4度C'!$B:$B,"平均") -> 17 | L22: =SUMIFS('0830 4度C'!$I:$I,'0830 4度C'!$A:$A,"新豐9線",'0830 4度C'!$B:$B,"平均") -> 16.625 | M22: =SUMIFS('0830 4度C'!$I:$I,'0830 4度C'!$A:$A,"新豐4線",'0830 4度C'!$B:$B,"平均") -> 17.25
B23: 主要應用設備 | D23: ET-55 | E23: 熱縮爐 | F23: L型包裝機 | G23: L型包裝機 | H23: 伺服包裝機 | I23: ET-55 | J23: 伺服包裝機 | K23: 三明治包裝機 | L23: 三明治包裝機 | M23: 三明治包裝機
B24: 次要應用設備 | F24: 圓盤機 | G24: ET-55
B25: 備註 | E25: 握沙拉 | F25: 共用L型包裝機 | H25: 調理麵包 | I25: 炒飯+沙拉 | J25: 調理麵包

Sheet 0830 4度C
A1: 新豐廠四度C日報分析 | C1: 總生產量 | D1: =SUM(F5:F75) -> 194783 | E1: 營業額 | F1: =SUM(G5:G75) -> 6882608.3 | G1: 出勤人數 | H1: =L9+L14+L50+L60+L22+L66+L37+L46+L29+L75 -> 157.06468 | I1: 產線配置圖 | L1: 生產實績 | O1: 人時性差異分析 | S1: 日報登錄 | Y1: 合計 次數 | Z1: 合計 時間/分 | AA1: 產線異常 分析說明(5分鐘以上) | AC1: 合計 次數 | AD1: 合計 設備次數 | AE1: 產能差異分析
A2: 46264 | B2: 星期日 | C2: 人時性 | D2: =AVERAGE(N9,N14,N50,N60,N22,N66,N29,N37,N46,N75) -> 148.14679 | E2: 平均廠價 | F2: =F1/D1 -> 35.334748 | G2: 多次生產數 | H2: =COUNT(H5:H75) -> 11 | Y2: =SUM(Y9+Y14+Y22+Y29+Y37+Y46+Y50+Y60+Y66+Y75) -> 0 | Z2: =SUM(Z9+Z14+Z22+Z29+Z37+Z46+Z50+Z60+Z66+Z75) -> 0 | AC2: 61 | AD2: =SUM(AD9+AD14+AD22+AD29+AD37+AD46+AD50+AD60+AD66+AD75) -> 0
A3: 線別 | B3: 品類 | C3: 品名 | E3: 廠價 | F3: 生產量 | G3: 營收 | H3: 多次 生產 | I3: 人數 | J3: 產能/時 | K3: 人時性 | L3: 人數 | M3: 產能/時 | N3: 人時性 | O3: 人數 | P3: 人時性 | Q3: 達成率 | R3: 達成率平均 | S3: 生產時間 | U3: 換線、休息/分 | V3: 稼動時間/分 | W3: 休息時間 | Y3: 產線異常統計 (5分鐘以上) | AA3: (新豐回填) | AC3: 短暫停線統計 (5分鐘以下) | AE3: 產能/時 | AF3: 達成率 | AG3: 達成率平均
S4: 開始 | T4: 結束 | W4: 開始 | X4: 結束 | Y4: 次數 | Z4: 時間/分 | AC4: 總次數 | AD4: 設備因素(次數)
A5: 新豐6線 | B5: 微波主食 | C5: 二配金咖哩果香甘口咖哩飯 | E5: 50.92 | F5: 1000 | G5: =E5*F5 -> 50920 | H5: 2 | I5: 15 | J5: 2000 | K5: =J5/I5 -> 133.33333 | L5: 15 | M5: =F5/V5*60 -> 1935.4839 | N5: =M5/L5 -> 129.03226 | O5: =L5-I5 -> 0 | P5: =N5-K5 -> -4.3010753 | Q5: =N5/K5 -> 0.96774194 | R5: =Q9 -> 0.95962334 | S5: 0.70833333 | T5: 0.72986111 | V5: =(T5-S5)*24*60 -> 31 | AC5: 4 | AE5: =M5-J5 -> -64.516129 | AF5: =M5/J5 -> 0.96774194 | AG5: =AF9 -> 0.95962334
A6: 新豐6線 | B6: 微波主食 | C6: 二配金咖哩濃厚辛口咖哩飯 | E6: 50.98 | F6: 2745 | G6: =E6*F6 -> 139940.1 | I6: 16 | J6: 2000 | K6: =J6/I6 -> 125 | L6: 16 | M6: =F6/V6*60 -> 1915.1163 | N6: =M6/L6 -> 119.69477 | O6: =L6-I6 -> 0 | P6: =N6-K6 -> -5.3052326 | Q6: =N6/K6 -> 0.95755814 | S6: 0.73402778 | T6: 0.79375 | U6: =IF(S6=TIME(17,0,0),"",(S6-T5)*24*60) -> 6 | V6: =(T6-S6)*24*60 -> 86 | AE6: =M6-J6 -> -84.883721 | AF6: =M6/J6 -> 0.95755814
A7: 新豐6線 | B7: 微波主食 | C7: 二配泰式綠咖哩雞 | E7: 50.67 | F7: 1635 | G7: =E7*F7 -> 82845.45 | I7: 15 | J7: 2000 | K7: =J7/I7 -> 133.33333 | L7: 15 | M7: =F7/V7*60 -> 1923.5294 | N7: =M7/L7 -> 128.23529 | O7: =L7-I7 -> 0 | P7: =N7-K7 -> -5.0980392 | Q7: =N7/K7 -> 0.96176471 | S7: 0.79722222 | T7: 0.83263889 | U7: =IF(S7=TIME(17,0,0),"",(S7-T6)*24*60) -> 5 | V7: =(T7-S7)*24*60 -> 51 | W7: =T7 -> 0.83263889 | X7: =S8 -> 0.87430556 | AE7: =M7-J7 -> -76.470588 | AF7: =M7/J7 -> 0.96176471
A8: 新豐6線 | B8: 微波主食 | C8: 二配金咖哩果香甘口咖哩飯 | E8: 50.92 | F8: 1554 | G8: =E8*F8 -> 79129.68 | I8: 15 | J8: 2000 | K8: =J8/I8 -> 133.33333 | L8: 15 | M8: =F8/V8*60 -> 1902.8571 | N8: =M8/L8 -> 126.85714 | O8: =L8-I8 -> 0 | P8: =N8-K8 -> -6.4761905 | Q8: =N8/K8 -> 0.95142857 | S8: 0.87430556 | T8: 0.90833333 | U8: =IF(S8=TIME(17,0,0),"",(S8-T7)*24*60) -> 60 | V8: =(T8-S8)*24*60 -> 49 | AE8: =M8-J8 -> -97.142857 | AF8: =M8/J8 -> 0.95142857
A9: 新豐6線 | B9: 平均 | I9: 15.25 | J9: 2000 | K9: =J9/I9 -> 131.14754 | L9: 15.25 | M9: =AVERAGE(M5:M8) -> 1919.2467 | N9: =M9/L9 -> 125.85224 | O9: =L9-I9 -> 0 | P9: =N9-K9 -> -5.2952999 | Q9: =N9/K9 -> 0.95962334 | Y9: =SUM(Y5:Y8) -> 0 | Z9: =SUM(Z5:Z8) -> 0 | AC9: 4 | AD9: =SUM(AD5:AD8) -> 0 | AE9: =M9-J9 -> -80.753324 | AF9: =M9/J9 -> 0.95962334
A10: 新豐2線 | B10: 沙拉 | C10: 青醬優格雞肉握沙拉(113年) | E10: 39.62 | F10: 2800 | G10: =E10*F10 -> 110936 | H10: 2 | I10: 19 | J10: 1500 | K10: =J10/I10 -> 78.947368 | L10: 19 | M10: =F10/V10*60 -> 1435.8974 | N10: =M10/L10 -> 75.573549 | O10: =L10-I10 -> 0 | P10: =N10-K10 -> -3.3738192 | Q10: =N10/K10 -> 0.95726496 | R10: =Q14 -> 0.9576171 | S10: 0.083333333 | T10: 0.16458333 | V10: =(T10-S10)*24*60 -> 117 | W10: =T10 -> 0.16458333 | X10: =S11 -> 0.18472222 | AC10: 4 | AE10: =M10-J10 -> -64.102564 | AF10: =M10/J10 -> 0.95726496 | AG10: =AF14 -> 0.9576171
A11: 新豐2線 | B11: 沙拉 | C11: 青檸烤雞握沙拉(113年) | E11: 39.8 | F11: 7721 | G11: =E11*F11 -> 307295.8 | I11: 17 | J11: 1500 | K11: =J11/I11 -> 88.235294 | L11: 17 | M11: =F11/V11*60 -> 1434.2415 | N11: =M11/L11 -> 84.367146 | O11: =L11-I11 -> 0 | P11: =N11-K11 -> -3.8681479 | Q11: =N11/K11 -> 0.95616099 | S11: 0.18472222 | T11: 0.40902778 | U11: =IF(S11=TIME(17,0,0),"",(S11-T10)*24*60) -> 29 | V11: =(T11-S11)*24*60 -> 323 | AE11: =M11-J11 -> -65.758514 | AF11: =M11/J11 -> 0.95616099
A12: 新豐2線 | B12: 沙拉 | C12: 地瓜瓜握沙拉 | E12: 39.52 | F12: 2325 | G12: =E12*F12 -> 91884 | I12: 19 | J12: 1500 | K12: =J12/I12 -> 78.947368 | L12: 19 | M12: =F12/V12*60 -> 1438.1443 | N12: =M12/L12 -> 75.691807 | O12: =L12-I12 -> 0 | P12: =N12-K12 -> -3.2555616 | Q12: =N12/K12 -> 0.95876289 | S12: 0.41388889 | T12: 0.48125 | U12: =IF(S12=TIME(17,0,0),"",(S12-T11)*24*60) -> 7 | V12: =(T12-S12)*24*60 -> 97 | W12: =T12 -> 0.48125 | X12: =S13 -> 0.52222222 | AE12: =M12-J12 -> -61.85567 | AF12: =M12/J12 -> 0.95876289
A13: 新豐2線 | B13: 沙拉 | C13: 青醬優格雞肉握沙拉(113年) | E13: 39.62 | F13: 2228 | G13: =E13*F13 -> 88273.36 | I13: 19 | J13: 1500 | K13: =J13/I13 -> 78.947368 | L13: 19 | M13: =F13/V13*60 -> 1437.4194 | N13: =M13/L13 -> 75.65365 | O13: =L13-I13 -> 0 | P13: =N13-K13 -> -3.2937182 | Q13: =N13/K13 -> 0.95827957 | S13: 0.52222222 | T13: 0.58680556 | U13: =IF(S13=TIME(17,0,0),"",(S13-T12)*24*60) -> 59 | V13: =(T13-S13)*24*60 -> 93 | AE13: =M13-J13 -> -62.580645 | AF13: =M13/J13 -> 0.95827957
A14: 新豐2線 | B14: 平均 | I14: 18.5 | J14: 1500 | K14: =J14/I14 -> 81.081081 | L14: 18.5 | M14: =AVERAGE(M10:M13) -> 1436.4257 | N14: =M14/L14 -> 77.64463 | O14: =L14-I14 -> 0 | P14: =N14-K14 -> -3.4364513 | Q14: =N14/K14 -> 0.9576171 | Y14: =SUM(Y10:Y13) -> 0 | Z14: =SUM(Z10:Z13) -> 0 | AC14: 4 | AD14: =SUM(AD10:AD13) -> 0 | AE14: =M14-J14 -> -63.574348 | AF14: =M14/J14 -> 0.9576171
A15: 新豐5線 | B15: 季節調理麵 | C15: 台式麻醬涼麵(115年) | E15: 31.11 | F15: 3524 | G15: =E15*F15 -> 109631.64 | I15: 14 | J15: 2000 | K15: =J15/I15 -> 142.85714 | L15: 14 | M15: =F15/V15*60 -> 1904.8649 | N15: =M15/L15 -> 136.06178 | O15: =L15-I15 -> 0 | P15: =N15-K15 -> -6.7953668 | Q15: =N15/K15 -> 0.95243243 | R15: =Q22 -> 0.95872924 | S15: 0.20833333 | T15: 0.28541667 | V15: =(T15-S15)*24*60 -> 111 | AC15: 7 | AE15: =M15-J15 -> -95.135135 | AF15: =M15/J15 -> 0.95243243 | AG15: =AF22 -> 0.95872924
A16: 新豐5線 | B16: 小吃 | C16: 剝皮辣椒雞湯 | E16: 41 | F16: 1720 | G16: =E16*F16 -> 70520 | I16: 26 | J16: 1500 | K16: =J16/I16 -> 57.692308 | L16: 26 | M16: =F16/V16*60 -> 1433.3333 | N16: =M16/L16 -> 55.128205 | O16: =L16-I16 -> 0 | P16: =N16-K16 -> -2.5641026 | Q16: =N16/K16 -> 0.95555556 | S16: 0.29097222 | T16: 0.34097222 | U16: =IF(S16=TIME(17,0,0),"",(S16-T15)*24*60) -> 8 | V16: =(T16-S16)*24*60 -> 72 | AE16: =M16-J16 -> -66.666667 | AF16: =M16/J16 -> 0.95555556
A17: 新豐5線 | B17: 季節調理麵 | C17: 嫩烤魚排佐花椰菜義大利麵 | E17: 68.88 | F17: 3315 | G17: =E17*F17 -> 228337.2 | I17: 16 | J17: 2000 | K17: =J17/I17 -> 125 | L17: 16 | M17: =F17/V17*60 -> 1912.5 | N17: =M17/L17 -> 119.53125 | O17: =L17-I17 -> 0 | P17: =N17-K17 -> -5.46875 | Q17: =N17/K17 -> 0.95625 | S17: 0.34583333 | T17: 0.41805556 | U17: =IF(S17=TIME(17,0,0),"",(S17-T16)*24*60) -> 7 | V17: =(T17-S17)*24*60 -> 104 | AE17: =M17-J17 -> -87.5 | AF17: =M17/J17 -> 0.95625
A18: 新豐5線 | B18: 沙拉 | C18: 厚蛋時蔬握沙拉 | E18: 39.46 | F18: 2456 | G18: =E18*F18 -> 96913.76 | I18: 15 | J18: 1500 | K18: =J18/I18 -> 100 | L18: 15 | M18: =F18/V18*60 -> 1430.6796 | N18: =M18/L18 -> 95.378641 | O18: =L18-I18 -> 0 | P18: =N18-K18 -> -4.6213592 | Q18: =N18/K18 -> 0.95378641 | S18: 0.42222222 | T18: 0.49375 | U18: =IF(S18=TIME(17,0,0),"",(S18-T17)*24*60) -> 6 | V18: =(T18-S18)*24*60 -> 103 | AE18: =M18-J18 -> -69.320388 | AF18: =M18/J18 -> 0.95378641
A19: 新豐5線 | B19: 微波主食 | C19: 二配玉米濃湯焗烤飯 | E19: 54.5 | F19: 1403 | G19: =E19*F19 -> 76463.5 | I19: 19 | J19: 1500 | K19: =J19/I19 -> 78.947368 | L19: 19 | M19: =F19/V19*60 -> 1451.3793 | N19: =M19/L19 -> 76.388385 | O19: =L19-I19 -> 0 | P19: =N19-K19 -> -2.5589837 | Q19: =N19/K19 -> 0.96758621 | S19: 0.70833333 | T19: 0.74861111 | U19: =IF(S19=TIME(17,0,0),"",(S19-T18)*24*60) | V19: =(T19-S19)*24*60 -> 58 | AE19: =M19-J19 -> -48.62069 | AF19: =M19/J19 -> 0.96758621
A20: 新豐5線 | B20: 微波主食 | C20: 二配港式香滑嫩蛋牛肉燴飯 | E20: 50.67 | F20: 1900 | G20: =E20*F20 -> 96273 | I20: 17 | J20: 2000 | K20: =J20/I20 -> 117.64706 | L20: 17 | M20: =F20/V20*60 -> 1932.2034 | N20: =M20/L20 -> 113.65902 | O20: =L20-I20 -> 0 | P20: =N20-K20 -> -3.9880359 | Q20: =N20/K20 -> 0.96610169 | S20: 0.75208333 | T20: 0.79305556 | U20: =IF(S20=TIME(17,0,0),"",(S20-T19)*24*60) -> 5 | V20: =(T20-S20)*24*60 -> 59 | AE20: =M20-J20 -> -67.79661 | AF20: =M20/J20 -> 0.96610169
A21: 新豐5線 | B21: 微波主食 | C21: 二配川味麻婆燒豆腐燴飯 | E21: 50.49 | F21: 2271 | G21: =E21*F21 -> 114662.79 | I21: 15 | J21: 2000 | K21: =J21/I21 -> 133.33333 | L21: 15 | M21: =F21/V21*60 -> 1919.1549 | N21: =M21/L21 -> 127.94366 | O21: =L21-I21 -> 0 | P21: =N21-K21 -> -5.3896714 | Q21: =N21/K21 -> 0.95957746 | S21: 0.79652778 | T21: 0.84583333 | U21: =IF(S21=TIME(17,0,0),"",(S21-T20)*24*60) -> 5 | V21: =(T21-S21)*24*60 -> 71 | AE21: =M21-J21 -> -80.84507 | AF21: =M21/J21 -> 0.95957746
A22: 新豐5線 | B22: 平均 | I22: 17.428571 | J22: 1785.7143 | K22: =J22/I22 -> 102.45902 | L22: 17.428571 | M22: =AVERAGE(M15:M21) -> 1712.0165 | N22: =M22/L22 -> 98.230454 | O22: =L22-I22 -> 0 | P22: =N22-K22 -> -4.228562 | Q22: =N22/K22 -> 0.95872924 | Y22: =SUM(Y15:Y21) -> 0 | Z22: =SUM(Z15:Z21) -> 0 | AC22: 7 | AD22: =SUM(AD15:AD21) -> 0 | AE22: =M22-J22 -> -73.697794 | AF22: =M22/J22 -> 0.95872924
A23: 新豐7線 | B23: 微波主食 | C23: 韓式泡菜豬肉豆腐丼飯 | E23: 50.67 | F23: 1846 | G23: =E23*F23 -> 93536.82 | I23: 17 | J23: 2000 | K23: =J23/I23 -> 117.64706 | L23: 17 | M23: =F23/V23*60 -> 1909.6552 | N23: =M23/L23 -> 112.33266 | O23: =L23-I23 -> 0 | P23: =N23-K23 -> -5.3144016 | Q23: =N23/K23 -> 0.95482759 | R23: =Q29 -> 0.95812003 | S23: 0.20833333 | T23: 0.24861111 | V23: =(T23-S23)*24*60 -> 58 | AC23: 6 | AE23: =M23-J23 -> -90.344828 | AF23: =M23/J23 -> 0.95482759 | AG23: =AF29 -> 0.95812003
A24: 新豐7線 | B24: 微波主食 | C24: 鐵板滑蛋炸豬排丼 | E24: 57.73 | F24: 3303 | G24: =E24*F24 -> 190682.19 | I24: 14 | J24: 2000 | K24: =J24/I24 -> 142.85714 | L24: 14 | M24: =F24/V24*60 -> 1905.5769 | N24: =M24/L24 -> 136.11264 | O24: =L24-I24 -> 0 | P24: =N24-K24 -> -6.7445055 | Q24: =N24/K24 -> 0.95278846 | S24: 0.25277778 | T24: 0.325 | U24: =IF(S24=TIME(17,0,0),"",(S24-T23)*24*60) -> 6 | V24: =(T24-S24)*24*60 -> 104 | AE24: =M24-J24 -> -94.423077 | AF24: =M24/J24 -> 0.95278846
A25: 新豐7線 | B25: 微波主食 | C25: 日式炙烤親子丼 | E25: 53.27 | F25: 2153 | G25: =E25*F25 -> 114690.31 | I25: 16 | J25: 2000 | K25: =J25/I25 -> 125 | L25: 16 | M25: =F25/V25*60 -> 1928.0597 | N25: =M25/L25 -> 120.50373 | O25: =L25-I25 -> 0 | P25: =N25-K25 -> -4.4962687 | Q25: =N25/K25 -> 0.96402985 | S25: 0.32986111 | T25: 0.37638889 | U25: =IF(S25=TIME(17,0,0),"",(S25-T24)*24*60) -> 7 | V25: =(T25-S25)*24*60 -> 67 | AE25: =M25-J25 -> -71.940299 | AF25: =M25/J25 -> 0.96402985
A26: 新豐7線 | B26: 微波主食 | C26: 爆炒雞丁飯 | E26: 59.04 | F26: 1286 | G26: =E26*F26 -> 75925.44 | I26: 19 | J26: 2000 | K26: =J26/I26 -> 105.26316 | L26: 19 | M26: =F26/V26*60 -> 1929 | N26: =M26/L26 -> 101.52632 | O26: =L26-I26 -> 0 | P26: =N26-K26 -> -3.7368421 | Q26: =N26/K26 -> 0.9645 | S26: 0.37986111 | T26: 0.40763889 | U26: =IF(S26=TIME(17,0,0),"",(S26-T25)*24*60) -> 5 | V26: =(T26-S26)*24*60 -> 40 | AE26: =M26-J26 -> -71 | AF26: =M26/J26 -> 0.9645
A27: 新豐7線 | B27: 微波主食 | C27: 二配打拋風味豬肉飯 | E27: 51.06 | F27: 3207 | G27: =E27*F27 -> 163749.42 | I27: 13 | J27: 2000 | K27: =J27/I27 -> 153.84615 | L27: 13 | M27: =F27/V27*60 -> 1905.1485 | N27: =M27/L27 -> 146.54989 | O27: =L27-I27 -> 0 | P27: =N27-K27 -> -7.2962681 | Q27: =N27/K27 -> 0.95257426 | S27: 0.70833333 | T27: 0.77847222 | U27: =IF(S27=TIME(17,0,0),"",(S27-T26)*24*60) | V27: =(T27-S27)*24*60 -> 101 | AE27: =M27-J27 -> -94.851485 | AF27: =M27/J27 -> 0.95257426
A28: 新豐7線 | B28: 微波主食 | C28: 二配美味蟹煲 | E28: 54.09 | F28: 2528 | G28: =E28*F28 -> 136739.52 | I28: 18 | J28: 2000 | K28: =J28/I28 -> 111.11111 | L28: 18 | M28: =F28/V28*60 -> 1920 | N28: =M28/L28 -> 106.66667 | O28: =L28-I28 -> 0 | P28: =N28-K28 -> -4.4444444 | Q28: =N28/K28 -> 0.96 | S28: 0.78194444 | T28: 0.83680556 | U28: =IF(S28=TIME(17,0,0),"",(S28-T27)*24*60) -> 5 | V28: =(T28-S28)*24*60 -> 79 | AE28: =M28-J28 -> -80 | AF28: =M28/J28 -> 0.96
A29: 新豐7線 | B29: 平均 | I29: 16.166667 | J29: 2000 | K29: =J29/I29 -> 123.71134 | L29: 16.166667 | M29: =AVERAGE(M23:M28) -> 1916.2401 | N29: =M29/L29 -> 118.53031 | O29: =L29-I29 -> 0 | P29: =N29-K29 -> -5.1810277 | Q29: =N29/K29 -> 0.95812003 | Y29: =SUM(Y23:Y28) -> 0 | Z29: =SUM(Z23:Z28) -> 0 | AC29: 6 | AD29: =SUM(AD23:AD28) -> 0 | AE29: =M29-J29 -> -83.759948 | AF29: =M29/J29 -> 0.95812003
A30: 新豐8線 | B30: 三明治 | C30: 紐奧良風味烤雞鮮蔬三明治 | E30: 31.29 | F30: 5800 | G30: =E30*F30 -> 181482 | H30: 2 | I30: 18 | J30: 2400 | K30: =J30/I30 -> 133.33333 | L30: 18 | M30: =F30/V30*60 -> 2289.4737 | N30: =M30/L30 -> 127.19298 | O30: =L30-I30 -> 0 | P30: =N30-K30 -> -6.1403509 | Q30: =N30/K30 -> 0.95394737 | R30: =Q37 -> 0.95513937 | S30: 0.083333333 | T30: 0.18888889 | V30: =(T30-S30)*24*60 -> 152 | W30: =T30 -> 0.18888889 | X30: =S31 -> 0.20625 | AC30: 7 | AE30: =M30-J30 -> -110.52632 | AF30: =M30/J30 -> 0.95394737 | AG30: =AF37 -> 0.95513937
A31: 新豐8線 | B31: 三明治 | C31: 醬燒烤雞三明治(115年) | E31: 26.37 | F31: 4200 | G31: =E31*F31 -> 110754 | H31: 2 | I31: 18 | J31: 2400 | K31: =J31/I31 -> 133.33333 | L31: 18 | M31: =F31/V31*60 -> 2290.9091 | N31: =M31/L31 -> 127.27273 | O31: =L31-I31 -> 0 | P31: =N31-K31 -> -6.0606061 | Q31: =N31/K31 -> 0.95454545 | S31: 0.20625 | T31: 0.28263889 | U31: =(S31-T30)*24*60 -> 25 | V31: =(T31-S31)*24*60 -> 110 | AE31: =M31-J31 -> -109.09091 | AF31: =M31/J31 -> 0.95454545
A32: 新豐8線 | B32: 三明治 | C32: 經典火腿玉米蛋三明治 | E32: 24.43 | F32: 4500 | G32: =E32*F32 -> 109935 | H32: 2 | I32: 14 | J32: 2400 | K32: =J32/I32 -> 171.42857 | L32: 14 | M32: =F32/V32*60 -> 2288.1356 | N32: =M32/L32 -> 163.43826 | O32: =L32-I32 -> 0 | P32: =N32-K32 -> -7.9903148 | Q32: =N32/K32 -> 0.95338983 | S32: 0.2875 | T32: 0.36944444 | U32: =(S32-T31)*24*60 -> 7 | V32: =(T32-S32)*24*60 -> 118 | AE32: =M32-J32 -> -111.86441 | AF32: =M32/J32 -> 0.95338983
A33: 新豐8線 | B33: 三明治 | C33: 好多蛋三明治 | E33: 34.1 | F33: 4000 | G33: =E33*F33 -> 136400 | H33: 2 | I33: 17 | J33: 1600 | K33: =J33/I33 -> 94.117647 | L33: 17 | M33: =F33/V33*60 -> 1528.6624 | N33: =M33/L33 -> 89.921319 | O33: =L33-I33 -> 0 | P33: =N33-K33 -> -4.1963282 | Q33: =N33/K33 -> 0.95541401 | S33: 0.37430556 | T33: 0.48333333 | U33: =(S33-T32)*24*60 -> 7 | V33: =(T33-S33)*24*60 -> 157 | W33: =T33 -> 0.48333333 | X33: =S34 -> 0.52222222 | AE33: =M33-J33 -> -71.33758 | AF33: =M33/J33 -> 0.95541401
A34: 新豐8線 | B34: 三明治 | C34: 紐奧良風味烤雞鮮蔬三明治 | E34: 31.29 | F34: 4698 | G34: =E34*F34 -> 147000.42 | I34: 18 | J34: 2400 | K34: =J34/I34 -> 133.33333 | L34: 18 | M34: =F34/V34*60 -> 2291.7073 | N34: =M34/L34 -> 127.31707 | O34: =L34-I34 -> 0 | P34: =N34-K34 -> -6.0162602 | Q34: =N34/K34 -> 0.95487805 | S34: 0.52222222 | T34: 0.60763889 | U34: =(S34-T33)*24*60 -> 56 | V34: =(T34-S34)*24*60 -> 123 | AE34: =M34-J34 -> -108.29268 | AF34: =M34/J34 -> 0.95487805
A35: 新豐8線 | B35: 三明治 | C35: 經典火腿玉米蛋三明治 | E35: 24.43 | F35: 3810 | G35: =E35*F35 -> 93078.3 | I35: 14 | J35: 2400 | K35: =J35/I35 -> 171.42857 | L35: 14 | M35: =F35/V35*60 -> 2286 | N35: =M35/L35 -> 163.28571 | O35: =L35-I35 -> 0 | P35: =N35-K35 -> -8.1428571 | Q35: =N35/K35 -> 0.9525 | S35: 0.6125 | T35: 0.68194444 | U35: =(S35-T34)*24*60 -> 7 | V35: =(T35-S35)*24*60 -> 100 | AE35: =M35-J35 -> -114 | AF35: =M35/J35 -> 0.9525
A36: 新豐8線 | B36: 三明治 | C36: 經典總匯三明治(115年) | E36: 26.18 | F36: 3038 | G36: =E36*F36 -> 79534.84 | I36: 20 | J36: 2400 | K36: =J36/I36 -> 120 | L36: 20 | M36: =F36/V36*60 -> 2307.3418 | N36: =M36/L36 -> 115.36709 | O36: =L36-I36 -> 0 | P36: =N36-K36 -> -4.6329114 | Q36: =N36/K36 -> 0.96139241 | S36: 0.6875 | T36: 0.74236111 | U36: =(S36-T35)*24*60 -> 8 | V36: =(T36-S36)*24*60 -> 79 | AE36: =M36-J36 -> -92.658228 | AF36: =M36/J36 -> 0.96139241
A37: 新豐8線 | B37: 平均 | I37: 17 | J37: 2285.7143 | K37: =J37/I37 -> 134.45378 | L37: 17 | M37: =AVERAGE(M30:M36) -> 2183.1757 | N37: =M37/L37 -> 128.4221 | O37: =L37-I37 -> 0 | P37: =N37-K37 -> -6.0316817 | Q37: =N37/K37 -> 0.95513937 | Y37: =SUM(Y30:Y36) -> 0 | Z37: =SUM(Z30:Z36) -> 0 | AC37: 7 | AD37: =SUM(AD30:AD36) -> 0 | AE37: =M37-J37 -> -102.53859 | AF37: =M37/J37 -> 0.95513937
A38: 新豐9線 | B38: 三明治 | C38: 經典總匯三明治(115年) | E38: 26.18 | F38: 3900 | G38: =E38*F38 -> 102102 | H38: 2 | I38: 20 | J38: 2400 | K38: =J38/I38 -> 120 | L38: 20 | M38: =F38/V38*60 -> 2294.1176 | N38: =M38/L38 -> 114.70588 | O38: =L38-I38 -> 0 | P38: =N38-K38 -> -5.2941176 | Q38: =N38/K38 -> 0.95588235 | R38: =Q46 -> 0.95645929 | S38: 0.083333333 | T38: 0.15416667 | V38: =(T38-S38)*24*60 -> 102 | W38: =T38 -> 0.15416667 | X38: =S39 -> 0.17222222 | AC38: 8 | AE38: =M38-J38 -> -105.88235 | AF38: =M38/J38 -> 0.95588235 | AG38: =AF46 -> 0.95645929
A39: 新豐9線 | B39: 三明治 | C39: 雙泰奶QQ三明治 | E39: 23.89 | F39: 1541 | G39: =E39*F39 -> 36814.49 | I39: 13 | J39: 2400 | K39: =J39/I39 -> 184.61538 | L39: 13 | M39: =F39/V39*60 -> 2311.5 | N39: =M39/L39 -> 177.80769 | O39: =L39-I39 -> 0 | P39: =N39-K39 -> -6.8076923 | Q39: =N39/K39 -> 0.963125 | S39: 0.17222222 | T39: 0.2 | U39: =(S39-T38)*24*60 -> 26 | V39: =(T39-S39)*24*60 -> 40 | AE39: =M39-J39 -> -88.5 | AF39: =M39/J39 -> 0.963125
A40: 新豐9線 | B40: 三明治 | C40: 鮪魚起司溏心蛋三明治(115年) | E40: 26.18 | F40: 5300 | G40: =E40*F40 -> 138754 | H40: 2 | I40: 18 | J40: 2400 | K40: =J40/I40 -> 133.33333 | L40: 18 | M40: =F40/V40*60 -> 2287.7698 | N40: =M40/L40 -> 127.09832 | O40: =L40-I40 -> 0 | P40: =N40-K40 -> -6.235012 | Q40: =N40/K40 -> 0.95323741 | S40: 0.20347222 | T40: 0.3 | U40: =(S40-T39)*24*60 -> 5 | V40: =(T40-S40)*24*60 -> 139 | AE40: =M40-J40 -> -112.23022 | AF40: =M40/J40 -> 0.95323741
...

Sheet 0829
B1: 屏榮 新豐廠組合室生產人時性分析
B3: 日期 | C3: =TEXT('0829 4度C'!A2,"yyyy.mm.ddaaaa") -> 2026.08.29星期六 | E3: 訂單量 | F3: ='0829 4度C'!D1 -> 145160 | H3: 營業額 | I3: ='0829 4度C'!F1 -> 5143553.2
B4: 人時性 | C4: 項目 | E4: ➀ | G4: ➁ | I4: ➂ | K4: 異常停線 | M4: 短暫停線
C5: 組合室 | E5: 全溫層 | G5: 4度C-各編組展開 | I5: ③三明治-各編組展開 | K5: 合計次數 | L5: 時間 | M5: 合計次數 | N5: 設備次數
C6: 排關平均 | E6: =AVERAGE(D13:M13) -> 156.06948 | F6: =AVERAGE(D31:O31,D13:J13) -> 162.63589 | G6: =AVERAGE(D13:J13) -> 162.63589 | I6: =AVERAGE(K13:M13) -> 140.74785 | K6: ='0829 4度C'!Y2 -> 0 | L6: ='0829 4度C'!Z2 -> 0 | M6: ='0829 4度C'!AC2 -> 52 | N6: ='0829 4度C'!AD2 -> 0
C7: 實績平均 | E7: =AVERAGE(D14:M14) -> 149.44208 | F7: =AVERAGE(D32:O32,D14:J14) -> 155.81796 | G7: =AVERAGE(D14:J14) -> 155.81796 | I7: =AVERAGE(K14:M14) -> 134.56501
C8: 達成率平均 | E8: =AVERAGE(D15:M15) -> 0.95827737 | F8: =AVERAGE(D15:J15,D33:O33) -> 0.95924252 | G8: =AVERAGE(D15:J15) -> 0.95924252 | I8: =AVERAGE(K15:M15) -> 0.95602534
K9: ※現行日本鮮食廠以達成率80%為基本(即為現行KPI)
B10: 溫層 | D10: ➁4度C-各編組展開 | K10: ③三明治-各編組展開
B11: 編組 | D11: 1 | E11: 2 | F11: 3 | G11: 4 | H11: 5 | I11: 6 | J11: 7 | K11: 1 | L11: 2 | M11: 3
D12: 新豐6線 | E12: 新豐2線 | F12: 新豐5線 | G12: 新豐7線 | H12: 新豐3線 | I12: 新豐1線 | J12: 新豐10線 | K12: 新豐8線 | L12: 新豐9線 | M12: 新豐4線
B13: 人時性 | C13: 排關 | D13: =SUMIFS('0829 4度C'!$K:$K,'0829 4度C'!$A:$A,"新豐6線",'0829 4度C'!$B:$B,"平均") -> 129.03226 | E13: =SUMIFS('0829 4度C'!$K:$K,'0829 4度C'!$A:$A,"新豐2線",'0829 4度C'!$B:$B,"平均") -> 88.235294 | F13: =SUMIFS('0829 4度C'!$K:$K,'0829 4度C'!$A:$A,"新豐5線",'0829 4度C'!$B:$B,"平均") -> 96.899225 | G13: =SUMIFS('0829 4度C'!$K:$K,'0829 4度C'!$A:$A,"新豐7線",'0829 4度C'!$B:$B,"平均") -> 128.44037 | H13: =SUMIFS('0829 4度C'!$K:$K,'0829 4度C'!$A:$A,"新豐3線",'0829 4度C'!$B:$B,"平均") -> 300 | I13: =SUMIFS('0829 4度C'!$K:$K,'0829 4度C'!$A:$A,"新豐1線",'0829 4度C'!$B:$B,"平均") -> 107.38255 | J13: =SUMIFS('0829 4度C'!$K:$K,'0829 4度C'!$A:$A,"新豐10線",'0829 4度C'!$B:$B,"平均") -> 288.46154 | K13: =SUMIFS('0829 4度C'!$K:$K,'0829 4度C'!$A:$A,"新豐8線",'0829 4度C'!$B:$B,"平均") -> 137.37374 | L13: =SUMIFS('0829 4度C'!$K:$K,'0829 4度C'!$A:$A,"新豐9線",'0829 4度C'!$B:$B,"平均") -> 146.93878 | M13: =SUMIFS('0829 4度C'!$K:$K,'0829 4度C'!$A:$A,"新豐4線",'0829 4度C'!$B:$B,"平均") -> 137.93103
C14: 實績 | D14: =SUMIFS('0829 4度C'!$N:$N,'0829 4度C'!$A:$A,"新豐6線",'0829 4度C'!$B:$B,"平均") -> 124.19207 | E14: =SUMIFS('0829 4度C'!$N:$N,'0829 4度C'!$A:$A,"新豐2線",'0829 4度C'!$B:$B,"平均") -> 84.210979 | F14: =SUMIFS('0829 4度C'!$N:$N,'0829 4度C'!$A:$A,"新豐5線",'0829 4度C'!$B:$B,"平均") -> 92.893233 | G14: =SUMIFS('0829 4度C'!$N:$N,'0829 4度C'!$A:$A,"新豐7線",'0829 4度C'!$B:$B,"平均") -> 124.03467 | H14: =SUMIFS('0829 4度C'!$N:$N,'0829 4度C'!$A:$A,"新豐3線",'0829 4度C'!$B:$B,"平均") -> 285.946 | I14: =SUMIFS('0829 4度C'!$N:$N,'0829 4度C'!$A:$A,"新豐1線",'0829 4度C'!$B:$B,"平均") -> 103.47294 | J14: =SUMIFS('0829 4度C'!$N:$N,'0829 4度C'!$A:$A,"新豐10線",'0829 4度C'!$B:$B,"平均") -> 275.97583 | K14: =SUMIFS('0829 4度C'!$N:$N,'0829 4度C'!$A:$A,"新豐8線",'0829 4度C'!$B:$B,"平均") -> 131.17975 | L14: =SUMIFS('0829 4度C'!$N:$N,'0829 4度C'!$A:$A,"新豐9線",'0829 4度C'!$B:$B,"平均") -> 140.78505 | M14: =SUMIFS('0829 4度C'!$N:$N,'0829 4度C'!$A:$A,"新豐4線",'0829 4度C'!$B:$B,"平均") -> 131.73022
C15: 達成率 | D15: =D14/D13 -> 0.96248856 | E15: =E14/E13 -> 0.95439109 | F15: =F14/F13 -> 0.95865817 | G15: =G14/G13 -> 0.96569852 | H15: =H14/H13 -> 0.95315333 | I15: =I14/I13 -> 0.96359178 | J15: =J14/J13 -> 0.95671623 | K15: =K14/K13 -> 0.95491144 | ... M15: =M14/M13 -> 0.95504407
B16: 作業 時間 | C16: 開始 | D16: =VLOOKUP("新豐6線",'0829 4度C'!$A:$T,19,0) -> 0.70833333 | E16: =VLOOKUP("新豐2線",'0829 4度C'!$A:$T,19,0) -> 0.083333333 | F16: =VLOOKUP("新豐5線",'0829 4度C'!$A:$T,19,0) -> 0.20833333 | G16: =VLOOKUP("新豐7線",'0829 4度C'!$A:$T,19,0) -> 0.20833333 | H16: =VLOOKUP("新豐3線",'0829 4度C'!$A:$T,19,0) -> 0.20833333 | I16: =VLOOKUP("新豐1線",'0829 4度C'!$A:$T,19,0) -> 0.20833333 | J16: =VLOOKUP("新豐10線",'0829 4度C'!$A:$T,19,0) -> 0.20833333 | K16: =VLOOKUP("新豐8線",'0829 4度C'!$A:$T,19,0) -> 0.083333333 | L16: =VLOOKUP("新豐9線",'0829 4度C'!$A:$T,19,0) -> 0.083333333 | M16: =VLOOKUP("新豐4線",'0829 4度C'!$A:$T,19,0) -> 0.083333333
C17: 結束 | D17: =LOOKUP(2,1/(('0829 4度C'!$A:$A="新豐6線")*('0829 4度C'!$T:$T<>"")),'0829 4度C'!$T:$T) -> 0.8125 | E17: =LOOKUP(2,1/(('0829 4度C'!$A:$A="新豐2線")*('0829 4度C'!$T:$T<>"")),'0829 4度C'!$T:$T) -> 0.45277778 | F17: =LOOKUP(2,1/(('0829 4度C'!$A:$A="新豐5線")*('0829 4度C'!$T:$T<>"")),'0829 4度C'!$T:$T) -> 0.83402778 | G17: =LOOKUP(2,1/(('0829 4度C'!$A:$A="新豐7線")*('0829 4度C'!$T:$T<>"")),'0829 4度C'!$T:$T) -> 0.84722222 | H17: =LOOKUP(2,1/(('0829 4度C'!$A:$A="新豐3線")*('0829 4度C'!$T:$T<>"")),'0829 4度C'!$T:$T) -> 0.40208333 | I17: =LOOKUP(2,1/(('0829 4度C'!$A:$A="新豐1線")*('0829 4度C'!$T:$T<>"")),'0829 4度C'!$T:$T) -> 0.84305556 | J17: =LOOKUP(2,1/(('0829 4度C'!$A:$A="新豐10線")*('0829 4度C'!$T:$T<>"")),'0829 4度C'!$T:$T) -> 0.40972222 | K17: =LOOKUP(2,1/(('0829 4度C'!$A:$A="新豐8線")*('0829 4度C'!$T:$T<>"")),'0829 4度C'!$T:$T) -> 0.65208333 | L17: =LOOKUP(2,1/(('0829 4度C'!$A:$A="新豐9線")*('0829 4度C'!$T:$T<>"")),'0829 4度C'!$T:$T) -> 0.48194444 | M17: =LOOKUP(2,1/(('0829 4度C'!$A:$A="新豐4線")*('0829 4度C'!$T:$T<>"")),'0829 4度C'!$T:$T) -> 0.48611111
