Workbook

Sheet 0228
B1: 屏榮 新豐廠組合室生產人時性分析
B3: 日期 | C3: =TEXT('0228 4度C'!A2,"yyyy.mm.ddaaaa") -> 2026.02.28星期六 | E3: 訂單量 | F3: ='0228 4度C'!D1 -> 131327 | H3: 營業額 | I3: ='0228 4度C'!F1 -> 4537803.8
B4: 人時性 | C4: 項目 | E4: ➀ | G4: ➁ | I4: ➂ | K4: 異常停線 | M4: 短暫停線
C5: 組合室 | E5: 全溫層 | G5: 4度C-各編組展開 | I5: ③三明治-各編組展開 | K5: 合計次數 | L5: 時間 | M5: 合計次數 | N5: 設備次數
C6: 排關平均 | E6: =AVERAGE(D13:M13) -> 145.6253 | F6: =AVERAGE(D31:O31,D13:J13) -> 149.26804 | G6: =AVERAGE(D13:J13) -> 149.26804 | I6: =AVERAGE(K13:M13) -> 137.12558 | K6: ='0228 4度C'!Y2 -> 0 | L6: ='0228 4度C'!Z2 -> 0 | M6: ='0228 4度C'!AC2 -> 51 | N6: ='0228 4度C'!AD2 -> 0
C7: 實績平均 | E7: =AVERAGE(D14:M14) -> 139.53963 | F7: =AVERAGE(D32:O32,D14:J14) -> 142.92827 | G7: =AVERAGE(D14:J14) -> 142.92827 | I7: =AVERAGE(K14:M14) -> 131.6328
C8: 達成率平均 | E8: =AVERAGE(D15:M15) -> 0.95779486 | F8: =AVERAGE(D15:J15,D33:O33) -> 0.95695138 | G8: =AVERAGE(D15:J15) -> 0.95695138 | I8: =AVERAGE(K15:M15) -> 0.95976298
K9: ※現行日本鮮食廠以達成率80%為基本(即為現行KPI)
B10: 溫層 | D10: ➁4度C-各編組展開 | K10: ③三明治-各編組展開
B11: 編組 | D11: 1 | E11: 2 | F11: 3 | G11: 4 | H11: 5 | I11: 6 | J11: 7 | K11: 1 | L11: 2 | M11: 3
D12: 新豐6線 | E12: 新豐2線 | F12: 新豐5線 | G12: 新豐7線 | H12: 新豐3線 | I12: 新豐1線 | J12: 新豐10線 | K12: 新豐8線 | L12: 新豐9線 | M12: 新豐4線
B13: 人時性 | C13: 排關 | D13: =SUMIFS('0228 4度C'!$K:$K,'0228 4度C'!$A:$A,"新豐6線",'0228 4度C'!$B:$B,"平均") -> 112.35955 | E13: =SUMIFS('0228 4度C'!$K:$K,'0228 4度C'!$A:$A,"新豐2線",'0228 4度C'!$B:$B,"平均") -> 83.333333 | F13: =SUMIFS('0228 4度C'!$K:$K,'0228 4度C'!$A:$A,"新豐5線",'0228 4度C'!$B:$B,"平均") -> 104.16667 | G13: =SUMIFS('0228 4度C'!$K:$K,'0228 4度C'!$A:$A,"新豐7線",'0228 4度C'!$B:$B,"平均") -> 128.37838 | H13: =SUMIFS('0228 4度C'!$K:$K,'0228 4度C'!$A:$A,"新豐3線",'0228 4度C'!$B:$B,"平均") -> 306.12245 | I13: =SUMIFS('0228 4度C'!$K:$K,'0228 4度C'!$A:$A,"新豐1線",'0228 4度C'!$B:$B,"平均") -> 104.16667 | J13: =SUMIFS('0228 4度C'!$K:$K,'0228 4度C'!$A:$A,"新豐10線",'0228 4度C'!$B:$B,"平均") -> 206.34921 | K13: =SUMIFS('0228 4度C'!$K:$K,'0228 4度C'!$A:$A,"新豐8線",'0228 4度C'!$B:$B,"平均") -> 130.43478 | L13: =SUMIFS('0228 4度C'!$K:$K,'0228 4度C'!$A:$A,"新豐9線",'0228 4度C'!$B:$B,"平均") -> 136.36364 | M13: =SUMIFS('0228 4度C'!$K:$K,'0228 4度C'!$A:$A,"新豐4線",'0228 4度C'!$B:$B,"平均") -> 144.57831
C14: 實績 | D14: =SUMIFS('0228 4度C'!$N:$N,'0228 4度C'!$A:$A,"新豐6線",'0228 4度C'!$B:$B,"平均") -> 108.1727 | E14: =SUMIFS('0228 4度C'!$N:$N,'0228 4度C'!$A:$A,"新豐2線",'0228 4度C'!$B:$B,"平均") -> 79.871809 | F14: =SUMIFS('0228 4度C'!$N:$N,'0228 4度C'!$A:$A,"新豐5線",'0228 4度C'!$B:$B,"平均") -> 99.811155 | G14: =SUMIFS('0228 4度C'!$N:$N,'0228 4度C'!$A:$A,"新豐7線",'0228 4度C'!$B:$B,"平均") -> 123.45107 | H14: =SUMIFS('0228 4度C'!$N:$N,'0228 4度C'!$A:$A,"新豐3線",'0228 4度C'!$B:$B,"平均") -> 292.56729 | I14: =SUMIFS('0228 4度C'!$N:$N,'0228 4度C'!$A:$A,"新豐1線",'0228 4度C'!$B:$B,"平均") -> 97.699855 | J14: =SUMIFS('0228 4度C'!$N:$N,'0228 4度C'!$A:$A,"新豐10線",'0228 4度C'!$B:$B,"平均") -> 198.92404 | K14: =SUMIFS('0228 4度C'!$N:$N,'0228 4度C'!$A:$A,"新豐8線",'0228 4度C'!$B:$B,"平均") -> 124.64154 | L14: =SUMIFS('0228 4度C'!$N:$N,'0228 4度C'!$A:$A,"新豐9線",'0228 4度C'!$B:$B,"平均") -> 130.62523 | M14: =SUMIFS('0228 4度C'!$N:$N,'0228 4度C'!$A:$A,"新豐4線",'0228 4度C'!$B:$B,"平均") -> 139.63163
C15: 達成率 | D15: =D14/D13 -> 0.96273706 | E15: =E14/E13 -> 0.95846171 | F15: =F14/F13 -> 0.95818709 | G15: =G14/G13 -> 0.96161887 | H15: =H14/H13 -> 0.95571981 | I15: =I14/I13 -> 0.93791861 | J15: =J14/J13 -> 0.96401648 | K15: =K14/K13 -> 0.95558515 | ... M15: =M14/M13 -> 0.96578545
B16: 作業 時間 | C16: 開始 | D16: =VLOOKUP("新豐6線",'0228 4度C'!$A:$T,19,0) -> 0.70833333 | E16: =VLOOKUP("新豐2線",'0228 4度C'!$A:$T,19,0) -> 0.20833333 | F16: =VLOOKUP("新豐5線",'0228 4度C'!$A:$T,19,0) -> 0.20833333 | G16: =VLOOKUP("新豐7線",'0228 4度C'!$A:$T,19,0) -> 0.20833333 | H16: =VLOOKUP("新豐3線",'0228 4度C'!$A:$T,19,0) -> 0.20833333 | I16: =VLOOKUP("新豐1線",'0228 4度C'!$A:$T,19,0) -> 0.20833333 | J16: =VLOOKUP("新豐10線",'0228 4度C'!$A:$T,19,0) -> 0.20833333 | K16: =VLOOKUP("新豐8線",'0228 4度C'!$A:$T,19,0) -> 0.125 | L16: =VLOOKUP("新豐9線",'0228 4度C'!$A:$T,19,0) -> 0.125 | M16: =VLOOKUP("新豐4線",'0228 4度C'!$A:$T,19,0) -> 0.125
C17: 結束 | D17: =LOOKUP(2,1/(('0228 4度C'!$A:$A="新豐6線")*('0228 4度C'!$T:$T<>"")),'0228 4度C'!$T:$T) -> 0.83194444 | E17: =LOOKUP(2,1/(('0228 4度C'!$A:$A="新豐2線")*('0228 4度C'!$T:$T<>"")),'0228 4度C'!$T:$T) -> 0.44583333 | F17: =LOOKUP(2,1/(('0228 4度C'!$A:$A="新豐5線")*('0228 4度C'!$T:$T<>"")),'0228 4度C'!$T:$T) -> 0.85902778 | G17: =LOOKUP(2,1/(('0228 4度C'!$A:$A="新豐7線")*('0228 4度C'!$T:$T<>"")),'0228 4度C'!$T:$T) -> 0.85763889 | H17: =LOOKUP(2,1/(('0228 4度C'!$A:$A="新豐3線")*('0228 4度C'!$T:$T<>"")),'0228 4度C'!$T:$T) -> 0.51041667 | I17: =LOOKUP(2,1/(('0228 4度C'!$A:$A="新豐1線")*('0228 4度C'!$T:$T<>"")),'0228 4度C'!$T:$T) -> 0.90347222 | J17: =LOOKUP(2,1/(('0228 4度C'!$A:$A="新豐10線")*('0228 4度C'!$T:$T<>"")),'0228 4度C'!$T:$T) -> 0.48888889 | K17: =LOOKUP(2,1/(('0228 4度C'!$A:$A="新豐8線")*('0228 4度C'!$T:$T<>"")),'0228 4度C'!$T:$T) -> 0.5 | L17: =LOOKUP(2,1/(('0228 4度C'!$A:$A="新豐9線")*('0228 4度C'!$T:$T<>"")),'0228 4度C'!$T:$T) -> 0.49027778 | M17: =LOOKUP(2,1/(('0228 4度C'!$A:$A="新豐4線")*('0228 4度C'!$T:$T<>"")),'0228 4度C'!$T:$T) -> 0.47847222
B18: 產線異常 (5分鐘以上) | C18: 次數 | D18: =SUMIFS('0228 4度C'!$Y:$Y,'0228 4度C'!$A:$A,"新豐6線",'0228 4度C'!$B:$B,"平均") -> 0 | E18: =SUMIFS('0228 4度C'!$Y:$Y,'0228 4度C'!$A:$A,"新豐2線",'0228 4度C'!$B:$B,"平均") -> 0 | F18: =SUMIFS('0228 4度C'!$Y:$Y,'0228 4度C'!$A:$A,"新豐5線",'0228 4度C'!$B:$B,"平均") -> 0 | G18: =SUMIFS('0228 4度C'!$Y:$Y,'0228 4度C'!$A:$A,"新豐7線",'0228 4度C'!$B:$B,"平均") -> 0 | H18: =SUMIFS('0228 4度C'!$Y:$Y,'0228 4度C'!$A:$A,"新豐3線",'0228 4度C'!$B:$B,"平均") -> 0 | I18: =SUMIFS('0228 4度C'!$Y:$Y,'0228 4度C'!$A:$A,"新豐1線",'0228 4度C'!$B:$B,"平均") -> 0 | J18: =SUMIFS('0228 4度C'!$Y:$Y,'0228 4度C'!$A:$A,"新豐10線",'0228 4度C'!$B:$B,"平均") -> 0 | K18: =SUMIFS('0228 4度C'!$Y:$Y,'0228 4度C'!$A:$A,"新豐8線",'0228 4度C'!$B:$B,"平均") -> 0 | L18: =SUMIFS('0228 4度C'!$Y:$Y,'0228 4度C'!$A:$A,"新豐9線",'0228 4度C'!$B:$B,"平均") -> 0 | M18: =SUMIFS('0228 4度C'!$Y:$Y,'0228 4度C'!$A:$A,"新豐4線",'0228 4度C'!$B:$B,"平均") -> 0
C19: 時間/分 | D19: =SUMIFS('0228 4度C'!$Z:$Z,'0228 4度C'!$A:$A,"新豐6線",'0228 4度C'!$B:$B,"平均") -> 0 | E19: =SUMIFS('0228 4度C'!$Z:$Z,'0228 4度C'!$A:$A,"新豐2線",'0228 4度C'!$B:$B,"平均") -> 0 | F19: =SUMIFS('0228 4度C'!$Z:$Z,'0228 4度C'!$A:$A,"新豐5線",'0228 4度C'!$B:$B,"平均") -> 0 | G19: =SUMIFS('0228 4度C'!$Z:$Z,'0228 4度C'!$A:$A,"新豐7線",'0228 4度C'!$B:$B,"平均") -> 0 | H19: =SUMIFS('0228 4度C'!$Z:$Z,'0228 4度C'!$A:$A,"新豐3線",'0228 4度C'!$B:$B,"平均") -> 0 | I19: =SUMIFS('0228 4度C'!$Z:$Z,'0228 4度C'!$A:$A,"新豐1線",'0228 4度C'!$B:$B,"平均") -> 0 | J19: =SUMIFS('0228 4度C'!$Z:$Z,'0228 4度C'!$A:$A,"新豐10線",'0228 4度C'!$B:$B,"平均") -> 0 | K19: =SUMIFS('0228 4度C'!$Z:$Z,'0228 4度C'!$A:$A,"新豐8線",'0228 4度C'!$B:$B,"平均") -> 0 | L19: =SUMIFS('0228 4度C'!$Z:$Z,'0228 4度C'!$A:$A,"新豐9線",'0228 4度C'!$B:$B,"平均") -> 0 | M19: =SUMIFS('0228 4度C'!$Z:$Z,'0228 4度C'!$A:$A,"新豐4線",'0228 4度C'!$B:$B,"平均") -> 0
B20: 短暫停線 (5分鐘以下) | C20: 次數 | D20: =SUMIFS('0228 4度C'!$AC:$AC,'0228 4度C'!$A:$A,"新豐6線",'0228 4度C'!$B:$B,"平均") -> 5 | E20: =SUMIFS('0228 4度C'!$AC:$AC,'0228 4度C'!$A:$A,"新豐2線",'0228 4度C'!$B:$B,"平均") -> 2 | F20: =SUMIFS('0228 4度C'!$AC:$AC,'0228 4度C'!$A:$A,"新豐5線",'0228 4度C'!$B:$B,"平均") -> 4 | G20: =SUMIFS('0228 4度C'!$AC:$AC,'0228 4度C'!$A:$A,"新豐7線",'0228 4度C'!$B:$B,"平均") -> 5 | H20: =SUMIFS('0228 4度C'!$AC:$AC,'0228 4度C'!$A:$A,"新豐3線",'0228 4度C'!$B:$B,"平均") -> 5 | I20: =SUMIFS('0228 4度C'!$AC:$AC,'0228 4度C'!$A:$A,"新豐1線",'0228 4度C'!$B:$B,"平均") -> 9 | J20: =SUMIFS('0228 4度C'!$AC:$AC,'0228 4度C'!$A:$A,"新豐10線",'0228 4度C'!$B:$B,"平均") -> 6 | K20: =SUMIFS('0228 4度C'!$AC:$AC,'0228 4度C'!$A:$A,"新豐8線",'0228 4度C'!$B:$B,"平均") -> 5 | L20: =SUMIFS('0228 4度C'!$AC:$AC,'0228 4度C'!$A:$A,"新豐9線",'0228 4度C'!$B:$B,"平均") -> 5 | M20: =SUMIFS('0228 4度C'!$AC:$AC,'0228 4度C'!$A:$A,"新豐4線",'0228 4度C'!$B:$B,"平均") -> 5
C21: 設備次數 | D21: =SUMIFS('0228 4度C'!$AD:$AD,'0228 4度C'!$A:$A,"新豐6線",'0228 4度C'!$B:$B,"平均") -> 0 | E21: =SUMIFS('0228 4度C'!$AD:$AD,'0228 4度C'!$A:$A,"新豐2線",'0228 4度C'!$B:$B,"平均") -> 0 | F21: =SUMIFS('0228 4度C'!$AD:$AD,'0228 4度C'!$A:$A,"新豐5線",'0228 4度C'!$B:$B,"平均") -> 0 | G21: =SUMIFS('0228 4度C'!$AD:$AD,'0228 4度C'!$A:$A,"新豐7線",'0228 4度C'!$B:$B,"平均") -> 0 | H21: =SUMIFS('0228 4度C'!$AD:$AD,'0228 4度C'!$A:$A,"新豐3線",'0228 4度C'!$B:$B,"平均") -> 0 | I21: =SUMIFS('0228 4度C'!$AD:$AD,'0228 4度C'!$A:$A,"新豐1線",'0228 4度C'!$B:$B,"平均") -> 0 | J21: =SUMIFS('0228 4度C'!$AD:$AD,'0228 4度C'!$A:$A,"新豐10線",'0228 4度C'!$B:$B,"平均") -> 0 | K21: =SUMIFS('0228 4度C'!$AD:$AD,'0228 4度C'!$A:$A,"新豐8線",'0228 4度C'!$B:$B,"平均") -> 0 | L21: =SUMIFS('0228 4度C'!$AD:$AD,'0228 4度C'!$A:$A,"新豐9線",'0228 4度C'!$B:$B,"平均") -> 0 | M21: =SUMIFS('0228 4度C'!$AD:$AD,'0228 4度C'!$A:$A,"新豐4線",'0228 4度C'!$B:$B,"平均") -> 0
B22: 配置人數 | D22: =SUMIFS('0228 4度C'!$I:$I,'0228 4度C'!$A:$A,"新豐6線",'0228 4度C'!$B:$B,"平均") -> 17.8 | E22: =SUMIFS('0228 4度C'!$I:$I,'0228 4度C'!$A:$A,"新豐2線",'0228 4度C'!$B:$B,"平均") -> 18 | F22: =SUMIFS('0228 4度C'!$I:$I,'0228 4度C'!$A:$A,"新豐5線",'0228 4度C'!$B:$B,"平均") -> 18 | G22: =SUMIFS('0228 4度C'!$I:$I,'0228 4度C'!$A:$A,"新豐7線",'0228 4度C'!$B:$B,"平均") -> 14.8 | H22: =SUMIFS('0228 4度C'!$I:$I,'0228 4度C'!$A:$A,"新豐3線",'0228 4度C'!$B:$B,"平均") -> 9.8 | I22: =SUMIFS('0228 4度C'!$I:$I,'0228 4度C'!$A:$A,"新豐1線",'0228 4度C'!$B:$B,"平均") -> 18.666667 | J22: =SUMIFS('0228 4度C'!$I:$I,'0228 4度C'!$A:$A,"新豐10線",'0228 4度C'!$B:$B,"平均") -> 10.5 | K22: =SUMIFS('0228 4度C'!$I:$I,'0228 4度C'!$A:$A,"新豐8線",'0228 4度C'!$B:$B,"平均") -> 18.4 | L22: =SUMIFS('0228 4度C'!$I:$I,'0228 4度C'!$A:$A,"新豐9線",'0228 4度C'!$B:$B,"平均") -> 17.6 | M22: =SUMIFS('0228 4度C'!$I:$I,'0228 4度C'!$A:$A,"新豐4線",'0228 4度C'!$B:$B,"平均") -> 16.6
B23: 主要應用設備 | D23: ET-55 | E23: 熱縮爐 | F23: L型包裝機 | G23: L型包裝機 | H23: 伺服包裝機 | I23: ET-55 | J23: 伺服包裝機 | K23: 三明治包裝機 | L23: 三明治包裝機 | M23: 三明治包裝機
B24: 次要應用設備 | F24: 圓盤機 | G24: ET-55
B25: 備註 | E25: 握沙拉 | F25: 共用L型包裝機 | H25: 調理麵包 | I25: 炒飯+沙拉 | J25: 調理麵包

Sheet 0228 4度C
A1: 新豐廠四度C日報分析 | C1: 總生產量 | D1: =SUM(F5:F65) -> 131327 | E1: 營業額 | F1: =SUM(G5:G65) -> 4537803.8 | G1: 出勤人數 | H1: =L10+L13+L42+L52+L18+L59+L30+L36+L24+L65 -> 160.16667 | I1: 產線配置圖 | L1: 生產實績 | O1: 人時性差異分析 | S1: 日報登錄 | Y1: 合計 次數 | Z1: 合計 時間/分 | AA1: 產線異常 分析說明(5分鐘以上) | AC1: 合計 次數 | AD1: 合計 設備次數 | AE1: 產能差異分析
A2: 46081 | B2: 星期六 | C2: 人時性 | D2: =AVERAGE(N10,N13,N42,N52,N18,N59,N24,N30,N36,N65) -> 139.53963 | E2: 平均廠價 | F2: =F1/D1 -> 34.553472 | G2: 多次生產數 | H2: =COUNT(H5:H65) -> 1 | Y2: =SUM(Y10+Y13+Y18+Y24+Y30+Y36+Y42+Y52+Y59+Y65) -> 0 | Z2: =SUM(Z10+Z13+Z18+Z24+Z30+Z36+Z42+Z52+Z59+Z65) -> 0 | AC2: 51 | AD2: =SUM(AD10+AD13+AD18+AD24+AD30+AD36+AD42+AD52+AD59+AD65) -> 0
A3: 線別 | B3: 品類 | C3: 品名 | E3: 廠價 | F3: 生產量 | G3: 營收 | H3: 多次 生產 | I3: 人數 | J3: 產能/時 | K3: 人時性 | L3: 人數 | M3: 產能/時 | N3: 人時性 | O3: 人數 | P3: 人時性 | Q3: 達成率 | R3: 達成率平均 | S3: 生產時間 | U3: 換線、休息/分 | V3: 稼動時間/分 | W3: 休息時間 | Y3: 產線異常統計 (5分鐘以上) | AA3: (新豐回填) | AC3: 短暫停線統計 (5分鐘以下) | AE3: 產能/時 | AF3: 達成率 | AG3: 達成率平均
S4: 開始 | T4: 結束 | W4: 開始 | X4: 結束 | Y4: 次數 | Z4: 時間/分 | AC4: 總次數 | AD4: 設備因素(次數)
A5: 新豐6線 | B5: 微波主食 | C5: 二配港式香滑嫩蛋牛肉燴飯 | E5: 50.67 | F5: 1567 | G5: =E5*F5 -> 79399.89 | I5: 17 | J5: 2000 | K5: =J5/I5 -> 117.64706 | L5: 17 | M5: =F5/V5*60 -> 1918.7755 | N5: =M5/L5 -> 112.86915 | O5: =L5-I5 -> 0 | P5: =N5-K5 -> -4.7779112 | Q5: =N5/K5 -> 0.95938776 | R5: =Q10 -> 0.96273706 | S5: 0.70833333 | T5: 0.74236111 | V5: =(T5-S5)*24*60 -> 49 | AC5: 5 | AE5: =M5-J5 -> -81.22449 | AF5: =M5/J5 -> 0.95938776 | AG5: =AF10 -> 0.96273706
A6: 新豐6線 | B6: 微波主食 | C6: 二配美味蟹煲 | E6: 54.09 | F6: 1355 | G6: =E6*F6 -> 73291.95 | I6: 19 | J6: 2000 | K6: =J6/I6 -> 105.26316 | L6: 19 | M6: =F6/V6*60 -> 1935.7143 | N6: =M6/L6 -> 101.8797 | O6: =L6-I6 -> 0 | P6: =N6-K6 -> -3.3834586 | Q6: =N6/K6 -> 0.96785714 | S6: 0.74583333 | T6: 0.775 | U6: =IF(S6=TIME(17,0,0),"",(S6-T5)*24*60) -> 5 | V6: =(T6-S6)*24*60 -> 42 | AE6: =M6-J6 -> -64.285714 | AF6: =M6/J6 -> 0.96785714
A7: 新豐6線 | B7: 微波主食 | C7: 二配麻油雞燴飯 | E7: 50.29 | F7: 574 | G7: =E7*F7 -> 28866.46 | I7: 16 | J7: 2000 | K7: =J7/I7 -> 125 | L7: 16 | M7: =F7/V7*60 -> 1913.3333 | N7: =M7/L7 -> 119.58333 | O7: =L7-I7 -> 0 | P7: =N7-K7 -> -5.4166667 | Q7: =N7/K7 -> 0.95666667 | S7: 0.77986111 | T7: 0.79236111 | U7: =IF(S7=TIME(17,0,0),"",(S7-T6)*24*60) -> 7 | V7: =(T7-S7)*24*60 -> 18 | AE7: =M7-J7 -> -86.666667 | AF7: =M7/J7 -> 0.95666667
A8: 新豐6線 | B8: 微波主食 | C8: 二配濃蕃茄火腿蛋包飯 | E8: 50.67 | F8: 543 | G8: =E8*F8 -> 27513.81 | I8: 21 | J8: 2000 | K8: =J8/I8 -> 95.238095 | L8: 21 | M8: =F8/V8*60 -> 1916.4706 | N8: =M8/L8 -> 91.260504 | O8: =L8-I8 -> 0 | P8: =N8-K8 -> -3.977591 | Q8: =N8/K8 -> 0.95823529 | S8: 0.79791667 | T8: 0.80972222 | U8: =IF(S8=TIME(17,0,0),"",(S8-T7)*24*60) -> 8 | V8: =(T8-S8)*24*60 -> 17 | AE8: =M8-J8 -> -83.529412 | AF8: =M8/J8 -> 0.95823529
A9: 新豐6線 | B9: 微波主食 | C9: 二配香炒沙茶豬肉飯 | E9: 50.67 | F9: 842 | G9: =E9*F9 -> 42664.14 | I9: 16 | J9: 2000 | K9: =J9/I9 -> 125 | L9: 16 | M9: =F9/V9*60 -> 1943.0769 | N9: =M9/L9 -> 121.44231 | O9: =L9-I9 -> 0 | P9: =N9-K9 -> -3.5576923 | Q9: =N9/K9 -> 0.97153846 | S9: 0.81388889 | T9: 0.83194444 | U9: =IF(S9=TIME(17,0,0),"",(S9-T8)*24*60) -> 6 | V9: =(T9-S9)*24*60 -> 26 | AE9: =M9-J9 -> -56.923077 | AF9: =M9/J9 -> 0.97153846
A10: 新豐6線 | B10: 平均 | I10: 17.8 | J10: 2000 | K10: =J10/I10 -> 112.35955 | L10: 17.8 | M10: =AVERAGE(M5:M9) -> 1925.4741 | N10: =M10/L10 -> 108.1727 | O10: =L10-I10 -> 0 | P10: =N10-K10 -> -4.1868467 | Q10: =N10/K10 -> 0.96273706 | Y10: =SUM(Y5:Y9) -> 0 | Z10: =SUM(Z5:Z9) -> 0 | AC10: 5 | AD10: =SUM(AD5:AD9) -> 0 | AE10: =M10-J10 -> -74.525872 | AF10: =M10/J10 -> 0.96273706
A11: 新豐2線 | B11: 沙拉 | C11: 青醬優格雞肉握沙拉(113年) | E11: 39.62 | F11: 3165 | G11: =E11*F11 -> 125397.3 | I11: 19 | J11: 1500 | K11: =J11/I11 -> 78.947368 | L11: 19 | M11: =F11/V11*60 -> 1438.6364 | N11: =M11/L11 -> 75.717703 | O11: =L11-I11 -> 0 | P11: =N11-K11 -> -3.2296651 | Q11: =N11/K11 -> 0.95909091 | R11: =Q13 -> 0.95846171 | S11: 0.20833333 | T11: 0.3 | V11: =(T11-S11)*24*60 -> 132 | AC11: 2 | AE11: =M11-J11 -> -61.363636 | AF11: =M11/J11 -> 0.95909091 | AG11: =AF13 -> 0.95846171
A12: 新豐2線 | B12: 沙拉 | C12: 青檸烤雞握沙拉(113年) | E12: 39.8 | F12: 4861 | G12: =E12*F12 -> 193467.8 | I12: 17 | J12: 1500 | K12: =J12/I12 -> 88.235294 | L12: 17 | M12: =F12/V12*60 -> 1436.7488 | N12: =M12/L12 -> 84.514633 | O12: =L12-I12 -> 0 | P12: =N12-K12 -> -3.7206607 | Q12: =N12/K12 -> 0.95783251 | S12: 0.30486111 | T12: 0.44583333 | U12: =IF(S12=TIME(17,0,0),"",(S12-T11)*24*60) -> 7 | V12: =(T12-S12)*24*60 -> 203 | AE12: =M12-J12 -> -63.251232 | AF12: =M12/J12 -> 0.95783251
A13: 新豐2線 | B13: 平均 | I13: 18 | J13: 1500 | K13: =J13/I13 -> 83.333333 | L13: 18 | M13: =AVERAGE(M11:M12) -> 1437.6926 | N13: =M13/L13 -> 79.871809 | O13: =L13-I13 -> 0 | P13: =N13-K13 -> -3.4615241 | Q13: =N13/K13 -> 0.95846171 | Y13: =SUM(Y11:Y12) -> 0 | Z13: =SUM(Z11:Z12) -> 0 | AC13: 2 | AD13: =SUM(AD11:AD12) -> 0 | AE13: =M13-J13 -> -62.307434 | AF13: =M13/J13 -> 0.95846171
A14: 新豐5線 | B14: 小吃 | C14: 剝皮辣椒雞湯 | E14: 41 | F14: 2529 | G14: =E14*F14 -> 103689 | I14: 26 | J14: 1500 | K14: =J14/I14 -> 57.692308 | L14: 26 | M14: =F14/V14*60 -> 1431.5094 | N14: =M14/L14 -> 55.058055 | O14: =L14-I14 -> 0 | P14: =N14-K14 -> -2.6342525 | Q14: =N14/K14 -> 0.95433962 | R14: =Q18 -> 0.95818709 | S14: 0.20833333 | T14: 0.28194444 | V14: =(T14-S14)*24*60 -> 106 | AC14: 4 | AE14: =M14-J14 -> -68.490566 | AF14: =M14/J14 -> 0.95433962 | AG14: =AF18 -> 0.95818709
A15: 新豐5線 | B15: 微波主食 | C15: 二配金咖哩濃厚辛口咖哩飯 | E15: 50.98 | F15: 2473 | G15: =E15*F15 -> 126073.54 | I15: 16 | J15: 2000 | K15: =J15/I15 -> 125 | L15: 16 | M15: =F15/V15*60 -> 1927.013 | N15: =M15/L15 -> 120.43831 | O15: =L15-I15 -> 0 | P15: =N15-K15 -> -4.5616883 | Q15: =N15/K15 -> 0.96350649 | S15: 0.70833333 | T15: 0.76180556 | U15: =IF(S15=TIME(17,0,0),"",(S15-T14)*24*60) | V15: =(T15-S15)*24*60 -> 77 | AE15: =M15-J15 -> -72.987013 | AF15: =M15/J15 -> 0.96350649
A16: 新豐5線 | B16: 微波主食 | C16: 二配金咖哩果香甘口咖哩飯 | E16: 50.92 | F16: 2337 | G16: =E16*F16 -> 119000.04 | I16: 15 | J16: 2000 | K16: =J16/I16 -> 133.33333 | L16: 15 | M16: =F16/V16*60 -> 1920.8219 | N16: =M16/L16 -> 128.05479 | O16: =L16-I16 -> 0 | P16: =N16-K16 -> -5.2785388 | Q16: =N16/K16 -> 0.96041096 | S16: 0.76736111 | T16: 0.81805556 | U16: =IF(S16=TIME(17,0,0),"",(S16-T15)*24*60) -> 8 | V16: =(T16-S16)*24*60 -> 73 | AE16: =M16-J16 -> -79.178082 | AF16: =M16/J16 -> 0.96041096
A17: 新豐5線 | B17: 微波主食 | C17: 二配泰式綠咖哩雞 | E17: 50.67 | F17: 1621 | G17: =E17*F17 -> 82136.07 | I17: 15 | J17: 2000 | K17: =J17/I17 -> 133.33333 | L17: 15 | M17: =F17/V17*60 -> 1907.0588 | N17: =M17/L17 -> 127.13725 | O17: =L17-I17 -> 0 | P17: =N17-K17 -> -6.1960784 | Q17: =N17/K17 -> 0.95352941 | S17: 0.82361111 | T17: 0.85902778 | U17: =IF(S17=TIME(17,0,0),"",(S17-T16)*24*60) -> 8 | V17: =(T17-S17)*24*60 -> 51 | AE17: =M17-J17 -> -92.941176 | AF17: =M17/J17 -> 0.95352941
A18: 新豐5線 | B18: 平均 | I18: 18 | J18: 1875 | K18: =J18/I18 -> 104.16667 | L18: 18 | M18: =AVERAGE(M14:M17) -> 1796.6008 | N18: =M18/L18 -> 99.811155 | O18: =L18-I18 -> 0 | P18: =N18-K18 -> -4.3555116 | Q18: =N18/K18 -> 0.95818709 | Y18: =SUM(Y14:Y17) -> 0 | Z18: =SUM(Z14:Z17) -> 0 | AC18: 4 | AD18: =SUM(AD14:AD17) -> 0 | AE18: =M18-J18 -> -78.399209 | AF18: =M18/J18 -> 0.95818709
A19: 新豐7線 | B19: 微波主食 | C19: 鐵板滑蛋炸豬排丼 | E19: 57.73 | F19: 2565 | G19: =E19*F19 -> 148077.45 | I19: 14 | J19: 2000 | K19: =J19/I19 -> 142.85714 | L19: 14 | M19: =F19/V19*60 -> 1923.75 | N19: =M19/L19 -> 137.41071 | O19: =L19-I19 -> 0 | P19: =N19-K19 -> -5.4464286 | Q19: =N19/K19 -> 0.961875 | R19: =Q24 -> 0.96161887 | S19: 0.20833333 | T19: 0.26388889 | V19: =(T19-S19)*24*60 -> 80 | AC19: 5 | AE19: =M19-J19 -> -76.25 | AF19: =M19/J19 -> 0.961875 | AG19: =AF24 -> 0.96161887
A20: 新豐7線 | B20: 微波主食 | C20: 極上炙烤親子丼 | E20: 53.68 | F20: 1444 | G20: =E20*F20 -> 77513.92 | I20: 16 | J20: 2000 | K20: =J20/I20 -> 125 | L20: 16 | M20: =F20/V20*60 -> 1925.3333 | N20: =M20/L20 -> 120.33333 | O20: =L20-I20 -> 0 | P20: =N20-K20 -> -4.6666667 | Q20: =N20/K20 -> 0.96266667 | S20: 0.26805556 | T20: 0.29930556 | U20: =IF(S20=TIME(17,0,0),"",(S20-T19)*24*60) -> 6 | V20: =(T20-S20)*24*60 -> 45 | AE20: =M20-J20 -> -74.666667 | AF20: =M20/J20 -> 0.96266667
A21: 新豐7線 | B21: 微波主食 | C21: 二配川味麻婆燒豆腐燴飯 | E21: 50.49 | F21: 2092 | G21: =E21*F21 -> 105625.08 | I21: 15 | J21: 2000 | K21: =J21/I21 -> 133.33333 | L21: 15 | M21: =F21/V21*60 -> 1931.0769 | N21: =M21/L21 -> 128.73846 | O21: =L21-I21 -> 0 | P21: =N21-K21 -> -4.5948718 | Q21: =N21/K21 -> 0.96553846 | S21: 0.70833333 | T21: 0.75347222 | U21: =IF(S21=TIME(17,0,0),"",(S21-T20)*24*60) | V21: =(T21-S21)*24*60 -> 65 | AE21: =M21-J21 -> -68.923077 | AF21: =M21/J21 -> 0.96553846
A22: 新豐7線 | B22: 微波主食 | C22: 二配厚香料咖哩雞排飯 | E22: 57.3 | F22: 1881 | G22: =E22*F22 -> 107781.3 | I22: 13 | J22: 2000 | K22: =J22/I22 -> 153.84615 | L22: 13 | M22: =F22/V22*60 -> 1912.8814 | N22: =M22/L22 -> 147.14472 | O22: =L22-I22 -> 0 | P22: =N22-K22 -> -6.7014342 | Q22: =N22/K22 -> 0.95644068 | S22: 0.75902778 | T22: 0.8 | U22: =IF(S22=TIME(17,0,0),"",(S22-T21)*24*60) -> 8 | V22: =(T22-S22)*24*60 -> 59 | AE22: =M22-J22 -> -87.118644 | AF22: =M22/J22 -> 0.95644068
A23: 新豐7線 | B23: 微波主食 | C23: 二配起司控培根白醬焗烤飯 | E23: 53.68 | F23: 1851 | G23: =E23*F23 -> 99361.68 | I23: 16 | J23: 1500 | K23: =J23/I23 -> 93.75 | L23: 16 | M23: =F23/V23*60 -> 1442.3377 | N23: =M23/L23 -> 90.146104 | O23: =L23-I23 -> 0 | P23: =N23-K23 -> -3.6038961 | Q23: =N23/K23 -> 0.96155844 | S23: 0.80416667 | T23: 0.85763889 | U23: =IF(S23=TIME(17,0,0),"",(S23-T22)*24*60) -> 6 | V23: =(T23-S23)*24*60 -> 77 | AE23: =M23-J23 -> -57.662338 | AF23: =M23/J23 -> 0.96155844
A24: 新豐7線 | B24: 平均 | I24: 14.8 | J24: 1900 | K24: =J24/I24 -> 128.37838 | L24: 14.8 | M24: =AVERAGE(M19:M23) -> 1827.0759 | N24: =M24/L24 -> 123.45107 | O24: =L24-I24 -> 0 | P24: =N24-K24 -> -4.9273071 | Q24: =N24/K24 -> 0.96161887 | Y24: =SUM(Y19:Y23) -> 0 | Z24: =SUM(Z19:Z23) -> 0 | AC24: 5 | AD24: =SUM(AD19:AD23) -> 0 | AE24: =M24-J24 -> -72.924145 | AF24: =M24/J24 -> 0.96161887
A25: 新豐8線 | B25: 三明治 | C25: 紐奧良風味烤雞鮮蔬三明治 | E25: 31.29 | F25: 7462 | G25: =E25*F25 -> 233485.98 | I25: 18 | J25: 2400 | K25: =J25/I25 -> 133.33333 | L25: 18 | M25: =F25/V25*60 -> 2284.2857 | N25: =M25/L25 -> 126.90476 | O25: =L25-I25 -> 0 | P25: =N25-K25 -> -6.4285714 | Q25: =N25/K25 -> 0.95178571 | R25: =Q30 -> 0.95558515 | S25: 0.125 | T25: 0.26111111 | V25: =(T25-S25)*24*60 -> 196 | W25: =T25 -> 0.26111111 | X25: =S26 -> 0.28194444 | AC25: 5 | AE25: =M25-J25 -> -115.71429 | AF25: =M25/J25 -> 0.95178571 | AG25: =AF30 -> 0.95558515
A26: 新豐8線 | B26: 三明治 | C26: 好多菜三明治(114年) | E26: 25.98 | F26: 2267 | G26: =E26*F26 -> 58896.66 | I26: 21 | J26: 2400 | K26: =J26/I26 -> 114.28571 | L26: 21 | M26: =F26/V26*60 -> 2305.4237 | N26: =M26/L26 -> 109.78208 | O26: =L26-I26 -> 0 | P26: =N26-K26 -> -4.503632 | Q26: =N26/K26 -> 0.96059322 | S26: 0.28194444 | T26: 0.32291667 | U26: =(S26-T25)*24*60 -> 30 | V26: =(T26-S26)*24*60 -> 59 | AE26: =M26-J26 -> -94.576271 | AF26: =M26/J26 -> 0.96059322
A27: 新豐8線 | B27: 三明治 | C27: 經典總匯三明治 | E27: 26.2 | F27: 4172 | G27: =E27*F27 -> 109306.4 | I27: 20 | J27: 2400 | K27: =J27/I27 -> 120 | L27: 20 | M27: =F27/V27*60 -> 2296.5138 | N27: =M27/L27 -> 114.82569 | O27: =L27-I27 -> 0 | P27: =N27-K27 -> -5.1743119 | Q27: =N27/K27 -> 0.95688073 | S27: 0.32847222 | T27: 0.40416667 | U27: =(S27-T26)*24*60 -> 8 | V27: =(T27-S27)*24*60 -> 109 | AE27: =M27-J27 -> -103.48624 | AF27: =M27/J27 -> 0.95688073
A28: 新豐8線 | B28: 三明治 | C28: 雞蛋沙拉三明治(114年) | E28: 25.99 | F28: 3327 | G28: =E28*F28 -> 86468.73 | I28: 14 | J28: 2400 | K28: =J28/I28 -> 171.42857 | L28: 14 | M28: =F28/V28*60 -> 2294.4828 | N28: =M28/L28 -> 163.89163 | O28: =L28-I28 -> 0 | P28: =N28-K28 -> -7.5369458 | Q28: =N28/K28 -> 0.95603448 | S28: 0.40763889 | T28: 0.46805556 | U28: =(S28-T27)*24*60 -> 5 | V28: =(T28-S28)*24*60 -> 87 | AE28: =M28-J28 -> -105.51724 | AF28: =M28/J28 -> 0.95603448
A29: 新豐8線 | B29: 三明治 | C29: 陽光地瓜總匯三明治 | E29: 26.18 | F29: 1448 | G29: =E29*F29 -> 37908.64 | I29: 19 | J29: 2400 | K29: =J29/I29 -> 126.31579 | L29: 19 | M29: =F29/V29*60 -> 2286.3158 | N29: =M29/L29 -> 120.33241 | O29: =L29-I29 -> 0 | P29: =N29-K29 -> -5.9833795 | Q29: =N29/K29 -> 0.95263158 | S29: 0.47361111 | T29: 0.5 | U29: =(S29-T28)*24*60 -> 8 | V29: =(T29-S29)*24*60 -> 38 | AE29: =M29-J29 -> -113.68421 | AF29: =M29/J29 -> 0.95263158
A30: 新豐8線 | B30: 平均 | I30: 18.4 | J30: 2400 | K30: =J30/I30 -> 130.43478 | L30: 18.4 | M30: =AVERAGE(M25:M29) -> 2293.4044 | N30: =M30/L30 -> 124.64154 | O30: =L30-I30 -> 0 | P30: =N30-K30 -> -5.7932418 | Q30: =N30/K30 -> 0.95558515 | Y30: =SUM(Y25:Y29) -> 0 | Z30: =SUM(Z25:Z29) -> 0 | AC30: 5 | AD30: =SUM(AD25:AD29) -> 0 | AE30: =M30-J30 -> -106.59565 | AF30: =M30/J30 -> 0.95558515
A31: 新豐9線 | B31: 三明治 | C31: 鮪魚起司溏心蛋三明治 | E31: 26.2 | F31: 5470 | G31: =E31*F31 -> 143314 | I31: 18 | J31: 2400 | K31: =J31/I31 -> 133.33333 | L31: 18 | M31: =F31/V31*60 -> 2295.1049 | N31: =M31/L31 -> 127.50583 | O31: =L31-I31 -> 0 | P31: =N31-K31 -> -5.8275058 | Q31: =N31/K31 -> 0.95629371 | R31: =Q36 -> 0.95791834 | S31: 0.125 | T31: 0.22430556 | V31: =(T31-S31)*24*60 -> 143 | W31: =T31 -> 0.22430556 | X31: =S32 -> 0.24236111 | AC31: 5 | AE31: =M31-J31 -> -104.8951 | AF31: =M31/J31 -> 0.95629371 | AG31: =AF36 -> 0.95791834
A32: 新豐9線 | B32: 三明治 | C32: 肉鬆火腿三明治 | E32: 20.52 | F32: 3068 | G32: =E32*F32 -> 62955.36 | I32: 18 | J32: 2400 | K32: =J32/I32 -> 133.33333 | L32: 18 | M32: =F32/V32*60 -> 2301 | N32: =M32/L32 -> 127.83333 | O32: =L32-I32 -> 0 | P32: =N32-K32 -> -5.5 | Q32: =N32/K32 -> 0.95875 | S32: 0.24236111 | T32: 0.29791667 | U32: =(S32-T31)*24*60 -> 26 | V32: =(T32-S32)*24*60 -> 80 | AE32: =M32-J32 -> -99 | AF32: =M32/J32 -> 0.95875
A33: 新豐9線 | B33: 三明治 | C33: 醬燒烤雞三明治 | E33: 26.39 | F33: 4517 | G33: =E33*F33 -> 119203.63 | I33: 19 | J33: 2400 | K33: =J33/I33 -> 126.31579 | L33: 19 | M33: =F33/V33*60 -> 2296.7797 | N33: =M33/L33 -> 120.88314 | O33: =L33-I33 -> 0 | P33: =N33-K33 -> -5.4326494 | Q33: =N33/K33 -> 0.95699153 | S33: 0.30277778 | T33: 0.38472222 | U33: =(S33-T32)*24*60 -> 7 | V33: =(T33-S33)*24*60 -> 118 | AE33: =M33-J33 -> -103.22034 | AF33: =M33/J33 -> 0.95699153
A34: 新豐9線 | B34: 三明治 | C34: 藍莓優格三明治 | E34: 20.21 | F34: 2639 | G34: =E34*F34 -> 53334.19 | I34: 15 | J34: 2400 | K34: =J34/I34 -> 160 | L34: 15 | M34: =F34/V34*60 -> 2294.7826 | N34: =M34/L34 -> 152.98551 | O34: =L34-I34 -> 0 | P34: =N34-K34 -> -7.0144928 | Q34: =N34/K34 -> 0.95615942 | S34: 0.38958333 | T34: 0.4375 | U34: =(S34-T33)*24*60 -> 7 | V34: =(T34-S34)*24*60 -> 69 | AE34: =M34-J34 -> -105.21739 | AF34: =M34/J34 -> 0.95615942
A35: 新豐9線 | B35: 三明治 | C35: 輕乳酪巧克力三明治 | E35: 20.52 | F35: 2615 | G35: =E35*F35 -> 53659.8 | I35: 18 | J35: 2400 | K35: =J35/I35 -> 133.33333 | L35: 18 | M35: =F35/V35*60 -> 2307.3529 | N35: =M35/L35 -> 128.18627 | O35: =L35-I35 -> 0 | P35: =N35-K35 -> -5.1470588 | Q35: =N35/K35 -> 0.96139706 | S35: 0.44305556 | T35: 0.49027778 | U35: =(S35-T34)*24*60 -> 8 | V35: =(T35-S35)*24*60 -> 68 | AE35: =M35-J35 -> -92.647059 | AF35: =M35/J35 -> 0.96139706
A36: 新豐9線 | B36: 平均 | I36: 17.6 | J36: 2400 | K36: =J36/I36 -> 136.36364 | L36: 17.6 | M36: =AVERAGE(M31:M35) -> 2299.004 | N36: =M36/L36 -> 130.62523 | O36: =L36-I36 -> 0 | P36: =N36-K36 -> -5.7384079 | Q36: =N36/K36 -> 0.95791834 | Y36: =SUM(Y31:Y35) -> 0 | Z36: =SUM(Z31:Z35) -> 0 | AC36: 5 | AD36: =SUM(AD31:AD35) -> 0 | AE36: =M36-J36 -> -100.99598 | AF36: =M36/J36 -> 0.95791834
A37: 新豐3線 | B37: 調理麵包 | C37: 茄汁薯餅蛋堡 | E37: 34.36 | F37: 2281 | G37: =E37*F37 -> 78375.16 | I37: 10 | J37: 3000 | K37: =J37/I37 -> 300 | L37: 10 | M37: =F37/V37*60 -> 2851.25 | N37: =M37/L37 -> 285.125 | O37: =L37-I37 -> 0 | P37: =N37-K37 -> -14.875 | Q37: =N37/K37 -> 0.95041667 | R37: =Q42 -> 0.95571981 | S37: 0.20833333 | T37: 0.24166667 | V37: =(T37-S37)*24*60 -> 48 | AC37: 5 | AE37: =M37-J37 -> -148.75 | AF37: =M37/J37 -> 0.95041667 | AG37: =AF42 -> 0.95571981
A38: 新豐3線 | B38: 調理麵包 | C38: 香雞蛋堡(112年) | E38: 26.78 | F38: 2728 | G38: =E38*F38 -> 73055.84 | I38: 10 | J38: 3000 | K38: =J38/I38 -> 300 | L38: 10 | M38: =F38/V38*60 -> 2871.5789 | N38: =M38/L38 -> 287.15789 | O38: =L38-I38 -> 0 | P38: =N38-K38 -> -12.842105 | Q38: =N38/K38 -> 0.95719298 | S38: 0.24722222 | T38: 0.28680556 | U38: =(S38-T37)*24*60 -> 8 | V38: =(T38-S38)*24*60 -> 57 | AE38: =M38-J38 -> -128.42105 | AF38: =M38/J38 -> 0.95719298
A39: 新豐3線 | B39: 調理麵包 | C39: 豬肉起司堡 | E39: 21.13 | F39: 4677 | G39: =E39*F39 -> 98825.01 | I39: 10 | J39: 3000 | K39: =J39/I39 -> 300 | L39: 10 | M39: =F39/V39*60 -> 2863.4694 | N39: =M39/L39 -> 286.34694 | O39: =L39-I39 -> 0 | P39: =N39-K39 -> -13.653061 | Q39: =N39/K39 -> 0.9544898 | S39: 0.29236111 | T39: 0.36041667 | U39: =(S39-T38)*24*60 -> 8 | V39: =(T39-S39)*24*60 -> 98 | AE39: =M39-J39 -> -136.53061 | AF39: =M39/J39 -> 0.9544898
A40: 新豐3線 | B40: 調理麵包 | C40: 豬肉起司蛋堡 | E40: 27.17 | F40: 6016 | G40: =E40*F40 -> 163454.72 | I40: 10 | J40: 3000 | K40: =J40/I40 -> 300 | L40: 10 | M40: =F40/V40*60 -> 2864.7619 | N40: =M40/L40 -> 286.47619 | O40: =L40-I40 -> 0 | P40: =N40-K40 -> -13.52381 | Q40: =N40/K40 -> 0.95492063 | S40: 0.36458333 | T40: 0.45208333 | U40: =(S40-T39)*24*60 -> 6 | V40: =(T40-S40)*24*60 -> 126 | AE40: =M40-J40 -> -135.2381 | AF40: =M40/J40 -> 0.95492063
...

Sheet 0227
B1: 屏榮 新豐廠組合室生產人時性分析
B3: 日期 | C3: =TEXT('0227 4度C'!A2,"yyyy.mm.ddaaaa") -> 2026.02.27星期五 | E3: 訂單量 | F3: ='0227 4度C'!D1 -> 119463 | H3: 營業額 | I3: ='0227 4度C'!F1 -> 4109978.4
B4: 人時性 | C4: 項目 | E4: ➀ | G4: ➁ | I4: ➂ | K4: 異常停線 | M4: 短暫停線
C5: 組合室 | E5: 全溫層 | G5: 4度C-各編組展開 | I5: ③三明治-各編組展開 | K5: 合計次數 | L5: 時間 | M5: 合計次數 | N5: 設備次數
C6: 排關平均 | E6: =AVERAGE(D13:M13) -> 145.24103 | F6: =AVERAGE(D31:O31,D13:J13) -> 148.71909 | G6: =AVERAGE(D13:J13) -> 148.71909 | I6: =AVERAGE(K13:M13) -> 137.12558 | K6: ='0227 4度C'!Y2 -> 0 | L6: ='0227 4度C'!Z2 -> 0 | M6: ='0227 4度C'!AC2 -> 53 | N6: ='0227 4度C'!AD2 -> 0
C7: 實績平均 | E7: =AVERAGE(D14:M14) -> 139.33386 | F7: =AVERAGE(D32:O32,D14:J14) -> 142.76168 | G7: =AVERAGE(D14:J14) -> 142.76168 | I7: =AVERAGE(K14:M14) -> 131.33563
C8: 達成率平均 | E8: =AVERAGE(D15:M15) -> 0.95881772 | F8: =AVERAGE(D15:J15,D33:O33) -> 0.95924734 | G8: =AVERAGE(D15:J15) -> 0.95924734 | I8: =AVERAGE(K15:M15) -> 0.95781528
K9: ※現行日本鮮食廠以達成率80%為基本(即為現行KPI)
B10: 溫層 | D10: ➁4度C-各編組展開 | K10: ③三明治-各編組展開
B11: 編組 | D11: 1 | E11: 2 | F11: 3 | G11: 4 | H11: 5 | I11: 6 | J11: 7 | K11: 1 | L11: 2 | M11: 3
D12: 新豐6線 | E12: 新豐2線 | F12: 新豐5線 | G12: 新豐7線 | H12: 新豐3線 | I12: 新豐1線 | J12: 新豐10線 | K12: 新豐8線 | L12: 新豐9線 | M12: 新豐4線
B13: 人時性 | C13: 排關 | D13: =SUMIFS('0227 4度C'!$K:$K,'0227 4度C'!$A:$A,"新豐6線",'0227 4度C'!$B:$B,"平均") -> 112.35955 | E13: =SUMIFS('0227 4度C'!$K:$K,'0227 4度C'!$A:$A,"新豐2線",'0227 4度C'!$B:$B,"平均") -> 83.333333 | F13: =SUMIFS('0227 4度C'!$K:$K,'0227 4度C'!$A:$A,"新豐5線",'0227 4度C'!$B:$B,"平均") -> 104.16667 | G13: =SUMIFS('0227 4度C'!$K:$K,'0227 4度C'!$A:$A,"新豐7線",'0227 4度C'!$B:$B,"平均") -> 128.37838 | H13: =SUMIFS('0227 4度C'!$K:$K,'0227 4度C'!$A:$A,"新豐3線",'0227 4度C'!$B:$B,"平均") -> 303.79747 | I13: =SUMIFS('0227 4度C'!$K:$K,'0227 4度C'!$A:$A,"新豐1線",'0227 4度C'!$B:$B,"平均") -> 102.64901 | J13: =SUMIFS('0227 4度C'!$K:$K,'0227 4度C'!$A:$A,"新豐10線",'0227 4度C'!$B:$B,"平均") -> 206.34921 | K13: =SUMIFS('0227 4度C'!$K:$K,'0227 4度C'!$A:$A,"新豐8線",'0227 4度C'!$B:$B,"平均") -> 130.43478 | L13: =SUMIFS('0227 4度C'!$K:$K,'0227 4度C'!$A:$A,"新豐9線",'0227 4度C'!$B:$B,"平均") -> 136.36364 | M13: =SUMIFS('0227 4度C'!$K:$K,'0227 4度C'!$A:$A,"新豐4線",'0227 4度C'!$B:$B,"平均") -> 144.57831
C14: 實績 | D14: =SUMIFS('0227 4度C'!$N:$N,'0227 4度C'!$A:$A,"新豐6線",'0227 4度C'!$B:$B,"平均") -> 108.87631 | E14: =SUMIFS('0227 4度C'!$N:$N,'0227 4度C'!$A:$A,"新豐2線",'0227 4度C'!$B:$B,"平均") -> 79.70297 | F14: =SUMIFS('0227 4度C'!$N:$N,'0227 4度C'!$A:$A,"新豐5線",'0227 4度C'!$B:$B,"平均") -> 99.90107 | G14: =SUMIFS('0227 4度C'!$N:$N,'0227 4度C'!$A:$A,"新豐7線",'0227 4度C'!$B:$B,"平均") -> 123.44317 | H14: =SUMIFS('0227 4度C'!$N:$N,'0227 4度C'!$A:$A,"新豐3線",'0227 4度C'!$B:$B,"平均") -> 292.01495 | I14: =SUMIFS('0227 4度C'!$N:$N,'0227 4度C'!$A:$A,"新豐1線",'0227 4度C'!$B:$B,"平均") -> 97.216721 | J14: =SUMIFS('0227 4度C'!$N:$N,'0227 4度C'!$A:$A,"新豐10線",'0227 4度C'!$B:$B,"平均") -> 198.17655 | K14: =SUMIFS('0227 4度C'!$N:$N,'0227 4度C'!$A:$A,"新豐8線",'0227 4度C'!$B:$B,"平均") -> 125.01974 | L14: =SUMIFS('0227 4度C'!$N:$N,'0227 4度C'!$A:$A,"新豐9線",'0227 4度C'!$B:$B,"平均") -> 130.72001 | M14: =SUMIFS('0227 4度C'!$N:$N,'0227 4度C'!$A:$A,"新豐4線",'0227 4度C'!$B:$B,"平均") -> 138.26715
C15: 達成率 | D15: =D14/D13 -> 0.96899919 | E15: =E14/E13 -> 0.95643564 | F15: =F14/F13 -> 0.95905027 | G15: =G14/G13 -> 0.96155735 | H15: =H14/H13 -> 0.96121587 | I15: =I14/I13 -> 0.94707903 | J15: =J14/J13 -> 0.96039406 | K15: =K14/K13 -> 0.95848466 | ... M15: =M14/M13 -> 0.95634775
B16: 作業 時間 | C16: 開始 | D16: =VLOOKUP("新豐6線",'0227 4度C'!$A:$T,19,0) -> 0.70833333 | E16: =VLOOKUP("新豐2線",'0227 4度C'!$A:$T,19,0) -> 0.20833333 | F16: =VLOOKUP("新豐5線",'0227 4度C'!$A:$T,19,0) -> 0.20833333 | G16: =VLOOKUP("新豐7線",'0227 4度C'!$A:$T,19,0) -> 0.20833333 | H16: =VLOOKUP("新豐3線",'0227 4度C'!$A:$T,19,0) -> 0.20833333 | I16: =VLOOKUP("新豐1線",'0227 4度C'!$A:$T,19,0) -> 0.20833333 | J16: =VLOOKUP("新豐10線",'0227 4度C'!$A:$T,19,0) -> 0.20833333 | K16: =VLOOKUP("新豐8線",'0227 4度C'!$A:$T,19,0) -> 0.125 | L16: =VLOOKUP("新豐9線",'0227 4度C'!$A:$T,19,0) -> 0.125 | M16: =VLOOKUP("新豐4線",'0227 4度C'!$A:$T,19,0) -> 0.125
C17: 結束 | D17: =LOOKUP(2,1/(('0227 4度C'!$A:$A="新豐6線")*('0227 4度C'!$T:$T<>"")),'0227 4度C'!$T:$T) -> 0.82361111 | E17: =LOOKUP(2,1/(('0227 4度C'!$A:$A="新豐2線")*('0227 4度C'!$T:$T<>"")),'0227 4度C'!$T:$T) -> 0.43888889 | F17: =LOOKUP(2,1/(('0227 4度C'!$A:$A="新豐5線")*('0227 4度C'!$T:$T<>"")),'0227 4度C'!$T:$T) -> 0.83819444 | G17: =LOOKUP(2,1/(('0227 4度C'!$A:$A="新豐7線")*('0227 4度C'!$T:$T<>"")),'0227 4度C'!$T:$T) -> 0.83125 | H17: =LOOKUP(2,1/(('0227 4度C'!$A:$A="新豐3線")*('0227 4度C'!$T:$T<>"")),'0227 4度C'!$T:$T) -> 0.60208333 | I17: =LOOKUP(2,1/(('0227 4度C'!$A:$A="新豐1線")*('0227 4度C'!$T:$T<>"")),'0227 4度C'!$T:$T) -> 0.84444444 | J17: =LOOKUP(2,1/(('0227 4度C'!$A:$A="新豐10線")*('0227 4度C'!$T:$T<>"")),'0227 4度C'!$T:$T) -> 0.3875 | K17: =LOOKUP(2,1/(('0227 4度C'!$A:$A="新豐8線")*('0227 4度C'!$T:$T<>"")),'0227 4度C'!$T:$T) -> 0.47152778 | L17: =LOOKUP(2,1/(('0227 4度C'!$A:$A="新豐9線")*('0227 4度C'!$T:$T<>"")),'0227 4度C'!$T:$T) -> 0.46944444 | M17: =LOOKUP(2,1/(('0227 4度C'!$A:$A="新豐4線")*('0227 4度C'!$T:$T<>"")),'0227 4度C'!$T:$T) -> 0.44583333
B18: 產線異常 (5分鐘以上) | C18: 次數 | D18: =SUMIFS('0227 4度C'!$Y:$Y,'0227 4度C'!$A:$A,"新豐6線",'0227 4度C'!$B:$B,"平均") -> 0 | E18: =SUMIFS('0227 4度C'!$Y:$Y,'0227 4度C'!$A:$A,"新豐2線",'0227 4度C'!$B:$B,"平均") -> 0 | F18: =SUMIFS('0227 4度C'!$Y:$Y,'0227 4度C'!$A:$A,"新豐5線",'0227 4度C'!$B:$B,"平均") -> 0 | G18: =SUMIFS('0227 4度C'!$Y:$Y,'0227 4度C'!$A:$A,"新豐7線",'0227 4度C'!$B:$B,"平均") -> 0 | H18: =SUMIFS('0227 4度C'!$Y:$Y,'0227 4度C'!$A:$A,"新豐3線",'0227 4度C'!$B:$B,"平均") -> 0 | I18: =SUMIFS('0227 4度C'!$Y:$Y,'0227 4度C'!$A:$A,"新豐1線",'0227 4度C'!$B:$B,"平均") -> 0 | J18: =SUMIFS('0227 4度C'!$Y:$Y,'0227 4度C'!$A:$A,"新豐10線",'0227 4度C'!$B:$B,"平均") -> 0 | K18: =SUMIFS('0227 4度C'!$Y:$Y,'0227 4度C'!$A:$A,"新豐8線",'0227 4度C'!$B:$B,"平均") -> 0 | L18: =SUMIFS('0227 4度C'!$Y:$Y,'0227 4度C'!$A:$A,"新豐9線",'0227 4度C'!$B:$B,"平均") -> 0 | M18: =SUMIFS('0227 4度C'!$Y:$Y,'0227 4度C'!$A:$A,"新豐4線",'0227 4度C'!$B:$B,"平均") -> 0
C19: 時間/分 | D19: =SUMIFS('0227 4度C'!$Z:$Z,'0227 4度C'!$A:$A,"新豐6線",'0227 4度C'!$B:$B,"平均") -> 0 | E19: =SUMIFS('0227 4度C'!$Z:$Z,'0227 4度C'!$A:$A,"新豐2線",'0227 4度C'!$B:$B,"平均") -> 0 | F19: =SUMIFS('0227 4度C'!$Z:$Z,'0227 4度C'!$A:$A,"新豐5線",'0227 4度C'!$B:$B,"平均") -> 0 | G19: =SUMIFS('0227 4度C'!$Z:$Z,'0227 4度C'!$A:$A,"新豐7線",'0227 4度C'!$B:$B,"平均") -> 0 | H19: =SUMIFS('0227 4度C'!$Z:$Z,'0227 4度C'!$A:$A,"新豐3線",'0227 4度C'!$B:$B,"平均") -> 0 | I19: =SUMIFS('0227 4度C'!$Z:$Z,'0227 4度C'!$A:$A,"新豐1線",'0227 4度C'!$B:$B,"平均") -> 0 | J19: =SUMIFS('0227 4度C'!$Z:$Z,'0227 4度C'!$A:$A,"新豐10線",'0227 4度C'!$B:$B,"平均") -> 0 | K19: =SUMIFS('0227 4度C'!$Z:$Z,'0227 4度C'!$A:$A,"新豐8線",'0227 4度C'!$B:$B,"平均") -> 0 | L19: =SUMIFS('0227 4度C'!$Z:$Z,'0227 4度C'!$A:$A,"新豐9線",'0227 4度C'!$B:$B,"平均") -> 0 | M19: =SUMIFS('0227 4度C'!$Z:$Z,'0227 4度C'!$A:$A,"新豐4線",'0227 4度C'!$B:$B,"平均") -> 0
B20: 短暫停線 (5分鐘以下) | C20: 次數 | D20: =SUMIFS('0227 4度C'!$AC:$AC,'0227 4度C'!$A:$A,"新豐6線",'0227 4度C'!$B:$B,"平均") -> 5 | E20: =SUMIFS('0227 4度C'!$AC:$AC,'0227 4度C'!$A:$A,"新豐2線",'0227 4度C'!$B:$B,"平均") -> 2 | F20: =SUMIFS('0227 4度C'!$AC:$AC,'0227 4度C'!$A:$A,"新豐5線",'0227 4度C'!$B:$B,"平均") -> 4 | G20: =SUMIFS('0227 4度C'!$AC:$AC,'0227 4度C'!$A:$A,"新豐7線",'0227 4度C'!$B:$B,"平均") -> 5 | H20: =SUMIFS('0227 4度C'!$AC:$AC,'0227 4度C'!$A:$A,"新豐3線",'0227 4度C'!$B:$B,"平均") -> 8 | I20: =SUMIFS('0227 4度C'!$AC:$AC,'0227 4度C'!$A:$A,"新豐1線",'0227 4度C'!$B:$B,"平均") -> 8 | J20: =SUMIFS('0227 4度C'!$AC:$AC,'0227 4度C'!$A:$A,"新豐10線",'0227 4度C'!$B:$B,"平均") -> 6 | K20: =SUMIFS('0227 4度C'!$AC:$AC,'0227 4度C'!$A:$A,"新豐8線",'0227 4度C'!$B:$B,"平均") -> 5 | L20: =SUMIFS('0227 4度C'!$AC:$AC,'0227 4度C'!$A:$A,"新豐9線",'0227 4度C'!$B:$B,"平均") -> 5 | M20: =SUMIFS('0227 4度C'!$AC:$AC,'0227 4度C'!$A:$A,"新豐4線",'0227 4度C'!$B:$B,"平均") -> 5
C21: 設備次數 | D21: =SUMIFS('0227 4度C'!$AD:$AD,'0227 4度C'!$A:$A,"新豐6線",'0227 4度C'!$B:$B,"平均") -> 0 | E21: =SUMIFS('0227 4度C'!$AD:$AD,'0227 4度C'!$A:$A,"新豐2線",'0227 4度C'!$B:$B,"平均") -> 0 | F21: =SUMIFS('0227 4度C'!$AD:$AD,'0227 4度C'!$A:$A,"新豐5線",'0227 4度C'!$B:$B,"平均") -> 0 | G21: =SUMIFS('0227 4度C'!$AD:$AD,'0227 4度C'!$A:$A,"新豐7線",'0227 4度C'!$B:$B,"平均") -> 0 | H21: =SUMIFS('0227 4度C'!$AD:$AD,'0227 4度C'!$A:$A,"新豐3線",'0227 4度C'!$B:$B,"平均") -> 0 | I21: =SUMIFS('0227 4度C'!$AD:$AD,'0227 4度C'!$A:$A,"新豐1線",'0227 4度C'!$B:$B,"平均") -> 0 | J21: =SUMIFS('0227 4度C'!$AD:$AD,'0227 4度C'!$A:$A,"新豐10線",'0227 4度C'!$B:$B,"平均") -> 0 | K21: =SUMIFS('0227 4度C'!$AD:$AD,'0227 4度C'!$A:$A,"新豐8線",'0227 4度C'!$B:$B,"平均") -> 0 | L21: =SUMIFS('0227 4度C'!$AD:$AD,'0227 4度C'!$A:$A,"新豐9線",'0227 4度C'!$B:$B,"平均") -> 0 | M21: =SUMIFS('0227 4度C'!$AD:$AD,'0227 4度C'!$A:$A,"新豐4線",'0227 4度C'!$B:$B,"平均") -> 0
B22: 配置人數 | D22: =SUMIFS('0227 4度C'!$I:$I,'0227 4度C'!$A:$A,"新豐6線",'0227 4度C'!$B:$B,"平均") -> 17.8 | E22: =SUMIFS('0227 4度C'!$I:$I,'0227 4度C'!$A:$A,"新豐2線",'0227 4度C'!$B:$B,"平均") -> 18 | F22: =SUMIFS('0227 4度C'!$I:$I,'0227 4度C'!$A:$A,"新豐5線",'0227 4度C'!$B:$B,"平均") -> 18 | G22: =SUMIFS('0227 4度C'!$I:$I,'0227 4度C'!$A:$A,"新豐7線",'0227 4度C'!$B:$B,"平均") -> 14.8 | H22: =SUMIFS('0227 4度C'!$I:$I,'0227 4度C'!$A:$A,"新豐3線",'0227 4度C'!$B:$B,"平均") -> 9.875 | I22: =SUMIFS('0227 4度C'!$I:$I,'0227 4度C'!$A:$A,"新豐1線",'0227 4度C'!$B:$B,"平均") -> 18.875 | J22: =SUMIFS('0227 4度C'!$I:$I,'0227 4度C'!$A:$A,"新豐10線",'0227 4度C'!$B:$B,"平均") -> 10.5 | K22: =SUMIFS('0227 4度C'!$I:$I,'0227 4度C'!$A:$A,"新豐8線",'0227 4度C'!$B:$B,"平均") -> 18.4 | L22: =SUMIFS('0227 4度C'!$I:$I,'0227 4度C'!$A:$A,"新豐9線",'0227 4度C'!$B:$B,"平均") -> 17.6 | M22: =SUMIFS('0227 4度C'!$I:$I,'0227 4度C'!$A:$A,"新豐4線",'0227 4度C'!$B:$B,"平均") -> 16.6
B23: 主要應用設備 | D23: ET-55 | E23: 熱縮爐 | F23: L型包裝機 | G23: L型包裝機 | H23: 伺服包裝機 | I23: ET-55 | J23: 伺服包裝機 | K23: 三明治包裝機 | L23: 三明治包裝機 | M23: 三明治包裝機
B24: 次要應用設備 | F24: 圓盤機 | G24: ET-55
B25: 備註 | E25: 握沙拉 | F25: 共用L型包裝機 | H25: 調理麵包 | I25: 炒飯+沙拉 | J25: 調理麵包

Sheet 0227 4度C
A1: 新豐廠四度C日報分析 | C1: 總生產量 | D1: =SUM(F5:F67) -> 119463 | E1: 營業額 | F1: =SUM(G5:G67) -> 4109978.4 | G1: 出勤人數 | H1: =L10+L13+L45+L54+L18+L61+L30+L36+L24+L67 -> 160.45 | I1: 產線配置圖 | L1: 生產實績 | O1: 人時性差異分析 | S1: 日報登錄 | Y1: 合計 次數 | Z1: 合計 時間/分 | AA1: 產線異常 分析說明(5分鐘以上) | AC1: 合計 次數 | AD1: 合計 設備次數 | AE1: 產能差異分析
A2: 46080 | B2: 星期五 | C2: 人時性 | D2: =AVERAGE(N10,N13,N45,N54,N18,N61,N24,N30,N36,N67) -> 139.33386 | E2: 平均廠價 | F2: =F1/D1 -> 34.403777 | G2: 多次生產數 | H2: =COUNT(H5:H67) -> 2 | Y2: =SUM(Y10+Y13+Y18+Y24+Y30+Y36+Y45+Y54+Y61+Y67) -> 0 | Z2: =SUM(Z10+Z13+Z18+Z24+Z30+Z36+Z45+Z54+Z61+Z67) -> 0 | AC2: 53 | AD2: =SUM(AD10+AD13+AD18+AD24+AD30+AD36+AD45+AD54+AD61+AD67) -> 0
A3: 線別 | B3: 品類 | C3: 品名 | E3: 廠價 | F3: 生產量 | G3: 營收 | H3: 多次 生產 | I3: 人數 | J3: 產能/時 | K3: 人時性 | L3: 人數 | M3: 產能/時 | N3: 人時性 | O3: 人數 | P3: 人時性 | Q3: 達成率 | R3: 達成率平均 | S3: 生產時間 | U3: 換線、休息/分 | V3: 稼動時間/分 | W3: 休息時間 | Y3: 產線異常統計 (5分鐘以上) | AA3: (新豐回填) | AC3: 短暫停線統計 (5分鐘以下) | AE3: 產能/時 | AF3: 達成率 | AG3: 達成率平均
S4: 開始 | T4: 結束 | W4: 開始 | X4: 結束 | Y4: 次數 | Z4: 時間/分 | AC4: 總次數 | AD4: 設備因素(次數)
A5: 新豐6線 | B5: 微波主食 | C5: 二配港式香滑嫩蛋牛肉燴飯 | E5: 50.67 | F5: 1399 | G5: =E5*F5 -> 70887.33 | I5: 17 | J5: 2000 | K5: =J5/I5 -> 117.64706 | L5: 17 | M5: =F5/V5*60 -> 1907.7273 | N5: =M5/L5 -> 112.21925 | O5: =L5-I5 -> 0 | P5: =N5-K5 -> -5.4278075 | Q5: =N5/K5 -> 0.95386364 | R5: =Q10 -> 0.96899919 | S5: 0.70833333 | T5: 0.73888889 | V5: =(T5-S5)*24*60 -> 44 | AC5: 5 | AE5: =M5-J5 -> -92.272727 | AF5: =M5/J5 -> 0.95386364 | AG5: =AF10 -> 0.96899919
A6: 新豐6線 | B6: 微波主食 | C6: 二配美味蟹煲 | E6: 54.09 | F6: 1220 | G6: =E6*F6 -> 65989.8 | I6: 19 | J6: 2000 | K6: =J6/I6 -> 105.26316 | L6: 19 | M6: =F6/V6*60 -> 1926.3158 | N6: =M6/L6 -> 101.38504 | O6: =L6-I6 -> 0 | P6: =N6-K6 -> -3.8781163 | Q6: =N6/K6 -> 0.96315789 | S6: 0.74305556 | T6: 0.76944444 | U6: =IF(S6=TIME(17,0,0),"",(S6-T5)*24*60) -> 6 | V6: =(T6-S6)*24*60 -> 38 | AE6: =M6-J6 -> -73.684211 | AF6: =M6/J6 -> 0.96315789
A7: 新豐6線 | B7: 微波主食 | C7: 二配麻油雞燴飯 | E7: 50.29 | F7: 499 | G7: =E7*F7 -> 25094.71 | I7: 16 | J7: 2000 | K7: =J7/I7 -> 125 | L7: 16 | M7: =F7/V7*60 -> 1996 | N7: =M7/L7 -> 124.75 | O7: =L7-I7 -> 0 | P7: =N7-K7 -> -0.25 | Q7: =N7/K7 -> 0.998 | S7: 0.775 | T7: 0.78541667 | U7: =IF(S7=TIME(17,0,0),"",(S7-T6)*24*60) -> 8 | V7: =(T7-S7)*24*60 -> 15 | AE7: =M7-J7 -> -4 | AF7: =M7/J7 -> 0.998
A8: 新豐6線 | B8: 微波主食 | C8: 二配濃蕃茄火腿蛋包飯 | E8: 50.67 | F8: 543 | G8: =E8*F8 -> 27513.81 | I8: 21 | J8: 2000 | K8: =J8/I8 -> 95.238095 | L8: 21 | M8: =F8/V8*60 -> 1916.4706 | N8: =M8/L8 -> 91.260504 | O8: =L8-I8 -> 0 | P8: =N8-K8 -> -3.977591 | Q8: =N8/K8 -> 0.95823529 | S8: 0.79027778 | T8: 0.80208333 | U8: =IF(S8=TIME(17,0,0),"",(S8-T7)*24*60) -> 7 | V8: =(T8-S8)*24*60 -> 17 | AE8: =M8-J8 -> -83.529412 | AF8: =M8/J8 -> 0.95823529
A9: 新豐6線 | B9: 微波主食 | C9: 二配香炒沙茶豬肉飯 | E9: 50.67 | F9: 745 | G9: =E9*F9 -> 37749.15 | I9: 16 | J9: 2000 | K9: =J9/I9 -> 125 | L9: 16 | M9: =F9/V9*60 -> 1943.4783 | N9: =M9/L9 -> 121.46739 | O9: =L9-I9 -> 0 | P9: =N9-K9 -> -3.5326087 | Q9: =N9/K9 -> 0.97173913 | S9: 0.80763889 | T9: 0.82361111 | U9: =IF(S9=TIME(17,0,0),"",(S9-T8)*24*60) -> 8 | V9: =(T9-S9)*24*60 -> 23 | AE9: =M9-J9 -> -56.521739 | AF9: =M9/J9 -> 0.97173913
A10: 新豐6線 | B10: 平均 | I10: 17.8 | J10: 2000 | K10: =J10/I10 -> 112.35955 | L10: 17.8 | M10: =AVERAGE(M5:M9) -> 1937.9984 | N10: =M10/L10 -> 108.87631 | O10: =L10-I10 -> 0 | P10: =N10-K10 -> -3.483237 | Q10: =N10/K10 -> 0.96899919 | Y10: =SUM(Y5:Y9) -> 0 | Z10: =SUM(Z5:Z9) -> 0 | AC10: 5 | AD10: =SUM(AD5:AD9) -> 0 | AE10: =M10-J10 -> -62.001618 | AF10: =M10/J10 -> 0.96899919
A11: 新豐2線 | B11: 沙拉 | C11: 青醬優格雞肉握沙拉(113年) | E11: 39.62 | F11: 2928 | G11: =E11*F11 -> 116007.36 | I11: 19 | J11: 1500 | K11: =J11/I11 -> 78.947368 | L11: 19 | M11: =F11/V11*60 -> 1440 | N11: =M11/L11 -> 75.789474 | O11: =L11-I11 -> 0 | P11: =N11-K11 -> -3.1578947 | Q11: =N11/K11 -> 0.96 | R11: =Q13 -> 0.95643564 | S11: 0.20833333 | T11: 0.29305556 | V11: =(T11-S11)*24*60 -> 122 | AC11: 2 | AE11: =M11-J11 -> -60 | AF11: =M11/J11 -> 0.96 | AG11: =AF13 -> 0.95643564
A12: 新豐2線 | B12: 沙拉 | C12: 青檸烤雞握沙拉(113年) | E12: 39.8 | F12: 4812 | G12: =E12*F12 -> 191517.6 | I12: 17 | J12: 1500 | K12: =J12/I12 -> 88.235294 | L12: 17 | M12: =F12/V12*60 -> 1429.3069 | N12: =M12/L12 -> 84.076878 | O12: =L12-I12 -> 0 | P12: =N12-K12 -> -4.1584158 | Q12: =N12/K12 -> 0.95287129 | S12: 0.29861111 | T12: 0.43888889 | U12: =IF(S12=TIME(17,0,0),"",(S12-T11)*24*60) -> 8 | V12: =(T12-S12)*24*60 -> 202 | AE12: =M12-J12 -> -70.693069 | AF12: =M12/J12 -> 0.95287129
A13: 新豐2線 | B13: 平均 | I13: 18 | J13: 1500 | K13: =J13/I13 -> 83.333333 | L13: 18 | M13: =AVERAGE(M11:M12) -> 1434.6535 | N13: =M13/L13 -> 79.70297 | O13: =L13-I13 -> 0 | P13: =N13-K13 -> -3.630363 | Q13: =N13/K13 -> 0.95643564 | Y13: =SUM(Y11:Y12) -> 0 | Z13: =SUM(Z11:Z12) -> 0 | AC13: 2 | AD13: =SUM(AD11:AD12) -> 0 | AE13: =M13-J13 -> -65.346535 | AF13: =M13/J13 -> 0.95643564
A14: 新豐5線 | B14: 小吃 | C14: 剝皮辣椒雞湯 | E14: 41 | F14: 2091 | G14: =E14*F14 -> 85731 | I14: 26 | J14: 1500 | K14: =J14/I14 -> 57.692308 | L14: 26 | M14: =F14/V14*60 -> 1442.069 | N14: =M14/L14 -> 55.464191 | O14: =L14-I14 -> 0 | P14: =N14-K14 -> -2.2281167 | Q14: =N14/K14 -> 0.96137931 | R14: =Q18 -> 0.95905027 | S14: 0.20833333 | T14: 0.26875 | V14: =(T14-S14)*24*60 -> 87 | AC14: 4 | AE14: =M14-J14 -> -57.931034 | AF14: =M14/J14 -> 0.96137931 | AG14: =AF18 -> 0.95905027
A15: 新豐5線 | B15: 微波主食 | C15: 二配金咖哩濃厚辛口咖哩飯 | E15: 50.98 | F15: 2189 | G15: =E15*F15 -> 111595.22 | I15: 16 | J15: 2000 | K15: =J15/I15 -> 125 | L15: 16 | M15: =F15/V15*60 -> 1931.4706 | N15: =M15/L15 -> 120.71691 | O15: =L15-I15 -> 0 | P15: =N15-K15 -> -4.2830882 | Q15: =N15/K15 -> 0.96573529 | S15: 0.70833333 | T15: 0.75555556 | U15: =IF(S15=TIME(17,0,0),"",(S15-T14)*24*60) | V15: =(T15-S15)*24*60 -> 68 | AE15: =M15-J15 -> -68.529412 | AF15: =M15/J15 -> 0.96573529
A16: 新豐5線 | B16: 微波主食 | C16: 二配金咖哩果香甘口咖哩飯 | E16: 50.92 | F16: 2134 | G16: =E16*F16 -> 108663.28 | I16: 15 | J16: 2000 | K16: =J16/I16 -> 133.33333 | L16: 15 | M16: =F16/V16*60 -> 1911.0448 | N16: =M16/L16 -> 127.40299 | O16: =L16-I16 -> 0 | P16: =N16-K16 -> -5.9303483 | Q16: =N16/K16 -> 0.95552239 | S16: 0.75972222 | T16: 0.80625 | U16: =IF(S16=TIME(17,0,0),"",(S16-T15)*24*60) -> 6 | V16: =(T16-S16)*24*60 -> 67 | AE16: =M16-J16 -> -88.955224 | AF16: =M16/J16 -> 0.95552239
A17: 新豐5線 | B17: 微波主食 | C17: 二配泰式綠咖哩雞 | E17: 50.67 | F17: 1304 | G17: =E17*F17 -> 66073.68 | I17: 15 | J17: 2000 | K17: =J17/I17 -> 133.33333 | L17: 15 | M17: =F17/V17*60 -> 1908.2927 | N17: =M17/L17 -> 127.21951 | O17: =L17-I17 -> 0 | P17: =N17-K17 -> -6.1138211 | Q17: =N17/K17 -> 0.95414634 | S17: 0.80972222 | T17: 0.83819444 | U17: =IF(S17=TIME(17,0,0),"",(S17-T16)*24*60) -> 5 | V17: =(T17-S17)*24*60 -> 41 | AE17: =M17-J17 -> -91.707317 | AF17: =M17/J17 -> 0.95414634
A18: 新豐5線 | B18: 平均 | I18: 18 | J18: 1875 | K18: =J18/I18 -> 104.16667 | L18: 18 | M18: =AVERAGE(M14:M17) -> 1798.2193 | N18: =M18/L18 -> 99.90107 | O18: =L18-I18 -> 0 | P18: =N18-K18 -> -4.265597 | Q18: =N18/K18 -> 0.95905027 | Y18: =SUM(Y14:Y17) -> 0 | Z18: =SUM(Z14:Z17) -> 0 | AC18: 4 | AD18: =SUM(AD14:AD17) -> 0 | AE18: =M18-J18 -> -76.780747 | AF18: =M18/J18 -> 0.95905027
A19: 新豐7線 | B19: 微波主食 | C19: 鐵板滑蛋炸豬排丼 | E19: 57.73 | F19: 2350 | G19: =E19*F19 -> 135665.5 | I19: 14 | J19: 2000 | K19: =J19/I19 -> 142.85714 | L19: 14 | M19: =F19/V19*60 -> 1905.4054 | N19: =M19/L19 -> 136.10039 | O19: =L19-I19 -> 0 | P19: =N19-K19 -> -6.7567568 | Q19: =N19/K19 -> 0.9527027 | R19: =Q24 -> 0.96155735 | S19: 0.20833333 | T19: 0.25972222 | V19: =(T19-S19)*24*60 -> 74 | AC19: 5 | AE19: =M19-J19 -> -94.594595 | AF19: =M19/J19 -> 0.9527027 | AG19: =AF24 -> 0.96155735
A20: 新豐7線 | B20: 微波主食 | C20: 極上炙烤親子丼 | E20: 53.68 | F20: 1257 | G20: =E20*F20 -> 67475.76 | I20: 16 | J20: 2000 | K20: =J20/I20 -> 125 | L20: 16 | M20: =F20/V20*60 -> 1933.8462 | N20: =M20/L20 -> 120.86538 | O20: =L20-I20 -> 0 | P20: =N20-K20 -> -4.1346154 | Q20: =N20/K20 -> 0.96692308 | S20: 0.26527778 | T20: 0.29236111 | U20: =IF(S20=TIME(17,0,0),"",(S20-T19)*24*60) -> 8 | V20: =(T20-S20)*24*60 -> 39 | AE20: =M20-J20 -> -66.153846 | AF20: =M20/J20 -> 0.96692308
A21: 新豐7線 | B21: 微波主食 | C21: 二配川味麻婆燒豆腐燴飯 | E21: 50.49 | F21: 1684 | G21: =E21*F21 -> 85025.16 | I21: 15 | J21: 2000 | K21: =J21/I21 -> 133.33333 | L21: 15 | M21: =F21/V21*60 -> 1906.4151 | N21: =M21/L21 -> 127.09434 | O21: =L21-I21 -> 0 | P21: =N21-K21 -> -6.2389937 | Q21: =N21/K21 -> 0.95320755 | S21: 0.70833333 | T21: 0.74513889 | U21: =IF(S21=TIME(17,0,0),"",(S21-T20)*24*60) | V21: =(T21-S21)*24*60 -> 53 | AE21: =M21-J21 -> -93.584906 | AF21: =M21/J21 -> 0.95320755
A22: 新豐7線 | B22: 微波主食 | C22: 二配厚香料咖哩雞排飯 | E22: 57.3 | F22: 1457 | G22: =E22*F22 -> 83486.1 | I22: 13 | J22: 2000 | K22: =J22/I22 -> 153.84615 | L22: 13 | M22: =F22/V22*60 -> 1942.6667 | N22: =M22/L22 -> 149.4359 | O22: =L22-I22 -> 0 | P22: =N22-K22 -> -4.4102564 | Q22: =N22/K22 -> 0.97133333 | S22: 0.75069444 | T22: 0.78194444 | U22: =IF(S22=TIME(17,0,0),"",(S22-T21)*24*60) -> 8 | V22: =(T22-S22)*24*60 -> 45 | AE22: =M22-J22 -> -57.333333 | AF22: =M22/J22 -> 0.97133333
A23: 新豐7線 | B23: 微波主食 | C23: 二配起司控培根白醬焗烤飯 | E23: 53.68 | F23: 1567 | G23: =E23*F23 -> 84116.56 | I23: 16 | J23: 1500 | K23: =J23/I23 -> 93.75 | L23: 16 | M23: =F23/V23*60 -> 1446.4615 | N23: =M23/L23 -> 90.403846 | O23: =L23-I23 -> 0 | P23: =N23-K23 -> -3.3461538 | Q23: =N23/K23 -> 0.96430769 | S23: 0.78611111 | T23: 0.83125 | U23: =IF(S23=TIME(17,0,0),"",(S23-T22)*24*60) -> 6 | V23: =(T23-S23)*24*60 -> 65 | AE23: =M23-J23 -> -53.538462 | AF23: =M23/J23 -> 0.96430769
A24: 新豐7線 | B24: 平均 | I24: 14.8 | J24: 1900 | K24: =J24/I24 -> 128.37838 | L24: 14.8 | M24: =AVERAGE(M19:M23) -> 1826.959 | N24: =M24/L24 -> 123.44317 | O24: =L24-I24 -> 0 | P24: =N24-K24 -> -4.9352046 | Q24: =N24/K24 -> 0.96155735 | Y24: =SUM(Y19:Y23) -> 0 | Z24: =SUM(Z19:Z23) -> 0 | AC24: 5 | AD24: =SUM(AD19:AD23) -> 0 | AE24: =M24-J24 -> -73.041028 | AF24: =M24/J24 -> 0.96155735
A25: 新豐8線 | B25: 三明治 | C25: 紐奧良風味烤雞鮮蔬三明治 | E25: 31.29 | F25: 6968 | G25: =E25*F25 -> 218028.72 | I25: 18 | J25: 2400 | K25: =J25/I25 -> 133.33333 | L25: 18 | M25: =F25/V25*60 -> 2297.1429 | N25: =M25/L25 -> 127.61905 | O25: =L25-I25 -> 0 | P25: =N25-K25 -> -5.7142857 | Q25: =N25/K25 -> 0.95714286 | R25: =Q30 -> 0.95848466 | S25: 0.125 | T25: 0.25138889 | V25: =(T25-S25)*24*60 -> 182 | W25: =T25 -> 0.25138889 | X25: =S26 -> 0.26944444 | AC25: 5 | AE25: =M25-J25 -> -102.85714 | AF25: =M25/J25 -> 0.95714286 | AG25: =AF30 -> 0.95848466
A26: 新豐8線 | B26: 三明治 | C26: 好多菜三明治(114年) | E26: 25.98 | F26: 2188 | G26: =E26*F26 -> 56844.24 | I26: 21 | J26: 2400 | K26: =J26/I26 -> 114.28571 | L26: 21 | M26: =F26/V26*60 -> 2303.1579 | N26: =M26/L26 -> 109.67419 | O26: =L26-I26 -> 0 | P26: =N26-K26 -> -4.6115288 | Q26: =N26/K26 -> 0.95964912 | S26: 0.26944444 | T26: 0.30902778 | U26: =(S26-T25)*24*60 -> 26 | V26: =(T26-S26)*24*60 -> 57 | AE26: =M26-J26 -> -96.842105 | AF26: =M26/J26 -> 0.95964912
A27: 新豐8線 | B27: 三明治 | C27: 經典總匯三明治 | E27: 26.2 | F27: 3803 | G27: =E27*F27 -> 99638.6 | I27: 20 | J27: 2400 | K27: =J27/I27 -> 120 | L27: 20 | M27: =F27/V27*60 -> 2304.8485 | N27: =M27/L27 -> 115.24242 | O27: =L27-I27 -> 0 | P27: =N27-K27 -> -4.7575758 | Q27: =N27/K27 -> 0.96035354 | S27: 0.3125 | T27: 0.38125 | U27: =(S27-T26)*24*60 -> 5 | V27: =(T27-S27)*24*60 -> 99 | AE27: =M27-J27 -> -95.151515 | AF27: =M27/J27 -> 0.96035354
A28: 新豐8線 | B28: 三明治 | C28: 雞蛋沙拉三明治(114年) | E28: 25.99 | F28: 3096 | G28: =E28*F28 -> 80465.04 | I28: 14 | J28: 2400 | K28: =J28/I28 -> 171.42857 | L28: 14 | M28: =F28/V28*60 -> 2293.3333 | N28: =M28/L28 -> 163.80952 | O28: =L28-I28 -> 0 | P28: =N28-K28 -> -7.6190476 | Q28: =N28/K28 -> 0.95555556 | S28: 0.38541667 | T28: 0.44166667 | U28: =(S28-T27)*24*60 -> 6 | V28: =(T28-S28)*24*60 -> 81 | AE28: =M28-J28 -> -106.66667 | AF28: =M28/J28 -> 0.95555556
A29: 新豐8線 | B29: 三明治 | C29: 陽光地瓜總匯三明治 | E29: 26.18 | F29: 1382 | G29: =E29*F29 -> 36180.76 | I29: 19 | J29: 2400 | K29: =J29/I29 -> 126.31579 | L29: 19 | M29: =F29/V29*60 -> 2303.3333 | N29: =M29/L29 -> 121.22807 | O29: =L29-I29 -> 0 | P29: =N29-K29 -> -5.0877193 | Q29: =N29/K29 -> 0.95972222 | S29: 0.44652778 | T29: 0.47152778 | U29: =(S29-T28)*24*60 -> 7 | V29: =(T29-S29)*24*60 -> 36 | AE29: =M29-J29 -> -96.666667 | AF29: =M29/J29 -> 0.95972222
A30: 新豐8線 | B30: 平均 | I30: 18.4 | J30: 2400 | K30: =J30/I30 -> 130.43478 | L30: 18.4 | M30: =AVERAGE(M25:M29) -> 2300.3632 | N30: =M30/L30 -> 125.01974 | O30: =L30-I30 -> 0 | P30: =N30-K30 -> -5.4150445 | Q30: =N30/K30 -> 0.95848466 | Y30: =SUM(Y25:Y29) -> 0 | Z30: =SUM(Z25:Z29) -> 0 | AC30: 5 | AD30: =SUM(AD25:AD29) -> 0 | AE30: =M30-J30 -> -99.636819 | AF30: =M30/J30 -> 0.95848466
A31: 新豐9線 | B31: 三明治 | C31: 鮪魚起司溏心蛋三明治 | E31: 26.2 | F31: 5045 | G31: =E31*F31 -> 132179 | I31: 18 | J31: 2400 | K31: =J31/I31 -> 133.33333 | L31: 18 | M31: =F31/V31*60 -> 2293.1818 | N31: =M31/L31 -> 127.39899 | O31: =L31-I31 -> 0 | P31: =N31-K31 -> -5.9343434 | Q31: =N31/K31 -> 0.95549242 | R31: =Q36 -> 0.95861342 | S31: 0.125 | T31: 0.21666667 | V31: =(T31-S31)*24*60 -> 132 | W31: =T31 -> 0.21666667 | X31: =S32 -> 0.2375 | AC31: 5 | AE31: =M31-J31 -> -106.81818 | AF31: =M31/J31 -> 0.95549242 | AG31: =AF36 -> 0.95861342
A32: 新豐9線 | B32: 三明治 | C32: 肉鬆火腿三明治 | E32: 20.52 | F32: 2865 | G32: =E32*F32 -> 58789.8 | I32: 18 | J32: 2400 | K32: =J32/I32 -> 133.33333 | L32: 18 | M32: =F32/V32*60 -> 2292 | N32: =M32/L32 -> 127.33333 | O32: =L32-I32 -> 0 | P32: =N32-K32 -> -6 | Q32: =N32/K32 -> 0.955 | S32: 0.2375 | T32: 0.28958333 | U32: =(S32-T31)*24*60 -> 30 | V32: =(T32-S32)*24*60 -> 75 | AE32: =M32-J32 -> -108 | AF32: =M32/J32 -> 0.955
A33: 新豐9線 | B33: 三明治 | C33: 醬燒烤雞三明治 | E33: 26.39 | F33: 4293 | G33: =E33*F33 -> 113292.27 | I33: 19 | J33: 2400 | K33: =J33/I33 -> 126.31579 | L33: 19 | M33: =F33/V33*60 -> 2299.8214 | N33: =M33/L33 -> 121.04323 | O33: =L33-I33 -> 0 | P33: =N33-K33 -> -5.2725564 | Q33: =N33/K33 -> 0.95825893 | S33: 0.29444444 | T33: 0.37222222 | U33: =(S33-T32)*24*60 -> 7 | V33: =(T33-S33)*24*60 -> 112 | AE33: =M33-J33 -> -100.17857 | AF33: =M33/J33 -> 0.95825893
A34: 新豐9線 | B34: 三明治 | C34: 藍莓優格三明治 | E34: 20.21 | F34: 2536 | G34: =E34*F34 -> 51252.56 | I34: 15 | J34: 2400 | K34: =J34/I34 -> 160 | L34: 15 | M34: =F34/V34*60 -> 2305.4545 | N34: =M34/L34 -> 153.69697 | O34: =L34-I34 -> 0 | P34: =N34-K34 -> -6.3030303 | Q34: =N34/K34 -> 0.96060606 | S34: 0.37708333 | T34: 0.42291667 | U34: =(S34-T33)*24*60 -> 7 | V34: =(T34-S34)*24*60 -> 66 | AE34: =M34-J34 -> -94.545455 | AF34: =M34/J34 -> 0.96060606
A35: 新豐9線 | B35: 三明治 | C35: 輕乳酪巧克力三明治 | E35: 20.52 | F35: 2390 | G35: =E35*F35 -> 49042.8 | I35: 18 | J35: 2400 | K35: =J35/I35 -> 133.33333 | L35: 18 | M35: =F35/V35*60 -> 2312.9032 | N35: =M35/L35 -> 128.49462 | O35: =L35-I35 -> 0 | P35: =N35-K35 -> -4.8387097 | Q35: =N35/K35 -> 0.96370968 | S35: 0.42638889 | T35: 0.46944444 | U35: =(S35-T34)*24*60 -> 5 | V35: =(T35-S35)*24*60 -> 62 | AE35: =M35-J35 -> -87.096774 | AF35: =M35/J35 -> 0.96370968
A36: 新豐9線 | B36: 平均 | I36: 17.6 | J36: 2400 | K36: =J36/I36 -> 136.36364 | L36: 17.6 | M36: =AVERAGE(M31:M35) -> 2300.6722 | N36: =M36/L36 -> 130.72001 | O36: =L36-I36 -> 0 | P36: =N36-K36 -> -5.6436248 | Q36: =N36/K36 -> 0.95861342 | Y36: =SUM(Y31:Y35) -> 0 | Z36: =SUM(Z31:Z35) -> 0 | AC36: 5 | AD36: =SUM(AD31:AD35) -> 0 | AE36: =M36-J36 -> -99.327796 | AF36: =M36/J36 -> 0.95861342
A37: 新豐3線 | B37: 調理麵包 | C37: 茄汁薯餅蛋堡 | E37: 34.36 | F37: 1965 | G37: =E37*F37 -> 67517.4 | I37: 10 | J37: 3000 | K37: =J37/I37 -> 300 | L37: 10 | M37: =F37/V37*60 -> 2875.6098 | N37: =M37/L37 -> 287.56098 | O37: =L37-I37 -> 0 | P37: =N37-K37 -> -12.439024 | Q37: =N37/K37 -> 0.95853659 | R37: =Q45 -> 0.96121587 | S37: 0.20833333 | T37: 0.23680556 | V37: =(T37-S37)*24*60 -> 41 | AC37: 8 | AE37: =M37-J37 -> -124.39024 | AF37: =M37/J37 -> 0.95853659 | AG37: =AF45 -> 0.96121587
A38: 新豐3線 | B38: 調理麵包 | C38: 經典雙牛起司堡(113年) | E38: 35.12 | F38: 3300 | G38: =E38*F38 -> 115896 | H38: 2 | I38: 10 | J38: 3000 | K38: =J38/I38 -> 300 | L38: 10 | M38: =F38/V38*60 -> 2869.5652 | N38: =M38/L38 -> 286.95652 | O38: =L38-I38 -> 0 | P38: =N38-K38 -> -13.043478 | Q38: =N38/K38 -> 0.95652174 | S38: 0.24166667 | T38: 0.28958333 | U38: =(S38-T37)*24*60 -> 7 | V38: =(T38-S38)*24*60 -> 69 | AE38: =M38-J38 -> -130.43478 | AF38: =M38/J38 -> 0.95652174
A39: 新豐3線 | B39: 調理麵包 | C39: 香雞蛋堡(112年) | E39: 26.78 | F39: 2309 | G39: =E39*F39 -> 61835.02 | I39: 10 | J39: 3000 | K39: =J39/I39 -> 300 | L39: 10 | M39: =F39/V39*60 -> 2886.25 | N39: =M39/L39 -> 288.625 | O39: =L39-I39 -> 0 | P39: =N39-K39 -> -11.375 | Q39: =N39/K39 -> 0.96208333 | S39: 0.29305556 | T39: 0.32638889 | U39: =(S39-T38)*24*60 -> 5 | V39: =(T39-S39)*24*60 -> 48 | AE39: =M39-J39 -> -113.75 | AF39: =M39/J39 -> 0.96208333
A40: 新豐3線 | B40: 調理麵包 | C40: 豬肉起司堡 | E40: 21.13 | F40: 4282 | G40: =E40*F40 -> 90478.66 | I40: 10 | J40: 3000 | K40: =J40/I40 -> 300 | L40: 10 | M40: =F40/V40*60 -> 2854.6667 | N40: =M40/L40 -> 285.46667 | O40: =L40-I40 -> 0 | P40: =N40-K40 -> -14.533333 | Q40: =N40/K40 -> 0.95155556 | S40: 0.33055556 | T40: 0.39305556 | U40: =(S40-T39)*24*60 -> 6 | V40: =(T40-S40)*24*60 -> 90 | AE40: =M40-J40 -> -145.33333 | AF40: =M40/J40 -> 0.95155556
...

Sheet 0226
B1: 屏榮 新豐廠組合室生產人時性分析
B3: 日期 | C3: =TEXT('0226 4度C'!A2,"yyyy.mm.ddaaaa") -> 2026.02.26星期四 | E3: 訂單量 | F3: ='0226 4度C'!D1 -> 124820 | H3: 營業額 | I3: ='0226 4度C'!F1 -> 4233006.4
B4: 人時性 | C4: 項目 | E4: ➀ | G4: ➁ | I4: ➂ | K4: 異常停線 | M4: 短暫停線
C5: 組合室 | E5: 全溫層 | G5: 4度C-各編組展開 | I5: ③三明治-各編組展開 | K5: 合計次數 | L5: 時間 | M5: 合計次數 | N5: 設備次數
C6: 排關平均 | E6: =AVERAGE(D13:M13) -> 144.82437 | F6: =AVERAGE(D31:O31,D13:J13) -> 148.12385 | G6: =AVERAGE(D13:J13) -> 148.12385 | I6: =AVERAGE(K13:M13) -> 137.12558 | K6: ='0226 4度C'!Y2 -> 0 | L6: ='0226 4度C'!Z2 -> 0 | M6: ='0226 4度C'!AC2 -> 54 | N6: ='0226 4度C'!AD2 -> 0
C7: 實績平均 | E7: =AVERAGE(D14:M14) -> 138.92205 | F7: =AVERAGE(D32:O32,D14:J14) -> 142.09193 | G7: =AVERAGE(D14:J14) -> 142.09193 | I7: =AVERAGE(K14:M14) -> 131.52565
C8: 達成率平均 | E8: =AVERAGE(D15:M15) -> 0.95877325 | F8: =AVERAGE(D15:J15,D33:O33) -> 0.95861728 | G8: =AVERAGE(D15:J15) -> 0.95861728 | I8: =AVERAGE(K15:M15) -> 0.95913717
K9: ※現行日本鮮食廠以達成率80%為基本(即為現行KPI)
B10: 溫層 | D10: ➁4度C-各編組展開 | K10: ③三明治-各編組展開
B11: 編組 | D11: 1 | E11: 2 | F11: 3 | G11: 4 | H11: 5 | I11: 6 | J11: 7 | K11: 1 | L11: 2 | M11: 3
D12: 新豐6線 | E12: 新豐2線 | F12: 新豐5線 | G12: 新豐7線 | H12: 新豐3線 | I12: 新豐1線 | J12: 新豐10線 | K12: 新豐8線 | L12: 新豐9線 | M12: 新豐4線
B13: 人時性 | C13: 排關 | D13: =SUMIFS('0226 4度C'!$K:$K,'0226 4度C'!$A:$A,"新豐6線",'0226 4度C'!$B:$B,"平均") -> 112.35955 | E13: =SUMIFS('0226 4度C'!$K:$K,'0226 4度C'!$A:$A,"新豐2線",'0226 4度C'!$B:$B,"平均") -> 83.333333 | F13: =SUMIFS('0226 4度C'!$K:$K,'0226 4度C'!$A:$A,"新豐5線",'0226 4度C'!$B:$B,"平均") -> 100 | G13: =SUMIFS('0226 4度C'!$K:$K,'0226 4度C'!$A:$A,"新豐7線",'0226 4度C'!$B:$B,"平均") -> 128.37838 | H13: =SUMIFS('0226 4度C'!$K:$K,'0226 4度C'!$A:$A,"新豐3線",'0226 4度C'!$B:$B,"平均") -> 303.79747 | I13: =SUMIFS('0226 4度C'!$K:$K,'0226 4度C'!$A:$A,"新豐1線",'0226 4度C'!$B:$B,"平均") -> 102.64901 | J13: =SUMIFS('0226 4度C'!$K:$K,'0226 4度C'!$A:$A,"新豐10線",'0226 4度C'!$B:$B,"平均") -> 206.34921 | K13: =SUMIFS('0226 4度C'!$K:$K,'0226 4度C'!$A:$A,"新豐8線",'0226 4度C'!$B:$B,"平均") -> 130.43478 | L13: =SUMIFS('0226 4度C'!$K:$K,'0226 4度C'!$A:$A,"新豐9線",'0226 4度C'!$B:$B,"平均") -> 136.36364 | M13: =SUMIFS('0226 4度C'!$K:$K,'0226 4度C'!$A:$A,"新豐4線",'0226 4度C'!$B:$B,"平均") -> 144.57831
C14: 實績 | D14: =SUMIFS('0226 4度C'!$N:$N,'0226 4度C'!$A:$A,"新豐6線",'0226 4度C'!$B:$B,"平均") -> 108.81612 | E14: =SUMIFS('0226 4度C'!$N:$N,'0226 4度C'!$A:$A,"新豐2線",'0226 4度C'!$B:$B,"平均") -> 79.592473 | F14: =SUMIFS('0226 4度C'!$N:$N,'0226 4度C'!$A:$A,"新豐5線",'0226 4度C'!$B:$B,"平均") -> 96.039251 | G14: =SUMIFS('0226 4度C'!$N:$N,'0226 4度C'!$A:$A,"新豐7線",'0226 4度C'!$B:$B,"平均") -> 122.95681 | H14: =SUMIFS('0226 4度C'!$N:$N,'0226 4度C'!$A:$A,"新豐3線",'0226 4度C'!$B:$B,"平均") -> 291.53999 | I14: =SUMIFS('0226 4度C'!$N:$N,'0226 4度C'!$A:$A,"新豐1線",'0226 4度C'!$B:$B,"平均") -> 97.212635 | J14: =SUMIFS('0226 4度C'!$N:$N,'0226 4度C'!$A:$A,"新豐10線",'0226 4度C'!$B:$B,"平均") -> 198.48622 | K14: =SUMIFS('0226 4度C'!$N:$N,'0226 4度C'!$A:$A,"新豐8線",'0226 4度C'!$B:$B,"平均") -> 125.18388 | L14: =SUMIFS('0226 4度C'!$N:$N,'0226 4度C'!$A:$A,"新豐9線",'0226 4度C'!$B:$B,"平均") -> 130.47925 | M14: =SUMIFS('0226 4度C'!$N:$N,'0226 4度C'!$A:$A,"新豐4線",'0226 4度C'!$B:$B,"平均") -> 138.91383
C15: 達成率 | D15: =D14/D13 -> 0.96846344 | E15: =E14/E13 -> 0.95510968 | F15: =F14/F13 -> 0.96039251 | G15: =G14/G13 -> 0.95776887 | H15: =H14/H13 -> 0.95965247 | I15: =I14/I13 -> 0.94703922 | J15: =J14/J13 -> 0.96189474 | K15: =K14/K13 -> 0.95974308 | ... M15: =M14/M13 -> 0.96082063
B16: 作業 時間 | C16: 開始 | D16: =VLOOKUP("新豐6線",'0226 4度C'!$A:$T,19,0) -> 0.70833333 | E16: =VLOOKUP("新豐2線",'0226 4度C'!$A:$T,19,0) -> 0.20833333 | F16: =VLOOKUP("新豐5線",'0226 4度C'!$A:$T,19,0) -> 0.20833333 | G16: =VLOOKUP("新豐7線",'0226 4度C'!$A:$T,19,0) -> 0.20833333 | H16: =VLOOKUP("新豐3線",'0226 4度C'!$A:$T,19,0) -> 0.20833333 | I16: =VLOOKUP("新豐1線",'0226 4度C'!$A:$T,19,0) -> 0.20833333 | J16: =VLOOKUP("新豐10線",'0226 4度C'!$A:$T,19,0) -> 0.20833333 | K16: =VLOOKUP("新豐8線",'0226 4度C'!$A:$T,19,0) -> 0.125 | L16: =VLOOKUP("新豐9線",'0226 4度C'!$A:$T,19,0) -> 0.125 | M16: =VLOOKUP("新豐4線",'0226 4度C'!$A:$T,19,0) -> 0.125
C17: 結束 | D17: =LOOKUP(2,1/(('0226 4度C'!$A:$A="新豐6線")*('0226 4度C'!$T:$T<>"")),'0226 4度C'!$T:$T) -> 0.80763889 | E17: =LOOKUP(2,1/(('0226 4度C'!$A:$A="新豐2線")*('0226 4度C'!$T:$T<>"")),'0226 4度C'!$T:$T) -> 0.43888889 | F17: =LOOKUP(2,1/(('0226 4度C'!$A:$A="新豐5線")*('0226 4度C'!$T:$T<>"")),'0226 4度C'!$T:$T) -> 0.83402778 | G17: =LOOKUP(2,1/(('0226 4度C'!$A:$A="新豐7線")*('0226 4度C'!$T:$T<>"")),'0226 4度C'!$T:$T) -> 0.82708333 | H17: =LOOKUP(2,1/(('0226 4度C'!$A:$A="新豐3線")*('0226 4度C'!$T:$T<>"")),'0226 4度C'!$T:$T) -> 0.625 | I17: =LOOKUP(2,1/(('0226 4度C'!$A:$A="新豐1線")*('0226 4度C'!$T:$T<>"")),'0226 4度C'!$T:$T) -> 0.83680556 | J17: =LOOKUP(2,1/(('0226 4度C'!$A:$A="新豐10線")*('0226 4度C'!$T:$T<>"")),'0226 4度C'!$T:$T) -> 0.39791667 | K17: =LOOKUP(2,1/(('0226 4度C'!$A:$A="新豐8線")*('0226 4度C'!$T:$T<>"")),'0226 4度C'!$T:$T) -> 0.50902778 | L17: =LOOKUP(2,1/(('0226 4度C'!$A:$A="新豐9線")*('0226 4度C'!$T:$T<>"")),'0226 4度C'!$T:$T) -> 0.49097222 | M17: =LOOKUP(2,1/(('0226 4度C'!$A:$A="新豐4線")*('0226 4度C'!$T:$T<>"")),'0226 4度C'!$T:$T) -> 0.47986111
B18: 產線異常 (5分鐘以上) | C18: 次數 | D18: =SUMIFS('0226 4度C'!$Y:$Y,'0226 4度C'!$A:$A,"新豐6線",'0226 4度C'!$B:$B,"平均") -> 0 | E18: =SUMIFS('0226 4度C'!$Y:$Y,'0226 4度C'!$A:$A,"新豐2線",'0226 4度C'!$B:$B,"平均") -> 0 | F18: =SUMIFS('0226 4度C'!$Y:$Y,'0226 4度C'!$A:$A,"新豐5線",'0226 4度C'!$B:$B,"平均") -> 0 | G18: =SUMIFS('0226 4度C'!$Y:$Y,'0226 4度C'!$A:$A,"新豐7線",'0226 4度C'!$B:$B,"平均") -> 0 | H18: =SUMIFS('0226 4度C'!$Y:$Y,'0226 4度C'!$A:$A,"新豐3線",'0226 4度C'!$B:$B,"平均") -> 0 | I18: =SUMIFS('0226 4度C'!$Y:$Y,'0226 4度C'!$A:$A,"新豐1線",'0226 4度C'!$B:$B,"平均") -> 0 | J18: =SUMIFS('0226 4度C'!$Y:$Y,'0226 4度C'!$A:$A,"新豐10線",'0226 4度C'!$B:$B,"平均") -> 0 | K18: =SUMIFS('0226 4度C'!$Y:$Y,'0226 4度C'!$A:$A,"新豐8線",'0226 4度C'!$B:$B,"平均") -> 0 | L18: =SUMIFS('0226 4度C'!$Y:$Y,'0226 4度C'!$A:$A,"新豐9線",'0226 4度C'!$B:$B,"平均") -> 0 | M18: =SUMIFS('0226 4度C'!$Y:$Y,'0226 4度C'!$A:$A,"新豐4線",'0226 4度C'!$B:$B,"平均") -> 0
