Workbook

Sheet 0531
B1: 屏榮 新豐廠組合室生產人時性分析
B3: 日期 | C3: =TEXT('0531 4度C'!A2,"yyyy.mm.ddaaaa") -> 2026.05.31星期日 | E3: 訂單量 | F3: ='0531 4度C'!D1 -> 207773 | H3: 營業額 | I3: ='0531 4度C'!F1 -> 7052754.7
B4: 人時性 | C4: 項目 | E4: ➀ | G4: ➁ | I4: ➂ | K4: 異常停線 | M4: 短暫停線
C5: 組合室 | E5: 全溫層 | G5: 4度C-各編組展開 | I5: ③三明治-各編組展開 | K5: 合計次數 | L5: 時間 | M5: 合計次數 | N5: 設備次數
C6: 排關平均 | E6: =AVERAGE(D13:M13) -> 153.31265 | F6: =AVERAGE(D31:O31,D13:J13) -> 159.82899 | G6: =AVERAGE(D13:J13) -> 159.82899 | I6: =AVERAGE(K13:M13) -> 138.10787 | K6: ='0531 4度C'!Y2 -> 0 | L6: ='0531 4度C'!Z2 -> 0 | M6: ='0531 4度C'!AC2 -> 62 | N6: ='0531 4度C'!AD2 -> 0
C7: 實績平均 | E7: =AVERAGE(D14:M14) -> 146.7097 | F7: =AVERAGE(D32:O32,D14:J14) -> 152.97717 | G7: =AVERAGE(D14:J14) -> 152.97717 | I7: =AVERAGE(K14:M14) -> 132.08561
C8: 達成率平均 | E8: =AVERAGE(D15:M15) -> 0.95676797 | F8: =AVERAGE(D15:J15,D33:O33) -> 0.9569517 | G8: =AVERAGE(D15:J15) -> 0.9569517 | I8: =AVERAGE(K15:M15) -> 0.95633926
K9: ※現行日本鮮食廠以達成率80%為基本(即為現行KPI)
B10: 溫層 | D10: ➁4度C-各編組展開 | K10: ③三明治-各編組展開
B11: 編組 | D11: 1 | E11: 2 | F11: 3 | G11: 4 | H11: 5 | I11: 6 | J11: 7 | K11: 1 | L11: 2 | M11: 3
D12: 新豐6線 | E12: 新豐2線 | F12: 新豐5線 | G12: 新豐7線 | H12: 新豐3線 | I12: 新豐1線 | J12: 新豐10線 | K12: 新豐8線 | L12: 新豐9線 | M12: 新豐4線
B13: 人時性 | C13: 排關 | D13: =SUMIFS('0531 4度C'!$K:$K,'0531 4度C'!$A:$A,"新豐6線",'0531 4度C'!$B:$B,"平均") -> 129.03226 | E13: =SUMIFS('0531 4度C'!$K:$K,'0531 4度C'!$A:$A,"新豐2線",'0531 4度C'!$B:$B,"平均") -> 85.227273 | F13: =SUMIFS('0531 4度C'!$K:$K,'0531 4度C'!$A:$A,"新豐5線",'0531 4度C'!$B:$B,"平均") -> 95.205479 | G13: =SUMIFS('0531 4度C'!$K:$K,'0531 4度C'!$A:$A,"新豐7線",'0531 4度C'!$B:$B,"平均") -> 125 | H13: =SUMIFS('0531 4度C'!$K:$K,'0531 4度C'!$A:$A,"新豐3線",'0531 4度C'!$B:$B,"平均") -> 255.81395 | I13: =SUMIFS('0531 4度C'!$K:$K,'0531 4度C'!$A:$A,"新豐1線",'0531 4度C'!$B:$B,"平均") -> 109.375 | J13: =SUMIFS('0531 4度C'!$K:$K,'0531 4度C'!$A:$A,"新豐10線",'0531 4度C'!$B:$B,"平均") -> 319.14894 | K13: =SUMIFS('0531 4度C'!$K:$K,'0531 4度C'!$A:$A,"新豐8線",'0531 4度C'!$B:$B,"平均") -> 137.70492 | L13: =SUMIFS('0531 4度C'!$K:$K,'0531 4度C'!$A:$A,"新豐9線",'0531 4度C'!$B:$B,"平均") -> 126.61871 | M13: =SUMIFS('0531 4度C'!$K:$K,'0531 4度C'!$A:$A,"新豐4線",'0531 4度C'!$B:$B,"平均") -> 150
C14: 實績 | D14: =SUMIFS('0531 4度C'!$N:$N,'0531 4度C'!$A:$A,"新豐6線",'0531 4度C'!$B:$B,"平均") -> 123.47451 | E14: =SUMIFS('0531 4度C'!$N:$N,'0531 4度C'!$A:$A,"新豐2線",'0531 4度C'!$B:$B,"平均") -> 81.393917 | F14: =SUMIFS('0531 4度C'!$N:$N,'0531 4度C'!$A:$A,"新豐5線",'0531 4度C'!$B:$B,"平均") -> 91.223383 | G14: =SUMIFS('0531 4度C'!$N:$N,'0531 4度C'!$A:$A,"新豐7線",'0531 4度C'!$B:$B,"平均") -> 119.41473 | H14: =SUMIFS('0531 4度C'!$N:$N,'0531 4度C'!$A:$A,"新豐3線",'0531 4度C'!$B:$B,"平均") -> 244.52157 | I14: =SUMIFS('0531 4度C'!$N:$N,'0531 4度C'!$A:$A,"新豐1線",'0531 4度C'!$B:$B,"平均") -> 104.859 | J14: =SUMIFS('0531 4度C'!$N:$N,'0531 4度C'!$A:$A,"新豐10線",'0531 4度C'!$B:$B,"平均") -> 305.95309 | K14: =SUMIFS('0531 4度C'!$N:$N,'0531 4度C'!$A:$A,"新豐8線",'0531 4度C'!$B:$B,"平均") -> 131.45684 | L14: =SUMIFS('0531 4度C'!$N:$N,'0531 4度C'!$A:$A,"新豐9線",'0531 4度C'!$B:$B,"平均") -> 121.08052 | M14: =SUMIFS('0531 4度C'!$N:$N,'0531 4度C'!$A:$A,"新豐4線",'0531 4度C'!$B:$B,"平均") -> 143.71947
C15: 達成率 | D15: =D14/D13 -> 0.95692748 | E15: =E14/E13 -> 0.95502196 | F15: =F14/F13 -> 0.95817367 | G15: =G14/G13 -> 0.95531783 | H15: =H14/H13 -> 0.95585705 | I15: =I14/I13 -> 0.95871088 | J15: =J14/J13 -> 0.95865302 | K15: =K14/K13 -> 0.95462703 | ... M15: =M14/M13 -> 0.95812981
B16: 作業 時間 | C16: 開始 | D16: =VLOOKUP("新豐6線",'0531 4度C'!$A:$T,19,0) -> 0.70833333 | E16: =VLOOKUP("新豐2線",'0531 4度C'!$A:$T,19,0) -> 0.083333333 | F16: =VLOOKUP("新豐5線",'0531 4度C'!$A:$T,19,0) -> 0.20833333 | G16: =VLOOKUP("新豐7線",'0531 4度C'!$A:$T,19,0) -> 0.20833333 | H16: =VLOOKUP("新豐3線",'0531 4度C'!$A:$T,19,0) -> 0.083333333 | I16: =VLOOKUP("新豐1線",'0531 4度C'!$A:$T,19,0) -> 0.20833333 | J16: =VLOOKUP("新豐10線",'0531 4度C'!$A:$T,19,0) -> 0.20833333 | K16: =VLOOKUP("新豐8線",'0531 4度C'!$A:$T,19,0) -> 0.083333333 | L16: =VLOOKUP("新豐9線",'0531 4度C'!$A:$T,19,0) -> 0.083333333 | M16: =VLOOKUP("新豐4線",'0531 4度C'!$A:$T,19,0) -> 0.083333333
C17: 結束 | D17: =LOOKUP(2,1/(('0531 4度C'!$A:$A="新豐6線")*('0531 4度C'!$T:$T<>"")),'0531 4度C'!$T:$T) -> 0.90138889 | E17: =LOOKUP(2,1/(('0531 4度C'!$A:$A="新豐2線")*('0531 4度C'!$T:$T<>"")),'0531 4度C'!$T:$T) -> 0.7375 | F17: =LOOKUP(2,1/(('0531 4度C'!$A:$A="新豐5線")*('0531 4度C'!$T:$T<>"")),'0531 4度C'!$T:$T) -> 0.83263889 | G17: =LOOKUP(2,1/(('0531 4度C'!$A:$A="新豐7線")*('0531 4度C'!$T:$T<>"")),'0531 4度C'!$T:$T) -> 0.80138889 | H17: =LOOKUP(2,1/(('0531 4度C'!$A:$A="新豐3線")*('0531 4度C'!$T:$T<>"")),'0531 4度C'!$T:$T) -> 0.44375 | I17: =LOOKUP(2,1/(('0531 4度C'!$A:$A="新豐1線")*('0531 4度C'!$T:$T<>"")),'0531 4度C'!$T:$T) -> 0.84722222 | J17: =LOOKUP(2,1/(('0531 4度C'!$A:$A="新豐10線")*('0531 4度C'!$T:$T<>"")),'0531 4度C'!$T:$T) -> 0.41666667 | K17: =LOOKUP(2,1/(('0531 4度C'!$A:$A="新豐8線")*('0531 4度C'!$T:$T<>"")),'0531 4度C'!$T:$T) -> 0.77222222 | L17: =LOOKUP(2,1/(('0531 4度C'!$A:$A="新豐9線")*('0531 4度C'!$T:$T<>"")),'0531 4度C'!$T:$T) -> 0.77361111 | M17: =LOOKUP(2,1/(('0531 4度C'!$A:$A="新豐4線")*('0531 4度C'!$T:$T<>"")),'0531 4度C'!$T:$T) -> 0.75833333
B18: 產線異常 (5分鐘以上) | C18: 次數 | D18: =SUMIFS('0531 4度C'!$Y:$Y,'0531 4度C'!$A:$A,"新豐6線",'0531 4度C'!$B:$B,"平均") -> 0 | E18: =SUMIFS('0531 4度C'!$Y:$Y,'0531 4度C'!$A:$A,"新豐2線",'0531 4度C'!$B:$B,"平均") -> 0 | F18: =SUMIFS('0531 4度C'!$Y:$Y,'0531 4度C'!$A:$A,"新豐5線",'0531 4度C'!$B:$B,"平均") -> 0 | G18: =SUMIFS('0531 4度C'!$Y:$Y,'0531 4度C'!$A:$A,"新豐7線",'0531 4度C'!$B:$B,"平均") -> 0 | H18: =SUMIFS('0531 4度C'!$Y:$Y,'0531 4度C'!$A:$A,"新豐3線",'0531 4度C'!$B:$B,"平均") -> 0 | I18: =SUMIFS('0531 4度C'!$Y:$Y,'0531 4度C'!$A:$A,"新豐1線",'0531 4度C'!$B:$B,"平均") -> 0 | J18: =SUMIFS('0531 4度C'!$Y:$Y,'0531 4度C'!$A:$A,"新豐10線",'0531 4度C'!$B:$B,"平均") -> 0 | K18: =SUMIFS('0531 4度C'!$Y:$Y,'0531 4度C'!$A:$A,"新豐8線",'0531 4度C'!$B:$B,"平均") -> 0 | L18: =SUMIFS('0531 4度C'!$Y:$Y,'0531 4度C'!$A:$A,"新豐9線",'0531 4度C'!$B:$B,"平均") -> 0 | M18: =SUMIFS('0531 4度C'!$Y:$Y,'0531 4度C'!$A:$A,"新豐4線",'0531 4度C'!$B:$B,"平均") -> 0
C19: 時間/分 | D19: =SUMIFS('0531 4度C'!$Z:$Z,'0531 4度C'!$A:$A,"新豐6線",'0531 4度C'!$B:$B,"平均") -> 0 | E19: =SUMIFS('0531 4度C'!$Z:$Z,'0531 4度C'!$A:$A,"新豐2線",'0531 4度C'!$B:$B,"平均") -> 0 | F19: =SUMIFS('0531 4度C'!$Z:$Z,'0531 4度C'!$A:$A,"新豐5線",'0531 4度C'!$B:$B,"平均") -> 0 | G19: =SUMIFS('0531 4度C'!$Z:$Z,'0531 4度C'!$A:$A,"新豐7線",'0531 4度C'!$B:$B,"平均") -> 0 | H19: =SUMIFS('0531 4度C'!$Z:$Z,'0531 4度C'!$A:$A,"新豐3線",'0531 4度C'!$B:$B,"平均") -> 0 | I19: =SUMIFS('0531 4度C'!$Z:$Z,'0531 4度C'!$A:$A,"新豐1線",'0531 4度C'!$B:$B,"平均") -> 0 | J19: =SUMIFS('0531 4度C'!$Z:$Z,'0531 4度C'!$A:$A,"新豐10線",'0531 4度C'!$B:$B,"平均") -> 0 | K19: =SUMIFS('0531 4度C'!$Z:$Z,'0531 4度C'!$A:$A,"新豐8線",'0531 4度C'!$B:$B,"平均") -> 0 | L19: =SUMIFS('0531 4度C'!$Z:$Z,'0531 4度C'!$A:$A,"新豐9線",'0531 4度C'!$B:$B,"平均") -> 0 | M19: =SUMIFS('0531 4度C'!$Z:$Z,'0531 4度C'!$A:$A,"新豐4線",'0531 4度C'!$B:$B,"平均") -> 0
B20: 短暫停線 (5分鐘以下) | C20: 次數 | D20: =SUMIFS('0531 4度C'!$AC:$AC,'0531 4度C'!$A:$A,"新豐6線",'0531 4度C'!$B:$B,"平均") -> 4 | E20: =SUMIFS('0531 4度C'!$AC:$AC,'0531 4度C'!$A:$A,"新豐2線",'0531 4度C'!$B:$B,"平均") -> 5 | F20: =SUMIFS('0531 4度C'!$AC:$AC,'0531 4度C'!$A:$A,"新豐5線",'0531 4度C'!$B:$B,"平均") -> 8 | G20: =SUMIFS('0531 4度C'!$AC:$AC,'0531 4度C'!$A:$A,"新豐7線",'0531 4度C'!$B:$B,"平均") -> 6 | H20: =SUMIFS('0531 4度C'!$AC:$AC,'0531 4度C'!$A:$A,"新豐3線",'0531 4度C'!$B:$B,"平均") -> 4 | I20: =SUMIFS('0531 4度C'!$AC:$AC,'0531 4度C'!$A:$A,"新豐1線",'0531 4度C'!$B:$B,"平均") -> 7 | J20: =SUMIFS('0531 4度C'!$AC:$AC,'0531 4度C'!$A:$A,"新豐10線",'0531 4度C'!$B:$B,"平均") -> 5 | K20: =SUMIFS('0531 4度C'!$AC:$AC,'0531 4度C'!$A:$A,"新豐8線",'0531 4度C'!$B:$B,"平均") -> 7 | L20: =SUMIFS('0531 4度C'!$AC:$AC,'0531 4度C'!$A:$A,"新豐9線",'0531 4度C'!$B:$B,"平均") -> 8 | M20: =SUMIFS('0531 4度C'!$AC:$AC,'0531 4度C'!$A:$A,"新豐4線",'0531 4度C'!$B:$B,"平均") -> 8
C21: 設備次數 | D21: =SUMIFS('0531 4度C'!$AD:$AD,'0531 4度C'!$A:$A,"新豐6線",'0531 4度C'!$B:$B,"平均") -> 0 | E21: =SUMIFS('0531 4度C'!$AD:$AD,'0531 4度C'!$A:$A,"新豐2線",'0531 4度C'!$B:$B,"平均") -> 0 | F21: =SUMIFS('0531 4度C'!$AD:$AD,'0531 4度C'!$A:$A,"新豐5線",'0531 4度C'!$B:$B,"平均") -> 0 | G21: =SUMIFS('0531 4度C'!$AD:$AD,'0531 4度C'!$A:$A,"新豐7線",'0531 4度C'!$B:$B,"平均") -> 0 | H21: =SUMIFS('0531 4度C'!$AD:$AD,'0531 4度C'!$A:$A,"新豐3線",'0531 4度C'!$B:$B,"平均") -> 0 | I21: =SUMIFS('0531 4度C'!$AD:$AD,'0531 4度C'!$A:$A,"新豐1線",'0531 4度C'!$B:$B,"平均") -> 0 | J21: =SUMIFS('0531 4度C'!$AD:$AD,'0531 4度C'!$A:$A,"新豐10線",'0531 4度C'!$B:$B,"平均") -> 0 | K21: =SUMIFS('0531 4度C'!$AD:$AD,'0531 4度C'!$A:$A,"新豐8線",'0531 4度C'!$B:$B,"平均") -> 0 | L21: =SUMIFS('0531 4度C'!$AD:$AD,'0531 4度C'!$A:$A,"新豐9線",'0531 4度C'!$B:$B,"平均") -> 0 | M21: =SUMIFS('0531 4度C'!$AD:$AD,'0531 4度C'!$A:$A,"新豐4線",'0531 4度C'!$B:$B,"平均") -> 0
B22: 配置人數 | D22: =SUMIFS('0531 4度C'!$I:$I,'0531 4度C'!$A:$A,"新豐6線",'0531 4度C'!$B:$B,"平均") -> 15.5 | E22: =SUMIFS('0531 4度C'!$I:$I,'0531 4度C'!$A:$A,"新豐2線",'0531 4度C'!$B:$B,"平均") -> 17.6 | F22: =SUMIFS('0531 4度C'!$I:$I,'0531 4度C'!$A:$A,"新豐5線",'0531 4度C'!$B:$B,"平均") -> 18.25 | G22: =SUMIFS('0531 4度C'!$I:$I,'0531 4度C'!$A:$A,"新豐7線",'0531 4度C'!$B:$B,"平均") -> 15.333333 | H22: =SUMIFS('0531 4度C'!$I:$I,'0531 4度C'!$A:$A,"新豐3線",'0531 4度C'!$B:$B,"平均") -> 10.75 | I22: =SUMIFS('0531 4度C'!$I:$I,'0531 4度C'!$A:$A,"新豐1線",'0531 4度C'!$B:$B,"平均") -> 18.285714 | J22: =SUMIFS('0531 4度C'!$I:$I,'0531 4度C'!$A:$A,"新豐10線",'0531 4度C'!$B:$B,"平均") -> 9.4 | K22: =SUMIFS('0531 4度C'!$I:$I,'0531 4度C'!$A:$A,"新豐8線",'0531 4度C'!$B:$B,"平均") -> 17.428571 | L22: =SUMIFS('0531 4度C'!$I:$I,'0531 4度C'!$A:$A,"新豐9線",'0531 4度C'!$B:$B,"平均") -> 17.375 | M22: =SUMIFS('0531 4度C'!$I:$I,'0531 4度C'!$A:$A,"新豐4線",'0531 4度C'!$B:$B,"平均") -> 16
B23: 主要應用設備 | D23: ET-55 | E23: 熱縮爐 | F23: L型包裝機 | G23: L型包裝機 | H23: 伺服包裝機 | I23: ET-55 | J23: 伺服包裝機 | K23: 三明治包裝機 | L23: 三明治包裝機 | M23: 三明治包裝機
B24: 次要應用設備 | F24: 圓盤機 | G24: ET-55
B25: 備註 | E25: 握沙拉 | F25: 共用L型包裝機 | H25: 調理麵包 | I25: 炒飯+沙拉 | J25: 調理麵包

Sheet 0531 4度C
A1: 新豐廠四度C日報分析 | C1: 總生產量 | D1: =SUM(F5:F76) -> 207773 | E1: 營業額 | F1: =SUM(G5:G76) -> 7052754.7 | G1: 出勤人數 | H1: =L9+L15+L53+L61+L24+L67+L39+L48+L31+L76 -> 155.92262 | I1: 產線配置圖 | L1: 生產實績 | O1: 人時性差異分析 | S1: 日報登錄 | Y1: 合計 次數 | Z1: 合計 時間/分 | AA1: 產線異常 分析說明(5分鐘以上) | AC1: 合計 次數 | AD1: 合計 設備次數 | AE1: 產能差異分析
A2: 46173 | B2: 星期日 | C2: 人時性 | D2: =AVERAGE(N9,N15,N53,N61,N24,N67,N31,N39,N48,N76) -> 146.7097 | E2: 平均廠價 | F2: =F1/D1 -> 33.94452 | G2: 多次生產數 | H2: =COUNT(H5:H76) -> 14 | Y2: =SUM(Y9+Y15+Y24+Y31+Y39+Y48+Y53+Y61+Y67+Y76) -> 0 | Z2: =SUM(Z9+Z15+Z24+Z31+Z39+Z48+Z53+Z61+Z67+Z76) -> 0 | AC2: 62 | AD2: =SUM(AD9+AD15+AD24+AD31+AD39+AD48+AD53+AD61+AD67+AD76) -> 0
A3: 線別 | B3: 品類 | C3: 品名 | E3: 廠價 | F3: 生產量 | G3: 營收 | H3: 多次 生產 | I3: 人數 | J3: 產能/時 | K3: 人時性 | L3: 人數 | M3: 產能/時 | N3: 人時性 | O3: 人數 | P3: 人時性 | Q3: 達成率 | R3: 達成率平均 | S3: 生產時間 | U3: 換線、休息/分 | V3: 稼動時間/分 | W3: 休息時間 | Y3: 產線異常統計 (5分鐘以上) | AA3: (新豐回填) | AC3: 短暫停線統計 (5分鐘以下) | AE3: 產能/時 | AF3: 達成率 | AG3: 達成率平均
S4: 開始 | T4: 結束 | W4: 開始 | X4: 結束 | Y4: 次數 | Z4: 時間/分 | AC4: 總次數 | AD4: 設備因素(次數)
A5: 新豐6線 | B5: 微波主食 | C5: 二配泰式綠咖哩雞 | E5: 50.67 | F5: 1765 | G5: =E5*F5 -> 89432.55 | I5: 15 | J5: 2000 | K5: =J5/I5 -> 133.33333 | L5: 15 | M5: =F5/V5*60 -> 1925.4545 | N5: =M5/L5 -> 128.36364 | O5: =L5-I5 -> 0 | P5: =N5-K5 -> -4.969697 | Q5: =N5/K5 -> 0.96272727 | R5: =Q9 -> 0.95692748 | S5: 0.70833333 | T5: 0.74652778 | V5: =(T5-S5)*24*60 -> 55 | AC5: 4 | AE5: =M5-J5 -> -74.545455 | AF5: =M5/J5 -> 0.96272727 | AG5: =AF9 -> 0.95692748
A6: 新豐6線 | B6: 微波主食 | C6: 二配金咖哩果香甘口咖哩飯 | E6: 50.92 | F6: 2364 | G6: =E6*F6 -> 120374.88 | I6: 15 | J6: 2000 | K6: =J6/I6 -> 133.33333 | L6: 15 | M6: =F6/V6*60 -> 1916.7568 | N6: =M6/L6 -> 127.78378 | O6: =L6-I6 -> 0 | P6: =N6-K6 -> -5.5495495 | Q6: =N6/K6 -> 0.95837838 | S6: 0.75069444 | T6: 0.80208333 | U6: =IF(S6=TIME(17,0,0),"",(S6-T5)*24*60) -> 6 | V6: =(T6-S6)*24*60 -> 74 | AE6: =M6-J6 -> -83.243243 | AF6: =M6/J6 -> 0.95837838
A7: 新豐6線 | B7: 微波主食 | C7: 二配金咖哩濃厚辛口咖哩飯 | E7: 50.98 | F7: 1400 | G7: =E7*F7 -> 71372 | H7: 2 | I7: 16 | J7: 2000 | K7: =J7/I7 -> 125 | L7: 16 | M7: =F7/V7*60 -> 1909.0909 | N7: =M7/L7 -> 119.31818 | O7: =L7-I7 -> 0 | P7: =N7-K7 -> -5.6818182 | Q7: =N7/K7 -> 0.95454545 | S7: 0.80625 | T7: 0.83680556 | U7: =IF(S7=TIME(17,0,0),"",(S7-T6)*24*60) -> 6 | V7: =(T7-S7)*24*60 -> 44 | W7: =T7 -> 0.83680556 | X7: =S8 -> 0.87777778 | AE7: =M7-J7 -> -90.909091 | AF7: =M7/J7 -> 0.95454545
A8: 新豐6線 | B8: 微波主食 | C8: 二配金咖哩濃厚辛口咖哩飯 | E8: 50.98 | F8: 1079 | G8: =E8*F8 -> 55007.42 | I8: 16 | J8: 2000 | K8: =J8/I8 -> 125 | L8: 16 | M8: =F8/V8*60 -> 1904.1176 | N8: =M8/L8 -> 119.00735 | O8: =L8-I8 -> 0 | P8: =N8-K8 -> -5.9926471 | Q8: =N8/K8 -> 0.95205882 | S8: 0.87777778 | T8: 0.90138889 | U8: =IF(S8=TIME(17,0,0),"",(S8-T7)*24*60) -> 59 | V8: =(T8-S8)*24*60 -> 34 | AE8: =M8-J8 -> -95.882353 | AF8: =M8/J8 -> 0.95205882
A9: 新豐6線 | B9: 平均 | I9: 15.5 | J9: 2000 | K9: =J9/I9 -> 129.03226 | L9: 15.5 | M9: =AVERAGE(M5:M8) -> 1913.855 | N9: =M9/L9 -> 123.47451 | O9: =L9-I9 -> 0 | P9: =N9-K9 -> -5.5577442 | Q9: =N9/K9 -> 0.95692748 | Y9: =SUM(Y5:Y8) -> 0 | Z9: =SUM(Z5:Z8) -> 0 | AC9: 4 | AD9: =SUM(AD5:AD8) -> 0 | AE9: =M9-J9 -> -86.145035 | AF9: =M9/J9 -> 0.95692748
A10: 新豐2線 | B10: 沙拉 | C10: 青醬優格雞肉握沙拉(113年) | E10: 39.62 | F10: 3600 | G10: =E10*F10 -> 142632 | H10: 2 | I10: 19 | J10: 1500 | K10: =J10/I10 -> 78.947368 | L10: 19 | M10: =F10/V10*60 -> 1430.4636 | N10: =M10/L10 -> 75.287557 | O10: =L10-I10 -> 0 | P10: =N10-K10 -> -3.6598118 | Q10: =N10/K10 -> 0.95364238 | R10: =Q15 -> 0.95502196 | S10: 0.083333333 | T10: 0.18819444 | V10: =(T10-S10)*24*60 -> 151 | W10: =T10 -> 0.18819444 | X10: =S11 -> 0.20833333 | AC10: 5 | AE10: =M10-J10 -> -69.536424 | AF10: =M10/J10 -> 0.95364238 | AG10: =AF15 -> 0.95502196
A11: 新豐2線 | B11: 沙拉 | C11: 青檸烤雞握沙拉(113年) | E11: 39.8 | F11: 5200 | G11: =E11*F11 -> 206960 | H11: 2 | I11: 17 | J11: 1500 | K11: =J11/I11 -> 88.235294 | L11: 17 | M11: =F11/V11*60 -> 1431.1927 | N11: =M11/L11 -> 84.187804 | O11: =L11-I11 -> 0 | P11: =N11-K11 -> -4.0474906 | Q11: =N11/K11 -> 0.95412844 | S11: 0.20833333 | T11: 0.35972222 | U11: =IF(S11=TIME(17,0,0),"",(S11-T10)*24*60) -> 29 | V11: =(T11-S11)*24*60 -> 218 | AE11: =M11-J11 -> -68.807339 | AF11: =M11/J11 -> 0.95412844
A12: 新豐2線 | B12: 沙拉 | C12: 厚蛋時蔬握沙拉 | E12: 39.46 | F12: 4700 | G12: =E12*F12 -> 185462 | H12: 2 | I12: 16 | J12: 1500 | K12: =J12/I12 -> 93.75 | L12: 16 | M12: =F12/V12*60 -> 1431.4721 | N12: =M12/L12 -> 89.467005 | O12: =L12-I12 -> 0 | P12: =N12-K12 -> -4.2829949 | Q12: =N12/K12 -> 0.95431472 | S12: 0.36527778 | T12: 0.50208333 | U12: =IF(S12=TIME(17,0,0),"",(S12-T11)*24*60) -> 8 | V12: =(T12-S12)*24*60 -> 197 | W12: =T12 -> 0.50208333 | X12: =S13 -> 0.54097222 | AE12: =M12-J12 -> -68.527919 | AF12: =M12/J12 -> 0.95431472
A13: 新豐2線 | B13: 沙拉 | C13: 青檸烤雞握沙拉(113年) | E13: 39.8 | F13: 3902 | G13: =E13*F13 -> 155299.6 | I13: 17 | J13: 1500 | K13: =J13/I13 -> 88.235294 | L13: 17 | M13: =F13/V13*60 -> 1436.319 | N13: =M13/L13 -> 84.489354 | O13: =L13-I13 -> 0 | P13: =N13-K13 -> -3.7459401 | Q13: =N13/K13 -> 0.95754601 | S13: 0.54097222 | T13: 0.65416667 | U13: =IF(S13=TIME(17,0,0),"",(S13-T12)*24*60) -> 56 | V13: =(T13-S13)*24*60 -> 163 | AE13: =M13-J13 -> -63.680982 | AF13: =M13/J13 -> 0.95754601
A14: 新豐2線 | B14: 沙拉 | C14: 青醬優格雞肉握沙拉(113年) | E14: 39.62 | F14: 2747 | G14: =E14*F14 -> 108836.14 | I14: 19 | J14: 1500 | K14: =J14/I14 -> 78.947368 | L14: 19 | M14: =F14/V14*60 -> 1433.2174 | N14: =M14/L14 -> 75.432494 | O14: =L14-I14 -> 0 | P14: =N14-K14 -> -3.5148741 | Q14: =N14/K14 -> 0.95547826 | S14: 0.65763889 | T14: 0.7375 | U14: =IF(S14=TIME(17,0,0),"",(S14-T13)*24*60) -> 5 | V14: =(T14-S14)*24*60 -> 115 | AE14: =M14-J14 -> -66.782609 | AF14: =M14/J14 -> 0.95547826
A15: 新豐2線 | B15: 平均 | I15: 17.6 | J15: 1500 | K15: =J15/I15 -> 85.227273 | L15: 17.6 | M15: =AVERAGE(M10:M14) -> 1432.5329 | N15: =M15/L15 -> 81.393917 | O15: =L15-I15 -> 0 | P15: =N15-K15 -> -3.8333554 | Q15: =N15/K15 -> 0.95502196 | Y15: =SUM(Y10:Y14) -> 0 | Z15: =SUM(Z10:Z14) -> 0 | AC15: 5 | AD15: =SUM(AD10:AD14) -> 0 | AE15: =M15-J15 -> -67.467054 | AF15: =M15/J15 -> 0.95502196
A16: 新豐5線 | B16: 小吃 | C16: 剝皮辣椒雞湯 | E16: 41 | F16: 1892 | G16: =E16*F16 -> 77572 | I16: 26 | J16: 1500 | K16: =J16/I16 -> 57.692308 | L16: 26 | M16: =F16/V16*60 -> 1436.962 | N16: =M16/L16 -> 55.26777 | O16: =L16-I16 -> 0 | P16: =N16-K16 -> -2.4245375 | Q16: =N16/K16 -> 0.95797468 | R16: =Q24 -> 0.95817367 | S16: 0.20833333 | T16: 0.26319444 | V16: =(T16-S16)*24*60 -> 79 | AC16: 8 | AE16: =M16-J16 -> -63.037975 | AF16: =M16/J16 -> 0.95797468 | AG16: =AF24 -> 0.95817367
A17: 新豐5線 | B17: 小吃 | C17: 香菇雞燉湯 | E17: 38.62 | F17: 2205 | G17: =E17*F17 -> 85157.1 | I17: 24 | J17: 1500 | K17: =J17/I17 -> 62.5 | L17: 24 | M17: =F17/V17*60 -> 1438.0435 | N17: =M17/L17 -> 59.918478 | O17: =L17-I17 -> 0 | P17: =N17-K17 -> -2.5815217 | Q17: =N17/K17 -> 0.95869565 | S17: 0.26875 | T17: 0.33263889 | U17: =IF(S17=TIME(17,0,0),"",(S17-T16)*24*60) -> 8 | V17: =(T17-S17)*24*60 -> 92 | AE17: =M17-J17 -> -61.956522 | AF17: =M17/J17 -> 0.95869565
A18: 新豐5線 | B18: 微波主食 | C18: 香菇雞粥 | E18: 37.03 | F18: 3836 | G18: =E18*F18 -> 142047.08 | I18: 13 | J18: 1500 | K18: =J18/I18 -> 115.38462 | L18: 13 | M18: =F18/V18*60 -> 1429.5652 | N18: =M18/L18 -> 109.96656 | O18: =L18-I18 -> 0 | P18: =N18-K18 -> -5.4180602 | Q18: =N18/K18 -> 0.95304348 | S18: 0.3375 | T18: 0.44930556 | U18: =IF(S18=TIME(17,0,0),"",(S18-T17)*24*60) -> 7 | V18: =(T18-S18)*24*60 -> 161 | AE18: =M18-J18 -> -70.434783 | AF18: =M18/J18 -> 0.95304348
A19: 新豐5線 | B19: 沙拉 | C19: 厚蛋時蔬握沙拉 | E19: 39.46 | F19: 2053 | G19: =E19*F19 -> 81011.38 | I19: 16 | J19: 1500 | K19: =J19/I19 -> 93.75 | L19: 16 | M19: =F19/V19*60 -> 1432.3256 | N19: =M19/L19 -> 89.520349 | O19: =L19-I19 -> 0 | P19: =N19-K19 -> -4.2296512 | Q19: =N19/K19 -> 0.95488372 | S19: 0.45277778 | T19: 0.5125 | U19: =IF(S19=TIME(17,0,0),"",(S19-T18)*24*60) -> 5 | V19: =(T19-S19)*24*60 -> 86 | W19: =T19 -> 0.5125 | X19: =S20 -> 0.55277778 | AE19: =M19-J19 -> -67.674419 | AF19: =M19/J19 -> 0.95488372
A20: 新豐5線 | B20: 三明治 | C20: 茄汁厚起司三明治 | E20: 25.99 | F20: 1690 | G20: =E20*F20 -> 43923.1 | I20: 18 | J20: 2400 | K20: =J20/I20 -> 133.33333 | L20: 18 | M20: =F20/V20*60 -> 2304.5455 | N20: =M20/L20 -> 128.0303 | O20: =L20-I20 -> 0 | P20: =N20-K20 -> -5.3030303 | Q20: =N20/K20 -> 0.96022727 | S20: 0.55277778 | T20: 0.58333333 | U20: =IF(S20=TIME(17,0,0),"",(S20-T19)*24*60) -> 58 | V20: =(T20-S20)*24*60 -> 44 | AE20: =M20-J20 -> -95.454545 | AF20: =M20/J20 -> 0.96022727
A21: 新豐5線 | B21: 微波主食 | C21: 二配起司控培根白醬焗烤飯 | E21: 53.68 | F21: 1386 | G21: =E21*F21 -> 74400.48 | I21: 16 | J21: 1500 | K21: =J21/I21 -> 93.75 | L21: 16 | M21: =F21/V21*60 -> 1433.7931 | N21: =M21/L21 -> 89.612069 | O21: =L21-I21 -> 0 | P21: =N21-K21 -> -4.137931 | Q21: =N21/K21 -> 0.95586207 | S21: 0.70833333 | T21: 0.74861111 | U21: =IF(S21=TIME(17,0,0),"",(S21-T20)*24*60) | V21: =(T21-S21)*24*60 -> 58 | AE21: =M21-J21 -> -66.206897 | AF21: =M21/J21 -> 0.95586207
A22: 新豐5線 | B22: 微波主食 | C22: 二配蔥爆牛肉燴飯 | E22: 52.86 | F22: 1679 | G22: =E22*F22 -> 88751.94 | I22: 16 | J22: 2000 | K22: =J22/I22 -> 125 | L22: 16 | M22: =F22/V22*60 -> 1937.3077 | N22: =M22/L22 -> 121.08173 | O22: =L22-I22 -> 0 | P22: =N22-K22 -> -3.9182692 | Q22: =N22/K22 -> 0.96865385 | S22: 0.75277778 | T22: 0.78888889 | U22: =IF(S22=TIME(17,0,0),"",(S22-T21)*24*60) -> 6 | V22: =(T22-S22)*24*60 -> 52 | AE22: =M22-J22 -> -62.692308 | AF22: =M22/J22 -> 0.96865385
A23: 新豐5線 | B23: 微波主食 | C23: 二配港式香滑嫩蛋牛肉燴飯 | E23: 50.67 | F23: 1779 | G23: =E23*F23 -> 90141.93 | I23: 17 | J23: 2000 | K23: =J23/I23 -> 117.64706 | L23: 17 | M23: =F23/V23*60 -> 1906.0714 | N23: =M23/L23 -> 112.12185 | O23: =L23-I23 -> 0 | P23: =N23-K23 -> -5.5252101 | Q23: =N23/K23 -> 0.95303571 | S23: 0.79375 | T23: 0.83263889 | U23: =IF(S23=TIME(17,0,0),"",(S23-T22)*24*60) -> 7 | V23: =(T23-S23)*24*60 -> 56 | AE23: =M23-J23 -> -93.928571 | AF23: =M23/J23 -> 0.95303571
A24: 新豐5線 | B24: 平均 | I24: 18.25 | J24: 1737.5 | K24: =J24/I24 -> 95.205479 | L24: 18.25 | M24: =AVERAGE(M16:M23) -> 1664.8267 | N24: =M24/L24 -> 91.223383 | O24: =L24-I24 -> 0 | P24: =N24-K24 -> -3.982096 | Q24: =N24/K24 -> 0.95817367 | Y24: =SUM(Y16:Y23) -> 0 | Z24: =SUM(Z16:Z23) -> 0 | AC24: 8 | AD24: =SUM(AD16:AD23) -> 0 | AE24: =M24-J24 -> -72.673252 | AF24: =M24/J24 -> 0.95817367
A25: 新豐7線 | B25: 微波主食 | C25: 韓式燒肉拌飯 | E25: 54.09 | F25: 1908 | G25: =E25*F25 -> 103203.72 | I25: 17 | J25: 1500 | K25: =J25/I25 -> 88.235294 | L25: 17 | M25: =F25/V25*60 -> 1431 | N25: =M25/L25 -> 84.176471 | O25: =L25-I25 -> 0 | P25: =N25-K25 -> -4.0588235 | Q25: =N25/K25 -> 0.954 | R25: =Q31 -> 0.95531783 | S25: 0.20833333 | T25: 0.26388889 | V25: =(T25-S25)*24*60 -> 80 | AC25: 6 | AE25: =M25-J25 -> -69 | AF25: =M25/J25 -> 0.954 | AG25: =AF31 -> 0.95531783
A26: 新豐7線 | B26: 微波主食 | C26: 韓式泡菜豬肉豆腐丼飯 | E26: 50.67 | F26: 2379 | G26: =E26*F26 -> 120543.93 | I26: 17 | J26: 2000 | K26: =J26/I26 -> 117.64706 | L26: 17 | M26: =F26/V26*60 -> 1903.2 | N26: =M26/L26 -> 111.95294 | O26: =L26-I26 -> 0 | P26: =N26-K26 -> -5.6941176 | Q26: =N26/K26 -> 0.9516 | S26: 0.26944444 | T26: 0.32152778 | U26: =IF(S26=TIME(17,0,0),"",(S26-T25)*24*60) -> 8 | V26: =(T26-S26)*24*60 -> 75 | AE26: =M26-J26 -> -96.8 | AF26: =M26/J26 -> 0.9516
A27: 新豐7線 | B27: 微波主食 | C27: 鐵板滑蛋炸豬排丼 | E27: 57.73 | F27: 2721 | G27: =E27*F27 -> 157083.33 | I27: 14 | J27: 2000 | K27: =J27/I27 -> 142.85714 | L27: 14 | M27: =F27/V27*60 -> 1920.7059 | N27: =M27/L27 -> 137.19328 | O27: =L27-I27 -> 0 | P27: =N27-K27 -> -5.6638655 | Q27: =N27/K27 -> 0.96035294 | S27: 0.325 | T27: 0.38402778 | U27: =IF(S27=TIME(17,0,0),"",(S27-T26)*24*60) -> 5 | V27: =(T27-S27)*24*60 -> 85 | AE27: =M27-J27 -> -79.294118 | AF27: =M27/J27 -> 0.96035294
A28: 新豐7線 | B28: 微波主食 | C28: 日式炙烤親子丼 | E28: 53.27 | F28: 2334 | G28: =E28*F28 -> 124332.18 | I28: 16 | J28: 2000 | K28: =J28/I28 -> 125 | L28: 16 | M28: =F28/V28*60 -> 1918.3562 | N28: =M28/L28 -> 119.89726 | O28: =L28-I28 -> 0 | P28: =N28-K28 -> -5.1027397 | Q28: =N28/K28 -> 0.95917808 | S28: 0.38888889 | T28: 0.43958333 | U28: =IF(S28=TIME(17,0,0),"",(S28-T27)*24*60) -> 7 | V28: =(T28-S28)*24*60 -> 73 | AE28: =M28-J28 -> -81.643836 | AF28: =M28/J28 -> 0.95917808
A29: 新豐7線 | B29: 微波主食 | C29: 二配川味麻婆燒豆腐燴飯 | E29: 50.49 | F29: 2162 | G29: =E29*F29 -> 109159.38 | I29: 15 | J29: 2000 | K29: =J29/I29 -> 133.33333 | L29: 15 | M29: =F29/V29*60 -> 1907.6471 | N29: =M29/L29 -> 127.17647 | O29: =L29-I29 -> 0 | P29: =N29-K29 -> -6.1568627 | Q29: =N29/K29 -> 0.95382353 | S29: 0.70833333 | T29: 0.75555556 | U29: =IF(S29=TIME(17,0,0),"",(S29-T28)*24*60) | V29: =(T29-S29)*24*60 -> 68 | AE29: =M29-J29 -> -92.352941 | AF29: =M29/J29 -> 0.95382353
A30: 新豐7線 | B30: 微波主食 | C30: 二配厚香料優格咖哩雞排飯 | E30: 56.43 | F30: 1937 | G30: =E30*F30 -> 109304.91 | I30: 13 | J30: 2000 | K30: =J30/I30 -> 153.84615 | L30: 13 | M30: =F30/V30*60 -> 1905.2459 | N30: =M30/L30 -> 146.55738 | O30: =L30-I30 -> 0 | P30: =N30-K30 -> -7.2887768 | Q30: =N30/K30 -> 0.95262295 | S30: 0.75902778 | T30: 0.80138889 | U30: =IF(S30=TIME(17,0,0),"",(S30-T29)*24*60) -> 5 | V30: =(T30-S30)*24*60 -> 61 | AE30: =M30-J30 -> -94.754098 | AF30: =M30/J30 -> 0.95262295
A31: 新豐7線 | B31: 平均 | I31: 15.333333 | J31: 1916.6667 | K31: =J31/I31 -> 125 | L31: 15.333333 | M31: =AVERAGE(M25:M30) -> 1831.0258 | N31: =M31/L31 -> 119.41473 | O31: =L31-I31 -> 0 | P31: =N31-K31 -> -5.5852717 | Q31: =N31/K31 -> 0.95531783 | Y31: =SUM(Y25:Y30) -> 0 | Z31: =SUM(Z25:Z30) -> 0 | AC31: 6 | AD31: =SUM(AD25:AD30) -> 0 | AE31: =M31-J31 -> -85.640832 | AF31: =M31/J31 -> 0.95531783
A32: 新豐8線 | B32: 三明治 | C32: 紐奧良風味烤雞鮮蔬三明治 | E32: 31.29 | F32: 6700 | G32: =E32*F32 -> 209643 | H32: 2 | I32: 18 | J32: 2400 | K32: =J32/I32 -> 133.33333 | L32: 18 | M32: =F32/V32*60 -> 2284.0909 | N32: =M32/L32 -> 126.89394 | O32: =L32-I32 -> 0 | P32: =N32-K32 -> -6.4393939 | Q32: =N32/K32 -> 0.95170455 | R32: =Q39 -> 0.95462703 | S32: 0.083333333 | T32: 0.20555556 | V32: =(T32-S32)*24*60 -> 176 | W32: =T32 -> 0.20555556 | X32: =S33 -> 0.225 | AC32: 7 | AE32: =M32-J32 -> -115.90909 | AF32: =M32/J32 -> 0.95170455 | AG32: =AF39 -> 0.95462703
A33: 新豐8線 | B33: 三明治 | C33: 醬燒烤雞三明治(115年) | E33: 26.37 | F33: 4600 | G33: =E33*F33 -> 121302 | H33: 2 | I33: 18 | J33: 2400 | K33: =J33/I33 -> 133.33333 | L33: 18 | M33: =F33/V33*60 -> 2300 | N33: =M33/L33 -> 127.77778 | O33: =L33-I33 -> 0 | P33: =N33-K33 -> -5.5555556 | Q33: =N33/K33 -> 0.95833333 | S33: 0.225 | T33: 0.30833333 | U33: =(S33-T32)*24*60 -> 28 | V33: =(T33-S33)*24*60 -> 120 | AE33: =M33-J33 -> -100 | AF33: =M33/J33 -> 0.95833333
A34: 新豐8線 | B34: 三明治 | C34: 鮪魚起司溏心蛋三明治(115年) | E34: 26.18 | F34: 5400 | G34: =E34*F34 -> 141372 | H34: 2 | I34: 18 | J34: 2400 | K34: =J34/I34 -> 133.33333 | L34: 18 | M34: =F34/V34*60 -> 2297.8723 | N34: =M34/L34 -> 127.65957 | O34: =L34-I34 -> 0 | P34: =N34-K34 -> -5.6737589 | Q34: =N34/K34 -> 0.95744681 | S34: 0.31388889 | T34: 0.41180556 | U34: =(S34-T33)*24*60 -> 8 | V34: =(T34-S34)*24*60 -> 141 | AE34: =M34-J34 -> -102.12766 | AF34: =M34/J34 -> 0.95744681
A35: 新豐8線 | B35: 三明治 | C35: 雞蛋沙拉三明治(114年) | E35: 25.99 | F35: 4999 | G35: =E35*F35 -> 129924.01 | I35: 14 | J35: 2400 | K35: =J35/I35 -> 171.42857 | L35: 14 | M35: =F35/V35*60 -> 2289.6183 | N35: =M35/L35 -> 163.54417 | O35: =L35-I35 -> 0 | P35: =N35-K35 -> -7.8844057 | Q35: =N35/K35 -> 0.95400763 | S35: 0.41527778 | T35: 0.50625 | U35: =(S35-T34)*24*60 -> 5 | V35: =(T35-S35)*24*60 -> 131 | W35: =T35 -> 0.50625 | X35: =S36 -> 0.54444444 | AE35: =M35-J35 -> -110.38168 | AF35: =M35/J35 -> 0.95400763
A36: 新豐8線 | B36: 三明治 | C36: 紐奧良風味烤雞鮮蔬三明治 | E36: 31.29 | F36: 4841 | G36: =E36*F36 -> 151474.89 | I36: 18 | J36: 2400 | K36: =J36/I36 -> 133.33333 | L36: 18 | M36: =F36/V36*60 -> 2287.0866 | N36: =M36/L36 -> 127.06037 | O36: =L36-I36 -> 0 | P36: =N36-K36 -> -6.2729659 | Q36: =N36/K36 -> 0.95295276 | S36: 0.54444444 | T36: 0.63263889 | U36: =(S36-T35)*24*60 -> 55 | V36: =(T36-S36)*24*60 -> 127 | AE36: =M36-J36 -> -112.91339 | AF36: =M36/J36 -> 0.95295276
A37: 新豐8線 | B37: 三明治 | C37: 鮪魚起司溏心蛋三明治(115年) | E37: 26.18 | F37: 3964 | G37: =E37*F37 -> 103777.52 | I37: 18 | J37: 2400 | K37: =J37/I37 -> 133.33333 | L37: 18 | M37: =F37/V37*60 -> 2286.9231 | N37: =M37/L37 -> 127.05128 | O37: =L37-I37 -> 0 | P37: =N37-K37 -> -6.2820513 | Q37: =N37/K37 -> 0.95288462 | S37: 0.63611111 | T37: 0.70833333 | U37: =(S37-T36)*24*60 -> 5 | V37: =(T37-S37)*24*60 -> 104 | AE37: =M37-J37 -> -113.07692 | AF37: =M37/J37 -> 0.95288462
A38: 新豐8線 | B38: 三明治 | C38: 醬燒烤雞三明治(115年) | E38: 26.37 | F38: 3209 | G38: =E38*F38 -> 84621.33 | I38: 18 | J38: 2400 | K38: =J38/I38 -> 133.33333 | L38: 18 | M38: =F38/V38*60 -> 2292.1429 | N38: =M38/L38 -> 127.34127 | O38: =L38-I38 -> 0 | P38: =N38-K38 -> -5.9920635 | Q38: =N38/K38 -> 0.95505952 | S38: 0.71388889 | T38: 0.77222222 | U38: =(S38-T37)*24*60 -> 8 | V38: =(T38-S38)*24*60 -> 84 | AE38: =M38-J38 -> -107.85714 | AF38: =M38/J38 -> 0.95505952
A39: 新豐8線 | B39: 平均 | I39: 17.428571 | J39: 2400 | K39: =J39/I39 -> 137.70492 | L39: 17.428571 | M39: =AVERAGE(M32:M38) -> 2291.1049 | N39: =M39/L39 -> 131.45684 | O39: =L39-I39 -> 0 | P39: =N39-K39 -> -6.248081 | Q39: =N39/K39 -> 0.95462703 | Y39: =SUM(Y32:Y38) -> 0 | Z39: =SUM(Z32:Z38) -> 0 | AC39: 7 | AD39: =SUM(AD32:AD38) -> 0 | AE39: =M39-J39 -> -108.89513 | AF39: =M39/J39 -> 0.95462703
A40: 新豐9線 | B40: 三明治 | C40: 經典總匯三明治(115年) | E40: 26.18 | F40: 4400 | G40: =E40*F40 -> 115192 | H40: 2 | I40: 20 | J40: 2400 | K40: =J40/I40 -> 120 | L40: 20 | M40: =F40/V40*60 -> 2295.6522 | N40: =M40/L40 -> 114.78261 | O40: =L40-I40 -> 0 | P40: =N40-K40 -> -5.2173913 | Q40: =N40/K40 -> 0.95652174 | R40: =Q48 -> 0.95626094 | S40: 0.083333333 | T40: 0.16319444 | V40: =(T40-S40)*24*60 -> 115 | W40: =T40 -> 0.16319444 | X40: =S41 -> 0.18263889 | AC40: 8 | AE40: =M40-J40 -> -104.34783 | AF40: =M40/J40 -> 0.95652174 | AG40: =AF48 -> 0.95626094
...

Sheet 0530
B1: 屏榮 新豐廠組合室生產人時性分析
B3: 日期 | C3: =TEXT('0530 4度C'!A2,"yyyy.mm.ddaaaa") -> 2026.05.30星期六 | E3: 訂單量 | F3: ='0530 4度C'!D1 -> 156221 | H3: 營業額 | I3: ='0530 4度C'!F1 -> 5347544.3
B4: 人時性 | C4: 項目 | E4: ➀ | G4: ➁ | I4: ➂ | K4: 異常停線 | M4: 短暫停線
C5: 組合室 | E5: 全溫層 | G5: 4度C-各編組展開 | I5: ③三明治-各編組展開 | K5: 合計次數 | L5: 時間 | M5: 合計次數 | N5: 設備次數
C6: 排關平均 | E6: =AVERAGE(D13:M13) -> 153.82204 | F6: =AVERAGE(D31:O31,D13:J13) -> 160.4743 | G6: =AVERAGE(D13:J13) -> 160.4743 | I6: =AVERAGE(K13:M13) -> 138.30008 | K6: ='0530 4度C'!Y2 -> 0 | L6: ='0530 4度C'!Z2 -> 0 | M6: ='0530 4度C'!AC2 -> 53 | N6: ='0530 4度C'!AD2 -> 0
C7: 實績平均 | E7: =AVERAGE(D14:M14) -> 147.55318 | F7: =AVERAGE(D32:O32,D14:J14) -> 154.13764 | G7: =AVERAGE(D14:J14) -> 154.13764 | I7: =AVERAGE(K14:M14) -> 132.18945
C8: 達成率平均 | E8: =AVERAGE(D15:M15) -> 0.95844857 | F8: =AVERAGE(D15:J15,D33:O33) -> 0.9595911 | G8: =AVERAGE(D15:J15) -> 0.9595911 | I8: =AVERAGE(K15:M15) -> 0.95578267
K9: ※現行日本鮮食廠以達成率80%為基本(即為現行KPI)
B10: 溫層 | D10: ➁4度C-各編組展開 | K10: ③三明治-各編組展開
B11: 編組 | D11: 1 | E11: 2 | F11: 3 | G11: 4 | H11: 5 | I11: 6 | J11: 7 | K11: 1 | L11: 2 | M11: 3
D12: 新豐6線 | E12: 新豐2線 | F12: 新豐5線 | G12: 新豐7線 | H12: 新豐3線 | I12: 新豐1線 | J12: 新豐10線 | K12: 新豐8線 | L12: 新豐9線 | M12: 新豐4線
B13: 人時性 | C13: 排關 | D13: =SUMIFS('0530 4度C'!$K:$K,'0530 4度C'!$A:$A,"新豐6線",'0530 4度C'!$B:$B,"平均") -> 130.43478 | E13: =SUMIFS('0530 4度C'!$K:$K,'0530 4度C'!$A:$A,"新豐2線",'0530 4度C'!$B:$B,"平均") -> 86.956522 | F13: =SUMIFS('0530 4度C'!$K:$K,'0530 4度C'!$A:$A,"新豐5線",'0530 4度C'!$B:$B,"平均") -> 96.590909 | G13: =SUMIFS('0530 4度C'!$K:$K,'0530 4度C'!$A:$A,"新豐7線",'0530 4度C'!$B:$B,"平均") -> 125 | H13: =SUMIFS('0530 4度C'!$K:$K,'0530 4度C'!$A:$A,"新豐3線",'0530 4度C'!$B:$B,"平均") -> 255.81395 | I13: =SUMIFS('0530 4度C'!$K:$K,'0530 4度C'!$A:$A,"新豐1線",'0530 4度C'!$B:$B,"平均") -> 109.375 | J13: =SUMIFS('0530 4度C'!$K:$K,'0530 4度C'!$A:$A,"新豐10線",'0530 4度C'!$B:$B,"平均") -> 319.14894 | K13: =SUMIFS('0530 4度C'!$K:$K,'0530 4度C'!$A:$A,"新豐8線",'0530 4度C'!$B:$B,"平均") -> 138.46154 | L13: =SUMIFS('0530 4度C'!$K:$K,'0530 4度C'!$A:$A,"新豐9線",'0530 4度C'!$B:$B,"平均") -> 121.6 | M13: =SUMIFS('0530 4度C'!$K:$K,'0530 4度C'!$A:$A,"新豐4線",'0530 4度C'!$B:$B,"平均") -> 154.83871
C14: 實績 | D14: =SUMIFS('0530 4度C'!$N:$N,'0530 4度C'!$A:$A,"新豐6線",'0530 4度C'!$B:$B,"平均") -> 125.23127 | E14: =SUMIFS('0530 4度C'!$N:$N,'0530 4度C'!$A:$A,"新豐2線",'0530 4度C'!$B:$B,"平均") -> 82.92548 | F14: =SUMIFS('0530 4度C'!$N:$N,'0530 4度C'!$A:$A,"新豐5線",'0530 4度C'!$B:$B,"平均") -> 92.985623 | G14: =SUMIFS('0530 4度C'!$N:$N,'0530 4度C'!$A:$A,"新豐7線",'0530 4度C'!$B:$B,"平均") -> 120.02295 | H14: =SUMIFS('0530 4度C'!$N:$N,'0530 4度C'!$A:$A,"新豐3線",'0530 4度C'!$B:$B,"平均") -> 244.18133 | I14: =SUMIFS('0530 4度C'!$N:$N,'0530 4度C'!$A:$A,"新豐1線",'0530 4度C'!$B:$B,"平均") -> 104.83421 | J14: =SUMIFS('0530 4度C'!$N:$N,'0530 4度C'!$A:$A,"新豐10線",'0530 4度C'!$B:$B,"平均") -> 308.78258 | K14: =SUMIFS('0530 4度C'!$N:$N,'0530 4度C'!$A:$A,"新豐8線",'0530 4度C'!$B:$B,"平均") -> 132.5432 | L14: =SUMIFS('0530 4度C'!$N:$N,'0530 4度C'!$A:$A,"新豐9線",'0530 4度C'!$B:$B,"平均") -> 116.08404 | M14: =SUMIFS('0530 4度C'!$N:$N,'0530 4度C'!$A:$A,"新豐4線",'0530 4度C'!$B:$B,"平均") -> 147.94113
C15: 達成率 | D15: =D14/D13 -> 0.96010637 | E15: =E14/E13 -> 0.95364302 | F15: =F14/F13 -> 0.96267468 | G15: =G14/G13 -> 0.96018364 | H15: =H14/H13 -> 0.95452702 | I15: =I14/I13 -> 0.95848423 | J15: =J14/J13 -> 0.96751875 | K15: =K14/K13 -> 0.95725642 | ... M15: =M14/M13 -> 0.95545312
B16: 作業 時間 | C16: 開始 | D16: =VLOOKUP("新豐6線",'0530 4度C'!$A:$T,19,0) -> 0.70833333 | E16: =VLOOKUP("新豐2線",'0530 4度C'!$A:$T,19,0) -> 0.083333333 | F16: =VLOOKUP("新豐5線",'0530 4度C'!$A:$T,19,0) -> 0.20833333 | G16: =VLOOKUP("新豐7線",'0530 4度C'!$A:$T,19,0) -> 0.20833333 | H16: =VLOOKUP("新豐3線",'0530 4度C'!$A:$T,19,0) -> 0.083333333 | I16: =VLOOKUP("新豐1線",'0530 4度C'!$A:$T,19,0) -> 0.20833333 | J16: =VLOOKUP("新豐10線",'0530 4度C'!$A:$T,19,0) -> 0.20833333 | K16: =VLOOKUP("新豐8線",'0530 4度C'!$A:$T,19,0) -> 0.083333333 | L16: =VLOOKUP("新豐9線",'0530 4度C'!$A:$T,19,0) -> 0.083333333 | M16: =VLOOKUP("新豐4線",'0530 4度C'!$A:$T,19,0) -> 0.083333333
C17: 結束 | D17: =LOOKUP(2,1/(('0530 4度C'!$A:$A="新豐6線")*('0530 4度C'!$T:$T<>"")),'0530 4度C'!$T:$T) -> 0.84236111 | E17: =LOOKUP(2,1/(('0530 4度C'!$A:$A="新豐2線")*('0530 4度C'!$T:$T<>"")),'0530 4度C'!$T:$T) -> 0.61458333 | F17: =LOOKUP(2,1/(('0530 4度C'!$A:$A="新豐5線")*('0530 4度C'!$T:$T<>"")),'0530 4度C'!$T:$T) -> 0.81041667 | G17: =LOOKUP(2,1/(('0530 4度C'!$A:$A="新豐7線")*('0530 4度C'!$T:$T<>"")),'0530 4度C'!$T:$T) -> 0.77986111 | H17: =LOOKUP(2,1/(('0530 4度C'!$A:$A="新豐3線")*('0530 4度C'!$T:$T<>"")),'0530 4度C'!$T:$T) -> 0.37152778 | I17: =LOOKUP(2,1/(('0530 4度C'!$A:$A="新豐1線")*('0530 4度C'!$T:$T<>"")),'0530 4度C'!$T:$T) -> 0.83611111 | J17: =LOOKUP(2,1/(('0530 4度C'!$A:$A="新豐10線")*('0530 4度C'!$T:$T<>"")),'0530 4度C'!$T:$T) -> 0.38611111 | K17: =LOOKUP(2,1/(('0530 4度C'!$A:$A="新豐8線")*('0530 4度C'!$T:$T<>"")),'0530 4度C'!$T:$T) -> 0.61041667 | L17: =LOOKUP(2,1/(('0530 4度C'!$A:$A="新豐9線")*('0530 4度C'!$T:$T<>"")),'0530 4度C'!$T:$T) -> 0.63333333 | M17: =LOOKUP(2,1/(('0530 4度C'!$A:$A="新豐4線")*('0530 4度C'!$T:$T<>"")),'0530 4度C'!$T:$T) -> 0.59513889
B18: 產線異常 (5分鐘以上) | C18: 次數 | D18: =SUMIFS('0530 4度C'!$Y:$Y,'0530 4度C'!$A:$A,"新豐6線",'0530 4度C'!$B:$B,"平均") -> 0 | E18: =SUMIFS('0530 4度C'!$Y:$Y,'0530 4度C'!$A:$A,"新豐2線",'0530 4度C'!$B:$B,"平均") -> 0 | F18: =SUMIFS('0530 4度C'!$Y:$Y,'0530 4度C'!$A:$A,"新豐5線",'0530 4度C'!$B:$B,"平均") -> 0 | G18: =SUMIFS('0530 4度C'!$Y:$Y,'0530 4度C'!$A:$A,"新豐7線",'0530 4度C'!$B:$B,"平均") -> 0 | H18: =SUMIFS('0530 4度C'!$Y:$Y,'0530 4度C'!$A:$A,"新豐3線",'0530 4度C'!$B:$B,"平均") -> 0 | I18: =SUMIFS('0530 4度C'!$Y:$Y,'0530 4度C'!$A:$A,"新豐1線",'0530 4度C'!$B:$B,"平均") -> 0 | J18: =SUMIFS('0530 4度C'!$Y:$Y,'0530 4度C'!$A:$A,"新豐10線",'0530 4度C'!$B:$B,"平均") -> 0 | K18: =SUMIFS('0530 4度C'!$Y:$Y,'0530 4度C'!$A:$A,"新豐8線",'0530 4度C'!$B:$B,"平均") -> 0 | L18: =SUMIFS('0530 4度C'!$Y:$Y,'0530 4度C'!$A:$A,"新豐9線",'0530 4度C'!$B:$B,"平均") -> 0 | M18: =SUMIFS('0530 4度C'!$Y:$Y,'0530 4度C'!$A:$A,"新豐4線",'0530 4度C'!$B:$B,"平均") -> 0
C19: 時間/分 | D19: =SUMIFS('0530 4度C'!$Z:$Z,'0530 4度C'!$A:$A,"新豐6線",'0530 4度C'!$B:$B,"平均") -> 0 | E19: =SUMIFS('0530 4度C'!$Z:$Z,'0530 4度C'!$A:$A,"新豐2線",'0530 4度C'!$B:$B,"平均") -> 0 | F19: =SUMIFS('0530 4度C'!$Z:$Z,'0530 4度C'!$A:$A,"新豐5線",'0530 4度C'!$B:$B,"平均") -> 0 | G19: =SUMIFS('0530 4度C'!$Z:$Z,'0530 4度C'!$A:$A,"新豐7線",'0530 4度C'!$B:$B,"平均") -> 0 | H19: =SUMIFS('0530 4度C'!$Z:$Z,'0530 4度C'!$A:$A,"新豐3線",'0530 4度C'!$B:$B,"平均") -> 0 | I19: =SUMIFS('0530 4度C'!$Z:$Z,'0530 4度C'!$A:$A,"新豐1線",'0530 4度C'!$B:$B,"平均") -> 0 | J19: =SUMIFS('0530 4度C'!$Z:$Z,'0530 4度C'!$A:$A,"新豐10線",'0530 4度C'!$B:$B,"平均") -> 0 | K19: =SUMIFS('0530 4度C'!$Z:$Z,'0530 4度C'!$A:$A,"新豐8線",'0530 4度C'!$B:$B,"平均") -> 0 | L19: =SUMIFS('0530 4度C'!$Z:$Z,'0530 4度C'!$A:$A,"新豐9線",'0530 4度C'!$B:$B,"平均") -> 0 | M19: =SUMIFS('0530 4度C'!$Z:$Z,'0530 4度C'!$A:$A,"新豐4線",'0530 4度C'!$B:$B,"平均") -> 0
B20: 短暫停線 (5分鐘以下) | C20: 次數 | D20: =SUMIFS('0530 4度C'!$AC:$AC,'0530 4度C'!$A:$A,"新豐6線",'0530 4度C'!$B:$B,"平均") -> 3 | E20: =SUMIFS('0530 4度C'!$AC:$AC,'0530 4度C'!$A:$A,"新豐2線",'0530 4度C'!$B:$B,"平均") -> 4 | F20: =SUMIFS('0530 4度C'!$AC:$AC,'0530 4度C'!$A:$A,"新豐5線",'0530 4度C'!$B:$B,"平均") -> 5 | G20: =SUMIFS('0530 4度C'!$AC:$AC,'0530 4度C'!$A:$A,"新豐7線",'0530 4度C'!$B:$B,"平均") -> 6 | H20: =SUMIFS('0530 4度C'!$AC:$AC,'0530 4度C'!$A:$A,"新豐3線",'0530 4度C'!$B:$B,"平均") -> 4 | I20: =SUMIFS('0530 4度C'!$AC:$AC,'0530 4度C'!$A:$A,"新豐1線",'0530 4度C'!$B:$B,"平均") -> 7 | J20: =SUMIFS('0530 4度C'!$AC:$AC,'0530 4度C'!$A:$A,"新豐10線",'0530 4度C'!$B:$B,"平均") -> 5 | K20: =SUMIFS('0530 4度C'!$AC:$AC,'0530 4度C'!$A:$A,"新豐8線",'0530 4度C'!$B:$B,"平均") -> 6 | L20: =SUMIFS('0530 4度C'!$AC:$AC,'0530 4度C'!$A:$A,"新豐9線",'0530 4度C'!$B:$B,"平均") -> 7 | M20: =SUMIFS('0530 4度C'!$AC:$AC,'0530 4度C'!$A:$A,"新豐4線",'0530 4度C'!$B:$B,"平均") -> 6
C21: 設備次數 | D21: =SUMIFS('0530 4度C'!$AD:$AD,'0530 4度C'!$A:$A,"新豐6線",'0530 4度C'!$B:$B,"平均") -> 0 | E21: =SUMIFS('0530 4度C'!$AD:$AD,'0530 4度C'!$A:$A,"新豐2線",'0530 4度C'!$B:$B,"平均") -> 0 | F21: =SUMIFS('0530 4度C'!$AD:$AD,'0530 4度C'!$A:$A,"新豐5線",'0530 4度C'!$B:$B,"平均") -> 0 | G21: =SUMIFS('0530 4度C'!$AD:$AD,'0530 4度C'!$A:$A,"新豐7線",'0530 4度C'!$B:$B,"平均") -> 0 | H21: =SUMIFS('0530 4度C'!$AD:$AD,'0530 4度C'!$A:$A,"新豐3線",'0530 4度C'!$B:$B,"平均") -> 0 | I21: =SUMIFS('0530 4度C'!$AD:$AD,'0530 4度C'!$A:$A,"新豐1線",'0530 4度C'!$B:$B,"平均") -> 0 | J21: =SUMIFS('0530 4度C'!$AD:$AD,'0530 4度C'!$A:$A,"新豐10線",'0530 4度C'!$B:$B,"平均") -> 0 | K21: =SUMIFS('0530 4度C'!$AD:$AD,'0530 4度C'!$A:$A,"新豐8線",'0530 4度C'!$B:$B,"平均") -> 0 | L21: =SUMIFS('0530 4度C'!$AD:$AD,'0530 4度C'!$A:$A,"新豐9線",'0530 4度C'!$B:$B,"平均") -> 0 | M21: =SUMIFS('0530 4度C'!$AD:$AD,'0530 4度C'!$A:$A,"新豐4線",'0530 4度C'!$B:$B,"平均") -> 0
B22: 配置人數 | D22: =SUMIFS('0530 4度C'!$I:$I,'0530 4度C'!$A:$A,"新豐6線",'0530 4度C'!$B:$B,"平均") -> 15.333333 | E22: =SUMIFS('0530 4度C'!$I:$I,'0530 4度C'!$A:$A,"新豐2線",'0530 4度C'!$B:$B,"平均") -> 17.25 | F22: =SUMIFS('0530 4度C'!$I:$I,'0530 4度C'!$A:$A,"新豐5線",'0530 4度C'!$B:$B,"平均") -> 17.6 | G22: =SUMIFS('0530 4度C'!$I:$I,'0530 4度C'!$A:$A,"新豐7線",'0530 4度C'!$B:$B,"平均") -> 15.333333 | H22: =SUMIFS('0530 4度C'!$I:$I,'0530 4度C'!$A:$A,"新豐3線",'0530 4度C'!$B:$B,"平均") -> 10.75 | I22: =SUMIFS('0530 4度C'!$I:$I,'0530 4度C'!$A:$A,"新豐1線",'0530 4度C'!$B:$B,"平均") -> 18.285714 | J22: =SUMIFS('0530 4度C'!$I:$I,'0530 4度C'!$A:$A,"新豐10線",'0530 4度C'!$B:$B,"平均") -> 9.4 | K22: =SUMIFS('0530 4度C'!$I:$I,'0530 4度C'!$A:$A,"新豐8線",'0530 4度C'!$B:$B,"平均") -> 17.333333 | L22: =SUMIFS('0530 4度C'!$I:$I,'0530 4度C'!$A:$A,"新豐9線",'0530 4度C'!$B:$B,"平均") -> 17.857143 | M22: =SUMIFS('0530 4度C'!$I:$I,'0530 4度C'!$A:$A,"新豐4線",'0530 4度C'!$B:$B,"平均") -> 15.5
B23: 主要應用設備 | D23: ET-55 | E23: 熱縮爐 | F23: L型包裝機 | G23: L型包裝機 | H23: 伺服包裝機 | I23: ET-55 | J23: 伺服包裝機 | K23: 三明治包裝機 | L23: 三明治包裝機 | M23: 三明治包裝機
B24: 次要應用設備 | F24: 圓盤機 | G24: ET-55
B25: 備註 | E25: 握沙拉 | F25: 共用L型包裝機 | H25: 調理麵包 | I25: 炒飯+沙拉 | J25: 調理麵包

Sheet 0530 4度C
A1: 新豐廠四度C日報分析 | C1: 總生產量 | D1: =SUM(F5:F67) -> 156221 | E1: 營業額 | F1: =SUM(G5:G67) -> 5347544.3 | G1: 出勤人數 | H1: =L8+L13+L46+L54+L19+L60+L33+L41+L26+L67 -> 154.64286 | I1: 產線配置圖 | L1: 生產實績 | O1: 人時性差異分析 | S1: 日報登錄 | Y1: 合計 次數 | Z1: 合計 時間/分 | AA1: 產線異常 分析說明(5分鐘以上) | AC1: 合計 次數 | AD1: 合計 設備次數 | AE1: 產能差異分析
A2: 46172 | B2: 星期六 | C2: 人時性 | D2: =AVERAGE(N8,N13,N46,N54,N19,N60,N26,N33,N41,N67) -> 147.55318 | E2: 平均廠價 | F2: =F1/D1 -> 34.230637 | G2: 多次生產數 | H2: =COUNT(H5:H67) -> 6 | Y2: =SUM(Y8+Y13+Y19+Y26+Y33+Y41+Y46+Y54+Y60+Y67) -> 0 | Z2: =SUM(Z8+Z13+Z19+Z26+Z33+Z41+Z46+Z54+Z60+Z67) -> 0 | AC2: 53 | AD2: =SUM(AD8+AD13+AD19+AD26+AD33+AD41+AD46+AD54+AD60+AD67) -> 0
A3: 線別 | B3: 品類 | C3: 品名 | E3: 廠價 | F3: 生產量 | G3: 營收 | H3: 多次 生產 | I3: 人數 | J3: 產能/時 | K3: 人時性 | L3: 人數 | M3: 產能/時 | N3: 人時性 | O3: 人數 | P3: 人時性 | Q3: 達成率 | R3: 達成率平均 | S3: 生產時間 | U3: 換線、休息/分 | V3: 稼動時間/分 | W3: 休息時間 | Y3: 產線異常統計 (5分鐘以上) | AA3: (新豐回填) | AC3: 短暫停線統計 (5分鐘以下) | AE3: 產能/時 | AF3: 達成率 | AG3: 達成率平均
S4: 開始 | T4: 結束 | W4: 開始 | X4: 結束 | Y4: 次數 | Z4: 時間/分 | AC4: 總次數 | AD4: 設備因素(次數)
A5: 新豐6線 | B5: 微波主食 | C5: 二配泰式綠咖哩雞 | E5: 50.67 | F5: 1489 | G5: =E5*F5 -> 75447.63 | I5: 15 | J5: 2000 | K5: =J5/I5 -> 133.33333 | L5: 15 | M5: =F5/V5*60 -> 1942.1739 | N5: =M5/L5 -> 129.47826 | O5: =L5-I5 -> 0 | P5: =N5-K5 -> -3.8550725 | Q5: =N5/K5 -> 0.97108696 | R5: =Q8 -> 0.96010637 | S5: 0.70833333 | T5: 0.74027778 | V5: =(T5-S5)*24*60 -> 46 | AC5: 3 | AE5: =M5-J5 -> -57.826087 | AF5: =M5/J5 -> 0.97108696 | AG5: =AF8 -> 0.96010637
A6: 新豐6線 | B6: 微波主食 | C6: 二配金咖哩果香甘口咖哩飯 | E6: 50.92 | F6: 2036 | G6: =E6*F6 -> 103673.12 | I6: 15 | J6: 2000 | K6: =J6/I6 -> 133.33333 | L6: 15 | M6: =F6/V6*60 -> 1908.75 | N6: =M6/L6 -> 127.25 | O6: =L6-I6 -> 0 | P6: =N6-K6 -> -6.0833333 | Q6: =N6/K6 -> 0.954375 | S6: 0.74583333 | T6: 0.79027778 | U6: =IF(S6=TIME(17,0,0),"",(S6-T5)*24*60) -> 8 | V6: =(T6-S6)*24*60 -> 64 | AE6: =M6-J6 -> -91.25 | AF6: =M6/J6 -> 0.954375
A7: 新豐6線 | B7: 微波主食 | C7: 二配金咖哩濃厚辛口咖哩飯 | E7: 50.98 | F7: 2228 | G7: =E7*F7 -> 113583.44 | I7: 16 | J7: 2000 | K7: =J7/I7 -> 125 | L7: 16 | M7: =F7/V7*60 -> 1909.7143 | N7: =M7/L7 -> 119.35714 | O7: =L7-I7 -> 0 | P7: =N7-K7 -> -5.6428571 | Q7: =N7/K7 -> 0.95485714 | S7: 0.79375 | T7: 0.84236111 | U7: =IF(S7=TIME(17,0,0),"",(S7-T6)*24*60) -> 5 | V7: =(T7-S7)*24*60 -> 70 | AE7: =M7-J7 -> -90.285714 | AF7: =M7/J7 -> 0.95485714
A8: 新豐6線 | B8: 平均 | I8: 15.333333 | J8: 2000 | K8: =J8/I8 -> 130.43478 | L8: 15.333333 | M8: =AVERAGE(M5:M7) -> 1920.2127 | N8: =M8/L8 -> 125.23127 | O8: =L8-I8 -> 0 | P8: =N8-K8 -> -5.2035174 | Q8: =N8/K8 -> 0.96010637 | Y8: =SUM(Y5:Y7) -> 0 | Z8: =SUM(Z5:Z7) -> 0 | AC8: 3 | AD8: =SUM(AD5:AD7) -> 0 | AE8: =M8-J8 -> -79.787267 | AF8: =M8/J8 -> 0.96010637
A9: 新豐2線 | B9: 沙拉 | C9: 青醬優格雞肉握沙拉(113年) | E9: 39.62 | F9: 4627 | G9: =E9*F9 -> 183321.74 | I9: 19 | J9: 1500 | K9: =J9/I9 -> 78.947368 | L9: 19 | M9: =F9/V9*60 -> 1431.0309 | N9: =M9/L9 -> 75.317417 | O9: =L9-I9 -> 0 | P9: =N9-K9 -> -3.6299512 | Q9: =N9/K9 -> 0.95402062 | R9: =Q13 -> 0.95364302 | S9: 0.083333333 | T9: 0.21805556 | V9: =(T9-S9)*24*60 -> 194 | W9: =T9 -> 0.21805556 | X9: =S10 -> 0.23680556 | AC9: 4 | AE9: =M9-J9 -> -68.969072 | AF9: =M9/J9 -> 0.95402062 | AG9: =AF13 -> 0.95364302
A10: 新豐2線 | B10: 沙拉 | C10: 青檸烤雞握沙拉(113年) | E10: 39.8 | F10: 3600 | G10: =E10*F10 -> 143280 | H10: 2 | I10: 17 | J10: 1500 | K10: =J10/I10 -> 88.235294 | L10: 17 | M10: =F10/V10*60 -> 1430.4636 | N10: =M10/L10 -> 84.144916 | O10: =L10-I10 -> 0 | P10: =N10-K10 -> -4.0903779 | Q10: =N10/K10 -> 0.95364238 | S10: 0.23680556 | T10: 0.34166667 | U10: =IF(S10=TIME(17,0,0),"",(S10-T9)*24*60) -> 27 | V10: =(T10-S10)*24*60 -> 151 | AE10: =M10-J10 -> -69.536424 | AF10: =M10/J10 -> 0.95364238
A11: 新豐2線 | B11: 沙拉 | C11: 厚蛋時蔬握沙拉 | E11: 39.46 | F11: 5117 | G11: =E11*F11 -> 201916.82 | I11: 16 | J11: 1500 | K11: =J11/I11 -> 93.75 | L11: 16 | M11: =F11/V11*60 -> 1428 | N11: =M11/L11 -> 89.25 | O11: =L11-I11 -> 0 | P11: =N11-K11 -> -4.5 | Q11: =N11/K11 -> 0.952 | S11: 0.34652778 | T11: 0.49583333 | U11: =IF(S11=TIME(17,0,0),"",(S11-T10)*24*60) -> 7 | V11: =(T11-S11)*24*60 -> 215 | W11: =T11 -> 0.49583333 | X11: =S12 -> 0.53819444 | AE11: =M11-J11 -> -72 | AF11: =M11/J11 -> 0.952
A12: 新豐2線 | B12: 沙拉 | C12: 青檸烤雞握沙拉(113年) | E12: 39.8 | F12: 2626 | G12: =E12*F12 -> 104514.8 | I12: 17 | J12: 1500 | K12: =J12/I12 -> 88.235294 | L12: 17 | M12: =F12/V12*60 -> 1432.3636 | N12: =M12/L12 -> 84.256684 | O12: =L12-I12 -> 0 | P12: =N12-K12 -> -3.9786096 | Q12: =N12/K12 -> 0.95490909 | S12: 0.53819444 | T12: 0.61458333 | U12: =IF(S12=TIME(17,0,0),"",(S12-T11)*24*60) -> 61 | V12: =(T12-S12)*24*60 -> 110 | AE12: =M12-J12 -> -67.636364 | AF12: =M12/J12 -> 0.95490909
A13: 新豐2線 | B13: 平均 | I13: 17.25 | J13: 1500 | K13: =J13/I13 -> 86.956522 | L13: 17.25 | M13: =AVERAGE(M9:M12) -> 1430.4645 | N13: =M13/L13 -> 82.92548 | O13: =L13-I13 -> 0 | P13: =N13-K13 -> -4.0310414 | Q13: =N13/K13 -> 0.95364302 | Y13: =SUM(Y9:Y12) -> 0 | Z13: =SUM(Z9:Z12) -> 0 | AC13: 4 | AD13: =SUM(AD9:AD12) -> 0 | AE13: =M13-J13 -> -69.535465 | AF13: =M13/J13 -> 0.95364302
A14: 新豐5線 | B14: 小吃 | C14: 剝皮辣椒雞湯 | E14: 41 | F14: 1423 | G14: =E14*F14 -> 58343 | I14: 26 | J14: 1500 | K14: =J14/I14 -> 57.692308 | L14: 26 | M14: =F14/V14*60 -> 1447.1186 | N14: =M14/L14 -> 55.658409 | O14: =L14-I14 -> 0 | P14: =N14-K14 -> -2.0338983 | Q14: =N14/K14 -> 0.96474576 | R14: =Q19 -> 0.96267468 | S14: 0.20833333 | T14: 0.24930556 | V14: =(T14-S14)*24*60 -> 59 | AC14: 5 | AE14: =M14-J14 -> -52.881356 | AF14: =M14/J14 -> 0.96474576 | AG14: =AF19 -> 0.96267468
A15: 新豐5線 | B15: 微波主食 | C15: 香菇雞粥 | E15: 37.03 | F15: 1860 | G15: =E15*F15 -> 68875.8 | I15: 13 | J15: 1500 | K15: =J15/I15 -> 115.38462 | L15: 13 | M15: =F15/V15*60 -> 1430.7692 | N15: =M15/L15 -> 110.05917 | O15: =L15-I15 -> 0 | P15: =N15-K15 -> -5.3254438 | Q15: =N15/K15 -> 0.95384615 | S15: 0.25277778 | T15: 0.30694444 | U15: =IF(S15=TIME(17,0,0),"",(S15-T14)*24*60) -> 5 | V15: =(T15-S15)*24*60 -> 78 | AE15: =M15-J15 -> -69.230769 | AF15: =M15/J15 -> 0.95384615
A16: 新豐5線 | B16: 微波主食 | C16: 二配起司控培根白醬焗烤飯 | E16: 53.68 | F16: 1120 | G16: =E16*F16 -> 60121.6 | I16: 16 | J16: 1500 | K16: =J16/I16 -> 93.75 | L16: 16 | M16: =F16/V16*60 -> 1429.7872 | N16: =M16/L16 -> 89.361702 | O16: =L16-I16 -> 0 | P16: =N16-K16 -> -4.3882979 | Q16: =N16/K16 -> 0.95319149 | S16: 0.70833333 | T16: 0.74097222 | U16: =IF(S16=TIME(17,0,0),"",(S16-T15)*24*60) | V16: =(T16-S16)*24*60 -> 47 | AE16: =M16-J16 -> -70.212766 | AF16: =M16/J16 -> 0.95319149
A17: 新豐5線 | B17: 微波主食 | C17: 二配蔥爆牛肉燴飯 | E17: 52.86 | F17: 1322 | G17: =E17*F17 -> 69880.92 | I17: 16 | J17: 2000 | K17: =J17/I17 -> 125 | L17: 16 | M17: =F17/V17*60 -> 1934.6341 | N17: =M17/L17 -> 120.91463 | O17: =L17-I17 -> 0 | P17: =N17-K17 -> -4.0853659 | Q17: =N17/K17 -> 0.96731707 | S17: 0.74583333 | T17: 0.77430556 | U17: =IF(S17=TIME(17,0,0),"",(S17-T16)*24*60) -> 7 | V17: =(T17-S17)*24*60 -> 41 | AE17: =M17-J17 -> -65.365854 | AF17: =M17/J17 -> 0.96731707
A18: 新豐5線 | B18: 微波主食 | C18: 二配港式香滑嫩蛋牛肉燴飯 | E18: 50.67 | F18: 1520 | G18: =E18*F18 -> 77018.4 | I18: 17 | J18: 2000 | K18: =J18/I18 -> 117.64706 | L18: 17 | M18: =F18/V18*60 -> 1940.4255 | N18: =M18/L18 -> 114.14268 | O18: =L18-I18 -> 0 | P18: =N18-K18 -> -3.5043805 | Q18: =N18/K18 -> 0.97021277 | S18: 0.77777778 | T18: 0.81041667 | U18: =IF(S18=TIME(17,0,0),"",(S18-T17)*24*60) -> 5 | V18: =(T18-S18)*24*60 -> 47 | AE18: =M18-J18 -> -59.574468 | AF18: =M18/J18 -> 0.97021277
A19: 新豐5線 | B19: 平均 | I19: 17.6 | J19: 1700 | K19: =J19/I19 -> 96.590909 | L19: 17.6 | M19: =AVERAGE(M14:M18) -> 1636.547 | N19: =M19/L19 -> 92.985623 | O19: =L19-I19 -> 0 | P19: =N19-K19 -> -3.6052865 | Q19: =N19/K19 -> 0.96267468 | Y19: =SUM(Y14:Y18) -> 0 | Z19: =SUM(Z14:Z18) -> 0 | AC19: 5 | AD19: =SUM(AD14:AD18) -> 0 | AE19: =M19-J19 -> -63.453043 | AF19: =M19/J19 -> 0.96267468
A20: 新豐7線 | B20: 微波主食 | C20: 韓式燒肉拌飯 | E20: 54.09 | F20: 1404 | G20: =E20*F20 -> 75942.36 | I20: 17 | J20: 1500 | K20: =J20/I20 -> 88.235294 | L20: 17 | M20: =F20/V20*60 -> 1427.7966 | N20: =M20/L20 -> 83.988036 | O20: =L20-I20 -> 0 | P20: =N20-K20 -> -4.2472582 | Q20: =N20/K20 -> 0.95186441 | R20: =Q26 -> 0.96018364 | S20: 0.20833333 | T20: 0.24930556 | V20: =(T20-S20)*24*60 -> 59 | AC20: 6 | AE20: =M20-J20 -> -72.20339 | AF20: =M20/J20 -> 0.95186441 | AG20: =AF26 -> 0.96018364
A21: 新豐7線 | B21: 微波主食 | C21: 韓式泡菜豬肉豆腐丼飯 | E21: 50.67 | F21: 1650 | G21: =E21*F21 -> 83605.5 | I21: 17 | J21: 2000 | K21: =J21/I21 -> 117.64706 | L21: 17 | M21: =F21/V21*60 -> 1941.1765 | N21: =M21/L21 -> 114.18685 | O21: =L21-I21 -> 0 | P21: =N21-K21 -> -3.4602076 | Q21: =N21/K21 -> 0.97058824 | S21: 0.25277778 | T21: 0.28819444 | U21: =IF(S21=TIME(17,0,0),"",(S21-T20)*24*60) -> 5 | V21: =(T21-S21)*24*60 -> 51 | AE21: =M21-J21 -> -58.823529 | AF21: =M21/J21 -> 0.97058824
A22: 新豐7線 | B22: 微波主食 | C22: 鐵板滑蛋炸豬排丼 | E22: 57.73 | F22: 2107 | G22: =E22*F22 -> 121637.11 | I22: 14 | J22: 2000 | K22: =J22/I22 -> 142.85714 | L22: 14 | M22: =F22/V22*60 -> 1915.4545 | N22: =M22/L22 -> 136.81818 | O22: =L22-I22 -> 0 | P22: =N22-K22 -> -6.038961 | Q22: =N22/K22 -> 0.95772727 | S22: 0.29305556 | T22: 0.33888889 | U22: =IF(S22=TIME(17,0,0),"",(S22-T21)*24*60) -> 7 | V22: =(T22-S22)*24*60 -> 66 | AE22: =M22-J22 -> -84.545455 | AF22: =M22/J22 -> 0.95772727
A23: 新豐7線 | B23: 微波主食 | C23: 日式炙烤親子丼 | E23: 53.27 | F23: 1908 | G23: =E23*F23 -> 101639.16 | I23: 16 | J23: 2000 | K23: =J23/I23 -> 125 | L23: 16 | M23: =F23/V23*60 -> 1908 | N23: =M23/L23 -> 119.25 | O23: =L23-I23 -> 0 | P23: =N23-K23 -> -5.75 | Q23: =N23/K23 -> 0.954 | S23: 0.34444444 | T23: 0.38611111 | U23: =IF(S23=TIME(17,0,0),"",(S23-T22)*24*60) -> 8 | V23: =(T23-S23)*24*60 -> 60 | AE23: =M23-J23 -> -92 | AF23: =M23/J23 -> 0.954
A24: 新豐7線 | B24: 微波主食 | C24: 二配川味麻婆燒豆腐燴飯 | E24: 50.49 | F24: 1906 | G24: =E24*F24 -> 96233.94 | I24: 15 | J24: 2000 | K24: =J24/I24 -> 133.33333 | L24: 15 | M24: =F24/V24*60 -> 1906 | N24: =M24/L24 -> 127.06667 | O24: =L24-I24 -> 0 | P24: =N24-K24 -> -6.2666667 | Q24: =N24/K24 -> 0.953 | S24: 0.70833333 | T24: 0.75 | U24: =IF(S24=TIME(17,0,0),"",(S24-T23)*24*60) | V24: =(T24-S24)*24*60 -> 60 | AE24: =M24-J24 -> -94 | AF24: =M24/J24 -> 0.953
A25: 新豐7線 | B25: 微波主食 | C25: 二配厚香料優格咖哩雞排飯 | E25: 56.43 | F25: 1231 | G25: =E25*F25 -> 69465.33 | I25: 13 | J25: 2000 | K25: =J25/I25 -> 153.84615 | L25: 13 | M25: =F25/V25*60 -> 1943.6842 | N25: =M25/L25 -> 149.51417 | O25: =L25-I25 -> 0 | P25: =N25-K25 -> -4.3319838 | Q25: =N25/K25 -> 0.97184211 | S25: 0.75347222 | T25: 0.77986111 | U25: =IF(S25=TIME(17,0,0),"",(S25-T24)*24*60) -> 5 | V25: =(T25-S25)*24*60 -> 38 | AE25: =M25-J25 -> -56.315789 | AF25: =M25/J25 -> 0.97184211
A26: 新豐7線 | B26: 平均 | I26: 15.333333 | J26: 1916.6667 | K26: =J26/I26 -> 125 | L26: 15.333333 | M26: =AVERAGE(M20:M25) -> 1840.352 | N26: =M26/L26 -> 120.02295 | O26: =L26-I26 -> 0 | P26: =N26-K26 -> -4.9770453 | Q26: =N26/K26 -> 0.96018364 | Y26: =SUM(Y20:Y25) -> 0 | Z26: =SUM(Z20:Z25) -> 0 | AC26: 6 | AD26: =SUM(AD20:AD25) -> 0 | AE26: =M26-J26 -> -76.314694 | AF26: =M26/J26 -> 0.96018364
A27: 新豐8線 | B27: 三明治 | C27: 紐奧良風味烤雞鮮蔬三明治 | E27: 31.29 | F27: 6000 | G27: =E27*F27 -> 187740 | H27: 2 | I27: 18 | J27: 2400 | K27: =J27/I27 -> 133.33333 | L27: 18 | M27: =F27/V27*60 -> 2292.9936 | N27: =M27/L27 -> 127.38854 | O27: =L27-I27 -> 0 | P27: =N27-K27 -> -5.9447983 | Q27: =N27/K27 -> 0.95541401 | R27: =Q33 -> 0.95725642 | S27: 0.083333333 | T27: 0.19236111 | V27: =(T27-S27)*24*60 -> 157 | W27: =T27 -> 0.19236111 | X27: =S28 -> 0.2125 | AC27: 6 | AE27: =M27-J27 -> -107.00637 | AF27: =M27/J27 -> 0.95541401 | AG27: =AF33 -> 0.95725642
A28: 新豐8線 | B28: 三明治 | C28: 醬燒烤雞三明治(115年) | E28: 26.37 | F28: 5871 | G28: =E28*F28 -> 154818.27 | I28: 18 | J28: 2400 | K28: =J28/I28 -> 133.33333 | L28: 18 | M28: =F28/V28*60 -> 2287.4026 | N28: =M28/L28 -> 127.07792 | O28: =L28-I28 -> 0 | P28: =N28-K28 -> -6.2554113 | Q28: =N28/K28 -> 0.95308442 | S28: 0.2125 | T28: 0.31944444 | U28: =(S28-T27)*24*60 -> 29 | V28: =(T28-S28)*24*60 -> 154 | AE28: =M28-J28 -> -112.5974 | AF28: =M28/J28 -> 0.95308442
A29: 新豐8線 | B29: 三明治 | C29: 鮪魚起司溏心蛋三明治(115年) | E29: 26.18 | F29: 4100 | G29: =E29*F29 -> 107338 | H29: 2 | I29: 18 | J29: 2400 | K29: =J29/I29 -> 133.33333 | L29: 18 | M29: =F29/V29*60 -> 2299.0654 | N29: =M29/L29 -> 127.72586 | O29: =L29-I29 -> 0 | P29: =N29-K29 -> -5.6074766 | Q29: =N29/K29 -> 0.95794393 | S29: 0.325 | T29: 0.39930556 | U29: =(S29-T28)*24*60 -> 8 | V29: =(T29-S29)*24*60 -> 107 | AE29: =M29-J29 -> -100.93458 | AF29: =M29/J29 -> 0.95794393
A30: 新豐8線 | B30: 三明治 | C30: 雞蛋沙拉三明治(114年) | E30: 25.99 | F30: 3516 | G30: =E30*F30 -> 91380.84 | I30: 14 | J30: 2400 | K30: =J30/I30 -> 171.42857 | L30: 14 | M30: =F30/V30*60 -> 2293.0435 | N30: =M30/L30 -> 163.78882 | O30: =L30-I30 -> 0 | P30: =N30-K30 -> -7.6397516 | Q30: =N30/K30 -> 0.95543478 | S30: 0.40347222 | T30: 0.46736111 | U30: =(S30-T29)*24*60 -> 6 | V30: =(T30-S30)*24*60 -> 92 | W30: =T30 -> 0.46736111 | X30: =S31 -> 0.50833333 | AE30: =M30-J30 -> -106.95652 | AF30: =M30/J30 -> 0.95543478
A31: 新豐8線 | B31: 三明治 | C31: 紐奧良風味烤雞鮮蔬三明治 | E31: 31.29 | F31: 2313 | G31: =E31*F31 -> 72373.77 | I31: 18 | J31: 2400 | K31: =J31/I31 -> 133.33333 | L31: 18 | M31: =F31/V31*60 -> 2313 | N31: =M31/L31 -> 128.5 | O31: =L31-I31 -> 0 | P31: =N31-K31 -> -4.8333333 | Q31: =N31/K31 -> 0.96375 | S31: 0.50833333 | T31: 0.55 | U31: =(S31-T30)*24*60 -> 59 | V31: =(T31-S31)*24*60 -> 60 | AE31: =M31-J31 -> -87 | AF31: =M31/J31 -> 0.96375
A32: 新豐8線 | B32: 三明治 | C32: 鮪魚起司溏心蛋三明治(115年) | E32: 26.18 | F32: 3027 | G32: =E32*F32 -> 79246.86 | I32: 18 | J32: 2400 | K32: =J32/I32 -> 133.33333 | L32: 18 | M32: =F32/V32*60 -> 2298.9873 | N32: =M32/L32 -> 127.72152 | O32: =L32-I32 -> 0 | P32: =N32-K32 -> -5.6118143 | Q32: =N32/K32 -> 0.95791139 | S32: 0.55555556 | T32: 0.61041667 | U32: =(S32-T31)*24*60 -> 8 | V32: =(T32-S32)*24*60 -> 79 | AE32: =M32-J32 -> -101.01266 | AF32: =M32/J32 -> 0.95791139
A33: 新豐8線 | B33: 平均 | I33: 17.333333 | J33: 2400 | K33: =J33/I33 -> 138.46154 | L33: 17.333333 | M33: =AVERAGE(M27:M32) -> 2297.4154 | N33: =M33/L33 -> 132.5432 | O33: =L33-I33 -> 0 | P33: =N33-K33 -> -5.9183416 | Q33: =N33/K33 -> 0.95725642 | Y33: =SUM(Y27:Y32) -> 0 | Z33: =SUM(Z27:Z32) -> 0 | AC33: 6 | AD33: =SUM(AD27:AD32) -> 0 | AE33: =M33-J33 -> -102.58459 | AF33: =M33/J33 -> 0.95725642
A34: 新豐9線 | B34: 三明治 | C34: 經典總匯三明治(115年) | E34: 26.18 | F34: 3500 | G34: =E34*F34 -> 91630 | H34: 2 | I34: 20 | J34: 2400 | K34: =J34/I34 -> 120 | L34: 20 | M34: =F34/V34*60 -> 2307.6923 | N34: =M34/L34 -> 115.38462 | O34: =L34-I34 -> 0 | P34: =N34-K34 -> -4.6153846 | Q34: =N34/K34 -> 0.96153846 | R34: =Q41 -> 0.95463847 | S34: 0.083333333 | T34: 0.14652778 | V34: =(T34-S34)*24*60 -> 91 | W34: =T34 -> 0.14652778 | X34: =S35 -> 0.16458333 | AC34: 7 | AE34: =M34-J34 -> -92.307692 | AF34: =M34/J34 -> 0.96153846 | AG34: =AF41 -> 0.95463847
A35: 新豐9線 | B35: 三明治 | C35: 經典火腿玉米蛋三明治 | E35: 24.43 | F35: 5858 | G35: =E35*F35 -> 143110.94 | I35: 14 | J35: 2400 | K35: =J35/I35 -> 171.42857 | L35: 14 | M35: =F35/V35*60 -> 2282.3377 | N35: =M35/L35 -> 163.02412 | O35: =L35-I35 -> 0 | P35: =N35-K35 -> -8.4044527 | Q35: =N35/K35 -> 0.95097403 | S35: 0.16458333 | T35: 0.27152778 | U35: =(S35-T34)*24*60 -> 26 | V35: =(T35-S35)*24*60 -> 154 | AE35: =M35-J35 -> -117.66234 | AF35: =M35/J35 -> 0.95097403
A36: 新豐9線 | B36: 三明治 | C36: 好多蛋三明治 | E36: 34.1 | F36: 3400 | G36: =E36*F36 -> 115940 | H36: 2 | I36: 17 | J36: 1600 | K36: =J36/I36 -> 94.117647 | L36: 17 | M36: =F36/V36*60 -> 1533.8346 | N36: =M36/L36 -> 90.225564 | O36: =L36-I36 -> 0 | P36: =N36-K36 -> -3.8920831 | Q36: =N36/K36 -> 0.95864662 | S36: 0.27708333 | T36: 0.36944444 | U36: =(S36-T35)*24*60 -> 8 | V36: =(T36-S36)*24*60 -> 133 | AE36: =M36-J36 -> -66.165414 | AF36: =M36/J36 -> 0.95864662
A37: 新豐9線 | B37: 三明治 | C37: 好多菜三明治(114年) | E37: 25.98 | F37: 2571 | G37: =E37*F37 -> 66794.58 | I37: 19 | J37: 2400 | K37: =J37/I37 -> 126.31579 | L37: 19 | M37: =F37/V37*60 -> 2302.3881 | N37: =M37/L37 -> 121.17832 | O37: =L37-I37 -> 0 | P37: =N37-K37 -> -5.1374705 | Q37: =N37/K37 -> 0.95932836 | S37: 0.37361111 | T37: 0.42013889 | U37: =(S37-T36)*24*60 -> 6 | V37: =(T37-S37)*24*60 -> 67 | AE37: =M37-J37 -> -97.61194 | AF37: =M37/J37 -> 0.95932836
A38: 新豐9線 | B38: 三明治 | C38: 茄汁厚起司三明治 | E38: 25.99 | F38: 2817 | G38: =E38*F38 -> 73213.83 | I38: 18 | J38: 2400 | K38: =J38/I38 -> 133.33333 | L38: 18 | M38: =F38/V38*60 -> 2284.0541 | N38: =M38/L38 -> 126.89189 | O38: =L38-I38 -> 0 | P38: =N38-K38 -> -6.4414414 | Q38: =N38/K38 -> 0.95168919 | S38: 0.425 | T38: 0.47638889 | U38: =(S38-T37)*24*60 -> 7 | V38: =(T38-S38)*24*60 -> 74 | W38: =T38 -> 0.47638889 | X38: =S39 -> 0.51597222 | AE38: =M38-J38 -> -115.94595 | AF38: =M38/J38 -> 0.95168919
A39: 新豐9線 | B39: 三明治 | C39: 好多蛋三明治 | E39: 34.1 | F39: 2559 | G39: =E39*F39 -> 87261.9 | I39: 17 | J39: 1600 | K39: =J39/I39 -> 94.117647 | L39: 17 | M39: =F39/V39*60 -> 1520.198 | N39: =M39/L39 -> 89.423413 | O39: =L39-I39 -> 0 | P39: =N39-K39 -> -4.6942341 | Q39: =N39/K39 -> 0.95012376 | S39: 0.51597222 | T39: 0.58611111 | U39: =(S39-T38)*24*60 -> 57 | V39: =(T39-S39)*24*60 -> 101 | AE39: =M39-J39 -> -79.80198 | AF39: =M39/J39 -> 0.95012376
A40: 新豐9線 | B40: 三明治 | C40: 經典總匯三明治(115年) | E40: 26.18 | F40: 2356 | G40: =E40*F40 -> 61680.08 | I40: 20 | J40: 2400 | K40: =J40/I40 -> 120 | L40: 20 | M40: =F40/V40*60 -> 2280 | N40: =M40/L40 -> 114 | O40: =L40-I40 -> 0 | P40: =N40-K40 -> -6 | Q40: =N40/K40 -> 0.95 | S40: 0.59027778 | T40: 0.63333333 | U40: =(S40-T39)*24*60 -> 6 | V40: =(T40-S40)*24*60 -> 62 | AE40: =M40-J40 -> -120 | AF40: =M40/J40 -> 0.95
...

Sheet 0529
B1: 屏榮 新豐廠組合室生產人時性分析
B3: 日期 | C3: =TEXT('0529 4度C'!A2,"yyyy.mm.ddaaaa") -> 2026.05.29星期五 | E3: 訂單量 | F3: ='0529 4度C'!D1 -> 146475 | H3: 營業額 | I3: ='0529 4度C'!F1 -> 4966653.3
B4: 人時性 | C4: 項目 | E4: ➀ | G4: ➁ | I4: ➂ | K4: 異常停線 | M4: 短暫停線
C5: 組合室 | E5: 全溫層 | G5: 4度C-各編組展開 | I5: ③三明治-各編組展開 | K5: 合計次數 | L5: 時間 | M5: 合計次數 | N5: 設備次數
C6: 排關平均 | E6: =AVERAGE(D13:M13) -> 153.82204 | F6: =AVERAGE(D31:O31,D13:J13) -> 160.4743 | G6: =AVERAGE(D13:J13) -> 160.4743 | I6: =AVERAGE(K13:M13) -> 138.30008 | K6: ='0529 4度C'!Y2 -> 0 | L6: ='0529 4度C'!Z2 -> 0 | M6: ='0529 4度C'!AC2 -> 53 | N6: ='0529 4度C'!AD2 -> 0
C7: 實績平均 | E7: =AVERAGE(D14:M14) -> 147.42325 | F7: =AVERAGE(D32:O32,D14:J14) -> 153.88611 | G7: =AVERAGE(D14:J14) -> 153.88611 | I7: =AVERAGE(K14:M14) -> 132.34325
C8: 達成率平均 | E8: =AVERAGE(D15:M15) -> 0.95779733 | F8: =AVERAGE(D15:J15,D33:O33) -> 0.95807519 | G8: =AVERAGE(D15:J15) -> 0.95807519 | I8: =AVERAGE(K15:M15) -> 0.95714898
K9: ※現行日本鮮食廠以達成率80%為基本(即為現行KPI)
B10: 溫層 | D10: ➁4度C-各編組展開 | K10: ③三明治-各編組展開
B11: 編組 | D11: 1 | E11: 2 | F11: 3 | G11: 4 | H11: 5 | I11: 6 | J11: 7 | K11: 1 | L11: 2 | M11: 3
D12: 新豐6線 | E12: 新豐2線 | F12: 新豐5線 | G12: 新豐7線 | H12: 新豐3線 | I12: 新豐1線 | J12: 新豐10線 | K12: 新豐8線 | L12: 新豐9線 | M12: 新豐4線
B13: 人時性 | C13: 排關 | D13: =SUMIFS('0529 4度C'!$K:$K,'0529 4度C'!$A:$A,"新豐6線",'0529 4度C'!$B:$B,"平均") -> 130.43478 | E13: =SUMIFS('0529 4度C'!$K:$K,'0529 4度C'!$A:$A,"新豐2線",'0529 4度C'!$B:$B,"平均") -> 86.956522 | F13: =SUMIFS('0529 4度C'!$K:$K,'0529 4度C'!$A:$A,"新豐5線",'0529 4度C'!$B:$B,"平均") -> 96.590909 | G13: =SUMIFS('0529 4度C'!$K:$K,'0529 4度C'!$A:$A,"新豐7線",'0529 4度C'!$B:$B,"平均") -> 125 | H13: =SUMIFS('0529 4度C'!$K:$K,'0529 4度C'!$A:$A,"新豐3線",'0529 4度C'!$B:$B,"平均") -> 255.81395 | I13: =SUMIFS('0529 4度C'!$K:$K,'0529 4度C'!$A:$A,"新豐1線",'0529 4度C'!$B:$B,"平均") -> 109.375 | J13: =SUMIFS('0529 4度C'!$K:$K,'0529 4度C'!$A:$A,"新豐10線",'0529 4度C'!$B:$B,"平均") -> 319.14894 | K13: =SUMIFS('0529 4度C'!$K:$K,'0529 4度C'!$A:$A,"新豐8線",'0529 4度C'!$B:$B,"平均") -> 138.46154 | L13: =SUMIFS('0529 4度C'!$K:$K,'0529 4度C'!$A:$A,"新豐9線",'0529 4度C'!$B:$B,"平均") -> 121.6 | M13: =SUMIFS('0529 4度C'!$K:$K,'0529 4度C'!$A:$A,"新豐4線",'0529 4度C'!$B:$B,"平均") -> 154.83871
C14: 實績 | D14: =SUMIFS('0529 4度C'!$N:$N,'0529 4度C'!$A:$A,"新豐6線",'0529 4度C'!$B:$B,"平均") -> 125.08972 | E14: =SUMIFS('0529 4度C'!$N:$N,'0529 4度C'!$A:$A,"新豐2線",'0529 4度C'!$B:$B,"平均") -> 82.981544 | F14: =SUMIFS('0529 4度C'!$N:$N,'0529 4度C'!$A:$A,"新豐5線",'0529 4度C'!$B:$B,"平均") -> 92.36529 | G14: =SUMIFS('0529 4度C'!$N:$N,'0529 4度C'!$A:$A,"新豐7線",'0529 4度C'!$B:$B,"平均") -> 120.0906 | H14: =SUMIFS('0529 4度C'!$N:$N,'0529 4度C'!$A:$A,"新豐3線",'0529 4度C'!$B:$B,"平均") -> 244.0578 | I14: =SUMIFS('0529 4度C'!$N:$N,'0529 4度C'!$A:$A,"新豐1線",'0529 4度C'!$B:$B,"平均") -> 104.72158 | J14: =SUMIFS('0529 4度C'!$N:$N,'0529 4度C'!$A:$A,"新豐10線",'0529 4度C'!$B:$B,"平均") -> 307.89625 | K14: =SUMIFS('0529 4度C'!$N:$N,'0529 4度C'!$A:$A,"新豐8線",'0529 4度C'!$B:$B,"平均") -> 132.43632 | L14: =SUMIFS('0529 4度C'!$N:$N,'0529 4度C'!$A:$A,"新豐9線",'0529 4度C'!$B:$B,"平均") -> 116.76429 | M14: =SUMIFS('0529 4度C'!$N:$N,'0529 4度C'!$A:$A,"新豐4線",'0529 4度C'!$B:$B,"平均") -> 147.82913
C15: 達成率 | D15: =D14/D13 -> 0.95902116 | E15: =E14/E13 -> 0.95428775 | F15: =F14/F13 -> 0.95625242 | G15: =G14/G13 -> 0.96072476 | H15: =H14/H13 -> 0.95404415 | I15: =I14/I13 -> 0.95745448 | J15: =J14/J13 -> 0.9647416 | K15: =K14/K13 -> 0.9564845 | ... M15: =M14/M13 -> 0.95472981
B16: 作業 時間 | C16: 開始 | D16: =VLOOKUP("新豐6線",'0529 4度C'!$A:$T,19,0) -> 0.70833333 | E16: =VLOOKUP("新豐2線",'0529 4度C'!$A:$T,19,0) -> 0.083333333 | F16: =VLOOKUP("新豐5線",'0529 4度C'!$A:$T,19,0) -> 0.20833333 | G16: =VLOOKUP("新豐7線",'0529 4度C'!$A:$T,19,0) -> 0.20833333 | H16: =VLOOKUP("新豐3線",'0529 4度C'!$A:$T,19,0) -> 0.083333333 | I16: =VLOOKUP("新豐1線",'0529 4度C'!$A:$T,19,0) -> 0.20833333 | J16: =VLOOKUP("新豐10線",'0529 4度C'!$A:$T,19,0) -> 0.20833333 | K16: =VLOOKUP("新豐8線",'0529 4度C'!$A:$T,19,0) -> 0.083333333 | L16: =VLOOKUP("新豐9線",'0529 4度C'!$A:$T,19,0) -> 0.083333333 | M16: =VLOOKUP("新豐4線",'0529 4度C'!$A:$T,19,0) -> 0.083333333
C17: 結束 | D17: =LOOKUP(2,1/(('0529 4度C'!$A:$A="新豐6線")*('0529 4度C'!$T:$T<>"")),'0529 4度C'!$T:$T) -> 0.82152778 | E17: =LOOKUP(2,1/(('0529 4度C'!$A:$A="新豐2線")*('0529 4度C'!$T:$T<>"")),'0529 4度C'!$T:$T) -> 0.60972222 | F17: =LOOKUP(2,1/(('0529 4度C'!$A:$A="新豐5線")*('0529 4度C'!$T:$T<>"")),'0529 4度C'!$T:$T) -> 0.80069444 | G17: =LOOKUP(2,1/(('0529 4度C'!$A:$A="新豐7線")*('0529 4度C'!$T:$T<>"")),'0529 4度C'!$T:$T) -> 0.77083333 | H17: =LOOKUP(2,1/(('0529 4度C'!$A:$A="新豐3線")*('0529 4度C'!$T:$T<>"")),'0529 4度C'!$T:$T) -> 0.34722222 | I17: =LOOKUP(2,1/(('0529 4度C'!$A:$A="新豐1線")*('0529 4度C'!$T:$T<>"")),'0529 4度C'!$T:$T) -> 0.81875 | J17: =LOOKUP(2,1/(('0529 4度C'!$A:$A="新豐10線")*('0529 4度C'!$T:$T<>"")),'0529 4度C'!$T:$T) -> 0.36597222 | K17: =LOOKUP(2,1/(('0529 4度C'!$A:$A="新豐8線")*('0529 4度C'!$T:$T<>"")),'0529 4度C'!$T:$T) -> 0.59027778 | L17: =LOOKUP(2,1/(('0529 4度C'!$A:$A="新豐9線")*('0529 4度C'!$T:$T<>"")),'0529 4度C'!$T:$T) -> 0.62430556 | M17: =LOOKUP(2,1/(('0529 4度C'!$A:$A="新豐4線")*('0529 4度C'!$T:$T<>"")),'0529 4度C'!$T:$T) -> 0.58125
