Workbook

Sheet 0630
B1: 屏榮 新豐廠組合室生產人時性分析
B3: 日期 | C3: =TEXT('0630 4度C'!A2,"yyyy.mm.ddaaaa") -> 2026.06.30星期二 | E3: 訂單量 | F3: ='0630 4度C'!D1 -> 183717 | H3: 營業額 | I3: ='0630 4度C'!F1 -> 6251108.9
B4: 人時性 | C4: 項目 | E4: ➀ | G4: ➁ | I4: ➂ | K4: 異常停線 | M4: 短暫停線
C5: 組合室 | E5: 全溫層 | G5: 4度C-各編組展開 | I5: ③三明治-各編組展開 | K5: 合計次數 | L5: 時間 | M5: 合計次數 | N5: 設備次數
C6: 排關平均 | E6: =AVERAGE(D13:M13) -> 158.32762 | F6: =AVERAGE(D31:O31,D13:J13) -> 166.71541 | G6: =AVERAGE(D13:J13) -> 166.71541 | I6: =AVERAGE(K13:M13) -> 138.75611 | K6: ='0630 4度C'!Y2 -> 0 | L6: ='0630 4度C'!Z2 -> 0 | M6: ='0630 4度C'!AC2 -> 58 | N6: ='0630 4度C'!AD2 -> 0
C7: 實績平均 | E7: =AVERAGE(D14:M14) -> 151.63496 | F7: =AVERAGE(D32:O32,D14:J14) -> 159.83092 | G7: =AVERAGE(D14:J14) -> 159.83092 | I7: =AVERAGE(K14:M14) -> 132.51106
C8: 達成率平均 | E8: =AVERAGE(D15:M15) -> 0.95806485 | F8: =AVERAGE(D15:J15,D33:O33) -> 0.95934448 | G8: =AVERAGE(D15:J15) -> 0.95934448 | I8: =AVERAGE(K15:M15) -> 0.95507905
K9: ※現行日本鮮食廠以達成率80%為基本(即為現行KPI)
B10: 溫層 | D10: ➁4度C-各編組展開 | K10: ③三明治-各編組展開
B11: 編組 | D11: 1 | E11: 2 | F11: 3 | G11: 4 | H11: 5 | I11: 6 | J11: 7 | K11: 1 | L11: 2 | M11: 3
D12: 新豐6線 | E12: 新豐2線 | F12: 新豐5線 | G12: 新豐7線 | H12: 新豐3線 | I12: 新豐1線 | J12: 新豐10線 | K12: 新豐8線 | L12: 新豐9線 | M12: 新豐4線
B13: 人時性 | C13: 排關 | D13: =SUMIFS('0630 4度C'!$K:$K,'0630 4度C'!$A:$A,"新豐6線",'0630 4度C'!$B:$B,"平均") -> 129.03226 | E13: =SUMIFS('0630 4度C'!$K:$K,'0630 4度C'!$A:$A,"新豐2線",'0630 4度C'!$B:$B,"平均") -> 86.206897 | F13: =SUMIFS('0630 4度C'!$K:$K,'0630 4度C'!$A:$A,"新豐5線",'0630 4度C'!$B:$B,"平均") -> 87.78626 | G13: =SUMIFS('0630 4度C'!$K:$K,'0630 4度C'!$A:$A,"新豐7線",'0630 4度C'!$B:$B,"平均") -> 120 | H13: =SUMIFS('0630 4度C'!$K:$K,'0630 4度C'!$A:$A,"新豐3線",'0630 4度C'!$B:$B,"平均") -> 300 | I13: =SUMIFS('0630 4度C'!$K:$K,'0630 4度C'!$A:$A,"新豐1線",'0630 4度C'!$B:$B,"平均") -> 119.65812 | J13: =SUMIFS('0630 4度C'!$K:$K,'0630 4度C'!$A:$A,"新豐10線",'0630 4度C'!$B:$B,"平均") -> 324.32432 | K13: =SUMIFS('0630 4度C'!$K:$K,'0630 4度C'!$A:$A,"新豐8線",'0630 4度C'!$B:$B,"平均") -> 137.14286 | L13: =SUMIFS('0630 4度C'!$K:$K,'0630 4度C'!$A:$A,"新豐9線",'0630 4度C'!$B:$B,"平均") -> 120.63492 | M13: =SUMIFS('0630 4度C'!$K:$K,'0630 4度C'!$A:$A,"新豐4線",'0630 4度C'!$B:$B,"平均") -> 158.49057
C14: 實績 | D14: =SUMIFS('0630 4度C'!$N:$N,'0630 4度C'!$A:$A,"新豐6線",'0630 4度C'!$B:$B,"平均") -> 124.49084 | E14: =SUMIFS('0630 4度C'!$N:$N,'0630 4度C'!$A:$A,"新豐2線",'0630 4度C'!$B:$B,"平均") -> 82.386731 | F14: =SUMIFS('0630 4度C'!$N:$N,'0630 4度C'!$A:$A,"新豐5線",'0630 4度C'!$B:$B,"平均") -> 84.508754 | G14: =SUMIFS('0630 4度C'!$N:$N,'0630 4度C'!$A:$A,"新豐7線",'0630 4度C'!$B:$B,"平均") -> 115.28643 | H14: =SUMIFS('0630 4度C'!$N:$N,'0630 4度C'!$A:$A,"新豐3線",'0630 4度C'!$B:$B,"平均") -> 287.05905 | I14: =SUMIFS('0630 4度C'!$N:$N,'0630 4度C'!$A:$A,"新豐1線",'0630 4度C'!$B:$B,"平均") -> 114.52726 | J14: =SUMIFS('0630 4度C'!$N:$N,'0630 4度C'!$A:$A,"新豐10線",'0630 4度C'!$B:$B,"平均") -> 310.55738 | K14: =SUMIFS('0630 4度C'!$N:$N,'0630 4度C'!$A:$A,"新豐8線",'0630 4度C'!$B:$B,"平均") -> 131.34792 | L14: =SUMIFS('0630 4度C'!$N:$N,'0630 4度C'!$A:$A,"新豐9線",'0630 4度C'!$B:$B,"平均") -> 115.14921 | M14: =SUMIFS('0630 4度C'!$N:$N,'0630 4度C'!$A:$A,"新豐4線",'0630 4度C'!$B:$B,"平均") -> 151.03605
C15: 達成率 | D15: =D14/D13 -> 0.96480397 | E15: =E14/E13 -> 0.95568608 | F15: =F14/F13 -> 0.96266494 | G15: =G14/G13 -> 0.96072022 | H15: =H14/H13 -> 0.95686349 | I15: =I14/I13 -> 0.95712071 | J15: =J14/J13 -> 0.95755194 | K15: =K14/K13 -> 0.95774526 | ... M15: =M14/M13 -> 0.95296552
B16: 作業 時間 | C16: 開始 | D16: =VLOOKUP("新豐6線",'0630 4度C'!$A:$T,19,0) -> 0.70833333 | E16: =VLOOKUP("新豐2線",'0630 4度C'!$A:$T,19,0) -> 0.125 | F16: =VLOOKUP("新豐5線",'0630 4度C'!$A:$T,19,0) -> 0.083333333 | G16: =VLOOKUP("新豐7線",'0630 4度C'!$A:$T,19,0) -> 0.20833333 | H16: =VLOOKUP("新豐3線",'0630 4度C'!$A:$T,19,0) -> 0.20833333 | I16: =VLOOKUP("新豐1線",'0630 4度C'!$A:$T,19,0) -> 0.16666667 | J16: =VLOOKUP("新豐10線",'0630 4度C'!$A:$T,19,0) -> 0.20833333 | K16: =VLOOKUP("新豐8線",'0630 4度C'!$A:$T,19,0) -> 0.083333333 | L16: =VLOOKUP("新豐9線",'0630 4度C'!$A:$T,19,0) -> 0.083333333 | M16: =VLOOKUP("新豐4線",'0630 4度C'!$A:$T,19,0) -> 0.083333333
C17: 結束 | D17: =LOOKUP(2,1/(('0630 4度C'!$A:$A="新豐6線")*('0630 4度C'!$T:$T<>"")),'0630 4度C'!$T:$T) -> 0.89722222 | E17: =LOOKUP(2,1/(('0630 4度C'!$A:$A="新豐2線")*('0630 4度C'!$T:$T<>"")),'0630 4度C'!$T:$T) -> 0.65763889 | F17: =LOOKUP(2,1/(('0630 4度C'!$A:$A="新豐5線")*('0630 4度C'!$T:$T<>"")),'0630 4度C'!$T:$T) -> 0.79375 | G17: =LOOKUP(2,1/(('0630 4度C'!$A:$A="新豐7線")*('0630 4度C'!$T:$T<>"")),'0630 4度C'!$T:$T) -> 0.82777778 | H17: =LOOKUP(2,1/(('0630 4度C'!$A:$A="新豐3線")*('0630 4度C'!$T:$T<>"")),'0630 4度C'!$T:$T) -> 0.44513889 | I17: =LOOKUP(2,1/(('0630 4度C'!$A:$A="新豐1線")*('0630 4度C'!$T:$T<>"")),'0630 4度C'!$T:$T) -> 0.84236111 | J17: =LOOKUP(2,1/(('0630 4度C'!$A:$A="新豐10線")*('0630 4度C'!$T:$T<>"")),'0630 4度C'!$T:$T) -> 0.44583333 | K17: =LOOKUP(2,1/(('0630 4度C'!$A:$A="新豐8線")*('0630 4度C'!$T:$T<>"")),'0630 4度C'!$T:$T) -> 0.71944444 | L17: =LOOKUP(2,1/(('0630 4度C'!$A:$A="新豐9線")*('0630 4度C'!$T:$T<>"")),'0630 4度C'!$T:$T) -> 0.67291667 | M17: =LOOKUP(2,1/(('0630 4度C'!$A:$A="新豐4線")*('0630 4度C'!$T:$T<>"")),'0630 4度C'!$T:$T) -> 0.71180556
B18: 產線異常 (5分鐘以上) | C18: 次數 | D18: =SUMIFS('0630 4度C'!$Y:$Y,'0630 4度C'!$A:$A,"新豐6線",'0630 4度C'!$B:$B,"平均") -> 0 | E18: =SUMIFS('0630 4度C'!$Y:$Y,'0630 4度C'!$A:$A,"新豐2線",'0630 4度C'!$B:$B,"平均") -> 0 | F18: =SUMIFS('0630 4度C'!$Y:$Y,'0630 4度C'!$A:$A,"新豐5線",'0630 4度C'!$B:$B,"平均") -> 0 | G18: =SUMIFS('0630 4度C'!$Y:$Y,'0630 4度C'!$A:$A,"新豐7線",'0630 4度C'!$B:$B,"平均") -> 0 | H18: =SUMIFS('0630 4度C'!$Y:$Y,'0630 4度C'!$A:$A,"新豐3線",'0630 4度C'!$B:$B,"平均") -> 0 | I18: =SUMIFS('0630 4度C'!$Y:$Y,'0630 4度C'!$A:$A,"新豐1線",'0630 4度C'!$B:$B,"平均") -> 0 | J18: =SUMIFS('0630 4度C'!$Y:$Y,'0630 4度C'!$A:$A,"新豐10線",'0630 4度C'!$B:$B,"平均") -> 0 | K18: =SUMIFS('0630 4度C'!$Y:$Y,'0630 4度C'!$A:$A,"新豐8線",'0630 4度C'!$B:$B,"平均") -> 0 | L18: =SUMIFS('0630 4度C'!$Y:$Y,'0630 4度C'!$A:$A,"新豐9線",'0630 4度C'!$B:$B,"平均") -> 0 | M18: =SUMIFS('0630 4度C'!$Y:$Y,'0630 4度C'!$A:$A,"新豐4線",'0630 4度C'!$B:$B,"平均") -> 0
C19: 時間/分 | D19: =SUMIFS('0630 4度C'!$Z:$Z,'0630 4度C'!$A:$A,"新豐6線",'0630 4度C'!$B:$B,"平均") -> 0 | E19: =SUMIFS('0630 4度C'!$Z:$Z,'0630 4度C'!$A:$A,"新豐2線",'0630 4度C'!$B:$B,"平均") -> 0 | F19: =SUMIFS('0630 4度C'!$Z:$Z,'0630 4度C'!$A:$A,"新豐5線",'0630 4度C'!$B:$B,"平均") -> 0 | G19: =SUMIFS('0630 4度C'!$Z:$Z,'0630 4度C'!$A:$A,"新豐7線",'0630 4度C'!$B:$B,"平均") -> 0 | H19: =SUMIFS('0630 4度C'!$Z:$Z,'0630 4度C'!$A:$A,"新豐3線",'0630 4度C'!$B:$B,"平均") -> 0 | I19: =SUMIFS('0630 4度C'!$Z:$Z,'0630 4度C'!$A:$A,"新豐1線",'0630 4度C'!$B:$B,"平均") -> 0 | J19: =SUMIFS('0630 4度C'!$Z:$Z,'0630 4度C'!$A:$A,"新豐10線",'0630 4度C'!$B:$B,"平均") -> 0 | K19: =SUMIFS('0630 4度C'!$Z:$Z,'0630 4度C'!$A:$A,"新豐8線",'0630 4度C'!$B:$B,"平均") -> 0 | L19: =SUMIFS('0630 4度C'!$Z:$Z,'0630 4度C'!$A:$A,"新豐9線",'0630 4度C'!$B:$B,"平均") -> 0 | M19: =SUMIFS('0630 4度C'!$Z:$Z,'0630 4度C'!$A:$A,"新豐4線",'0630 4度C'!$B:$B,"平均") -> 0
B20: 短暫停線 (5分鐘以下) | C20: 次數 | D20: =SUMIFS('0630 4度C'!$AC:$AC,'0630 4度C'!$A:$A,"新豐6線",'0630 4度C'!$B:$B,"平均") -> 4 | E20: =SUMIFS('0630 4度C'!$AC:$AC,'0630 4度C'!$A:$A,"新豐2線",'0630 4度C'!$B:$B,"平均") -> 5 | F20: =SUMIFS('0630 4度C'!$AC:$AC,'0630 4度C'!$A:$A,"新豐5線",'0630 4度C'!$B:$B,"平均") -> 7 | G20: =SUMIFS('0630 4度C'!$AC:$AC,'0630 4度C'!$A:$A,"新豐7線",'0630 4度C'!$B:$B,"平均") -> 6 | H20: =SUMIFS('0630 4度C'!$AC:$AC,'0630 4度C'!$A:$A,"新豐3線",'0630 4度C'!$B:$B,"平均") -> 3 | I20: =SUMIFS('0630 4度C'!$AC:$AC,'0630 4度C'!$A:$A,"新豐1線",'0630 4度C'!$B:$B,"平均") -> 7 | J20: =SUMIFS('0630 4度C'!$AC:$AC,'0630 4度C'!$A:$A,"新豐10線",'0630 4度C'!$B:$B,"平均") -> 4 | K20: =SUMIFS('0630 4度C'!$AC:$AC,'0630 4度C'!$A:$A,"新豐8線",'0630 4度C'!$B:$B,"平均") -> 8 | L20: =SUMIFS('0630 4度C'!$AC:$AC,'0630 4度C'!$A:$A,"新豐9線",'0630 4度C'!$B:$B,"平均") -> 7 | M20: =SUMIFS('0630 4度C'!$AC:$AC,'0630 4度C'!$A:$A,"新豐4線",'0630 4度C'!$B:$B,"平均") -> 7
C21: 設備次數 | D21: =SUMIFS('0630 4度C'!$AD:$AD,'0630 4度C'!$A:$A,"新豐6線",'0630 4度C'!$B:$B,"平均") -> 0 | E21: =SUMIFS('0630 4度C'!$AD:$AD,'0630 4度C'!$A:$A,"新豐2線",'0630 4度C'!$B:$B,"平均") -> 0 | F21: =SUMIFS('0630 4度C'!$AD:$AD,'0630 4度C'!$A:$A,"新豐5線",'0630 4度C'!$B:$B,"平均") -> 0 | G21: =SUMIFS('0630 4度C'!$AD:$AD,'0630 4度C'!$A:$A,"新豐7線",'0630 4度C'!$B:$B,"平均") -> 0 | H21: =SUMIFS('0630 4度C'!$AD:$AD,'0630 4度C'!$A:$A,"新豐3線",'0630 4度C'!$B:$B,"平均") -> 0 | I21: =SUMIFS('0630 4度C'!$AD:$AD,'0630 4度C'!$A:$A,"新豐1線",'0630 4度C'!$B:$B,"平均") -> 0 | J21: =SUMIFS('0630 4度C'!$AD:$AD,'0630 4度C'!$A:$A,"新豐10線",'0630 4度C'!$B:$B,"平均") -> 0 | K21: =SUMIFS('0630 4度C'!$AD:$AD,'0630 4度C'!$A:$A,"新豐8線",'0630 4度C'!$B:$B,"平均") -> 0 | L21: =SUMIFS('0630 4度C'!$AD:$AD,'0630 4度C'!$A:$A,"新豐9線",'0630 4度C'!$B:$B,"平均") -> 0 | M21: =SUMIFS('0630 4度C'!$AD:$AD,'0630 4度C'!$A:$A,"新豐4線",'0630 4度C'!$B:$B,"平均") -> 0
B22: 配置人數 | D22: =SUMIFS('0630 4度C'!$I:$I,'0630 4度C'!$A:$A,"新豐6線",'0630 4度C'!$B:$B,"平均") -> 15.5 | E22: =SUMIFS('0630 4度C'!$I:$I,'0630 4度C'!$A:$A,"新豐2線",'0630 4度C'!$B:$B,"平均") -> 17.4 | F22: =SUMIFS('0630 4度C'!$I:$I,'0630 4度C'!$A:$A,"新豐5線",'0630 4度C'!$B:$B,"平均") -> 18.714286 | G22: =SUMIFS('0630 4度C'!$I:$I,'0630 4度C'!$A:$A,"新豐7線",'0630 4度C'!$B:$B,"平均") -> 16.666667 | H22: =SUMIFS('0630 4度C'!$I:$I,'0630 4度C'!$A:$A,"新豐3線",'0630 4度C'!$B:$B,"平均") -> 10 | I22: =SUMIFS('0630 4度C'!$I:$I,'0630 4度C'!$A:$A,"新豐1線",'0630 4度C'!$B:$B,"平均") -> 16.714286 | J22: =SUMIFS('0630 4度C'!$I:$I,'0630 4度C'!$A:$A,"新豐10線",'0630 4度C'!$B:$B,"平均") -> 9.25 | K22: =SUMIFS('0630 4度C'!$I:$I,'0630 4度C'!$A:$A,"新豐8線",'0630 4度C'!$B:$B,"平均") -> 17.5 | L22: =SUMIFS('0630 4度C'!$I:$I,'0630 4度C'!$A:$A,"新豐9線",'0630 4度C'!$B:$B,"平均") -> 18 | M22: =SUMIFS('0630 4度C'!$I:$I,'0630 4度C'!$A:$A,"新豐4線",'0630 4度C'!$B:$B,"平均") -> 15.142857
B23: 主要應用設備 | D23: ET-55 | E23: 熱縮爐 | F23: L型包裝機 | G23: L型包裝機 | H23: 伺服包裝機 | I23: ET-55 | J23: 伺服包裝機 | K23: 三明治包裝機 | L23: 三明治包裝機 | M23: 三明治包裝機
B24: 次要應用設備 | F24: 圓盤機 | G24: ET-55
B25: 備註 | E25: 握沙拉 | F25: 共用L型包裝機 | H25: 調理麵包 | I25: 炒飯+沙拉 | J25: 調理麵包

Sheet 0630 4度C
A1: 新豐廠四度C日報分析 | C1: 總生產量 | D1: =SUM(F5:F72) -> 183717 | E1: 營業額 | F1: =SUM(G5:G72) -> 6251108.9 | G1: 出勤人數 | H1: =L9+L15+L51+L59+L23+L64+L39+L47+L30+L72 -> 154.8881 | I1: 產線配置圖 | L1: 生產實績 | O1: 人時性差異分析 | S1: 日報登錄 | Y1: 合計 次數 | Z1: 合計 時間/分 | AA1: 產線異常 分析說明(5分鐘以上) | AC1: 合計 次數 | AD1: 合計 設備次數 | AE1: 產能差異分析
A2: 46203 | B2: 星期二 | C2: 人時性 | D2: =AVERAGE(N9,N15,N51,N59,N23,N64,N30,N39,N47,N72) -> 151.63496 | E2: 平均廠價 | F2: =F1/D1 -> 34.025751 | G2: 多次生產數 | H2: =COUNT(H5:H72) -> 10 | Y2: =SUM(Y9+Y15+Y23+Y30+Y39+Y47+Y51+Y59+Y64+Y72) -> 0 | Z2: =SUM(Z9+Z15+Z23+Z30+Z39+Z47+Z51+Z59+Z64+Z72) -> 0 | AC2: =SUM(AC9+AC15+AC23+AC30+AC39+AC47+AC51+AC59+AC64+AC72) -> 58 | AD2: =SUM(AD9+AD15+AD23+AD30+AD39+AD47+AD51+AD59+AD64+AD72) -> 0
A3: 線別 | B3: 品類 | C3: 品名 | E3: 廠價 | F3: 生產量 | G3: 營收 | H3: 多次 生產 | I3: 人數 | J3: 產能/時 | K3: 人時性 | L3: 人數 | M3: 產能/時 | N3: 人時性 | O3: 人數 | P3: 人時性 | Q3: 達成率 | R3: 達成率平均 | S3: 生產時間 | U3: 換線、休息/分 | V3: 稼動時間/分 | W3: 休息時間 | Y3: 產線異常統計 (5分鐘以上) | AA3: (新豐回填) | AC3: 短暫停線統計 (5分鐘以下) | AE3: 產能/時 | AF3: 達成率 | AG3: 達成率平均
S4: 開始 | T4: 結束 | W4: 開始 | X4: 結束 | Y4: 次數 | Z4: 時間/分 | AC4: 總次數 | AD4: 設備因素(次數)
A5: 新豐6線 | B5: 微波主食 | C5: 二配泰式綠咖哩雞 | E5: 50.67 | F5: 1546 | G5: =E5*F5 -> 78335.82 | I5: 15 | J5: 2000 | K5: =J5/I5 -> 133.33333 | L5: 15 | M5: =F5/V5*60 -> 1932.5 | N5: =M5/L5 -> 128.83333 | O5: =L5-I5 -> 0 | P5: =N5-K5 -> -4.5 | Q5: =N5/K5 -> 0.96625 | R5: =Q9 -> 0.96480397 | S5: 0.70833333 | T5: 0.74166667 | V5: =(T5-S5)*24*60 -> 48 | AC5: 4 | AE5: =M5-J5 -> -67.5 | AF5: =M5/J5 -> 0.96625 | AG5: =AF9 -> 0.96480397
A6: 新豐6線 | B6: 微波主食 | C6: 二配金咖哩果香甘口咖哩飯 | E6: 50.92 | F6: 2442 | G6: =E6*F6 -> 124346.64 | I6: 15 | J6: 2000 | K6: =J6/I6 -> 133.33333 | L6: 15 | M6: =F6/V6*60 -> 1927.8947 | N6: =M6/L6 -> 128.52632 | O6: =L6-I6 -> 0 | P6: =N6-K6 -> -4.8070175 | Q6: =N6/K6 -> 0.96394737 | S6: 0.74583333 | T6: 0.79861111 | U6: =IF(S6=TIME(17,0,0),"",(S6-T5)*24*60) -> 6 | V6: =(T6-S6)*24*60 -> 76 | AE6: =M6-J6 -> -72.105263 | AF6: =M6/J6 -> 0.96394737
A7: 新豐6線 | B7: 微波主食 | C7: 二配金咖哩濃厚辛口咖哩飯 | E7: 50.98 | F7: 1000 | G7: =E7*F7 -> 50980 | H7: 2 | I7: 16 | J7: 2000 | K7: =J7/I7 -> 125 | L7: 16 | M7: =F7/V7*60 -> 1935.4839 | N7: =M7/L7 -> 120.96774 | O7: =L7-I7 -> 0 | P7: =N7-K7 -> -4.0322581 | Q7: =N7/K7 -> 0.96774194 | S7: 0.80208333 | T7: 0.82361111 | U7: =IF(S7=TIME(17,0,0),"",(S7-T6)*24*60) -> 5 | V7: =(T7-S7)*24*60 -> 31 | W7: =T7 -> 0.82361111 | X7: =S8 -> 0.86458333 | AE7: =M7-J7 -> -64.516129 | AF7: =M7/J7 -> 0.96774194
A8: 新豐6線 | B8: 微波主食 | C8: 二配金咖哩濃厚辛口咖哩飯 | E8: 50.98 | F8: 1506 | G8: =E8*F8 -> 76775.88 | I8: 16 | J8: 2000 | K8: =J8/I8 -> 125 | L8: 16 | M8: =F8/V8*60 -> 1922.5532 | N8: =M8/L8 -> 120.15957 | O8: =L8-I8 -> 0 | P8: =N8-K8 -> -4.8404255 | Q8: =N8/K8 -> 0.9612766 | S8: 0.86458333 | T8: 0.89722222 | U8: =IF(S8=TIME(17,0,0),"",(S8-T7)*24*60) -> 59 | V8: =(T8-S8)*24*60 -> 47 | AE8: =M8-J8 -> -77.446809 | AF8: =M8/J8 -> 0.9612766
A9: 新豐6線 | B9: 平均 | I9: 15.5 | J9: 2000 | K9: =J9/I9 -> 129.03226 | L9: 15.5 | M9: =AVERAGE(M5:M8) -> 1929.6079 | N9: =M9/L9 -> 124.49084 | O9: =L9-I9 -> 0 | P9: =N9-K9 -> -4.5414226 | Q9: =N9/K9 -> 0.96480397 | Y9: =SUM(Y5:Y8) -> 0 | Z9: =SUM(Z5:Z8) -> 0 | AC9: 4 | AD9: =SUM(AD5:AD8) -> 0 | AE9: =M9-J9 -> -70.39205 | AF9: =M9/J9 -> 0.96480397
A10: 新豐2線 | B10: 沙拉 | C10: 青醬優格雞肉握沙拉(113年) | E10: 39.62 | F10: 3100 | G10: =E10*F10 -> 122822 | H10: 2 | I10: 19 | J10: 1500 | K10: =J10/I10 -> 78.947368 | L10: 19 | M10: =F10/V10*60 -> 1430.7692 | N10: =M10/L10 -> 75.303644 | O10: =L10-I10 -> 0 | P10: =N10-K10 -> -3.6437247 | Q10: =N10/K10 -> 0.95384615 | R10: =Q15 -> 0.95568608 | S10: 0.125 | T10: 0.21527778 | V10: =(T10-S10)*24*60 -> 130 | W10: =T10 -> 0.21527778 | X10: =S11 -> 0.23263889 | AC10: 5 | AE10: =M10-J10 -> -69.230769 | AF10: =M10/J10 -> 0.95384615 | AG10: =AF15 -> 0.95568608
A11: 新豐2線 | B11: 沙拉 | C11: 厚蛋時蔬握沙拉 | E11: 39.46 | F11: 3984 | G11: =E11*F11 -> 157208.64 | I11: 15 | J11: 1500 | K11: =J11/I11 -> 100 | L11: 15 | M11: =F11/V11*60 -> 1431.3772 | N11: =M11/L11 -> 95.42515 | O11: =L11-I11 -> 0 | P11: =N11-K11 -> -4.5748503 | Q11: =N11/K11 -> 0.9542515 | S11: 0.23263889 | T11: 0.34861111 | U11: =IF(S11=TIME(17,0,0),"",(S11-T10)*24*60) -> 25 | V11: =(T11-S11)*24*60 -> 167 | AE11: =M11-J11 -> -68.622754 | AF11: =M11/J11 -> 0.9542515
A12: 新豐2線 | B12: 沙拉 | C12: 青檸烤雞握沙拉(113年) | E12: 39.8 | F12: 4700 | G12: =E12*F12 -> 187060 | H12: 2 | I12: 17 | J12: 1500 | K12: =J12/I12 -> 88.235294 | L12: 17 | M12: =F12/V12*60 -> 1431.4721 | N12: =M12/L12 -> 84.20424 | O12: =L12-I12 -> 0 | P12: =N12-K12 -> -4.031054 | Q12: =N12/K12 -> 0.95431472 | S12: 0.35347222 | T12: 0.49027778 | U12: =IF(S12=TIME(17,0,0),"",(S12-T11)*24*60) -> 7 | V12: =(T12-S12)*24*60 -> 197 | W12: =T12 -> 0.49027778 | X12: =S13 -> 0.53194444 | AE12: =M12-J12 -> -68.527919 | AF12: =M12/J12 -> 0.95431472
A13: 新豐2線 | B13: 沙拉 | C13: 青檸烤雞握沙拉(113年) | E13: 39.8 | F13: 2469 | G13: =E13*F13 -> 98266.2 | I13: 17 | J13: 1500 | K13: =J13/I13 -> 88.235294 | L13: 17 | M13: =F13/V13*60 -> 1438.2524 | N13: =M13/L13 -> 84.603084 | O13: =L13-I13 -> 0 | P13: =N13-K13 -> -3.6322102 | Q13: =N13/K13 -> 0.95883495 | S13: 0.53194444 | T13: 0.60347222 | U13: =IF(S13=TIME(17,0,0),"",(S13-T12)*24*60) -> 60 | V13: =(T13-S13)*24*60 -> 103 | AE13: =M13-J13 -> -61.747573 | AF13: =M13/J13 -> 0.95883495
A14: 新豐2線 | B14: 沙拉 | C14: 青醬優格雞肉握沙拉(113年) | E14: 39.62 | F14: 1699 | G14: =E14*F14 -> 67314.38 | I14: 19 | J14: 1500 | K14: =J14/I14 -> 78.947368 | L14: 19 | M14: =F14/V14*60 -> 1435.7746 | N14: =M14/L14 -> 75.567087 | O14: =L14-I14 -> 0 | P14: =N14-K14 -> -3.3802817 | Q14: =N14/K14 -> 0.9571831 | S14: 0.60833333 | T14: 0.65763889 | U14: =IF(S14=TIME(17,0,0),"",(S14-T13)*24*60) -> 7 | V14: =(T14-S14)*24*60 -> 71 | AE14: =M14-J14 -> -64.225352 | AF14: =M14/J14 -> 0.9571831
A15: 新豐2線 | B15: 平均 | I15: 17.4 | J15: 1500 | K15: =J15/I15 -> 86.206897 | L15: 17.4 | M15: =AVERAGE(M10:M14) -> 1433.5291 | N15: =M15/L15 -> 82.386731 | O15: =L15-I15 -> 0 | P15: =N15-K15 -> -3.8201651 | Q15: =N15/K15 -> 0.95568608 | Y15: =SUM(Y10:Y14) -> 0 | Z15: =SUM(Z10:Z14) -> 0 | AC15: 5 | AD15: =SUM(AD10:AD14) -> 0 | AE15: =M15-J15 -> -66.470873 | AF15: =M15/J15 -> 0.95568608
A16: 新豐5線 | B16: 小吃 | C16: 香菇雞燉湯 | E16: 38.62 | F16: 2583 | G16: =E16*F16 -> 99755.46 | I16: 24 | J16: 1500 | K16: =J16/I16 -> 62.5 | L16: 24 | M16: =F16/V16*60 -> 1435 | N16: =M16/L16 -> 59.791667 | O16: =L16-I16 -> 0 | P16: =N16-K16 -> -2.7083333 | Q16: =N16/K16 -> 0.95666667 | R16: =Q23 -> 0.96266494 | S16: 0.083333333 | T16: 0.15833333 | V16: =(T16-S16)*24*60 -> 108 | W16: =T16 -> 0.15833333 | X16: =S17 -> 0.17638889 | AC16: 7 | AE16: =M16-J16 -> -65 | AF16: =M16/J16 -> 0.95666667 | AG16: =AF23 -> 0.96266494
A17: 新豐5線 | B17: 小吃 | C17: 剝皮辣椒雞湯 | E17: 41 | F17: 2212 | G17: =E17*F17 -> 90692 | I17: 26 | J17: 1500 | K17: =J17/I17 -> 57.692308 | L17: 26 | M17: =F17/V17*60 -> 1427.0968 | N17: =M17/L17 -> 54.888337 | O17: =L17-I17 -> 0 | P17: =N17-K17 -> -2.8039702 | Q17: =N17/K17 -> 0.95139785 | S17: 0.17638889 | T17: 0.24097222 | U17: =IF(S17=TIME(17,0,0),"",(S17-T16)*24*60) -> 26 | V17: =(T17-S17)*24*60 -> 93 | AE17: =M17-J17 -> -72.903226 | AF17: =M17/J17 -> 0.95139785
A18: 新豐5線 | B18: 微波主食 | C18: 香菇雞粥 | E18: 37.03 | F18: 3731 | G18: =E18*F18 -> 138158.93 | I18: 13 | J18: 1500 | K18: =J18/I18 -> 115.38462 | L18: 13 | M18: =F18/V18*60 -> 1425.8599 | N18: =M18/L18 -> 109.68153 | O18: =L18-I18 -> 0 | P18: =N18-K18 -> -5.7030867 | Q18: =N18/K18 -> 0.95057325 | S18: 0.24513889 | T18: 0.35416667 | U18: =IF(S18=TIME(17,0,0),"",(S18-T17)*24*60) -> 6 | V18: =(T18-S18)*24*60 -> 157 | AE18: =M18-J18 -> -74.140127 | AF18: =M18/J18 -> 0.95057325
A19: 新豐5線 | B19: 沙拉 | C19: 地瓜瓜握沙拉 | E19: 39.52 | F19: 3128 | G19: =E19*F19 -> 123618.56 | I19: 19 | J19: 1500 | K19: =J19/I19 -> 78.947368 | L19: 19 | M19: =F19/V19*60 -> 1432.6718 | N19: =M19/L19 -> 75.403777 | O19: =L19-I19 -> 0 | P19: =N19-K19 -> -3.5435918 | Q19: =N19/K19 -> 0.9551145 | S19: 0.35972222 | T19: 0.45069444 | U19: =IF(S19=TIME(17,0,0),"",(S19-T18)*24*60) -> 8 | V19: =(T19-S19)*24*60 -> 131 | AE19: =M19-J19 -> -67.328244 | AF19: =M19/J19 -> 0.9551145
A20: 新豐5線 | B20: 微波主食 | C20: 二配起司控培根白醬焗烤飯 | E20: 53.68 | F20: 1088 | G20: =E20*F20 -> 58403.84 | I20: 16 | J20: 1500 | K20: =J20/I20 -> 93.75 | L20: 16 | M20: =F20/V20*60 -> 1450.6667 | N20: =M20/L20 -> 90.666667 | O20: =L20-I20 -> 0 | P20: =N20-K20 -> -3.0833333 | Q20: =N20/K20 -> 0.96711111 | S20: 0.70833333 | T20: 0.73958333 | U20: =IF(S20=TIME(17,0,0),"",(S20-T19)*24*60) | V20: =(T20-S20)*24*60 -> 45 | AE20: =M20-J20 -> -49.333333 | AF20: =M20/J20 -> 0.96711111
A21: 新豐5線 | B21: 微波主食 | C21: 二配蔥爆牛肉燴飯 | E21: 52.86 | F21: 557 | G21: =E21*F21 -> 29443.02 | I21: 16 | J21: 2000 | K21: =J21/I21 -> 125 | L21: 16 | M21: =F21/V21*60 -> 1965.8824 | N21: =M21/L21 -> 122.86765 | O21: =L21-I21 -> 0 | P21: =N21-K21 -> -2.1323529 | Q21: =N21/K21 -> 0.98294118 | S21: 0.74375 | T21: 0.75555556 | U21: =IF(S21=TIME(17,0,0),"",(S21-T20)*24*60) -> 6 | V21: =(T21-S21)*24*60 -> 17 | AE21: =M21-J21 -> -34.117647 | AF21: =M21/J21 -> 0.98294118
A22: 新豐5線 | B22: 微波主食 | C22: 二配港式香滑嫩蛋牛肉燴飯 | E22: 50.67 | F22: 1579 | G22: =E22*F22 -> 80007.93 | I22: 17 | J22: 2000 | K22: =J22/I22 -> 117.64706 | L22: 17 | M22: =F22/V22*60 -> 1933.4694 | N22: =M22/L22 -> 113.73349 | O22: =L22-I22 -> 0 | P22: =N22-K22 -> -3.9135654 | Q22: =N22/K22 -> 0.96673469 | S22: 0.75972222 | T22: 0.79375 | U22: =IF(S22=TIME(17,0,0),"",(S22-T21)*24*60) -> 6 | V22: =(T22-S22)*24*60 -> 49 | AE22: =M22-J22 -> -66.530612 | AF22: =M22/J22 -> 0.96673469
A23: 新豐5線 | B23: 平均 | I23: 18.714286 | J23: 1642.8571 | K23: =J23/I23 -> 87.78626 | L23: 18.714286 | M23: =AVERAGE(M16:M22) -> 1581.521 | N23: =M23/L23 -> 84.508754 | O23: =L23-I23 -> 0 | P23: =N23-K23 -> -3.2775053 | Q23: =N23/K23 -> 0.96266494 | Y23: =SUM(Y16:Y22) -> 0 | Z23: =SUM(Z16:Z22) -> 0 | AC23: 7 | AD23: =SUM(AD16:AD22) -> 0 | AE23: =M23-J23 -> -61.33617 | AF23: =M23/J23 -> 0.96266494
A24: 新豐7線 | B24: 微波主食 | C24: 韓式泡菜豬肉豆腐丼飯 | E24: 50.67 | F24: 2180 | G24: =E24*F24 -> 110460.6 | I24: 17 | J24: 2000 | K24: =J24/I24 -> 117.64706 | L24: 17 | M24: =F24/V24*60 -> 1923.5294 | N24: =M24/L24 -> 113.14879 | O24: =L24-I24 -> 0 | P24: =N24-K24 -> -4.4982699 | Q24: =N24/K24 -> 0.96176471 | R24: =Q30 -> 0.96072022 | S24: 0.20833333 | T24: 0.25555556 | V24: =(T24-S24)*24*60 -> 68 | AC24: 6 | AE24: =M24-J24 -> -76.470588 | AF24: =M24/J24 -> 0.96176471 | AG24: =AF30 -> 0.96072022
A25: 新豐7線 | B25: 微波主食 | C25: 鐵板滑蛋炸豬排丼 | E25: 57.73 | F25: 2718 | G25: =E25*F25 -> 156910.14 | I25: 14 | J25: 2000 | K25: =J25/I25 -> 142.85714 | L25: 14 | M25: =F25/V25*60 -> 1918.5882 | N25: =M25/L25 -> 137.04202 | O25: =L25-I25 -> 0 | P25: =N25-K25 -> -5.8151261 | Q25: =N25/K25 -> 0.95929412 | S25: 0.25902778 | T25: 0.31805556 | U25: =IF(S25=TIME(17,0,0),"",(S25-T24)*24*60) -> 5 | V25: =(T25-S25)*24*60 -> 85 | AE25: =M25-J25 -> -81.411765 | AF25: =M25/J25 -> 0.95929412
A26: 新豐7線 | B26: 微波主食 | C26: 日式炙烤親子丼 | E26: 53.27 | F26: 1897 | G26: =E26*F26 -> 101053.19 | I26: 16 | J26: 2000 | K26: =J26/I26 -> 125 | L26: 16 | M26: =F26/V26*60 -> 1929.1525 | N26: =M26/L26 -> 120.57203 | O26: =L26-I26 -> 0 | P26: =N26-K26 -> -4.4279661 | Q26: =N26/K26 -> 0.96457627 | S26: 0.32152778 | T26: 0.3625 | U26: =IF(S26=TIME(17,0,0),"",(S26-T25)*24*60) -> 5 | V26: =(T26-S26)*24*60 -> 59 | AE26: =M26-J26 -> -70.847458 | AF26: =M26/J26 -> 0.96457627
A27: 新豐7線 | B27: 微波主食 | C27: 炙烤醬香燒豚飯 | E27: 51.44 | F27: 2269 | G27: =E27*F27 -> 116717.36 | I27: 25 | J27: 2000 | K27: =J27/I27 -> 80 | L27: 25 | M27: =F27/V27*60 -> 1917.4648 | N27: =M27/L27 -> 76.698592 | O27: =L27-I27 -> 0 | P27: =N27-K27 -> -3.3014085 | Q27: =N27/K27 -> 0.95873239 | S27: 0.36597222 | T27: 0.41527778 | U27: =IF(S27=TIME(17,0,0),"",(S27-T26)*24*60) -> 5 | V27: =(T27-S27)*24*60 -> 71 | AE27: =M27-J27 -> -82.535211 | AF27: =M27/J27 -> 0.95873239
A28: 新豐7線 | B28: 微波主食 | C28: 二配川味麻婆燒豆腐燴飯 | E28: 50.49 | F28: 2076 | G28: =E28*F28 -> 104817.24 | I28: 15 | J28: 2000 | K28: =J28/I28 -> 133.33333 | L28: 15 | M28: =F28/V28*60 -> 1916.3077 | N28: =M28/L28 -> 127.75385 | O28: =L28-I28 -> 0 | P28: =N28-K28 -> -5.5794872 | Q28: =N28/K28 -> 0.95815385 | S28: 0.70833333 | T28: 0.75347222 | U28: =IF(S28=TIME(17,0,0),"",(S28-T27)*24*60) | V28: =(T28-S28)*24*60 -> 65 | AE28: =M28-J28 -> -83.692308 | AF28: =M28/J28 -> 0.95815385
A29: 新豐7線 | B29: 微波主食 | C29: 二配打拋風味豬肉飯 | E29: 51.06 | F29: 3206 | G29: =E29*F29 -> 163698.36 | I29: 13 | J29: 2000 | K29: =J29/I29 -> 153.84615 | L29: 13 | M29: =F29/V29*60 -> 1923.6 | N29: =M29/L29 -> 147.96923 | O29: =L29-I29 -> 0 | P29: =N29-K29 -> -5.8769231 | Q29: =N29/K29 -> 0.9618 | S29: 0.75833333 | T29: 0.82777778 | U29: =IF(S29=TIME(17,0,0),"",(S29-T28)*24*60) -> 7 | V29: =(T29-S29)*24*60 -> 100 | AE29: =M29-J29 -> -76.4 | AF29: =M29/J29 -> 0.9618
A30: 新豐7線 | B30: 平均 | I30: 16.666667 | J30: 2000 | K30: =J30/I30 -> 120 | L30: 16.666667 | M30: =AVERAGE(M24:M29) -> 1921.4404 | N30: =M30/L30 -> 115.28643 | O30: =L30-I30 -> 0 | P30: =N30-K30 -> -4.7135733 | Q30: =N30/K30 -> 0.96072022 | Y30: =SUM(Y24:Y29) -> 0 | Z30: =SUM(Z24:Z29) -> 0 | AC30: 6 | AD30: =SUM(AD24:AD29) -> 0 | AE30: =M30-J30 -> -78.559555 | AF30: =M30/J30 -> 0.96072022
A31: 新豐8線 | B31: 三明治 | C31: 紐奧良風味烤雞鮮蔬三明治 | E31: 31.29 | F31: 5800 | G31: =E31*F31 -> 181482 | H31: 2 | I31: 18 | J31: 2400 | K31: =J31/I31 -> 133.33333 | L31: 18 | M31: =F31/V31*60 -> 2289.4737 | N31: =M31/L31 -> 127.19298 | O31: =L31-I31 -> 0 | P31: =N31-K31 -> -6.1403509 | Q31: =N31/K31 -> 0.95394737 | R31: =Q39 -> 0.95774526 | S31: 0.083333333 | T31: 0.18888889 | V31: =(T31-S31)*24*60 -> 152 | W31: =T31 -> 0.18888889 | X31: =S32 -> 0.20833333 | AC31: 8 | AE31: =M31-J31 -> -110.52632 | AF31: =M31/J31 -> 0.95394737 | AG31: =AF39 -> 0.95774526
A32: 新豐8線 | B32: 三明治 | C32: 醬燒烤雞三明治(115年) | E32: 26.37 | F32: 3900 | G32: =E32*F32 -> 102843 | H32: 2 | I32: 18 | J32: 2400 | K32: =J32/I32 -> 133.33333 | L32: 18 | M32: =F32/V32*60 -> 2294.1176 | N32: =M32/L32 -> 127.45098 | O32: =L32-I32 -> 0 | P32: =N32-K32 -> -5.8823529 | Q32: =N32/K32 -> 0.95588235 | S32: 0.20833333 | T32: 0.27916667 | U32: =(S32-T31)*24*60 -> 28 | V32: =(T32-S32)*24*60 -> 102 | AE32: =M32-J32 -> -105.88235 | AF32: =M32/J32 -> 0.95588235
A33: 新豐8線 | B33: 三明治 | C33: 鮪魚起司溏心蛋三明治(115年) | E33: 26.18 | F33: 4700 | G33: =E33*F33 -> 123046 | H33: 2 | I33: 18 | J33: 2400 | K33: =J33/I33 -> 133.33333 | L33: 18 | M33: =F33/V33*60 -> 2292.6829 | N33: =M33/L33 -> 127.37127 | O33: =L33-I33 -> 0 | P33: =N33-K33 -> -5.9620596 | Q33: =N33/K33 -> 0.95528455 | S33: 0.28263889 | T33: 0.36805556 | U33: =(S33-T32)*24*60 -> 5 | V33: =(T33-S33)*24*60 -> 123 | AE33: =M33-J33 -> -107.31707 | AF33: =M33/J33 -> 0.95528455
A34: 新豐8線 | B34: 三明治 | C34: 茄汁厚起司三明治 | E34: 25.99 | F34: 1778 | G34: =E34*F34 -> 46210.22 | I34: 18 | J34: 2400 | K34: =J34/I34 -> 133.33333 | L34: 18 | M34: =F34/V34*60 -> 2319.1304 | N34: =M34/L34 -> 128.84058 | O34: =L34-I34 -> 0 | P34: =N34-K34 -> -4.4927536 | Q34: =N34/K34 -> 0.96630435 | S34: 0.37291667 | T34: 0.40486111 | U34: =(S34-T33)*24*60 -> 7 | V34: =(T34-S34)*24*60 -> 46 | AE34: =M34-J34 -> -80.869565 | AF34: =M34/J34 -> 0.96630435
A35: 新豐8線 | B35: 三明治 | C35: 雞蛋沙拉三明治(114年) | E35: 25.99 | F35: 4394 | G35: =E35*F35 -> 114200.06 | I35: 14 | J35: 2400 | K35: =J35/I35 -> 171.42857 | L35: 14 | M35: =F35/V35*60 -> 2292.5217 | N35: =M35/L35 -> 163.75155 | O35: =L35-I35 -> 0 | P35: =N35-K35 -> -7.6770186 | Q35: =N35/K35 -> 0.95521739 | S35: 0.40833333 | T35: 0.48819444 | U35: =(S35-T34)*24*60 -> 5 | V35: =(T35-S35)*24*60 -> 115 | W35: =T35 -> 0.48819444 | X35: =S36 -> 0.52916667 | AE35: =M35-J35 -> -107.47826 | AF35: =M35/J35 -> 0.95521739
A36: 新豐8線 | B36: 三明治 | C36: 鮪魚起司溏心蛋三明治(115年) | E36: 26.18 | F36: 3576 | G36: =E36*F36 -> 93619.68 | I36: 18 | J36: 2400 | K36: =J36/I36 -> 133.33333 | L36: 18 | M36: =F36/V36*60 -> 2307.0968 | N36: =M36/L36 -> 128.17204 | O36: =L36-I36 -> 0 | P36: =N36-K36 -> -5.1612903 | Q36: =N36/K36 -> 0.96129032 | S36: 0.52916667 | T36: 0.59375 | U36: =(S36-T35)*24*60 -> 59 | V36: =(T36-S36)*24*60 -> 93 | AE36: =M36-J36 -> -92.903226 | AF36: =M36/J36 -> 0.96129032
A37: 新豐8線 | B37: 三明治 | C37: 醬燒烤雞三明治(115年) | E37: 26.37 | F37: 2679 | G37: =E37*F37 -> 70645.23 | I37: 18 | J37: 2400 | K37: =J37/I37 -> 133.33333 | L37: 18 | M37: =F37/V37*60 -> 2296.2857 | N37: =M37/L37 -> 127.57143 | O37: =L37-I37 -> 0 | P37: =N37-K37 -> -5.7619048 | Q37: =N37/K37 -> 0.95678571 | S37: 0.59791667 | T37: 0.64652778 | U37: =(S37-T36)*24*60 -> 6 | V37: =(T37-S37)*24*60 -> 70 | AE37: =M37-J37 -> -103.71429 | AF37: =M37/J37 -> 0.95678571
A38: 新豐8線 | B38: 三明治 | C38: 紐奧良風味烤雞鮮蔬三明治 | E38: 31.29 | F38: 3829 | G38: =E38*F38 -> 119809.41 | I38: 18 | J38: 2400 | K38: =J38/I38 -> 133.33333 | L38: 18 | M38: =F38/V38*60 -> 2297.4 | N38: =M38/L38 -> 127.63333 | O38: =L38-I38 -> 0 | P38: =N38-K38 -> -5.7 | Q38: =N38/K38 -> 0.95725 | S38: 0.65 | T38: 0.71944444 | U38: =(S38-T37)*24*60 -> 5 | V38: =(T38-S38)*24*60 -> 100 | AE38: =M38-J38 -> -102.6 | AF38: =M38/J38 -> 0.95725
A39: 新豐8線 | B39: 平均 | I39: 17.5 | J39: 2400 | K39: =J39/I39 -> 137.14286 | L39: 17.5 | M39: =AVERAGE(M31:M38) -> 2298.5886 | N39: =M39/L39 -> 131.34792 | O39: =L39-I39 -> 0 | P39: =N39-K39 -> -5.7949363 | Q39: =N39/K39 -> 0.95774526 | Y39: =SUM(Y31:Y38) -> 0 | Z39: =SUM(Z31:Z38) -> 0 | AC39: 8 | AD39: =SUM(AD31:AD38) -> 0 | AE39: =M39-J39 -> -101.41138 | AF39: =M39/J39 -> 0.95774526
A40: 新豐9線 | B40: 三明治 | C40: 經典總匯三明治(115年) | E40: 26.18 | F40: 3800 | G40: =E40*F40 -> 99484 | H40: 2 | I40: 20 | J40: 2400 | K40: =J40/I40 -> 120 | L40: 20 | M40: =F40/V40*60 -> 2303.0303 | N40: =M40/L40 -> 115.15152 | O40: =L40-I40 -> 0 | P40: =N40-K40 -> -4.8484848 | Q40: =N40/K40 -> 0.95959596 | R40: =Q47 -> 0.95452636 | S40: 0.083333333 | T40: 0.15208333 | V40: =(T40-S40)*24*60 -> 99 | W40: =T40 -> 0.15208333 | X40: =S41 -> 0.17083333 | AC40: 7 | AE40: =M40-J40 -> -96.969697 | AF40: =M40/J40 -> 0.95959596 | AG40: =AF47 -> 0.95452636
...

Sheet 0629
B1: 屏榮 新豐廠組合室生產人時性分析
B3: 日期 | C3: =TEXT('0629 4度C'!A2,"yyyy.mm.ddaaaa") -> 2026.06.29星期一 | E3: 訂單量 | F3: ='0629 4度C'!D1 -> 196622 | H3: 營業額 | I3: ='0629 4度C'!F1 -> 6758725.1
B4: 人時性 | C4: 項目 | E4: ➀ | G4: ➁ | I4: ➂ | K4: 異常停線 | M4: 短暫停線
C5: 組合室 | E5: 全溫層 | G5: 4度C-各編組展開 | I5: ③三明治-各編組展開 | K5: 合計次數 | L5: 時間 | M5: 合計次數 | N5: 設備次數
C6: 排關平均 | E6: =AVERAGE(D13:M13) -> 158.32762 | F6: =AVERAGE(D31:O31,D13:J13) -> 166.71541 | G6: =AVERAGE(D13:J13) -> 166.71541 | I6: =AVERAGE(K13:M13) -> 138.75611 | K6: ='0629 4度C'!Y2 -> 0 | L6: ='0629 4度C'!Z2 -> 0 | M6: ='0629 4度C'!AC2 -> 58 | N6: ='0629 4度C'!AD2 -> 0
C7: 實績平均 | E7: =AVERAGE(D14:M14) -> 151.50654 | F7: =AVERAGE(D32:O32,D14:J14) -> 159.57359 | G7: =AVERAGE(D14:J14) -> 159.57359 | I7: =AVERAGE(K14:M14) -> 132.68343
C8: 達成率平均 | E8: =AVERAGE(D15:M15) -> 0.95736809 | F8: =AVERAGE(D15:J15,D33:O33) -> 0.95781634 | G8: =AVERAGE(D15:J15) -> 0.95781634 | I8: =AVERAGE(K15:M15) -> 0.95632219
K9: ※現行日本鮮食廠以達成率80%為基本(即為現行KPI)
B10: 溫層 | D10: ➁4度C-各編組展開 | K10: ③三明治-各編組展開
B11: 編組 | D11: 1 | E11: 2 | F11: 3 | G11: 4 | H11: 5 | I11: 6 | J11: 7 | K11: 1 | L11: 2 | M11: 3
D12: 新豐6線 | E12: 新豐2線 | F12: 新豐5線 | G12: 新豐7線 | H12: 新豐3線 | I12: 新豐1線 | J12: 新豐10線 | K12: 新豐8線 | L12: 新豐9線 | M12: 新豐4線
B13: 人時性 | C13: 排關 | D13: =SUMIFS('0629 4度C'!$K:$K,'0629 4度C'!$A:$A,"新豐6線",'0629 4度C'!$B:$B,"平均") -> 129.03226 | E13: =SUMIFS('0629 4度C'!$K:$K,'0629 4度C'!$A:$A,"新豐2線",'0629 4度C'!$B:$B,"平均") -> 86.206897 | F13: =SUMIFS('0629 4度C'!$K:$K,'0629 4度C'!$A:$A,"新豐5線",'0629 4度C'!$B:$B,"平均") -> 87.78626 | G13: =SUMIFS('0629 4度C'!$K:$K,'0629 4度C'!$A:$A,"新豐7線",'0629 4度C'!$B:$B,"平均") -> 120 | H13: =SUMIFS('0629 4度C'!$K:$K,'0629 4度C'!$A:$A,"新豐3線",'0629 4度C'!$B:$B,"平均") -> 300 | I13: =SUMIFS('0629 4度C'!$K:$K,'0629 4度C'!$A:$A,"新豐1線",'0629 4度C'!$B:$B,"平均") -> 119.65812 | J13: =SUMIFS('0629 4度C'!$K:$K,'0629 4度C'!$A:$A,"新豐10線",'0629 4度C'!$B:$B,"平均") -> 324.32432 | K13: =SUMIFS('0629 4度C'!$K:$K,'0629 4度C'!$A:$A,"新豐8線",'0629 4度C'!$B:$B,"平均") -> 137.14286 | L13: =SUMIFS('0629 4度C'!$K:$K,'0629 4度C'!$A:$A,"新豐9線",'0629 4度C'!$B:$B,"平均") -> 120.63492 | M13: =SUMIFS('0629 4度C'!$K:$K,'0629 4度C'!$A:$A,"新豐4線",'0629 4度C'!$B:$B,"平均") -> 158.49057
C14: 實績 | D14: =SUMIFS('0629 4度C'!$N:$N,'0629 4度C'!$A:$A,"新豐6線",'0629 4度C'!$B:$B,"平均") -> 124.01449 | E14: =SUMIFS('0629 4度C'!$N:$N,'0629 4度C'!$A:$A,"新豐2線",'0629 4度C'!$B:$B,"平均") -> 82.248168 | F14: =SUMIFS('0629 4度C'!$N:$N,'0629 4度C'!$A:$A,"新豐5線",'0629 4度C'!$B:$B,"平均") -> 84.377484 | G14: =SUMIFS('0629 4度C'!$N:$N,'0629 4度C'!$A:$A,"新豐7線",'0629 4度C'!$B:$B,"平均") -> 115.09602 | H14: =SUMIFS('0629 4度C'!$N:$N,'0629 4度C'!$A:$A,"新豐3線",'0629 4度C'!$B:$B,"平均") -> 286.74087 | I14: =SUMIFS('0629 4度C'!$N:$N,'0629 4度C'!$A:$A,"新豐1線",'0629 4度C'!$B:$B,"平均") -> 114.60878 | J14: =SUMIFS('0629 4度C'!$N:$N,'0629 4度C'!$A:$A,"新豐10線",'0629 4度C'!$B:$B,"平均") -> 309.92928 | K14: =SUMIFS('0629 4度C'!$N:$N,'0629 4度C'!$A:$A,"新豐8線",'0629 4度C'!$B:$B,"平均") -> 131.39031 | L14: =SUMIFS('0629 4度C'!$N:$N,'0629 4度C'!$A:$A,"新豐9線",'0629 4度C'!$B:$B,"平均") -> 115.36389 | M14: =SUMIFS('0629 4度C'!$N:$N,'0629 4度C'!$A:$A,"新豐4線",'0629 4度C'!$B:$B,"平均") -> 151.29609
C15: 達成率 | D15: =D14/D13 -> 0.96111234 | E15: =E14/E13 -> 0.95407875 | F15: =F14/F13 -> 0.9611696 | G15: =G14/G13 -> 0.95913351 | H15: =H14/H13 -> 0.95580289 | I15: =I14/I13 -> 0.95780198 | J15: =J14/J13 -> 0.95561528 | K15: =K14/K13 -> 0.95805436 | ... M15: =M14/M13 -> 0.95460627
B16: 作業 時間 | C16: 開始 | D16: =VLOOKUP("新豐6線",'0629 4度C'!$A:$T,19,0) -> 0.70833333 | E16: =VLOOKUP("新豐2線",'0629 4度C'!$A:$T,19,0) -> 0.125 | F16: =VLOOKUP("新豐5線",'0629 4度C'!$A:$T,19,0) -> 0.083333333 | G16: =VLOOKUP("新豐7線",'0629 4度C'!$A:$T,19,0) -> 0.20833333 | H16: =VLOOKUP("新豐3線",'0629 4度C'!$A:$T,19,0) -> 0.20833333 | I16: =VLOOKUP("新豐1線",'0629 4度C'!$A:$T,19,0) -> 0.16666667 | J16: =VLOOKUP("新豐10線",'0629 4度C'!$A:$T,19,0) -> 0.20833333 | K16: =VLOOKUP("新豐8線",'0629 4度C'!$A:$T,19,0) -> 0.083333333 | L16: =VLOOKUP("新豐9線",'0629 4度C'!$A:$T,19,0) -> 0.083333333 | M16: =VLOOKUP("新豐4線",'0629 4度C'!$A:$T,19,0) -> 0.083333333
C17: 結束 | D17: =LOOKUP(2,1/(('0629 4度C'!$A:$A="新豐6線")*('0629 4度C'!$T:$T<>"")),'0629 4度C'!$T:$T) -> 0.90208333 | E17: =LOOKUP(2,1/(('0629 4度C'!$A:$A="新豐2線")*('0629 4度C'!$T:$T<>"")),'0629 4度C'!$T:$T) -> 0.73541667 | F17: =LOOKUP(2,1/(('0629 4度C'!$A:$A="新豐5線")*('0629 4度C'!$T:$T<>"")),'0629 4度C'!$T:$T) -> 0.81527778 | G17: =LOOKUP(2,1/(('0629 4度C'!$A:$A="新豐7線")*('0629 4度C'!$T:$T<>"")),'0629 4度C'!$T:$T) -> 0.83611111 | H17: =LOOKUP(2,1/(('0629 4度C'!$A:$A="新豐3線")*('0629 4度C'!$T:$T<>"")),'0629 4度C'!$T:$T) -> 0.4625 | I17: =LOOKUP(2,1/(('0629 4度C'!$A:$A="新豐1線")*('0629 4度C'!$T:$T<>"")),'0629 4度C'!$T:$T) -> 0.84930556 | J17: =LOOKUP(2,1/(('0629 4度C'!$A:$A="新豐10線")*('0629 4度C'!$T:$T<>"")),'0629 4度C'!$T:$T) -> 0.45625 | K17: =LOOKUP(2,1/(('0629 4度C'!$A:$A="新豐8線")*('0629 4度C'!$T:$T<>"")),'0629 4度C'!$T:$T) -> 0.73611111 | L17: =LOOKUP(2,1/(('0629 4度C'!$A:$A="新豐9線")*('0629 4度C'!$T:$T<>"")),'0629 4度C'!$T:$T) -> 0.69027778 | M17: =LOOKUP(2,1/(('0629 4度C'!$A:$A="新豐4線")*('0629 4度C'!$T:$T<>"")),'0629 4度C'!$T:$T) -> 0.7125
B18: 產線異常 (5分鐘以上) | C18: 次數 | D18: =SUMIFS('0629 4度C'!$Y:$Y,'0629 4度C'!$A:$A,"新豐6線",'0629 4度C'!$B:$B,"平均") -> 0 | E18: =SUMIFS('0629 4度C'!$Y:$Y,'0629 4度C'!$A:$A,"新豐2線",'0629 4度C'!$B:$B,"平均") -> 0 | F18: =SUMIFS('0629 4度C'!$Y:$Y,'0629 4度C'!$A:$A,"新豐5線",'0629 4度C'!$B:$B,"平均") -> 0 | G18: =SUMIFS('0629 4度C'!$Y:$Y,'0629 4度C'!$A:$A,"新豐7線",'0629 4度C'!$B:$B,"平均") -> 0 | H18: =SUMIFS('0629 4度C'!$Y:$Y,'0629 4度C'!$A:$A,"新豐3線",'0629 4度C'!$B:$B,"平均") -> 0 | I18: =SUMIFS('0629 4度C'!$Y:$Y,'0629 4度C'!$A:$A,"新豐1線",'0629 4度C'!$B:$B,"平均") -> 0 | J18: =SUMIFS('0629 4度C'!$Y:$Y,'0629 4度C'!$A:$A,"新豐10線",'0629 4度C'!$B:$B,"平均") -> 0 | K18: =SUMIFS('0629 4度C'!$Y:$Y,'0629 4度C'!$A:$A,"新豐8線",'0629 4度C'!$B:$B,"平均") -> 0 | L18: =SUMIFS('0629 4度C'!$Y:$Y,'0629 4度C'!$A:$A,"新豐9線",'0629 4度C'!$B:$B,"平均") -> 0 | M18: =SUMIFS('0629 4度C'!$Y:$Y,'0629 4度C'!$A:$A,"新豐4線",'0629 4度C'!$B:$B,"平均") -> 0
C19: 時間/分 | D19: =SUMIFS('0629 4度C'!$Z:$Z,'0629 4度C'!$A:$A,"新豐6線",'0629 4度C'!$B:$B,"平均") -> 0 | E19: =SUMIFS('0629 4度C'!$Z:$Z,'0629 4度C'!$A:$A,"新豐2線",'0629 4度C'!$B:$B,"平均") -> 0 | F19: =SUMIFS('0629 4度C'!$Z:$Z,'0629 4度C'!$A:$A,"新豐5線",'0629 4度C'!$B:$B,"平均") -> 0 | G19: =SUMIFS('0629 4度C'!$Z:$Z,'0629 4度C'!$A:$A,"新豐7線",'0629 4度C'!$B:$B,"平均") -> 0 | H19: =SUMIFS('0629 4度C'!$Z:$Z,'0629 4度C'!$A:$A,"新豐3線",'0629 4度C'!$B:$B,"平均") -> 0 | I19: =SUMIFS('0629 4度C'!$Z:$Z,'0629 4度C'!$A:$A,"新豐1線",'0629 4度C'!$B:$B,"平均") -> 0 | J19: =SUMIFS('0629 4度C'!$Z:$Z,'0629 4度C'!$A:$A,"新豐10線",'0629 4度C'!$B:$B,"平均") -> 0 | K19: =SUMIFS('0629 4度C'!$Z:$Z,'0629 4度C'!$A:$A,"新豐8線",'0629 4度C'!$B:$B,"平均") -> 0 | L19: =SUMIFS('0629 4度C'!$Z:$Z,'0629 4度C'!$A:$A,"新豐9線",'0629 4度C'!$B:$B,"平均") -> 0 | M19: =SUMIFS('0629 4度C'!$Z:$Z,'0629 4度C'!$A:$A,"新豐4線",'0629 4度C'!$B:$B,"平均") -> 0
B20: 短暫停線 (5分鐘以下) | C20: 次數 | D20: =SUMIFS('0629 4度C'!$AC:$AC,'0629 4度C'!$A:$A,"新豐6線",'0629 4度C'!$B:$B,"平均") -> 4 | E20: =SUMIFS('0629 4度C'!$AC:$AC,'0629 4度C'!$A:$A,"新豐2線",'0629 4度C'!$B:$B,"平均") -> 5 | F20: =SUMIFS('0629 4度C'!$AC:$AC,'0629 4度C'!$A:$A,"新豐5線",'0629 4度C'!$B:$B,"平均") -> 7 | G20: =SUMIFS('0629 4度C'!$AC:$AC,'0629 4度C'!$A:$A,"新豐7線",'0629 4度C'!$B:$B,"平均") -> 6 | H20: =SUMIFS('0629 4度C'!$AC:$AC,'0629 4度C'!$A:$A,"新豐3線",'0629 4度C'!$B:$B,"平均") -> 3 | I20: =SUMIFS('0629 4度C'!$AC:$AC,'0629 4度C'!$A:$A,"新豐1線",'0629 4度C'!$B:$B,"平均") -> 7 | J20: =SUMIFS('0629 4度C'!$AC:$AC,'0629 4度C'!$A:$A,"新豐10線",'0629 4度C'!$B:$B,"平均") -> 4 | K20: =SUMIFS('0629 4度C'!$AC:$AC,'0629 4度C'!$A:$A,"新豐8線",'0629 4度C'!$B:$B,"平均") -> 8 | L20: =SUMIFS('0629 4度C'!$AC:$AC,'0629 4度C'!$A:$A,"新豐9線",'0629 4度C'!$B:$B,"平均") -> 7 | M20: =SUMIFS('0629 4度C'!$AC:$AC,'0629 4度C'!$A:$A,"新豐4線",'0629 4度C'!$B:$B,"平均") -> 7
C21: 設備次數 | D21: =SUMIFS('0629 4度C'!$AD:$AD,'0629 4度C'!$A:$A,"新豐6線",'0629 4度C'!$B:$B,"平均") -> 0 | E21: =SUMIFS('0629 4度C'!$AD:$AD,'0629 4度C'!$A:$A,"新豐2線",'0629 4度C'!$B:$B,"平均") -> 0 | F21: =SUMIFS('0629 4度C'!$AD:$AD,'0629 4度C'!$A:$A,"新豐5線",'0629 4度C'!$B:$B,"平均") -> 0 | G21: =SUMIFS('0629 4度C'!$AD:$AD,'0629 4度C'!$A:$A,"新豐7線",'0629 4度C'!$B:$B,"平均") -> 0 | H21: =SUMIFS('0629 4度C'!$AD:$AD,'0629 4度C'!$A:$A,"新豐3線",'0629 4度C'!$B:$B,"平均") -> 0 | I21: =SUMIFS('0629 4度C'!$AD:$AD,'0629 4度C'!$A:$A,"新豐1線",'0629 4度C'!$B:$B,"平均") -> 0 | J21: =SUMIFS('0629 4度C'!$AD:$AD,'0629 4度C'!$A:$A,"新豐10線",'0629 4度C'!$B:$B,"平均") -> 0 | K21: =SUMIFS('0629 4度C'!$AD:$AD,'0629 4度C'!$A:$A,"新豐8線",'0629 4度C'!$B:$B,"平均") -> 0 | L21: =SUMIFS('0629 4度C'!$AD:$AD,'0629 4度C'!$A:$A,"新豐9線",'0629 4度C'!$B:$B,"平均") -> 0 | M21: =SUMIFS('0629 4度C'!$AD:$AD,'0629 4度C'!$A:$A,"新豐4線",'0629 4度C'!$B:$B,"平均") -> 0
B22: 配置人數 | D22: =SUMIFS('0629 4度C'!$I:$I,'0629 4度C'!$A:$A,"新豐6線",'0629 4度C'!$B:$B,"平均") -> 15.5 | E22: =SUMIFS('0629 4度C'!$I:$I,'0629 4度C'!$A:$A,"新豐2線",'0629 4度C'!$B:$B,"平均") -> 17.4 | F22: =SUMIFS('0629 4度C'!$I:$I,'0629 4度C'!$A:$A,"新豐5線",'0629 4度C'!$B:$B,"平均") -> 18.714286 | G22: =SUMIFS('0629 4度C'!$I:$I,'0629 4度C'!$A:$A,"新豐7線",'0629 4度C'!$B:$B,"平均") -> 16.666667 | H22: =SUMIFS('0629 4度C'!$I:$I,'0629 4度C'!$A:$A,"新豐3線",'0629 4度C'!$B:$B,"平均") -> 10 | I22: =SUMIFS('0629 4度C'!$I:$I,'0629 4度C'!$A:$A,"新豐1線",'0629 4度C'!$B:$B,"平均") -> 16.714286 | J22: =SUMIFS('0629 4度C'!$I:$I,'0629 4度C'!$A:$A,"新豐10線",'0629 4度C'!$B:$B,"平均") -> 9.25 | K22: =SUMIFS('0629 4度C'!$I:$I,'0629 4度C'!$A:$A,"新豐8線",'0629 4度C'!$B:$B,"平均") -> 17.5 | L22: =SUMIFS('0629 4度C'!$I:$I,'0629 4度C'!$A:$A,"新豐9線",'0629 4度C'!$B:$B,"平均") -> 18 | M22: =SUMIFS('0629 4度C'!$I:$I,'0629 4度C'!$A:$A,"新豐4線",'0629 4度C'!$B:$B,"平均") -> 15.142857
B23: 主要應用設備 | D23: ET-55 | E23: 熱縮爐 | F23: L型包裝機 | G23: L型包裝機 | H23: 伺服包裝機 | I23: ET-55 | J23: 伺服包裝機 | K23: 三明治包裝機 | L23: 三明治包裝機 | M23: 三明治包裝機
B24: 次要應用設備 | F24: 圓盤機 | G24: ET-55
B25: 備註 | E25: 握沙拉 | F25: 共用L型包裝機 | H25: 調理麵包 | I25: 炒飯+沙拉 | J25: 調理麵包

Sheet 0629 4度C
A1: 新豐廠四度C日報分析 | C1: 總生產量 | D1: =SUM(F5:F72) -> 196622 | E1: 營業額 | F1: =SUM(G5:G72) -> 6758725.1 | G1: 出勤人數 | H1: =L9+L15+L51+L59+L23+L64+L39+L47+L30+L72 -> 154.8881 | I1: 產線配置圖 | L1: 生產實績 | O1: 人時性差異分析 | S1: 日報登錄 | Y1: 合計 次數 | Z1: 合計 時間/分 | AA1: 產線異常 分析說明(5分鐘以上) | AC1: 合計 次數 | AD1: 合計 設備次數 | AE1: 產能差異分析
A2: 46202 | B2: 星期一 | C2: 人時性 | D2: =AVERAGE(N9,N15,N51,N59,N23,N64,N30,N39,N47,N72) -> 151.50654 | E2: 平均廠價 | F2: =F1/D1 -> 34.374206 | G2: 多次生產數 | H2: =COUNT(H5:H72) -> 10 | Y2: =SUM(Y9+Y15+Y23+Y30+Y39+Y47+Y51+Y59+Y64+Y72) -> 0 | Z2: =SUM(Z9+Z15+Z23+Z30+Z39+Z47+Z51+Z59+Z64+Z72) -> 0 | AC2: 58 | AD2: =SUM(AD9+AD15+AD23+AD30+AD39+AD47+AD51+AD59+AD64+AD72) -> 0
A3: 線別 | B3: 品類 | C3: 品名 | E3: 廠價 | F3: 生產量 | G3: 營收 | H3: 多次 生產 | I3: 人數 | J3: 產能/時 | K3: 人時性 | L3: 人數 | M3: 產能/時 | N3: 人時性 | O3: 人數 | P3: 人時性 | Q3: 達成率 | R3: 達成率平均 | S3: 生產時間 | U3: 換線、休息/分 | V3: 稼動時間/分 | W3: 休息時間 | Y3: 產線異常統計 (5分鐘以上) | AA3: (新豐回填) | AC3: 短暫停線統計 (5分鐘以下) | AE3: 產能/時 | AF3: 達成率 | AG3: 達成率平均
S4: 開始 | T4: 結束 | W4: 開始 | X4: 結束 | Y4: 次數 | Z4: 時間/分 | AC4: 總次數 | AD4: 設備因素(次數)
A5: 新豐6線 | B5: 微波主食 | C5: 二配泰式綠咖哩雞 | E5: 50.67 | F5: 1532 | G5: =E5*F5 -> 77626.44 | I5: 15 | J5: 2000 | K5: =J5/I5 -> 133.33333 | L5: 15 | M5: =F5/V5*60 -> 1915 | N5: =M5/L5 -> 127.66667 | O5: =L5-I5 -> 0 | P5: =N5-K5 -> -5.6666667 | Q5: =N5/K5 -> 0.9575 | R5: =Q9 -> 0.96111234 | S5: 0.70833333 | T5: 0.74166667 | V5: =(T5-S5)*24*60 -> 48 | AC5: 4 | AE5: =M5-J5 -> -85 | AF5: =M5/J5 -> 0.9575 | AG5: =AF9 -> 0.96111234
A6: 新豐6線 | B6: 微波主食 | C6: 二配金咖哩果香甘口咖哩飯 | E6: 50.92 | F6: 2585 | G6: =E6*F6 -> 131628.2 | I6: 15 | J6: 2000 | K6: =J6/I6 -> 133.33333 | L6: 15 | M6: =F6/V6*60 -> 1914.8148 | N6: =M6/L6 -> 127.65432 | O6: =L6-I6 -> 0 | P6: =N6-K6 -> -5.6790123 | Q6: =N6/K6 -> 0.95740741 | S6: 0.74513889 | T6: 0.80138889 | U6: =IF(S6=TIME(17,0,0),"",(S6-T5)*24*60) -> 5 | V6: =(T6-S6)*24*60 -> 81 | AE6: =M6-J6 -> -85.185185 | AF6: =M6/J6 -> 0.95740741
A7: 新豐6線 | B7: 微波主食 | C7: 二配金咖哩濃厚辛口咖哩飯 | E7: 50.98 | F7: 1000 | G7: =E7*F7 -> 50980 | H7: 2 | I7: 16 | J7: 2000 | K7: =J7/I7 -> 125 | L7: 16 | M7: =F7/V7*60 -> 1935.4839 | N7: =M7/L7 -> 120.96774 | O7: =L7-I7 -> 0 | P7: =N7-K7 -> -4.0322581 | Q7: =N7/K7 -> 0.96774194 | S7: 0.80625 | T7: 0.82777778 | U7: =IF(S7=TIME(17,0,0),"",(S7-T6)*24*60) -> 7 | V7: =(T7-S7)*24*60 -> 31 | W7: =T7 -> 0.82777778 | X7: =S8 -> 0.86736111 | AE7: =M7-J7 -> -64.516129 | AF7: =M7/J7 -> 0.96774194
A8: 新豐6線 | B8: 微波主食 | C8: 二配金咖哩濃厚辛口咖哩飯 | E8: 50.98 | F8: 1603 | G8: =E8*F8 -> 81720.94 | I8: 16 | J8: 2000 | K8: =J8/I8 -> 125 | L8: 16 | M8: =F8/V8*60 -> 1923.6 | N8: =M8/L8 -> 120.225 | O8: =L8-I8 -> 0 | P8: =N8-K8 -> -4.775 | Q8: =N8/K8 -> 0.9618 | S8: 0.86736111 | T8: 0.90208333 | U8: =IF(S8=TIME(17,0,0),"",(S8-T7)*24*60) -> 57 | V8: =(T8-S8)*24*60 -> 50 | AE8: =M8-J8 -> -76.4 | AF8: =M8/J8 -> 0.9618
A9: 新豐6線 | B9: 平均 | I9: 15.5 | J9: 2000 | K9: =J9/I9 -> 129.03226 | L9: 15.5 | M9: =AVERAGE(M5:M8) -> 1922.2247 | N9: =M9/L9 -> 124.01449 | O9: =L9-I9 -> 0 | P9: =N9-K9 -> -5.0177631 | Q9: =N9/K9 -> 0.96111234 | Y9: =SUM(Y5:Y8) -> 0 | Z9: =SUM(Z5:Z8) -> 0 | AC9: 4 | AD9: =SUM(AD5:AD8) -> 0 | AE9: =M9-J9 -> -77.775329 | AF9: =M9/J9 -> 0.96111234
A10: 新豐2線 | B10: 沙拉 | C10: 青醬優格雞肉握沙拉(113年) | E10: 39.62 | F10: 3100 | G10: =E10*F10 -> 122822 | H10: 2 | I10: 19 | J10: 1500 | K10: =J10/I10 -> 78.947368 | L10: 19 | M10: =F10/V10*60 -> 1430.7692 | N10: =M10/L10 -> 75.303644 | O10: =L10-I10 -> 0 | P10: =N10-K10 -> -3.6437247 | Q10: =N10/K10 -> 0.95384615 | R10: =Q15 -> 0.95407875 | S10: 0.125 | T10: 0.21527778 | V10: =(T10-S10)*24*60 -> 130 | W10: =T10 -> 0.21527778 | X10: =S11 -> 0.23263889 | AC10: 5 | AE10: =M10-J10 -> -69.230769 | AF10: =M10/J10 -> 0.95384615 | AG10: =AF15 -> 0.95407875
A11: 新豐2線 | B11: 沙拉 | C11: 厚蛋時蔬握沙拉 | E11: 39.46 | F11: 4832 | G11: =E11*F11 -> 190670.72 | I11: 15 | J11: 1500 | K11: =J11/I11 -> 100 | L11: 15 | M11: =F11/V11*60 -> 1428.1773 | N11: =M11/L11 -> 95.211823 | O11: =L11-I11 -> 0 | P11: =N11-K11 -> -4.7881773 | Q11: =N11/K11 -> 0.95211823 | S11: 0.23263889 | T11: 0.37361111 | U11: =IF(S11=TIME(17,0,0),"",(S11-T10)*24*60) -> 25 | V11: =(T11-S11)*24*60 -> 203 | AE11: =M11-J11 -> -71.82266 | AF11: =M11/J11 -> 0.95211823
A12: 新豐2線 | B12: 沙拉 | C12: 青檸烤雞握沙拉(113年) | E12: 39.8 | F12: 4700 | G12: =E12*F12 -> 187060 | H12: 2 | I12: 17 | J12: 1500 | K12: =J12/I12 -> 88.235294 | L12: 17 | M12: =F12/V12*60 -> 1431.4721 | N12: =M12/L12 -> 84.20424 | O12: =L12-I12 -> 0 | P12: =N12-K12 -> -4.031054 | Q12: =N12/K12 -> 0.95431472 | S12: 0.37777778 | T12: 0.51458333 | U12: =IF(S12=TIME(17,0,0),"",(S12-T11)*24*60) -> 6 | V12: =(T12-S12)*24*60 -> 197 | W12: =T12 -> 0.51458333 | X12: =S13 -> 0.55486111 | AE12: =M12-J12 -> -68.527919 | AF12: =M12/J12 -> 0.95431472
A13: 新豐2線 | B13: 沙拉 | C13: 青檸烤雞握沙拉(113年) | E13: 39.8 | F13: 3630 | G13: =E13*F13 -> 144474 | I13: 17 | J13: 1500 | K13: =J13/I13 -> 88.235294 | L13: 17 | M13: =F13/V13*60 -> 1432.8947 | N13: =M13/L13 -> 84.287926 | O13: =L13-I13 -> 0 | P13: =N13-K13 -> -3.9473684 | Q13: =N13/K13 -> 0.95526316 | S13: 0.55486111 | T13: 0.66041667 | U13: =IF(S13=TIME(17,0,0),"",(S13-T12)*24*60) -> 58 | V13: =(T13-S13)*24*60 -> 152 | AE13: =M13-J13 -> -67.105263 | AF13: =M13/J13 -> 0.95526316
A14: 新豐2線 | B14: 沙拉 | C14: 青醬優格雞肉握沙拉(113年) | E14: 39.62 | F14: 2411 | G14: =E14*F14 -> 95523.82 | I14: 19 | J14: 1500 | K14: =J14/I14 -> 78.947368 | L14: 19 | M14: =F14/V14*60 -> 1432.2772 | N14: =M14/L14 -> 75.383012 | O14: =L14-I14 -> 0 | P14: =N14-K14 -> -3.5643564 | Q14: =N14/K14 -> 0.95485149 | S14: 0.66527778 | T14: 0.73541667 | U14: =IF(S14=TIME(17,0,0),"",(S14-T13)*24*60) -> 7 | V14: =(T14-S14)*24*60 -> 101 | AE14: =M14-J14 -> -67.722772 | AF14: =M14/J14 -> 0.95485149
A15: 新豐2線 | B15: 平均 | I15: 17.4 | J15: 1500 | K15: =J15/I15 -> 86.206897 | L15: 17.4 | M15: =AVERAGE(M10:M14) -> 1431.1181 | N15: =M15/L15 -> 82.248168 | O15: =L15-I15 -> 0 | P15: =N15-K15 -> -3.9587285 | Q15: =N15/K15 -> 0.95407875 | Y15: =SUM(Y10:Y14) -> 0 | Z15: =SUM(Z10:Z14) -> 0 | AC15: 5 | AD15: =SUM(AD10:AD14) -> 0 | AE15: =M15-J15 -> -68.881877 | AF15: =M15/J15 -> 0.95407875
A16: 新豐5線 | B16: 小吃 | C16: 香菇雞燉湯 | E16: 38.62 | F16: 2819 | G16: =E16*F16 -> 108869.78 | I16: 24 | J16: 1500 | K16: =J16/I16 -> 62.5 | L16: 24 | M16: =F16/V16*60 -> 1433.3898 | N16: =M16/L16 -> 59.724576 | O16: =L16-I16 -> 0 | P16: =N16-K16 -> -2.7754237 | Q16: =N16/K16 -> 0.95559322 | R16: =Q23 -> 0.9611696 | S16: 0.083333333 | T16: 0.16527778 | V16: =(T16-S16)*24*60 -> 118 | W16: =T16 -> 0.16527778 | X16: =S17 -> 0.18472222 | AC16: 7 | AE16: =M16-J16 -> -66.610169 | AF16: =M16/J16 -> 0.95559322 | AG16: =AF23 -> 0.9611696
A17: 新豐5線 | B17: 小吃 | C17: 剝皮辣椒雞湯 | E17: 41 | F17: 2332 | G17: =E17*F17 -> 95612 | I17: 26 | J17: 1500 | K17: =J17/I17 -> 57.692308 | L17: 26 | M17: =F17/V17*60 -> 1442.4742 | N17: =M17/L17 -> 55.479778 | O17: =L17-I17 -> 0 | P17: =N17-K17 -> -2.2125297 | Q17: =N17/K17 -> 0.96164948 | S17: 0.18472222 | T17: 0.25208333 | U17: =IF(S17=TIME(17,0,0),"",(S17-T16)*24*60) -> 28 | V17: =(T17-S17)*24*60 -> 97 | AE17: =M17-J17 -> -57.525773 | AF17: =M17/J17 -> 0.96164948
A18: 新豐5線 | B18: 微波主食 | C18: 香菇雞粥 | E18: 37.03 | F18: 3900 | G18: =E18*F18 -> 144417 | I18: 13 | J18: 1500 | K18: =J18/I18 -> 115.38462 | L18: 13 | M18: =F18/V18*60 -> 1435.5828 | N18: =M18/L18 -> 110.42945 | O18: =L18-I18 -> 0 | P18: =N18-K18 -> -4.9551675 | Q18: =N18/K18 -> 0.95705521 | S18: 0.25555556 | T18: 0.36875 | U18: =IF(S18=TIME(17,0,0),"",(S18-T17)*24*60) -> 5 | V18: =(T18-S18)*24*60 -> 163 | AE18: =M18-J18 -> -64.417178 | AF18: =M18/J18 -> 0.95705521
A19: 新豐5線 | B19: 沙拉 | C19: 地瓜瓜握沙拉 | E19: 39.52 | F19: 3802 | G19: =E19*F19 -> 150255.04 | I19: 19 | J19: 1500 | K19: =J19/I19 -> 78.947368 | L19: 19 | M19: =F19/V19*60 -> 1434.717 | N19: =M19/L19 -> 75.51142 | O19: =L19-I19 -> 0 | P19: =N19-K19 -> -3.4359484 | Q19: =N19/K19 -> 0.95647799 | S19: 0.37222222 | T19: 0.48263889 | U19: =IF(S19=TIME(17,0,0),"",(S19-T18)*24*60) -> 5 | V19: =(T19-S19)*24*60 -> 159 | AE19: =M19-J19 -> -65.283019 | AF19: =M19/J19 -> 0.95647799
A20: 新豐5線 | B20: 微波主食 | C20: 二配起司控培根白醬焗烤飯 | E20: 53.68 | F20: 1134 | G20: =E20*F20 -> 60873.12 | I20: 16 | J20: 1500 | K20: =J20/I20 -> 93.75 | L20: 16 | M20: =F20/V20*60 -> 1447.6596 | N20: =M20/L20 -> 90.478723 | O20: =L20-I20 -> 0 | P20: =N20-K20 -> -3.2712766 | Q20: =N20/K20 -> 0.96510638 | S20: 0.70833333 | T20: 0.74097222 | U20: =IF(S20=TIME(17,0,0),"",(S20-T19)*24*60) | V20: =(T20-S20)*24*60 -> 47 | AE20: =M20-J20 -> -52.340426 | AF20: =M20/J20 -> 0.96510638
A21: 新豐5線 | B21: 微波主食 | C21: 二配蔥爆牛肉燴飯 | E21: 52.86 | F21: 1323 | G21: =E21*F21 -> 69933.78 | I21: 16 | J21: 2000 | K21: =J21/I21 -> 125 | L21: 16 | M21: =F21/V21*60 -> 1936.0976 | N21: =M21/L21 -> 121.0061 | O21: =L21-I21 -> 0 | P21: =N21-K21 -> -3.9939024 | Q21: =N21/K21 -> 0.96804878 | S21: 0.74652778 | T21: 0.775 | U21: =IF(S21=TIME(17,0,0),"",(S21-T20)*24*60) -> 8 | V21: =(T21-S21)*24*60 -> 41 | AE21: =M21-J21 -> -63.902439 | AF21: =M21/J21 -> 0.96804878
A22: 新豐5線 | B22: 微波主食 | C22: 二配港式香滑嫩蛋牛肉燴飯 | E22: 50.67 | F22: 1635 | G22: =E22*F22 -> 82845.45 | I22: 17 | J22: 2000 | K22: =J22/I22 -> 117.64706 | L22: 17 | M22: =F22/V22*60 -> 1923.5294 | N22: =M22/L22 -> 113.14879 | O22: =L22-I22 -> 0 | P22: =N22-K22 -> -4.4982699 | Q22: =N22/K22 -> 0.96176471 | S22: 0.77986111 | T22: 0.81527778 | U22: =IF(S22=TIME(17,0,0),"",(S22-T21)*24*60) -> 7 | V22: =(T22-S22)*24*60 -> 51 | AE22: =M22-J22 -> -76.470588 | AF22: =M22/J22 -> 0.96176471
A23: 新豐5線 | B23: 平均 | I23: 18.714286 | J23: 1642.8571 | K23: =J23/I23 -> 87.78626 | L23: 18.714286 | M23: =AVERAGE(M16:M22) -> 1579.0643 | N23: =M23/L23 -> 84.377484 | O23: =L23-I23 -> 0 | P23: =N23-K23 -> -3.4087755 | Q23: =N23/K23 -> 0.9611696 | Y23: =SUM(Y16:Y22) -> 0 | Z23: =SUM(Z16:Z22) -> 0 | AC23: 7 | AD23: =SUM(AD16:AD22) -> 0 | AE23: =M23-J23 -> -63.792799 | AF23: =M23/J23 -> 0.9611696
A24: 新豐7線 | B24: 微波主食 | C24: 韓式泡菜豬肉豆腐丼飯 | E24: 50.67 | F24: 2396 | G24: =E24*F24 -> 121405.32 | I24: 17 | J24: 2000 | K24: =J24/I24 -> 117.64706 | L24: 17 | M24: =F24/V24*60 -> 1916.8 | N24: =M24/L24 -> 112.75294 | O24: =L24-I24 -> 0 | P24: =N24-K24 -> -4.8941176 | Q24: =N24/K24 -> 0.9584 | R24: =Q30 -> 0.95913351 | S24: 0.20833333 | T24: 0.26041667 | V24: =(T24-S24)*24*60 -> 75 | AC24: 6 | AE24: =M24-J24 -> -83.2 | AF24: =M24/J24 -> 0.9584 | AG24: =AF30 -> 0.95913351
A25: 新豐7線 | B25: 微波主食 | C25: 鐵板滑蛋炸豬排丼 | E25: 57.73 | F25: 2975 | G25: =E25*F25 -> 171746.75 | I25: 14 | J25: 2000 | K25: =J25/I25 -> 142.85714 | L25: 14 | M25: =F25/V25*60 -> 1919.3548 | N25: =M25/L25 -> 137.09677 | O25: =L25-I25 -> 0 | P25: =N25-K25 -> -5.7603687 | Q25: =N25/K25 -> 0.95967742 | S25: 0.26597222 | T25: 0.33055556 | U25: =IF(S25=TIME(17,0,0),"",(S25-T24)*24*60) -> 8 | V25: =(T25-S25)*24*60 -> 93 | AE25: =M25-J25 -> -80.645161 | AF25: =M25/J25 -> 0.95967742
A26: 新豐7線 | B26: 微波主食 | C26: 日式炙烤親子丼 | E26: 53.27 | F26: 1981 | G26: =E26*F26 -> 105527.87 | I26: 16 | J26: 2000 | K26: =J26/I26 -> 125 | L26: 16 | M26: =F26/V26*60 -> 1917.0968 | N26: =M26/L26 -> 119.81855 | O26: =L26-I26 -> 0 | P26: =N26-K26 -> -5.1814516 | Q26: =N26/K26 -> 0.95854839 | S26: 0.33402778 | T26: 0.37708333 | U26: =IF(S26=TIME(17,0,0),"",(S26-T25)*24*60) -> 5 | V26: =(T26-S26)*24*60 -> 62 | AE26: =M26-J26 -> -82.903226 | AF26: =M26/J26 -> 0.95854839
A27: 新豐7線 | B27: 微波主食 | C27: 炙烤醬香燒豚飯 | E27: 51.44 | F27: 2595 | G27: =E27*F27 -> 133486.8 | I27: 25 | J27: 2000 | K27: =J27/I27 -> 80 | L27: 25 | M27: =F27/V27*60 -> 1922.2222 | N27: =M27/L27 -> 76.888889 | O27: =L27-I27 -> 0 | P27: =N27-K27 -> -3.1111111 | Q27: =N27/K27 -> 0.96111111 | S27: 0.38055556 | T27: 0.43680556 | U27: =IF(S27=TIME(17,0,0),"",(S27-T26)*24*60) -> 5 | V27: =(T27-S27)*24*60 -> 81 | AE27: =M27-J27 -> -77.777778 | AF27: =M27/J27 -> 0.96111111
A28: 新豐7線 | B28: 微波主食 | C28: 二配川味麻婆燒豆腐燴飯 | E28: 50.49 | F28: 2178 | G28: =E28*F28 -> 109967.22 | I28: 15 | J28: 2000 | K28: =J28/I28 -> 133.33333 | L28: 15 | M28: =F28/V28*60 -> 1921.7647 | N28: =M28/L28 -> 128.11765 | O28: =L28-I28 -> 0 | P28: =N28-K28 -> -5.2156863 | Q28: =N28/K28 -> 0.96088235 | S28: 0.70833333 | T28: 0.75555556 | U28: =IF(S28=TIME(17,0,0),"",(S28-T27)*24*60) | V28: =(T28-S28)*24*60 -> 68 | AE28: =M28-J28 -> -78.235294 | AF28: =M28/J28 -> 0.96088235
A29: 新豐7線 | B29: 微波主食 | C29: 二配打拋風味豬肉飯 | E29: 51.06 | F29: 3506 | G29: =E29*F29 -> 179016.36 | I29: 13 | J29: 2000 | K29: =J29/I29 -> 153.84615 | L29: 13 | M29: =F29/V29*60 -> 1912.3636 | N29: =M29/L29 -> 147.1049 | O29: =L29-I29 -> 0 | P29: =N29-K29 -> -6.7412587 | Q29: =N29/K29 -> 0.95618182 | S29: 0.75972222 | T29: 0.83611111 | U29: =IF(S29=TIME(17,0,0),"",(S29-T28)*24*60) -> 6 | V29: =(T29-S29)*24*60 -> 110 | AE29: =M29-J29 -> -87.636364 | AF29: =M29/J29 -> 0.95618182
A30: 新豐7線 | B30: 平均 | I30: 16.666667 | J30: 2000 | K30: =J30/I30 -> 120 | L30: 16.666667 | M30: =AVERAGE(M24:M29) -> 1918.267 | N30: =M30/L30 -> 115.09602 | O30: =L30-I30 -> 0 | P30: =N30-K30 -> -4.9039782 | Q30: =N30/K30 -> 0.95913351 | Y30: =SUM(Y24:Y29) -> 0 | Z30: =SUM(Z24:Z29) -> 0 | AC30: 6 | AD30: =SUM(AD24:AD29) -> 0 | AE30: =M30-J30 -> -81.73297 | AF30: =M30/J30 -> 0.95913351
A31: 新豐8線 | B31: 三明治 | C31: 紐奧良風味烤雞鮮蔬三明治 | E31: 31.29 | F31: 5800 | G31: =E31*F31 -> 181482 | H31: 2 | I31: 18 | J31: 2400 | K31: =J31/I31 -> 133.33333 | L31: 18 | M31: =F31/V31*60 -> 2289.4737 | N31: =M31/L31 -> 127.19298 | O31: =L31-I31 -> 0 | P31: =N31-K31 -> -6.1403509 | Q31: =N31/K31 -> 0.95394737 | R31: =Q39 -> 0.95805436 | S31: 0.083333333 | T31: 0.18888889 | V31: =(T31-S31)*24*60 -> 152 | W31: =T31 -> 0.18888889 | X31: =S32 -> 0.20833333 | AC31: 8 | AE31: =M31-J31 -> -110.52632 | AF31: =M31/J31 -> 0.95394737 | AG31: =AF39 -> 0.95805436
A32: 新豐8線 | B32: 三明治 | C32: 醬燒烤雞三明治(115年) | E32: 26.37 | F32: 3900 | G32: =E32*F32 -> 102843 | H32: 2 | I32: 18 | J32: 2400 | K32: =J32/I32 -> 133.33333 | L32: 18 | M32: =F32/V32*60 -> 2294.1176 | N32: =M32/L32 -> 127.45098 | O32: =L32-I32 -> 0 | P32: =N32-K32 -> -5.8823529 | Q32: =N32/K32 -> 0.95588235 | S32: 0.20833333 | T32: 0.27916667 | U32: =(S32-T31)*24*60 -> 28 | V32: =(T32-S32)*24*60 -> 102 | AE32: =M32-J32 -> -105.88235 | AF32: =M32/J32 -> 0.95588235
A33: 新豐8線 | B33: 三明治 | C33: 鮪魚起司溏心蛋三明治(115年) | E33: 26.18 | F33: 4700 | G33: =E33*F33 -> 123046 | H33: 2 | I33: 18 | J33: 2400 | K33: =J33/I33 -> 133.33333 | L33: 18 | M33: =F33/V33*60 -> 2292.6829 | N33: =M33/L33 -> 127.37127 | O33: =L33-I33 -> 0 | P33: =N33-K33 -> -5.9620596 | Q33: =N33/K33 -> 0.95528455 | S33: 0.28333333 | T33: 0.36875 | U33: =(S33-T32)*24*60 -> 6 | V33: =(T33-S33)*24*60 -> 123 | AE33: =M33-J33 -> -107.31707 | AF33: =M33/J33 -> 0.95528455
A34: 新豐8線 | B34: 三明治 | C34: 茄汁厚起司三明治 | E34: 25.99 | F34: 1865 | G34: =E34*F34 -> 48471.35 | I34: 18 | J34: 2400 | K34: =J34/I34 -> 133.33333 | L34: 18 | M34: =F34/V34*60 -> 2331.25 | N34: =M34/L34 -> 129.51389 | O34: =L34-I34 -> 0 | P34: =N34-K34 -> -3.8194444 | Q34: =N34/K34 -> 0.97135417 | S34: 0.37222222 | T34: 0.40555556 | U34: =(S34-T33)*24*60 -> 5 | V34: =(T34-S34)*24*60 -> 48 | AE34: =M34-J34 -> -68.75 | AF34: =M34/J34 -> 0.97135417
A35: 新豐8線 | B35: 三明治 | C35: 雞蛋沙拉三明治(114年) | E35: 25.99 | F35: 4406 | G35: =E35*F35 -> 114511.94 | I35: 14 | J35: 2400 | K35: =J35/I35 -> 171.42857 | L35: 14 | M35: =F35/V35*60 -> 2298.7826 | N35: =M35/L35 -> 164.19876 | O35: =L35-I35 -> 0 | P35: =N35-K35 -> -7.2298137 | Q35: =N35/K35 -> 0.95782609 | S35: 0.41111111 | T35: 0.49097222 | U35: =(S35-T34)*24*60 -> 8 | V35: =(T35-S35)*24*60 -> 115 | W35: =T35 -> 0.49097222 | X35: =S36 -> 0.53055556 | AE35: =M35-J35 -> -101.21739 | AF35: =M35/J35 -> 0.95782609
A36: 新豐8線 | B36: 三明治 | C36: 鮪魚起司溏心蛋三明治(115年) | E36: 26.18 | F36: 3645 | G36: =E36*F36 -> 95426.1 | I36: 18 | J36: 2400 | K36: =J36/I36 -> 133.33333 | L36: 18 | M36: =F36/V36*60 -> 2302.1053 | N36: =M36/L36 -> 127.89474 | O36: =L36-I36 -> 0 | P36: =N36-K36 -> -5.4385965 | Q36: =N36/K36 -> 0.95921053 | S36: 0.53055556 | T36: 0.59652778 | U36: =(S36-T35)*24*60 -> 57 | V36: =(T36-S36)*24*60 -> 95 | AE36: =M36-J36 -> -97.894737 | AF36: =M36/J36 -> 0.95921053
A37: 新豐8線 | B37: 三明治 | C37: 醬燒烤雞三明治(115年) | E37: 26.37 | F37: 2867 | G37: =E37*F37 -> 75602.79 | I37: 18 | J37: 2400 | K37: =J37/I37 -> 133.33333 | L37: 18 | M37: =F37/V37*60 -> 2293.6 | N37: =M37/L37 -> 127.42222 | O37: =L37-I37 -> 0 | P37: =N37-K37 -> -5.9111111 | Q37: =N37/K37 -> 0.95566667 | S37: 0.6 | T37: 0.65208333 | U37: =(S37-T36)*24*60 -> 5 | V37: =(T37-S37)*24*60 -> 75 | AE37: =M37-J37 -> -106.4 | AF37: =M37/J37 -> 0.95566667
A38: 新豐8線 | B38: 三明治 | C38: 紐奧良風味烤雞鮮蔬三明治 | E38: 31.29 | F38: 4356 | G38: =E38*F38 -> 136299.24 | I38: 18 | J38: 2400 | K38: =J38/I38 -> 133.33333 | L38: 18 | M38: =F38/V38*60 -> 2292.6316 | N38: =M38/L38 -> 127.36842 | O38: =L38-I38 -> 0 | P38: =N38-K38 -> -5.9649123 | Q38: =N38/K38 -> 0.95526316 | S38: 0.65694444 | T38: 0.73611111 | U38: =(S38-T37)*24*60 -> 7 | V38: =(T38-S38)*24*60 -> 114 | AE38: =M38-J38 -> -107.36842 | AF38: =M38/J38 -> 0.95526316
A39: 新豐8線 | B39: 平均 | I39: 17.5 | J39: 2400 | K39: =J39/I39 -> 137.14286 | L39: 17.5 | M39: =AVERAGE(M31:M38) -> 2299.3305 | N39: =M39/L39 -> 131.39031 | O39: =L39-I39 -> 0 | P39: =N39-K39 -> -5.7525449 | Q39: =N39/K39 -> 0.95805436 | Y39: =SUM(Y31:Y38) -> 0 | Z39: =SUM(Z31:Z38) -> 0 | AC39: 8 | AD39: =SUM(AD31:AD38) -> 0 | AE39: =M39-J39 -> -100.66954 | AF39: =M39/J39 -> 0.95805436
A40: 新豐9線 | B40: 三明治 | C40: 經典總匯三明治(115年) | E40: 26.18 | F40: 3800 | G40: =E40*F40 -> 99484 | H40: 2 | I40: 20 | J40: 2400 | K40: =J40/I40 -> 120 | L40: 20 | M40: =F40/V40*60 -> 2303.0303 | N40: =M40/L40 -> 115.15152 | O40: =L40-I40 -> 0 | P40: =N40-K40 -> -4.8484848 | Q40: =N40/K40 -> 0.95959596 | R40: =Q47 -> 0.95630595 | S40: 0.083333333 | T40: 0.15208333 | V40: =(T40-S40)*24*60 -> 99 | W40: =T40 -> 0.15208333 | X40: =S41 -> 0.17083333 | AC40: 7 | AE40: =M40-J40 -> -96.969697 | AF40: =M40/J40 -> 0.95959596 | AG40: =AF47 -> 0.95630595
...

Sheet 0628
B1: 屏榮 新豐廠組合室生產人時性分析
B3: 日期 | C3: =TEXT('0628 4度C'!A2,"yyyy.mm.ddaaaa") -> 2026.06.28星期日 | E3: 訂單量 | F3: ='0628 4度C'!D1 -> 206309 | H3: 營業額 | I3: ='0628 4度C'!F1 -> 7066147.2
B4: 人時性 | C4: 項目 | E4: ➀ | G4: ➁ | I4: ➂ | K4: 異常停線 | M4: 短暫停線
C5: 組合室 | E5: 全溫層 | G5: 4度C-各編組展開 | I5: ③三明治-各編組展開 | K5: 合計次數 | L5: 時間 | M5: 合計次數 | N5: 設備次數
C6: 排關平均 | E6: =AVERAGE(D13:M13) -> 158.28246 | F6: =AVERAGE(D31:O31,D13:J13) -> 167.00518 | G6: =AVERAGE(D13:J13) -> 167.00518 | I6: =AVERAGE(K13:M13) -> 137.92945 | K6: ='0628 4度C'!Y2 -> 0 | L6: ='0628 4度C'!Z2 -> 0 | M6: ='0628 4度C'!AC2 -> 61 | N6: ='0628 4度C'!AD2 -> 0
C7: 實績平均 | E7: =AVERAGE(D14:M14) -> 151.54345 | F7: =AVERAGE(D32:O32,D14:J14) -> 159.95133 | G7: =AVERAGE(D14:J14) -> 159.95133 | I7: =AVERAGE(K14:M14) -> 131.92507
C8: 達成率平均 | E8: =AVERAGE(D15:M15) -> 0.95744022 | F8: =AVERAGE(D15:J15,D33:O33) -> 0.95787513 | G8: =AVERAGE(D15:J15) -> 0.95787513 | I8: =AVERAGE(K15:M15) -> 0.95642543
K9: ※現行日本鮮食廠以達成率80%為基本(即為現行KPI)
B10: 溫層 | D10: ➁4度C-各編組展開 | K10: ③三明治-各編組展開
B11: 編組 | D11: 1 | E11: 2 | F11: 3 | G11: 4 | H11: 5 | I11: 6 | J11: 7 | K11: 1 | L11: 2 | M11: 3
D12: 新豐6線 | E12: 新豐2線 | F12: 新豐5線 | G12: 新豐7線 | H12: 新豐3線 | I12: 新豐1線 | J12: 新豐10線 | K12: 新豐8線 | L12: 新豐9線 | M12: 新豐4線
B13: 人時性 | C13: 排關 | D13: =SUMIFS('0628 4度C'!$K:$K,'0628 4度C'!$A:$A,"新豐6線",'0628 4度C'!$B:$B,"平均") -> 129.03226 | E13: =SUMIFS('0628 4度C'!$K:$K,'0628 4度C'!$A:$A,"新豐2線",'0628 4度C'!$B:$B,"平均") -> 88.235294 | F13: =SUMIFS('0628 4度C'!$K:$K,'0628 4度C'!$A:$A,"新豐5線",'0628 4度C'!$B:$B,"平均") -> 87.78626 | G13: =SUMIFS('0628 4度C'!$K:$K,'0628 4度C'!$A:$A,"新豐7線",'0628 4度C'!$B:$B,"平均") -> 120 | H13: =SUMIFS('0628 4度C'!$K:$K,'0628 4度C'!$A:$A,"新豐3線",'0628 4度C'!$B:$B,"平均") -> 300 | I13: =SUMIFS('0628 4度C'!$K:$K,'0628 4度C'!$A:$A,"新豐1線",'0628 4度C'!$B:$B,"平均") -> 119.65812 | J13: =SUMIFS('0628 4度C'!$K:$K,'0628 4度C'!$A:$A,"新豐10線",'0628 4度C'!$B:$B,"平均") -> 324.32432 | K13: =SUMIFS('0628 4度C'!$K:$K,'0628 4度C'!$A:$A,"新豐8線",'0628 4度C'!$B:$B,"平均") -> 137.14286 | L13: =SUMIFS('0628 4度C'!$K:$K,'0628 4度C'!$A:$A,"新豐9線",'0628 4度C'!$B:$B,"平均") -> 120.54795 | M13: =SUMIFS('0628 4度C'!$K:$K,'0628 4度C'!$A:$A,"新豐4線",'0628 4度C'!$B:$B,"平均") -> 156.09756
C14: 實績 | D14: =SUMIFS('0628 4度C'!$N:$N,'0628 4度C'!$A:$A,"新豐6線",'0628 4度C'!$B:$B,"平均") -> 124.31656 | E14: =SUMIFS('0628 4度C'!$N:$N,'0628 4度C'!$A:$A,"新豐2線",'0628 4度C'!$B:$B,"平均") -> 84.298706 | F14: =SUMIFS('0628 4度C'!$N:$N,'0628 4度C'!$A:$A,"新豐5線",'0628 4度C'!$B:$B,"平均") -> 84.437645 | G14: =SUMIFS('0628 4度C'!$N:$N,'0628 4度C'!$A:$A,"新豐7線",'0628 4度C'!$B:$B,"平均") -> 114.47568 | H14: =SUMIFS('0628 4度C'!$N:$N,'0628 4度C'!$A:$A,"新豐3線",'0628 4度C'!$B:$B,"平均") -> 286.84131 | I14: =SUMIFS('0628 4度C'!$N:$N,'0628 4度C'!$A:$A,"新豐1線",'0628 4度C'!$B:$B,"平均") -> 114.34272 | J14: =SUMIFS('0628 4度C'!$N:$N,'0628 4度C'!$A:$A,"新豐10線",'0628 4度C'!$B:$B,"平均") -> 310.94666 | K14: =SUMIFS('0628 4度C'!$N:$N,'0628 4度C'!$A:$A,"新豐8線",'0628 4度C'!$B:$B,"平均") -> 131.0952 | L14: =SUMIFS('0628 4度C'!$N:$N,'0628 4度C'!$A:$A,"新豐9線",'0628 4度C'!$B:$B,"平均") -> 115.26942 | M14: =SUMIFS('0628 4度C'!$N:$N,'0628 4度C'!$A:$A,"新豐4線",'0628 4度C'!$B:$B,"平均") -> 149.41058
C15: 達成率 | D15: =D14/D13 -> 0.96345334 | E15: =E14/E13 -> 0.95538533 | F15: =F14/F13 -> 0.96185491 | G15: =G14/G13 -> 0.95396403 | H15: =H14/H13 -> 0.95613769 | I15: =I14/I13 -> 0.95557845 | J15: =J14/J13 -> 0.95875219 | K15: =K14/K13 -> 0.95590253 | ... M15: =M14/M13 -> 0.95716152
B16: 作業 時間 | C16: 開始 | D16: =VLOOKUP("新豐6線",'0628 4度C'!$A:$T,19,0) -> 0.70833333 | E16: =VLOOKUP("新豐2線",'0628 4度C'!$A:$T,19,0) -> 0.16666667 | F16: =VLOOKUP("新豐5線",'0628 4度C'!$A:$T,19,0) -> 0.083333333 | G16: =VLOOKUP("新豐7線",'0628 4度C'!$A:$T,19,0) -> 0.20833333 | H16: =VLOOKUP("新豐3線",'0628 4度C'!$A:$T,19,0) -> 0.20833333 | I16: =VLOOKUP("新豐1線",'0628 4度C'!$A:$T,19,0) -> 0.16666667 | J16: =VLOOKUP("新豐10線",'0628 4度C'!$A:$T,19,0) -> 0.20833333 | K16: =VLOOKUP("新豐8線",'0628 4度C'!$A:$T,19,0) -> 0.083333333 | L16: =VLOOKUP("新豐9線",'0628 4度C'!$A:$T,19,0) -> 0.083333333 | M16: =VLOOKUP("新豐4線",'0628 4度C'!$A:$T,19,0) -> 0.083333333
C17: 結束 | D17: =LOOKUP(2,1/(('0628 4度C'!$A:$A="新豐6線")*('0628 4度C'!$T:$T<>"")),'0628 4度C'!$T:$T) -> 0.9125 | E17: =LOOKUP(2,1/(('0628 4度C'!$A:$A="新豐2線")*('0628 4度C'!$T:$T<>"")),'0628 4度C'!$T:$T) -> 0.82083333 | F17: =LOOKUP(2,1/(('0628 4度C'!$A:$A="新豐5線")*('0628 4度C'!$T:$T<>"")),'0628 4度C'!$T:$T) -> 0.82152778 | G17: =LOOKUP(2,1/(('0628 4度C'!$A:$A="新豐7線")*('0628 4度C'!$T:$T<>"")),'0628 4度C'!$T:$T) -> 0.84236111 | H17: =LOOKUP(2,1/(('0628 4度C'!$A:$A="新豐3線")*('0628 4度C'!$T:$T<>"")),'0628 4度C'!$T:$T) -> 0.47291667 | I17: =LOOKUP(2,1/(('0628 4度C'!$A:$A="新豐1線")*('0628 4度C'!$T:$T<>"")),'0628 4度C'!$T:$T) -> 0.85486111 | J17: =LOOKUP(2,1/(('0628 4度C'!$A:$A="新豐10線")*('0628 4度C'!$T:$T<>"")),'0628 4度C'!$T:$T) -> 0.45416667 | K17: =LOOKUP(2,1/(('0628 4度C'!$A:$A="新豐8線")*('0628 4度C'!$T:$T<>"")),'0628 4度C'!$T:$T) -> 0.76388889 | L17: =LOOKUP(2,1/(('0628 4度C'!$A:$A="新豐9線")*('0628 4度C'!$T:$T<>"")),'0628 4度C'!$T:$T) -> 0.75486111 | M17: =LOOKUP(2,1/(('0628 4度C'!$A:$A="新豐4線")*('0628 4度C'!$T:$T<>"")),'0628 4度C'!$T:$T) -> 0.75347222
