Workbook

Sheet 0131
B1: 屏榮 新豐廠組合室生產人時性分析
B3: 日期 | C3: =TEXT('0131 4度C'!A2,"yyyy.mm.ddaaaa") -> 2026.01.31星期六 | E3: 訂單量 | F3: ='0131 4度C'!D1 -> 135047 | H3: 營業額 | I3: ='0131 4度C'!F1 -> 4693379.2
B4: 人時性 | C4: 項目 | E4: ➀ | G4: ➁ | I4: ➂ | K4: 異常停線 | M4: 短暫停線
C5: 組合室 | E5: 全溫層 | G5: 4度C-各編組展開 | I5: ③三明治-各編組展開 | K5: 合計次數 | L5: 時間 | M5: 合計次數 | N5: 設備次數
C6: 排關平均 | E6: =AVERAGE(D13:M13) -> 143.77629 | F6: =AVERAGE(D31:O31,D13:J13) -> 146.44823 | G6: =AVERAGE(D13:J13) -> 146.44823 | I6: =AVERAGE(K13:M13) -> 137.54177 | K6: ='0131 4度C'!Y2 -> 0 | L6: ='0131 4度C'!Z2 -> 0 | M6: ='0131 4度C'!AC2 -> 32 | N6: ='0131 4度C'!AD2 -> 0
C7: 實績平均 | E7: =AVERAGE(D14:M14) -> 137.81224 | F7: =AVERAGE(D32:O32,D14:J14) -> 140.36758 | G7: =AVERAGE(D14:J14) -> 140.36758 | I7: =AVERAGE(K14:M14) -> 131.8498
C8: 達成率平均 | E8: =AVERAGE(D15:M15) -> 0.95778451 | F8: =AVERAGE(D15:J15,D33:O33) -> 0.95746998 | G8: =AVERAGE(D15:J15) -> 0.95746998 | I8: =AVERAGE(K15:M15) -> 0.95851843
K9: ※現行日本鮮食廠以達成率80%為基本(即為現行KPI)
B10: 溫層 | D10: ➁4度C-各編組展開 | K10: ③三明治-各編組展開
B11: 編組 | D11: 1 | E11: 2 | F11: 3 | G11: 4 | H11: 5 | I11: 6 | J11: 7 | K11: 1 | L11: 2 | M11: 3
D12: 新豐6線 | E12: 新豐2線 | F12: 新豐5線 | G12: 新豐7線 | H12: 新豐3線 | I12: 新豐1線 | J12: 新豐10線 | K12: 新豐8線 | L12: 新豐9線 | M12: 新豐4線
B13: 人時性 | C13: 排關 | D13: =SUMIFS('0131 4度C'!$K:$K,'0131 4度C'!$A:$A,"新豐6線",'0131 4度C'!$B:$B,"平均") -> 116.50485 | E13: =SUMIFS('0131 4度C'!$K:$K,'0131 4度C'!$A:$A,"新豐2線",'0131 4度C'!$B:$B,"平均") -> 83.333333 | F13: =SUMIFS('0131 4度C'!$K:$K,'0131 4度C'!$A:$A,"新豐5線",'0131 4度C'!$B:$B,"平均") -> 110.16949 | G13: =SUMIFS('0131 4度C'!$K:$K,'0131 4度C'!$A:$A,"新豐7線",'0131 4度C'!$B:$B,"平均") -> 122.72727 | H13: =SUMIFS('0131 4度C'!$K:$K,'0131 4度C'!$A:$A,"新豐3線",'0131 4度C'!$B:$B,"平均") -> 300 | I13: =SUMIFS('0131 4度C'!$K:$K,'0131 4度C'!$A:$A,"新豐1線",'0131 4度C'!$B:$B,"平均") -> 103.7234 | J13: =SUMIFS('0131 4度C'!$K:$K,'0131 4度C'!$A:$A,"新豐10線",'0131 4度C'!$B:$B,"平均") -> 188.67925 | K13: =SUMIFS('0131 4度C'!$K:$K,'0131 4度C'!$A:$A,"新豐8線",'0131 4度C'!$B:$B,"平均") -> 135.84906 | L13: =SUMIFS('0131 4度C'!$K:$K,'0131 4度C'!$A:$A,"新豐9線",'0131 4度C'!$B:$B,"平均") -> 130.43478 | M13: =SUMIFS('0131 4度C'!$K:$K,'0131 4度C'!$A:$A,"新豐4線",'0131 4度C'!$B:$B,"平均") -> 146.34146
C14: 實績 | D14: =SUMIFS('0131 4度C'!$N:$N,'0131 4度C'!$A:$A,"新豐6線",'0131 4度C'!$B:$B,"平均") -> 111.81794 | E14: =SUMIFS('0131 4度C'!$N:$N,'0131 4度C'!$A:$A,"新豐2線",'0131 4度C'!$B:$B,"平均") -> 79.556488 | F14: =SUMIFS('0131 4度C'!$N:$N,'0131 4度C'!$A:$A,"新豐5線",'0131 4度C'!$B:$B,"平均") -> 106.29959 | G14: =SUMIFS('0131 4度C'!$N:$N,'0131 4度C'!$A:$A,"新豐7線",'0131 4度C'!$B:$B,"平均") -> 118.40803 | H14: =SUMIFS('0131 4度C'!$N:$N,'0131 4度C'!$A:$A,"新豐3線",'0131 4度C'!$B:$B,"平均") -> 288.15876 | I14: =SUMIFS('0131 4度C'!$N:$N,'0131 4度C'!$A:$A,"新豐1線",'0131 4度C'!$B:$B,"平均") -> 97.32076 | J14: =SUMIFS('0131 4度C'!$N:$N,'0131 4度C'!$A:$A,"新豐10線",'0131 4度C'!$B:$B,"平均") -> 181.01147 | K14: =SUMIFS('0131 4度C'!$N:$N,'0131 4度C'!$A:$A,"新豐8線",'0131 4度C'!$B:$B,"平均") -> 130.2393 | L14: =SUMIFS('0131 4度C'!$N:$N,'0131 4度C'!$A:$A,"新豐9線",'0131 4度C'!$B:$B,"平均") -> 124.67632 | M14: =SUMIFS('0131 4度C'!$N:$N,'0131 4度C'!$A:$A,"新豐4線",'0131 4度C'!$B:$B,"平均") -> 140.63379
C15: 達成率 | D15: =D14/D13 -> 0.95977066 | E15: =E14/E13 -> 0.95467786 | F15: =F14/F13 -> 0.96487322 | G15: =G14/G13 -> 0.96480619 | H15: =H14/H13 -> 0.9605292 | I15: =I14/I13 -> 0.93827194 | J15: =J14/J13 -> 0.95936079 | K15: =K14/K13 -> 0.95870596 | ... M15: =M14/M13 -> 0.96099756
B16: 作業 時間 | C16: 開始 | D16: =VLOOKUP("新豐6線",'0131 4度C'!$A:$T,19,0) -> 0.70833333 | E16: =VLOOKUP("新豐2線",'0131 4度C'!$A:$T,19,0) -> 0.20833333 | F16: =VLOOKUP("新豐5線",'0131 4度C'!$A:$T,19,0) -> 0.20833333 | G16: =VLOOKUP("新豐7線",'0131 4度C'!$A:$T,19,0) -> 0.20833333 | H16: =VLOOKUP("新豐3線",'0131 4度C'!$A:$T,19,0) -> 0.20833333 | I16: =VLOOKUP("新豐1線",'0131 4度C'!$A:$T,19,0) -> 0.20833333 | J16: =VLOOKUP("新豐10線",'0131 4度C'!$A:$T,19,0) -> 0.20833333 | K16: =VLOOKUP("新豐8線",'0131 4度C'!$A:$T,19,0) -> 0.125 | L16: =VLOOKUP("新豐9線",'0131 4度C'!$A:$T,19,0) -> 0.125 | M16: =VLOOKUP("新豐4線",'0131 4度C'!$A:$T,19,0) -> 0.125
C17: 結束 | D17: =LOOKUP(2,1/(('0131 4度C'!$A:$A="新豐6線")*('0131 4度C'!$T:$T<>"")),'0131 4度C'!$T:$T) -> 0.88472222 | E17: =LOOKUP(2,1/(('0131 4度C'!$A:$A="新豐2線")*('0131 4度C'!$T:$T<>"")),'0131 4度C'!$T:$T) -> 0.41180556 | F17: =LOOKUP(2,1/(('0131 4度C'!$A:$A="新豐5線")*('0131 4度C'!$T:$T<>"")),'0131 4度C'!$T:$T) -> 0.90555556 | G17: =LOOKUP(2,1/(('0131 4度C'!$A:$A="新豐7線")*('0131 4度C'!$T:$T<>"")),'0131 4度C'!$T:$T) -> 0.90416667 | H17: =LOOKUP(2,1/(('0131 4度C'!$A:$A="新豐3線")*('0131 4度C'!$T:$T<>"")),'0131 4度C'!$T:$T) -> 0.63125 | I17: =LOOKUP(2,1/(('0131 4度C'!$A:$A="新豐1線")*('0131 4度C'!$T:$T<>"")),'0131 4度C'!$T:$T) -> 0.88958333 | J17: =LOOKUP(2,1/(('0131 4度C'!$A:$A="新豐10線")*('0131 4度C'!$T:$T<>"")),'0131 4度C'!$T:$T) -> 0.42083333 | K17: =LOOKUP(2,1/(('0131 4度C'!$A:$A="新豐8線")*('0131 4度C'!$T:$T<>"")),'0131 4度C'!$T:$T) -> 0.52013889 | L17: =LOOKUP(2,1/(('0131 4度C'!$A:$A="新豐9線")*('0131 4度C'!$T:$T<>"")),'0131 4度C'!$T:$T) -> 0.50902778 | M17: =LOOKUP(2,1/(('0131 4度C'!$A:$A="新豐4線")*('0131 4度C'!$T:$T<>"")),'0131 4度C'!$T:$T) -> 0.48819444
B18: 產線異常 (5分鐘以上) | C18: 次數 | D18: =SUMIFS('0131 4度C'!$Y:$Y,'0131 4度C'!$A:$A,"新豐6線",'0131 4度C'!$B:$B,"平均") -> 0 | E18: =SUMIFS('0131 4度C'!$Y:$Y,'0131 4度C'!$A:$A,"新豐2線",'0131 4度C'!$B:$B,"平均") -> 0 | F18: =SUMIFS('0131 4度C'!$Y:$Y,'0131 4度C'!$A:$A,"新豐5線",'0131 4度C'!$B:$B,"平均") -> 0 | G18: =SUMIFS('0131 4度C'!$Y:$Y,'0131 4度C'!$A:$A,"新豐7線",'0131 4度C'!$B:$B,"平均") -> 0 | H18: =SUMIFS('0131 4度C'!$Y:$Y,'0131 4度C'!$A:$A,"新豐3線",'0131 4度C'!$B:$B,"平均") -> 0 | I18: =SUMIFS('0131 4度C'!$Y:$Y,'0131 4度C'!$A:$A,"新豐1線",'0131 4度C'!$B:$B,"平均") -> 0 | J18: =SUMIFS('0131 4度C'!$Y:$Y,'0131 4度C'!$A:$A,"新豐10線",'0131 4度C'!$B:$B,"平均") -> 0 | K18: =SUMIFS('0131 4度C'!$Y:$Y,'0131 4度C'!$A:$A,"新豐8線",'0131 4度C'!$B:$B,"平均") -> 0 | L18: =SUMIFS('0131 4度C'!$Y:$Y,'0131 4度C'!$A:$A,"新豐9線",'0131 4度C'!$B:$B,"平均") -> 0 | M18: =SUMIFS('0131 4度C'!$Y:$Y,'0131 4度C'!$A:$A,"新豐4線",'0131 4度C'!$B:$B,"平均") -> 0
C19: 時間/分 | D19: =SUMIFS('0131 4度C'!$Z:$Z,'0131 4度C'!$A:$A,"新豐6線",'0131 4度C'!$B:$B,"平均") -> 0 | E19: =SUMIFS('0131 4度C'!$Z:$Z,'0131 4度C'!$A:$A,"新豐2線",'0131 4度C'!$B:$B,"平均") -> 0 | F19: =SUMIFS('0131 4度C'!$Z:$Z,'0131 4度C'!$A:$A,"新豐5線",'0131 4度C'!$B:$B,"平均") -> 0 | G19: =SUMIFS('0131 4度C'!$Z:$Z,'0131 4度C'!$A:$A,"新豐7線",'0131 4度C'!$B:$B,"平均") -> 0 | H19: =SUMIFS('0131 4度C'!$Z:$Z,'0131 4度C'!$A:$A,"新豐3線",'0131 4度C'!$B:$B,"平均") -> 0 | I19: =SUMIFS('0131 4度C'!$Z:$Z,'0131 4度C'!$A:$A,"新豐1線",'0131 4度C'!$B:$B,"平均") -> 0 | J19: =SUMIFS('0131 4度C'!$Z:$Z,'0131 4度C'!$A:$A,"新豐10線",'0131 4度C'!$B:$B,"平均") -> 0 | K19: =SUMIFS('0131 4度C'!$Z:$Z,'0131 4度C'!$A:$A,"新豐8線",'0131 4度C'!$B:$B,"平均") -> 0 | L19: =SUMIFS('0131 4度C'!$Z:$Z,'0131 4度C'!$A:$A,"新豐9線",'0131 4度C'!$B:$B,"平均") -> 0 | M19: =SUMIFS('0131 4度C'!$Z:$Z,'0131 4度C'!$A:$A,"新豐4線",'0131 4度C'!$B:$B,"平均") -> 0
B20: 短暫停線 (5分鐘以下) | C20: 次數 | D20: =SUMIFS('0131 4度C'!$AC:$AC,'0131 4度C'!$A:$A,"新豐6線",'0131 4度C'!$B:$B,"平均") -> 1 | E20: =SUMIFS('0131 4度C'!$AC:$AC,'0131 4度C'!$A:$A,"新豐2線",'0131 4度C'!$B:$B,"平均") -> 2 | F20: =SUMIFS('0131 4度C'!$AC:$AC,'0131 4度C'!$A:$A,"新豐5線",'0131 4度C'!$B:$B,"平均") -> 3 | G20: =SUMIFS('0131 4度C'!$AC:$AC,'0131 4度C'!$A:$A,"新豐7線",'0131 4度C'!$B:$B,"平均") -> 3 | H20: =SUMIFS('0131 4度C'!$AC:$AC,'0131 4度C'!$A:$A,"新豐3線",'0131 4度C'!$B:$B,"平均") -> 0 | I20: =SUMIFS('0131 4度C'!$AC:$AC,'0131 4度C'!$A:$A,"新豐1線",'0131 4度C'!$B:$B,"平均") -> 4 | J20: =SUMIFS('0131 4度C'!$AC:$AC,'0131 4度C'!$A:$A,"新豐10線",'0131 4度C'!$B:$B,"平均") -> 1 | K20: =SUMIFS('0131 4度C'!$AC:$AC,'0131 4度C'!$A:$A,"新豐8線",'0131 4度C'!$B:$B,"平均") -> 6 | L20: =SUMIFS('0131 4度C'!$AC:$AC,'0131 4度C'!$A:$A,"新豐9線",'0131 4度C'!$B:$B,"平均") -> 6 | M20: =SUMIFS('0131 4度C'!$AC:$AC,'0131 4度C'!$A:$A,"新豐4線",'0131 4度C'!$B:$B,"平均") -> 6
C21: 設備次數 | D21: =SUMIFS('0131 4度C'!$AD:$AD,'0131 4度C'!$A:$A,"新豐6線",'0131 4度C'!$B:$B,"平均") -> 0 | E21: =SUMIFS('0131 4度C'!$AD:$AD,'0131 4度C'!$A:$A,"新豐2線",'0131 4度C'!$B:$B,"平均") -> 0 | F21: =SUMIFS('0131 4度C'!$AD:$AD,'0131 4度C'!$A:$A,"新豐5線",'0131 4度C'!$B:$B,"平均") -> 0 | G21: =SUMIFS('0131 4度C'!$AD:$AD,'0131 4度C'!$A:$A,"新豐7線",'0131 4度C'!$B:$B,"平均") -> 0 | H21: =SUMIFS('0131 4度C'!$AD:$AD,'0131 4度C'!$A:$A,"新豐3線",'0131 4度C'!$B:$B,"平均") -> 0 | I21: =SUMIFS('0131 4度C'!$AD:$AD,'0131 4度C'!$A:$A,"新豐1線",'0131 4度C'!$B:$B,"平均") -> 0 | J21: =SUMIFS('0131 4度C'!$AD:$AD,'0131 4度C'!$A:$A,"新豐10線",'0131 4度C'!$B:$B,"平均") -> 0 | K21: =SUMIFS('0131 4度C'!$AD:$AD,'0131 4度C'!$A:$A,"新豐8線",'0131 4度C'!$B:$B,"平均") -> 0 | L21: =SUMIFS('0131 4度C'!$AD:$AD,'0131 4度C'!$A:$A,"新豐9線",'0131 4度C'!$B:$B,"平均") -> 0 | M21: =SUMIFS('0131 4度C'!$AD:$AD,'0131 4度C'!$A:$A,"新豐4線",'0131 4度C'!$B:$B,"平均") -> 0
B22: 配置人數 | D22: =SUMIFS('0131 4度C'!$I:$I,'0131 4度C'!$A:$A,"新豐6線",'0131 4度C'!$B:$B,"平均") -> 17.166667 | E22: =SUMIFS('0131 4度C'!$I:$I,'0131 4度C'!$A:$A,"新豐2線",'0131 4度C'!$B:$B,"平均") -> 18 | F22: =SUMIFS('0131 4度C'!$I:$I,'0131 4度C'!$A:$A,"新豐5線",'0131 4度C'!$B:$B,"平均") -> 16.857143 | G22: =SUMIFS('0131 4度C'!$I:$I,'0131 4度C'!$A:$A,"新豐7線",'0131 4度C'!$B:$B,"平均") -> 15.714286 | H22: =SUMIFS('0131 4度C'!$I:$I,'0131 4度C'!$A:$A,"新豐3線",'0131 4度C'!$B:$B,"平均") -> 10 | I22: =SUMIFS('0131 4度C'!$I:$I,'0131 4度C'!$A:$A,"新豐1線",'0131 4度C'!$B:$B,"平均") -> 18.8 | J22: =SUMIFS('0131 4度C'!$I:$I,'0131 4度C'!$A:$A,"新豐10線",'0131 4度C'!$B:$B,"平均") -> 10.6 | K22: =SUMIFS('0131 4度C'!$I:$I,'0131 4度C'!$A:$A,"新豐8線",'0131 4度C'!$B:$B,"平均") -> 17.666667 | L22: =SUMIFS('0131 4度C'!$I:$I,'0131 4度C'!$A:$A,"新豐9線",'0131 4度C'!$B:$B,"平均") -> 18.4 | M22: =SUMIFS('0131 4度C'!$I:$I,'0131 4度C'!$A:$A,"新豐4線",'0131 4度C'!$B:$B,"平均") -> 16.4
B23: 主要應用設備 | D23: ET-55 | E23: 熱縮爐 | F23: L型包裝機 | G23: L型包裝機 | H23: 伺服包裝機 | I23: ET-55 | J23: 伺服包裝機 | K23: 三明治包裝機 | L23: 三明治包裝機 | M23: 三明治包裝機
B24: 次要應用設備 | F24: 圓盤機 | G24: ET-55
B25: 備註 | E25: 握沙拉 | F25: 共用L型包裝機 | H25: 調理麵包 | I25: 炒飯+沙拉 | J25: 調理麵包

Sheet 0131 4度C
A1: 新豐廠四度C日報分析 | C1: 總生產量 | D1: =SUM(F5:F77) -> 135047 | E1: 營業額 | F1: =SUM(G5:G77) -> 4693379.2 | G1: 出勤人數 | H1: =L11+L14+L54+L65+L22+L71+L37+L43+L30+L77 -> 159.60476 | I1: 產線配置圖 | L1: 生產實績 | O1: 人時性差異分析 | S1: 日報登錄 | Y1: 合計 次數 | Z1: 合計 時間/分 | AA1: 產線異常 分析說明(5分鐘以上) | AC1: 合計 次數 | AD1: 合計 設備次數 | AE1: 產能差異分析
A2: 46053 | B2: 星期六 | C2: 人時性 | D2: =AVERAGE(N11,N14,N54,N65,N22,N71,N30,N37,N43,N77) -> 137.81224 | E2: 平均廠價 | F2: =F1/D1 -> 34.753672 | G2: 多次生產數 | H2: =COUNT(H5:H77) -> 7 | Y2: =SUM(Y11+Y14+Y22+Y30+Y37+Y43+Y54+Y65+Y71+Y77) -> 0 | Z2: =SUM(Z11+Z14+Z22+Z30+Z37+Z43+Z54+Z65+Z71+Z77) -> 0 | AC2: 32 | AD2: =SUM(AD11+AD14+AD22+AD30+AD37+AD43+AD54+AD65+AD71+AD77) -> 0
A3: 線別 | B3: 品類 | C3: 品名 | E3: 廠價 | F3: 生產量 | G3: 營收 | H3: 多次 生產 | I3: 人數 | J3: 產能/時 | K3: 人時性 | L3: 人數 | M3: 產能/時 | N3: 人時性 | O3: 人數 | P3: 人時性 | Q3: 達成率 | R3: 達成率平均 | S3: 生產時間 | U3: 換線、休息/分 | V3: 稼動時間/分 | W3: 休息時間 | Y3: 產線異常統計 (5分鐘以上) | AA3: (新豐回填) | AC3: 短暫停線統計 (5分鐘以下) | AE3: 產能/時 | AF3: 達成率 | AG3: 達成率平均
S4: 開始 | T4: 結束 | W4: 開始 | X4: 結束 | Y4: 次數 | Z4: 時間/分 | AC4: 總次數 | AD4: 設備因素(次數)
A5: 新豐6線 | B5: 微波主食 | C5: 二配港式香滑嫩蛋牛肉燴飯 | E5: 50.67 | F5: 1213 | G5: =E5*F5 -> 61462.71 | I5: 17 | J5: 2000 | K5: =J5/I5 -> 117.64706 | L5: 17 | M5: =F5/V5*60 -> 1915.2632 | N5: =M5/L5 -> 112.66254 | O5: =L5-I5 -> 0 | P5: =N5-K5 -> -4.9845201 | Q5: =N5/K5 -> 0.95763158 | R5: =Q11 -> 0.95977066 | S5: 0.70833333 | T5: 0.73472222 | V5: =(T5-S5)*24*60 -> 38 | AC5: 1 | AE5: =M5-J5 -> -84.736842 | AF5: =M5/J5 -> 0.95763158 | AG5: =AF11 -> 0.95977066
A6: 新豐6線 | B6: 微波主食 | C6: 二配美味蟹煲 | E6: 54.09 | F6: 1182 | G6: =E6*F6 -> 63934.38 | I6: 19 | J6: 2000 | K6: =J6/I6 -> 105.26316 | L6: 19 | M6: =F6/V6*60 -> 1916.7568 | N6: =M6/L6 -> 100.88193 | O6: =L6-I6 -> 0 | P6: =N6-K6 -> -4.3812233 | Q6: =N6/K6 -> 0.95837838 | S6: 0.73958333 | T6: 0.76527778 | U6: =IF(S6=TIME(17,0,0),"",(S6-T5)*24*60) -> 7 | V6: =(T6-S6)*24*60 -> 37 | AE6: =M6-J6 -> -83.243243 | AF6: =M6/J6 -> 0.95837838
A7: 新豐6線 | B7: 微波主食 | C7: 二配麻油雞燴飯 | E7: 50.29 | F7: 711 | G7: =E7*F7 -> 35756.19 | I7: 16 | J7: 2000 | K7: =J7/I7 -> 125 | L7: 16 | M7: =F7/V7*60 -> 1939.0909 | N7: =M7/L7 -> 121.19318 | O7: =L7-I7 -> 0 | P7: =N7-K7 -> -3.8068182 | Q7: =N7/K7 -> 0.96954545 | S7: 0.77083333 | T7: 0.78611111 | U7: =IF(S7=TIME(17,0,0),"",(S7-T6)*24*60) -> 8 | V7: =(T7-S7)*24*60 -> 22 | AE7: =M7-J7 -> -60.909091 | AF7: =M7/J7 -> 0.96954545
A8: 新豐6線 | B8: 微波主食 | C8: 二配紅燒牛肉燴飯 | E8: 57.3 | F8: 700 | G8: =E8*F8 -> 40110 | H8: 2 | I8: 15 | J8: 2000 | K8: =J8/I8 -> 133.33333 | L8: 15 | M8: =F8/V8*60 -> 1909.0909 | N8: =M8/L8 -> 127.27273 | O8: =L8-I8 -> 0 | P8: =N8-K8 -> -6.0606061 | Q8: =N8/K8 -> 0.95454545 | S8: 0.79097222 | T8: 0.80625 | U8: =IF(S8=TIME(17,0,0),"",(S8-T7)*24*60) -> 7 | V8: =(T8-S8)*24*60 -> 22 | AE8: =M8-J8 -> -90.909091 | AF8: =M8/J8 -> 0.95454545
A9: 新豐6線 | B9: 微波主食 | C9: 二配濃蕃茄火腿蛋包飯 | E9: 50.67 | F9: 838 | G9: =E9*F9 -> 42461.46 | I9: 21 | J9: 2000 | K9: =J9/I9 -> 95.238095 | L9: 21 | M9: =F9/V9*60 -> 1933.8462 | N9: =M9/L9 -> 92.087912 | O9: =L9-I9 -> 0 | P9: =N9-K9 -> -3.1501832 | Q9: =N9/K9 -> 0.96692308 | S9: 0.81111111 | T9: 0.82916667 | U9: =IF(S9=TIME(17,0,0),"",(S9-T8)*24*60) -> 7 | V9: =(T9-S9)*24*60 -> 26 | W9: =T9 -> 0.82916667 | X9: =S10 -> 0.86736111 | AE9: =M9-J9 -> -66.153846 | AF9: =M9/J9 -> 0.96692308
A10: 新豐6線 | B10: 微波主食 | C10: 二配紅燒牛肉燴飯 | E10: 57.3 | F10: 793 | G10: =E10*F10 -> 45438.9 | I10: 15 | J10: 2000 | K10: =J10/I10 -> 133.33333 | L10: 15 | M10: =F10/V10*60 -> 1903.2 | N10: =M10/L10 -> 126.88 | O10: =L10-I10 -> 0 | P10: =N10-K10 -> -6.4533333 | Q10: =N10/K10 -> 0.9516 | S10: 0.86736111 | T10: 0.88472222 | U10: =IF(S10=TIME(17,0,0),"",(S10-T9)*24*60) -> 55 | V10: =(T10-S10)*24*60 -> 25 | AE10: =M10-J10 -> -96.8 | AF10: =M10/J10 -> 0.9516
A11: 新豐6線 | B11: 平均 | I11: 17.166667 | J11: 2000 | K11: =J11/I11 -> 116.50485 | L11: 17.166667 | M11: =AVERAGE(M5:M10) -> 1919.5413 | N11: =M11/L11 -> 111.81794 | O11: =L11-I11 -> 0 | P11: =N11-K11 -> -4.6869137 | Q11: =N11/K11 -> 0.95977066 | Y11: =SUM(Y5:Y10) -> 0 | Z11: =SUM(Z5:Z10) -> 0 | AC11: 1 | AD11: =SUM(AD5:AD10) -> 0 | AE11: =M11-J11 -> -80.458686 | AF11: =M11/J11 -> 0.95977066
A12: 新豐2線 | B12: 沙拉 | C12: 青醬優格雞肉握沙拉(113年) | E12: 39.62 | F12: 2600 | G12: =E12*F12 -> 103012 | I12: 19 | J12: 1500 | K12: =J12/I12 -> 78.947368 | L12: 19 | M12: =F12/V12*60 -> 1431.1927 | N12: =M12/L12 -> 75.32593 | O12: =L12-I12 -> 0 | P12: =N12-K12 -> -3.6214389 | Q12: =N12/K12 -> 0.95412844 | R12: =Q14 -> 0.95467786 | S12: 0.20833333 | T12: 0.28402778 | V12: =(T12-S12)*24*60 -> 109 | AC12: 2 | AE12: =M12-J12 -> -68.807339 | AF12: =M12/J12 -> 0.95412844 | AG12: =AF14 -> 0.95467786
A13: 新豐2線 | B13: 沙拉 | C13: 青檸烤雞握沙拉(113年) | E13: 39.8 | F13: 4203 | G13: =E13*F13 -> 167279.4 | I13: 17 | J13: 1500 | K13: =J13/I13 -> 88.235294 | L13: 17 | M13: =F13/V13*60 -> 1432.8409 | N13: =M13/L13 -> 84.284759 | O13: =L13-I13 -> 0 | P13: =N13-K13 -> -3.9505348 | Q13: =N13/K13 -> 0.95522727 | S13: 0.28958333 | T13: 0.41180556 | U13: =IF(S13=TIME(17,0,0),"",(S13-T12)*24*60) -> 8 | V13: =(T13-S13)*24*60 -> 176 | AE13: =M13-J13 -> -67.159091 | AF13: =M13/J13 -> 0.95522727
A14: 新豐2線 | B14: 平均 | I14: 18 | J14: 1500 | K14: =J14/I14 -> 83.333333 | L14: 18 | M14: =AVERAGE(M12:M13) -> 1432.0168 | N14: =M14/L14 -> 79.556488 | O14: =L14-I14 -> 0 | P14: =N14-K14 -> -3.7768453 | Q14: =N14/K14 -> 0.95467786 | Y14: =SUM(Y12:Y13) -> 0 | Z14: =SUM(Z12:Z13) -> 0 | AC14: 2 | AD14: =SUM(AD12:AD13) -> 0 | AE14: =M14-J14 -> -67.983215 | AF14: =M14/J14 -> 0.95467786
A15: 新豐5線 | B15: 小吃 | C15: 剝皮辣椒雞湯 | E15: 41 | F15: 1943 | G15: =E15*F15 -> 79663 | I15: 26 | J15: 1500 | K15: =J15/I15 -> 57.692308 | L15: 26 | M15: =F15/V15*60 -> 1439.2593 | N15: =M15/L15 -> 55.356125 | O15: =L15-I15 -> 0 | P15: =N15-K15 -> -2.3361823 | Q15: =N15/K15 -> 0.95950617 | R15: =Q22 -> 0.96487322 | S15: 0.20833333 | T15: 0.26458333 | V15: =(T15-S15)*24*60 -> 81 | AC15: 3 | AE15: =M15-J15 -> -60.740741 | AF15: =M15/J15 -> 0.95950617 | AG15: =AF22 -> 0.96487322
A16: 新豐5線 | B16: 季節調理麵 | C16: 柚子雞白湯拉麵 | E16: 72.4 | F16: 781 | G16: =E16*F16 -> 56544.4 | I16: 18 | J16: 1500 | K16: =J16/I16 -> 83.333333 | L16: 18 | M16: =F16/V16*60 -> 1464.375 | N16: =M16/L16 -> 81.354167 | O16: =L16-I16 -> 0 | P16: =N16-K16 -> -1.9791667 | Q16: =N16/K16 -> 0.97625 | S16: 0.27013889 | T16: 0.29236111 | U16: =IF(S16=TIME(17,0,0),"",(S16-T15)*24*60) -> 8 | V16: =(T16-S16)*24*60 -> 32 | AE16: =M16-J16 -> -35.625 | AF16: =M16/J16 -> 0.97625
A17: 新豐5線 | B17: 微波主食 | C17: 二配金咖哩濃厚辛口咖哩飯 | E17: 50.98 | F17: 1000 | G17: =E17*F17 -> 50980 | H17: 2 | I17: 16 | J17: 2000 | K17: =J17/I17 -> 125 | L17: 16 | M17: =F17/V17*60 -> 1935.4839 | N17: =M17/L17 -> 120.96774 | O17: =L17-I17 -> 0 | P17: =N17-K17 -> -4.0322581 | Q17: =N17/K17 -> 0.96774194 | S17: 0.70833333 | T17: 0.72986111 | U17: =IF(S17=TIME(17,0,0),"",(S17-T16)*24*60) | V17: =(T17-S17)*24*60 -> 31 | AE17: =M17-J17 -> -64.516129 | AF17: =M17/J17 -> 0.96774194
A18: 新豐5線 | B18: 微波主食 | C18: 二配金咖哩果香甘口咖哩飯 | E18: 50.92 | F18: 700 | G18: =E18*F18 -> 35644 | H18: 2 | I18: 15 | J18: 2000 | K18: =J18/I18 -> 133.33333 | L18: 15 | M18: =F18/V18*60 -> 1909.0909 | N18: =M18/L18 -> 127.27273 | O18: =L18-I18 -> 0 | P18: =N18-K18 -> -6.0606061 | Q18: =N18/K18 -> 0.95454545 | S18: 0.73333333 | T18: 0.74861111 | U18: =IF(S18=TIME(17,0,0),"",(S18-T17)*24*60) -> 5 | V18: =(T18-S18)*24*60 -> 22 | AE18: =M18-J18 -> -90.909091 | AF18: =M18/J18 -> 0.95454545
A19: 新豐5線 | B19: 微波主食 | C19: 二配泰式綠咖哩雞 | E19: 50.67 | F19: 1536 | G19: =E19*F19 -> 77829.12 | I19: 15 | J19: 2000 | K19: =J19/I19 -> 133.33333 | L19: 15 | M19: =F19/V19*60 -> 1920 | N19: =M19/L19 -> 128 | O19: =L19-I19 -> 0 | P19: =N19-K19 -> -5.3333333 | Q19: =N19/K19 -> 0.96 | S19: 0.75347222 | T19: 0.78680556 | U19: =IF(S19=TIME(17,0,0),"",(S19-T18)*24*60) -> 7 | V19: =(T19-S19)*24*60 -> 48 | AE19: =M19-J19 -> -80 | AF19: =M19/J19 -> 0.96
A20: 新豐5線 | B20: 微波主食 | C20: 二配厚香料咖哩雞排飯 | E20: 57.3 | F20: 1808 | G20: =E20*F20 -> 103598.4 | I20: 13 | J20: 2000 | K20: =J20/I20 -> 153.84615 | L20: 13 | M20: =F20/V20*60 -> 1937.1429 | N20: =M20/L20 -> 149.01099 | O20: =L20-I20 -> 0 | P20: =N20-K20 -> -4.8351648 | Q20: =N20/K20 -> 0.96857143 | S20: 0.79236111 | T20: 0.83125 | U20: =IF(S20=TIME(17,0,0),"",(S20-T19)*24*60) -> 8 | V20: =(T20-S20)*24*60 -> 56 | W20: =T20 -> 0.83125 | X20: =S21 -> 0.87083333 | AE20: =M20-J20 -> -62.857143 | AF20: =M20/J20 -> 0.96857143
A21: 新豐5線 | B21: 微波主食 | C21: 二配金咖哩果香甘口咖哩飯 | E21: 50.92 | F21: 1615 | G21: =E21*F21 -> 82235.8 | I21: 15 | J21: 2000 | K21: =J21/I21 -> 133.33333 | L21: 15 | M21: =F21/V21*60 -> 1938 | N21: =M21/L21 -> 129.2 | O21: =L21-I21 -> 0 | P21: =N21-K21 -> -4.1333333 | Q21: =N21/K21 -> 0.969 | S21: 0.87083333 | T21: 0.90555556 | U21: =IF(S21=TIME(17,0,0),"",(S21-T20)*24*60) -> 57 | V21: =(T21-S21)*24*60 -> 50 | AE21: =M21-J21 -> -62 | AF21: =M21/J21 -> 0.969
A22: 新豐5線 | B22: 平均 | I22: 16.857143 | J22: 1857.1429 | K22: =J22/I22 -> 110.16949 | L22: 16.857143 | M22: =AVERAGE(M15:M21) -> 1791.9074 | N22: =M22/L22 -> 106.29959 | O22: =L22-I22 -> 0 | P22: =N22-K22 -> -3.8698992 | Q22: =N22/K22 -> 0.96487322 | Y22: =SUM(Y15:Y21) -> 0 | Z22: =SUM(Z15:Z21) -> 0 | AC22: 3 | AD22: =SUM(AD15:AD21) -> 0 | AE22: =M22-J22 -> -65.235443 | AF22: =M22/J22 -> 0.96487322
A23: 新豐7線 | B23: 小吃 | C23: 古早味炒炊粉 | E23: 43.14 | F23: 910 | G23: =E23*F23 -> 39257.4 | I23: 17 | J23: 2000 | K23: =J23/I23 -> 117.64706 | L23: 17 | M23: =F23/V23*60 -> 1950 | N23: =M23/L23 -> 114.70588 | O23: =L23-I23 -> 0 | P23: =N23-K23 -> -2.9411765 | Q23: =N23/K23 -> 0.975 | R23: =Q30 -> 0.96480619 | S23: 0.20833333 | T23: 0.22777778 | V23: =(T23-S23)*24*60 -> 28 | AC23: 3 | AE23: =M23-J23 -> -50 | AF23: =M23/J23 -> 0.975 | AG23: =AF30 -> 0.96480619
A24: 新豐7線 | B24: 微波主食 | C24: 鐵板滑蛋炸豬排丼 | E24: 57.73 | F24: 2200 | G24: =E24*F24 -> 127006 | I24: 14 | J24: 2000 | K24: =J24/I24 -> 142.85714 | L24: 14 | M24: =F24/V24*60 -> 1913.0435 | N24: =M24/L24 -> 136.64596 | O24: =L24-I24 -> 0 | P24: =N24-K24 -> -6.2111801 | Q24: =N24/K24 -> 0.95652174 | S24: 0.23125 | T24: 0.27916667 | U24: =IF(S24=TIME(17,0,0),"",(S24-T23)*24*60) -> 5 | V24: =(T24-S24)*24*60 -> 69 | AE24: =M24-J24 -> -86.956522 | AF24: =M24/J24 -> 0.95652174
A25: 新豐7線 | B25: 微波主食 | C25: 極上炙烤親子丼 | E25: 53.68 | F25: 1353 | G25: =E25*F25 -> 72629.04 | I25: 16 | J25: 2000 | K25: =J25/I25 -> 125 | L25: 16 | M25: =F25/V25*60 -> 1932.8571 | N25: =M25/L25 -> 120.80357 | O25: =L25-I25 -> 0 | P25: =N25-K25 -> -4.1964286 | Q25: =N25/K25 -> 0.96642857 | S25: 0.28333333 | T25: 0.3125 | U25: =IF(S25=TIME(17,0,0),"",(S25-T24)*24*60) -> 6 | V25: =(T25-S25)*24*60 -> 42 | AE25: =M25-J25 -> -67.142857 | AF25: =M25/J25 -> 0.96642857
A26: 新豐7線 | B26: 微波主食 | C26: 二配川味麻婆燒豆腐燴飯 | E26: 50.49 | F26: 1886 | G26: =E26*F26 -> 95224.14 | I26: 15 | J26: 2000 | K26: =J26/I26 -> 133.33333 | L26: 15 | M26: =F26/V26*60 -> 1917.9661 | N26: =M26/L26 -> 127.86441 | O26: =L26-I26 -> 0 | P26: =N26-K26 -> -5.4689266 | Q26: =N26/K26 -> 0.95898305 | S26: 0.70833333 | T26: 0.74930556 | U26: =IF(S26=TIME(17,0,0),"",(S26-T25)*24*60) | V26: =(T26-S26)*24*60 -> 59 | AE26: =M26-J26 -> -82.033898 | AF26: =M26/J26 -> 0.95898305
A27: 新豐7線 | B27: 微波主食 | C27: 二配香炒沙茶豬肉飯 | E27: 50.67 | F27: 943 | G27: =E27*F27 -> 47781.81 | I27: 16 | J27: 2000 | K27: =J27/I27 -> 125 | L27: 16 | M27: =F27/V27*60 -> 1951.0345 | N27: =M27/L27 -> 121.93966 | O27: =L27-I27 -> 0 | P27: =N27-K27 -> -3.0603448 | Q27: =N27/K27 -> 0.97551724 | S27: 0.75486111 | T27: 0.775 | U27: =IF(S27=TIME(17,0,0),"",(S27-T26)*24*60) -> 8 | V27: =(T27-S27)*24*60 -> 29 | AE27: =M27-J27 -> -48.965517 | AF27: =M27/J27 -> 0.97551724
A28: 新豐7線 | B28: 微波主食 | C28: 二配起司控培根白醬焗烤飯 | E28: 53.68 | F28: 1994 | G28: =E28*F28 -> 107037.92 | I28: 16 | J28: 1500 | K28: =J28/I28 -> 93.75 | L28: 16 | M28: =F28/V28*60 -> 1441.4458 | N28: =M28/L28 -> 90.090361 | O28: =L28-I28 -> 0 | P28: =N28-K28 -> -3.6596386 | Q28: =N28/K28 -> 0.96096386 | S28: 0.77847222 | T28: 0.83611111 | U28: =IF(S28=TIME(17,0,0),"",(S28-T27)*24*60) -> 5 | V28: =(T28-S28)*24*60 -> 83 | W28: =T28 -> 0.83611111 | X28: =S29 -> 0.87569444 | AE28: =M28-J28 -> -58.554217 | AF28: =M28/J28 -> 0.96096386
A29: 新豐7線 | B29: 微波主食 | C29: 二配金咖哩濃厚辛口咖哩飯 | E29: 50.98 | F29: 1311 | G29: =E29*F29 -> 66834.78 | I29: 16 | J29: 2000 | K29: =J29/I29 -> 125 | L29: 16 | M29: =F29/V29*60 -> 1918.5366 | N29: =M29/L29 -> 119.90854 | O29: =L29-I29 -> 0 | P29: =N29-K29 -> -5.0914634 | Q29: =N29/K29 -> 0.95926829 | S29: 0.87569444 | T29: 0.90416667 | U29: =IF(S29=TIME(17,0,0),"",(S29-T28)*24*60) -> 57 | V29: =(T29-S29)*24*60 -> 41 | AE29: =M29-J29 -> -81.463415 | AF29: =M29/J29 -> 0.95926829
A30: 新豐7線 | B30: 平均 | I30: 15.714286 | J30: 1928.5714 | K30: =J30/I30 -> 122.72727 | L30: 15.714286 | M30: =AVERAGE(M23:M29) -> 1860.6977 | N30: =M30/L30 -> 118.40803 | O30: =L30-I30 -> 0 | P30: =N30-K30 -> -4.3192402 | Q30: =N30/K30 -> 0.96480619 | Y30: =SUM(Y23:Y29) -> 0 | Z30: =SUM(Z23:Z29) -> 0 | AC30: 3 | AD30: =SUM(AD23:AD29) -> 0 | AE30: =M30-J30 -> -67.873775 | AF30: =M30/J30 -> 0.96480619
A31: 新豐8線 | B31: 三明治 | C31: 紐奧良風味烤雞鮮蔬三明治 | E31: 31.29 | F31: 6933 | G31: =E31*F31 -> 216933.57 | I31: 18 | J31: 2400 | K31: =J31/I31 -> 133.33333 | L31: 18 | M31: =F31/V31*60 -> 2285.6044 | N31: =M31/L31 -> 126.97802 | O31: =L31-I31 -> 0 | P31: =N31-K31 -> -6.3553114 | Q31: =N31/K31 -> 0.95233516 | R31: =Q37 -> 0.95870596 | S31: 0.125 | T31: 0.25138889 | V31: =(T31-S31)*24*60 -> 182 | W31: =T31 -> 0.25138889 | X31: =S32 -> 0.26944444 | AC31: 6 | AE31: =M31-J31 -> -114.3956 | AF31: =M31/J31 -> 0.95233516 | AG31: =AF37 -> 0.95870596
A32: 新豐8線 | B32: 三明治 | C32: 經典總匯三明治 | E32: 26.2 | F32: 3667 | G32: =E32*F32 -> 96075.4 | I32: 20 | J32: 2400 | K32: =J32/I32 -> 120 | L32: 20 | M32: =F32/V32*60 -> 2291.875 | N32: =M32/L32 -> 114.59375 | O32: =L32-I32 -> 0 | P32: =N32-K32 -> -5.40625 | Q32: =N32/K32 -> 0.95494792 | S32: 0.26944444 | T32: 0.33611111 | U32: =(S32-T31)*24*60 -> 26 | V32: =(T32-S32)*24*60 -> 96 | AE32: =M32-J32 -> -108.125 | AF32: =M32/J32 -> 0.95494792
A33: 新豐8線 | B33: 三明治 | C33: 雞蛋沙拉三明治(114年) | E33: 25.99 | F33: 3081 | G33: =E33*F33 -> 80075.19 | I33: 14 | J33: 2400 | K33: =J33/I33 -> 171.42857 | L33: 14 | M33: =F33/V33*60 -> 2282.2222 | N33: =M33/L33 -> 163.01587 | O33: =L33-I33 -> 0 | P33: =N33-K33 -> -8.4126984 | Q33: =N33/K33 -> 0.95092593 | S33: 0.34166667 | T33: 0.39791667 | U33: =(S33-T32)*24*60 -> 8 | V33: =(T33-S33)*24*60 -> 81 | AE33: =M33-J33 -> -117.77778 | AF33: =M33/J33 -> 0.95092593
A34: 新豐8線 | B34: 三明治 | C34: 肉鬆火腿三明治 | E34: 20.52 | F34: 2899 | G34: =E34*F34 -> 59487.48 | I34: 18 | J34: 2400 | K34: =J34/I34 -> 133.33333 | L34: 18 | M34: =F34/V34*60 -> 2288.6842 | N34: =M34/L34 -> 127.14912 | O34: =L34-I34 -> 0 | P34: =N34-K34 -> -6.1842105 | Q34: =N34/K34 -> 0.95361842 | S34: 0.40277778 | T34: 0.45555556 | U34: =(S34-T33)*24*60 -> 7 | V34: =(T34-S34)*24*60 -> 76 | AE34: =M34-J34 -> -111.31579 | AF34: =M34/J34 -> 0.95361842
A35: 新豐8線 | B35: 三明治 | C35: 好多菜三明治(114年) | E35: 25.98 | F35: 2273 | G35: =E35*F35 -> 59052.54 | I35: 21 | J35: 2400 | K35: =J35/I35 -> 114.28571 | L35: 21 | M35: =F35/V35*60 -> 2311.5254 | N35: =M35/L35 -> 110.07264 | O35: =L35-I35 -> 0 | P35: =N35-K35 -> -4.2130751 | Q35: =N35/K35 -> 0.96313559 | S35: 0.45972222 | T35: 0.50069444 | U35: =(S35-T34)*24*60 -> 6 | V35: =(T35-S35)*24*60 -> 59 | AE35: =M35-J35 -> -88.474576 | AF35: =M35/J35 -> 0.96313559
A36: 新豐8線 | B36: 三明治 | C36: 覆盆莓榛果可可三明治 | E36: 22.69 | F36: 860 | G36: =E36*F36 -> 19513.4 | I36: 15 | J36: 2400 | K36: =J36/I36 -> 160 | L36: 15 | M36: =F36/V36*60 -> 2345.4545 | N36: =M36/L36 -> 156.36364 | O36: =L36-I36 -> 0 | P36: =N36-K36 -> -3.6363636 | Q36: =N36/K36 -> 0.97727273 | S36: 0.50486111 | T36: 0.52013889 | U36: =(S36-T35)*24*60 -> 6 | V36: =(T36-S36)*24*60 -> 22 | AE36: =M36-J36 -> -54.545455 | AF36: =M36/J36 -> 0.97727273
A37: 新豐8線 | B37: 平均 | I37: 17.666667 | J37: 2400 | K37: =J37/I37 -> 135.84906 | L37: 17.666667 | M37: =AVERAGE(M31:M36) -> 2300.8943 | N37: =M37/L37 -> 130.2393 | O37: =L37-I37 -> 0 | P37: =N37-K37 -> -5.6097566 | Q37: =N37/K37 -> 0.95870596 | Y37: =SUM(Y31:Y36) -> 0 | Z37: =SUM(Z31:Z36) -> 0 | AC37: 6 | AD37: =SUM(AD31:AD36) -> 0 | AE37: =M37-J37 -> -99.1057 | AF37: =M37/J37 -> 0.95870596
A38: 新豐9線 | B38: 三明治 | C38: 鮪魚起司溏心蛋三明治 | E38: 26.2 | F38: 4861 | G38: =E38*F38 -> 127358.2 | I38: 18 | J38: 2400 | K38: =J38/I38 -> 133.33333 | L38: 18 | M38: =F38/V38*60 -> 2296.5354 | N38: =M38/L38 -> 127.5853 | O38: =L38-I38 -> 0 | P38: =N38-K38 -> -5.7480315 | Q38: =N38/K38 -> 0.95688976 | R38: =Q43 -> 0.95585176 | S38: 0.125 | T38: 0.21319444 | V38: =(T38-S38)*24*60 -> 127 | W38: =T38 -> 0.21319444 | X38: =S39 -> 0.23263889 | AC38: 6 | AE38: =M38-J38 -> -103.46457 | AF38: =M38/J38 -> 0.95688976 | AG38: =AF43 -> 0.95585176
A39: 新豐9線 | B39: 三明治 | C39: 陽光地瓜總匯三明治 | E39: 26.18 | F39: 1499 | G39: =E39*F39 -> 39243.82 | I39: 19 | J39: 2400 | K39: =J39/I39 -> 126.31579 | L39: 19 | M39: =F39/V39*60 -> 2306.1538 | N39: =M39/L39 -> 121.37652 | O39: =L39-I39 -> 0 | P39: =N39-K39 -> -4.9392713 | Q39: =N39/K39 -> 0.96089744 | S39: 0.23263889 | T39: 0.25972222 | U39: =(S39-T38)*24*60 -> 28 | V39: =(T39-S39)*24*60 -> 39 | AE39: =M39-J39 -> -93.846154 | AF39: =M39/J39 -> 0.96089744
A40: 新豐9線 | B40: 三明治 | C40: 醬燒烤雞三明治 | E40: 26.39 | F40: 4436 | G40: =E40*F40 -> 117066.04 | I40: 19 | J40: 2400 | K40: =J40/I40 -> 126.31579 | L40: 19 | M40: =F40/V40*60 -> 2294.4828 | N40: =M40/L40 -> 120.76225 | O40: =L40-I40 -> 0 | P40: =N40-K40 -> -5.553539 | Q40: =N40/K40 -> 0.95603448 | S40: 0.26527778 | T40: 0.34583333 | U40: =(S40-T39)*24*60 -> 8 | V40: =(T40-S40)*24*60 -> 116 | AE40: =M40-J40 -> -105.51724 | AF40: =M40/J40 -> 0.95603448
...

Sheet 0130
B1: 屏榮 新豐廠組合室生產人時性分析
B3: 日期 | C3: =TEXT('0130 4度C'!A2,"yyyy.mm.ddaaaa") -> 2026.01.30星期五 | E3: 訂單量 | F3: ='0130 4度C'!D1 -> 128261 | H3: 營業額 | I3: ='0130 4度C'!F1 -> 4449272.8
B4: 人時性 | C4: 項目 | E4: ➀ | G4: ➁ | I4: ➂ | K4: 異常停線 | M4: 短暫停線
C5: 組合室 | E5: 全溫層 | G5: 4度C-各編組展開 | I5: ③三明治-各編組展開 | K5: 合計次數 | L5: 時間 | M5: 合計次數 | N5: 設備次數
C6: 排關平均 | E6: =AVERAGE(D13:M13) -> 143.41888 | F6: =AVERAGE(D31:O31,D13:J13) -> 145.91425 | G6: =AVERAGE(D13:J13) -> 145.91425 | I6: =AVERAGE(K13:M13) -> 137.59634 | K6: ='0130 4度C'!Y2 -> 0 | L6: ='0130 4度C'!Z2 -> 0 | M6: ='0130 4度C'!AC2 -> 30 | N6: ='0130 4度C'!AD2 -> 0
C7: 實績平均 | E7: =AVERAGE(D14:M14) -> 137.44239 | F7: =AVERAGE(D32:O32,D14:J14) -> 139.92684 | G7: =AVERAGE(D14:J14) -> 139.92684 | I7: =AVERAGE(K14:M14) -> 131.64535
C8: 達成率平均 | E8: =AVERAGE(D15:M15) -> 0.9569515 | F8: =AVERAGE(D15:J15,D33:O33) -> 0.95702613 | G8: =AVERAGE(D15:J15) -> 0.95702613 | I8: =AVERAGE(K15:M15) -> 0.95677735
K9: ※現行日本鮮食廠以達成率80%為基本(即為現行KPI)
B10: 溫層 | D10: ➁4度C-各編組展開 | K10: ③三明治-各編組展開
B11: 編組 | D11: 1 | E11: 2 | F11: 3 | G11: 4 | H11: 5 | I11: 6 | J11: 7 | K11: 1 | L11: 2 | M11: 3
D12: 新豐6線 | E12: 新豐2線 | F12: 新豐5線 | G12: 新豐7線 | H12: 新豐3線 | I12: 新豐1線 | J12: 新豐10線 | K12: 新豐8線 | L12: 新豐9線 | M12: 新豐4線
B13: 人時性 | C13: 排關 | D13: =SUMIFS('0130 4度C'!$K:$K,'0130 4度C'!$A:$A,"新豐6線",'0130 4度C'!$B:$B,"平均") -> 113.63636 | E13: =SUMIFS('0130 4度C'!$K:$K,'0130 4度C'!$A:$A,"新豐2線",'0130 4度C'!$B:$B,"平均") -> 83.333333 | F13: =SUMIFS('0130 4度C'!$K:$K,'0130 4度C'!$A:$A,"新豐5線",'0130 4度C'!$B:$B,"平均") -> 109.2437 | G13: =SUMIFS('0130 4度C'!$K:$K,'0130 4度C'!$A:$A,"新豐7線",'0130 4度C'!$B:$B,"平均") -> 122.34043 | H13: =SUMIFS('0130 4度C'!$K:$K,'0130 4度C'!$A:$A,"新豐3線",'0130 4度C'!$B:$B,"平均") -> 300 | I13: =SUMIFS('0130 4度C'!$K:$K,'0130 4度C'!$A:$A,"新豐1線",'0130 4度C'!$B:$B,"平均") -> 104.16667 | J13: =SUMIFS('0130 4度C'!$K:$K,'0130 4度C'!$A:$A,"新豐10線",'0130 4度C'!$B:$B,"平均") -> 188.67925 | K13: =SUMIFS('0130 4度C'!$K:$K,'0130 4度C'!$A:$A,"新豐8線",'0130 4度C'!$B:$B,"平均") -> 131.86813 | L13: =SUMIFS('0130 4度C'!$K:$K,'0130 4度C'!$A:$A,"新豐9線",'0130 4度C'!$B:$B,"平均") -> 134.57944 | M13: =SUMIFS('0130 4度C'!$K:$K,'0130 4度C'!$A:$A,"新豐4線",'0130 4度C'!$B:$B,"平均") -> 146.34146
C14: 實績 | D14: =SUMIFS('0130 4度C'!$N:$N,'0130 4度C'!$A:$A,"新豐6線",'0130 4度C'!$B:$B,"平均") -> 109.55093 | E14: =SUMIFS('0130 4度C'!$N:$N,'0130 4度C'!$A:$A,"新豐2線",'0130 4度C'!$B:$B,"平均") -> 79.629586 | F14: =SUMIFS('0130 4度C'!$N:$N,'0130 4度C'!$A:$A,"新豐5線",'0130 4度C'!$B:$B,"平均") -> 104.81436 | G14: =SUMIFS('0130 4度C'!$N:$N,'0130 4度C'!$A:$A,"新豐7線",'0130 4度C'!$B:$B,"平均") -> 117.4338 | H14: =SUMIFS('0130 4度C'!$N:$N,'0130 4度C'!$A:$A,"新豐3線",'0130 4度C'!$B:$B,"平均") -> 288.20019 | I14: =SUMIFS('0130 4度C'!$N:$N,'0130 4度C'!$A:$A,"新豐1線",'0130 4度C'!$B:$B,"平均") -> 96.816582 | J14: =SUMIFS('0130 4度C'!$N:$N,'0130 4度C'!$A:$A,"新豐10線",'0130 4度C'!$B:$B,"平均") -> 183.04246 | K14: =SUMIFS('0130 4度C'!$N:$N,'0130 4度C'!$A:$A,"新豐8線",'0130 4度C'!$B:$B,"平均") -> 126.29611 | L14: =SUMIFS('0130 4度C'!$N:$N,'0130 4度C'!$A:$A,"新豐9線",'0130 4度C'!$B:$B,"平均") -> 128.72988 | M14: =SUMIFS('0130 4度C'!$N:$N,'0130 4度C'!$A:$A,"新豐4線",'0130 4度C'!$B:$B,"平均") -> 139.91005
C15: 達成率 | D15: =D14/D13 -> 0.96404822 | E15: =E14/E13 -> 0.95555504 | F15: =F14/F13 -> 0.95945448 | G15: =G14/G13 -> 0.95989365 | H15: =H14/H13 -> 0.9606673 | I15: =I14/I13 -> 0.92943919 | J15: =J14/J13 -> 0.97012506 | K15: =K14/K13 -> 0.95774551 | ... M15: =M14/M13 -> 0.95605198
B16: 作業 時間 | C16: 開始 | D16: =VLOOKUP("新豐6線",'0130 4度C'!$A:$T,19,0) -> 0.70833333 | E16: =VLOOKUP("新豐2線",'0130 4度C'!$A:$T,19,0) -> 0.20833333 | F16: =VLOOKUP("新豐5線",'0130 4度C'!$A:$T,19,0) -> 0.20833333 | G16: =VLOOKUP("新豐7線",'0130 4度C'!$A:$T,19,0) -> 0.20833333 | H16: =VLOOKUP("新豐3線",'0130 4度C'!$A:$T,19,0) -> 0.20833333 | I16: =VLOOKUP("新豐1線",'0130 4度C'!$A:$T,19,0) -> 0.20833333 | J16: =VLOOKUP("新豐10線",'0130 4度C'!$A:$T,19,0) -> 0.20833333 | K16: =VLOOKUP("新豐8線",'0130 4度C'!$A:$T,19,0) -> 0.125 | L16: =VLOOKUP("新豐9線",'0130 4度C'!$A:$T,19,0) -> 0.125 | M16: =VLOOKUP("新豐4線",'0130 4度C'!$A:$T,19,0) -> 0.125
C17: 結束 | D17: =LOOKUP(2,1/(('0130 4度C'!$A:$A="新豐6線")*('0130 4度C'!$T:$T<>"")),'0130 4度C'!$T:$T) -> 0.84236111 | E17: =LOOKUP(2,1/(('0130 4度C'!$A:$A="新豐2線")*('0130 4度C'!$T:$T<>"")),'0130 4度C'!$T:$T) -> 0.4 | F17: =LOOKUP(2,1/(('0130 4度C'!$A:$A="新豐5線")*('0130 4度C'!$T:$T<>"")),'0130 4度C'!$T:$T) -> 0.92013889 | G17: =LOOKUP(2,1/(('0130 4度C'!$A:$A="新豐7線")*('0130 4度C'!$T:$T<>"")),'0130 4度C'!$T:$T) -> 0.82916667 | H17: =LOOKUP(2,1/(('0130 4度C'!$A:$A="新豐3線")*('0130 4度C'!$T:$T<>"")),'0130 4度C'!$T:$T) -> 0.59930556 | I17: =LOOKUP(2,1/(('0130 4度C'!$A:$A="新豐1線")*('0130 4度C'!$T:$T<>"")),'0130 4度C'!$T:$T) -> 0.85486111 | J17: =LOOKUP(2,1/(('0130 4度C'!$A:$A="新豐10線")*('0130 4度C'!$T:$T<>"")),'0130 4度C'!$T:$T) -> 0.40833333 | K17: =LOOKUP(2,1/(('0130 4度C'!$A:$A="新豐8線")*('0130 4度C'!$T:$T<>"")),'0130 4度C'!$T:$T) -> 0.49305556 | L17: =LOOKUP(2,1/(('0130 4度C'!$A:$A="新豐9線")*('0130 4度C'!$T:$T<>"")),'0130 4度C'!$T:$T) -> 0.51805556 | M17: =LOOKUP(2,1/(('0130 4度C'!$A:$A="新豐4線")*('0130 4度C'!$T:$T<>"")),'0130 4度C'!$T:$T) -> 0.47569444
B18: 產線異常 (5分鐘以上) | C18: 次數 | D18: =SUMIFS('0130 4度C'!$Y:$Y,'0130 4度C'!$A:$A,"新豐6線",'0130 4度C'!$B:$B,"平均") -> 0 | E18: =SUMIFS('0130 4度C'!$Y:$Y,'0130 4度C'!$A:$A,"新豐2線",'0130 4度C'!$B:$B,"平均") -> 0 | F18: =SUMIFS('0130 4度C'!$Y:$Y,'0130 4度C'!$A:$A,"新豐5線",'0130 4度C'!$B:$B,"平均") -> 0 | G18: =SUMIFS('0130 4度C'!$Y:$Y,'0130 4度C'!$A:$A,"新豐7線",'0130 4度C'!$B:$B,"平均") -> 0 | H18: =SUMIFS('0130 4度C'!$Y:$Y,'0130 4度C'!$A:$A,"新豐3線",'0130 4度C'!$B:$B,"平均") -> 0 | I18: =SUMIFS('0130 4度C'!$Y:$Y,'0130 4度C'!$A:$A,"新豐1線",'0130 4度C'!$B:$B,"平均") -> 0 | J18: =SUMIFS('0130 4度C'!$Y:$Y,'0130 4度C'!$A:$A,"新豐10線",'0130 4度C'!$B:$B,"平均") -> 0 | K18: =SUMIFS('0130 4度C'!$Y:$Y,'0130 4度C'!$A:$A,"新豐8線",'0130 4度C'!$B:$B,"平均") -> 0 | L18: =SUMIFS('0130 4度C'!$Y:$Y,'0130 4度C'!$A:$A,"新豐9線",'0130 4度C'!$B:$B,"平均") -> 0 | M18: =SUMIFS('0130 4度C'!$Y:$Y,'0130 4度C'!$A:$A,"新豐4線",'0130 4度C'!$B:$B,"平均") -> 0
C19: 時間/分 | D19: =SUMIFS('0130 4度C'!$Z:$Z,'0130 4度C'!$A:$A,"新豐6線",'0130 4度C'!$B:$B,"平均") -> 0 | E19: =SUMIFS('0130 4度C'!$Z:$Z,'0130 4度C'!$A:$A,"新豐2線",'0130 4度C'!$B:$B,"平均") -> 0 | F19: =SUMIFS('0130 4度C'!$Z:$Z,'0130 4度C'!$A:$A,"新豐5線",'0130 4度C'!$B:$B,"平均") -> 0 | G19: =SUMIFS('0130 4度C'!$Z:$Z,'0130 4度C'!$A:$A,"新豐7線",'0130 4度C'!$B:$B,"平均") -> 0 | H19: =SUMIFS('0130 4度C'!$Z:$Z,'0130 4度C'!$A:$A,"新豐3線",'0130 4度C'!$B:$B,"平均") -> 0 | I19: =SUMIFS('0130 4度C'!$Z:$Z,'0130 4度C'!$A:$A,"新豐1線",'0130 4度C'!$B:$B,"平均") -> 0 | J19: =SUMIFS('0130 4度C'!$Z:$Z,'0130 4度C'!$A:$A,"新豐10線",'0130 4度C'!$B:$B,"平均") -> 0 | K19: =SUMIFS('0130 4度C'!$Z:$Z,'0130 4度C'!$A:$A,"新豐8線",'0130 4度C'!$B:$B,"平均") -> 0 | L19: =SUMIFS('0130 4度C'!$Z:$Z,'0130 4度C'!$A:$A,"新豐9線",'0130 4度C'!$B:$B,"平均") -> 0 | M19: =SUMIFS('0130 4度C'!$Z:$Z,'0130 4度C'!$A:$A,"新豐4線",'0130 4度C'!$B:$B,"平均") -> 0
B20: 短暫停線 (5分鐘以下) | C20: 次數 | D20: =SUMIFS('0130 4度C'!$AC:$AC,'0130 4度C'!$A:$A,"新豐6線",'0130 4度C'!$B:$B,"平均") -> 1 | E20: =SUMIFS('0130 4度C'!$AC:$AC,'0130 4度C'!$A:$A,"新豐2線",'0130 4度C'!$B:$B,"平均") -> 2 | F20: =SUMIFS('0130 4度C'!$AC:$AC,'0130 4度C'!$A:$A,"新豐5線",'0130 4度C'!$B:$B,"平均") -> 3 | G20: =SUMIFS('0130 4度C'!$AC:$AC,'0130 4度C'!$A:$A,"新豐7線",'0130 4度C'!$B:$B,"平均") -> 2 | H20: =SUMIFS('0130 4度C'!$AC:$AC,'0130 4度C'!$A:$A,"新豐3線",'0130 4度C'!$B:$B,"平均") -> 0 | I20: =SUMIFS('0130 4度C'!$AC:$AC,'0130 4度C'!$A:$A,"新豐1線",'0130 4度C'!$B:$B,"平均") -> 4 | J20: =SUMIFS('0130 4度C'!$AC:$AC,'0130 4度C'!$A:$A,"新豐10線",'0130 4度C'!$B:$B,"平均") -> 1 | K20: =SUMIFS('0130 4度C'!$AC:$AC,'0130 4度C'!$A:$A,"新豐8線",'0130 4度C'!$B:$B,"平均") -> 6 | L20: =SUMIFS('0130 4度C'!$AC:$AC,'0130 4度C'!$A:$A,"新豐9線",'0130 4度C'!$B:$B,"平均") -> 6 | M20: =SUMIFS('0130 4度C'!$AC:$AC,'0130 4度C'!$A:$A,"新豐4線",'0130 4度C'!$B:$B,"平均") -> 5
C21: 設備次數 | D21: =SUMIFS('0130 4度C'!$AD:$AD,'0130 4度C'!$A:$A,"新豐6線",'0130 4度C'!$B:$B,"平均") -> 0 | E21: =SUMIFS('0130 4度C'!$AD:$AD,'0130 4度C'!$A:$A,"新豐2線",'0130 4度C'!$B:$B,"平均") -> 0 | F21: =SUMIFS('0130 4度C'!$AD:$AD,'0130 4度C'!$A:$A,"新豐5線",'0130 4度C'!$B:$B,"平均") -> 0 | G21: =SUMIFS('0130 4度C'!$AD:$AD,'0130 4度C'!$A:$A,"新豐7線",'0130 4度C'!$B:$B,"平均") -> 0 | H21: =SUMIFS('0130 4度C'!$AD:$AD,'0130 4度C'!$A:$A,"新豐3線",'0130 4度C'!$B:$B,"平均") -> 0 | I21: =SUMIFS('0130 4度C'!$AD:$AD,'0130 4度C'!$A:$A,"新豐1線",'0130 4度C'!$B:$B,"平均") -> 0 | J21: =SUMIFS('0130 4度C'!$AD:$AD,'0130 4度C'!$A:$A,"新豐10線",'0130 4度C'!$B:$B,"平均") -> 0 | K21: =SUMIFS('0130 4度C'!$AD:$AD,'0130 4度C'!$A:$A,"新豐8線",'0130 4度C'!$B:$B,"平均") -> 0 | L21: =SUMIFS('0130 4度C'!$AD:$AD,'0130 4度C'!$A:$A,"新豐9線",'0130 4度C'!$B:$B,"平均") -> 0 | M21: =SUMIFS('0130 4度C'!$AD:$AD,'0130 4度C'!$A:$A,"新豐4線",'0130 4度C'!$B:$B,"平均") -> 0
B22: 配置人數 | D22: =SUMIFS('0130 4度C'!$I:$I,'0130 4度C'!$A:$A,"新豐6線",'0130 4度C'!$B:$B,"平均") -> 17.6 | E22: =SUMIFS('0130 4度C'!$I:$I,'0130 4度C'!$A:$A,"新豐2線",'0130 4度C'!$B:$B,"平均") -> 18 | F22: =SUMIFS('0130 4度C'!$I:$I,'0130 4度C'!$A:$A,"新豐5線",'0130 4度C'!$B:$B,"平均") -> 17 | G22: =SUMIFS('0130 4度C'!$I:$I,'0130 4度C'!$A:$A,"新豐7線",'0130 4度C'!$B:$B,"平均") -> 15.666667 | H22: =SUMIFS('0130 4度C'!$I:$I,'0130 4度C'!$A:$A,"新豐3線",'0130 4度C'!$B:$B,"平均") -> 10 | I22: =SUMIFS('0130 4度C'!$I:$I,'0130 4度C'!$A:$A,"新豐1線",'0130 4度C'!$B:$B,"平均") -> 18.666667 | J22: =SUMIFS('0130 4度C'!$I:$I,'0130 4度C'!$A:$A,"新豐10線",'0130 4度C'!$B:$B,"平均") -> 10.6 | K22: =SUMIFS('0130 4度C'!$I:$I,'0130 4度C'!$A:$A,"新豐8線",'0130 4度C'!$B:$B,"平均") -> 18.2 | L22: =SUMIFS('0130 4度C'!$I:$I,'0130 4度C'!$A:$A,"新豐9線",'0130 4度C'!$B:$B,"平均") -> 17.833333 | M22: =SUMIFS('0130 4度C'!$I:$I,'0130 4度C'!$A:$A,"新豐4線",'0130 4度C'!$B:$B,"平均") -> 16.4
B23: 主要應用設備 | D23: ET-55 | E23: 熱縮爐 | F23: L型包裝機 | G23: L型包裝機 | H23: 伺服包裝機 | I23: ET-55 | J23: 伺服包裝機 | K23: 三明治包裝機 | L23: 三明治包裝機 | M23: 三明治包裝機
B24: 次要應用設備 | F24: 圓盤機 | G24: ET-55
B25: 備註 | E25: 握沙拉 | F25: 共用L型包裝機 | H25: 調理麵包 | I25: 炒飯+沙拉 | J25: 調理麵包

Sheet 0130 4度C
A1: 新豐廠四度C日報分析 | C1: 總生產量 | D1: =SUM(F5:F73) -> 128261 | E1: 營業額 | F1: =SUM(G5:G73) -> 4449272.8 | G1: 出勤人數 | H1: =L10+L13+L51+L61+L21+L67+L34+L41+L28+L73 -> 159.96667 | I1: 產線配置圖 | L1: 生產實績 | O1: 人時性差異分析 | S1: 日報登錄 | Y1: 合計 次數 | Z1: 合計 時間/分 | AA1: 產線異常 分析說明(5分鐘以上) | AC1: 合計 次數 | AD1: 合計 設備次數 | AE1: 產能差異分析
A2: 46052 | B2: 星期五 | C2: 人時性 | D2: =AVERAGE(N10,N13,N51,N61,N21,N67,N28,N34,N41,N73) -> 137.44239 | E2: 平均廠價 | F2: =F1/D1 -> 34.68921 | G2: 多次生產數 | H2: =COUNT(H5:H73) -> 3 | Y2: =SUM(Y10+Y13+Y21+Y28+Y34+Y41+Y51+Y61+Y67+Y73) -> 0 | Z2: =SUM(Z10+Z13+Z21+Z28+Z34+Z41+Z51+Z61+Z67+Z73) -> 0 | AC2: 30 | AD2: =SUM(AD10+AD13+AD21+AD28+AD34+AD41+AD51+AD61+AD67+AD73) -> 0
A3: 線別 | B3: 品類 | C3: 品名 | E3: 廠價 | F3: 生產量 | G3: 營收 | H3: 多次 生產 | I3: 人數 | J3: 產能/時 | K3: 人時性 | L3: 人數 | M3: 產能/時 | N3: 人時性 | O3: 人數 | P3: 人時性 | Q3: 達成率 | R3: 達成率平均 | S3: 生產時間 | U3: 換線、休息/分 | V3: 稼動時間/分 | W3: 休息時間 | Y3: 產線異常統計 (5分鐘以上) | AA3: (新豐回填) | AC3: 短暫停線統計 (5分鐘以下) | AE3: 產能/時 | AF3: 達成率 | AG3: 達成率平均
S4: 開始 | T4: 結束 | W4: 開始 | X4: 結束 | Y4: 次數 | Z4: 時間/分 | AC4: 總次數 | AD4: 設備因素(次數)
A5: 新豐6線 | B5: 微波主食 | C5: 二配港式香滑嫩蛋牛肉燴飯 | E5: 50.67 | F5: 1174 | G5: =E5*F5 -> 59486.58 | I5: 17 | J5: 2000 | K5: =J5/I5 -> 117.64706 | L5: 17 | M5: =F5/V5*60 -> 1903.7838 | N5: =M5/L5 -> 111.98728 | O5: =L5-I5 -> 0 | P5: =N5-K5 -> -5.6597774 | Q5: =N5/K5 -> 0.95189189 | R5: =Q10 -> 0.96404822 | S5: 0.70833333 | T5: 0.73402778 | V5: =(T5-S5)*24*60 -> 37 | AC5: 1 | AE5: =M5-J5 -> -96.216216 | AF5: =M5/J5 -> 0.95189189 | AG5: =AF10 -> 0.96404822
A6: 新豐6線 | B6: 微波主食 | C6: 二配美味蟹煲 | E6: 54.09 | F6: 1129 | G6: =E6*F6 -> 61067.61 | I6: 19 | J6: 2000 | K6: =J6/I6 -> 105.26316 | L6: 19 | M6: =F6/V6*60 -> 1935.4286 | N6: =M6/L6 -> 101.86466 | O6: =L6-I6 -> 0 | P6: =N6-K6 -> -3.3984962 | Q6: =N6/K6 -> 0.96771429 | S6: 0.73888889 | T6: 0.76319444 | U6: =IF(S6=TIME(17,0,0),"",(S6-T5)*24*60) -> 7 | V6: =(T6-S6)*24*60 -> 35 | AE6: =M6-J6 -> -64.571429 | AF6: =M6/J6 -> 0.96771429
A7: 新豐6線 | B7: 微波主食 | C7: 二配麻油雞燴飯 | E7: 50.29 | F7: 736 | G7: =E7*F7 -> 37013.44 | I7: 16 | J7: 2000 | K7: =J7/I7 -> 125 | L7: 16 | M7: =F7/V7*60 -> 1920 | N7: =M7/L7 -> 120 | O7: =L7-I7 -> 0 | P7: =N7-K7 -> -5 | Q7: =N7/K7 -> 0.96 | S7: 0.76736111 | T7: 0.78333333 | U7: =IF(S7=TIME(17,0,0),"",(S7-T6)*24*60) -> 6 | V7: =(T7-S7)*24*60 -> 23 | AE7: =M7-J7 -> -80 | AF7: =M7/J7 -> 0.96
A8: 新豐6線 | B8: 微波主食 | C8: 二配紅燒牛肉燴飯 | E8: 57.3 | F8: 1362 | G8: =E8*F8 -> 78042.6 | I8: 15 | J8: 2000 | K8: =J8/I8 -> 133.33333 | L8: 15 | M8: =F8/V8*60 -> 1945.7143 | N8: =M8/L8 -> 129.71429 | O8: =L8-I8 -> 0 | P8: =N8-K8 -> -3.6190476 | Q8: =N8/K8 -> 0.97285714 | S8: 0.78888889 | T8: 0.81805556 | U8: =IF(S8=TIME(17,0,0),"",(S8-T7)*24*60) -> 8 | V8: =(T8-S8)*24*60 -> 42 | AE8: =M8-J8 -> -54.285714 | AF8: =M8/J8 -> 0.97285714
A9: 新豐6線 | B9: 微波主食 | C9: 二配濃蕃茄火腿蛋包飯 | E9: 50.67 | F9: 871 | G9: =E9*F9 -> 44133.57 | I9: 21 | J9: 2000 | K9: =J9/I9 -> 95.238095 | L9: 21 | M9: =F9/V9*60 -> 1935.5556 | N9: =M9/L9 -> 92.169312 | O9: =L9-I9 -> 0 | P9: =N9-K9 -> -3.0687831 | Q9: =N9/K9 -> 0.96777778 | S9: 0.82361111 | T9: 0.84236111 | U9: =IF(S9=TIME(17,0,0),"",(S9-T8)*24*60) -> 8 | V9: =(T9-S9)*24*60 -> 27 | AE9: =M9-J9 -> -64.444444 | AF9: =M9/J9 -> 0.96777778
A10: 新豐6線 | B10: 平均 | I10: 17.6 | J10: 2000 | K10: =J10/I10 -> 113.63636 | L10: 17.6 | M10: =AVERAGE(M5:M9) -> 1928.0964 | N10: =M10/L10 -> 109.55093 | O10: =L10-I10 -> 0 | P10: =N10-K10 -> -4.0854296 | Q10: =N10/K10 -> 0.96404822 | Y10: =SUM(Y5:Y9) -> 0 | Z10: =SUM(Z5:Z9) -> 0 | AC10: 1 | AD10: =SUM(AD5:AD9) -> 0 | AE10: =M10-J10 -> -71.903561 | AF10: =M10/J10 -> 0.96404822
A11: 新豐2線 | B11: 沙拉 | C11: 青醬優格雞肉握沙拉(113年) | E11: 39.62 | F11: 2417 | G11: =E11*F11 -> 95761.54 | I11: 19 | J11: 1500 | K11: =J11/I11 -> 78.947368 | L11: 19 | M11: =F11/V11*60 -> 1435.8416 | N11: =M11/L11 -> 75.57061 | O11: =L11-I11 -> 0 | P11: =N11-K11 -> -3.3767587 | Q11: =N11/K11 -> 0.95722772 | R11: =Q13 -> 0.95555504 | S11: 0.20833333 | T11: 0.27847222 | V11: =(T11-S11)*24*60 -> 101 | AC11: 2 | AE11: =M11-J11 -> -64.158416 | AF11: =M11/J11 -> 0.95722772 | AG11: =AF13 -> 0.95555504
A12: 新豐2線 | B12: 沙拉 | C12: 青檸烤雞握沙拉(113年) | E12: 39.8 | F12: 4054 | G12: =E12*F12 -> 161349.2 | I12: 17 | J12: 1500 | K12: =J12/I12 -> 88.235294 | L12: 17 | M12: =F12/V12*60 -> 1430.8235 | N12: =M12/L12 -> 84.16609 | O12: =L12-I12 -> 0 | P12: =N12-K12 -> -4.0692042 | Q12: =N12/K12 -> 0.95388235 | S12: 0.28194444 | T12: 0.4 | U12: =IF(S12=TIME(17,0,0),"",(S12-T11)*24*60) -> 5 | V12: =(T12-S12)*24*60 -> 170 | AE12: =M12-J12 -> -69.176471 | AF12: =M12/J12 -> 0.95388235
A13: 新豐2線 | B13: 平均 | I13: 18 | J13: 1500 | K13: =J13/I13 -> 83.333333 | L13: 18 | M13: =AVERAGE(M11:M12) -> 1433.3326 | N13: =M13/L13 -> 79.629586 | O13: =L13-I13 -> 0 | P13: =N13-K13 -> -3.7037468 | Q13: =N13/K13 -> 0.95555504 | Y13: =SUM(Y11:Y12) -> 0 | Z13: =SUM(Z11:Z12) -> 0 | AC13: 2 | AD13: =SUM(AD11:AD12) -> 0 | AE13: =M13-J13 -> -66.667443 | AF13: =M13/J13 -> 0.95555504
A14: 新豐5線 | B14: 小吃 | C14: 剝皮辣椒雞湯 | E14: 41 | F14: 1716 | G14: =E14*F14 -> 70356 | I14: 26 | J14: 1500 | K14: =J14/I14 -> 57.692308 | L14: 26 | M14: =F14/V14*60 -> 1430 | N14: =M14/L14 -> 55 | O14: =L14-I14 -> 0 | P14: =N14-K14 -> -2.6923077 | Q14: =N14/K14 -> 0.95333333 | R14: =Q21 -> 0.95945448 | S14: 0.20833333 | T14: 0.25833333 | V14: =(T14-S14)*24*60 -> 72 | AC14: 3 | AE14: =M14-J14 -> -70 | AF14: =M14/J14 -> 0.95333333 | AG14: =AF21 -> 0.95945448
A15: 新豐5線 | B15: 季節調理麵 | C15: 柚子雞白湯拉麵 | E15: 72.4 | F15: 672 | G15: =E15*F15 -> 48652.8 | I15: 18 | J15: 1500 | K15: =J15/I15 -> 83.333333 | L15: 18 | M15: =F15/V15*60 -> 1440 | N15: =M15/L15 -> 80 | O15: =L15-I15 -> 0 | P15: =N15-K15 -> -3.3333333 | Q15: =N15/K15 -> 0.96 | S15: 0.26319444 | T15: 0.28263889 | U15: =IF(S15=TIME(17,0,0),"",(S15-T14)*24*60) -> 7 | V15: =(T15-S15)*24*60 -> 28 | AE15: =M15-J15 -> -60 | AF15: =M15/J15 -> 0.96
A16: 新豐5線 | B16: 微波主食 | C16: 二配金咖哩濃厚辛口咖哩飯 | E16: 50.98 | F16: 1000 | G16: =E16*F16 -> 50980 | H16: 2 | I16: 16 | J16: 2000 | K16: =J16/I16 -> 125 | L16: 16 | M16: =F16/V16*60 -> 1935.4839 | N16: =M16/L16 -> 120.96774 | O16: =L16-I16 -> 0 | P16: =N16-K16 -> -4.0322581 | Q16: =N16/K16 -> 0.96774194 | S16: 0.70833333 | T16: 0.72986111 | U16: =IF(S16=TIME(17,0,0),"",(S16-T15)*24*60) | V16: =(T16-S16)*24*60 -> 31 | AE16: =M16-J16 -> -64.516129 | AF16: =M16/J16 -> 0.96774194
A17: 新豐5線 | B17: 微波主食 | C17: 二配金咖哩果香甘口咖哩飯 | E17: 50.92 | F17: 2054 | G17: =E17*F17 -> 104589.68 | I17: 15 | J17: 2000 | K17: =J17/I17 -> 133.33333 | L17: 15 | M17: =F17/V17*60 -> 1925.625 | N17: =M17/L17 -> 128.375 | O17: =L17-I17 -> 0 | P17: =N17-K17 -> -4.9583333 | Q17: =N17/K17 -> 0.9628125 | S17: 0.73541667 | T17: 0.77986111 | U17: =IF(S17=TIME(17,0,0),"",(S17-T16)*24*60) -> 8 | V17: =(T17-S17)*24*60 -> 64 | AE17: =M17-J17 -> -74.375 | AF17: =M17/J17 -> 0.9628125
A18: 新豐5線 | B18: 微波主食 | C18: 二配泰式綠咖哩雞 | E18: 50.67 | F18: 1415 | G18: =E18*F18 -> 71698.05 | I18: 15 | J18: 2000 | K18: =J18/I18 -> 133.33333 | L18: 15 | M18: =F18/V18*60 -> 1929.5455 | N18: =M18/L18 -> 128.63636 | O18: =L18-I18 -> 0 | P18: =N18-K18 -> -4.6969697 | Q18: =N18/K18 -> 0.96477273 | S18: 0.78333333 | T18: 0.81388889 | U18: =IF(S18=TIME(17,0,0),"",(S18-T17)*24*60) -> 5 | V18: =(T18-S18)*24*60 -> 44 | AE18: =M18-J18 -> -70.454545 | AF18: =M18/J18 -> 0.96477273
A19: 新豐5線 | B19: 微波主食 | C19: 二配厚香料咖哩雞排飯 | E19: 57.3 | F19: 1720 | G19: =E19*F19 -> 98556 | I19: 13 | J19: 2000 | K19: =J19/I19 -> 153.84615 | L19: 13 | M19: =F19/V19*60 -> 1911.1111 | N19: =M19/L19 -> 147.00855 | O19: =L19-I19 -> 0 | P19: =N19-K19 -> -6.8376068 | Q19: =N19/K19 -> 0.95555556 | S19: 0.81805556 | T19: 0.85555556 | U19: =IF(S19=TIME(17,0,0),"",(S19-T18)*24*60) -> 6 | V19: =(T19-S19)*24*60 -> 54 | W19: =T19 -> 0.85555556 | X19: =S20 -> 0.89583333 | AE19: =M19-J19 -> -88.888889 | AF19: =M19/J19 -> 0.95555556
A20: 新豐5線 | B20: 微波主食 | C20: 二配金咖哩濃厚辛口咖哩飯 | E20: 50.98 | F20: 1109 | G20: =E20*F20 -> 56536.82 | I20: 16 | J20: 2000 | K20: =J20/I20 -> 125 | L20: 16 | M20: =F20/V20*60 -> 1901.1429 | N20: =M20/L20 -> 118.82143 | O20: =L20-I20 -> 0 | P20: =N20-K20 -> -6.1785714 | Q20: =N20/K20 -> 0.95057143 | S20: 0.89583333 | T20: 0.92013889 | U20: =IF(S20=TIME(17,0,0),"",(S20-T19)*24*60) -> 58 | V20: =(T20-S20)*24*60 -> 35 | AE20: =M20-J20 -> -98.857143 | AF20: =M20/J20 -> 0.95057143
A21: 新豐5線 | B21: 平均 | I21: 17 | J21: 1857.1429 | K21: =J21/I21 -> 109.2437 | L21: 17 | M21: =AVERAGE(M14:M20) -> 1781.844 | N21: =M21/L21 -> 104.81436 | O21: =L21-I21 -> 0 | P21: =N21-K21 -> -4.4293421 | Q21: =N21/K21 -> 0.95945448 | Y21: =SUM(Y14:Y20) -> 0 | Z21: =SUM(Z14:Z20) -> 0 | AC21: 3 | AD21: =SUM(AD14:AD20) -> 0 | AE21: =M21-J21 -> -75.298815 | AF21: =M21/J21 -> 0.95945448
A22: 新豐7線 | B22: 小吃 | C22: 古早味炒炊粉 | E22: 43.14 | F22: 708 | G22: =E22*F22 -> 30543.12 | I22: 17 | J22: 2000 | K22: =J22/I22 -> 117.64706 | L22: 17 | M22: =F22/V22*60 -> 1930.9091 | N22: =M22/L22 -> 113.58289 | O22: =L22-I22 -> 0 | P22: =N22-K22 -> -4.0641711 | Q22: =N22/K22 -> 0.96545455 | R22: =Q28 -> 0.95989365 | S22: 0.20833333 | T22: 0.22361111 | V22: =(T22-S22)*24*60 -> 22 | AC22: 2 | AE22: =M22-J22 -> -69.090909 | AF22: =M22/J22 -> 0.96545455 | AG22: =AF28 -> 0.95989365
A23: 新豐7線 | B23: 微波主食 | C23: 鐵板滑蛋炸豬排丼 | E23: 57.73 | F23: 2163 | G23: =E23*F23 -> 124869.99 | I23: 14 | J23: 2000 | K23: =J23/I23 -> 142.85714 | L23: 14 | M23: =F23/V23*60 -> 1908.5294 | N23: =M23/L23 -> 136.32353 | O23: =L23-I23 -> 0 | P23: =N23-K23 -> -6.5336134 | Q23: =N23/K23 -> 0.95426471 | S23: 0.22777778 | T23: 0.275 | U23: =IF(S23=TIME(17,0,0),"",(S23-T22)*24*60) -> 6 | V23: =(T23-S23)*24*60 -> 68 | AE23: =M23-J23 -> -91.470588 | AF23: =M23/J23 -> 0.95426471
A24: 新豐7線 | B24: 微波主食 | C24: 極上炙烤親子丼 | E24: 53.68 | F24: 1187 | G24: =E24*F24 -> 63718.16 | I24: 16 | J24: 2000 | K24: =J24/I24 -> 125 | L24: 16 | M24: =F24/V24*60 -> 1924.8649 | N24: =M24/L24 -> 120.30405 | O24: =L24-I24 -> 0 | P24: =N24-K24 -> -4.6959459 | Q24: =N24/K24 -> 0.96243243 | S24: 0.28055556 | T24: 0.30625 | U24: =IF(S24=TIME(17,0,0),"",(S24-T23)*24*60) -> 8 | V24: =(T24-S24)*24*60 -> 37 | AE24: =M24-J24 -> -75.135135 | AF24: =M24/J24 -> 0.96243243
A25: 新豐7線 | B25: 微波主食 | C25: 二配川味麻婆燒豆腐燴飯 | E25: 50.49 | F25: 1716 | G25: =E25*F25 -> 86640.84 | I25: 15 | J25: 2000 | K25: =J25/I25 -> 133.33333 | L25: 15 | M25: =F25/V25*60 -> 1906.6667 | N25: =M25/L25 -> 127.11111 | O25: =L25-I25 -> 0 | P25: =N25-K25 -> -6.2222222 | Q25: =N25/K25 -> 0.95333333 | S25: 0.70833333 | T25: 0.74583333 | U25: =IF(S25=TIME(17,0,0),"",(S25-T24)*24*60) | V25: =(T25-S25)*24*60 -> 54 | AE25: =M25-J25 -> -93.333333 | AF25: =M25/J25 -> 0.95333333
A26: 新豐7線 | B26: 微波主食 | C26: 二配香炒沙茶豬肉飯 | E26: 50.67 | F26: 931 | G26: =E26*F26 -> 47173.77 | I26: 16 | J26: 2000 | K26: =J26/I26 -> 125 | L26: 16 | M26: =F26/V26*60 -> 1926.2069 | N26: =M26/L26 -> 120.38793 | O26: =L26-I26 -> 0 | P26: =N26-K26 -> -4.612069 | Q26: =N26/K26 -> 0.96310345 | S26: 0.75138889 | T26: 0.77152778 | U26: =IF(S26=TIME(17,0,0),"",(S26-T25)*24*60) -> 8 | V26: =(T26-S26)*24*60 -> 29 | AE26: =M26-J26 -> -73.793103 | AF26: =M26/J26 -> 0.96310345
A27: 新豐7線 | B27: 微波主食 | C27: 二配起司控培根白醬焗烤飯 | E27: 53.68 | F27: 1802 | G27: =E27*F27 -> 96731.36 | I27: 16 | J27: 1500 | K27: =J27/I27 -> 93.75 | L27: 16 | M27: =F27/V27*60 -> 1441.6 | N27: =M27/L27 -> 90.1 | O27: =L27-I27 -> 0 | P27: =N27-K27 -> -3.65 | Q27: =N27/K27 -> 0.96106667 | S27: 0.77708333 | T27: 0.82916667 | U27: =IF(S27=TIME(17,0,0),"",(S27-T26)*24*60) -> 8 | V27: =(T27-S27)*24*60 -> 75 | AE27: =M27-J27 -> -58.4 | AF27: =M27/J27 -> 0.96106667
A28: 新豐7線 | B28: 平均 | I28: 15.666667 | J28: 1916.6667 | K28: =J28/I28 -> 122.34043 | L28: 15.666667 | M28: =AVERAGE(M22:M27) -> 1839.7962 | N28: =M28/L28 -> 117.4338 | O28: =L28-I28 -> 0 | P28: =N28-K28 -> -4.9066284 | Q28: =N28/K28 -> 0.95989365 | Y28: =SUM(Y22:Y27) -> 0 | Z28: =SUM(Z22:Z27) -> 0 | AC28: 2 | AD28: =SUM(AD22:AD27) -> 0 | AE28: =M28-J28 -> -76.870512 | AF28: =M28/J28 -> 0.95989365
A29: 新豐8線 | B29: 三明治 | C29: 紐奧良風味烤雞鮮蔬三明治 | E29: 31.29 | F29: 6673 | G29: =E29*F29 -> 208798.17 | I29: 18 | J29: 2400 | K29: =J29/I29 -> 133.33333 | L29: 18 | M29: =F29/V29*60 -> 2287.8857 | N29: =M29/L29 -> 127.10476 | O29: =L29-I29 -> 0 | P29: =N29-K29 -> -6.2285714 | Q29: =N29/K29 -> 0.95328571 | R29: =Q34 -> 0.95774551 | S29: 0.125 | T29: 0.24652778 | V29: =(T29-S29)*24*60 -> 175 | W29: =T29 -> 0.24652778 | X29: =S30 -> 0.26458333 | AC29: 6 | AE29: =M29-J29 -> -112.11429 | AF29: =M29/J29 -> 0.95328571 | AG29: =AF34 -> 0.95774551
A30: 新豐8線 | B30: 三明治 | C30: 經典總匯三明治 | E30: 26.2 | F30: 3586 | G30: =E30*F30 -> 93953.2 | I30: 20 | J30: 2400 | K30: =J30/I30 -> 120 | L30: 20 | M30: =F30/V30*60 -> 2288.9362 | N30: =M30/L30 -> 114.44681 | O30: =L30-I30 -> 0 | P30: =N30-K30 -> -5.5531915 | Q30: =N30/K30 -> 0.9537234 | S30: 0.26458333 | T30: 0.32986111 | U30: =(S30-T29)*24*60 -> 26 | V30: =(T30-S30)*24*60 -> 94 | AE30: =M30-J30 -> -111.06383 | AF30: =M30/J30 -> 0.9537234
A31: 新豐8線 | B31: 三明治 | C31: 雞蛋沙拉三明治(114年) | E31: 25.99 | F31: 3037 | G31: =E31*F31 -> 78931.63 | I31: 14 | J31: 2400 | K31: =J31/I31 -> 171.42857 | L31: 14 | M31: =F31/V31*60 -> 2306.5823 | N31: =M31/L31 -> 164.75588 | O31: =L31-I31 -> 0 | P31: =N31-K31 -> -6.6726944 | Q31: =N31/K31 -> 0.96107595 | S31: 0.33541667 | T31: 0.39027778 | U31: =(S31-T30)*24*60 -> 8 | V31: =(T31-S31)*24*60 -> 79 | AE31: =M31-J31 -> -93.417722 | AF31: =M31/J31 -> 0.96107595
A32: 新豐8線 | B32: 三明治 | C32: 肉鬆火腿三明治 | E32: 20.52 | F32: 2843 | G32: =E32*F32 -> 58338.36 | I32: 18 | J32: 2400 | K32: =J32/I32 -> 133.33333 | L32: 18 | M32: =F32/V32*60 -> 2305.1351 | N32: =M32/L32 -> 128.06306 | O32: =L32-I32 -> 0 | P32: =N32-K32 -> -5.2702703 | Q32: =N32/K32 -> 0.96047297 | S32: 0.39513889 | T32: 0.44652778 | U32: =(S32-T31)*24*60 -> 7 | V32: =(T32-S32)*24*60 -> 74 | AE32: =M32-J32 -> -94.864865 | AF32: =M32/J32 -> 0.96047297
A33: 新豐8線 | B33: 三明治 | C33: 好多菜三明治(114年) | E33: 25.98 | F33: 2266 | G33: =E33*F33 -> 58870.68 | I33: 21 | J33: 2400 | K33: =J33/I33 -> 114.28571 | L33: 21 | M33: =F33/V33*60 -> 2304.4068 | N33: =M33/L33 -> 109.73366 | O33: =L33-I33 -> 0 | P33: =N33-K33 -> -4.5520581 | Q33: =N33/K33 -> 0.96016949 | S33: 0.45208333 | T33: 0.49305556 | U33: =(S33-T32)*24*60 -> 8 | V33: =(T33-S33)*24*60 -> 59 | AE33: =M33-J33 -> -95.59322 | AF33: =M33/J33 -> 0.96016949
A34: 新豐8線 | B34: 平均 | I34: 18.2 | J34: 2400 | K34: =J34/I34 -> 131.86813 | L34: 18.2 | M34: =AVERAGE(M29:M33) -> 2298.5892 | N34: =M34/L34 -> 126.29611 | O34: =L34-I34 -> 0 | P34: =N34-K34 -> -5.5720211 | Q34: =N34/K34 -> 0.95774551 | Y34: =SUM(Y29:Y33) -> 0 | Z34: =SUM(Z29:Z33) -> 0 | AC34: 6 | AD34: =SUM(AD29:AD33) -> 0 | AE34: =M34-J34 -> -101.41078 | AF34: =M34/J34 -> 0.95774551
A35: 新豐9線 | B35: 三明治 | C35: 鮪魚起司溏心蛋三明治 | E35: 26.2 | F35: 4550 | G35: =E35*F35 -> 119210 | I35: 18 | J35: 2400 | K35: =J35/I35 -> 133.33333 | L35: 18 | M35: =F35/V35*60 -> 2294.1176 | N35: =M35/L35 -> 127.45098 | O35: =L35-I35 -> 0 | P35: =N35-K35 -> -5.8823529 | Q35: =N35/K35 -> 0.95588235 | R35: =Q41 -> 0.95653455 | S35: 0.125 | T35: 0.20763889 | V35: =(T35-S35)*24*60 -> 119 | W35: =T35 -> 0.20763889 | X35: =S36 -> 0.22777778 | AC35: 6 | AE35: =M35-J35 -> -105.88235 | AF35: =M35/J35 -> 0.95588235 | AG35: =AF41 -> 0.95653455
A36: 新豐9線 | B36: 三明治 | C36: 陽光地瓜總匯三明治 | E36: 26.18 | F36: 1538 | G36: =E36*F36 -> 40264.84 | I36: 19 | J36: 2400 | K36: =J36/I36 -> 126.31579 | L36: 19 | M36: =F36/V36*60 -> 2307 | N36: =M36/L36 -> 121.42105 | O36: =L36-I36 -> 0 | P36: =N36-K36 -> -4.8947368 | Q36: =N36/K36 -> 0.96125 | S36: 0.22777778 | T36: 0.25555556 | U36: =(S36-T35)*24*60 -> 29 | V36: =(T36-S36)*24*60 -> 40 | AE36: =M36-J36 -> -93 | AF36: =M36/J36 -> 0.96125
A37: 新豐9線 | B37: 三明治 | C37: 醬燒烤雞三明治 | E37: 26.39 | F37: 4277 | G37: =E37*F37 -> 112870.03 | I37: 19 | J37: 2400 | K37: =J37/I37 -> 126.31579 | L37: 19 | M37: =F37/V37*60 -> 2291.25 | N37: =M37/L37 -> 120.59211 | O37: =L37-I37 -> 0 | P37: =N37-K37 -> -5.7236842 | Q37: =N37/K37 -> 0.9546875 | S37: 0.26041667 | T37: 0.33819444 | U37: =(S37-T36)*24*60 -> 7 | V37: =(T37-S37)*24*60 -> 112 | AE37: =M37-J37 -> -108.75 | AF37: =M37/J37 -> 0.9546875
A38: 新豐9線 | B38: 三明治 | C38: 覆盆莓榛果可可三明治 | E38: 22.69 | F38: 958 | G38: =E38*F38 -> 21737.02 | I38: 15 | J38: 2400 | K38: =J38/I38 -> 160 | L38: 15 | M38: =F38/V38*60 -> 2299.2 | N38: =M38/L38 -> 153.28 | O38: =L38-I38 -> 0 | P38: =N38-K38 -> -6.72 | Q38: =N38/K38 -> 0.958 | S38: 0.34236111 | T38: 0.35972222 | U38: =(S38-T37)*24*60 -> 6 | V38: =(T38-S38)*24*60 -> 25 | AE38: =M38-J38 -> -100.8 | AF38: =M38/J38 -> 0.958
A39: 新豐9線 | B39: 三明治 | C39: 瘋狂起司三明治(113年) | E39: 24.45 | F39: 1838 | G39: =E39*F39 -> 44939.1 | I39: 20 | J39: 2400 | K39: =J39/I39 -> 120 | L39: 20 | M39: =F39/V39*60 -> 2297.5 | N39: =M39/L39 -> 114.875 | O39: =L39-I39 -> 0 | P39: =N39-K39 -> -5.125 | Q39: =N39/K39 -> 0.95729167 | S39: 0.36458333 | T39: 0.39791667 | U39: =(S39-T38)*24*60 -> 7 | V39: =(T39-S39)*24*60 -> 48 | AE39: =M39-J39 -> -102.5 | AF39: =M39/J39 -> 0.95729167
A40: 新豐9線 | B40: 三明治 | C40: 草莓優格三明治 | E40: 22.69 | F40: 6360 | G40: =E40*F40 -> 144308.4 | I40: 16 | J40: 2400 | K40: =J40/I40 -> 150 | L40: 16 | M40: =F40/V40*60 -> 2285.0299 | N40: =M40/L40 -> 142.81437 | O40: =L40-I40 -> 0 | P40: =N40-K40 -> -7.1856287 | Q40: =N40/K40 -> 0.95209581 | S40: 0.40208333 | T40: 0.51805556 | U40: =(S40-T39)*24*60 -> 6 | V40: =(T40-S40)*24*60 -> 167 | AE40: =M40-J40 -> -114.97006 | AF40: =M40/J40 -> 0.95209581
...

Sheet 0129
B1: 屏榮 新豐廠組合室生產人時性分析
B3: 日期 | C3: =TEXT('0129 4度C'!A2,"yyyy.mm.ddaaaa") -> 2026.01.29星期四 | E3: 訂單量 | F3: ='0129 4度C'!D1 -> 142095 | H3: 營業額 | I3: ='0129 4度C'!F1 -> 4855613.6
B4: 人時性 | C4: 項目 | E4: ➀ | G4: ➁ | I4: ➂ | K4: 異常停線 | M4: 短暫停線
C5: 組合室 | E5: 全溫層 | G5: 4度C-各編組展開 | I5: ③三明治-各編組展開 | K5: 合計次數 | L5: 時間 | M5: 合計次數 | N5: 設備次數
C6: 排關平均 | E6: =AVERAGE(D13:M13) -> 143.64367 | F6: =AVERAGE(D31:O31,D13:J13) -> 145.91425 | G6: =AVERAGE(D13:J13) -> 145.91425 | I6: =AVERAGE(K13:M13) -> 138.34564 | K6: ='0129 4度C'!Y2 -> 0 | L6: ='0129 4度C'!Z2 -> 0 | M6: ='0129 4度C'!AC2 -> 33 | N6: ='0129 4度C'!AD2 -> 0
C7: 實績平均 | E7: =AVERAGE(D14:M14) -> 137.60153 | F7: =AVERAGE(D32:O32,D14:J14) -> 139.79505 | G7: =AVERAGE(D14:J14) -> 139.79505 | I7: =AVERAGE(K14:M14) -> 132.48331
C8: 達成率平均 | E8: =AVERAGE(D15:M15) -> 0.95661008 | F8: =AVERAGE(D15:J15,D33:O33) -> 0.95619422 | G8: =AVERAGE(D15:J15) -> 0.95619422 | I8: =AVERAGE(K15:M15) -> 0.9575804
K9: ※現行日本鮮食廠以達成率80%為基本(即為現行KPI)
B10: 溫層 | D10: ➁4度C-各編組展開 | K10: ③三明治-各編組展開
B11: 編組 | D11: 1 | E11: 2 | F11: 3 | G11: 4 | H11: 5 | I11: 6 | J11: 7 | K11: 1 | L11: 2 | M11: 3
D12: 新豐6線 | E12: 新豐2線 | F12: 新豐5線 | G12: 新豐7線 | H12: 新豐3線 | I12: 新豐1線 | J12: 新豐10線 | K12: 新豐8線 | L12: 新豐9線 | M12: 新豐4線
B13: 人時性 | C13: 排關 | D13: =SUMIFS('0129 4度C'!$K:$K,'0129 4度C'!$A:$A,"新豐6線",'0129 4度C'!$B:$B,"平均") -> 113.63636 | E13: =SUMIFS('0129 4度C'!$K:$K,'0129 4度C'!$A:$A,"新豐2線",'0129 4度C'!$B:$B,"平均") -> 83.333333 | F13: =SUMIFS('0129 4度C'!$K:$K,'0129 4度C'!$A:$A,"新豐5線",'0129 4度C'!$B:$B,"平均") -> 109.2437 | G13: =SUMIFS('0129 4度C'!$K:$K,'0129 4度C'!$A:$A,"新豐7線",'0129 4度C'!$B:$B,"平均") -> 122.34043 | H13: =SUMIFS('0129 4度C'!$K:$K,'0129 4度C'!$A:$A,"新豐3線",'0129 4度C'!$B:$B,"平均") -> 300 | I13: =SUMIFS('0129 4度C'!$K:$K,'0129 4度C'!$A:$A,"新豐1線",'0129 4度C'!$B:$B,"平均") -> 104.16667 | J13: =SUMIFS('0129 4度C'!$K:$K,'0129 4度C'!$A:$A,"新豐10線",'0129 4度C'!$B:$B,"平均") -> 188.67925 | K13: =SUMIFS('0129 4度C'!$K:$K,'0129 4度C'!$A:$A,"新豐8線",'0129 4度C'!$B:$B,"平均") -> 132.11009 | L13: =SUMIFS('0129 4度C'!$K:$K,'0129 4度C'!$A:$A,"新豐9線",'0129 4度C'!$B:$B,"平均") -> 136.58537 | M13: =SUMIFS('0129 4度C'!$K:$K,'0129 4度C'!$A:$A,"新豐4線",'0129 4度C'!$B:$B,"平均") -> 146.34146
C14: 實績 | D14: =SUMIFS('0129 4度C'!$N:$N,'0129 4度C'!$A:$A,"新豐6線",'0129 4度C'!$B:$B,"平均") -> 109.6557 | E14: =SUMIFS('0129 4度C'!$N:$N,'0129 4度C'!$A:$A,"新豐2線",'0129 4度C'!$B:$B,"平均") -> 79.41769 | F14: =SUMIFS('0129 4度C'!$N:$N,'0129 4度C'!$A:$A,"新豐5線",'0129 4度C'!$B:$B,"平均") -> 105.28088 | G14: =SUMIFS('0129 4度C'!$N:$N,'0129 4度C'!$A:$A,"新豐7線",'0129 4度C'!$B:$B,"平均") -> 117.49972 | H14: =SUMIFS('0129 4度C'!$N:$N,'0129 4度C'!$A:$A,"新豐3線",'0129 4度C'!$B:$B,"平均") -> 288.3249 | I14: =SUMIFS('0129 4度C'!$N:$N,'0129 4度C'!$A:$A,"新豐1線",'0129 4度C'!$B:$B,"平均") -> 96.439129 | J14: =SUMIFS('0129 4度C'!$N:$N,'0129 4度C'!$A:$A,"新豐10線",'0129 4度C'!$B:$B,"平均") -> 181.94735 | K14: =SUMIFS('0129 4度C'!$N:$N,'0129 4度C'!$A:$A,"新豐8線",'0129 4度C'!$B:$B,"平均") -> 126.30936 | L14: =SUMIFS('0129 4度C'!$N:$N,'0129 4度C'!$A:$A,"新豐9線",'0129 4度C'!$B:$B,"平均") -> 130.826 | M14: =SUMIFS('0129 4度C'!$N:$N,'0129 4度C'!$A:$A,"新豐4線",'0129 4度C'!$B:$B,"平均") -> 140.31458
C15: 達成率 | D15: =D14/D13 -> 0.96497018 | E15: =E14/E13 -> 0.95301229 | F15: =F14/F13 -> 0.963725 | G15: =G14/G13 -> 0.96043252 | H15: =H14/H13 -> 0.96108301 | I15: =I14/I13 -> 0.92581564 | J15: =J14/J13 -> 0.96432093 | K15: =K14/K13 -> 0.95609171 | ... M15: =M14/M13 -> 0.95881628
B16: 作業 時間 | C16: 開始 | D16: =VLOOKUP("新豐6線",'0129 4度C'!$A:$T,19,0) -> 0.70833333 | E16: =VLOOKUP("新豐2線",'0129 4度C'!$A:$T,19,0) -> 0.20833333 | F16: =VLOOKUP("新豐5線",'0129 4度C'!$A:$T,19,0) -> 0.20833333 | G16: =VLOOKUP("新豐7線",'0129 4度C'!$A:$T,19,0) -> 0.20833333 | H16: =VLOOKUP("新豐3線",'0129 4度C'!$A:$T,19,0) -> 0.20833333 | I16: =VLOOKUP("新豐1線",'0129 4度C'!$A:$T,19,0) -> 0.20833333 | J16: =VLOOKUP("新豐10線",'0129 4度C'!$A:$T,19,0) -> 0.20833333 | K16: =VLOOKUP("新豐8線",'0129 4度C'!$A:$T,19,0) -> 0.125 | L16: =VLOOKUP("新豐9線",'0129 4度C'!$A:$T,19,0) -> 0.125 | M16: =VLOOKUP("新豐4線",'0129 4度C'!$A:$T,19,0) -> 0.125
C17: 結束 | D17: =LOOKUP(2,1/(('0129 4度C'!$A:$A="新豐6線")*('0129 4度C'!$T:$T<>"")),'0129 4度C'!$T:$T) -> 0.83333333 | E17: =LOOKUP(2,1/(('0129 4度C'!$A:$A="新豐2線")*('0129 4度C'!$T:$T<>"")),'0129 4度C'!$T:$T) -> 0.42430556 | F17: =LOOKUP(2,1/(('0129 4度C'!$A:$A="新豐5線")*('0129 4度C'!$T:$T<>"")),'0129 4度C'!$T:$T) -> 0.91597222 | G17: =LOOKUP(2,1/(('0129 4度C'!$A:$A="新豐7線")*('0129 4度C'!$T:$T<>"")),'0129 4度C'!$T:$T) -> 0.82708333 | H17: =LOOKUP(2,1/(('0129 4度C'!$A:$A="新豐3線")*('0129 4度C'!$T:$T<>"")),'0129 4度C'!$T:$T) -> 0.65138889 | I17: =LOOKUP(2,1/(('0129 4度C'!$A:$A="新豐1線")*('0129 4度C'!$T:$T<>"")),'0129 4度C'!$T:$T) -> 0.84375 | J17: =LOOKUP(2,1/(('0129 4度C'!$A:$A="新豐10線")*('0129 4度C'!$T:$T<>"")),'0129 4度C'!$T:$T) -> 0.44652778 | K17: =LOOKUP(2,1/(('0129 4度C'!$A:$A="新豐8線")*('0129 4度C'!$T:$T<>"")),'0129 4度C'!$T:$T) -> 0.57569444 | L17: =LOOKUP(2,1/(('0129 4度C'!$A:$A="新豐9線")*('0129 4度C'!$T:$T<>"")),'0129 4度C'!$T:$T) -> 0.60625 | M17: =LOOKUP(2,1/(('0129 4度C'!$A:$A="新豐4線")*('0129 4度C'!$T:$T<>"")),'0129 4度C'!$T:$T) -> 0.51319444
B18: 產線異常 (5分鐘以上) | C18: 次數 | D18: =SUMIFS('0129 4度C'!$Y:$Y,'0129 4度C'!$A:$A,"新豐6線",'0129 4度C'!$B:$B,"平均") -> 0 | E18: =SUMIFS('0129 4度C'!$Y:$Y,'0129 4度C'!$A:$A,"新豐2線",'0129 4度C'!$B:$B,"平均") -> 0 | F18: =SUMIFS('0129 4度C'!$Y:$Y,'0129 4度C'!$A:$A,"新豐5線",'0129 4度C'!$B:$B,"平均") -> 0 | G18: =SUMIFS('0129 4度C'!$Y:$Y,'0129 4度C'!$A:$A,"新豐7線",'0129 4度C'!$B:$B,"平均") -> 0 | H18: =SUMIFS('0129 4度C'!$Y:$Y,'0129 4度C'!$A:$A,"新豐3線",'0129 4度C'!$B:$B,"平均") -> 0 | I18: =SUMIFS('0129 4度C'!$Y:$Y,'0129 4度C'!$A:$A,"新豐1線",'0129 4度C'!$B:$B,"平均") -> 0 | J18: =SUMIFS('0129 4度C'!$Y:$Y,'0129 4度C'!$A:$A,"新豐10線",'0129 4度C'!$B:$B,"平均") -> 0 | K18: =SUMIFS('0129 4度C'!$Y:$Y,'0129 4度C'!$A:$A,"新豐8線",'0129 4度C'!$B:$B,"平均") -> 0 | L18: =SUMIFS('0129 4度C'!$Y:$Y,'0129 4度C'!$A:$A,"新豐9線",'0129 4度C'!$B:$B,"平均") -> 0 | M18: =SUMIFS('0129 4度C'!$Y:$Y,'0129 4度C'!$A:$A,"新豐4線",'0129 4度C'!$B:$B,"平均") -> 0
