Workbook

Sheet 0430
B1: 屏榮 新豐廠組合室生產人時性分析
B3: 日期 | C3: =TEXT('0430 4度C'!A2,"yyyy.mm.ddaaaa") -> 2026.04.30星期四 | E3: 訂單量 | F3: ='0430 4度C'!D1 -> 145179 | H3: 營業額 | I3: ='0430 4度C'!F1 -> 4913951.9
B4: 人時性 | C4: 項目 | E4: ➀ | G4: ➁ | I4: ➂ | K4: 異常停線 | M4: 短暫停線
C5: 組合室 | E5: 全溫層 | G5: 4度C-各編組展開 | I5: ③三明治-各編組展開 | K5: 合計次數 | L5: 時間 | M5: 合計次數 | N5: 設備次數
C6: 排關平均 | E6: =AVERAGE(D13:M13) -> 151.17421 | F6: =AVERAGE(D31:O31,D13:J13) -> 157.40334 | G6: =AVERAGE(D13:J13) -> 157.40334 | I6: =AVERAGE(K13:M13) -> 136.63956 | K6: ='0430 4度C'!Y2 -> 0 | L6: ='0430 4度C'!Z2 -> 0 | M6: ='0430 4度C'!AC2 -> 53 | N6: ='0430 4度C'!AD2 -> 0
C7: 實績平均 | E7: =AVERAGE(D14:M14) -> 145.22076 | F7: =AVERAGE(D32:O32,D14:J14) -> 151.45037 | G7: =AVERAGE(D14:J14) -> 151.45037 | I7: =AVERAGE(K14:M14) -> 130.685
C8: 達成率平均 | E8: =AVERAGE(D15:M15) -> 0.96100495 | F8: =AVERAGE(D15:J15,D33:O33) -> 0.96300115 | G8: =AVERAGE(D15:J15) -> 0.96300115 | I8: =AVERAGE(K15:M15) -> 0.95634714
K9: ※現行日本鮮食廠以達成率80%為基本(即為現行KPI)
B10: 溫層 | D10: ➁4度C-各編組展開 | K10: ③三明治-各編組展開
B11: 編組 | D11: 1 | E11: 2 | F11: 3 | G11: 4 | H11: 5 | I11: 6 | J11: 7 | K11: 1 | L11: 2 | M11: 3
D12: 新豐6線 | E12: 新豐2線 | F12: 新豐5線 | G12: 新豐7線 | H12: 新豐3線 | I12: 新豐1線 | J12: 新豐10線 | K12: 新豐8線 | L12: 新豐9線 | M12: 新豐4線
B13: 人時性 | C13: 排關 | D13: =SUMIFS('0430 4度C'!$K:$K,'0430 4度C'!$A:$A,"新豐6線",'0430 4度C'!$B:$B,"平均") -> 119.40299 | E13: =SUMIFS('0430 4度C'!$K:$K,'0430 4度C'!$A:$A,"新豐2線",'0430 4度C'!$B:$B,"平均") -> 83.333333 | F13: =SUMIFS('0430 4度C'!$K:$K,'0430 4度C'!$A:$A,"新豐5線",'0430 4度C'!$B:$B,"平均") -> 100 | G13: =SUMIFS('0430 4度C'!$K:$K,'0430 4度C'!$A:$A,"新豐7線",'0430 4度C'!$B:$B,"平均") -> 123.45679 | H13: =SUMIFS('0430 4度C'!$K:$K,'0430 4度C'!$A:$A,"新豐3線",'0430 4度C'!$B:$B,"平均") -> 255.81395 | I13: =SUMIFS('0430 4度C'!$K:$K,'0430 4度C'!$A:$A,"新豐1線",'0430 4度C'!$B:$B,"平均") -> 104.02685 | J13: =SUMIFS('0430 4度C'!$K:$K,'0430 4度C'!$A:$A,"新豐10線",'0430 4度C'!$B:$B,"平均") -> 315.78947 | K13: =SUMIFS('0430 4度C'!$K:$K,'0430 4度C'!$A:$A,"新豐8線",'0430 4度C'!$B:$B,"平均") -> 134.57944 | L13: =SUMIFS('0430 4度C'!$K:$K,'0430 4度C'!$A:$A,"新豐9線",'0430 4度C'!$B:$B,"平均") -> 126.66667 | M13: =SUMIFS('0430 4度C'!$K:$K,'0430 4度C'!$A:$A,"新豐4線",'0430 4度C'!$B:$B,"平均") -> 148.67257
C14: 實績 | D14: =SUMIFS('0430 4度C'!$N:$N,'0430 4度C'!$A:$A,"新豐6線",'0430 4度C'!$B:$B,"平均") -> 116.40681 | E14: =SUMIFS('0430 4度C'!$N:$N,'0430 4度C'!$A:$A,"新豐2線",'0430 4度C'!$B:$B,"平均") -> 79.397381 | F14: =SUMIFS('0430 4度C'!$N:$N,'0430 4度C'!$A:$A,"新豐5線",'0430 4度C'!$B:$B,"平均") -> 96.735627 | G14: =SUMIFS('0430 4度C'!$N:$N,'0430 4度C'!$A:$A,"新豐7線",'0430 4度C'!$B:$B,"平均") -> 118.3966 | H14: =SUMIFS('0430 4度C'!$N:$N,'0430 4度C'!$A:$A,"新豐3線",'0430 4度C'!$B:$B,"平均") -> 244.69778 | I14: =SUMIFS('0430 4度C'!$N:$N,'0430 4度C'!$A:$A,"新豐1線",'0430 4度C'!$B:$B,"平均") -> 100.74761 | J14: =SUMIFS('0430 4度C'!$N:$N,'0430 4度C'!$A:$A,"新豐10線",'0430 4度C'!$B:$B,"平均") -> 303.77079 | K14: =SUMIFS('0430 4度C'!$N:$N,'0430 4度C'!$A:$A,"新豐8線",'0430 4度C'!$B:$B,"平均") -> 128.63837 | L14: =SUMIFS('0430 4度C'!$N:$N,'0430 4度C'!$A:$A,"新豐9線",'0430 4度C'!$B:$B,"平均") -> 121.00196 | M14: =SUMIFS('0430 4度C'!$N:$N,'0430 4度C'!$A:$A,"新豐4線",'0430 4度C'!$B:$B,"平均") -> 142.41468
C15: 達成率 | D15: =D14/D13 -> 0.97490706 | E15: =E14/E13 -> 0.95276857 | F15: =F14/F13 -> 0.96735627 | G15: =G14/G13 -> 0.95901248 | H15: =H14/H13 -> 0.95654587 | I15: =I14/I13 -> 0.968477 | J15: =J14/J13 -> 0.96194083 | K15: =K14/K13 -> 0.95585452 | ... M15: =M14/M13 -> 0.95790829
B16: 作業 時間 | C16: 開始 | D16: =VLOOKUP("新豐6線",'0430 4度C'!$A:$T,19,0) -> 0.70833333 | E16: =VLOOKUP("新豐2線",'0430 4度C'!$A:$T,19,0) -> 0.20833333 | F16: =VLOOKUP("新豐5線",'0430 4度C'!$A:$T,19,0) -> 0.20833333 | G16: =VLOOKUP("新豐7線",'0430 4度C'!$A:$T,19,0) -> 0.20833333 | H16: =VLOOKUP("新豐3線",'0430 4度C'!$A:$T,19,0) -> 0.083333333 | I16: =VLOOKUP("新豐1線",'0430 4度C'!$A:$T,19,0) -> 0.20833333 | J16: =VLOOKUP("新豐10線",'0430 4度C'!$A:$T,19,0) -> 0.20833333 | K16: =VLOOKUP("新豐8線",'0430 4度C'!$A:$T,19,0) -> 0.083333333 | L16: =VLOOKUP("新豐9線",'0430 4度C'!$A:$T,19,0) -> 0.083333333 | M16: =VLOOKUP("新豐4線",'0430 4度C'!$A:$T,19,0) -> 0.083333333
C17: 結束 | D17: =LOOKUP(2,1/(('0430 4度C'!$A:$A="新豐6線")*('0430 4度C'!$T:$T<>"")),'0430 4度C'!$T:$T) -> 0.80625 | E17: =LOOKUP(2,1/(('0430 4度C'!$A:$A="新豐2線")*('0430 4度C'!$T:$T<>"")),'0430 4度C'!$T:$T) -> 0.47152778 | F17: =LOOKUP(2,1/(('0430 4度C'!$A:$A="新豐5線")*('0430 4度C'!$T:$T<>"")),'0430 4度C'!$T:$T) -> 0.79930556 | G17: =LOOKUP(2,1/(('0430 4度C'!$A:$A="新豐7線")*('0430 4度C'!$T:$T<>"")),'0430 4度C'!$T:$T) -> 0.77916667 | H17: =LOOKUP(2,1/(('0430 4度C'!$A:$A="新豐3線")*('0430 4度C'!$T:$T<>"")),'0430 4度C'!$T:$T) -> 0.4125 | I17: =LOOKUP(2,1/(('0430 4度C'!$A:$A="新豐1線")*('0430 4度C'!$T:$T<>"")),'0430 4度C'!$T:$T) -> 0.78402778 | J17: =LOOKUP(2,1/(('0430 4度C'!$A:$A="新豐10線")*('0430 4度C'!$T:$T<>"")),'0430 4度C'!$T:$T) -> 0.37361111 | K17: =LOOKUP(2,1/(('0430 4度C'!$A:$A="新豐8線")*('0430 4度C'!$T:$T<>"")),'0430 4度C'!$T:$T) -> 0.62569444 | L17: =LOOKUP(2,1/(('0430 4度C'!$A:$A="新豐9線")*('0430 4度C'!$T:$T<>"")),'0430 4度C'!$T:$T) -> 0.65347222 | M17: =LOOKUP(2,1/(('0430 4度C'!$A:$A="新豐4線")*('0430 4度C'!$T:$T<>"")),'0430 4度C'!$T:$T) -> 0.62361111
B18: 產線異常 (5分鐘以上) | C18: 次數 | D18: =SUMIFS('0430 4度C'!$Y:$Y,'0430 4度C'!$A:$A,"新豐6線",'0430 4度C'!$B:$B,"平均") -> 0 | E18: =SUMIFS('0430 4度C'!$Y:$Y,'0430 4度C'!$A:$A,"新豐2線",'0430 4度C'!$B:$B,"平均") -> 0 | F18: =SUMIFS('0430 4度C'!$Y:$Y,'0430 4度C'!$A:$A,"新豐5線",'0430 4度C'!$B:$B,"平均") -> 0 | G18: =SUMIFS('0430 4度C'!$Y:$Y,'0430 4度C'!$A:$A,"新豐7線",'0430 4度C'!$B:$B,"平均") -> 0 | H18: =SUMIFS('0430 4度C'!$Y:$Y,'0430 4度C'!$A:$A,"新豐3線",'0430 4度C'!$B:$B,"平均") -> 0 | I18: =SUMIFS('0430 4度C'!$Y:$Y,'0430 4度C'!$A:$A,"新豐1線",'0430 4度C'!$B:$B,"平均") -> 0 | J18: =SUMIFS('0430 4度C'!$Y:$Y,'0430 4度C'!$A:$A,"新豐10線",'0430 4度C'!$B:$B,"平均") -> 0 | K18: =SUMIFS('0430 4度C'!$Y:$Y,'0430 4度C'!$A:$A,"新豐8線",'0430 4度C'!$B:$B,"平均") -> 0 | L18: =SUMIFS('0430 4度C'!$Y:$Y,'0430 4度C'!$A:$A,"新豐9線",'0430 4度C'!$B:$B,"平均") -> 0 | M18: =SUMIFS('0430 4度C'!$Y:$Y,'0430 4度C'!$A:$A,"新豐4線",'0430 4度C'!$B:$B,"平均") -> 0
C19: 時間/分 | D19: =SUMIFS('0430 4度C'!$Z:$Z,'0430 4度C'!$A:$A,"新豐6線",'0430 4度C'!$B:$B,"平均") -> 0 | E19: =SUMIFS('0430 4度C'!$Z:$Z,'0430 4度C'!$A:$A,"新豐2線",'0430 4度C'!$B:$B,"平均") -> 0 | F19: =SUMIFS('0430 4度C'!$Z:$Z,'0430 4度C'!$A:$A,"新豐5線",'0430 4度C'!$B:$B,"平均") -> 0 | G19: =SUMIFS('0430 4度C'!$Z:$Z,'0430 4度C'!$A:$A,"新豐7線",'0430 4度C'!$B:$B,"平均") -> 0 | H19: =SUMIFS('0430 4度C'!$Z:$Z,'0430 4度C'!$A:$A,"新豐3線",'0430 4度C'!$B:$B,"平均") -> 0 | I19: =SUMIFS('0430 4度C'!$Z:$Z,'0430 4度C'!$A:$A,"新豐1線",'0430 4度C'!$B:$B,"平均") -> 0 | J19: =SUMIFS('0430 4度C'!$Z:$Z,'0430 4度C'!$A:$A,"新豐10線",'0430 4度C'!$B:$B,"平均") -> 0 | K19: =SUMIFS('0430 4度C'!$Z:$Z,'0430 4度C'!$A:$A,"新豐8線",'0430 4度C'!$B:$B,"平均") -> 0 | L19: =SUMIFS('0430 4度C'!$Z:$Z,'0430 4度C'!$A:$A,"新豐9線",'0430 4度C'!$B:$B,"平均") -> 0 | M19: =SUMIFS('0430 4度C'!$Z:$Z,'0430 4度C'!$A:$A,"新豐4線",'0430 4度C'!$B:$B,"平均") -> 0
B20: 短暫停線 (5分鐘以下) | C20: 次數 | D20: =SUMIFS('0430 4度C'!$AC:$AC,'0430 4度C'!$A:$A,"新豐6線",'0430 4度C'!$B:$B,"平均") -> 4 | E20: =SUMIFS('0430 4度C'!$AC:$AC,'0430 4度C'!$A:$A,"新豐2線",'0430 4度C'!$B:$B,"平均") -> 2 | F20: =SUMIFS('0430 4度C'!$AC:$AC,'0430 4度C'!$A:$A,"新豐5線",'0430 4度C'!$B:$B,"平均") -> 4 | G20: =SUMIFS('0430 4度C'!$AC:$AC,'0430 4度C'!$A:$A,"新豐7線",'0430 4度C'!$B:$B,"平均") -> 5 | H20: =SUMIFS('0430 4度C'!$AC:$AC,'0430 4度C'!$A:$A,"新豐3線",'0430 4度C'!$B:$B,"平均") -> 4 | I20: =SUMIFS('0430 4度C'!$AC:$AC,'0430 4度C'!$A:$A,"新豐1線",'0430 4度C'!$B:$B,"平均") -> 8 | J20: =SUMIFS('0430 4度C'!$AC:$AC,'0430 4度C'!$A:$A,"新豐10線",'0430 4度C'!$B:$B,"平均") -> 6 | K20: =SUMIFS('0430 4度C'!$AC:$AC,'0430 4度C'!$A:$A,"新豐8線",'0430 4度C'!$B:$B,"平均") -> 6 | L20: =SUMIFS('0430 4度C'!$AC:$AC,'0430 4度C'!$A:$A,"新豐9線",'0430 4度C'!$B:$B,"平均") -> 7 | M20: =SUMIFS('0430 4度C'!$AC:$AC,'0430 4度C'!$A:$A,"新豐4線",'0430 4度C'!$B:$B,"平均") -> 7
C21: 設備次數 | D21: =SUMIFS('0430 4度C'!$AD:$AD,'0430 4度C'!$A:$A,"新豐6線",'0430 4度C'!$B:$B,"平均") -> 0 | E21: =SUMIFS('0430 4度C'!$AD:$AD,'0430 4度C'!$A:$A,"新豐2線",'0430 4度C'!$B:$B,"平均") -> 0 | F21: =SUMIFS('0430 4度C'!$AD:$AD,'0430 4度C'!$A:$A,"新豐5線",'0430 4度C'!$B:$B,"平均") -> 0 | G21: =SUMIFS('0430 4度C'!$AD:$AD,'0430 4度C'!$A:$A,"新豐7線",'0430 4度C'!$B:$B,"平均") -> 0 | H21: =SUMIFS('0430 4度C'!$AD:$AD,'0430 4度C'!$A:$A,"新豐3線",'0430 4度C'!$B:$B,"平均") -> 0 | I21: =SUMIFS('0430 4度C'!$AD:$AD,'0430 4度C'!$A:$A,"新豐1線",'0430 4度C'!$B:$B,"平均") -> 0 | J21: =SUMIFS('0430 4度C'!$AD:$AD,'0430 4度C'!$A:$A,"新豐10線",'0430 4度C'!$B:$B,"平均") -> 0 | K21: =SUMIFS('0430 4度C'!$AD:$AD,'0430 4度C'!$A:$A,"新豐8線",'0430 4度C'!$B:$B,"平均") -> 0 | L21: =SUMIFS('0430 4度C'!$AD:$AD,'0430 4度C'!$A:$A,"新豐9線",'0430 4度C'!$B:$B,"平均") -> 0 | M21: =SUMIFS('0430 4度C'!$AD:$AD,'0430 4度C'!$A:$A,"新豐4線",'0430 4度C'!$B:$B,"平均") -> 0
B22: 配置人數 | D22: =SUMIFS('0430 4度C'!$I:$I,'0430 4度C'!$A:$A,"新豐6線",'0430 4度C'!$B:$B,"平均") -> 16.75 | E22: =SUMIFS('0430 4度C'!$I:$I,'0430 4度C'!$A:$A,"新豐2線",'0430 4度C'!$B:$B,"平均") -> 18 | F22: =SUMIFS('0430 4度C'!$I:$I,'0430 4度C'!$A:$A,"新豐5線",'0430 4度C'!$B:$B,"平均") -> 17.5 | G22: =SUMIFS('0430 4度C'!$I:$I,'0430 4度C'!$A:$A,"新豐7線",'0430 4度C'!$B:$B,"平均") -> 16.2 | H22: =SUMIFS('0430 4度C'!$I:$I,'0430 4度C'!$A:$A,"新豐3線",'0430 4度C'!$B:$B,"平均") -> 10.75 | I22: =SUMIFS('0430 4度C'!$I:$I,'0430 4度C'!$A:$A,"新豐1線",'0430 4度C'!$B:$B,"平均") -> 18.625 | J22: =SUMIFS('0430 4度C'!$I:$I,'0430 4度C'!$A:$A,"新豐10線",'0430 4度C'!$B:$B,"平均") -> 9.5 | K22: =SUMIFS('0430 4度C'!$I:$I,'0430 4度C'!$A:$A,"新豐8線",'0430 4度C'!$B:$B,"平均") -> 17.833333 | L22: =SUMIFS('0430 4度C'!$I:$I,'0430 4度C'!$A:$A,"新豐9線",'0430 4度C'!$B:$B,"平均") -> 17.142857 | M22: =SUMIFS('0430 4度C'!$I:$I,'0430 4度C'!$A:$A,"新豐4線",'0430 4度C'!$B:$B,"平均") -> 16.142857
B23: 主要應用設備 | D23: ET-55 | E23: 熱縮爐 | F23: L型包裝機 | G23: L型包裝機 | H23: 伺服包裝機 | I23: ET-55 | J23: 伺服包裝機 | K23: 三明治包裝機 | L23: 三明治包裝機 | M23: 三明治包裝機
B24: 次要應用設備 | F24: 圓盤機 | G24: ET-55
B25: 備註 | E25: 握沙拉 | F25: 共用L型包裝機 | H25: 調理麵包 | I25: 炒飯+沙拉 | J25: 調理麵包

Sheet 0430 4度C
A1: 新豐廠四度C日報分析 | C1: 總生產量 | D1: =SUM(F5:F67) -> 145179 | E1: 營業額 | F1: =SUM(G5:G67) -> 4913951.9 | G1: 出勤人數 | H1: =L9+L12+L43+L52+L17+L59+L30+L38+L23+L67 -> 158.44405 | I1: 產線配置圖 | L1: 生產實績 | O1: 人時性差異分析 | S1: 日報登錄 | Y1: 合計 次數 | Z1: 合計 時間/分 | AA1: 產線異常 分析說明(5分鐘以上) | AC1: 合計 次數 | AD1: 合計 設備次數 | AE1: 產能差異分析
A2: 46142 | B2: 星期四 | C2: 人時性 | D2: =AVERAGE(N9,N12,N43,N52,N17,N59,N23,N30,N38,N67) -> 145.22076 | E2: 平均廠價 | F2: =F1/D1 -> 33.847539 | G2: 多次生產數 | H2: =COUNT(H5:H67) -> 5 | Y2: =SUM(Y9+Y12+Y17+Y23+Y30+Y38+Y43+Y52+Y59+Y67) -> 0 | Z2: =SUM(Z9+Z12+Z17+Z23+Z30+Z38+Z43+Z52+Z59+Z67) -> 0 | AC2: =SUM(AC9+AC12+AC17+AC23+AC30+AC38+AC43+AC52+AC59+AC67) -> 53 | AD2: =SUM(AD9+AD12+AD17+AD23+AD30+AD38+AD43+AD52+AD59+AD67) -> 0
A3: 線別 | B3: 品類 | C3: 品名 | E3: 廠價 | F3: 生產量 | G3: 營收 | H3: 多次 生產 | I3: 人數 | J3: 產能/時 | K3: 人時性 | L3: 人數 | M3: 產能/時 | N3: 人時性 | O3: 人數 | P3: 人時性 | Q3: 達成率 | R3: 達成率平均 | S3: 生產時間 | U3: 換線、休息/分 | V3: 稼動時間/分 | W3: 休息時間 | Y3: 產線異常統計 (5分鐘以上) | AA3: (新豐回填) | AC3: 短暫停線統計 (5分鐘以下) | AE3: 產能/時 | AF3: 達成率 | AG3: 達成率平均
S4: 開始 | T4: 結束 | W4: 開始 | X4: 結束 | Y4: 次數 | Z4: 時間/分 | AC4: 總次數 | AD4: 設備因素(次數)
A5: 新豐6線 | B5: 微波主食 | C5: 二配港式香滑嫩蛋牛肉燴飯 | E5: 50.67 | F5: 1001 | G5: =E5*F5 -> 50720.67 | I5: 17 | J5: 2000 | K5: =J5/I5 -> 117.64706 | L5: 17 | M5: =F5/V5*60 -> 1937.4194 | N5: =M5/L5 -> 113.96584 | O5: =L5-I5 -> 0 | P5: =N5-K5 -> -3.6812144 | Q5: =N5/K5 -> 0.96870968 | R5: =Q9 -> 0.97490706 | S5: 0.70833333 | T5: 0.72986111 | V5: =(T5-S5)*24*60 -> 31 | AC5: 4 | AE5: =M5-J5 -> -62.580645 | AF5: =M5/J5 -> 0.96870968 | AG5: =AF9 -> 0.97490706
A6: 新豐6線 | B6: 微波主食 | C6: 二配美味蟹煲 | E6: 54.09 | F6: 846 | G6: =E6*F6 -> 45760.14 | I6: 19 | J6: 2000 | K6: =J6/I6 -> 105.26316 | L6: 19 | M6: =F6/V6*60 -> 1952.3077 | N6: =M6/L6 -> 102.75304 | O6: =L6-I6 -> 0 | P6: =N6-K6 -> -2.5101215 | Q6: =N6/K6 -> 0.97615385 | S6: 0.73402778 | T6: 0.75208333 | U6: =IF(S6=TIME(17,0,0),"",(S6-T5)*24*60) -> 6 | V6: =(T6-S6)*24*60 -> 26 | AE6: =M6-J6 -> -47.692308 | AF6: =M6/J6 -> 0.97615385
A7: 新豐6線 | B7: 微波主食 | C7: 二配泰式綠咖哩雞 | E7: 50.67 | F7: 978 | G7: =E7*F7 -> 49555.26 | I7: 15 | J7: 2000 | K7: =J7/I7 -> 133.33333 | L7: 15 | M7: =F7/V7*60 -> 1956 | N7: =M7/L7 -> 130.4 | O7: =L7-I7 -> 0 | P7: =N7-K7 -> -2.9333333 | Q7: =N7/K7 -> 0.978 | S7: 0.75694444 | T7: 0.77777778 | U7: =IF(S7=TIME(17,0,0),"",(S7-T6)*24*60) -> 7 | V7: =(T7-S7)*24*60 -> 30 | AE7: =M7-J7 -> -44 | AF7: =M7/J7 -> 0.978
A8: 新豐6線 | B8: 微波主食 | C8: 二配蔥爆牛肉燴飯 | E8: 52.86 | F8: 1107 | G8: =E8*F8 -> 58516.02 | I8: 16 | J8: 2000 | K8: =J8/I8 -> 125 | L8: 16 | M8: =F8/V8*60 -> 1953.5294 | N8: =M8/L8 -> 122.09559 | O8: =L8-I8 -> 0 | P8: =N8-K8 -> -2.9044118 | Q8: =N8/K8 -> 0.97676471 | S8: 0.78263889 | T8: 0.80625 | U8: =IF(S8=TIME(17,0,0),"",(S8-T7)*24*60) -> 7 | V8: =(T8-S8)*24*60 -> 34 | AE8: =M8-J8 -> -46.470588 | AF8: =M8/J8 -> 0.97676471
A9: 新豐6線 | B9: 平均 | I9: 16.75 | J9: 2000 | K9: =J9/I9 -> 119.40299 | L9: 16.75 | M9: =AVERAGE(M5:M8) -> 1949.8141 | N9: =M9/L9 -> 116.40681 | O9: =L9-I9 -> 0 | P9: =N9-K9 -> -2.9961723 | Q9: =N9/K9 -> 0.97490706 | Y9: =SUM(Y5:Y8) -> 0 | Z9: =SUM(Z5:Z8) -> 0 | AC9: =SUM(AC5:AC8) -> 4 | AD9: =SUM(AD5:AD8) -> 0 | AE9: =M9-J9 -> -50.185885 | AF9: =M9/J9 -> 0.97490706
A10: 新豐2線 | B10: 沙拉 | C10: 青醬優格雞肉握沙拉(113年) | E10: 39.62 | F10: 3594 | G10: =E10*F10 -> 142394.28 | I10: 19 | J10: 1500 | K10: =J10/I10 -> 78.947368 | L10: 19 | M10: =F10/V10*60 -> 1428.0795 | N10: =M10/L10 -> 75.162077 | O10: =L10-I10 -> 0 | P10: =N10-K10 -> -3.785291 | Q10: =N10/K10 -> 0.95205298 | R10: =Q12 -> 0.95276857 | S10: 0.20833333 | T10: 0.31319444 | V10: =(T10-S10)*24*60 -> 151 | AC10: 2 | AE10: =M10-J10 -> -71.92053 | AF10: =M10/J10 -> 0.95205298 | AG10: =AF12 -> 0.95276857
A11: 新豐2線 | B11: 沙拉 | C11: 青檸烤雞握沙拉(113年) | E11: 39.8 | F11: 5268 | G11: =E11*F11 -> 209666.4 | I11: 17 | J11: 1500 | K11: =J11/I11 -> 88.235294 | L11: 17 | M11: =F11/V11*60 -> 1430.2262 | N11: =M11/L11 -> 84.130956 | O11: =L11-I11 -> 0 | P11: =N11-K11 -> -4.1043386 | Q11: =N11/K11 -> 0.95348416 | S11: 0.31805556 | T11: 0.47152778 | U11: =IF(S11=TIME(17,0,0),"",(S11-T10)*24*60) -> 7 | V11: =(T11-S11)*24*60 -> 221 | AE11: =M11-J11 -> -69.773756 | AF11: =M11/J11 -> 0.95348416
A12: 新豐2線 | B12: 平均 | I12: 18 | J12: 1500 | K12: =J12/I12 -> 83.333333 | L12: 18 | M12: =AVERAGE(M10:M11) -> 1429.1529 | N12: =M12/L12 -> 79.397381 | O12: =L12-I12 -> 0 | P12: =N12-K12 -> -3.9359524 | Q12: =N12/K12 -> 0.95276857 | Y12: =SUM(Y10:Y11) -> 0 | Z12: =SUM(Z10:Z11) -> 0 | AC12: =SUM(AC10:AC11) -> 2 | AD12: =SUM(AD10:AD11) -> 0 | AE12: =M12-J12 -> -70.847143 | AF12: =M12/J12 -> 0.95276857
A13: 新豐5線 | B13: 小吃 | C13: 剝皮辣椒雞湯 | E13: 41 | F13: 1605 | G13: =E13*F13 -> 65805 | I13: 26 | J13: 1500 | K13: =J13/I13 -> 57.692308 | L13: 26 | M13: =F13/V13*60 -> 1437.3134 | N13: =M13/L13 -> 55.281286 | O13: =L13-I13 -> 0 | P13: =N13-K13 -> -2.4110218 | Q13: =N13/K13 -> 0.95820896 | R13: =Q17 -> 0.96735627 | S13: 0.20833333 | T13: 0.25486111 | V13: =(T13-S13)*24*60 -> 67 | AC13: 4 | AE13: =M13-J13 -> -62.686567 | AF13: =M13/J13 -> 0.95820896 | AG13: =AF17 -> 0.96735627
A14: 新豐5線 | B14: 微波主食 | C14: 二配起司控培根白醬焗烤飯 | E14: 53.68 | F14: 905 | G14: =E14*F14 -> 48580.4 | I14: 16 | J14: 1500 | K14: =J14/I14 -> 93.75 | L14: 16 | M14: =F14/V14*60 -> 1467.5676 | N14: =M14/L14 -> 91.722973 | O14: =L14-I14 -> 0 | P14: =N14-K14 -> -2.027027 | Q14: =N14/K14 -> 0.97837838 | S14: 0.70833333 | T14: 0.73402778 | U14: =IF(S14=TIME(17,0,0),"",(S14-T13)*24*60) | V14: =(T14-S14)*24*60 -> 37 | AE14: =M14-J14 -> -32.432432 | AF14: =M14/J14 -> 0.97837838
A15: 新豐5線 | B15: 微波主食 | C15: 二配金咖哩果香甘口咖哩飯 | E15: 50.92 | F15: 1548 | G15: =E15*F15 -> 78824.16 | I15: 15 | J15: 2000 | K15: =J15/I15 -> 133.33333 | L15: 15 | M15: =F15/V15*60 -> 1935 | N15: =M15/L15 -> 129 | O15: =L15-I15 -> 0 | P15: =N15-K15 -> -4.3333333 | Q15: =N15/K15 -> 0.9675 | S15: 0.73958333 | T15: 0.77291667 | U15: =IF(S15=TIME(17,0,0),"",(S15-T14)*24*60) -> 8 | V15: =(T15-S15)*24*60 -> 48 | AE15: =M15-J15 -> -65 | AF15: =M15/J15 -> 0.9675
A16: 新豐5線 | B16: 微波主食 | C16: 二配厚香料咖哩雞排飯 | E16: 57.3 | F16: 998 | G16: =E16*F16 -> 57185.4 | I16: 13 | J16: 2000 | K16: =J16/I16 -> 153.84615 | L16: 13 | M16: =F16/V16*60 -> 1931.6129 | N16: =M16/L16 -> 148.58561 | O16: =L16-I16 -> 0 | P16: =N16-K16 -> -5.2605459 | Q16: =N16/K16 -> 0.96580645 | S16: 0.77777778 | T16: 0.79930556 | U16: =IF(S16=TIME(17,0,0),"",(S16-T15)*24*60) -> 7 | V16: =(T16-S16)*24*60 -> 31 | AE16: =M16-J16 -> -68.387097 | AF16: =M16/J16 -> 0.96580645
A17: 新豐5線 | B17: 平均 | I17: 17.5 | J17: 1750 | K17: =J17/I17 -> 100 | L17: 17.5 | M17: =AVERAGE(M13:M16) -> 1692.8735 | N17: =M17/L17 -> 96.735627 | O17: =L17-I17 -> 0 | P17: =N17-K17 -> -3.2643728 | Q17: =N17/K17 -> 0.96735627 | Y17: =SUM(Y13:Y16) -> 0 | Z17: =SUM(Z13:Z16) -> 0 | AC17: =SUM(AC13:AC16) -> 4 | AD17: =SUM(AD13:AD16) -> 0 | AE17: =M17-J17 -> -57.126524 | AF17: =M17/J17 -> 0.96735627
A18: 新豐7線 | B18: 微波主食 | C18: 爆炒雞丁飯 | E18: 59.04 | F18: 7516 | G18: =E18*F18 -> 443744.64 | I18: 19 | J18: 2000 | K18: =J18/I18 -> 105.26316 | L18: 19 | M18: =F18/V18*60 -> 1902.7848 | N18: =M18/L18 -> 100.14657 | O18: =L18-I18 -> 0 | P18: =N18-K18 -> -5.1165889 | Q18: =N18/K18 -> 0.95139241 | R18: =Q23 -> 0.95901248 | S18: 0.20833333 | T18: 0.37291667 | V18: =(T18-S18)*24*60 -> 237 | AC18: 5 | AE18: =M18-J18 -> -97.21519 | AF18: =M18/J18 -> 0.95139241 | AG18: =AF23 -> 0.95901248
A19: 新豐7線 | B19: 微波主食 | C19: 韓式泡菜豬肉豆腐丼飯 | E19: 50.67 | F19: 1662 | G19: =E19*F19 -> 84213.54 | I19: 17 | J19: 2000 | K19: =J19/I19 -> 117.64706 | L19: 17 | M19: =F19/V19*60 -> 1917.6923 | N19: =M19/L19 -> 112.80543 | O19: =L19-I19 -> 0 | P19: =N19-K19 -> -4.841629 | Q19: =N19/K19 -> 0.95884615 | S19: 0.37708333 | T19: 0.41319444 | U19: =IF(S19=TIME(17,0,0),"",(S19-T18)*24*60) -> 6 | V19: =(T19-S19)*24*60 -> 52 | AE19: =M19-J19 -> -82.307692 | AF19: =M19/J19 -> 0.95884615
A20: 新豐7線 | B20: 微波主食 | C20: 鐵板滑蛋炸豬排丼 | E20: 57.73 | F20: 1737 | G20: =E20*F20 -> 100277.01 | I20: 14 | J20: 2000 | K20: =J20/I20 -> 142.85714 | L20: 14 | M20: =F20/V20*60 -> 1930 | N20: =M20/L20 -> 137.85714 | O20: =L20-I20 -> 0 | P20: =N20-K20 -> -5 | Q20: =N20/K20 -> 0.965 | S20: 0.41805556 | T20: 0.45555556 | U20: =IF(S20=TIME(17,0,0),"",(S20-T19)*24*60) -> 7 | V20: =(T20-S20)*24*60 -> 54 | AE20: =M20-J20 -> -70 | AF20: =M20/J20 -> 0.965
A21: 新豐7線 | B21: 微波主食 | C21: 二配川味麻婆燒豆腐燴飯 | E21: 50.49 | F21: 1311 | G21: =E21*F21 -> 66192.39 | I21: 15 | J21: 2000 | K21: =J21/I21 -> 133.33333 | L21: 15 | M21: =F21/V21*60 -> 1918.5366 | N21: =M21/L21 -> 127.90244 | O21: =L21-I21 -> 0 | P21: =N21-K21 -> -5.4308943 | Q21: =N21/K21 -> 0.95926829 | S21: 0.70833333 | T21: 0.73680556 | U21: =IF(S21=TIME(17,0,0),"",(S21-T20)*24*60) | V21: =(T21-S21)*24*60 -> 41 | AE21: =M21-J21 -> -81.463415 | AF21: =M21/J21 -> 0.95926829
A22: 新豐7線 | B22: 微波主食 | C22: 二配金咖哩濃厚辛口咖哩飯 | E22: 50.98 | F22: 1729 | G22: =E22*F22 -> 88144.42 | I22: 16 | J22: 2000 | K22: =J22/I22 -> 125 | L22: 16 | M22: =F22/V22*60 -> 1921.1111 | N22: =M22/L22 -> 120.06944 | O22: =L22-I22 -> 0 | P22: =N22-K22 -> -4.9305556 | Q22: =N22/K22 -> 0.96055556 | S22: 0.74166667 | T22: 0.77916667 | U22: =IF(S22=TIME(17,0,0),"",(S22-T21)*24*60) -> 7 | V22: =(T22-S22)*24*60 -> 54 | AE22: =M22-J22 -> -78.888889 | AF22: =M22/J22 -> 0.96055556
A23: 新豐7線 | B23: 平均 | I23: 16.2 | J23: 2000 | K23: =J23/I23 -> 123.45679 | L23: 16.2 | M23: =AVERAGE(M18:M22) -> 1918.025 | N23: =M23/L23 -> 118.3966 | O23: =L23-I23 -> 0 | P23: =N23-K23 -> -5.0601875 | Q23: =N23/K23 -> 0.95901248 | Y23: =SUM(Y18:Y22) -> 0 | Z23: =SUM(Z18:Z22) -> 0 | AC23: =SUM(AC18:AC22) -> 5 | AD23: =SUM(AD18:AD22) -> 0 | AE23: =M23-J23 -> -81.975037 | AF23: =M23/J23 -> 0.95901248
A24: 新豐8線 | B24: 三明治 | C24: 紐奧良風味烤雞鮮蔬三明治 | E24: 31.29 | F24: 5600 | G24: =E24*F24 -> 175224 | H24: 2 | I24: 18 | J24: 2400 | K24: =J24/I24 -> 133.33333 | L24: 18 | M24: =F24/V24*60 -> 2285.7143 | N24: =M24/L24 -> 126.98413 | O24: =L24-I24 -> 0 | P24: =N24-K24 -> -6.3492063 | Q24: =N24/K24 -> 0.95238095 | R24: =Q30 -> 0.95585452 | S24: 0.083333333 | T24: 0.18541667 | V24: =(T24-S24)*24*60 -> 147 | W24: =T24 -> 0.18541667 | X24: =S25 -> 0.20347222 | AC24: 6 | AE24: =M24-J24 -> -114.28571 | AF24: =M24/J24 -> 0.95238095 | AG24: =AF30 -> 0.95585452
A25: 新豐8線 | B25: 三明治 | C25: 經典總匯三明治 | E25: 26.2 | F25: 4855 | G25: =E25*F25 -> 127201 | I25: 20 | J25: 2400 | K25: =J25/I25 -> 120 | L25: 20 | M25: =F25/V25*60 -> 2293.7008 | N25: =M25/L25 -> 114.68504 | O25: =L25-I25 -> 0 | P25: =N25-K25 -> -5.3149606 | Q25: =N25/K25 -> 0.95570866 | S25: 0.20347222 | T25: 0.29166667 | U25: =(S25-T24)*24*60 -> 26 | V25: =(T25-S25)*24*60 -> 127 | AE25: =M25-J25 -> -106.29921 | AF25: =M25/J25 -> 0.95570866
A26: 新豐8線 | B26: 三明治 | C26: 醬燒烤雞三明治(115年) | E26: 26.37 | F26: 6714 | G26: =E26*F26 -> 177048.18 | I26: 19 | J26: 2400 | K26: =J26/I26 -> 126.31579 | L26: 19 | M26: =F26/V26*60 -> 2288.8636 | N26: =M26/L26 -> 120.46651 | O26: =L26-I26 -> 0 | P26: =N26-K26 -> -5.8492823 | Q26: =N26/K26 -> 0.95369318 | S26: 0.29652778 | T26: 0.41875 | U26: =(S26-T25)*24*60 -> 7 | V26: =(T26-S26)*24*60 -> 176 | AE26: =M26-J26 -> -111.13636 | AF26: =M26/J26 -> 0.95369318
A27: 新豐8線 | B27: 三明治 | C27: 雞蛋沙拉三明治(114年) | E27: 25.99 | F27: 3856 | G27: =E27*F27 -> 100217.44 | I27: 14 | J27: 2400 | K27: =J27/I27 -> 171.42857 | L27: 14 | M27: =F27/V27*60 -> 2290.6931 | N27: =M27/L27 -> 163.62093 | O27: =L27-I27 -> 0 | P27: =N27-K27 -> -7.8076379 | Q27: =N27/K27 -> 0.95445545 | S27: 0.42291667 | T27: 0.49305556 | U27: =(S27-T26)*24*60 -> 6 | V27: =(T27-S27)*24*60 -> 101 | W27: =T27 -> 0.49305556 | X27: =S28 -> 0.53472222 | AE27: =M27-J27 -> -109.30693 | AF27: =M27/J27 -> 0.95445545
A28: 新豐8線 | B28: 三明治 | C28: 紐奧良風味烤雞鮮蔬三明治 | E28: 31.29 | F28: 3458 | G28: =E28*F28 -> 108200.82 | I28: 18 | J28: 2400 | K28: =J28/I28 -> 133.33333 | L28: 18 | M28: =F28/V28*60 -> 2305.3333 | N28: =M28/L28 -> 128.07407 | O28: =L28-I28 -> 0 | P28: =N28-K28 -> -5.2592593 | Q28: =N28/K28 -> 0.96055556 | S28: 0.53472222 | T28: 0.59722222 | U28: =(S28-T27)*24*60 -> 60 | V28: =(T28-S28)*24*60 -> 90 | AE28: =M28-J28 -> -94.666667 | AF28: =M28/J28 -> 0.96055556
A29: 新豐8線 | B29: 三明治 | C29: 鮪魚起司溏心蛋三明治 | E29: 26.2 | F29: 1380 | G29: =E29*F29 -> 36156 | I29: 18 | J29: 2400 | K29: =J29/I29 -> 133.33333 | L29: 18 | M29: =F29/V29*60 -> 2300 | N29: =M29/L29 -> 127.77778 | O29: =L29-I29 -> 0 | P29: =N29-K29 -> -5.5555556 | Q29: =N29/K29 -> 0.95833333 | S29: 0.60069444 | T29: 0.62569444 | U29: =(S29-T28)*24*60 -> 5 | V29: =(T29-S29)*24*60 -> 36 | AE29: =M29-J29 -> -100 | AF29: =M29/J29 -> 0.95833333
A30: 新豐8線 | B30: 平均 | I30: 17.833333 | J30: 2400 | K30: =J30/I30 -> 134.57944 | L30: 17.833333 | M30: =AVERAGE(M24:M29) -> 2294.0509 | N30: =M30/L30 -> 128.63837 | O30: =L30-I30 -> 0 | P30: =N30-K30 -> -5.9410737 | Q30: =N30/K30 -> 0.95585452 | Y30: =SUM(Y24:Y29) -> 0 | Z30: =SUM(Z24:Z29) -> 0 | AC30: =SUM(AC24:AC29) -> 6 | AD30: =SUM(AD24:AD29) -> 0 | AE30: =M30-J30 -> -105.94915 | AF30: =M30/J30 -> 0.95585452
A31: 新豐9線 | B31: 三明治 | C31: 肉鬆火腿三明治(115年) | E31: 20.36 | F31: 3900 | G31: =E31*F31 -> 79404 | H31: 2 | I31: 18 | J31: 2400 | K31: =J31/I31 -> 133.33333 | L31: 18 | M31: =F31/V31*60 -> 2294.1176 | N31: =M31/L31 -> 127.45098 | O31: =L31-I31 -> 0 | P31: =N31-K31 -> -5.8823529 | Q31: =N31/K31 -> 0.95588235 | R31: =Q38 -> 0.95527862 | S31: 0.083333333 | T31: 0.15416667 | V31: =(T31-S31)*24*60 -> 102 | W31: =T31 -> 0.15416667 | X31: =S32 -> 0.17430556 | AC31: 7 | AE31: =M31-J31 -> -105.88235 | AF31: =M31/J31 -> 0.95588235 | AG31: =AF38 -> 0.95527862
A32: 新豐9線 | B32: 三明治 | C32: 經典火腿玉米蛋三明治 | E32: 24.43 | F32: 5859 | G32: =E32*F32 -> 143135.37 | I32: 14 | J32: 2400 | K32: =J32/I32 -> 171.42857 | L32: 14 | M32: =F32/V32*60 -> 2282.7273 | N32: =M32/L32 -> 163.05195 | O32: =L32-I32 -> 0 | P32: =N32-K32 -> -8.3766234 | Q32: =N32/K32 -> 0.95113636 | S32: 0.17430556 | T32: 0.28125 | U32: =(S32-T31)*24*60 -> 29 | V32: =(T32-S32)*24*60 -> 154 | AE32: =M32-J32 -> -117.27273 | AF32: =M32/J32 -> 0.95113636
A33: 新豐9線 | B33: 三明治 | C33: 好多菜三明治(114年) | E33: 25.98 | F33: 2793 | G33: =E33*F33 -> 72562.14 | I33: 21 | J33: 2400 | K33: =J33/I33 -> 114.28571 | L33: 21 | M33: =F33/V33*60 -> 2295.6164 | N33: =M33/L33 -> 109.31507 | O33: =L33-I33 -> 0 | P33: =N33-K33 -> -4.9706458 | Q33: =N33/K33 -> 0.95650685 | S33: 0.28541667 | T33: 0.33611111 | U33: =(S33-T32)*24*60 -> 6 | V33: =(T33-S33)*24*60 -> 73 | AE33: =M33-J33 -> -104.38356 | AF33: =M33/J33 -> 0.95650685
A34: 新豐9線 | B34: 三明治 | C34: 好多蛋三明治 | E34: 34.1 | F34: 4000 | G34: =E34*F34 -> 136400 | H34: 2 | I34: 17 | J34: 1600 | K34: =J34/I34 -> 94.117647 | L34: 17 | M34: =F34/V34*60 -> 1528.6624 | N34: =M34/L34 -> 89.921319 | O34: =L34-I34 -> 0 | P34: =N34-K34 -> -4.1963282 | Q34: =N34/K34 -> 0.95541401 | S34: 0.34097222 | T34: 0.45 | U34: =(S34-T33)*24*60 -> 7 | V34: =(T34-S34)*24*60 -> 157 | AE34: =M34-J34 -> -71.33758 | AF34: =M34/J34 -> 0.95541401
A35: 新豐9線 | B35: 三明治 | C35: 香鬆起司蛋三明治(114年) | E35: 20.2 | F35: 1760 | G35: =E35*F35 -> 35552 | I35: 15 | J35: 2400 | K35: =J35/I35 -> 160 | L35: 15 | M35: =F35/V35*60 -> 2295.6522 | N35: =M35/L35 -> 153.04348 | O35: =L35-I35 -> 0 | P35: =N35-K35 -> -6.9565217 | Q35: =N35/K35 -> 0.95652174 | S35: 0.45555556 | T35: 0.4875 | U35: =(S35-T34)*24*60 -> 8 | V35: =(T35-S35)*24*60 -> 46 | W35: =T35 -> 0.4875 | X35: =S36 -> 0.52638889 | AE35: =M35-J35 -> -104.34783 | AF35: =M35/J35 -> 0.95652174
A36: 新豐9線 | B36: 三明治 | C36: 好多蛋三明治 | E36: 34.1 | F36: 2715 | G36: =E36*F36 -> 92581.5 | I36: 17 | J36: 1600 | K36: =J36/I36 -> 94.117647 | L36: 17 | M36: =F36/V36*60 -> 1536.7925 | N36: =M36/L36 -> 90.399556 | O36: =L36-I36 -> 0 | P36: =N36-K36 -> -3.718091 | Q36: =N36/K36 -> 0.96049528 | S36: 0.52638889 | T36: 0.6 | U36: =(S36-T35)*24*60 -> 56 | V36: =(T36-S36)*24*60 -> 106 | AE36: =M36-J36 -> -63.207547 | AF36: =M36/J36 -> 0.96049528
A37: 新豐9線 | B37: 三明治 | C37: 肉鬆火腿三明治(115年) | E37: 20.36 | F37: 2744 | G37: =E37*F37 -> 55867.84 | I37: 18 | J37: 2400 | K37: =J37/I37 -> 133.33333 | L37: 18 | M37: =F37/V37*60 -> 2286.6667 | N37: =M37/L37 -> 127.03704 | O37: =L37-I37 -> 0 | P37: =N37-K37 -> -6.2962963 | Q37: =N37/K37 -> 0.95277778 | S37: 0.60347222 | T37: 0.65347222 | U37: =(S37-T36)*24*60 -> 5 | V37: =(T37-S37)*24*60 -> 72 | AE37: =M37-J37 -> -113.33333 | AF37: =M37/J37 -> 0.95277778
A38: 新豐9線 | B38: 平均 | I38: 17.142857 | J38: 2171.4286 | K38: =J38/I38 -> 126.66667 | L38: 17.142857 | M38: =AVERAGE(M31:M37) -> 2074.3193 | N38: =M38/L38 -> 121.00196 | O38: =L38-I38 -> 0 | P38: =N38-K38 -> -5.6647077 | Q38: =N38/K38 -> 0.95527862 | Y38: =SUM(Y31:Y37) -> 0 | Z38: =SUM(Z31:Z37) -> 0 | AC38: =SUM(AC31:AC37) -> 7 | AD38: =SUM(AD31:AD37) -> 0 | AE38: =M38-J38 -> -97.109275 | AF38: =M38/J38 -> 0.95527862
A39: 新豐3線 | B39: 調理麵包 | C39: 黑胡椒豬肉鐵板炒麵麵包 | E39: 37.88 | F39: 5050 | G39: =E39*F39 -> 191294 | I39: 13 | J39: 2000 | K39: =J39/I39 -> 153.84615 | L39: 13 | M39: =F39/V39*60 -> 1905.6604 | N39: =M39/L39 -> 146.58926 | O39: =L39-I39 -> 0 | P39: =N39-K39 -> -7.256894 | Q39: =N39/K39 -> 0.95283019 | R39: =Q43 -> 0.95654587 | S39: 0.083333333 | T39: 0.19375 | V39: =(T39-S39)*24*60 -> 159 | W39: =T39 -> 0.19375 | X39: =S40 -> 0.2125 | AC39: 4 | AE39: =M39-J39 -> -94.339623 | AF39: =M39/J39 -> 0.95283019 | AG39: =AF43 -> 0.95654587
A40: 新豐3線 | B40: 調理麵包 | C40: 經典雙牛起司堡(113年) | E40: 35.12 | F40: 3884 | G40: =E40*F40 -> 136406.08 | I40: 10 | J40: 3000 | K40: =J40/I40 -> 300 | L40: 10 | M40: =F40/V40*60 -> 2877.037 | N40: =M40/L40 -> 287.7037 | O40: =L40-I40 -> 0 | P40: =N40-K40 -> -12.296296 | Q40: =N40/K40 -> 0.95901235 | S40: 0.2125 | T40: 0.26875 | U40: =(S40-T39)*24*60 -> 27 | V40: =(T40-S40)*24*60 -> 81 | AE40: =M40-J40 -> -122.96296 | AF40: =M40/J40 -> 0.95901235
...

Sheet 0429
B1: 屏榮 新豐廠組合室生產人時性分析
B3: 日期 | C3: =TEXT('0429 4度C'!A2,"yyyy.mm.ddaaaa") -> 2026.04.29星期三 | E3: 訂單量 | F3: ='0429 4度C'!D1 -> 178103 | H3: 營業額 | I3: ='0429 4度C'!F1 -> 5954445.1
B4: 人時性 | C4: 項目 | E4: ➀ | G4: ➁ | I4: ➂ | K4: 異常停線 | M4: 短暫停線
C5: 組合室 | E5: 全溫層 | G5: 4度C-各編組展開 | I5: ③三明治-各編組展開 | K5: 合計次數 | L5: 時間 | M5: 合計次數 | N5: 設備次數
C6: 排關平均 | E6: =AVERAGE(D13:M13) -> 151.07581 | F6: =AVERAGE(D31:O31,D13:J13) -> 157.40334 | G6: =AVERAGE(D13:J13) -> 157.40334 | I6: =AVERAGE(K13:M13) -> 136.31158 | K6: ='0429 4度C'!Y2 -> 0 | L6: ='0429 4度C'!Z2 -> 0 | M6: ='0429 4度C'!AC2 -> 58 | N6: ='0429 4度C'!AD2 -> 0
C7: 實績平均 | E7: =AVERAGE(D14:M14) -> 144.8514 | F7: =AVERAGE(D32:O32,D14:J14) -> 151.06614 | G7: =AVERAGE(D14:J14) -> 151.06614 | I7: =AVERAGE(K14:M14) -> 130.35032
C8: 達成率平均 | E8: =AVERAGE(D15:M15) -> 0.958816 | F8: =AVERAGE(D15:J15,D33:O33) -> 0.95995787 | G8: =AVERAGE(D15:J15) -> 0.95995787 | I8: =AVERAGE(K15:M15) -> 0.95615165
K9: ※現行日本鮮食廠以達成率80%為基本(即為現行KPI)
B10: 溫層 | D10: ➁4度C-各編組展開 | K10: ③三明治-各編組展開
B11: 編組 | D11: 1 | E11: 2 | F11: 3 | G11: 4 | H11: 5 | I11: 6 | J11: 7 | K11: 1 | L11: 2 | M11: 3
D12: 新豐6線 | E12: 新豐2線 | F12: 新豐5線 | G12: 新豐7線 | H12: 新豐3線 | I12: 新豐1線 | J12: 新豐10線 | K12: 新豐8線 | L12: 新豐9線 | M12: 新豐4線
B13: 人時性 | C13: 排關 | D13: =SUMIFS('0429 4度C'!$K:$K,'0429 4度C'!$A:$A,"新豐6線",'0429 4度C'!$B:$B,"平均") -> 119.40299 | E13: =SUMIFS('0429 4度C'!$K:$K,'0429 4度C'!$A:$A,"新豐2線",'0429 4度C'!$B:$B,"平均") -> 83.333333 | F13: =SUMIFS('0429 4度C'!$K:$K,'0429 4度C'!$A:$A,"新豐5線",'0429 4度C'!$B:$B,"平均") -> 100 | G13: =SUMIFS('0429 4度C'!$K:$K,'0429 4度C'!$A:$A,"新豐7線",'0429 4度C'!$B:$B,"平均") -> 123.45679 | H13: =SUMIFS('0429 4度C'!$K:$K,'0429 4度C'!$A:$A,"新豐3線",'0429 4度C'!$B:$B,"平均") -> 255.81395 | I13: =SUMIFS('0429 4度C'!$K:$K,'0429 4度C'!$A:$A,"新豐1線",'0429 4度C'!$B:$B,"平均") -> 104.02685 | J13: =SUMIFS('0429 4度C'!$K:$K,'0429 4度C'!$A:$A,"新豐10線",'0429 4度C'!$B:$B,"平均") -> 315.78947 | K13: =SUMIFS('0429 4度C'!$K:$K,'0429 4度C'!$A:$A,"新豐8線",'0429 4度C'!$B:$B,"平均") -> 131.25 | L13: =SUMIFS('0429 4度C'!$K:$K,'0429 4度C'!$A:$A,"新豐9線",'0429 4度C'!$B:$B,"平均") -> 131.34328 | M13: =SUMIFS('0429 4度C'!$K:$K,'0429 4度C'!$A:$A,"新豐4線",'0429 4度C'!$B:$B,"平均") -> 146.34146
C14: 實績 | D14: =SUMIFS('0429 4度C'!$N:$N,'0429 4度C'!$A:$A,"新豐6線",'0429 4度C'!$B:$B,"平均") -> 114.16627 | E14: =SUMIFS('0429 4度C'!$N:$N,'0429 4度C'!$A:$A,"新豐2線",'0429 4度C'!$B:$B,"平均") -> 79.629357 | F14: =SUMIFS('0429 4度C'!$N:$N,'0429 4度C'!$A:$A,"新豐5線",'0429 4度C'!$B:$B,"平均") -> 96.654847 | G14: =SUMIFS('0429 4度C'!$N:$N,'0429 4度C'!$A:$A,"新豐7線",'0429 4度C'!$B:$B,"平均") -> 118.24046 | H14: =SUMIFS('0429 4度C'!$N:$N,'0429 4度C'!$A:$A,"新豐3線",'0429 4度C'!$B:$B,"平均") -> 244.17454 | I14: =SUMIFS('0429 4度C'!$N:$N,'0429 4度C'!$A:$A,"新豐1線",'0429 4度C'!$B:$B,"平均") -> 100.52192 | J14: =SUMIFS('0429 4度C'!$N:$N,'0429 4度C'!$A:$A,"新豐10線",'0429 4度C'!$B:$B,"平均") -> 304.07561 | K14: =SUMIFS('0429 4度C'!$N:$N,'0429 4度C'!$A:$A,"新豐8線",'0429 4度C'!$B:$B,"平均") -> 125.18267 | L14: =SUMIFS('0429 4度C'!$N:$N,'0429 4度C'!$A:$A,"新豐9線",'0429 4度C'!$B:$B,"平均") -> 125.48409 | M14: =SUMIFS('0429 4度C'!$N:$N,'0429 4度C'!$A:$A,"新豐4線",'0429 4度C'!$B:$B,"平均") -> 140.38419
C15: 達成率 | D15: =D14/D13 -> 0.95614252 | E15: =E14/E13 -> 0.95555228 | F15: =F14/F13 -> 0.96654847 | G15: =G14/G13 -> 0.95774771 | H15: =H14/H13 -> 0.95450046 | I15: =I14/I13 -> 0.96630753 | J15: =J14/J13 -> 0.96290609 | K15: =K14/K13 -> 0.95377274 | ... M15: =M14/M13 -> 0.95929197
B16: 作業 時間 | C16: 開始 | D16: =VLOOKUP("新豐6線",'0429 4度C'!$A:$T,19,0) -> 0.70833333 | E16: =VLOOKUP("新豐2線",'0429 4度C'!$A:$T,19,0) -> 0.20833333 | F16: =VLOOKUP("新豐5線",'0429 4度C'!$A:$T,19,0) -> 0.20833333 | G16: =VLOOKUP("新豐7線",'0429 4度C'!$A:$T,19,0) -> 0.20833333 | H16: =VLOOKUP("新豐3線",'0429 4度C'!$A:$T,19,0) -> 0.083333333 | I16: =VLOOKUP("新豐1線",'0429 4度C'!$A:$T,19,0) -> 0.20833333 | J16: =VLOOKUP("新豐10線",'0429 4度C'!$A:$T,19,0) -> 0.20833333 | K16: =VLOOKUP("新豐8線",'0429 4度C'!$A:$T,19,0) -> 0.083333333 | L16: =VLOOKUP("新豐9線",'0429 4度C'!$A:$T,19,0) -> 0.083333333 | M16: =VLOOKUP("新豐4線",'0429 4度C'!$A:$T,19,0) -> 0.083333333
C17: 結束 | D17: =LOOKUP(2,1/(('0429 4度C'!$A:$A="新豐6線")*('0429 4度C'!$T:$T<>"")),'0429 4度C'!$T:$T) -> 0.825 | E17: =LOOKUP(2,1/(('0429 4度C'!$A:$A="新豐2線")*('0429 4度C'!$T:$T<>"")),'0429 4度C'!$T:$T) -> 0.52013889 | F17: =LOOKUP(2,1/(('0429 4度C'!$A:$A="新豐5線")*('0429 4度C'!$T:$T<>"")),'0429 4度C'!$T:$T) -> 0.81805556 | G17: =LOOKUP(2,1/(('0429 4度C'!$A:$A="新豐7線")*('0429 4度C'!$T:$T<>"")),'0429 4度C'!$T:$T) -> 0.79236111 | H17: =LOOKUP(2,1/(('0429 4度C'!$A:$A="新豐3線")*('0429 4度C'!$T:$T<>"")),'0429 4度C'!$T:$T) -> 0.47569444 | I17: =LOOKUP(2,1/(('0429 4度C'!$A:$A="新豐1線")*('0429 4度C'!$T:$T<>"")),'0429 4度C'!$T:$T) -> 0.79444444 | J17: =LOOKUP(2,1/(('0429 4度C'!$A:$A="新豐10線")*('0429 4度C'!$T:$T<>"")),'0429 4度C'!$T:$T) -> 0.41597222 | K17: =LOOKUP(2,1/(('0429 4度C'!$A:$A="新豐8線")*('0429 4度C'!$T:$T<>"")),'0429 4度C'!$T:$T) -> 0.75763889 | L17: =LOOKUP(2,1/(('0429 4度C'!$A:$A="新豐9線")*('0429 4度C'!$T:$T<>"")),'0429 4度C'!$T:$T) -> 0.74722222 | M17: =LOOKUP(2,1/(('0429 4度C'!$A:$A="新豐4線")*('0429 4度C'!$T:$T<>"")),'0429 4度C'!$T:$T) -> 0.78263889
B18: 產線異常 (5分鐘以上) | C18: 次數 | D18: =SUMIFS('0429 4度C'!$Y:$Y,'0429 4度C'!$A:$A,"新豐6線",'0429 4度C'!$B:$B,"平均") -> 0 | E18: =SUMIFS('0429 4度C'!$Y:$Y,'0429 4度C'!$A:$A,"新豐2線",'0429 4度C'!$B:$B,"平均") -> 0 | F18: =SUMIFS('0429 4度C'!$Y:$Y,'0429 4度C'!$A:$A,"新豐5線",'0429 4度C'!$B:$B,"平均") -> 0 | G18: =SUMIFS('0429 4度C'!$Y:$Y,'0429 4度C'!$A:$A,"新豐7線",'0429 4度C'!$B:$B,"平均") -> 0 | H18: =SUMIFS('0429 4度C'!$Y:$Y,'0429 4度C'!$A:$A,"新豐3線",'0429 4度C'!$B:$B,"平均") -> 0 | I18: =SUMIFS('0429 4度C'!$Y:$Y,'0429 4度C'!$A:$A,"新豐1線",'0429 4度C'!$B:$B,"平均") -> 0 | J18: =SUMIFS('0429 4度C'!$Y:$Y,'0429 4度C'!$A:$A,"新豐10線",'0429 4度C'!$B:$B,"平均") -> 0 | K18: =SUMIFS('0429 4度C'!$Y:$Y,'0429 4度C'!$A:$A,"新豐8線",'0429 4度C'!$B:$B,"平均") -> 0 | L18: =SUMIFS('0429 4度C'!$Y:$Y,'0429 4度C'!$A:$A,"新豐9線",'0429 4度C'!$B:$B,"平均") -> 0 | M18: =SUMIFS('0429 4度C'!$Y:$Y,'0429 4度C'!$A:$A,"新豐4線",'0429 4度C'!$B:$B,"平均") -> 0
C19: 時間/分 | D19: =SUMIFS('0429 4度C'!$Z:$Z,'0429 4度C'!$A:$A,"新豐6線",'0429 4度C'!$B:$B,"平均") -> 0 | E19: =SUMIFS('0429 4度C'!$Z:$Z,'0429 4度C'!$A:$A,"新豐2線",'0429 4度C'!$B:$B,"平均") -> 0 | F19: =SUMIFS('0429 4度C'!$Z:$Z,'0429 4度C'!$A:$A,"新豐5線",'0429 4度C'!$B:$B,"平均") -> 0 | G19: =SUMIFS('0429 4度C'!$Z:$Z,'0429 4度C'!$A:$A,"新豐7線",'0429 4度C'!$B:$B,"平均") -> 0 | H19: =SUMIFS('0429 4度C'!$Z:$Z,'0429 4度C'!$A:$A,"新豐3線",'0429 4度C'!$B:$B,"平均") -> 0 | I19: =SUMIFS('0429 4度C'!$Z:$Z,'0429 4度C'!$A:$A,"新豐1線",'0429 4度C'!$B:$B,"平均") -> 0 | J19: =SUMIFS('0429 4度C'!$Z:$Z,'0429 4度C'!$A:$A,"新豐10線",'0429 4度C'!$B:$B,"平均") -> 0 | K19: =SUMIFS('0429 4度C'!$Z:$Z,'0429 4度C'!$A:$A,"新豐8線",'0429 4度C'!$B:$B,"平均") -> 0 | L19: =SUMIFS('0429 4度C'!$Z:$Z,'0429 4度C'!$A:$A,"新豐9線",'0429 4度C'!$B:$B,"平均") -> 0 | M19: =SUMIFS('0429 4度C'!$Z:$Z,'0429 4度C'!$A:$A,"新豐4線",'0429 4度C'!$B:$B,"平均") -> 0
B20: 短暫停線 (5分鐘以下) | C20: 次數 | D20: =SUMIFS('0429 4度C'!$AC:$AC,'0429 4度C'!$A:$A,"新豐6線",'0429 4度C'!$B:$B,"平均") -> 4 | E20: =SUMIFS('0429 4度C'!$AC:$AC,'0429 4度C'!$A:$A,"新豐2線",'0429 4度C'!$B:$B,"平均") -> 2 | F20: =SUMIFS('0429 4度C'!$AC:$AC,'0429 4度C'!$A:$A,"新豐5線",'0429 4度C'!$B:$B,"平均") -> 4 | G20: =SUMIFS('0429 4度C'!$AC:$AC,'0429 4度C'!$A:$A,"新豐7線",'0429 4度C'!$B:$B,"平均") -> 5 | H20: =SUMIFS('0429 4度C'!$AC:$AC,'0429 4度C'!$A:$A,"新豐3線",'0429 4度C'!$B:$B,"平均") -> 4 | I20: =SUMIFS('0429 4度C'!$AC:$AC,'0429 4度C'!$A:$A,"新豐1線",'0429 4度C'!$B:$B,"平均") -> 8 | J20: =SUMIFS('0429 4度C'!$AC:$AC,'0429 4度C'!$A:$A,"新豐10線",'0429 4度C'!$B:$B,"平均") -> 6 | K20: =SUMIFS('0429 4度C'!$AC:$AC,'0429 4度C'!$A:$A,"新豐8線",'0429 4度C'!$B:$B,"平均") -> 7 | L20: =SUMIFS('0429 4度C'!$AC:$AC,'0429 4度C'!$A:$A,"新豐9線",'0429 4度C'!$B:$B,"平均") -> 8 | M20: =SUMIFS('0429 4度C'!$AC:$AC,'0429 4度C'!$A:$A,"新豐4線",'0429 4度C'!$B:$B,"平均") -> 10
C21: 設備次數 | D21: =SUMIFS('0429 4度C'!$AD:$AD,'0429 4度C'!$A:$A,"新豐6線",'0429 4度C'!$B:$B,"平均") -> 0 | E21: =SUMIFS('0429 4度C'!$AD:$AD,'0429 4度C'!$A:$A,"新豐2線",'0429 4度C'!$B:$B,"平均") -> 0 | F21: =SUMIFS('0429 4度C'!$AD:$AD,'0429 4度C'!$A:$A,"新豐5線",'0429 4度C'!$B:$B,"平均") -> 0 | G21: =SUMIFS('0429 4度C'!$AD:$AD,'0429 4度C'!$A:$A,"新豐7線",'0429 4度C'!$B:$B,"平均") -> 0 | H21: =SUMIFS('0429 4度C'!$AD:$AD,'0429 4度C'!$A:$A,"新豐3線",'0429 4度C'!$B:$B,"平均") -> 0 | I21: =SUMIFS('0429 4度C'!$AD:$AD,'0429 4度C'!$A:$A,"新豐1線",'0429 4度C'!$B:$B,"平均") -> 0 | J21: =SUMIFS('0429 4度C'!$AD:$AD,'0429 4度C'!$A:$A,"新豐10線",'0429 4度C'!$B:$B,"平均") -> 0 | K21: =SUMIFS('0429 4度C'!$AD:$AD,'0429 4度C'!$A:$A,"新豐8線",'0429 4度C'!$B:$B,"平均") -> 0 | L21: =SUMIFS('0429 4度C'!$AD:$AD,'0429 4度C'!$A:$A,"新豐9線",'0429 4度C'!$B:$B,"平均") -> 0 | M21: =SUMIFS('0429 4度C'!$AD:$AD,'0429 4度C'!$A:$A,"新豐4線",'0429 4度C'!$B:$B,"平均") -> 0
B22: 配置人數 | D22: =SUMIFS('0429 4度C'!$I:$I,'0429 4度C'!$A:$A,"新豐6線",'0429 4度C'!$B:$B,"平均") -> 16.75 | E22: =SUMIFS('0429 4度C'!$I:$I,'0429 4度C'!$A:$A,"新豐2線",'0429 4度C'!$B:$B,"平均") -> 18 | F22: =SUMIFS('0429 4度C'!$I:$I,'0429 4度C'!$A:$A,"新豐5線",'0429 4度C'!$B:$B,"平均") -> 17.5 | G22: =SUMIFS('0429 4度C'!$I:$I,'0429 4度C'!$A:$A,"新豐7線",'0429 4度C'!$B:$B,"平均") -> 16.2 | H22: =SUMIFS('0429 4度C'!$I:$I,'0429 4度C'!$A:$A,"新豐3線",'0429 4度C'!$B:$B,"平均") -> 10.75 | I22: =SUMIFS('0429 4度C'!$I:$I,'0429 4度C'!$A:$A,"新豐1線",'0429 4度C'!$B:$B,"平均") -> 18.625 | J22: =SUMIFS('0429 4度C'!$I:$I,'0429 4度C'!$A:$A,"新豐10線",'0429 4度C'!$B:$B,"平均") -> 9.5 | K22: =SUMIFS('0429 4度C'!$I:$I,'0429 4度C'!$A:$A,"新豐8線",'0429 4度C'!$B:$B,"平均") -> 18.285714 | L22: =SUMIFS('0429 4度C'!$I:$I,'0429 4度C'!$A:$A,"新豐9線",'0429 4度C'!$B:$B,"平均") -> 16.75 | M22: =SUMIFS('0429 4度C'!$I:$I,'0429 4度C'!$A:$A,"新豐4線",'0429 4度C'!$B:$B,"平均") -> 16.4
B23: 主要應用設備 | D23: ET-55 | E23: 熱縮爐 | F23: L型包裝機 | G23: L型包裝機 | H23: 伺服包裝機 | I23: ET-55 | J23: 伺服包裝機 | K23: 三明治包裝機 | L23: 三明治包裝機 | M23: 三明治包裝機
B24: 次要應用設備 | F24: 圓盤機 | G24: ET-55
B25: 備註 | E25: 握沙拉 | F25: 共用L型包裝機 | H25: 調理麵包 | I25: 炒飯+沙拉 | J25: 調理麵包

Sheet 0429 4度C
A1: 新豐廠四度C日報分析 | C1: 總生產量 | D1: =SUM(F5:F72) -> 178103 | E1: 營業額 | F1: =SUM(G5:G72) -> 5954445.1 | G1: 出勤人數 | H1: =L9+L12+L45+L54+L17+L61+L31+L40+L23+L72 -> 158.76071 | I1: 產線配置圖 | L1: 生產實績 | O1: 人時性差異分析 | S1: 日報登錄 | Y1: 合計 次數 | Z1: 合計 時間/分 | AA1: 產線異常 分析說明(5分鐘以上) | AC1: 合計 次數 | AD1: 合計 設備次數 | AE1: 產能差異分析
A2: 46141 | B2: 星期三 | C2: 人時性 | D2: =AVERAGE(N9,N12,N45,N54,N17,N61,N23,N31,N40,N72) -> 144.8514 | E2: 平均廠價 | F2: =F1/D1 -> 33.432593 | G2: 多次生產數 | H2: =COUNT(H5:H72) -> 10 | Y2: =SUM(Y9+Y12+Y17+Y23+Y31+Y40+Y45+Y54+Y61+Y72) -> 0 | Z2: =SUM(Z9+Z12+Z17+Z23+Z31+Z40+Z45+Z54+Z61+Z72) -> 0 | AC2: 58 | AD2: =SUM(AD9+AD12+AD17+AD23+AD31+AD40+AD45+AD54+AD61+AD72) -> 0
A3: 線別 | B3: 品類 | C3: 品名 | E3: 廠價 | F3: 生產量 | G3: 營收 | H3: 多次 生產 | I3: 人數 | J3: 產能/時 | K3: 人時性 | L3: 人數 | M3: 產能/時 | N3: 人時性 | O3: 人數 | P3: 人時性 | Q3: 達成率 | R3: 達成率平均 | S3: 生產時間 | U3: 換線、休息/分 | V3: 稼動時間/分 | W3: 休息時間 | Y3: 產線異常統計 (5分鐘以上) | AA3: (新豐回填) | AC3: 短暫停線統計 (5分鐘以下) | AE3: 產能/時 | AF3: 達成率 | AG3: 達成率平均
S4: 開始 | T4: 結束 | W4: 開始 | X4: 結束 | Y4: 次數 | Z4: 時間/分 | AC4: 總次數 | AD4: 設備因素(次數)
A5: 新豐6線 | B5: 微波主食 | C5: 二配港式香滑嫩蛋牛肉燴飯 | E5: 50.67 | F5: 1151 | G5: =E5*F5 -> 58321.17 | I5: 17 | J5: 2000 | K5: =J5/I5 -> 117.64706 | L5: 17 | M5: =F5/V5*60 -> 1918.3333 | N5: =M5/L5 -> 112.84314 | O5: =L5-I5 -> 0 | P5: =N5-K5 -> -4.8039216 | Q5: =N5/K5 -> 0.95916667 | R5: =Q9 -> 0.95614252 | S5: 0.70833333 | T5: 0.73333333 | V5: =(T5-S5)*24*60 -> 36 | AC5: 4 | AE5: =M5-J5 -> -81.666667 | AF5: =M5/J5 -> 0.95916667 | AG5: =AF9 -> 0.95614252
A6: 新豐6線 | B6: 微波主食 | C6: 二配美味蟹煲 | E6: 54.09 | F6: 984 | G6: =E6*F6 -> 53224.56 | I6: 19 | J6: 2000 | K6: =J6/I6 -> 105.26316 | L6: 19 | M6: =F6/V6*60 -> 1904.5161 | N6: =M6/L6 -> 100.23769 | O6: =L6-I6 -> 0 | P6: =N6-K6 -> -5.0254669 | Q6: =N6/K6 -> 0.95225806 | S6: 0.73819444 | T6: 0.75972222 | U6: =IF(S6=TIME(17,0,0),"",(S6-T5)*24*60) -> 7 | V6: =(T6-S6)*24*60 -> 31 | AE6: =M6-J6 -> -95.483871 | AF6: =M6/J6 -> 0.95225806
A7: 新豐6線 | B7: 微波主食 | C7: 二配泰式綠咖哩雞 | E7: 50.67 | F7: 1269 | G7: =E7*F7 -> 64300.23 | I7: 15 | J7: 2000 | K7: =J7/I7 -> 133.33333 | L7: 15 | M7: =F7/V7*60 -> 1903.5 | N7: =M7/L7 -> 126.9 | O7: =L7-I7 -> 0 | P7: =N7-K7 -> -6.4333333 | Q7: =N7/K7 -> 0.95175 | S7: 0.76388889 | T7: 0.79166667 | U7: =IF(S7=TIME(17,0,0),"",(S7-T6)*24*60) -> 6 | V7: =(T7-S7)*24*60 -> 40 | AE7: =M7-J7 -> -96.5 | AF7: =M7/J7 -> 0.95175
A8: 新豐6線 | B8: 微波主食 | C8: 二配蔥爆牛肉燴飯 | E8: 52.86 | F8: 1378 | G8: =E8*F8 -> 72841.08 | I8: 16 | J8: 2000 | K8: =J8/I8 -> 125 | L8: 16 | M8: =F8/V8*60 -> 1922.7907 | N8: =M8/L8 -> 120.17442 | O8: =L8-I8 -> 0 | P8: =N8-K8 -> -4.8255814 | Q8: =N8/K8 -> 0.96139535 | S8: 0.79513889 | T8: 0.825 | U8: =IF(S8=TIME(17,0,0),"",(S8-T7)*24*60) -> 5 | V8: =(T8-S8)*24*60 -> 43 | AE8: =M8-J8 -> -77.209302 | AF8: =M8/J8 -> 0.96139535
A9: 新豐6線 | B9: 平均 | I9: 16.75 | J9: 2000 | K9: =J9/I9 -> 119.40299 | L9: 16.75 | M9: =AVERAGE(M5:M8) -> 1912.285 | N9: =M9/L9 -> 114.16627 | O9: =L9-I9 -> 0 | P9: =N9-K9 -> -5.236714 | Q9: =N9/K9 -> 0.95614252 | Y9: =SUM(Y5:Y8) -> 0 | Z9: =SUM(Z5:Z8) -> 0 | AC9: 4 | AD9: =SUM(AD5:AD8) -> 0 | AE9: =M9-J9 -> -87.71496 | AF9: =M9/J9 -> 0.95614252
A10: 新豐2線 | B10: 沙拉 | C10: 青醬優格雞肉握沙拉(113年) | E10: 39.62 | F10: 4169 | G10: =E10*F10 -> 165175.78 | I10: 19 | J10: 1500 | K10: =J10/I10 -> 78.947368 | L10: 19 | M10: =F10/V10*60 -> 1437.5862 | N10: =M10/L10 -> 75.662432 | O10: =L10-I10 -> 0 | P10: =N10-K10 -> -3.2849365 | Q10: =N10/K10 -> 0.9583908 | R10: =Q12 -> 0.95555228 | S10: 0.20833333 | T10: 0.32916667 | V10: =(T10-S10)*24*60 -> 174 | AC10: 2 | AE10: =M10-J10 -> -62.413793 | AF10: =M10/J10 -> 0.9583908 | AG10: =AF12 -> 0.95555228
A11: 新豐2線 | B11: 沙拉 | C11: 青檸烤雞握沙拉(113年) | E11: 39.8 | F11: 6407 | G11: =E11*F11 -> 254998.6 | I11: 17 | J11: 1500 | K11: =J11/I11 -> 88.235294 | L11: 17 | M11: =F11/V11*60 -> 1429.0706 | N11: =M11/L11 -> 84.062978 | O11: =L11-I11 -> 0 | P11: =N11-K11 -> -4.1723158 | Q11: =N11/K11 -> 0.95271375 | S11: 0.33333333 | T11: 0.52013889 | U11: =IF(S11=TIME(17,0,0),"",(S11-T10)*24*60) -> 6 | V11: =(T11-S11)*24*60 -> 269 | AE11: =M11-J11 -> -70.929368 | AF11: =M11/J11 -> 0.95271375
A12: 新豐2線 | B12: 平均 | I12: 18 | J12: 1500 | K12: =J12/I12 -> 83.333333 | L12: 18 | M12: =AVERAGE(M10:M11) -> 1433.3284 | N12: =M12/L12 -> 79.629357 | O12: =L12-I12 -> 0 | P12: =N12-K12 -> -3.7039767 | Q12: =N12/K12 -> 0.95555228 | Y12: =SUM(Y10:Y11) -> 0 | Z12: =SUM(Z10:Z11) -> 0 | AC12: 2 | AD12: =SUM(AD10:AD11) -> 0 | AE12: =M12-J12 -> -66.671581 | AF12: =M12/J12 -> 0.95555228
A13: 新豐5線 | B13: 小吃 | C13: 剝皮辣椒雞湯 | E13: 41 | F13: 1836 | G13: =E13*F13 -> 75276 | I13: 26 | J13: 1500 | K13: =J13/I13 -> 57.692308 | L13: 26 | M13: =F13/V13*60 -> 1430.6494 | N13: =M13/L13 -> 55.024975 | O13: =L13-I13 -> 0 | P13: =N13-K13 -> -2.6673327 | Q13: =N13/K13 -> 0.95376623 | R13: =Q17 -> 0.96654847 | S13: 0.20833333 | T13: 0.26180556 | V13: =(T13-S13)*24*60 -> 77 | AC13: 4 | AE13: =M13-J13 -> -69.350649 | AF13: =M13/J13 -> 0.95376623 | AG13: =AF17 -> 0.96654847
A14: 新豐5線 | B14: 微波主食 | C14: 二配起司控培根白醬焗烤飯 | E14: 53.68 | F14: 1115 | G14: =E14*F14 -> 59853.2 | I14: 16 | J14: 1500 | K14: =J14/I14 -> 93.75 | L14: 16 | M14: =F14/V14*60 -> 1454.3478 | N14: =M14/L14 -> 90.896739 | O14: =L14-I14 -> 0 | P14: =N14-K14 -> -2.8532609 | Q14: =N14/K14 -> 0.96956522 | S14: 0.70833333 | T14: 0.74027778 | U14: =IF(S14=TIME(17,0,0),"",(S14-T13)*24*60) | V14: =(T14-S14)*24*60 -> 46 | AE14: =M14-J14 -> -45.652174 | AF14: =M14/J14 -> 0.96956522
A15: 新豐5線 | B15: 微波主食 | C15: 二配金咖哩果香甘口咖哩飯 | E15: 50.92 | F15: 1840 | G15: =E15*F15 -> 93692.8 | I15: 15 | J15: 2000 | K15: =J15/I15 -> 133.33333 | L15: 15 | M15: =F15/V15*60 -> 1936.8421 | N15: =M15/L15 -> 129.12281 | O15: =L15-I15 -> 0 | P15: =N15-K15 -> -4.2105263 | Q15: =N15/K15 -> 0.96842105 | S15: 0.74513889 | T15: 0.78472222 | U15: =IF(S15=TIME(17,0,0),"",(S15-T14)*24*60) -> 7 | V15: =(T15-S15)*24*60 -> 57 | AE15: =M15-J15 -> -63.157895 | AF15: =M15/J15 -> 0.96842105
A16: 新豐5線 | B16: 微波主食 | C16: 二配厚香料咖哩雞排飯 | E16: 57.3 | F16: 1296 | G16: =E16*F16 -> 74260.8 | I16: 13 | J16: 2000 | K16: =J16/I16 -> 153.84615 | L16: 13 | M16: =F16/V16*60 -> 1944 | N16: =M16/L16 -> 149.53846 | O16: =L16-I16 -> 0 | P16: =N16-K16 -> -4.3076923 | Q16: =N16/K16 -> 0.972 | S16: 0.79027778 | T16: 0.81805556 | U16: =IF(S16=TIME(17,0,0),"",(S16-T15)*24*60) -> 8 | V16: =(T16-S16)*24*60 -> 40 | AE16: =M16-J16 -> -56 | AF16: =M16/J16 -> 0.972
A17: 新豐5線 | B17: 平均 | I17: 17.5 | J17: 1750 | K17: =J17/I17 -> 100 | L17: 17.5 | M17: =AVERAGE(M13:M16) -> 1691.4598 | N17: =M17/L17 -> 96.654847 | O17: =L17-I17 -> 0 | P17: =N17-K17 -> -3.3451531 | Q17: =N17/K17 -> 0.96654847 | Y17: =SUM(Y13:Y16) -> 0 | Z17: =SUM(Z13:Z16) -> 0 | AC17: 4 | AD17: =SUM(AD13:AD16) -> 0 | AE17: =M17-J17 -> -58.54018 | AF17: =M17/J17 -> 0.96654847
A18: 新豐7線 | B18: 微波主食 | C18: 爆炒雞丁飯 | E18: 59.04 | F18: 7910 | G18: =E18*F18 -> 467006.4 | I18: 19 | J18: 2000 | K18: =J18/I18 -> 105.26316 | L18: 19 | M18: =F18/V18*60 -> 1906.0241 | N18: =M18/L18 -> 100.31706 | O18: =L18-I18 -> 0 | P18: =N18-K18 -> -4.9461002 | Q18: =N18/K18 -> 0.95301205 | R18: =Q23 -> 0.95774771 | S18: 0.20833333 | T18: 0.38125 | V18: =(T18-S18)*24*60 -> 249 | AC18: 5 | AE18: =M18-J18 -> -93.975904 | AF18: =M18/J18 -> 0.95301205 | AG18: =AF23 -> 0.95774771
A19: 新豐7線 | B19: 微波主食 | C19: 韓式泡菜豬肉豆腐丼飯 | E19: 50.67 | F19: 1973 | G19: =E19*F19 -> 99971.91 | I19: 17 | J19: 2000 | K19: =J19/I19 -> 117.64706 | L19: 17 | M19: =F19/V19*60 -> 1909.3548 | N19: =M19/L19 -> 112.31499 | O19: =L19-I19 -> 0 | P19: =N19-K19 -> -5.3320683 | Q19: =N19/K19 -> 0.95467742 | S19: 0.38472222 | T19: 0.42777778 | U19: =IF(S19=TIME(17,0,0),"",(S19-T18)*24*60) -> 5 | V19: =(T19-S19)*24*60 -> 62 | AE19: =M19-J19 -> -90.645161 | AF19: =M19/J19 -> 0.95467742
A20: 新豐7線 | B20: 微波主食 | C20: 鐵板滑蛋炸豬排丼 | E20: 57.73 | F20: 1886 | G20: =E20*F20 -> 108878.78 | I20: 14 | J20: 2000 | K20: =J20/I20 -> 142.85714 | L20: 14 | M20: =F20/V20*60 -> 1917.9661 | N20: =M20/L20 -> 136.99758 | O20: =L20-I20 -> 0 | P20: =N20-K20 -> -5.8595642 | Q20: =N20/K20 -> 0.95898305 | S20: 0.43194444 | T20: 0.47291667 | U20: =IF(S20=TIME(17,0,0),"",(S20-T19)*24*60) -> 6 | V20: =(T20-S20)*24*60 -> 59 | AE20: =M20-J20 -> -82.033898 | AF20: =M20/J20 -> 0.95898305
A21: 新豐7線 | B21: 微波主食 | C21: 二配川味麻婆燒豆腐燴飯 | E21: 50.49 | F21: 1697 | G21: =E21*F21 -> 85681.53 | I21: 15 | J21: 2000 | K21: =J21/I21 -> 133.33333 | L21: 15 | M21: =F21/V21*60 -> 1921.1321 | N21: =M21/L21 -> 128.07547 | O21: =L21-I21 -> 0 | P21: =N21-K21 -> -5.2578616 | Q21: =N21/K21 -> 0.96056604 | S21: 0.70833333 | T21: 0.74513889 | U21: =IF(S21=TIME(17,0,0),"",(S21-T20)*24*60) | V21: =(T21-S21)*24*60 -> 53 | AE21: =M21-J21 -> -78.867925 | AF21: =M21/J21 -> 0.96056604
A22: 新豐7線 | B22: 微波主食 | C22: 二配金咖哩濃厚辛口咖哩飯 | E22: 50.98 | F22: 1923 | G22: =E22*F22 -> 98034.54 | I22: 16 | J22: 2000 | K22: =J22/I22 -> 125 | L22: 16 | M22: =F22/V22*60 -> 1923 | N22: =M22/L22 -> 120.1875 | O22: =L22-I22 -> 0 | P22: =N22-K22 -> -4.8125 | Q22: =N22/K22 -> 0.9615 | S22: 0.75069444 | T22: 0.79236111 | U22: =IF(S22=TIME(17,0,0),"",(S22-T21)*24*60) -> 8 | V22: =(T22-S22)*24*60 -> 60 | AE22: =M22-J22 -> -77 | AF22: =M22/J22 -> 0.9615
A23: 新豐7線 | B23: 平均 | I23: 16.2 | J23: 2000 | K23: =J23/I23 -> 123.45679 | L23: 16.2 | M23: =AVERAGE(M18:M22) -> 1915.4954 | N23: =M23/L23 -> 118.24046 | O23: =L23-I23 -> 0 | P23: =N23-K23 -> -5.2163319 | Q23: =N23/K23 -> 0.95774771 | Y23: =SUM(Y18:Y22) -> 0 | Z23: =SUM(Z18:Z22) -> 0 | AC23: 5 | AD23: =SUM(AD18:AD22) -> 0 | AE23: =M23-J23 -> -84.504578 | AF23: =M23/J23 -> 0.95774771
A24: 新豐8線 | B24: 三明治 | C24: 紐奧良風味烤雞鮮蔬三明治 | E24: 31.29 | F24: 7000 | G24: =E24*F24 -> 219030 | H24: 2 | I24: 18 | J24: 2400 | K24: =J24/I24 -> 133.33333 | L24: 18 | M24: =F24/V24*60 -> 2282.6087 | N24: =M24/L24 -> 126.81159 | O24: =L24-I24 -> 0 | P24: =N24-K24 -> -6.5217391 | Q24: =N24/K24 -> 0.95108696 | R24: =Q31 -> 0.95377274 | S24: 0.083333333 | T24: 0.21111111 | V24: =(T24-S24)*24*60 -> 184 | W24: =T24 -> 0.21111111 | X24: =S25 -> 0.23263889 | AC24: 7 | AE24: =M24-J24 -> -117.3913 | AF24: =M24/J24 -> 0.95108696 | AG24: =AF31 -> 0.95377274
A25: 新豐8線 | B25: 三明治 | C25: 經典總匯三明治 | E25: 26.2 | F25: 3600 | G25: =E25*F25 -> 94320 | H25: 2 | I25: 20 | J25: 2400 | K25: =J25/I25 -> 120 | L25: 20 | M25: =F25/V25*60 -> 2297.8723 | N25: =M25/L25 -> 114.89362 | O25: =L25-I25 -> 0 | P25: =N25-K25 -> -5.106383 | Q25: =N25/K25 -> 0.95744681 | S25: 0.23263889 | T25: 0.29791667 | U25: =(S25-T24)*24*60 -> 31 | V25: =(T25-S25)*24*60 -> 94 | AE25: =M25-J25 -> -102.12766 | AF25: =M25/J25 -> 0.95744681
A26: 新豐8線 | B26: 三明治 | C26: 醬燒烤雞三明治(115年) | E26: 26.37 | F26: 5700 | G26: =E26*F26 -> 150309 | H26: 2 | I26: 19 | J26: 2400 | K26: =J26/I26 -> 126.31579 | L26: 19 | M26: =F26/V26*60 -> 2295.302 | N26: =M26/L26 -> 120.80537 | O26: =L26-I26 -> 0 | P26: =N26-K26 -> -5.5104203 | Q26: =N26/K26 -> 0.95637584 | S26: 0.30208333 | T26: 0.40555556 | U26: =(S26-T25)*24*60 -> 6 | V26: =(T26-S26)*24*60 -> 149 | AE26: =M26-J26 -> -104.69799 | AF26: =M26/J26 -> 0.95637584
A27: 新豐8線 | B27: 三明治 | C27: 雞蛋沙拉三明治(114年) | E27: 25.99 | F27: 4911 | G27: =E27*F27 -> 127636.89 | I27: 14 | J27: 2400 | K27: =J27/I27 -> 171.42857 | L27: 14 | M27: =F27/V27*60 -> 2284.186 | N27: =M27/L27 -> 163.15615 | O27: =L27-I27 -> 0 | P27: =N27-K27 -> -8.2724252 | Q27: =N27/K27 -> 0.95174419 | S27: 0.41111111 | T27: 0.50069444 | U27: =(S27-T26)*24*60 -> 8 | V27: =(T27-S27)*24*60 -> 129 | W27: =T27 -> 0.50069444 | X27: =S28 -> 0.54305556 | AE27: =M27-J27 -> -115.81395 | AF27: =M27/J27 -> 0.95174419
A28: 新豐8線 | B28: 三明治 | C28: 醬燒烤雞三明治(115年) | E28: 26.37 | F28: 4003 | G28: =E28*F28 -> 105559.11 | I28: 19 | J28: 2400 | K28: =J28/I28 -> 126.31579 | L28: 19 | M28: =F28/V28*60 -> 2287.4286 | N28: =M28/L28 -> 120.39098 | O28: =L28-I28 -> 0 | P28: =N28-K28 -> -5.924812 | Q28: =N28/K28 -> 0.95309524 | S28: 0.54305556 | T28: 0.61597222 | U28: =(S28-T27)*24*60 -> 61 | V28: =(T28-S28)*24*60 -> 105 | AE28: =M28-J28 -> -112.57143 | AF28: =M28/J28 -> 0.95309524
A29: 新豐8線 | B29: 三明治 | C29: 紐奧良風味烤雞鮮蔬三明治 | E29: 31.29 | F29: 4616 | G29: =E29*F29 -> 144434.64 | I29: 18 | J29: 2400 | K29: =J29/I29 -> 133.33333 | L29: 18 | M29: =F29/V29*60 -> 2288.9256 | N29: =M29/L29 -> 127.16253 | O29: =L29-I29 -> 0 | P29: =N29-K29 -> -6.1707989 | Q29: =N29/K29 -> 0.95371901 | S29: 0.62083333 | T29: 0.70486111 | U29: =(S29-T28)*24*60 -> 7 | V29: =(T29-S29)*24*60 -> 121 | AE29: =M29-J29 -> -111.07438 | AF29: =M29/J29 -> 0.95371901
A30: 新豐8線 | B30: 三明治 | C30: 經典總匯三明治 | E30: 26.2 | F30: 2592 | G30: =E30*F30 -> 67910.4 | I30: 20 | J30: 2400 | K30: =J30/I30 -> 120 | L30: 20 | M30: =F30/V30*60 -> 2287.0588 | N30: =M30/L30 -> 114.35294 | O30: =L30-I30 -> 0 | P30: =N30-K30 -> -5.6470588 | Q30: =N30/K30 -> 0.95294118 | S30: 0.71041667 | T30: 0.75763889 | U30: =(S30-T29)*24*60 -> 8 | V30: =(T30-S30)*24*60 -> 68 | AE30: =M30-J30 -> -112.94118 | AF30: =M30/J30 -> 0.95294118
A31: 新豐8線 | B31: 平均 | I31: 18.285714 | J31: 2400 | K31: =J31/I31 -> 131.25 | L31: 18.285714 | M31: =AVERAGE(M24:M30) -> 2289.0546 | N31: =M31/L31 -> 125.18267 | O31: =L31-I31 -> 0 | P31: =N31-K31 -> -6.0673273 | Q31: =N31/K31 -> 0.95377274 | Y31: =SUM(Y24:Y30) -> 0 | Z31: =SUM(Z24:Z30) -> 0 | AC31: 7 | AD31: =SUM(AD24:AD30) -> 0 | AE31: =M31-J31 -> -110.94541 | AF31: =M31/J31 -> 0.95377274
A32: 新豐9線 | B32: 三明治 | C32: 肉鬆火腿三明治(115年) | E32: 20.36 | F32: 4300 | G32: =E32*F32 -> 87548 | H32: 2 | I32: 18 | J32: 2400 | K32: =J32/I32 -> 133.33333 | L32: 18 | M32: =F32/V32*60 -> 2283.1858 | N32: =M32/L32 -> 126.84366 | O32: =L32-I32 -> 0 | P32: =N32-K32 -> -6.4896755 | Q32: =N32/K32 -> 0.95132743 | R32: =Q40 -> 0.95539023 | S32: 0.083333333 | T32: 0.16180556 | V32: =(T32-S32)*24*60 -> 113 | W32: =T32 -> 0.16180556 | X32: =S33 -> 0.18055556 | AC32: 8 | AE32: =M32-J32 -> -116.81416 | AF32: =M32/J32 -> 0.95132743 | AG32: =AF40 -> 0.95539023
A33: 新豐9線 | B33: 三明治 | C33: 經典火腿玉米蛋三明治 | E33: 24.43 | F33: 4300 | G33: =E33*F33 -> 105049 | H33: 2 | I33: 14 | J33: 2400 | K33: =J33/I33 -> 171.42857 | L33: 14 | M33: =F33/V33*60 -> 2283.1858 | N33: =M33/L33 -> 163.0847 | O33: =L33-I33 -> 0 | P33: =N33-K33 -> -8.3438685 | Q33: =N33/K33 -> 0.95132743 | S33: 0.18055556 | T33: 0.25902778 | U33: =(S33-T32)*24*60 -> 27 | V33: =(T33-S33)*24*60 -> 113 | AE33: =M33-J33 -> -116.81416 | AF33: =M33/J33 -> 0.95132743
A34: 新豐9線 | B34: 三明治 | C34: 好多菜三明治(114年) | E34: 25.98 | F34: 3418 | G34: =E34*F34 -> 88799.64 | I34: 21 | J34: 2400 | K34: =J34/I34 -> 114.28571 | L34: 21 | M34: =F34/V34*60 -> 2304.2697 | N34: =M34/L34 -> 109.72713 | O34: =L34-I34 -> 0 | P34: =N34-K34 -> -4.5585875 | Q34: =N34/K34 -> 0.96011236 | S34: 0.26458333 | T34: 0.32638889 | U34: =(S34-T33)*24*60 -> 8 | V34: =(T34-S34)*24*60 -> 89 | AE34: =M34-J34 -> -95.730337 | AF34: =M34/J34 -> 0.96011236
A35: 新豐9線 | B35: 三明治 | C35: 好多蛋三明治 | E35: 34.1 | F35: 4300 | G35: =E35*F35 -> 146630 | H35: 2 | I35: 17 | J35: 1600 | K35: =J35/I35 -> 94.117647 | L35: 17 | M35: =F35/V35*60 -> 1526.6272 | N35: =M35/L35 -> 89.801601 | O35: =L35-I35 -> 0 | P35: =N35-K35 -> -4.3160459 | Q35: =N35/K35 -> 0.95414201 | S35: 0.32986111 | T35: 0.44722222 | U35: =(S35-T34)*24*60 -> 5 | V35: =(T35-S35)*24*60 -> 169 | AE35: =M35-J35 -> -73.372781 | AF35: =M35/J35 -> 0.95414201
A36: 新豐9線 | B36: 三明治 | C36: 香鬆起司蛋三明治(114年) | E36: 20.2 | F36: 2279 | G36: =E36*F36 -> 46035.8 | I36: 15 | J36: 2400 | K36: =J36/I36 -> 160 | L36: 15 | M36: =F36/V36*60 -> 2317.6271 | N36: =M36/L36 -> 154.50847 | O36: =L36-I36 -> 0 | P36: =N36-K36 -> -5.4915254 | Q36: =N36/K36 -> 0.96567797 | S36: 0.45138889 | T36: 0.49236111 | U36: =(S36-T35)*24*60 -> 6 | V36: =(T36-S36)*24*60 -> 59 | W36: =T36 -> 0.49236111 | X36: =S37 -> 0.53194444 | AE36: =M36-J36 -> -82.372881 | AF36: =M36/J36 -> 0.96567797
A37: 新豐9線 | B37: 三明治 | C37: 好多蛋三明治 | E37: 34.1 | F37: 3197 | G37: =E37*F37 -> 109017.7 | I37: 17 | J37: 1600 | K37: =J37/I37 -> 94.117647 | L37: 17 | M37: =F37/V37*60 -> 1522.381 | N37: =M37/L37 -> 89.551821 | O37: =L37-I37 -> 0 | P37: =N37-K37 -> -4.5658263 | Q37: =N37/K37 -> 0.9514881 | S37: 0.53194444 | T37: 0.61944444 | U37: =(S37-T36)*24*60 -> 57 | V37: =(T37-S37)*24*60 -> 126 | AE37: =M37-J37 -> -77.619048 | AF37: =M37/J37 -> 0.9514881
A38: 新豐9線 | B38: 三明治 | C38: 肉鬆火腿三明治(115年) | E38: 20.36 | F38: 3284 | G38: =E38*F38 -> 66862.24 | I38: 18 | J38: 2400 | K38: =J38/I38 -> 133.33333 | L38: 18 | M38: =F38/V38*60 -> 2291.1628 | N38: =M38/L38 -> 127.28682 | O38: =L38-I38 -> 0 | P38: =N38-K38 -> -6.0465116 | Q38: =N38/K38 -> 0.95465116 | S38: 0.625 | T38: 0.68472222 | U38: =(S38-T37)*24*60 -> 8 | V38: =(T38-S38)*24*60 -> 86 | AE38: =M38-J38 -> -108.83721 | AF38: =M38/J38 -> 0.95465116
A39: 新豐9線 | B39: 三明治 | C39: 經典火腿玉米蛋三明治 | E39: 24.43 | F39: 3201 | G39: =E39*F39 -> 78200.43 | I39: 14 | J39: 2400 | K39: =J39/I39 -> 171.42857 | L39: 14 | M39: =F39/V39*60 -> 2286.4286 | N39: =M39/L39 -> 163.31633 | O39: =L39-I39 -> 0 | P39: =N39-K39 -> -8.1122449 | Q39: =N39/K39 -> 0.95267857 | S39: 0.68888889 | T39: 0.74722222 | U39: =(S39-T38)*24*60 -> 6 | V39: =(T39-S39)*24*60 -> 84 | AE39: =M39-J39 -> -113.57143 | AF39: =M39/J39 -> 0.95267857
A40: 新豐9線 | B40: 平均 | I40: 16.75 | J40: 2200 | K40: =J40/I40 -> 131.34328 | L40: 16.75 | M40: =AVERAGE(M32:M39) -> 2101.8585 | N40: =M40/L40 -> 125.48409 | O40: =L40-I40 -> 0 | P40: =N40-K40 -> -5.8591941 | Q40: =N40/K40 -> 0.95539023 | Y40: =SUM(Y32:Y39) -> 0 | Z40: =SUM(Z32:Z39) -> 0 | AC40: 8 | AD40: =SUM(AD32:AD39) -> 0 | AE40: =M40-J40 -> -98.1415 | AF40: =M40/J40 -> 0.95539023
...

Sheet 0428
B1: 屏榮 新豐廠組合室生產人時性分析
B3: 日期 | C3: =TEXT('0428 4度C'!A2,"yyyy.mm.ddaaaa") -> 2026.04.28星期二 | E3: 訂單量 | F3: ='0428 4度C'!D1 -> 223497 | H3: 營業額 | I3: ='0428 4度C'!F1 -> 7569445.1
B4: 人時性 | C4: 項目 | E4: ➀ | G4: ➁ | I4: ➂ | K4: 異常停線 | M4: 短暫停線
C5: 組合室 | E5: 全溫層 | G5: 4度C-各編組展開 | I5: ③三明治-各編組展開 | K5: 合計次數 | L5: 時間 | M5: 合計次數 | N5: 設備次數
C6: 排關平均 | E6: =AVERAGE(D13:M13) -> 149.98611 | F6: =AVERAGE(D31:O31,D13:J13) -> 157.5994 | G6: =AVERAGE(D13:J13) -> 157.5994 | I6: =AVERAGE(K13:M13) -> 132.22177 | K6: ='0428 4度C'!Y2 -> 0 | L6: ='0428 4度C'!Z2 -> 0 | M6: ='0428 4度C'!AC2 -> 62 | N6: ='0428 4度C'!AD2 -> 0
C7: 實績平均 | E7: =AVERAGE(D14:M14) -> 143.71983 | F7: =AVERAGE(D32:O32,D14:J14) -> 151.19283 | G7: =AVERAGE(D14:J14) -> 151.19283 | I7: =AVERAGE(K14:M14) -> 126.28281
C8: 達成率平均 | E8: =AVERAGE(D15:M15) -> 0.95767833 | F8: =AVERAGE(D15:J15,D33:O33) -> 0.95887797 | G8: =AVERAGE(D15:J15) -> 0.95887797 | I8: =AVERAGE(K15:M15) -> 0.95487919
K9: ※現行日本鮮食廠以達成率80%為基本(即為現行KPI)
B10: 溫層 | D10: ➁4度C-各編組展開 | K10: ③三明治-各編組展開
B11: 編組 | D11: 1 | E11: 2 | F11: 3 | G11: 4 | H11: 5 | I11: 6 | J11: 7 | K11: 1 | L11: 2 | M11: 3
D12: 新豐6線 | E12: 新豐2線 | F12: 新豐5線 | G12: 新豐7線 | H12: 新豐3線 | I12: 新豐1線 | J12: 新豐10線 | K12: 新豐8線 | L12: 新豐9線 | M12: 新豐4線
B13: 人時性 | C13: 排關 | D13: =SUMIFS('0428 4度C'!$K:$K,'0428 4度C'!$A:$A,"新豐6線",'0428 4度C'!$B:$B,"平均") -> 119.40299 | E13: =SUMIFS('0428 4度C'!$K:$K,'0428 4度C'!$A:$A,"新豐2線",'0428 4度C'!$B:$B,"平均") -> 83.333333 | F13: =SUMIFS('0428 4度C'!$K:$K,'0428 4度C'!$A:$A,"新豐5線",'0428 4度C'!$B:$B,"平均") -> 128.37838 | G13: =SUMIFS('0428 4度C'!$K:$K,'0428 4度C'!$A:$A,"新豐7線",'0428 4度C'!$B:$B,"平均") -> 121.73913 | H13: =SUMIFS('0428 4度C'!$K:$K,'0428 4度C'!$A:$A,"新豐3線",'0428 4度C'!$B:$B,"平均") -> 232.14286 | I13: =SUMIFS('0428 4度C'!$K:$K,'0428 4度C'!$A:$A,"新豐1線",'0428 4度C'!$B:$B,"平均") -> 102.40964 | J13: =SUMIFS('0428 4度C'!$K:$K,'0428 4度C'!$A:$A,"新豐10線",'0428 4度C'!$B:$B,"平均") -> 315.78947 | K13: =SUMIFS('0428 4度C'!$K:$K,'0428 4度C'!$A:$A,"新豐8線",'0428 4度C'!$B:$B,"平均") -> 132.11009 | L13: =SUMIFS('0428 4度C'!$K:$K,'0428 4度C'!$A:$A,"新豐9線",'0428 4度C'!$B:$B,"平均") -> 111.82796 | M13: =SUMIFS('0428 4度C'!$K:$K,'0428 4度C'!$A:$A,"新豐4線",'0428 4度C'!$B:$B,"平均") -> 152.72727
C14: 實績 | D14: =SUMIFS('0428 4度C'!$N:$N,'0428 4度C'!$A:$A,"新豐6線",'0428 4度C'!$B:$B,"平均") -> 115.06372 | E14: =SUMIFS('0428 4度C'!$N:$N,'0428 4度C'!$A:$A,"新豐2線",'0428 4度C'!$B:$B,"平均") -> 79.651332 | F14: =SUMIFS('0428 4度C'!$N:$N,'0428 4度C'!$A:$A,"新豐5線",'0428 4度C'!$B:$B,"平均") -> 122.81704 | G14: =SUMIFS('0428 4度C'!$N:$N,'0428 4度C'!$A:$A,"新豐7線",'0428 4度C'!$B:$B,"平均") -> 116.32189 | H14: =SUMIFS('0428 4度C'!$N:$N,'0428 4度C'!$A:$A,"新豐3線",'0428 4度C'!$B:$B,"平均") -> 221.73744 | I14: =SUMIFS('0428 4度C'!$N:$N,'0428 4度C'!$A:$A,"新豐1線",'0428 4度C'!$B:$B,"平均") -> 98.500706 | J14: =SUMIFS('0428 4度C'!$N:$N,'0428 4度C'!$A:$A,"新豐10線",'0428 4度C'!$B:$B,"平均") -> 304.2577 | K14: =SUMIFS('0428 4度C'!$N:$N,'0428 4度C'!$A:$A,"新豐8線",'0428 4度C'!$B:$B,"平均") -> 126.21782 | L14: =SUMIFS('0428 4度C'!$N:$N,'0428 4度C'!$A:$A,"新豐9線",'0428 4度C'!$B:$B,"平均") -> 106.53151 | M14: =SUMIFS('0428 4度C'!$N:$N,'0428 4度C'!$A:$A,"新豐4線",'0428 4度C'!$B:$B,"平均") -> 146.0991
C15: 達成率 | D15: =D14/D13 -> 0.96365864 | E15: =E14/E13 -> 0.95581598 | F15: =F14/F13 -> 0.95668012 | G15: =G14/G13 -> 0.9555012 | H15: =H14/H13 -> 0.95517665 | I15: =I14/I13 -> 0.96183042 | J15: =J14/J13 -> 0.96348273 | K15: =K14/K13 -> 0.95539878 | ... M15: =M14/M13 -> 0.95660124
B16: 作業 時間 | C16: 開始 | D16: =VLOOKUP("新豐6線",'0428 4度C'!$A:$T,19,0) -> 0.70833333 | E16: =VLOOKUP("新豐2線",'0428 4度C'!$A:$T,19,0) -> 0.20833333 | F16: =VLOOKUP("新豐5線",'0428 4度C'!$A:$T,19,0) -> 0.083333333 | G16: =VLOOKUP("新豐7線",'0428 4度C'!$A:$T,19,0) -> 0.20833333 | H16: =VLOOKUP("新豐3線",'0428 4度C'!$A:$T,19,0) -> 0.083333333 | I16: =VLOOKUP("新豐1線",'0428 4度C'!$A:$T,19,0) -> 0.20833333 | J16: =VLOOKUP("新豐10線",'0428 4度C'!$A:$T,19,0) -> 0.20833333 | K16: =VLOOKUP("新豐8線",'0428 4度C'!$A:$T,19,0) -> 0.083333333 | L16: =VLOOKUP("新豐9線",'0428 4度C'!$A:$T,19,0) -> 0.083333333 | M16: =VLOOKUP("新豐4線",'0428 4度C'!$A:$T,19,0) -> 0.083333333
C17: 結束 | D17: =LOOKUP(2,1/(('0428 4度C'!$A:$A="新豐6線")*('0428 4度C'!$T:$T<>"")),'0428 4度C'!$T:$T) -> 0.84444444 | E17: =LOOKUP(2,1/(('0428 4度C'!$A:$A="新豐2線")*('0428 4度C'!$T:$T<>"")),'0428 4度C'!$T:$T) -> 0.64305556 | F17: =LOOKUP(2,1/(('0428 4度C'!$A:$A="新豐5線")*('0428 4度C'!$T:$T<>"")),'0428 4度C'!$T:$T) -> 0.84027778 | G17: =LOOKUP(2,1/(('0428 4度C'!$A:$A="新豐7線")*('0428 4度C'!$T:$T<>"")),'0428 4度C'!$T:$T) -> 0.83263889 | H17: =LOOKUP(2,1/(('0428 4度C'!$A:$A="新豐3線")*('0428 4度C'!$T:$T<>"")),'0428 4度C'!$T:$T) -> 0.64583333 | I17: =LOOKUP(2,1/(('0428 4度C'!$A:$A="新豐1線")*('0428 4度C'!$T:$T<>"")),'0428 4度C'!$T:$T) -> 0.81944444 | J17: =LOOKUP(2,1/(('0428 4度C'!$A:$A="新豐10線")*('0428 4度C'!$T:$T<>"")),'0428 4度C'!$T:$T) -> 0.44861111 | K17: =LOOKUP(2,1/(('0428 4度C'!$A:$A="新豐8線")*('0428 4度C'!$T:$T<>"")),'0428 4度C'!$T:$T) -> 0.74722222 | L17: =LOOKUP(2,1/(('0428 4度C'!$A:$A="新豐9線")*('0428 4度C'!$T:$T<>"")),'0428 4度C'!$T:$T) -> 0.75763889 | M17: =LOOKUP(2,1/(('0428 4度C'!$A:$A="新豐4線")*('0428 4度C'!$T:$T<>"")),'0428 4度C'!$T:$T) -> 0.72013889
