Workbook

Sheet 0928
B1: 屏榮 新豐廠組合室生產人時性分析
B3: 日期 | C3: =TEXT('0928 4度C'!A2,"yyyy.mm.ddaaaa") -> 2026.09.28星期一 | E3: 訂單量 | F3: ='0928 4度C'!D1 -> 189843 | H3: 營業額 | I3: ='0928 4度C'!F1 -> 6454757.6
B4: 人時性 | C4: 項目 | E4: ➀ | G4: ➁ | I4: ➂ | K4: 異常停線 | M4: 短暫停線
C5: 組合室 | E5: 全溫層 | G5: 4度C-各編組展開 | I5: ③三明治-各編組展開 | K5: 合計次數 | L5: 時間 | M5: 合計次數 | N5: 設備次數
C6: 排關平均 | E6: =AVERAGE(D13:M13) -> 150.27499 | F6: =AVERAGE(D31:O31,D13:J13) -> 155.4995 | G6: =AVERAGE(D13:J13) -> 155.4995 | I6: =AVERAGE(K13:M13) -> 138.08446 | K6: ='0928 4度C'!Y2 -> 0 | L6: ='0928 4度C'!Z2 -> 0 | M6: ='0928 4度C'!AC2 -> 60 | N6: ='0928 4度C'!AD2 -> 0
C7: 實績平均 | E7: =AVERAGE(D14:M14) -> 144.11362 | F7: =AVERAGE(D32:O32,D14:J14) -> 149.15211 | G7: =AVERAGE(D14:J14) -> 149.15211 | I7: =AVERAGE(K14:M14) -> 132.35717
C8: 達成率平均 | E8: =AVERAGE(D15:M15) -> 0.95879388 | F8: =AVERAGE(D15:J15,D33:O33) -> 0.95893061 | G8: =AVERAGE(D15:J15) -> 0.95893061 | I8: =AVERAGE(K15:M15) -> 0.95847485
K9: ※現行日本鮮食廠以達成率80%為基本(即為現行KPI)
B10: 溫層 | D10: ➁4度C-各編組展開 | K10: ③三明治-各編組展開
B11: 編組 | D11: 1 | E11: 2 | F11: 3 | G11: 4 | H11: 5 | I11: 6 | J11: 7 | K11: 1 | L11: 2 | M11: 3
D12: 新豐6線 | E12: 新豐2線 | F12: 新豐5線 | G12: 新豐7線 | H12: 新豐3線 | I12: 新豐1線 | J12: 新豐10線 | K12: 新豐8線 | L12: 新豐9線 | M12: 新豐4線
B13: 人時性 | C13: 排關 | D13: =SUMIFS('0928 4度C'!$K:$K,'0928 4度C'!$A:$A,"新豐6線",'0928 4度C'!$B:$B,"平均") -> 129.03226 | E13: =SUMIFS('0928 4度C'!$K:$K,'0928 4度C'!$A:$A,"新豐2線",'0928 4度C'!$B:$B,"平均") -> 83.333333 | F13: =SUMIFS('0928 4度C'!$K:$K,'0928 4度C'!$A:$A,"新豐5線",'0928 4度C'!$B:$B,"平均") -> 105 | G13: =SUMIFS('0928 4度C'!$K:$K,'0928 4度C'!$A:$A,"新豐7線",'0928 4度C'!$B:$B,"平均") -> 125 | H13: =SUMIFS('0928 4度C'!$K:$K,'0928 4度C'!$A:$A,"新豐3線",'0928 4度C'!$B:$B,"平均") -> 242.42424 | I13: =SUMIFS('0928 4度C'!$K:$K,'0928 4度C'!$A:$A,"新豐1線",'0928 4度C'!$B:$B,"平均") -> 109.58904 | J13: =SUMIFS('0928 4度C'!$K:$K,'0928 4度C'!$A:$A,"新豐10線",'0928 4度C'!$B:$B,"平均") -> 294.11765 | K13: =SUMIFS('0928 4度C'!$K:$K,'0928 4度C'!$A:$A,"新豐8線",'0928 4度C'!$B:$B,"平均") -> 141.17647 | L13: =SUMIFS('0928 4度C'!$K:$K,'0928 4度C'!$A:$A,"新豐9線",'0928 4度C'!$B:$B,"平均") -> 123.07692 | M13: =SUMIFS('0928 4度C'!$K:$K,'0928 4度C'!$A:$A,"新豐4線",'0928 4度C'!$B:$B,"平均") -> 150
C14: 實績 | D14: =SUMIFS('0928 4度C'!$N:$N,'0928 4度C'!$A:$A,"新豐6線",'0928 4度C'!$B:$B,"平均") -> 124.09133 | E14: =SUMIFS('0928 4度C'!$N:$N,'0928 4度C'!$A:$A,"新豐2線",'0928 4度C'!$B:$B,"平均") -> 79.361316 | F14: =SUMIFS('0928 4度C'!$N:$N,'0928 4度C'!$A:$A,"新豐5線",'0928 4度C'!$B:$B,"平均") -> 100.78582 | G14: =SUMIFS('0928 4度C'!$N:$N,'0928 4度C'!$A:$A,"新豐7線",'0928 4度C'!$B:$B,"平均") -> 120.16999 | H14: =SUMIFS('0928 4度C'!$N:$N,'0928 4度C'!$A:$A,"新豐3線",'0928 4度C'!$B:$B,"平均") -> 231.84101 | I14: =SUMIFS('0928 4度C'!$N:$N,'0928 4度C'!$A:$A,"新豐1線",'0928 4度C'!$B:$B,"平均") -> 105.21044 | J14: =SUMIFS('0928 4度C'!$N:$N,'0928 4度C'!$A:$A,"新豐10線",'0928 4度C'!$B:$B,"平均") -> 282.60484 | K14: =SUMIFS('0928 4度C'!$N:$N,'0928 4度C'!$A:$A,"新豐8線",'0928 4度C'!$B:$B,"平均") -> 134.84569 | L14: =SUMIFS('0928 4度C'!$N:$N,'0928 4度C'!$A:$A,"新豐9線",'0928 4度C'!$B:$B,"平均") -> 118.00834 | M14: =SUMIFS('0928 4度C'!$N:$N,'0928 4度C'!$A:$A,"新豐4線",'0928 4度C'!$B:$B,"平均") -> 144.21747
C15: 達成率 | D15: =D14/D13 -> 0.96170777 | E15: =E14/E13 -> 0.95233579 | F15: =F14/F13 -> 0.95986496 | G15: =G14/G13 -> 0.96135993 | H15: =H14/H13 -> 0.95634415 | I15: =I14/I13 -> 0.96004522 | J15: =J14/J13 -> 0.96085646 | K15: =K14/K13 -> 0.95515697 | ... M15: =M14/M13 -> 0.96144978
B16: 作業 時間 | C16: 開始 | D16: =VLOOKUP("新豐6線",'0928 4度C'!$A:$T,19,0) -> 0.70833333 | E16: =VLOOKUP("新豐2線",'0928 4度C'!$A:$T,19,0) -> 0.083333333 | F16: =VLOOKUP("新豐5線",'0928 4度C'!$A:$T,19,0) -> 0.20833333 | G16: =VLOOKUP("新豐7線",'0928 4度C'!$A:$T,19,0) -> 0.25 | H16: =VLOOKUP("新豐3線",'0928 4度C'!$A:$T,19,0) -> 0.20833333 | I16: =VLOOKUP("新豐1線",'0928 4度C'!$A:$T,19,0) -> 0.20833333 | J16: =VLOOKUP("新豐10線",'0928 4度C'!$A:$T,19,0) -> 0.20833333 | K16: =VLOOKUP("新豐8線",'0928 4度C'!$A:$T,19,0) -> 0.083333333 | L16: =VLOOKUP("新豐9線",'0928 4度C'!$A:$T,19,0) -> 0.083333333 | M16: =VLOOKUP("新豐4線",'0928 4度C'!$A:$T,19,0) -> 0.083333333
C17: 結束 | D17: =LOOKUP(2,1/(('0928 4度C'!$A:$A="新豐6線")*('0928 4度C'!$T:$T<>"")),'0928 4度C'!$T:$T) -> 0.91666667 | E17: =LOOKUP(2,1/(('0928 4度C'!$A:$A="新豐2線")*('0928 4度C'!$T:$T<>"")),'0928 4度C'!$T:$T) -> 0.48541667 | F17: =LOOKUP(2,1/(('0928 4度C'!$A:$A="新豐5線")*('0928 4度C'!$T:$T<>"")),'0928 4度C'!$T:$T) -> 0.83680556 | G17: =LOOKUP(2,1/(('0928 4度C'!$A:$A="新豐7線")*('0928 4度C'!$T:$T<>"")),'0928 4度C'!$T:$T) -> 0.91805556 | H17: =LOOKUP(2,1/(('0928 4度C'!$A:$A="新豐3線")*('0928 4度C'!$T:$T<>"")),'0928 4度C'!$T:$T) -> 0.49791667 | I17: =LOOKUP(2,1/(('0928 4度C'!$A:$A="新豐1線")*('0928 4度C'!$T:$T<>"")),'0928 4度C'!$T:$T) -> 0.85416667 | J17: =LOOKUP(2,1/(('0928 4度C'!$A:$A="新豐10線")*('0928 4度C'!$T:$T<>"")),'0928 4度C'!$T:$T) -> 0.4875 | K17: =LOOKUP(2,1/(('0928 4度C'!$A:$A="新豐8線")*('0928 4度C'!$T:$T<>"")),'0928 4度C'!$T:$T) -> 0.74027778 | L17: =LOOKUP(2,1/(('0928 4度C'!$A:$A="新豐9線")*('0928 4度C'!$T:$T<>"")),'0928 4度C'!$T:$T) -> 0.75902778 | M17: =LOOKUP(2,1/(('0928 4度C'!$A:$A="新豐4線")*('0928 4度C'!$T:$T<>"")),'0928 4度C'!$T:$T) -> 0.73402778
B18: 產線異常 (5分鐘以上) | C18: 次數 | D18: =SUMIFS('0928 4度C'!$Y:$Y,'0928 4度C'!$A:$A,"新豐6線",'0928 4度C'!$B:$B,"平均") -> 0 | E18: =SUMIFS('0928 4度C'!$Y:$Y,'0928 4度C'!$A:$A,"新豐2線",'0928 4度C'!$B:$B,"平均") -> 0 | F18: =SUMIFS('0928 4度C'!$Y:$Y,'0928 4度C'!$A:$A,"新豐5線",'0928 4度C'!$B:$B,"平均") -> 0 | G18: =SUMIFS('0928 4度C'!$Y:$Y,'0928 4度C'!$A:$A,"新豐7線",'0928 4度C'!$B:$B,"平均") -> 0 | H18: =SUMIFS('0928 4度C'!$Y:$Y,'0928 4度C'!$A:$A,"新豐3線",'0928 4度C'!$B:$B,"平均") -> 0 | I18: =SUMIFS('0928 4度C'!$Y:$Y,'0928 4度C'!$A:$A,"新豐1線",'0928 4度C'!$B:$B,"平均") -> 0 | J18: =SUMIFS('0928 4度C'!$Y:$Y,'0928 4度C'!$A:$A,"新豐10線",'0928 4度C'!$B:$B,"平均") -> 0 | K18: =SUMIFS('0928 4度C'!$Y:$Y,'0928 4度C'!$A:$A,"新豐8線",'0928 4度C'!$B:$B,"平均") -> 0 | L18: =SUMIFS('0928 4度C'!$Y:$Y,'0928 4度C'!$A:$A,"新豐9線",'0928 4度C'!$B:$B,"平均") -> 0 | M18: =SUMIFS('0928 4度C'!$Y:$Y,'0928 4度C'!$A:$A,"新豐4線",'0928 4度C'!$B:$B,"平均") -> 0
C19: 時間/分 | D19: =SUMIFS('0928 4度C'!$Z:$Z,'0928 4度C'!$A:$A,"新豐6線",'0928 4度C'!$B:$B,"平均") -> 0 | E19: =SUMIFS('0928 4度C'!$Z:$Z,'0928 4度C'!$A:$A,"新豐2線",'0928 4度C'!$B:$B,"平均") -> 0 | F19: =SUMIFS('0928 4度C'!$Z:$Z,'0928 4度C'!$A:$A,"新豐5線",'0928 4度C'!$B:$B,"平均") -> 0 | G19: =SUMIFS('0928 4度C'!$Z:$Z,'0928 4度C'!$A:$A,"新豐7線",'0928 4度C'!$B:$B,"平均") -> 0 | H19: =SUMIFS('0928 4度C'!$Z:$Z,'0928 4度C'!$A:$A,"新豐3線",'0928 4度C'!$B:$B,"平均") -> 0 | I19: =SUMIFS('0928 4度C'!$Z:$Z,'0928 4度C'!$A:$A,"新豐1線",'0928 4度C'!$B:$B,"平均") -> 0 | J19: =SUMIFS('0928 4度C'!$Z:$Z,'0928 4度C'!$A:$A,"新豐10線",'0928 4度C'!$B:$B,"平均") -> 0 | K19: =SUMIFS('0928 4度C'!$Z:$Z,'0928 4度C'!$A:$A,"新豐8線",'0928 4度C'!$B:$B,"平均") -> 0 | L19: =SUMIFS('0928 4度C'!$Z:$Z,'0928 4度C'!$A:$A,"新豐9線",'0928 4度C'!$B:$B,"平均") -> 0 | M19: =SUMIFS('0928 4度C'!$Z:$Z,'0928 4度C'!$A:$A,"新豐4線",'0928 4度C'!$B:$B,"平均") -> 0
B20: 短暫停線 (5分鐘以下) | C20: 次數 | D20: =SUMIFS('0928 4度C'!$AC:$AC,'0928 4度C'!$A:$A,"新豐6線",'0928 4度C'!$B:$B,"平均") -> 4 | E20: =SUMIFS('0928 4度C'!$AC:$AC,'0928 4度C'!$A:$A,"新豐2線",'0928 4度C'!$B:$B,"平均") -> 2 | F20: =SUMIFS('0928 4度C'!$AC:$AC,'0928 4度C'!$A:$A,"新豐5線",'0928 4度C'!$B:$B,"平均") -> 6 | G20: =SUMIFS('0928 4度C'!$AC:$AC,'0928 4度C'!$A:$A,"新豐7線",'0928 4度C'!$B:$B,"平均") -> 7 | H20: =SUMIFS('0928 4度C'!$AC:$AC,'0928 4度C'!$A:$A,"新豐3線",'0928 4度C'!$B:$B,"平均") -> 3 | I20: =SUMIFS('0928 4度C'!$AC:$AC,'0928 4度C'!$A:$A,"新豐1線",'0928 4度C'!$B:$B,"平均") -> 8 | J20: =SUMIFS('0928 4度C'!$AC:$AC,'0928 4度C'!$A:$A,"新豐10線",'0928 4度C'!$B:$B,"平均") -> 5 | K20: =SUMIFS('0928 4度C'!$AC:$AC,'0928 4度C'!$A:$A,"新豐8線",'0928 4度C'!$B:$B,"平均") -> 7 | L20: =SUMIFS('0928 4度C'!$AC:$AC,'0928 4度C'!$A:$A,"新豐9線",'0928 4度C'!$B:$B,"平均") -> 8 | M20: =SUMIFS('0928 4度C'!$AC:$AC,'0928 4度C'!$A:$A,"新豐4線",'0928 4度C'!$B:$B,"平均") -> 10
C21: 設備次數 | D21: =SUMIFS('0928 4度C'!$AD:$AD,'0928 4度C'!$A:$A,"新豐6線",'0928 4度C'!$B:$B,"平均") -> 0 | E21: =SUMIFS('0928 4度C'!$AD:$AD,'0928 4度C'!$A:$A,"新豐2線",'0928 4度C'!$B:$B,"平均") -> 0 | F21: =SUMIFS('0928 4度C'!$AD:$AD,'0928 4度C'!$A:$A,"新豐5線",'0928 4度C'!$B:$B,"平均") -> 0 | G21: =SUMIFS('0928 4度C'!$AD:$AD,'0928 4度C'!$A:$A,"新豐7線",'0928 4度C'!$B:$B,"平均") -> 0 | H21: =SUMIFS('0928 4度C'!$AD:$AD,'0928 4度C'!$A:$A,"新豐3線",'0928 4度C'!$B:$B,"平均") -> 0 | I21: =SUMIFS('0928 4度C'!$AD:$AD,'0928 4度C'!$A:$A,"新豐1線",'0928 4度C'!$B:$B,"平均") -> 0 | J21: =SUMIFS('0928 4度C'!$AD:$AD,'0928 4度C'!$A:$A,"新豐10線",'0928 4度C'!$B:$B,"平均") -> 0 | K21: =SUMIFS('0928 4度C'!$AD:$AD,'0928 4度C'!$A:$A,"新豐8線",'0928 4度C'!$B:$B,"平均") -> 0 | L21: =SUMIFS('0928 4度C'!$AD:$AD,'0928 4度C'!$A:$A,"新豐9線",'0928 4度C'!$B:$B,"平均") -> 0 | M21: =SUMIFS('0928 4度C'!$AD:$AD,'0928 4度C'!$A:$A,"新豐4線",'0928 4度C'!$B:$B,"平均") -> 0
B22: 配置人數 | D22: =SUMIFS('0928 4度C'!$I:$I,'0928 4度C'!$A:$A,"新豐6線",'0928 4度C'!$B:$B,"平均") -> 15.5 | E22: =SUMIFS('0928 4度C'!$I:$I,'0928 4度C'!$A:$A,"新豐2線",'0928 4度C'!$B:$B,"平均") -> 18 | F22: =SUMIFS('0928 4度C'!$I:$I,'0928 4度C'!$A:$A,"新豐5線",'0928 4度C'!$B:$B,"平均") -> 16.666667 | G22: =SUMIFS('0928 4度C'!$I:$I,'0928 4度C'!$A:$A,"新豐7線",'0928 4度C'!$B:$B,"平均") -> 16 | H22: =SUMIFS('0928 4度C'!$I:$I,'0928 4度C'!$A:$A,"新豐3線",'0928 4度C'!$B:$B,"平均") -> 11 | I22: =SUMIFS('0928 4度C'!$I:$I,'0928 4度C'!$A:$A,"新豐1線",'0928 4度C'!$B:$B,"平均") -> 18.25 | J22: =SUMIFS('0928 4度C'!$I:$I,'0928 4度C'!$A:$A,"新豐10線",'0928 4度C'!$B:$B,"平均") -> 10.2 | K22: =SUMIFS('0928 4度C'!$I:$I,'0928 4度C'!$A:$A,"新豐8線",'0928 4度C'!$B:$B,"平均") -> 17 | L22: =SUMIFS('0928 4度C'!$I:$I,'0928 4度C'!$A:$A,"新豐9線",'0928 4度C'!$B:$B,"平均") -> 17.875 | M22: =SUMIFS('0928 4度C'!$I:$I,'0928 4度C'!$A:$A,"新豐4線",'0928 4度C'!$B:$B,"平均") -> 16
B23: 主要應用設備 | D23: ET-55 | E23: 熱縮爐 | F23: L型包裝機 | G23: L型包裝機 | H23: 伺服包裝機 | I23: ET-55 | J23: 伺服包裝機 | K23: 三明治包裝機 | L23: 三明治包裝機 | M23: 三明治包裝機
B24: 次要應用設備 | F24: 圓盤機 | G24: ET-55
B25: 備註 | E25: 握沙拉 | F25: 共用L型包裝機 | H25: 調理麵包 | I25: 炒飯+沙拉 | J25: 調理麵包

Sheet 0928 4度C
A1: 新豐廠四度C日報分析 | C1: 總生產量 | D1: =SUM(F5:F74) -> 189843 | E1: 營業額 | F1: =SUM(G5:G74) -> 6454757.6 | G1: 出勤人數 | H1: =L9+L12+L48+L57+L19+L63+L35+L44+L27+L74 -> 156.49167 | I1: 產線配置圖 | L1: 生產實績 | O1: 人時性差異分析 | S1: 日報登錄 | Y1: 合計 次數 | Z1: 合計 時間/分 | AA1: 產線異常 分析說明(5分鐘以上) | AC1: 合計 次數 | AD1: 合計 設備次數 | AE1: 產能差異分析
A2: 46293 | B2: 星期一 | C2: 人時性 | D2: =AVERAGE(N9,N12,N48,N57,N19,N63,N27,N35,N44,N74) -> 144.11362 | E2: 平均廠價 | F2: =F1/D1 -> 34.000504 | G2: 多次生產數 | H2: =COUNT(H5:H74) -> 11 | Y2: =SUM(Y9+Y12+Y19+Y27+Y35+Y44+Y48+Y57+Y63+Y74) -> 0 | Z2: =SUM(Z9+Z12+Z19+Z27+Z35+Z44+Z48+Z57+Z63+Z74) -> 0 | AC2: 60 | AD2: =SUM(AD9+AD12+AD19+AD27+AD35+AD44+AD48+AD57+AD63+AD74) -> 0
A3: 線別 | B3: 品類 | C3: 品名 | E3: 廠價 | F3: 生產量 | G3: 營收 | H3: 多次 生產 | I3: 人數 | J3: 產能/時 | K3: 人時性 | L3: 人數 | M3: 產能/時 | N3: 人時性 | O3: 人數 | P3: 人時性 | Q3: 達成率 | R3: 達成率平均 | S3: 生產時間 | U3: 換線、休息/分 | V3: 稼動時間/分 | W3: 休息時間 | Y3: 產線異常統計 (5分鐘以上) | AA3: (新豐回填) | AC3: 短暫停線統計 (5分鐘以下) | AE3: 產能/時 | AF3: 達成率 | AG3: 達成率平均
S4: 開始 | T4: 結束 | W4: 開始 | X4: 結束 | Y4: 次數 | Z4: 時間/分 | AC4: 總次數 | AD4: 設備因素(次數)
A5: 新豐6線 | B5: 微波主食 | C5: 二配金咖哩果香甘口咖哩飯 | E5: 50.92 | F5: 2715 | G5: =E5*F5 -> 138247.8 | I5: 15 | J5: 2000 | K5: =J5/I5 -> 133.33333 | L5: 15 | M5: =F5/V5*60 -> 1916.4706 | N5: =M5/L5 -> 127.76471 | O5: =L5-I5 -> 0 | P5: =N5-K5 -> -5.5686275 | Q5: =N5/K5 -> 0.95823529 | R5: =Q9 -> 0.96170777 | S5: 0.70833333 | T5: 0.76736111 | V5: =(T5-S5)*24*60 -> 85 | AC5: 4 | AE5: =M5-J5 -> -83.529412 | AF5: =M5/J5 -> 0.95823529 | AG5: =AF9 -> 0.96170777
A6: 新豐6線 | B6: 微波主食 | C6: 二配金咖哩濃厚辛口咖哩飯 | E6: 50.98 | F6: 1000 | G6: =E6*F6 -> 50980 | H6: 2 | I6: 16 | J6: 2000 | K6: =J6/I6 -> 125 | L6: 16 | M6: =F6/V6*60 -> 1935.4839 | N6: =M6/L6 -> 120.96774 | O6: =L6-I6 -> 0 | P6: =N6-K6 -> -4.0322581 | Q6: =N6/K6 -> 0.96774194 | S6: 0.77083333 | T6: 0.79236111 | U6: =IF(S6=TIME(17,0,0),"",(S6-T5)*24*60) -> 5 | V6: =(T6-S6)*24*60 -> 31 | AE6: =M6-J6 -> -64.516129 | AF6: =M6/J6 -> 0.96774194
A7: 新豐6線 | B7: 微波主食 | C7: 二配泰式綠咖哩雞 | E7: 50.67 | F7: 1702 | G7: =E7*F7 -> 86240.34 | I7: 15 | J7: 2000 | K7: =J7/I7 -> 133.33333 | L7: 15 | M7: =F7/V7*60 -> 1926.7925 | N7: =M7/L7 -> 128.45283 | O7: =L7-I7 -> 0 | P7: =N7-K7 -> -4.8805031 | Q7: =N7/K7 -> 0.96339623 | S7: 0.79652778 | T7: 0.83333333 | U7: =IF(S7=TIME(17,0,0),"",(S7-T6)*24*60) -> 6 | V7: =(T7-S7)*24*60 -> 53 | W7: =T7 -> 0.83333333 | X7: =S8 -> 0.87569444 | AE7: =M7-J7 -> -73.207547 | AF7: =M7/J7 -> 0.96339623
A8: 新豐6線 | B8: 微波主食 | C8: 二配金咖哩濃厚辛口咖哩飯 | E8: 50.98 | F8: 1883 | G8: =E8*F8 -> 95995.34 | I8: 16 | J8: 2000 | K8: =J8/I8 -> 125 | L8: 16 | M8: =F8/V8*60 -> 1914.9153 | N8: =M8/L8 -> 119.6822 | O8: =L8-I8 -> 0 | P8: =N8-K8 -> -5.3177966 | Q8: =N8/K8 -> 0.95745763 | S8: 0.87569444 | T8: 0.91666667 | U8: =IF(S8=TIME(17,0,0),"",(S8-T7)*24*60) -> 61 | V8: =(T8-S8)*24*60 -> 59 | AE8: =M8-J8 -> -85.084746 | AF8: =M8/J8 -> 0.95745763
A9: 新豐6線 | B9: 平均 | I9: 15.5 | J9: 2000 | K9: =J9/I9 -> 129.03226 | L9: 15.5 | M9: =AVERAGE(M5:M8) -> 1923.4155 | N9: =M9/L9 -> 124.09133 | O9: =L9-I9 -> 0 | P9: =N9-K9 -> -4.9409328 | Q9: =N9/K9 -> 0.96170777 | Y9: =SUM(Y5:Y8) -> 0 | Z9: =SUM(Z5:Z8) -> 0 | AC9: 4 | AD9: =SUM(AD5:AD8) -> 0 | AE9: =M9-J9 -> -76.584458 | AF9: =M9/J9 -> 0.96170777
A10: 新豐2線 | B10: 沙拉 | C10: 青醬優格雞肉握沙拉(113年) | E10: 39.62 | F10: 5288 | G10: =E10*F10 -> 209510.56 | I10: 19 | J10: 1500 | K10: =J10/I10 -> 78.947368 | L10: 19 | M10: =F10/V10*60 -> 1429.1892 | N10: =M10/L10 -> 75.220484 | O10: =L10-I10 -> 0 | P10: =N10-K10 -> -3.7268848 | Q10: =N10/K10 -> 0.95279279 | R10: =Q12 -> 0.95233579 | S10: 0.083333333 | T10: 0.2375 | V10: =(T10-S10)*24*60 -> 222 | W10: =T10 -> 0.2375 | X10: =S11 -> 0.25625 | AC10: 2 | AE10: =M10-J10 -> -70.810811 | AF10: =M10/J10 -> 0.95279279 | AG10: =AF12 -> 0.95233579
A11: 新豐2線 | B11: 沙拉 | C11: 青檸烤雞握沙拉(113年) | E11: 39.8 | F11: 7853 | G11: =E11*F11 -> 312549.4 | I11: 17 | J11: 1500 | K11: =J11/I11 -> 88.235294 | L11: 17 | M11: =F11/V11*60 -> 1427.8182 | N11: =M11/L11 -> 83.989305 | O11: =L11-I11 -> 0 | P11: =N11-K11 -> -4.2459893 | Q11: =N11/K11 -> 0.95187879 | S11: 0.25625 | T11: 0.48541667 | U11: =IF(S11=TIME(17,0,0),"",(S11-T10)*24*60) -> 27 | V11: =(T11-S11)*24*60 -> 330 | AE11: =M11-J11 -> -72.181818 | AF11: =M11/J11 -> 0.95187879
A12: 新豐2線 | B12: 平均 | I12: 18 | J12: 1500 | K12: =J12/I12 -> 83.333333 | L12: 18 | M12: =AVERAGE(M10:M11) -> 1428.5037 | N12: =M12/L12 -> 79.361316 | O12: =L12-I12 -> 0 | P12: =N12-K12 -> -3.9720175 | Q12: =N12/K12 -> 0.95233579 | Y12: =SUM(Y10:Y11) -> 0 | Z12: =SUM(Z10:Z11) -> 0 | AC12: 2 | AD12: =SUM(AD10:AD11) -> 0 | AE12: =M12-J12 -> -71.496314 | AF12: =M12/J12 -> 0.95233579
A13: 新豐5線 | B13: 季節調理麵 | C13: 台式麻醬涼麵(115年) | E13: 31.11 | F13: 2567 | G13: =E13*F13 -> 79859.37 | I13: 14 | J13: 2000 | K13: =J13/I13 -> 142.85714 | L13: 14 | M13: =F13/V13*60 -> 1901.4815 | N13: =M13/L13 -> 135.82011 | O13: =L13-I13 -> 0 | P13: =N13-K13 -> -7.037037 | Q13: =N13/K13 -> 0.95074074 | R13: =Q19 -> 0.95986496 | S13: 0.20833333 | T13: 0.26458333 | V13: =(T13-S13)*24*60 -> 81 | AC13: 6 | AE13: =M13-J13 -> -98.518519 | AF13: =M13/J13 -> 0.95074074 | AG13: =AF19 -> 0.95986496
A14: 新豐5線 | B14: 小吃 | C14: 剝皮辣椒雞湯 | E14: 41 | F14: 2180 | G14: =E14*F14 -> 89380 | I14: 26 | J14: 1500 | K14: =J14/I14 -> 57.692308 | L14: 26 | M14: =F14/V14*60 -> 1437.3626 | N14: =M14/L14 -> 55.283178 | O14: =L14-I14 -> 0 | P14: =N14-K14 -> -2.4091293 | Q14: =N14/K14 -> 0.95824176 | S14: 0.26805556 | T14: 0.33125 | U14: =IF(S14=TIME(17,0,0),"",(S14-T13)*24*60) -> 5 | V14: =(T14-S14)*24*60 -> 91 | AE14: =M14-J14 -> -62.637363 | AF14: =M14/J14 -> 0.95824176
A15: 新豐5線 | B15: 沙拉 | C15: 厚蛋時蔬握沙拉 | E15: 39.46 | F15: 2615 | G15: =E15*F15 -> 103187.9 | I15: 15 | J15: 1500 | K15: =J15/I15 -> 100 | L15: 15 | M15: =F15/V15*60 -> 1439.4495 | N15: =M15/L15 -> 95.963303 | O15: =L15-I15 -> 0 | P15: =N15-K15 -> -4.0366972 | Q15: =N15/K15 -> 0.95963303 | S15: 0.33541667 | T15: 0.41111111 | U15: =IF(S15=TIME(17,0,0),"",(S15-T14)*24*60) -> 6 | V15: =(T15-S15)*24*60 -> 109 | AE15: =M15-J15 -> -60.550459 | AF15: =M15/J15 -> 0.95963303
A16: 新豐5線 | B16: 微波主食 | C16: 二配打拋風味豬肉飯 | E16: 51.06 | F16: 3197 | G16: =E16*F16 -> 163238.82 | I16: 13 | J16: 2000 | K16: =J16/I16 -> 153.84615 | L16: 13 | M16: =F16/V16*60 -> 1918.2 | N16: =M16/L16 -> 147.55385 | O16: =L16-I16 -> 0 | P16: =N16-K16 -> -6.2923077 | Q16: =N16/K16 -> 0.9591 | S16: 0.70833333 | T16: 0.77777778 | U16: =IF(S16=TIME(17,0,0),"",(S16-T15)*24*60) | V16: =(T16-S16)*24*60 -> 100 | AE16: =M16-J16 -> -81.8 | AF16: =M16/J16 -> 0.9591
A17: 新豐5線 | B17: 微波主食 | C17: 二配厚香料優格咖哩雞排飯 | E17: 56.43 | F17: 1313 | G17: =E17*F17 -> 74092.59 | I17: 13 | J17: 2000 | K17: =J17/I17 -> 153.84615 | L17: 13 | M17: =F17/V17*60 -> 1921.4634 | N17: =M17/L17 -> 147.80488 | O17: =L17-I17 -> 0 | P17: =N17-K17 -> -6.0412758 | Q17: =N17/K17 -> 0.96073171 | S17: 0.78194444 | T17: 0.81041667 | U17: =IF(S17=TIME(17,0,0),"",(S17-T16)*24*60) -> 6 | V17: =(T17-S17)*24*60 -> 41 | AE17: =M17-J17 -> -78.536585 | AF17: =M17/J17 -> 0.96073171
A18: 新豐5線 | B18: 微波主食 | C18: 二配玉米濃湯焗烤飯 | E18: 54.5 | F18: 779 | G18: =E18*F18 -> 42455.5 | I18: 19 | J18: 1500 | K18: =J18/I18 -> 78.947368 | L18: 19 | M18: =F18/V18*60 -> 1460.625 | N18: =M18/L18 -> 76.875 | O18: =L18-I18 -> 0 | P18: =N18-K18 -> -2.0723684 | Q18: =N18/K18 -> 0.97375 | S18: 0.81458333 | T18: 0.83680556 | U18: =IF(S18=TIME(17,0,0),"",(S18-T17)*24*60) -> 6 | V18: =(T18-S18)*24*60 -> 32 | AE18: =M18-J18 -> -39.375 | AF18: =M18/J18 -> 0.97375
A19: 新豐5線 | B19: 平均 | I19: 16.666667 | J19: 1750 | K19: =J19/I19 -> 105 | L19: 16.666667 | M19: =AVERAGE(M13:M18) -> 1679.7637 | N19: =M19/L19 -> 100.78582 | O19: =L19-I19 -> 0 | P19: =N19-K19 -> -4.2141793 | Q19: =N19/K19 -> 0.95986496 | Y19: =SUM(Y13:Y18) -> 0 | Z19: =SUM(Z13:Z18) -> 0 | AC19: 6 | AD19: =SUM(AD13:AD18) -> 0 | AE19: =M19-J19 -> -70.236321 | AF19: =M19/J19 -> 0.95986496
A20: 新豐7線 | B20: 微波主食 | C20: 韓式泡菜豬肉豆腐丼飯 | E20: 50.67 | F20: 1929 | G20: =E20*F20 -> 97742.43 | I20: 17 | J20: 2000 | K20: =J20/I20 -> 117.64706 | L20: 17 | M20: =F20/V20*60 -> 1929 | N20: =M20/L20 -> 113.47059 | O20: =L20-I20 -> 0 | P20: =N20-K20 -> -4.1764706 | Q20: =N20/K20 -> 0.9645 | R20: =Q27 -> 0.96135993 | S20: 0.25 | T20: 0.29166667 | V20: =(T20-S20)*24*60 -> 60 | AC20: 7 | AE20: =M20-J20 -> -71 | AF20: =M20/J20 -> 0.9645 | AG20: =AF27 -> 0.96135993
A21: 新豐7線 | B21: 微波主食 | C21: 鐵板滑蛋炸豬排丼 | E21: 57.73 | F21: 3116 | G21: =E21*F21 -> 179886.68 | I21: 14 | J21: 2000 | K21: =J21/I21 -> 142.85714 | L21: 14 | M21: =F21/V21*60 -> 1907.7551 | N21: =M21/L21 -> 136.26822 | O21: =L21-I21 -> 0 | P21: =N21-K21 -> -6.5889213 | Q21: =N21/K21 -> 0.95387755 | S21: 0.29722222 | T21: 0.36527778 | U21: =IF(S21=TIME(17,0,0),"",(S21-T20)*24*60) -> 8 | V21: =(T21-S21)*24*60 -> 98 | AE21: =M21-J21 -> -92.244898 | AF21: =M21/J21 -> 0.95387755
A22: 新豐7線 | B22: 微波主食 | C22: 日式炙烤親子丼 | E22: 53.27 | F22: 1753 | G22: =E22*F22 -> 93382.31 | I22: 16 | J22: 2000 | K22: =J22/I22 -> 125 | L22: 16 | M22: =F22/V22*60 -> 1912.3636 | N22: =M22/L22 -> 119.52273 | O22: =L22-I22 -> 0 | P22: =N22-K22 -> -5.4772727 | Q22: =N22/K22 -> 0.95618182 | S22: 0.37013889 | T22: 0.40833333 | U22: =IF(S22=TIME(17,0,0),"",(S22-T21)*24*60) -> 7 | V22: =(T22-S22)*24*60 -> 55 | AE22: =M22-J22 -> -87.636364 | AF22: =M22/J22 -> 0.95618182
A23: 新豐7線 | B23: 微波主食 | C23: 二配川味麻婆燒豆腐燴飯 | E23: 50.49 | F23: 2401 | G23: =E23*F23 -> 121226.49 | I23: 15 | J23: 2000 | K23: =J23/I23 -> 133.33333 | L23: 15 | M23: =F23/V23*60 -> 1920.8 | N23: =M23/L23 -> 128.05333 | O23: =L23-I23 -> 0 | P23: =N23-K23 -> -5.28 | Q23: =N23/K23 -> 0.9604 | S23: 0.70833333 | T23: 0.76041667 | U23: =IF(S23=TIME(17,0,0),"",(S23-T22)*24*60) | V23: =(T23-S23)*24*60 -> 75 | AE23: =M23-J23 -> -79.2 | AF23: =M23/J23 -> 0.9604
A24: 新豐7線 | B24: 微波主食 | C24: 二配美味蟹煲 | E24: 54.09 | F24: 2127 | G24: =E24*F24 -> 115049.43 | I24: 18 | J24: 2000 | K24: =J24/I24 -> 111.11111 | L24: 18 | M24: =F24/V24*60 -> 1933.6364 | N24: =M24/L24 -> 107.42424 | O24: =L24-I24 -> 0 | P24: =N24-K24 -> -3.6868687 | Q24: =N24/K24 -> 0.96681818 | S24: 0.76458333 | T24: 0.81041667 | U24: =IF(S24=TIME(17,0,0),"",(S24-T23)*24*60) -> 6 | V24: =(T24-S24)*24*60 -> 66 | AE24: =M24-J24 -> -66.363636 | AF24: =M24/J24 -> 0.96681818
A25: 新豐7線 | B25: 微波主食 | C25: 二配港式滑蛋牛肉燴飯 | E25: 50.67 | F25: 1000 | G25: =E25*F25 -> 50670 | H25: 2 | I25: 16 | J25: 2000 | K25: =J25/I25 -> 125 | L25: 16 | M25: =F25/V25*60 -> 1935.4839 | N25: =M25/L25 -> 120.96774 | O25: =L25-I25 -> 0 | P25: =N25-K25 -> -4.0322581 | Q25: =N25/K25 -> 0.96774194 | S25: 0.81388889 | T25: 0.83541667 | U25: =IF(S25=TIME(17,0,0),"",(S25-T24)*24*60) -> 5 | V25: =(T25-S25)*24*60 -> 31 | W25: =T25 -> 0.83541667 | X25: =S26 -> 0.87638889 | AE25: =M25-J25 -> -64.516129 | AF25: =M25/J25 -> 0.96774194
A26: 新豐7線 | B26: 微波主食 | C26: 二配港式滑蛋牛肉燴飯 | E26: 50.67 | F26: 1920 | G26: =E26*F26 -> 97286.4 | I26: 16 | J26: 2000 | K26: =J26/I26 -> 125 | L26: 16 | M26: =F26/V26*60 -> 1920 | N26: =M26/L26 -> 120 | O26: =L26-I26 -> 0 | P26: =N26-K26 -> -5 | Q26: =N26/K26 -> 0.96 | S26: 0.87638889 | T26: 0.91805556 | U26: =IF(S26=TIME(17,0,0),"",(S26-T25)*24*60) -> 59 | V26: =(T26-S26)*24*60 -> 60 | AE26: =M26-J26 -> -80 | AF26: =M26/J26 -> 0.96
A27: 新豐7線 | B27: 平均 | I27: 16 | J27: 2000 | K27: =J27/I27 -> 125 | L27: 16 | M27: =AVERAGE(M20:M26) -> 1922.7199 | N27: =M27/L27 -> 120.16999 | O27: =L27-I27 -> 0 | P27: =N27-K27 -> -4.8300092 | Q27: =N27/K27 -> 0.96135993 | Y27: =SUM(Y20:Y26) -> 0 | Z27: =SUM(Z20:Z26) -> 0 | AC27: 7 | AD27: =SUM(AD20:AD26) -> 0 | AE27: =M27-J27 -> -77.280147 | AF27: =M27/J27 -> 0.96135993
A28: 新豐8線 | B28: 三明治 | C28: 紐奧良風味烤雞鮮蔬三明治 | E28: 31.29 | F28: 6300 | G28: =E28*F28 -> 197127 | H28: 2 | I28: 18 | J28: 2400 | K28: =J28/I28 -> 133.33333 | L28: 18 | M28: =F28/V28*60 -> 2290.9091 | N28: =M28/L28 -> 127.27273 | O28: =L28-I28 -> 0 | P28: =N28-K28 -> -6.0606061 | Q28: =N28/K28 -> 0.95454545 | R28: =Q35 -> 0.95515697 | S28: 0.083333333 | T28: 0.19791667 | V28: =(T28-S28)*24*60 -> 165 | W28: =T28 -> 0.19791667 | X28: =S29 -> 0.21736111 | AC28: 7 | AE28: =M28-J28 -> -109.09091 | AF28: =M28/J28 -> 0.95454545 | AG28: =AF35 -> 0.95515697
A29: 新豐8線 | B29: 三明治 | C29: 醬燒烤雞三明治(115年) | E29: 26.37 | F29: 4600 | G29: =E29*F29 -> 121302 | H29: 2 | I29: 18 | J29: 2400 | K29: =J29/I29 -> 133.33333 | L29: 18 | M29: =F29/V29*60 -> 2300 | N29: =M29/L29 -> 127.77778 | O29: =L29-I29 -> 0 | P29: =N29-K29 -> -5.5555556 | Q29: =N29/K29 -> 0.95833333 | S29: 0.21736111 | T29: 0.30069444 | U29: =(S29-T28)*24*60 -> 28 | V29: =(T29-S29)*24*60 -> 120 | AE29: =M29-J29 -> -100 | AF29: =M29/J29 -> 0.95833333
A30: 新豐8線 | B30: 三明治 | C30: 經典火腿玉米蛋三明治 | E30: 24.43 | F30: 5100 | G30: =E30*F30 -> 124593 | H30: 2 | I30: 14 | J30: 2400 | K30: =J30/I30 -> 171.42857 | L30: 14 | M30: =F30/V30*60 -> 2283.5821 | N30: =M30/L30 -> 163.11301 | O30: =L30-I30 -> 0 | P30: =N30-K30 -> -8.315565 | Q30: =N30/K30 -> 0.95149254 | S30: 0.30486111 | T30: 0.39791667 | U30: =(S30-T29)*24*60 -> 6 | V30: =(T30-S30)*24*60 -> 134 | AE30: =M30-J30 -> -116.41791 | AF30: =M30/J30 -> 0.95149254
A31: 新豐8線 | B31: 三明治 | C31: 好多菜三明治 | E31: 25.98 | F31: 4393 | G31: =E31*F31 -> 114130.14 | I31: 19 | J31: 2400 | K31: =J31/I31 -> 126.31579 | L31: 19 | M31: =F31/V31*60 -> 2292 | N31: =M31/L31 -> 120.63158 | O31: =L31-I31 -> 0 | P31: =N31-K31 -> -5.6842105 | Q31: =N31/K31 -> 0.955 | S31: 0.40208333 | T31: 0.48194444 | U31: =(S31-T30)*24*60 -> 6 | V31: =(T31-S31)*24*60 -> 115 | W31: =T31 -> 0.48194444 | X31: =S32 -> 0.52083333 | AE31: =M31-J31 -> -108 | AF31: =M31/J31 -> 0.955
A32: 新豐8線 | B32: 三明治 | C32: 紐奧良風味烤雞鮮蔬三明治 | E32: 31.29 | F32: 4586 | G32: =E32*F32 -> 143495.94 | I32: 18 | J32: 2400 | K32: =J32/I32 -> 133.33333 | L32: 18 | M32: =F32/V32*60 -> 2293 | N32: =M32/L32 -> 127.38889 | O32: =L32-I32 -> 0 | P32: =N32-K32 -> -5.9444444 | Q32: =N32/K32 -> 0.95541667 | S32: 0.52083333 | T32: 0.60416667 | U32: =(S32-T31)*24*60 -> 56 | V32: =(T32-S32)*24*60 -> 120 | AE32: =M32-J32 -> -107 | AF32: =M32/J32 -> 0.95541667
A33: 新豐8線 | B33: 三明治 | C33: 醬燒烤雞三明治(115年) | E33: 26.37 | F33: 3094 | G33: =E33*F33 -> 81588.78 | I33: 18 | J33: 2400 | K33: =J33/I33 -> 133.33333 | L33: 18 | M33: =F33/V33*60 -> 2291.8519 | N33: =M33/L33 -> 127.3251 | O33: =L33-I33 -> 0 | P33: =N33-K33 -> -6.0082305 | Q33: =N33/K33 -> 0.95493827 | S33: 0.60833333 | T33: 0.66458333 | U33: =(S33-T32)*24*60 -> 6 | V33: =(T33-S33)*24*60 -> 81 | AE33: =M33-J33 -> -108.14815 | AF33: =M33/J33 -> 0.95493827
A34: 新豐8線 | B34: 三明治 | C34: 經典火腿玉米蛋三明治 | E34: 24.43 | F34: 3902 | G34: =E34*F34 -> 95325.86 | I34: 14 | J34: 2400 | K34: =J34/I34 -> 171.42857 | L34: 14 | M34: =F34/V34*60 -> 2295.2941 | N34: =M34/L34 -> 163.94958 | O34: =L34-I34 -> 0 | P34: =N34-K34 -> -7.4789916 | Q34: =N34/K34 -> 0.95637255 | S34: 0.66944444 | T34: 0.74027778 | U34: =(S34-T33)*24*60 -> 7 | V34: =(T34-S34)*24*60 -> 102 | AE34: =M34-J34 -> -104.70588 | AF34: =M34/J34 -> 0.95637255
A35: 新豐8線 | B35: 平均 | I35: 17 | J35: 2400 | K35: =J35/I35 -> 141.17647 | L35: 17 | M35: =AVERAGE(M28:M34) -> 2292.3767 | N35: =M35/L35 -> 134.84569 | O35: =L35-I35 -> 0 | P35: =N35-K35 -> -6.3307803 | Q35: =N35/K35 -> 0.95515697 | Y35: =SUM(Y28:Y34) -> 0 | Z35: =SUM(Z28:Z34) -> 0 | AC35: 7 | AD35: =SUM(AD28:AD34) -> 0 | AE35: =M35-J35 -> -107.62326 | AF35: =M35/J35 -> 0.95515697
A36: 新豐9線 | B36: 三明治 | C36: 經典總匯三明治(115年) | E36: 26.18 | F36: 4100 | G36: =E36*F36 -> 107338 | H36: 2 | I36: 20 | J36: 2400 | K36: =J36/I36 -> 120 | L36: 20 | M36: =F36/V36*60 -> 2299.0654 | N36: =M36/L36 -> 114.95327 | O36: =L36-I36 -> 0 | P36: =N36-K36 -> -5.046729 | Q36: =N36/K36 -> 0.95794393 | R36: =Q44 -> 0.95881778 | S36: 0.083333333 | T36: 0.15763889 | V36: =(T36-S36)*24*60 -> 107 | W36: =T36 -> 0.15763889 | X36: =S37 -> 0.17708333 | AC36: 8 | AE36: =M36-J36 -> -100.93458 | AF36: =M36/J36 -> 0.95794393 | AG36: =AF44 -> 0.95881778
A37: 新豐9線 | B37: 三明治 | C37: 鮪魚起司溏心蛋三明治(115年) | E37: 26.18 | F37: 5400 | G37: =E37*F37 -> 141372 | H37: 2 | I37: 18 | J37: 2400 | K37: =J37/I37 -> 133.33333 | L37: 18 | M37: =F37/V37*60 -> 2297.8723 | N37: =M37/L37 -> 127.65957 | O37: =L37-I37 -> 0 | P37: =N37-K37 -> -5.6737589 | Q37: =N37/K37 -> 0.95744681 | S37: 0.17708333 | T37: 0.275 | U37: =(S37-T36)*24*60 -> 28 | V37: =(T37-S37)*24*60 -> 141 | AE37: =M37-J37 -> -102.12766 | AF37: =M37/J37 -> 0.95744681
A38: 新豐9線 | B38: 三明治 | C38: 好多蛋三明治 | E38: 34.1 | F38: 4100 | G38: =E38*F38 -> 139810 | H38: 2 | I38: 17 | J38: 1600 | K38: =J38/I38 -> 94.117647 | L38: 17 | M38: =F38/V38*60 -> 1527.9503 | N38: =M38/L38 -> 89.87943 | O38: =L38-I38 -> 0 | P38: =N38-K38 -> -4.238217 | Q38: =N38/K38 -> 0.95496894 | S38: 0.27847222 | T38: 0.39027778 | U38: =(S38-T37)*24*60 -> 5 | V38: =(T38-S38)*24*60 -> 161 | AE38: =M38-J38 -> -72.049689 | AF38: =M38/J38 -> 0.95496894
A39: 新豐9線 | B39: 三明治 | C39: 金黃玉米蛋三明治 | E39: 24.25 | F39: 1779 | G39: =E39*F39 -> 43140.75 | I39: 16 | J39: 2400 | K39: =J39/I39 -> 150 | L39: 16 | M39: =F39/V39*60 -> 2320.4348 | N39: =M39/L39 -> 145.02717 | O39: =L39-I39 -> 0 | P39: =N39-K39 -> -4.9728261 | Q39: =N39/K39 -> 0.96684783 | S39: 0.39583333 | T39: 0.42777778 | U39: =(S39-T38)*24*60 -> 8 | V39: =(T39-S39)*24*60 -> 46 | AE39: =M39-J39 -> -79.565217 | AF39: =M39/J39 -> 0.96684783
A40: 新豐9線 | B40: 三明治 | C40: 巧克力肉鬆三明治 | E40: 23.89 | F40: 3187 | G40: =E40*F40 -> 76137.43 | I40: 17 | J40: 2400 | K40: =J40/I40 -> 141.17647 | L40: 17 | M40: =F40/V40*60 -> 2303.8554 | N40: =M40/L40 -> 135.52091 | O40: =L40-I40 -> 0 | P40: =N40-K40 -> -5.6555634 | Q40: =N40/K40 -> 0.95993976 | S40: 0.43333333 | T40: 0.49097222 | U40: =(S40-T39)*24*60 -> 8 | V40: =(T40-S40)*24*60 -> 83 | W40: =T40 -> 0.49097222 | X40: =S41 -> 0.53125 | AE40: =M40-J40 -> -96.144578 | AF40: =M40/J40 -> 0.95993976
...

Sheet 0927
B1: 屏榮 新豐廠組合室生產人時性分析
B3: 日期 | C3: =TEXT('0927 4度C'!A2,"yyyy.mm.ddaaaa") -> 2026.09.27星期日 | E3: 訂單量 | F3: ='0927 4度C'!D1 -> 130438 | H3: 營業額 | I3: ='0927 4度C'!F1 -> 4560731
B4: 人時性 | C4: 項目 | E4: ➀ | G4: ➁ | I4: ➂ | K4: 異常停線 | M4: 短暫停線
C5: 組合室 | E5: 全溫層 | G5: 4度C-各編組展開 | I5: ③三明治-各編組展開 | K5: 合計次數 | L5: 時間 | M5: 合計次數 | N5: 設備次數
C6: 排關平均 | E6: =AVERAGE(D13:M13) -> 150.23892 | F6: =AVERAGE(D31:O31,D13:J13) -> 155.69986 | G6: =AVERAGE(D13:J13) -> 155.69986 | I6: =AVERAGE(K13:M13) -> 137.49671 | K6: ='0927 4度C'!Y2 -> 0 | L6: ='0927 4度C'!Z2 -> 0 | M6: ='0927 4度C'!AC2 -> 50 | N6: ='0927 4度C'!AD2 -> 0
C7: 實績平均 | E7: =AVERAGE(D14:M14) -> 144.07146 | F7: =AVERAGE(D32:O32,D14:J14) -> 149.37564 | G7: =AVERAGE(D14:J14) -> 149.37564 | I7: =AVERAGE(K14:M14) -> 131.69505
C8: 達成率平均 | E8: =AVERAGE(D15:M15) -> 0.95916789 | F8: =AVERAGE(D15:J15,D33:O33) -> 0.95975334 | G8: =AVERAGE(D15:J15) -> 0.95975334 | I8: =AVERAGE(K15:M15) -> 0.95780183
K9: ※現行日本鮮食廠以達成率80%為基本(即為現行KPI)
B10: 溫層 | D10: ➁4度C-各編組展開 | K10: ③三明治-各編組展開
B11: 編組 | D11: 1 | E11: 2 | F11: 3 | G11: 4 | H11: 5 | I11: 6 | J11: 7 | K11: 1 | L11: 2 | M11: 3
D12: 新豐6線 | E12: 新豐2線 | F12: 新豐5線 | G12: 新豐7線 | H12: 新豐3線 | I12: 新豐1線 | J12: 新豐10線 | K12: 新豐8線 | L12: 新豐9線 | M12: 新豐4線
B13: 人時性 | C13: 排關 | D13: =SUMIFS('0927 4度C'!$K:$K,'0927 4度C'!$A:$A,"新豐6線",'0927 4度C'!$B:$B,"平均") -> 130.43478 | E13: =SUMIFS('0927 4度C'!$K:$K,'0927 4度C'!$A:$A,"新豐2線",'0927 4度C'!$B:$B,"平均") -> 83.333333 | F13: =SUMIFS('0927 4度C'!$K:$K,'0927 4度C'!$A:$A,"新豐5線",'0927 4度C'!$B:$B,"平均") -> 105 | G13: =SUMIFS('0927 4度C'!$K:$K,'0927 4度C'!$A:$A,"新豐7線",'0927 4度C'!$B:$B,"平均") -> 125 | H13: =SUMIFS('0927 4度C'!$K:$K,'0927 4度C'!$A:$A,"新豐3線",'0927 4度C'!$B:$B,"平均") -> 242.42424 | I13: =SUMIFS('0927 4度C'!$K:$K,'0927 4度C'!$A:$A,"新豐1線",'0927 4度C'!$B:$B,"平均") -> 109.58904 | J13: =SUMIFS('0927 4度C'!$K:$K,'0927 4度C'!$A:$A,"新豐10線",'0927 4度C'!$B:$B,"平均") -> 294.11765 | K13: =SUMIFS('0927 4度C'!$K:$K,'0927 4度C'!$A:$A,"新豐8線",'0927 4度C'!$B:$B,"平均") -> 139.13043 | L13: =SUMIFS('0927 4度C'!$K:$K,'0927 4度C'!$A:$A,"新豐9線",'0927 4度C'!$B:$B,"平均") -> 127.27273 | M13: =SUMIFS('0927 4度C'!$K:$K,'0927 4度C'!$A:$A,"新豐4線",'0927 4度C'!$B:$B,"平均") -> 146.08696
C14: 實績 | D14: =SUMIFS('0927 4度C'!$N:$N,'0927 4度C'!$A:$A,"新豐6線",'0927 4度C'!$B:$B,"平均") -> 125.42014 | E14: =SUMIFS('0927 4度C'!$N:$N,'0927 4度C'!$A:$A,"新豐2線",'0927 4度C'!$B:$B,"平均") -> 79.460853 | F14: =SUMIFS('0927 4度C'!$N:$N,'0927 4度C'!$A:$A,"新豐5線",'0927 4度C'!$B:$B,"平均") -> 101.00814 | G14: =SUMIFS('0927 4度C'!$N:$N,'0927 4度C'!$A:$A,"新豐7線",'0927 4度C'!$B:$B,"平均") -> 120.0601 | H14: =SUMIFS('0927 4度C'!$N:$N,'0927 4度C'!$A:$A,"新豐3線",'0927 4度C'!$B:$B,"平均") -> 231.91662 | I14: =SUMIFS('0927 4度C'!$N:$N,'0927 4度C'!$A:$A,"新豐1線",'0927 4度C'!$B:$B,"平均") -> 105.79448 | J14: =SUMIFS('0927 4度C'!$N:$N,'0927 4度C'!$A:$A,"新豐10線",'0927 4度C'!$B:$B,"平均") -> 281.96913 | K14: =SUMIFS('0927 4度C'!$N:$N,'0927 4度C'!$A:$A,"新豐8線",'0927 4度C'!$B:$B,"平均") -> 132.56295 | L14: =SUMIFS('0927 4度C'!$N:$N,'0927 4度C'!$A:$A,"新豐9線",'0927 4度C'!$B:$B,"平均") -> 122.12841 | M14: =SUMIFS('0927 4度C'!$N:$N,'0927 4度C'!$A:$A,"新豐4線",'0927 4度C'!$B:$B,"平均") -> 140.3938
C15: 達成率 | D15: =D14/D13 -> 0.96155437 | E15: =E14/E13 -> 0.95353023 | F15: =F14/F13 -> 0.96198224 | G15: =G14/G13 -> 0.96048084 | H15: =H14/H13 -> 0.95665604 | I15: =I14/I13 -> 0.96537461 | J15: =J14/J13 -> 0.95869503 | K15: =K14/K13 -> 0.95279617 | ... M15: =M14/M13 -> 0.96102898
B16: 作業 時間 | C16: 開始 | D16: =VLOOKUP("新豐6線",'0927 4度C'!$A:$T,19,0) -> 0.70833333 | E16: =VLOOKUP("新豐2線",'0927 4度C'!$A:$T,19,0) -> 0.083333333 | F16: =VLOOKUP("新豐5線",'0927 4度C'!$A:$T,19,0) -> 0.20833333 | G16: =VLOOKUP("新豐7線",'0927 4度C'!$A:$T,19,0) -> 0.25 | H16: =VLOOKUP("新豐3線",'0927 4度C'!$A:$T,19,0) -> 0.20833333 | I16: =VLOOKUP("新豐1線",'0927 4度C'!$A:$T,19,0) -> 0.20833333 | J16: =VLOOKUP("新豐10線",'0927 4度C'!$A:$T,19,0) -> 0.20833333 | K16: =VLOOKUP("新豐8線",'0927 4度C'!$A:$T,19,0) -> 0.083333333 | L16: =VLOOKUP("新豐9線",'0927 4度C'!$A:$T,19,0) -> 0.083333333 | M16: =VLOOKUP("新豐4線",'0927 4度C'!$A:$T,19,0) -> 0.083333333
C17: 結束 | D17: =LOOKUP(2,1/(('0927 4度C'!$A:$A="新豐6線")*('0927 4度C'!$T:$T<>"")),'0927 4度C'!$T:$T) -> 0.85416667 | E17: =LOOKUP(2,1/(('0927 4度C'!$A:$A="新豐2線")*('0927 4度C'!$T:$T<>"")),'0927 4度C'!$T:$T) -> 0.32708333 | F17: =LOOKUP(2,1/(('0927 4度C'!$A:$A="新豐5線")*('0927 4度C'!$T:$T<>"")),'0927 4度C'!$T:$T) -> 0.83958333 | G17: =LOOKUP(2,1/(('0927 4度C'!$A:$A="新豐7線")*('0927 4度C'!$T:$T<>"")),'0927 4度C'!$T:$T) -> 0.90763889 | H17: =LOOKUP(2,1/(('0927 4度C'!$A:$A="新豐3線")*('0927 4度C'!$T:$T<>"")),'0927 4度C'!$T:$T) -> 0.39444444 | I17: =LOOKUP(2,1/(('0927 4度C'!$A:$A="新豐1線")*('0927 4度C'!$T:$T<>"")),'0927 4度C'!$T:$T) -> 0.84791667 | J17: =LOOKUP(2,1/(('0927 4度C'!$A:$A="新豐10線")*('0927 4度C'!$T:$T<>"")),'0927 4度C'!$T:$T) -> 0.40208333 | K17: =LOOKUP(2,1/(('0927 4度C'!$A:$A="新豐8線")*('0927 4度C'!$T:$T<>"")),'0927 4度C'!$T:$T) -> 0.49097222 | L17: =LOOKUP(2,1/(('0927 4度C'!$A:$A="新豐9線")*('0927 4度C'!$T:$T<>"")),'0927 4度C'!$T:$T) -> 0.50069444 | M17: =LOOKUP(2,1/(('0927 4度C'!$A:$A="新豐4線")*('0927 4度C'!$T:$T<>"")),'0927 4度C'!$T:$T) -> 0.49861111
B18: 產線異常 (5分鐘以上) | C18: 次數 | D18: =SUMIFS('0927 4度C'!$Y:$Y,'0927 4度C'!$A:$A,"新豐6線",'0927 4度C'!$B:$B,"平均") -> 0 | E18: =SUMIFS('0927 4度C'!$Y:$Y,'0927 4度C'!$A:$A,"新豐2線",'0927 4度C'!$B:$B,"平均") -> 0 | F18: =SUMIFS('0927 4度C'!$Y:$Y,'0927 4度C'!$A:$A,"新豐5線",'0927 4度C'!$B:$B,"平均") -> 0 | G18: =SUMIFS('0927 4度C'!$Y:$Y,'0927 4度C'!$A:$A,"新豐7線",'0927 4度C'!$B:$B,"平均") -> 0 | H18: =SUMIFS('0927 4度C'!$Y:$Y,'0927 4度C'!$A:$A,"新豐3線",'0927 4度C'!$B:$B,"平均") -> 0 | I18: =SUMIFS('0927 4度C'!$Y:$Y,'0927 4度C'!$A:$A,"新豐1線",'0927 4度C'!$B:$B,"平均") -> 0 | J18: =SUMIFS('0927 4度C'!$Y:$Y,'0927 4度C'!$A:$A,"新豐10線",'0927 4度C'!$B:$B,"平均") -> 0 | K18: =SUMIFS('0927 4度C'!$Y:$Y,'0927 4度C'!$A:$A,"新豐8線",'0927 4度C'!$B:$B,"平均") -> 0 | L18: =SUMIFS('0927 4度C'!$Y:$Y,'0927 4度C'!$A:$A,"新豐9線",'0927 4度C'!$B:$B,"平均") -> 0 | M18: =SUMIFS('0927 4度C'!$Y:$Y,'0927 4度C'!$A:$A,"新豐4線",'0927 4度C'!$B:$B,"平均") -> 0
C19: 時間/分 | D19: =SUMIFS('0927 4度C'!$Z:$Z,'0927 4度C'!$A:$A,"新豐6線",'0927 4度C'!$B:$B,"平均") -> 0 | E19: =SUMIFS('0927 4度C'!$Z:$Z,'0927 4度C'!$A:$A,"新豐2線",'0927 4度C'!$B:$B,"平均") -> 0 | F19: =SUMIFS('0927 4度C'!$Z:$Z,'0927 4度C'!$A:$A,"新豐5線",'0927 4度C'!$B:$B,"平均") -> 0 | G19: =SUMIFS('0927 4度C'!$Z:$Z,'0927 4度C'!$A:$A,"新豐7線",'0927 4度C'!$B:$B,"平均") -> 0 | H19: =SUMIFS('0927 4度C'!$Z:$Z,'0927 4度C'!$A:$A,"新豐3線",'0927 4度C'!$B:$B,"平均") -> 0 | I19: =SUMIFS('0927 4度C'!$Z:$Z,'0927 4度C'!$A:$A,"新豐1線",'0927 4度C'!$B:$B,"平均") -> 0 | J19: =SUMIFS('0927 4度C'!$Z:$Z,'0927 4度C'!$A:$A,"新豐10線",'0927 4度C'!$B:$B,"平均") -> 0 | K19: =SUMIFS('0927 4度C'!$Z:$Z,'0927 4度C'!$A:$A,"新豐8線",'0927 4度C'!$B:$B,"平均") -> 0 | L19: =SUMIFS('0927 4度C'!$Z:$Z,'0927 4度C'!$A:$A,"新豐9線",'0927 4度C'!$B:$B,"平均") -> 0 | M19: =SUMIFS('0927 4度C'!$Z:$Z,'0927 4度C'!$A:$A,"新豐4線",'0927 4度C'!$B:$B,"平均") -> 0
B20: 短暫停線 (5分鐘以下) | C20: 次數 | D20: =SUMIFS('0927 4度C'!$AC:$AC,'0927 4度C'!$A:$A,"新豐6線",'0927 4度C'!$B:$B,"平均") -> 3 | E20: =SUMIFS('0927 4度C'!$AC:$AC,'0927 4度C'!$A:$A,"新豐2線",'0927 4度C'!$B:$B,"平均") -> 2 | F20: =SUMIFS('0927 4度C'!$AC:$AC,'0927 4度C'!$A:$A,"新豐5線",'0927 4度C'!$B:$B,"平均") -> 6 | G20: =SUMIFS('0927 4度C'!$AC:$AC,'0927 4度C'!$A:$A,"新豐7線",'0927 4度C'!$B:$B,"平均") -> 7 | H20: =SUMIFS('0927 4度C'!$AC:$AC,'0927 4度C'!$A:$A,"新豐3線",'0927 4度C'!$B:$B,"平均") -> 3 | I20: =SUMIFS('0927 4度C'!$AC:$AC,'0927 4度C'!$A:$A,"新豐1線",'0927 4度C'!$B:$B,"平均") -> 8 | J20: =SUMIFS('0927 4度C'!$AC:$AC,'0927 4度C'!$A:$A,"新豐10線",'0927 4度C'!$B:$B,"平均") -> 5 | K20: =SUMIFS('0927 4度C'!$AC:$AC,'0927 4度C'!$A:$A,"新豐8線",'0927 4度C'!$B:$B,"平均") -> 4 | L20: =SUMIFS('0927 4度C'!$AC:$AC,'0927 4度C'!$A:$A,"新豐9線",'0927 4度C'!$B:$B,"平均") -> 5 | M20: =SUMIFS('0927 4度C'!$AC:$AC,'0927 4度C'!$A:$A,"新豐4線",'0927 4度C'!$B:$B,"平均") -> 7
C21: 設備次數 | D21: =SUMIFS('0927 4度C'!$AD:$AD,'0927 4度C'!$A:$A,"新豐6線",'0927 4度C'!$B:$B,"平均") -> 0 | E21: =SUMIFS('0927 4度C'!$AD:$AD,'0927 4度C'!$A:$A,"新豐2線",'0927 4度C'!$B:$B,"平均") -> 0 | F21: =SUMIFS('0927 4度C'!$AD:$AD,'0927 4度C'!$A:$A,"新豐5線",'0927 4度C'!$B:$B,"平均") -> 0 | G21: =SUMIFS('0927 4度C'!$AD:$AD,'0927 4度C'!$A:$A,"新豐7線",'0927 4度C'!$B:$B,"平均") -> 0 | H21: =SUMIFS('0927 4度C'!$AD:$AD,'0927 4度C'!$A:$A,"新豐3線",'0927 4度C'!$B:$B,"平均") -> 0 | I21: =SUMIFS('0927 4度C'!$AD:$AD,'0927 4度C'!$A:$A,"新豐1線",'0927 4度C'!$B:$B,"平均") -> 0 | J21: =SUMIFS('0927 4度C'!$AD:$AD,'0927 4度C'!$A:$A,"新豐10線",'0927 4度C'!$B:$B,"平均") -> 0 | K21: =SUMIFS('0927 4度C'!$AD:$AD,'0927 4度C'!$A:$A,"新豐8線",'0927 4度C'!$B:$B,"平均") -> 0 | L21: =SUMIFS('0927 4度C'!$AD:$AD,'0927 4度C'!$A:$A,"新豐9線",'0927 4度C'!$B:$B,"平均") -> 0 | M21: =SUMIFS('0927 4度C'!$AD:$AD,'0927 4度C'!$A:$A,"新豐4線",'0927 4度C'!$B:$B,"平均") -> 0
B22: 配置人數 | D22: =SUMIFS('0927 4度C'!$I:$I,'0927 4度C'!$A:$A,"新豐6線",'0927 4度C'!$B:$B,"平均") -> 15.333333 | E22: =SUMIFS('0927 4度C'!$I:$I,'0927 4度C'!$A:$A,"新豐2線",'0927 4度C'!$B:$B,"平均") -> 18 | F22: =SUMIFS('0927 4度C'!$I:$I,'0927 4度C'!$A:$A,"新豐5線",'0927 4度C'!$B:$B,"平均") -> 16.666667 | G22: =SUMIFS('0927 4度C'!$I:$I,'0927 4度C'!$A:$A,"新豐7線",'0927 4度C'!$B:$B,"平均") -> 16 | H22: =SUMIFS('0927 4度C'!$I:$I,'0927 4度C'!$A:$A,"新豐3線",'0927 4度C'!$B:$B,"平均") -> 11 | I22: =SUMIFS('0927 4度C'!$I:$I,'0927 4度C'!$A:$A,"新豐1線",'0927 4度C'!$B:$B,"平均") -> 18.25 | J22: =SUMIFS('0927 4度C'!$I:$I,'0927 4度C'!$A:$A,"新豐10線",'0927 4度C'!$B:$B,"平均") -> 10.2 | K22: =SUMIFS('0927 4度C'!$I:$I,'0927 4度C'!$A:$A,"新豐8線",'0927 4度C'!$B:$B,"平均") -> 17.25 | L22: =SUMIFS('0927 4度C'!$I:$I,'0927 4度C'!$A:$A,"新豐9線",'0927 4度C'!$B:$B,"平均") -> 17.6 | M22: =SUMIFS('0927 4度C'!$I:$I,'0927 4度C'!$A:$A,"新豐4線",'0927 4度C'!$B:$B,"平均") -> 16.428571
B23: 主要應用設備 | D23: ET-55 | E23: 熱縮爐 | F23: L型包裝機 | G23: L型包裝機 | H23: 伺服包裝機 | I23: ET-55 | J23: 伺服包裝機 | K23: 三明治包裝機 | L23: 三明治包裝機 | M23: 三明治包裝機
B24: 次要應用設備 | F24: 圓盤機 | G24: ET-55
B25: 備註 | E25: 握沙拉 | F25: 共用L型包裝機 | H25: 調理麵包 | I25: 炒飯+沙拉 | J25: 調理麵包

Sheet 0927 4度C
A1: 新豐廠四度C日報分析 | C1: 總生產量 | D1: =SUM(F5:F64) -> 130438 | E1: 營業額 | F1: =SUM(G5:G64) -> 4560731 | G1: 出勤人數 | H1: =L8+L11+L41+L50+L18+L56+L31+L37+L26+L64 -> 156.72857 | I1: 產線配置圖 | L1: 生產實績 | O1: 人時性差異分析 | S1: 日報登錄 | Y1: 合計 次數 | Z1: 合計 時間/分 | AA1: 產線異常 分析說明(5分鐘以上) | AC1: 合計 次數 | AD1: 合計 設備次數 | AE1: 產能差異分析
A2: 46292 | B2: 星期日 | C2: 人時性 | D2: =AVERAGE(N8,N11,N41,N50,N18,N56,N26,N31,N37,N64) -> 144.07146 | E2: 平均廠價 | F2: =F1/D1 -> 34.964742 | G2: 多次生產數 | H2: =COUNT(H5:H64) -> 1 | Y2: =SUM(Y8+Y11+Y18+Y26+Y31+Y37+Y41+Y50+Y56+Y64) -> 0 | Z2: =SUM(Z8+Z11+Z18+Z26+Z31+Z37+Z41+Z50+Z56+Z64) -> 0 | AC2: 50 | AD2: =SUM(AD8+AD11+AD18+AD26+AD31+AD37+AD41+AD50+AD56+AD64) -> 0
A3: 線別 | B3: 品類 | C3: 品名 | E3: 廠價 | F3: 生產量 | G3: 營收 | H3: 多次 生產 | I3: 人數 | J3: 產能/時 | K3: 人時性 | L3: 人數 | M3: 產能/時 | N3: 人時性 | O3: 人數 | P3: 人時性 | Q3: 達成率 | R3: 達成率平均 | S3: 生產時間 | U3: 換線、休息/分 | V3: 稼動時間/分 | W3: 休息時間 | Y3: 產線異常統計 (5分鐘以上) | AA3: (新豐回填) | AC3: 短暫停線統計 (5分鐘以下) | AE3: 產能/時 | AF3: 達成率 | AG3: 達成率平均
S4: 開始 | T4: 結束 | W4: 開始 | X4: 結束 | Y4: 次數 | Z4: 時間/分 | AC4: 總次數 | AD4: 設備因素(次數)
A5: 新豐6線 | B5: 微波主食 | C5: 二配金咖哩果香甘口咖哩飯 | E5: 50.92 | F5: 2306 | G5: =E5*F5 -> 117421.52 | I5: 15 | J5: 2000 | K5: =J5/I5 -> 133.33333 | L5: 15 | M5: =F5/V5*60 -> 1921.6667 | N5: =M5/L5 -> 128.11111 | O5: =L5-I5 -> 0 | P5: =N5-K5 -> -5.2222222 | Q5: =N5/K5 -> 0.96083333 | R5: =Q8 -> 0.96155437 | S5: 0.70833333 | T5: 0.75833333 | V5: =(T5-S5)*24*60 -> 72 | AC5: 3 | AE5: =M5-J5 -> -78.333333 | AF5: =M5/J5 -> 0.96083333 | AG5: =AF8 -> 0.96155437
A6: 新豐6線 | B6: 微波主食 | C6: 二配金咖哩濃厚辛口咖哩飯 | E6: 50.98 | F6: 2528 | G6: =E6*F6 -> 128877.44 | I6: 16 | J6: 2000 | K6: =J6/I6 -> 125 | L6: 16 | M6: =F6/V6*60 -> 1920 | N6: =M6/L6 -> 120 | O6: =L6-I6 -> 0 | P6: =N6-K6 -> -5 | Q6: =N6/K6 -> 0.96 | S6: 0.76180556 | T6: 0.81666667 | U6: =IF(S6=TIME(17,0,0),"",(S6-T5)*24*60) -> 5 | V6: =(T6-S6)*24*60 -> 79 | AE6: =M6-J6 -> -80 | AF6: =M6/J6 -> 0.96
A7: 新豐6線 | B7: 微波主食 | C7: 二配泰式綠咖哩雞 | E7: 50.67 | F7: 1510 | G7: =E7*F7 -> 76511.7 | I7: 15 | J7: 2000 | K7: =J7/I7 -> 133.33333 | L7: 15 | M7: =F7/V7*60 -> 1927.6596 | N7: =M7/L7 -> 128.51064 | O7: =L7-I7 -> 0 | P7: =N7-K7 -> -4.822695 | Q7: =N7/K7 -> 0.96382979 | S7: 0.82152778 | T7: 0.85416667 | U7: =IF(S7=TIME(17,0,0),"",(S7-T6)*24*60) -> 7 | V7: =(T7-S7)*24*60 -> 47 | AE7: =M7-J7 -> -72.340426 | AF7: =M7/J7 -> 0.96382979
A8: 新豐6線 | B8: 平均 | I8: 15.333333 | J8: 2000 | K8: =J8/I8 -> 130.43478 | L8: 15.333333 | M8: =AVERAGE(M5:M7) -> 1923.1087 | N8: =M8/L8 -> 125.42014 | O8: =L8-I8 -> 0 | P8: =N8-K8 -> -5.0146469 | Q8: =N8/K8 -> 0.96155437 | Y8: =SUM(Y5:Y7) -> 0 | Z8: =SUM(Z5:Z7) -> 0 | AC8: 3 | AD8: =SUM(AD5:AD7) -> 0 | AE8: =M8-J8 -> -76.891253 | AF8: =M8/J8 -> 0.96155437
A9: 新豐2線 | B9: 沙拉 | C9: 青醬優格雞肉握沙拉(113年) | E9: 39.62 | F9: 3127 | G9: =E9*F9 -> 123891.74 | I9: 19 | J9: 1500 | K9: =J9/I9 -> 78.947368 | L9: 19 | M9: =F9/V9*60 -> 1432.2137 | N9: =M9/L9 -> 75.379671 | O9: =L9-I9 -> 0 | P9: =N9-K9 -> -3.5676979 | Q9: =N9/K9 -> 0.95480916 | R9: =Q11 -> 0.95353023 | S9: 0.083333333 | T9: 0.17430556 | V9: =(T9-S9)*24*60 -> 131 | W9: =T9 -> 0.17430556 | X9: =S10 -> 0.19444444 | AC9: 2 | AE9: =M9-J9 -> -67.78626 | AF9: =M9/J9 -> 0.95480916 | AG9: =AF11 -> 0.95353023
A10: 新豐2線 | B10: 沙拉 | C10: 青檸烤雞握沙拉(113年) | E10: 39.8 | F10: 4547 | G10: =E10*F10 -> 180970.6 | I10: 17 | J10: 1500 | K10: =J10/I10 -> 88.235294 | L10: 17 | M10: =F10/V10*60 -> 1428.377 | N10: =M10/L10 -> 84.022174 | O10: =L10-I10 -> 0 | P10: =N10-K10 -> -4.2131198 | Q10: =N10/K10 -> 0.95225131 | S10: 0.19444444 | T10: 0.32708333 | U10: =IF(S10=TIME(17,0,0),"",(S10-T9)*24*60) -> 29 | V10: =(T10-S10)*24*60 -> 191 | AE10: =M10-J10 -> -71.623037 | AF10: =M10/J10 -> 0.95225131
A11: 新豐2線 | B11: 平均 | I11: 18 | J11: 1500 | K11: =J11/I11 -> 83.333333 | L11: 18 | M11: =AVERAGE(M9:M10) -> 1430.2954 | N11: =M11/L11 -> 79.460853 | O11: =L11-I11 -> 0 | P11: =N11-K11 -> -3.8724804 | Q11: =N11/K11 -> 0.95353023 | Y11: =SUM(Y9:Y10) -> 0 | Z11: =SUM(Z9:Z10) -> 0 | AC11: 2 | AD11: =SUM(AD9:AD10) -> 0 | AE11: =M11-J11 -> -69.704648 | AF11: =M11/J11 -> 0.95353023
A12: 新豐5線 | B12: 季節調理麵 | C12: 台式麻醬涼麵(115年) | E12: 31.11 | F12: 2183 | G12: =E12*F12 -> 67913.13 | I12: 14 | J12: 2000 | K12: =J12/I12 -> 142.85714 | L12: 14 | M12: =F12/V12*60 -> 1926.1765 | N12: =M12/L12 -> 137.58403 | O12: =L12-I12 -> 0 | P12: =N12-K12 -> -5.2731092 | Q12: =N12/K12 -> 0.96308824 | R12: =Q18 -> 0.96198224 | S12: 0.20833333 | T12: 0.25555556 | V12: =(T12-S12)*24*60 -> 68 | AC12: 6 | AE12: =M12-J12 -> -73.823529 | AF12: =M12/J12 -> 0.96308824 | AG12: =AF18 -> 0.96198224
A13: 新豐5線 | B13: 小吃 | C13: 剝皮辣椒雞湯 | E13: 41 | F13: 1333 | G13: =E13*F13 -> 54653 | I13: 26 | J13: 1500 | K13: =J13/I13 -> 57.692308 | L13: 26 | M13: =F13/V13*60 -> 1454.1818 | N13: =M13/L13 -> 55.93007 | O13: =L13-I13 -> 0 | P13: =N13-K13 -> -1.7622378 | Q13: =N13/K13 -> 0.96945455 | S13: 0.26041667 | T13: 0.29861111 | U13: =IF(S13=TIME(17,0,0),"",(S13-T12)*24*60) -> 7 | V13: =(T13-S13)*24*60 -> 55 | AE13: =M13-J13 -> -45.818182 | AF13: =M13/J13 -> 0.96945455
A14: 新豐5線 | B14: 沙拉 | C14: 厚蛋時蔬握沙拉 | E14: 39.46 | F14: 1626 | G14: =E14*F14 -> 64161.96 | I14: 15 | J14: 1500 | K14: =J14/I14 -> 100 | L14: 15 | M14: =F14/V14*60 -> 1434.7059 | N14: =M14/L14 -> 95.647059 | O14: =L14-I14 -> 0 | P14: =N14-K14 -> -4.3529412 | Q14: =N14/K14 -> 0.95647059 | S14: 0.30277778 | T14: 0.35 | U14: =IF(S14=TIME(17,0,0),"",(S14-T13)*24*60) -> 6 | V14: =(T14-S14)*24*60 -> 68 | AE14: =M14-J14 -> -65.294118 | AF14: =M14/J14 -> 0.95647059
A15: 新豐5線 | B15: 微波主食 | C15: 二配打拋風味豬肉飯 | E15: 51.06 | F15: 2986 | G15: =E15*F15 -> 152465.16 | I15: 13 | J15: 2000 | K15: =J15/I15 -> 153.84615 | L15: 13 | M15: =F15/V15*60 -> 1905.9574 | N15: =M15/L15 -> 146.61211 | O15: =L15-I15 -> 0 | P15: =N15-K15 -> -7.2340426 | Q15: =N15/K15 -> 0.95297872 | S15: 0.70833333 | T15: 0.77361111 | U15: =IF(S15=TIME(17,0,0),"",(S15-T14)*24*60) | V15: =(T15-S15)*24*60 -> 94 | AE15: =M15-J15 -> -94.042553 | AF15: =M15/J15 -> 0.95297872
A16: 新豐5線 | B16: 微波主食 | C16: 二配厚香料優格咖哩雞排飯 | E16: 56.43 | F16: 1380 | G16: =E16*F16 -> 77873.4 | I16: 13 | J16: 2000 | K16: =J16/I16 -> 153.84615 | L16: 13 | M16: =F16/V16*60 -> 1925.5814 | N16: =M16/L16 -> 148.12165 | O16: =L16-I16 -> 0 | P16: =N16-K16 -> -5.7245081 | Q16: =N16/K16 -> 0.9627907 | S16: 0.77916667 | T16: 0.80902778 | U16: =IF(S16=TIME(17,0,0),"",(S16-T15)*24*60) -> 8 | V16: =(T16-S16)*24*60 -> 43 | AE16: =M16-J16 -> -74.418605 | AF16: =M16/J16 -> 0.9627907
A17: 新豐5線 | B17: 微波主食 | C17: 二配玉米濃湯焗烤飯 | E17: 54.5 | F17: 921 | G17: =E17*F17 -> 50194.5 | I17: 19 | J17: 1500 | K17: =J17/I17 -> 78.947368 | L17: 19 | M17: =F17/V17*60 -> 1454.2105 | N17: =M17/L17 -> 76.537396 | O17: =L17-I17 -> 0 | P17: =N17-K17 -> -2.4099723 | Q17: =N17/K17 -> 0.96947368 | S17: 0.81319444 | T17: 0.83958333 | U17: =IF(S17=TIME(17,0,0),"",(S17-T16)*24*60) -> 6 | V17: =(T17-S17)*24*60 -> 38 | AE17: =M17-J17 -> -45.789474 | AF17: =M17/J17 -> 0.96947368
A18: 新豐5線 | B18: 平均 | I18: 16.666667 | J18: 1750 | K18: =J18/I18 -> 105 | L18: 16.666667 | M18: =AVERAGE(M12:M17) -> 1683.4689 | N18: =M18/L18 -> 101.00814 | O18: =L18-I18 -> 0 | P18: =N18-K18 -> -3.9918646 | Q18: =N18/K18 -> 0.96198224 | Y18: =SUM(Y12:Y17) -> 0 | Z18: =SUM(Z12:Z17) -> 0 | AC18: 6 | AD18: =SUM(AD12:AD17) -> 0 | AE18: =M18-J18 -> -66.531077 | AF18: =M18/J18 -> 0.96198224
A19: 新豐7線 | B19: 微波主食 | C19: 韓式泡菜豬肉豆腐丼飯 | E19: 50.67 | F19: 1218 | G19: =E19*F19 -> 61716.06 | I19: 17 | J19: 2000 | K19: =J19/I19 -> 117.64706 | L19: 17 | M19: =F19/V19*60 -> 1923.1579 | N19: =M19/L19 -> 113.12693 | O19: =L19-I19 -> 0 | P19: =N19-K19 -> -4.5201238 | Q19: =N19/K19 -> 0.96157895 | R19: =Q26 -> 0.96048084 | S19: 0.25 | T19: 0.27638889 | V19: =(T19-S19)*24*60 -> 38 | AC19: 7 | AE19: =M19-J19 -> -76.842105 | AF19: =M19/J19 -> 0.96157895 | AG19: =AF26 -> 0.96048084
A20: 新豐7線 | B20: 微波主食 | C20: 鐵板滑蛋炸豬排丼 | E20: 57.73 | F20: 2050 | G20: =E20*F20 -> 118346.5 | I20: 14 | J20: 2000 | K20: =J20/I20 -> 142.85714 | L20: 14 | M20: =F20/V20*60 -> 1921.875 | N20: =M20/L20 -> 137.27679 | O20: =L20-I20 -> 0 | P20: =N20-K20 -> -5.5803571 | Q20: =N20/K20 -> 0.9609375 | S20: 0.27986111 | T20: 0.32430556 | U20: =IF(S20=TIME(17,0,0),"",(S20-T19)*24*60) -> 5 | V20: =(T20-S20)*24*60 -> 64 | AE20: =M20-J20 -> -78.125 | AF20: =M20/J20 -> 0.9609375
A21: 新豐7線 | B21: 微波主食 | C21: 日式炙烤親子丼 | E21: 53.27 | F21: 1232 | G21: =E21*F21 -> 65628.64 | I21: 16 | J21: 2000 | K21: =J21/I21 -> 125 | L21: 16 | M21: =F21/V21*60 -> 1945.2632 | N21: =M21/L21 -> 121.57895 | O21: =L21-I21 -> 0 | P21: =N21-K21 -> -3.4210526 | Q21: =N21/K21 -> 0.97263158 | S21: 0.32986111 | T21: 0.35625 | U21: =IF(S21=TIME(17,0,0),"",(S21-T20)*24*60) -> 8 | V21: =(T21-S21)*24*60 -> 38 | AE21: =M21-J21 -> -54.736842 | AF21: =M21/J21 -> 0.97263158
A22: 新豐7線 | B22: 微波主食 | C22: 二配川味麻婆燒豆腐燴飯 | E22: 50.49 | F22: 2129 | G22: =E22*F22 -> 107493.21 | I22: 15 | J22: 2000 | K22: =J22/I22 -> 133.33333 | L22: 15 | M22: =F22/V22*60 -> 1906.5672 | N22: =M22/L22 -> 127.10448 | O22: =L22-I22 -> 0 | P22: =N22-K22 -> -6.2288557 | Q22: =N22/K22 -> 0.95328358 | S22: 0.70833333 | T22: 0.75486111 | U22: =IF(S22=TIME(17,0,0),"",(S22-T21)*24*60) | V22: =(T22-S22)*24*60 -> 67 | AE22: =M22-J22 -> -93.432836 | AF22: =M22/J22 -> 0.95328358
A23: 新豐7線 | B23: 微波主食 | C23: 二配美味蟹煲 | E23: 54.09 | F23: 2066 | G23: =E23*F23 -> 111749.94 | I23: 18 | J23: 2000 | K23: =J23/I23 -> 111.11111 | L23: 18 | M23: =F23/V23*60 -> 1907.0769 | N23: =M23/L23 -> 105.94872 | O23: =L23-I23 -> 0 | P23: =N23-K23 -> -5.1623932 | Q23: =N23/K23 -> 0.95353846 | S23: 0.75833333 | T23: 0.80347222 | U23: =IF(S23=TIME(17,0,0),"",(S23-T22)*24*60) -> 5 | V23: =(T23-S23)*24*60 -> 65 | AE23: =M23-J23 -> -92.923077 | AF23: =M23/J23 -> 0.95353846
A24: 新豐7線 | B24: 微波主食 | C24: 二配港式滑蛋牛肉燴飯 | E24: 50.67 | F24: 1000 | G24: =E24*F24 -> 50670 | H24: 2 | I24: 16 | J24: 2000 | K24: =J24/I24 -> 125 | L24: 16 | M24: =F24/V24*60 -> 1935.4839 | N24: =M24/L24 -> 120.96774 | O24: =L24-I24 -> 0 | P24: =N24-K24 -> -4.0322581 | Q24: =N24/K24 -> 0.96774194 | S24: 0.80902778 | T24: 0.83055556 | U24: =IF(S24=TIME(17,0,0),"",(S24-T23)*24*60) -> 8 | V24: =(T24-S24)*24*60 -> 31 | W24: =T24 -> 0.83055556 | X24: =S25 -> 0.87152778 | AE24: =M24-J24 -> -64.516129 | AF24: =M24/J24 -> 0.96774194
A25: 新豐7線 | B25: 微波主食 | C25: 二配港式滑蛋牛肉燴飯 | E25: 50.67 | F25: 1653 | G25: =E25*F25 -> 83757.51 | I25: 16 | J25: 2000 | K25: =J25/I25 -> 125 | L25: 16 | M25: =F25/V25*60 -> 1907.3077 | N25: =M25/L25 -> 119.20673 | O25: =L25-I25 -> 0 | P25: =N25-K25 -> -5.7932692 | Q25: =N25/K25 -> 0.95365385 | S25: 0.87152778 | T25: 0.90763889 | U25: =IF(S25=TIME(17,0,0),"",(S25-T24)*24*60) -> 59 | V25: =(T25-S25)*24*60 -> 52 | AE25: =M25-J25 -> -92.692308 | AF25: =M25/J25 -> 0.95365385
A26: 新豐7線 | B26: 平均 | I26: 16 | J26: 2000 | K26: =J26/I26 -> 125 | L26: 16 | M26: =AVERAGE(M19:M25) -> 1920.9617 | N26: =M26/L26 -> 120.0601 | O26: =L26-I26 -> 0 | P26: =N26-K26 -> -4.9398955 | Q26: =N26/K26 -> 0.96048084 | Y26: =SUM(Y19:Y25) -> 0 | Z26: =SUM(Z19:Z25) -> 0 | AC26: 7 | AD26: =SUM(AD19:AD25) -> 0 | AE26: =M26-J26 -> -79.038328 | AF26: =M26/J26 -> 0.96048084
A27: 新豐8線 | B27: 三明治 | C27: 紐奧良風味烤雞鮮蔬三明治 | E27: 31.29 | F27: 7310 | G27: =E27*F27 -> 228729.9 | I27: 18 | J27: 2400 | K27: =J27/I27 -> 133.33333 | L27: 18 | M27: =F27/V27*60 -> 2284.375 | N27: =M27/L27 -> 126.90972 | O27: =L27-I27 -> 0 | P27: =N27-K27 -> -6.4236111 | Q27: =N27/K27 -> 0.95182292 | R27: =Q31 -> 0.95279617 | S27: 0.083333333 | T27: 0.21666667 | V27: =(T27-S27)*24*60 -> 192 | W27: =T27 -> 0.21666667 | X27: =S28 -> 0.23611111 | AC27: 4 | AE27: =M27-J27 -> -115.625 | AF27: =M27/J27 -> 0.95182292 | AG27: =AF31 -> 0.95279617
A28: 新豐8線 | B28: 三明治 | C28: 醬燒烤雞三明治(115年) | E28: 26.37 | F28: 4922 | G28: =E28*F28 -> 129793.14 | I28: 18 | J28: 2400 | K28: =J28/I28 -> 133.33333 | L28: 18 | M28: =F28/V28*60 -> 2289.3023 | N28: =M28/L28 -> 127.18346 | O28: =L28-I28 -> 0 | P28: =N28-K28 -> -6.1498708 | Q28: =N28/K28 -> 0.95387597 | S28: 0.23611111 | T28: 0.32569444 | U28: =(S28-T27)*24*60 -> 28 | V28: =(T28-S28)*24*60 -> 129 | AE28: =M28-J28 -> -110.69767 | AF28: =M28/J28 -> 0.95387597
A29: 新豐8線 | B29: 三明治 | C29: 經典火腿玉米蛋三明治 | E29: 24.43 | F29: 5553 | G29: =E29*F29 -> 135659.79 | I29: 14 | J29: 2400 | K29: =J29/I29 -> 171.42857 | L29: 14 | M29: =F29/V29*60 -> 2282.0548 | N29: =M29/L29 -> 163.00391 | O29: =L29-I29 -> 0 | P29: =N29-K29 -> -8.4246575 | Q29: =N29/K29 -> 0.95085616 | S29: 0.32916667 | T29: 0.43055556 | U29: =(S29-T28)*24*60 -> 5 | V29: =(T29-S29)*24*60 -> 146 | AE29: =M29-J29 -> -117.94521 | AF29: =M29/J29 -> 0.95085616
A30: 新豐8線 | B30: 三明治 | C30: 好多菜三明治 | E30: 25.98 | F30: 3093 | G30: =E30*F30 -> 80356.14 | I30: 19 | J30: 2400 | K30: =J30/I30 -> 126.31579 | L30: 19 | M30: =F30/V30*60 -> 2291.1111 | N30: =M30/L30 -> 120.5848 | O30: =L30-I30 -> 0 | P30: =N30-K30 -> -5.7309942 | Q30: =N30/K30 -> 0.95462963 | S30: 0.43472222 | T30: 0.49097222 | U30: =(S30-T29)*24*60 -> 6 | V30: =(T30-S30)*24*60 -> 81 | AE30: =M30-J30 -> -108.88889 | AF30: =M30/J30 -> 0.95462963
A31: 新豐8線 | B31: 平均 | I31: 17.25 | J31: 2400 | K31: =J31/I31 -> 139.13043 | L31: 17.25 | M31: =AVERAGE(M27:M30) -> 2286.7108 | N31: =M31/L31 -> 132.56295 | O31: =L31-I31 -> 0 | P31: =N31-K31 -> -6.5674894 | Q31: =N31/K31 -> 0.95279617 | Y31: =SUM(Y27:Y30) -> 0 | Z31: =SUM(Z27:Z30) -> 0 | AC31: 4 | AD31: =SUM(AD27:AD30) -> 0 | AE31: =M31-J31 -> -113.28919 | AF31: =M31/J31 -> 0.95279617
A32: 新豐9線 | B32: 三明治 | C32: 經典總匯三明治(115年) | E32: 26.18 | F32: 4652 | G32: =E32*F32 -> 121789.36 | I32: 20 | J32: 2400 | K32: =J32/I32 -> 120 | L32: 20 | M32: =F32/V32*60 -> 2287.8689 | N32: =M32/L32 -> 114.39344 | O32: =L32-I32 -> 0 | P32: =N32-K32 -> -5.6065574 | Q32: =N32/K32 -> 0.95327869 | R32: =Q37 -> 0.95958034 | S32: 0.083333333 | T32: 0.16805556 | V32: =(T32-S32)*24*60 -> 122 | W32: =T32 -> 0.16805556 | X32: =S33 -> 0.18541667 | AC32: 5 | AE32: =M32-J32 -> -112.13115 | AF32: =M32/J32 -> 0.95327869 | AG32: =AF37 -> 0.95958034
A33: 新豐9線 | B33: 三明治 | C33: 鮪魚起司溏心蛋三明治(115年) | E33: 26.18 | F33: 6019 | G33: =E33*F33 -> 157577.42 | I33: 18 | J33: 2400 | K33: =J33/I33 -> 133.33333 | L33: 18 | M33: =F33/V33*60 -> 2285.6962 | N33: =M33/L33 -> 126.98312 | O33: =L33-I33 -> 0 | P33: =N33-K33 -> -6.350211 | Q33: =N33/K33 -> 0.95237342 | S33: 0.18541667 | T33: 0.29513889 | U33: =(S33-T32)*24*60 -> 25 | V33: =(T33-S33)*24*60 -> 158 | AE33: =M33-J33 -> -114.3038 | AF33: =M33/J33 -> 0.95237342
A34: 新豐9線 | B34: 三明治 | C34: 好多蛋三明治 | E34: 34.1 | F34: 4916 | G34: =E34*F34 -> 167635.6 | I34: 17 | J34: 1600 | K34: =J34/I34 -> 94.117647 | L34: 17 | M34: =F34/V34*60 -> 1528.2902 | N34: =M34/L34 -> 89.899421 | O34: =L34-I34 -> 0 | P34: =N34-K34 -> -4.2182262 | Q34: =N34/K34 -> 0.95518135 | S34: 0.3 | T34: 0.43402778 | U34: =(S34-T33)*24*60 -> 7 | V34: =(T34-S34)*24*60 -> 193 | AE34: =M34-J34 -> -71.709845 | AF34: =M34/J34 -> 0.95518135
A35: 新豐9線 | B35: 三明治 | C35: 金黃玉米蛋三明治 | E35: 24.25 | F35: 1126 | G35: =E35*F35 -> 27305.5 | I35: 16 | J35: 2400 | K35: =J35/I35 -> 150 | L35: 16 | M35: =F35/V35*60 -> 2329.6552 | N35: =M35/L35 -> 145.60345 | O35: =L35-I35 -> 0 | P35: =N35-K35 -> -4.3965517 | Q35: =N35/K35 -> 0.97068966 | S35: 0.4375 | T35: 0.45763889 | U35: =(S35-T34)*24*60 -> 5 | V35: =(T35-S35)*24*60 -> 29 | AE35: =M35-J35 -> -70.344828 | AF35: =M35/J35 -> 0.97068966
A36: 新豐9線 | B36: 三明治 | C36: 巧克力肉鬆三明治 | E36: 23.89 | F36: 2200 | G36: =E36*F36 -> 52558 | I36: 17 | J36: 2400 | K36: =J36/I36 -> 141.17647 | L36: 17 | M36: =F36/V36*60 -> 2315.7895 | N36: =M36/L36 -> 136.22291 | O36: =L36-I36 -> 0 | P36: =N36-K36 -> -4.9535604 | Q36: =N36/K36 -> 0.96491228 | S36: 0.46111111 | T36: 0.50069444 | U36: =(S36-T35)*24*60 -> 5 | V36: =(T36-S36)*24*60 -> 57 | AE36: =M36-J36 -> -84.210526 | AF36: =M36/J36 -> 0.96491228
A37: 新豐9線 | B37: 平均 | I37: 17.6 | J37: 2240 | K37: =J37/I37 -> 127.27273 | L37: 17.6 | M37: =AVERAGE(M32:M36) -> 2149.46 | N37: =M37/L37 -> 122.12841 | O37: =L37-I37 -> 0 | P37: =N37-K37 -> -5.1443198 | Q37: =N37/K37 -> 0.95958034 | Y37: =SUM(Y32:Y36) -> 0 | Z37: =SUM(Z32:Z36) -> 0 | AC37: 5 | AD37: =SUM(AD32:AD36) -> 0 | AE37: =M37-J37 -> -90.540029 | AF37: =M37/J37 -> 0.95958034
A38: 新豐3線 | B38: 調理麵包 | C38: 豬肉起司堡 | E38: 21.13 | F38: 4014 | G38: =E38*F38 -> 84815.82 | I38: 10 | J38: 3000 | K38: =J38/I38 -> 300 | L38: 10 | M38: =F38/V38*60 -> 2867.1429 | N38: =M38/L38 -> 286.71429 | O38: =L38-I38 -> 0 | P38: =N38-K38 -> -13.285714 | Q38: =N38/K38 -> 0.95571429 | R38: =Q41 -> 0.95665604 | S38: 0.20833333 | T38: 0.26666667 | V38: =(T38-S38)*24*60 -> 84 | AC38: 3 | AE38: =M38-J38 -> -132.85714 | AF38: =M38/J38 -> 0.95571429 | AG38: =AF41 -> 0.95665604
A39: 新豐3線 | B39: 調理麵包 | C39: 豬肉起司蛋堡 | E39: 27.17 | F39: 4699 | G39: =E39*F39 -> 127671.83 | I39: 10 | J39: 3000 | K39: =J39/I39 -> 300 | L39: 10 | M39: =F39/V39*60 -> 2876.9388 | N39: =M39/L39 -> 287.69388 | O39: =L39-I39 -> 0 | P39: =N39-K39 -> -12.306122 | Q39: =N39/K39 -> 0.95897959 | S39: 0.27152778 | T39: 0.33958333 | U39: =(S39-T38)*24*60 -> 7 | V39: =(T39-S39)*24*60 -> 98 | AE39: =M39-J39 -> -123.06122 | AF39: =M39/J39 -> 0.95897959
A40: 新豐3線 | B40: 調理麵包 | C40: 墨西哥辣醬熱狗堡 | E40: 37.88 | F40: 2291 | G40: =E40*F40 -> 86783.08 | I40: 13 | J40: 2000 | K40: =J40/I40 -> 153.84615 | L40: 13 | M40: =F40/V40*60 -> 1909.1667 | N40: =M40/L40 -> 146.85897 | O40: =L40-I40 -> 0 | P40: =N40-K40 -> -6.9871795 | Q40: =N40/K40 -> 0.95458333 | S40: 0.34444444 | T40: 0.39444444 | U40: =(S40-T39)*24*60 -> 7 | V40: =(T40-S40)*24*60 -> 72 | AE40: =M40-J40 -> -90.833333 | AF40: =M40/J40 -> 0.95458333
...

Sheet 0926
B1: 屏榮 新豐廠組合室生產人時性分析
B3: 日期 | C3: =TEXT('0926 4度C'!A2,"yyyy.mm.ddaaaa") -> 2026.09.26星期六 | E3: 訂單量 | F3: ='0926 4度C'!D1 -> 117582 | H3: 營業額 | I3: ='0926 4度C'!F1 -> 3999174.8
B4: 人時性 | C4: 項目 | E4: ➀ | G4: ➁ | I4: ➂ | K4: 異常停線 | M4: 短暫停線
C5: 組合室 | E5: 全溫層 | G5: 4度C-各編組展開 | I5: ③三明治-各編組展開 | K5: 合計次數 | L5: 時間 | M5: 合計次數 | N5: 設備次數
C6: 排關平均 | E6: =AVERAGE(D13:M13) -> 151.16939 | F6: =AVERAGE(D31:O31,D13:J13) -> 155.88783 | G6: =AVERAGE(D13:J13) -> 155.88783 | I6: =AVERAGE(K13:M13) -> 140.15968 | K6: ='0926 4度C'!Y2 -> 0 | L6: ='0926 4度C'!Z2 -> 0 | M6: ='0926 4度C'!AC2 -> 50 | N6: ='0926 4度C'!AD2 -> 0
C7: 實績平均 | E7: =AVERAGE(D14:M14) -> 145.1635 | F7: =AVERAGE(D32:O32,D14:J14) -> 149.71467 | G7: =AVERAGE(D14:J14) -> 149.71467 | I7: =AVERAGE(K14:M14) -> 134.54412
C8: 達成率平均 | E8: =AVERAGE(D15:M15) -> 0.96071083 | F8: =AVERAGE(D15:J15,D33:O33) -> 0.96099551 | G8: =AVERAGE(D15:J15) -> 0.96099551 | I8: =AVERAGE(K15:M15) -> 0.96004659
K9: ※現行日本鮮食廠以達成率80%為基本(即為現行KPI)
B10: 溫層 | D10: ➁4度C-各編組展開 | K10: ③三明治-各編組展開
B11: 編組 | D11: 1 | E11: 2 | F11: 3 | G11: 4 | H11: 5 | I11: 6 | J11: 7 | K11: 1 | L11: 2 | M11: 3
D12: 新豐6線 | E12: 新豐2線 | F12: 新豐5線 | G12: 新豐7線 | H12: 新豐3線 | I12: 新豐1線 | J12: 新豐10線 | K12: 新豐8線 | L12: 新豐9線 | M12: 新豐4線
B13: 人時性 | C13: 排關 | D13: =SUMIFS('0926 4度C'!$K:$K,'0926 4度C'!$A:$A,"新豐6線",'0926 4度C'!$B:$B,"平均") -> 130.43478 | E13: =SUMIFS('0926 4度C'!$K:$K,'0926 4度C'!$A:$A,"新豐2線",'0926 4度C'!$B:$B,"平均") -> 83.333333 | F13: =SUMIFS('0926 4度C'!$K:$K,'0926 4度C'!$A:$A,"新豐5線",'0926 4度C'!$B:$B,"平均") -> 105 | G13: =SUMIFS('0926 4度C'!$K:$K,'0926 4度C'!$A:$A,"新豐7線",'0926 4度C'!$B:$B,"平均") -> 126.31579 | H13: =SUMIFS('0926 4度C'!$K:$K,'0926 4度C'!$A:$A,"新豐3線",'0926 4度C'!$B:$B,"平均") -> 242.42424 | I13: =SUMIFS('0926 4度C'!$K:$K,'0926 4度C'!$A:$A,"新豐1線",'0926 4度C'!$B:$B,"平均") -> 109.58904 | J13: =SUMIFS('0926 4度C'!$K:$K,'0926 4度C'!$A:$A,"新豐10線",'0926 4度C'!$B:$B,"平均") -> 294.11765 | K13: =SUMIFS('0926 4度C'!$K:$K,'0926 4度C'!$A:$A,"新豐8線",'0926 4度C'!$B:$B,"平均") -> 146.34146 | L13: =SUMIFS('0926 4度C'!$K:$K,'0926 4度C'!$A:$A,"新豐9線",'0926 4度C'!$B:$B,"平均") -> 131.76471 | M13: =SUMIFS('0926 4度C'!$K:$K,'0926 4度C'!$A:$A,"新豐4線",'0926 4度C'!$B:$B,"平均") -> 142.37288
C14: 實績 | D14: =SUMIFS('0926 4度C'!$N:$N,'0926 4度C'!$A:$A,"新豐6線",'0926 4度C'!$B:$B,"平均") -> 125.81398 | E14: =SUMIFS('0926 4度C'!$N:$N,'0926 4度C'!$A:$A,"新豐2線",'0926 4度C'!$B:$B,"平均") -> 79.43166 | F14: =SUMIFS('0926 4度C'!$N:$N,'0926 4度C'!$A:$A,"新豐5線",'0926 4度C'!$B:$B,"平均") -> 101.28758 | G14: =SUMIFS('0926 4度C'!$N:$N,'0926 4度C'!$A:$A,"新豐7線",'0926 4度C'!$B:$B,"平均") -> 121.08184 | H14: =SUMIFS('0926 4度C'!$N:$N,'0926 4度C'!$A:$A,"新豐3線",'0926 4度C'!$B:$B,"平均") -> 231.72561 | I14: =SUMIFS('0926 4度C'!$N:$N,'0926 4度C'!$A:$A,"新豐1線",'0926 4度C'!$B:$B,"平均") -> 106.32099 | J14: =SUMIFS('0926 4度C'!$N:$N,'0926 4度C'!$A:$A,"新豐10線",'0926 4度C'!$B:$B,"平均") -> 282.34101 | K14: =SUMIFS('0926 4度C'!$N:$N,'0926 4度C'!$A:$A,"新豐8線",'0926 4度C'!$B:$B,"平均") -> 139.45001 | L14: =SUMIFS('0926 4度C'!$N:$N,'0926 4度C'!$A:$A,"新豐9線",'0926 4度C'!$B:$B,"平均") -> 126.73379 | M14: =SUMIFS('0926 4度C'!$N:$N,'0926 4度C'!$A:$A,"新豐4線",'0926 4度C'!$B:$B,"平均") -> 137.44855
C15: 達成率 | D15: =D14/D13 -> 0.96457385 | E15: =E14/E13 -> 0.95317992 | F15: =F14/F13 -> 0.96464364 | G15: =G14/G13 -> 0.95856453 | H15: =H14/H13 -> 0.95586813 | I15: =I14/I13 -> 0.97017905 | J15: =J14/J13 -> 0.95995943 | K15: =K14/K13 -> 0.95290838 | ... M15: =M14/M13 -> 0.96541241
B16: 作業 時間 | C16: 開始 | D16: =VLOOKUP("新豐6線",'0926 4度C'!$A:$T,19,0) -> 0.70833333 | E16: =VLOOKUP("新豐2線",'0926 4度C'!$A:$T,19,0) -> 0.083333333 | F16: =VLOOKUP("新豐5線",'0926 4度C'!$A:$T,19,0) -> 0.20833333 | G16: =VLOOKUP("新豐7線",'0926 4度C'!$A:$T,19,0) -> 0.25 | H16: =VLOOKUP("新豐3線",'0926 4度C'!$A:$T,19,0) -> 0.20833333 | I16: =VLOOKUP("新豐1線",'0926 4度C'!$A:$T,19,0) -> 0.20833333 | J16: =VLOOKUP("新豐10線",'0926 4度C'!$A:$T,19,0) -> 0.20833333 | K16: =VLOOKUP("新豐8線",'0926 4度C'!$A:$T,19,0) -> 0.083333333 | L16: =VLOOKUP("新豐9線",'0926 4度C'!$A:$T,19,0) -> 0.083333333 | M16: =VLOOKUP("新豐4線",'0926 4度C'!$A:$T,19,0) -> 0.083333333
C17: 結束 | D17: =LOOKUP(2,1/(('0926 4度C'!$A:$A="新豐6線")*('0926 4度C'!$T:$T<>"")),'0926 4度C'!$T:$T) -> 0.81597222 | E17: =LOOKUP(2,1/(('0926 4度C'!$A:$A="新豐2線")*('0926 4度C'!$T:$T<>"")),'0926 4度C'!$T:$T) -> 0.32291667 | F17: =LOOKUP(2,1/(('0926 4度C'!$A:$A="新豐5線")*('0926 4度C'!$T:$T<>"")),'0926 4度C'!$T:$T) -> 0.79513889 | G17: =LOOKUP(2,1/(('0926 4度C'!$A:$A="新豐7線")*('0926 4度C'!$T:$T<>"")),'0926 4度C'!$T:$T) -> 0.83125 | H17: =LOOKUP(2,1/(('0926 4度C'!$A:$A="新豐3線")*('0926 4度C'!$T:$T<>"")),'0926 4度C'!$T:$T) -> 0.37708333 | I17: =LOOKUP(2,1/(('0926 4度C'!$A:$A="新豐1線")*('0926 4度C'!$T:$T<>"")),'0926 4度C'!$T:$T) -> 0.80625 | J17: =LOOKUP(2,1/(('0926 4度C'!$A:$A="新豐10線")*('0926 4度C'!$T:$T<>"")),'0926 4度C'!$T:$T) -> 0.4 | K17: =LOOKUP(2,1/(('0926 4度C'!$A:$A="新豐8線")*('0926 4度C'!$T:$T<>"")),'0926 4度C'!$T:$T) -> 0.48333333 | L17: =LOOKUP(2,1/(('0926 4度C'!$A:$A="新豐9線")*('0926 4度C'!$T:$T<>"")),'0926 4度C'!$T:$T) -> 0.49027778 | M17: =LOOKUP(2,1/(('0926 4度C'!$A:$A="新豐4線")*('0926 4度C'!$T:$T<>"")),'0926 4度C'!$T:$T) -> 0.47083333
